File: Data/compression 11/AutoNoHeating-10-11-1-240529_05292024_155944.csv
Time (sec),S:Load (lbs),S:HL1 (DIM),S:LVDT (in),S:Position (in),Ch:Position (mm),Ch:Load (N),Ch:Stress (MPa),Ch:Strain (mm/mm),Ch:HL1 (DIM),Set Point (),Cycles ()
0.110000,0.004845,-1297.909668,-0.009593,-0.000000,-0.000000,0.021550,0.001098,-0.000000,-1297.909668,0.000208,0.000000
0.350000,-0.016380,-1297.954102,-0.009580,0.000000,0.000009,-0.072863,-0.003712,0.000087,-1297.954102,0.000416,0.000000
0.590000,0.011169,-1297.954102,-0.009593,0.000138,0.003512,0.049684,0.002531,0.035122,-1297.954102,0.004405,0.000000
0.830000,0.038353,-1297.909668,-0.009511,0.000283,0.007198,0.170603,0.008691,0.071979,-1297.909668,0.008412,0.000000
1.070000,0.065910,-1297.909668,-0.009360,0.000445,0.011309,0.293184,0.014935,0.113085,-1297.909668,0.012401,0.000000
1.310000,0.053253,-1297.865234,-0.009201,0.000600,0.015237,0.236882,0.012067,0.152370,-1297.865234,0.016408,0.000000
1.550000,0.013405,-1297.909668,-0.009041,0.000754,0.019140,0.059628,0.003038,0.191396,-1297.909668,0.020397,0.000000
1.790000,0.040962,-1297.998657,-0.008873,0.000915,0.023242,0.182209,0.009282,0.232417,-1297.998657,0.024404,0.000000
2.030000,0.033890,-1297.998657,-0.008731,0.001067,0.027109,0.150749,0.007680,0.271095,-1297.998657,0.028393,0.000000
2.270000,0.023834,-1297.954102,-0.008558,0.001234,0.031333,0.106020,0.005401,0.313329,-1297.954102,0.032399,0.000000
2.510000,-0.017128,-1297.998657,-0.008407,0.001388,0.035244,-0.076189,-0.003881,0.352440,-1297.998657,0.036389,0.000000
2.750000,0.044312,-1297.865234,-0.008244,0.001546,0.039268,0.197107,0.010041,0.392679,-1297.865234,0.040395,0.000000
2.990000,0.074844,-1297.909668,-0.008106,0.001698,0.043127,0.332924,0.016960,0.431272,-1297.909668,0.044385,0.000000
3.230000,0.060326,-1297.998657,-0.007929,0.001863,0.047316,0.268342,0.013670,0.473157,-1297.998657,0.048391,0.000000
3.470000,0.049896,-1297.865234,-0.007774,0.002017,0.051236,0.221950,0.011307,0.512357,-1297.865234,0.052380,0.000000
3.710000,0.026810,-1297.909668,-0.007631,0.002172,0.055173,0.119255,0.006075,0.551728,-1297.909668,0.056387,0.000000
3.950000,0.050270,-1297.954102,-0.007450,0.002328,0.059136,0.223612,0.011391,0.591361,-1297.954102,0.060376,0.000000
4.190000,0.014153,-1297.909668,-0.007286,0.002493,0.063333,0.062954,0.003207,0.633334,-1297.909668,0.064383,0.000000
4.430000,-0.022713,-1297.954102,-0.007114,0.002650,0.067305,-0.101031,-0.005147,0.673053,-1297.954102,0.068372,0.000000
4.670000,0.018990,-1297.909668,-0.006959,0.002804,0.071217,0.084470,0.004303,0.712166,-1297.909668,0.072379,0.000000
4.910000,0.068146,-1297.909668,-0.006812,0.002959,0.075171,0.303127,0.015442,0.751710,-1297.909668,0.076385,0.000000
5.150000,0.072243,-1297.954102,-0.006635,0.003120,0.079238,0.321352,0.016370,0.792385,-1297.954102,0.080375,0.000000
5.390000,0.047661,-1297.909668,-0.006493,0.003275,0.083193,0.212006,0.010800,0.831929,-1297.909668,0.084381,0.000000
5.630000,0.051018,-1297.909668,-0.006325,0.003437,0.087295,0.226938,0.011561,0.872950,-1297.909668,0.088370,0.000000
5.870000,0.037613,-1297.954102,-0.006170,0.003588,0.091128,0.167311,0.008523,0.911280,-1297.954102,0.092377,0.000000
6.110000,0.035004,-1297.998657,-0.006028,0.003745,0.095126,0.155704,0.007932,0.951260,-1297.998657,0.096366,0.000000
6.350000,0.006706,-1298.087646,-0.005864,0.003910,0.099323,0.029831,0.001520,0.993234,-1298.087646,0.100373,0.000000
6.590000,-0.007446,-1297.954102,-0.005713,0.004064,0.103217,-0.033123,-0.001687,1.032171,-1297.954102,0.104362,0.000000
6.830000,0.054741,-1297.998657,-0.005553,0.004219,0.107172,0.243500,0.012404,1.071718,-1297.998657,0.108369,0.000000
7.070000,0.073357,-1297.909668,-0.005389,0.004376,0.111161,0.326307,0.016623,1.111610,-1297.909668,0.112358,0.000000
7.310000,0.078201,-1297.954102,-0.005226,0.004540,0.115306,0.347857,0.017721,1.153063,-1297.954102,0.116364,0.000000
7.550000,0.050644,-1297.998657,-0.005075,0.004695,0.119261,0.225275,0.011476,1.192609,-1297.998657,0.120354,0.000000
7.790000,0.070381,-1297.954102,-0.004919,0.004854,0.123294,0.313071,0.015949,1.232935,-1297.954102,0.124360,0.000000
8.030001,0.064049,-1297.998657,-0.004769,0.005003,0.127083,0.284903,0.014514,1.270831,-1297.998657,0.128349,0.000000
8.270000,0.062935,-1297.909668,-0.004596,0.005167,0.131246,0.279948,0.014261,1.312460,-1297.909668,0.132356,0.000000
8.510000,-0.000000,-1298.043091,-0.004441,0.005325,0.135252,-0.000000,-0.000000,1.352525,-1298.043091,0.136345,0.000000
8.750000,0.048035,-1297.954102,-0.004281,0.005480,0.139190,0.213669,0.010885,1.391897,-1297.954102,0.140352,0.000000
8.990001,0.095703,-1297.998657,-0.004139,0.005633,0.143084,0.425709,0.021687,1.430836,-1297.998657,0.144341,0.000000
9.230000,0.126236,-1297.954102,-0.003975,0.005798,0.147272,0.561526,0.028605,1.472722,-1297.954102,0.148348,0.000000
9.470000,0.238693,-1297.954102,-0.003803,0.005953,0.151218,1.061761,0.054089,1.512181,-1297.954102,0.152337,0.000000
9.710000,0.609573,-1297.998657,-0.003648,0.006115,0.155329,2.711518,0.138131,1.553287,-1297.998657,0.156343,0.000000
9.950001,0.613670,-1298.043091,-0.003596,-0.000000,-0.000000,2.729742,0.139060,-0.000000,-1298.043091,0.000260,0.000000
10.190001,0.582764,-1297.909668,-0.003591,-0.000000,-0.000000,2.592262,0.132056,-0.000000,-1297.909668,0.000260,0.000000
10.430000,0.571220,-1297.998657,-0.003596,-0.000000,-0.000000,2.540915,0.129440,-0.000000,-1297.998657,0.000520,0.000000
10.670000,0.571594,-1297.998657,-0.003596,-0.000000,-0.000000,2.542578,0.129525,-0.000000,-1297.998657,0.000928,0.000000
10.910001,0.626328,-1297.954102,-0.003604,0.000018,0.000468,2.786044,0.141928,0.004682,-1297.954102,0.001327,0.000000
11.150001,0.682190,-1298.087646,-0.003591,0.000038,0.000954,3.034532,0.154586,0.009538,-1298.087646,0.001726,0.000000
11.390000,0.723145,-1297.954102,-0.003583,0.000053,0.001336,3.216707,0.163867,0.013355,-1297.954102,0.002125,0.000000
11.630000,0.749962,-1298.043091,-0.003566,0.000063,0.001604,3.335997,0.169944,0.016042,-1298.043091,0.002524,0.000000
11.870001,0.786827,-1297.998657,-0.003557,0.000080,0.002021,3.499982,0.178298,0.020206,-1297.998657,0.002923,0.000000
12.110001,0.811775,-1297.998657,-0.003540,0.000093,0.002367,3.610956,0.183951,0.023675,-1297.998657,0.003321,0.000000
12.350000,0.872467,-1297.998657,-0.003531,0.000112,0.002844,3.880927,0.197704,0.028443,-1297.998657,0.003720,0.000000
12.590000,0.899277,-1297.998657,-0.003514,0.000126,0.003191,4.000183,0.203779,0.031912,-1297.998657,0.004128,0.000000
12.830001,0.942101,-1297.998657,-0.003514,0.000140,0.003556,4.190672,0.213483,0.035555,-1297.998657,0.004527,0.000000
13.070001,0.964821,-1297.998657,-0.003497,0.000159,0.004032,4.291738,0.218632,0.040324,-1297.998657,0.004926,0.000000
13.310000,1.027748,-1298.043091,-0.003458,0.000177,0.004483,4.571652,0.232891,0.044834,-1298.043091,0.005325,0.000000
13.550000,1.039291,-1297.954102,-0.003454,0.000190,0.004830,4.622999,0.235507,0.048303,-1297.954102,0.005724,0.000000
13.790001,1.045998,-1297.998657,-0.003441,0.000205,0.005212,4.652830,0.237026,0.052120,-1297.998657,0.006122,0.000000
14.030001,1.045998,-1298.043091,-0.003423,0.000216,0.005481,4.652830,0.237026,0.054807,-1298.043091,0.006521,0.000000
14.270000,1.122704,-1298.043091,-0.003410,0.000235,0.005975,4.994035,0.254408,0.059750,-1298.043091,0.006920,0.000000
14.510000,1.121216,-1298.043091,-0.003393,0.000248,0.006305,4.987417,0.254071,0.063047,-1298.043091,0.007328,0.000000
14.750001,1.151001,-1298.087646,-0.003389,0.000261,0.006634,5.119908,0.260821,0.066342,-1298.087646,0.007727,0.000000
14.990001,1.242981,-1297.954102,-0.003367,0.000286,0.007259,5.529056,0.281664,0.072587,-1297.954102,0.008126,0.000000
15.230000,1.242981,-1298.087646,-0.003341,0.000304,0.007718,5.529056,0.281664,0.077182,-1298.087646,0.008525,0.000000
15.470000,1.261223,-1297.998657,-0.003320,0.000318,0.008082,5.610199,0.285797,0.080825,-1297.998657,0.008924,0.000000
15.710001,1.293625,-1298.043091,-0.003320,0.000333,0.008447,5.754331,0.293140,0.084468,-1298.043091,0.009323,0.000000
15.950001,1.285431,-1298.043091,-0.003307,0.000344,0.008742,5.717882,0.291283,0.087416,-1298.043091,0.009722,0.000000
16.190001,1.355812,-1297.998657,-0.003281,0.000362,0.009184,6.030953,0.307231,0.091839,-1297.998657,0.010120,0.000000
16.430000,1.387085,-1298.043091,-0.003272,0.000377,0.009574,6.170062,0.314318,0.095741,-1298.043091,0.010528,0.000000
16.670000,1.382248,-1298.043091,-0.003255,0.000387,0.009834,6.148546,0.313222,0.098343,-1298.043091,0.010927,0.000000
16.910002,1.409431,-1297.998657,-0.003251,0.000403,0.010225,6.269464,0.319382,0.102245,-1297.998657,0.011326,0.000000
17.150002,1.468636,-1298.087646,-0.003234,0.000427,0.010858,6.532817,0.332798,0.108575,-1298.087646,0.011725,0.000000
17.390001,1.468262,-1297.998657,-0.003199,0.000439,0.011144,6.531154,0.332713,0.111437,-1297.998657,0.012124,0.000000
17.630001,1.471245,-1298.043091,-0.003195,0.000457,0.011612,6.544424,0.333389,0.116121,-1298.043091,0.012523,0.000000
17.870001,1.467148,-1297.998657,-0.003169,0.000470,0.011933,6.526199,0.332460,0.119330,-1297.998657,0.012922,0.000000
18.110001,1.513695,-1297.998657,-0.003169,0.000485,0.012315,6.733251,0.343008,0.123145,-1297.998657,0.013321,0.000000
18.350000,1.585190,-1298.043091,-0.003147,0.000506,0.012852,7.051277,0.359209,0.128522,-1298.043091,0.013728,0.000000
18.590000,1.556892,-1298.043091,-0.003126,0.000515,0.013069,6.925403,0.352797,0.130691,-1298.043091,0.014127,0.000000
18.830002,1.607529,-1298.043091,-0.003122,0.000534,0.013572,7.150645,0.364271,0.135721,-1298.043091,0.014526,0.000000
19.070002,1.669716,-1298.087646,-0.003109,0.000555,0.014092,7.427267,0.378363,0.140923,-1298.087646,0.014925,0.000000
19.310001,1.670837,-1298.043091,-0.003074,0.000570,0.014474,7.432256,0.378617,0.144740,-1298.043091,0.015324,0.000000
19.550001,1.643654,-1298.087646,-0.003065,0.000583,0.014821,7.311337,0.372457,0.148209,-1298.087646,0.015723,0.000000
19.790001,1.630249,-1297.998657,-0.003061,0.000595,0.015107,7.251710,0.369420,0.151070,-1297.998657,0.016122,0.000000
20.030001,1.730789,-1298.087646,-0.003044,0.000614,0.015584,7.698935,0.392202,0.155839,-1298.087646,0.016520,0.000000
20.270000,1.762436,-1298.043091,-0.003031,0.000628,0.015940,7.839706,0.399374,0.159395,-1298.043091,0.016928,0.000000
20.510000,1.760574,-1298.043091,-0.003009,0.000640,0.016260,7.831426,0.398952,0.162605,-1298.043091,0.017327,0.000000
20.750002,1.825371,-1298.043091,-0.002992,0.000661,0.016798,8.119655,0.413635,0.167981,-1298.043091,0.017726,0.000000
20.990002,1.862610,-1297.998657,-0.002979,0.000679,0.017249,8.285302,0.422073,0.172491,-1297.998657,0.018125,0.000000
21.230001,1.871170,-1298.087646,-0.002966,0.000695,0.017657,8.323380,0.424013,0.176567,-1298.087646,0.018524,0.000000
21.470001,1.852928,-1298.043091,-0.002936,0.000712,0.018073,8.242236,0.419880,0.180729,-1298.043091,0.018923,0.000000
21.710001,1.869308,-1298.043091,-0.002923,0.000725,0.018411,8.315100,0.423591,0.184111,-1298.043091,0.019322,0.000000
21.950001,1.936707,-1298.087646,-0.002932,0.000743,0.018862,8.614901,0.438864,0.188620,-1298.087646,0.019729,0.000000
22.190001,1.978043,-1298.087646,-0.002893,0.000758,0.019244,8.798773,0.448231,0.192437,-1298.087646,0.020128,0.000000
22.430000,1.939690,-1298.043091,-0.002893,0.000768,0.019512,8.628170,0.439540,0.195125,-1298.043091,0.020527,0.000000
22.670002,2.000755,-1298.087646,-0.002876,0.000784,0.019920,8.899804,0.453378,0.199201,-1298.087646,0.020926,0.000000
22.910002,2.070023,-1298.043091,-0.002850,0.000806,0.020475,9.207920,0.469074,0.204751,-1298.043091,0.021325,0.000000
23.150002,2.076347,-1298.132080,-0.002846,0.000821,0.020848,9.236054,0.470507,0.208480,-1298.132080,0.021724,0.000000
23.390001,2.075974,-1297.998657,-0.002828,0.000838,0.021282,9.234391,0.470422,0.212817,-1297.998657,0.022123,0.000000
23.630001,2.107628,-1298.087646,-0.002807,0.000853,0.021672,9.375197,0.477595,0.216719,-1298.087646,0.022522,0.000000
23.870001,2.126244,-1298.043091,-0.002790,0.000867,0.022010,9.458004,0.481814,0.220101,-1298.043091,0.022929,0.000000
24.110001,2.176888,-1298.043091,-0.002781,0.000880,0.022357,9.683279,0.493290,0.223570,-1298.043091,0.023328,0.000000
24.350000,2.195511,-1298.132080,-0.002768,0.000895,0.022730,9.766120,0.497510,0.227300,-1298.132080,0.023727,0.000000
24.590002,2.273705,-1298.087646,-0.002746,0.000913,0.023198,10.113943,0.515229,0.231982,-1298.087646,0.024126,0.000000
24.830002,2.367172,-1298.132080,-0.002729,0.000936,0.023771,10.529708,0.536409,0.237707,-1298.132080,0.024525,0.000000
25.070002,2.329933,-1298.176514,-0.002712,0.000946,0.024031,10.364060,0.527970,0.240307,-1298.176514,0.024924,0.000000
25.310001,2.337379,-1298.087646,-0.002699,0.000962,0.024430,10.397183,0.529658,0.244296,-1298.087646,0.025323,0.000000
25.550001,2.376854,-1298.087646,-0.002686,0.000977,0.024820,10.572774,0.538603,0.248198,-1298.087646,0.025722,0.000000
25.790001,2.375366,-1298.087646,-0.002665,0.000991,0.025167,10.566156,0.538266,0.251669,-1298.087646,0.026129,0.000000
26.030001,2.455055,-1298.087646,-0.002647,0.001010,0.025661,10.920631,0.556323,0.256612,-1298.087646,0.026528,0.000000
26.270000,2.482239,-1298.132080,-0.002643,0.001023,0.025982,11.041550,0.562483,0.259820,-1298.132080,0.026927,0.000000
26.510002,2.496758,-1298.132080,-0.002630,0.001037,0.026329,11.106133,0.565773,0.263289,-1298.132080,0.027326,0.000000
26.750002,2.605492,-1298.087646,-0.002621,0.001060,0.026919,11.589806,0.590413,0.269186,-1298.087646,0.027725,0.000000
26.990002,2.600281,-1298.087646,-0.002587,0.001072,0.027231,11.566627,0.589232,0.272308,-1298.087646,0.028124,0.000000
27.230001,2.592461,-1298.087646,-0.002574,0.001088,0.027638,11.531841,0.587460,0.276384,-1298.087646,0.028523,0.000000
27.470001,2.623367,-1298.087646,-0.002565,0.001103,0.028011,11.669321,0.594464,0.280113,-1298.087646,0.028922,0.000000
27.710001,2.593575,-1298.043091,-0.002544,0.001113,0.028271,11.536796,0.587712,0.282715,-1298.043091,0.029330,0.000000
27.950001,2.765984,-1298.176514,-0.002539,0.001137,0.028879,12.303709,0.626781,0.288786,-1298.176514,0.029728,0.000000
28.190001,2.738426,-1298.132080,-0.002509,0.001149,0.029173,12.181129,0.620536,0.291734,-1298.132080,0.030127,0.000000
28.430002,2.783485,-1298.132080,-0.002496,0.001164,0.029555,12.381561,0.630747,0.295549,-1298.132080,0.030526,0.000000
28.670002,2.839714,-1298.132080,-0.002488,0.001182,0.030015,12.631679,0.643488,0.300146,-1298.132080,0.030925,0.000000
28.910002,2.914558,-1298.087646,-0.002462,0.001201,0.030518,12.964603,0.660448,0.305176,-1298.087646,0.031324,0.000000
29.150002,2.863914,-1298.132080,-0.002458,0.001214,0.030847,12.739327,0.648972,0.308471,-1298.132080,0.031723,0.000000
29.390001,2.857956,-1298.132080,-0.002432,0.001226,0.031151,12.712823,0.647622,0.311506,-1298.132080,0.032122,0.000000
29.630001,3.013985,-1298.087646,-0.002419,0.001251,0.031766,13.406874,0.682979,0.317664,-1298.087646,0.032529,0.000000
29.870001,3.028130,-1298.132080,-0.002402,0.001266,0.032148,13.469793,0.686184,0.321480,-1298.132080,0.032928,0.000000
30.110001,3.030365,-1298.087646,-0.002389,0.001277,0.032426,13.479736,0.686691,0.324256,-1298.087646,0.033327,0.000000
30.350002,3.078033,-1298.176514,-0.002384,0.001292,0.032816,13.691776,0.697492,0.328158,-1298.176514,0.033726,0.000000
30.590002,3.206131,-1298.132080,-0.002350,0.001313,0.033362,14.261583,0.726520,0.333621,-1298.132080,0.034125,0.000000
30.830002,3.172615,-1298.176514,-0.002337,0.001324,0.033631,14.112496,0.718925,0.336309,-1298.176514,0.034524,0.000000
31.070002,3.197937,-1298.176514,-0.002328,0.001341,0.034056,14.225134,0.724663,0.340559,-1298.176514,0.034923,0.000000
31.310001,3.197189,-1298.087646,-0.002311,0.001355,0.034412,14.221808,0.724493,0.344115,-1298.087646,0.035322,0.000000
31.550001,3.297729,-1298.176514,-0.002302,0.001374,0.034888,14.669033,0.747276,0.348884,-1298.176514,0.035730,0.000000
31.790001,3.342041,-1298.132080,-0.002281,0.001390,0.035296,14.866141,0.757317,0.352960,-1298.132080,0.036129,0.000000
32.030003,3.374809,-1298.087646,-0.002268,0.001404,0.035669,15.011901,0.764743,0.356688,-1298.087646,0.036527,0.000000
32.270000,3.428436,-1298.176514,-0.002255,0.001420,0.036059,15.250446,0.776895,0.360591,-1298.176514,0.036926,0.000000
32.510002,3.555038,-1298.132080,-0.002229,0.001441,0.036597,15.813601,0.805583,0.365969,-1298.132080,0.037325,0.000000
32.750000,3.543121,-1298.132080,-0.002220,0.001453,0.036900,15.760591,0.802883,0.369005,-1298.132080,0.037724,0.000000
32.990002,3.531578,-1298.132080,-0.002199,0.001464,0.037195,15.709244,0.800267,0.371953,-1298.132080,0.038123,0.000000
33.230003,3.616112,-1298.176514,-0.002190,0.001480,0.037603,16.085268,0.819423,0.376027,-1298.176514,0.038522,0.000000
33.470001,3.689842,-1298.176514,-0.002173,0.001497,0.038028,16.413239,0.836130,0.380278,-1298.176514,0.038930,0.000000
33.710003,3.765800,-1298.132080,-0.002160,0.001514,0.038453,16.751118,0.853343,0.384526,-1298.132080,0.039329,0.000000
33.950001,3.781067,-1298.176514,-0.002151,0.001528,0.038800,16.819025,0.856802,0.387995,-1298.176514,0.039728,0.000000
34.190002,3.836182,-1298.132080,-0.002130,0.001542,0.039173,17.064188,0.869291,0.391725,-1298.132080,0.040127,0.000000
34.430000,4.024605,-1298.132080,-0.002130,0.001563,0.039710,17.902336,0.911988,0.397102,-1298.132080,0.040525,0.000000
34.670002,3.995186,-1298.176514,-0.002100,0.001578,0.040074,17.771475,0.905322,0.400745,-1298.176514,0.040924,0.000000
34.910000,3.994064,-1298.087646,-0.002074,0.001591,0.040404,17.766485,0.905068,0.404039,-1298.087646,0.041323,0.000000
35.150002,4.024971,-1298.221069,-0.002070,0.001607,0.040820,17.903965,0.912071,0.408203,-1298.221069,0.041731,0.000000
35.390003,4.105782,-1298.132080,-0.002065,0.001621,0.041184,18.263428,0.930383,0.411844,-1298.132080,0.042130,0.000000
35.630001,4.137802,-1298.132080,-0.002039,0.001636,0.041557,18.405863,0.937639,0.415574,-1298.132080,0.042529,0.000000
35.870003,4.218605,-1298.221069,-0.002022,0.001651,0.041939,18.765293,0.955950,0.419389,-1298.221069,0.042928,0.000000
36.110001,4.296059,-1298.176514,-0.002018,0.001667,0.042329,19.109823,0.973501,0.423291,-1298.176514,0.043326,0.000000
36.350002,4.480385,-1298.221069,-0.002005,0.001687,0.042858,19.929747,1.015270,0.428583,-1298.221069,0.043725,0.000000
36.590000,4.500122,-1298.132080,-0.001970,0.001705,0.043309,20.017542,1.019742,0.433092,-1298.132080,0.044124,0.000000
36.830002,4.517624,-1298.176514,-0.001957,0.001720,0.043699,20.095394,1.023708,0.436995,-1298.176514,0.044523,0.000000
37.070004,4.513901,-1298.221069,-0.001957,0.001733,0.044020,20.078833,1.022864,0.440202,-1298.221069,0.044931,0.000000
37.310001,4.477409,-1298.176514,-0.001936,0.001743,0.044280,19.916512,1.014596,0.442804,-1298.176514,0.045330,0.000000
37.550003,4.725410,-1298.221069,-0.001927,0.001766,0.044844,21.019676,1.070793,0.448442,-1298.221069,0.045729,0.000000
37.790001,4.729874,-1298.265503,-0.001897,0.001779,0.045182,21.039528,1.071805,0.451824,-1298.265503,0.046128,0.000000
38.030003,4.819992,-1298.221069,-0.001888,0.001792,0.045529,21.440395,1.092226,0.455293,-1298.221069,0.046527,0.000000
38.270000,4.923882,-1298.176514,-0.001871,0.001810,0.045980,21.902519,1.115767,0.459802,-1298.176514,0.046926,0.000000
38.510002,5.107460,-1298.176514,-0.001858,0.001830,0.046492,22.719116,1.157367,0.464919,-1298.176514,0.047324,0.000000
38.750000,5.123848,-1298.221069,-0.001854,0.001847,0.046917,22.792013,1.161081,0.469168,-1298.221069,0.047723,0.000000
38.990002,5.138367,-1298.221069,-0.001819,0.001860,0.047255,22.856596,1.164371,0.472550,-1298.221069,0.048131,0.000000
39.230003,5.119377,-1298.087646,-0.001815,0.001874,0.047593,22.772127,1.160067,0.475934,-1298.087646,0.048530,0.000000
39.470001,5.285828,-1298.265503,-0.001802,0.001890,0.048018,23.512535,1.197786,0.480182,-1298.265503,0.048929,0.000000
39.710003,5.423233,-1298.221069,-0.001781,0.001907,0.048443,24.123745,1.228922,0.484431,-1298.221069,0.049328,0.000000
39.950001,5.378548,-1298.265503,-0.001768,0.001918,0.048712,23.924974,1.218796,0.487120,-1298.265503,0.049727,0.000000
40.190002,5.674210,-1298.176514,-0.001763,0.001940,0.049276,25.240145,1.285794,0.492757,-1298.176514,0.050126,0.000000
40.430000,5.771027,-1298.221069,-0.001729,0.001957,0.049709,25.670809,1.307733,0.497093,-1298.221069,0.050525,0.000000
40.670002,5.782204,-1298.310059,-0.001716,0.001972,0.050082,25.720526,1.310266,0.500823,-1298.310059,0.050923,0.000000
40.910004,5.769913,-1298.176514,-0.001699,0.001986,0.050438,25.665854,1.307481,0.504377,-1298.176514,0.051331,0.000000
41.150002,5.792252,-1298.221069,-0.001699,0.001998,0.050741,25.765223,1.312543,0.507412,-1298.221069,0.051730,0.000000
41.390003,6.098343,-1298.176514,-0.001664,0.002017,0.051227,27.126783,1.381904,0.512268,-1298.176514,0.052129,0.000000
41.630001,6.015678,-1298.176514,-0.001664,0.002027,0.051496,26.759073,1.363172,0.514958,-1298.176514,0.052528,0.000000
41.870003,6.058128,-1298.265503,-0.001647,0.002040,0.051825,26.947901,1.372792,0.518252,-1298.265503,0.052927,0.000000
42.110001,6.379860,-1298.221069,-0.001638,0.002062,0.052363,28.379034,1.445697,0.523631,-1298.221069,0.053326,0.000000
42.350002,6.614456,-1298.221069,-0.001638,0.002083,0.052909,29.422571,1.498857,0.529094,-1298.221069,0.053725,0.000000
42.590000,6.615196,-1298.265503,-0.001591,0.002097,0.053274,29.425863,1.499025,0.532735,-1298.265503,0.054123,0.000000
42.830002,6.632698,-1298.221069,-0.001587,0.002112,0.053655,29.503714,1.502991,0.536552,-1298.221069,0.054531,0.000000
43.070004,6.634560,-1298.265503,-0.001561,0.002126,0.054002,29.511995,1.503413,0.540021,-1298.265503,0.054930,0.000000
43.310001,6.904533,-1298.176514,-0.001552,0.002143,0.054427,30.712898,1.564590,0.544270,-1298.176514,0.055329,0.000000
43.550003,7.039330,-1298.310059,-0.001552,0.002158,0.054808,31.312502,1.595135,0.548085,-1298.310059,0.055728,0.000000
43.790001,7.006187,-1298.176514,-0.001518,0.002169,0.055086,31.165079,1.587625,0.550861,-1298.176514,0.056127,0.000000
44.030003,7.321960,-1298.310059,-0.001505,0.002189,0.055598,32.569706,1.659180,0.555978,-1298.310059,0.056526,0.000000
44.270000,7.677948,-1298.310059,-0.001505,0.002210,0.056135,34.153217,1.739848,0.561355,-1298.310059,0.056925,0.000000
44.510002,7.583366,-1298.221069,-0.001479,0.002223,0.056465,33.732498,1.718415,0.564650,-1298.221069,0.057324,0.000000
44.750004,7.698799,-1298.310059,-0.001466,0.002241,0.056916,34.245968,1.744573,0.569159,-1298.310059,0.057731,0.000000
44.990002,7.744972,-1298.310059,-0.001453,0.002252,0.057211,34.451359,1.755036,0.572108,-1298.310059,0.058130,0.000000
45.230003,7.828758,-1298.221069,-0.001436,0.002267,0.057592,34.824055,1.774022,0.575923,-1298.221069,0.058529,0.000000
45.470001,7.999680,-1298.265503,-0.001406,0.002280,0.057913,35.584351,1.812753,0.579132,-1298.265503,0.058928,0.000000
45.710003,8.120323,-1298.221069,-0.001414,0.002295,0.058286,36.121002,1.840092,0.582862,-1298.221069,0.059327,0.000000
45.950001,8.508339,-1298.310059,-0.001401,0.002314,0.058772,37.846981,1.928017,0.587718,-1298.310059,0.059726,0.000000
46.190002,8.924652,-1298.221069,-0.001375,0.002337,0.059362,39.698833,2.022355,0.593615,-1298.221069,0.060125,0.000000
46.430000,8.729156,-1298.221069,-0.001358,0.002347,0.059613,38.829227,1.978055,0.596130,-1298.221069,0.060524,0.000000
46.670002,8.934708,-1298.221069,-0.001345,0.002364,0.060038,39.743565,2.024634,0.600379,-1298.221069,0.060931,0.000000
46.910004,9.040833,-1298.221069,-0.001350,0.002378,0.060393,40.215633,2.048682,0.603935,-1298.221069,0.061330,0.000000
47.150002,9.057587,-1298.310059,-0.001319,0.002391,0.060740,40.290157,2.052479,0.607404,-1298.310059,0.061729,0.000000
47.390003,9.499222,-1298.176514,-0.001302,0.002410,0.061209,42.254650,2.152555,0.612088,-1298.176514,0.062128,0.000000
47.630001,9.526405,-1298.221069,-0.001293,0.002422,0.061521,42.375568,2.158714,0.615208,-1298.221069,0.062527,0.000000
47.870003,9.724876,-1298.265503,-0.001276,0.002439,0.061955,43.258411,2.203688,0.619546,-1298.265503,0.062926,0.000000
48.110001,10.267426,-1298.221069,-0.001276,0.002460,0.062484,45.671791,2.326632,0.624835,-1298.221069,0.063325,0.000000
48.350002,10.207474,-1298.310059,-0.001255,0.002473,0.062822,45.405109,2.313046,0.628217,-1298.310059,0.063732,0.000000
48.590004,10.406693,-1298.310059,-0.001224,0.002490,0.063247,46.291279,2.358190,0.632467,-1298.310059,0.064131,0.000000
48.830002,10.582451,-1298.265503,-0.001224,0.002504,0.063611,47.073093,2.398017,0.636108,-1298.265503,0.064530,0.000000
49.070004,10.599953,-1298.265503,-0.001207,0.002517,0.063941,47.150944,2.401984,0.639405,-1298.265503,0.064929,0.000000
49.310001,11.153671,-1298.176514,-0.001194,0.002537,0.064444,49.614006,2.527458,0.644435,-1298.176514,0.065328,0.000000
49.550003,11.135796,-1298.265503,-0.001199,0.002548,0.064712,49.534492,2.523407,0.647122,-1298.265503,0.065727,0.000000
49.790001,11.370392,-1298.265503,-0.001168,0.002564,0.065129,50.578030,2.576568,0.651286,-1298.265503,0.066126,0.000000
50.030003,11.912567,-1298.265503,-0.001151,0.002586,0.065684,52.989746,2.699426,0.656836,-1298.265503,0.066525,0.000000
50.270004,12.219406,-1298.310059,-0.001130,0.002602,0.066083,54.354633,2.768957,0.660826,-1298.310059,0.066932,0.000000
50.510002,12.225357,-1298.265503,-0.001125,0.002615,0.066412,54.381104,2.770306,0.664120,-1298.265503,0.067331,0.000000
50.750004,12.213814,-1298.310059,-0.001121,0.002627,0.066724,54.329758,2.767690,0.667243,-1298.310059,0.067730,0.000000
50.990002,13.090752,-1298.221069,-0.001095,0.002653,0.067383,58.230572,2.966407,0.673834,-1298.221069,0.068129,0.000000
51.230003,13.129478,-1298.265503,-0.001087,0.002666,0.067704,58.402836,2.975182,0.677042,-1298.265503,0.068528,0.000000
51.470001,13.162994,-1298.265503,-0.001065,0.002677,0.067990,58.551922,2.982777,0.679903,-1298.265503,0.068927,0.000000
51.710003,13.527176,-1298.176514,-0.001065,0.002692,0.068381,60.171883,3.065302,0.683807,-1298.176514,0.069326,0.000000
51.950001,14.181808,-1298.265503,-0.001039,0.002714,0.068927,63.083836,3.213644,0.689271,-1298.265503,0.069725,0.000000
52.190002,14.139359,-1298.310059,-0.001035,0.002725,0.069205,62.895008,3.204025,0.692045,-1298.310059,0.070132,0.000000
52.430004,14.478210,-1298.310059,-0.001013,0.002741,0.069629,64.402298,3.280809,0.696294,-1298.310059,0.070531,0.000000
52.670002,14.998421,-1298.265503,-0.000992,0.002760,0.070115,66.716309,3.398691,0.701152,-1298.265503,0.070930,0.000000
52.910004,15.323502,-1298.265503,-0.000992,0.002776,0.070505,68.162338,3.472355,0.705054,-1298.265503,0.071329,0.000000
53.150002,15.529053,-1298.310059,-0.000983,0.002788,0.070826,69.076675,3.518934,0.708262,-1298.310059,0.071728,0.000000
53.390003,15.927116,-1298.176514,-0.000970,0.002807,0.071286,70.847351,3.609136,0.712858,-1298.176514,0.072127,0.000000
53.630001,16.398911,-1298.221069,-0.000949,0.002824,0.071728,72.945999,3.716046,0.717281,-1298.221069,0.072526,0.000000
53.870003,16.931404,-1298.221069,-0.000940,0.002842,0.072188,75.314644,3.836711,0.721878,-1298.221069,0.072925,0.000000
54.110004,16.974602,-1298.265503,-0.000927,0.002854,0.072491,75.506798,3.846500,0.724913,-1298.265503,0.073333,0.000000
54.350002,17.075142,-1298.265503,-0.000905,0.002866,0.072804,75.954025,3.869282,0.728036,-1298.265503,0.073731,0.000000
54.590004,17.493683,-1298.221069,-0.000901,0.002880,0.073159,77.815788,3.964125,0.731590,-1298.221069,0.074130,0.000000
54.830002,18.163582,-1298.310059,-0.000901,0.002899,0.073636,80.795647,4.115927,0.736361,-1298.310059,0.074529,0.000000
55.070004,18.566116,-1298.221069,-0.000867,0.002913,0.073983,82.586212,4.207142,0.739830,-1298.221069,0.074928,0.000000
55.310001,18.967537,-1298.310059,-0.000862,0.002928,0.074382,84.371819,4.298105,0.743819,-1298.310059,0.075327,0.000000
55.550003,19.240112,-1298.221069,-0.000849,0.002942,0.074737,85.584297,4.359872,0.747375,-1298.221069,0.075726,0.000000
55.790001,20.220940,-1298.221069,-0.000841,0.002964,0.075275,89.947235,4.582130,0.752751,-1298.221069,0.076125,0.000000
56.030003,20.527031,-1298.265503,-0.000806,0.002978,0.075639,91.308792,4.651492,0.756394,-1298.265503,0.076533,0.000000
56.270004,20.777641,-1298.265503,-0.000802,0.002994,0.076047,92.423561,4.708281,0.760469,-1298.265503,0.076932,0.000000
56.510002,21.180550,-1298.310059,-0.000802,0.003007,0.076368,94.215790,4.799581,0.763678,-1298.310059,0.077331,0.000000
56.750004,21.694794,-1298.265503,-0.000793,0.003023,0.076775,96.503265,4.916111,0.767755,-1298.265503,0.077729,0.000000
56.990002,22.077217,-1298.221069,-0.000772,0.003038,0.077157,98.204369,5.002769,0.771570,-1298.221069,0.078128,0.000000
57.230003,22.473427,-1298.310059,-0.000759,0.003050,0.077461,99.966797,5.092551,0.774605,-1298.310059,0.078527,0.000000
57.470001,23.209976,-1298.265503,-0.000755,0.003068,0.077929,103.243134,5.259456,0.779289,-1298.265503,0.078926,0.000000
57.710003,24.305870,-1298.354492,-0.000755,0.003091,0.078510,108.117912,5.507789,0.785099,-1298.354492,0.079325,0.000000
57.950005,24.802612,-1298.310059,-0.000720,0.003104,0.078839,110.327530,5.620352,0.788394,-1298.310059,0.079733,0.000000
58.190002,25.277763,-1298.265503,-0.000733,0.003122,0.079299,112.441109,5.728023,0.792990,-1298.265503,0.080132,0.000000
58.430004,25.482193,-1298.310059,-0.000703,0.003133,0.079585,113.350456,5.774347,0.795852,-1298.310059,0.080530,0.000000
58.670002,25.640076,-1298.354492,-0.000703,0.003143,0.079837,114.052750,5.810124,0.798367,-1298.354492,0.080929,0.000000
58.910004,26.905403,-1298.265503,-0.000681,0.003165,0.080400,119.681213,6.096852,0.804004,-1298.265503,0.081328,0.000000
59.150002,27.269211,-1298.221069,-0.000673,0.003180,0.080765,121.299507,6.179291,0.807647,-1298.221069,0.081727,0.000000
59.390003,27.774521,-1298.354492,-0.000668,0.003193,0.081112,123.547241,6.293797,0.811116,-1298.354492,0.082126,0.000000
59.630001,28.700607,-1298.310059,-0.000655,0.003211,0.081571,127.666679,6.503651,0.815711,-1298.310059,0.082525,0.000000
59.870003,29.745110,-1298.310059,-0.000642,0.003231,0.082057,132.312851,6.740338,0.820569,-1298.310059,0.082933,0.000000
60.110004,30.353569,-1298.310059,-0.000629,0.003247,0.082464,135.019424,6.878217,0.824643,-1298.310059,0.083332,0.000000
60.350002,30.850311,-1298.265503,-0.000621,0.003260,0.082803,137.229034,6.990780,0.828027,-1298.265503,0.083731,0.000000
60.590004,31.236092,-1298.398926,-0.000617,0.003273,0.083123,138.945068,7.078199,0.831235,-1298.398926,0.084130,0.000000
60.830002,32.223251,-1298.310059,-0.000612,0.003291,0.083592,143.336182,7.301893,0.835919,-1298.310059,0.084528,0.000000
61.070004,33.020874,-1298.221069,-0.000595,0.003306,0.083973,146.884186,7.482637,0.839734,-1298.221069,0.084927,0.000000
61.310001,33.246902,-1298.398926,-0.000582,0.003317,0.084260,147.889603,7.533856,0.842595,-1298.398926,0.085326,0.000000
61.550003,34.693573,-1298.310059,-0.000586,0.003341,0.084849,154.324722,7.861676,0.848492,-1298.310059,0.085734,0.000000
61.790005,35.536995,-1298.354492,-0.000569,0.003357,0.085257,158.076447,8.052798,0.852568,-1298.354492,0.086133,0.000000
62.030003,36.212479,-1298.310059,-0.000548,0.003371,0.085630,161.081146,8.205865,0.856298,-1298.310059,0.086532,0.000000
62.270004,36.792259,-1298.354492,-0.000548,0.003385,0.085977,163.660141,8.337246,0.859767,-1298.354492,0.086931,0.000000
62.510002,37.206337,-1298.354492,-0.000535,0.003396,0.086263,165.502060,8.431076,0.862629,-1298.354492,0.087330,0.000000
62.750004,38.486183,-1298.354492,-0.000530,0.003416,0.086775,171.195099,8.721093,0.867746,-1298.354492,0.087728,0.000000
62.990002,38.983299,-1298.398926,-0.000517,0.003429,0.087095,173.406372,8.833742,0.870954,-1298.398926,0.088127,0.000000
63.230003,39.514679,-1298.354492,-0.000504,0.003443,0.087442,175.770065,8.954154,0.874422,-1298.354492,0.088526,0.000000
63.470001,41.075661,-1298.310059,-0.000504,0.003463,0.087971,182.713669,9.307878,0.879714,-1298.310059,0.088934,0.000000
63.710003,42.383064,-1298.354492,-0.000496,0.003482,0.088448,188.529282,9.604139,0.884483,-1298.354492,0.089333,0.000000
63.950005,43.156853,-1298.354492,-0.000500,0.003497,0.088813,191.971268,9.779483,0.888126,-1298.354492,0.089732,0.000000
64.190002,43.969742,-1298.443481,-0.000479,0.003512,0.089211,195.587173,9.963686,0.892115,-1298.443481,0.090131,0.000000
64.430000,44.708527,-1298.354492,-0.000470,0.003525,0.089532,198.873459,10.131097,0.895323,-1298.354492,0.090530,0.000000
64.670006,45.784683,-1298.398926,-0.000466,0.003542,0.089957,203.660446,10.374958,0.899573,-1298.398926,0.090929,0.000000
64.910004,46.707054,-1298.354492,-0.000453,0.003558,0.090373,207.763351,10.583970,0.903735,-1298.354492,0.091327,0.000000
65.150002,47.195602,-1298.310059,-0.000448,0.003568,0.090625,209.936523,10.694676,0.906250,-1298.310059,0.091726,0.000000
65.389999,48.571144,-1298.398926,-0.000435,0.003588,0.091128,216.055237,11.006378,0.911280,-1298.398926,0.092134,0.000000
65.630005,50.212936,-1298.310059,-0.000435,0.003609,0.091657,223.358292,11.378414,0.916571,-1298.310059,0.092533,0.000000
65.870003,51.057854,-1298.398926,-0.000423,0.003622,0.092004,227.116669,11.569875,0.920040,-1298.398926,0.092932,0.000000
66.110001,52.119484,-1298.354492,-0.000410,0.003639,0.092438,231.839050,11.810444,0.924375,-1298.354492,0.093331,0.000000
66.350006,52.883217,-1298.354492,-0.000405,0.003651,0.092724,235.236298,11.983508,0.927237,-1298.354492,0.093730,0.000000
66.590004,53.711006,-1298.398926,-0.000397,0.003666,0.093105,238.918488,12.171088,0.931052,-1298.398926,0.094129,0.000000
66.830002,54.840034,-1298.354492,-0.000388,0.003679,0.093452,243.940659,12.426929,0.934521,-1298.354492,0.094528,0.000000
67.070000,55.883797,-1298.398926,-0.000384,0.003694,0.093816,248.583542,12.663449,0.938164,-1298.398926,0.094926,0.000000
67.310005,57.379616,-1298.443481,-0.000371,0.003713,0.094302,255.237274,13.002406,0.943020,-1298.443481,0.095334,0.000000
67.550003,59.238129,-1298.398926,-0.000371,0.003736,0.094883,263.504364,13.423553,0.948832,-1298.398926,0.095733,0.000000
67.790001,59.764664,-1298.443481,-0.000358,0.003745,0.095135,265.846497,13.542866,0.951347,-1298.443481,0.096132,0.000000
68.030006,60.917526,-1298.398926,-0.000362,0.003762,0.095560,270.974701,13.804109,0.955595,-1298.398926,0.096531,0.000000
68.270004,62.004112,-1298.398926,-0.000345,0.003776,0.095915,275.808075,14.050333,0.959151,-1298.398926,0.096930,0.000000
68.510002,62.854240,-1298.354492,-0.000358,0.003790,0.096262,279.589630,14.242974,0.962620,-1298.354492,0.097329,0.000000
68.750000,64.557838,-1298.354492,-0.000336,0.003808,0.096730,287.167603,14.629016,0.967302,-1298.354492,0.097727,0.000000
68.990005,65.419884,-1298.443481,-0.000336,0.003820,0.097034,291.002167,14.824358,0.970337,-1298.443481,0.098126,0.000000
69.230003,66.566048,-1298.354492,-0.000332,0.003838,0.097485,296.100555,15.084082,0.974847,-1298.354492,0.098534,0.000000
69.470001,67.667519,-1298.487915,-0.000315,0.003843,0.097606,301.000153,15.333679,0.976062,-1298.487915,0.097832,0.000000
69.710007,67.154396,-1298.398926,-0.000315,0.003843,0.097606,298.717682,15.217403,0.976062,-1298.398926,0.097832,0.000000
69.950005,66.726173,-1298.398926,-0.000297,0.003841,0.097554,296.812836,15.120367,0.975542,-1298.398926,0.097606,0.000000
70.190002,66.326607,-1298.443481,-0.000306,0.003840,0.097528,295.035492,15.029824,0.975280,-1298.443481,0.097606,0.000000
70.430000,65.989235,-1298.443481,-0.000306,0.003839,0.097520,293.534790,14.953375,0.975195,-1298.443481,0.097606,0.000000
70.670006,65.656715,-1298.532349,-0.000297,0.003839,0.097511,292.055664,14.878025,0.975108,-1298.532349,0.097606,0.000000
70.910004,65.387489,-1298.398926,-0.000293,0.003839,0.097502,290.858093,14.817017,0.975021,-1298.398926,0.097606,0.000000
71.150002,65.134651,-1298.487915,-0.000293,0.003838,0.097493,289.733398,14.759723,0.974934,-1298.487915,0.097606,0.000000
71.390007,64.918297,-1298.443481,-0.000285,0.003838,0.097493,288.770996,14.710696,0.974934,-1298.443481,0.097606,0.000000
71.630005,64.703072,-1298.354492,-0.000293,0.003838,0.097493,287.813629,14.661925,0.974934,-1298.354492,0.097606,0.000000
71.870003,64.515770,-1298.487915,-0.000289,0.003838,0.097493,286.980469,14.619482,0.974934,-1298.487915,0.097606,0.000000
72.110001,64.340370,-1298.443481,-0.000289,0.003838,0.097493,286.200256,14.579737,0.974934,-1298.443481,0.097606,0.000000
72.350006,64.177284,-1298.443481,-0.000297,0.003838,0.097493,285.474823,14.542781,0.974934,-1298.443481,0.097606,0.000000
72.590004,64.031303,-1298.443481,-0.000289,0.003838,0.097485,284.825470,14.509701,0.974847,-1298.443481,0.097606,0.000000
72.830002,63.875282,-1298.398926,-0.000289,0.003838,0.097485,284.131439,14.474346,0.974847,-1298.398926,0.097606,0.000000
73.070000,63.751656,-1298.487915,-0.000285,0.003838,0.097485,283.581512,14.446332,0.974847,-1298.487915,0.097606,0.000000
73.310005,63.605690,-1298.354492,-0.000280,0.003838,0.097485,282.932251,14.413256,0.974847,-1298.354492,0.097606,0.000000
73.550003,63.524132,-1298.532349,-0.000289,0.003838,0.097485,282.569458,14.394774,0.974847,-1298.532349,0.097606,0.000000
73.790001,63.378166,-1298.398926,-0.000289,0.003838,0.097485,281.920166,14.361698,0.974847,-1298.398926,0.097606,0.000000
74.030006,63.281715,-1298.398926,-0.000280,0.003838,0.097485,281.491119,14.339842,0.974847,-1298.398926,0.097606,0.000000
74.270004,63.180061,-1298.532349,-0.000289,0.003838,0.097485,281.038940,14.316806,0.974847,-1298.532349,0.097606,0.000000
74.510002,63.082878,-1298.487915,-0.000276,0.003838,0.097485,280.606659,14.294785,0.974847,-1298.487915,0.097606,0.000000
74.750000,62.989784,-1298.487915,-0.000293,0.003838,0.097485,280.192566,14.273689,0.974847,-1298.487915,0.097606,0.000000
74.990005,62.915306,-1298.487915,-0.000272,0.003838,0.097485,279.861267,14.256812,0.974847,-1298.487915,0.097606,0.000000
75.230003,62.846420,-1298.487915,-0.000276,0.003838,0.097485,279.554840,14.241202,0.974847,-1298.487915,0.097606,0.000000
75.470001,62.755188,-1298.398926,-0.000280,0.003838,0.097485,279.149017,14.220529,0.974847,-1298.398926,0.097606,0.000000
75.710007,62.665443,-1298.487915,-0.000276,0.003838,0.097485,278.749817,14.200192,0.974847,-1298.487915,0.097606,0.000000
75.950005,62.594696,-1298.532349,-0.000276,0.003838,0.097485,278.435120,14.184160,0.974847,-1298.532349,0.097606,0.000000
76.190002,62.519478,-1298.443481,-0.000263,0.003838,0.097485,278.100525,14.167116,0.974847,-1298.443481,0.097606,0.000000
76.430000,62.446487,-1298.532349,-0.000280,0.003838,0.097485,277.775848,14.150576,0.974847,-1298.532349,0.097606,0.000000
76.670006,62.385796,-1298.532349,-0.000272,0.003838,0.097485,277.505890,14.136823,0.974847,-1298.532349,0.097606,0.000000
76.910004,62.325844,-1298.487915,-0.000276,0.003838,0.097485,277.239197,14.123239,0.974847,-1298.487915,0.097606,0.000000
77.150002,62.255463,-1298.576904,-0.000267,0.003838,0.097485,276.926117,14.107289,0.974847,-1298.576904,0.097606,0.000000
77.390007,62.208542,-1298.398926,-0.000285,0.003838,0.097485,276.717407,14.096658,0.974847,-1298.398926,0.097606,0.000000
77.630005,62.148964,-1298.487915,-0.000280,0.003838,0.097485,276.452393,14.083156,0.974847,-1298.487915,0.097606,0.000000
77.870003,62.081192,-1298.532349,-0.000280,0.003838,0.097485,276.150940,14.067799,0.974847,-1298.532349,0.097606,0.000000
78.110001,62.048424,-1298.443481,-0.000276,0.003838,0.097485,276.005188,14.060374,0.974847,-1298.443481,0.097606,0.000000
78.350006,61.987724,-1298.532349,-0.000276,0.003838,0.097485,275.735168,14.046619,0.974847,-1298.532349,0.097606,0.000000
78.590004,61.948997,-1298.532349,-0.000267,0.003838,0.097485,275.562897,14.037843,0.974847,-1298.532349,0.097606,0.000000
78.830002,61.874901,-1298.532349,-0.000280,0.003838,0.097485,275.233307,14.021053,0.974847,-1298.532349,0.097606,0.000000
79.070007,61.848457,-1298.487915,-0.000267,0.003838,0.097476,275.115692,14.015060,0.974760,-1298.487915,0.097606,0.000000
79.310005,61.795952,-1298.487915,-0.000272,0.003838,0.097476,274.882111,14.003162,0.974760,-1298.487915,0.097606,0.000000
79.550003,61.747177,-1298.532349,-0.000267,0.003838,0.097476,274.665161,13.992110,0.974760,-1298.532349,0.097606,0.000000
79.790001,61.696533,-1298.487915,-0.000276,0.003838,0.097476,274.439880,13.980635,0.974760,-1298.487915,0.097606,0.000000
80.030006,61.659668,-1298.532349,-0.000280,0.003838,0.097476,274.275909,13.972281,0.974760,-1298.532349,0.097606,0.000000
80.270004,61.611633,-1298.487915,-0.000272,0.003838,0.097476,274.062225,13.961395,0.974760,-1298.487915,0.097606,0.000000
80.510002,61.579605,-1298.487915,-0.000276,0.003838,0.097476,273.919769,13.954138,0.974760,-1298.487915,0.097606,0.000000
80.750008,61.540138,-1298.532349,-0.000276,0.003838,0.097476,273.744202,13.945195,0.974760,-1298.532349,0.097606,0.000000
80.990005,61.487259,-1298.532349,-0.000267,0.003838,0.097476,273.509003,13.933212,0.974760,-1298.532349,0.097606,0.000000
81.230003,61.458588,-1298.487915,-0.000272,0.003838,0.097476,273.381439,13.926715,0.974760,-1298.487915,0.097606,0.000000
81.470001,61.424324,-1298.532349,-0.000280,0.003838,0.097476,273.229034,13.918950,0.974760,-1298.532349,0.097606,0.000000
81.710007,61.396400,-1298.576904,-0.000280,0.003838,0.097476,273.104828,13.912623,0.974760,-1298.576904,0.097606,0.000000
81.950005,61.356552,-1298.532349,-0.000267,0.003838,0.097476,272.927582,13.903593,0.974760,-1298.532349,0.097606,0.000000
82.190002,61.317825,-1298.532349,-0.000276,0.003838,0.097476,272.755310,13.894818,0.974760,-1298.532349,0.097606,0.000000
82.430000,61.288780,-1298.487915,-0.000272,0.003838,0.097476,272.626099,13.888236,0.974760,-1298.487915,0.097606,0.000000
82.670006,61.237396,-1298.487915,-0.000267,0.003838,0.097476,272.397552,13.876593,0.974760,-1298.487915,0.097606,0.000000
82.910004,61.216919,-1298.487915,-0.000280,0.003838,0.097476,272.306458,13.871952,0.974760,-1298.487915,0.097606,0.000000
83.150002,61.164413,-1298.532349,-0.000263,0.003838,0.097476,272.072906,13.860054,0.974760,-1298.532349,0.097606,0.000000
83.390007,61.128662,-1298.487915,-0.000280,0.003838,0.097476,271.913879,13.851953,0.974760,-1298.487915,0.097606,0.000000
83.630005,61.105949,-1298.532349,-0.000272,0.003838,0.097476,271.812836,13.846806,0.974760,-1298.532349,0.097606,0.000000
83.870003,61.085472,-1298.487915,-0.000267,0.003838,0.097476,271.721741,13.842166,0.974760,-1298.487915,0.097606,0.000000
84.110001,61.055679,-1298.487915,-0.000285,0.003838,0.097476,271.589233,13.835414,0.974760,-1298.487915,0.097606,0.000000
84.350006,61.024773,-1298.487915,-0.000272,0.003838,0.097476,271.451752,13.828411,0.974760,-1298.487915,0.097606,0.000000
84.590004,61.006897,-1298.487915,-0.000276,0.003838,0.097476,271.372223,13.824361,0.974760,-1298.487915,0.097606,0.000000
84.830002,60.975243,-1298.532349,-0.000272,0.003838,0.097476,271.231415,13.817187,0.974760,-1298.532349,0.097606,0.000000
85.070007,60.947319,-1298.487915,-0.000263,0.003838,0.097476,271.107208,13.810860,0.974760,-1298.487915,0.097606,0.000000
85.310005,60.908966,-1298.532349,-0.000280,0.003838,0.097476,270.936615,13.802169,0.974760,-1298.532349,0.097606,0.000000
85.550003,60.904869,-1298.487915,-0.000267,0.003838,0.097476,270.918396,13.801241,0.974760,-1298.487915,0.097606,0.000000
85.790001,60.859436,-1298.443481,-0.000272,0.003838,0.097476,270.716278,13.790946,0.974760,-1298.443481,0.097606,0.000000
86.030006,60.850502,-1298.532349,-0.000272,0.003838,0.097476,270.676544,13.788921,0.974760,-1298.532349,0.097606,0.000000
86.270004,60.807678,-1298.398926,-0.000267,0.003838,0.097476,270.486053,13.779217,0.974760,-1298.398926,0.097606,0.000000
86.510002,60.785706,-1298.487915,-0.000280,0.003838,0.097476,270.388336,13.774238,0.974760,-1298.487915,0.097606,0.000000
86.750008,60.757782,-1298.576904,-0.000272,0.003838,0.097476,270.264099,13.767910,0.974760,-1298.576904,0.097606,0.000000
86.990005,60.737671,-1298.487915,-0.000272,0.003838,0.097476,270.174652,13.763352,0.974760,-1298.487915,0.097606,0.000000
87.230003,60.713097,-1298.487915,-0.000267,0.003838,0.097476,270.065338,13.757784,0.974760,-1298.487915,0.097606,0.000000
87.470001,60.681442,-1298.443481,-0.000272,0.003838,0.097476,269.924530,13.750611,0.974760,-1298.443481,0.097606,0.000000
87.710007,60.674744,-1298.487915,-0.000280,0.003838,0.097476,269.894745,13.749093,0.974760,-1298.487915,0.097606,0.000000
87.950005,60.645325,-1298.487915,-0.000276,0.003838,0.097476,269.763885,13.742427,0.974760,-1298.487915,0.097606,0.000000
88.190002,60.627449,-1298.487915,-0.000263,0.003838,0.097476,269.684357,13.738376,0.974760,-1298.487915,0.097606,0.000000
88.430008,60.601013,-1298.532349,-0.000267,0.003838,0.097476,269.566772,13.732387,0.974760,-1298.532349,0.097606,0.000000
88.670006,60.577179,-1298.532349,-0.000272,0.003838,0.097476,269.460754,13.726985,0.974760,-1298.532349,0.097606,0.000000
88.910004,60.540688,-1298.487915,-0.000276,0.003838,0.097476,269.298431,13.718716,0.974760,-1298.487915,0.097606,0.000000
89.150002,60.534355,-1298.532349,-0.000263,0.003838,0.097476,269.270264,13.717280,0.974760,-1298.532349,0.097606,0.000000
89.390007,60.509033,-1298.487915,-0.000263,0.003838,0.097476,269.157623,13.711543,0.974760,-1298.487915,0.097606,0.000000
89.630005,60.484459,-1298.532349,-0.000263,0.003838,0.097476,269.048309,13.705975,0.974760,-1298.532349,0.097606,0.000000
89.870003,60.450943,-1298.532349,-0.000272,0.003838,0.097476,268.899231,13.698380,0.974760,-1298.532349,0.097606,0.000000
90.110001,60.463608,-1298.532349,-0.000272,0.003838,0.097476,268.955566,13.701249,0.974760,-1298.532349,0.097606,0.000000
90.350006,60.430092,-1298.487915,-0.000259,0.003838,0.097476,268.806488,13.693655,0.974760,-1298.487915,0.097606,0.000000
90.590004,60.390991,-1298.487915,-0.000276,0.003838,0.097476,268.632538,13.684794,0.974760,-1298.487915,0.097606,0.000000
90.830002,60.386528,-1298.621338,-0.000272,0.003838,0.097476,268.612701,13.683783,0.974760,-1298.621338,0.097606,0.000000
91.070007,60.372749,-1298.532349,-0.000267,0.003838,0.097476,268.551392,13.680661,0.974760,-1298.532349,0.097606,0.000000
91.310005,60.368279,-1298.576904,-0.000267,0.003838,0.097476,268.531525,13.679647,0.974760,-1298.576904,0.097606,0.000000
91.550003,60.338120,-1298.532349,-0.000272,0.003838,0.097476,268.397369,13.672813,0.974760,-1298.532349,0.097606,0.000000
91.790001,60.310188,-1298.576904,-0.000276,0.003838,0.097476,268.273102,13.666484,0.974760,-1298.576904,0.097606,0.000000
92.030006,60.292686,-1298.576904,-0.000272,0.003838,0.097476,268.195251,13.662518,0.974760,-1298.576904,0.097606,0.000000
92.270004,60.272583,-1298.532349,-0.000272,0.003838,0.097476,268.105835,13.657962,0.974760,-1298.532349,0.097606,0.000000
92.510002,60.252098,-1298.621338,-0.000267,0.003838,0.097476,268.014709,13.653320,0.974760,-1298.621338,0.097606,0.000000
92.750008,60.240181,-1298.532349,-0.000272,0.003838,0.097476,267.961700,13.650620,0.974760,-1298.532349,0.097606,0.000000
92.990005,60.211884,-1298.576904,-0.000272,0.003838,0.097476,267.835846,13.644208,0.974760,-1298.576904,0.097606,0.000000
93.230003,60.183952,-1298.576904,-0.000267,0.003838,0.097476,267.711578,13.637878,0.974760,-1298.576904,0.097606,0.000000
93.470001,60.186562,-1298.532349,-0.000263,0.003838,0.097476,267.723206,13.638470,0.974760,-1298.532349,0.097606,0.000000
93.710007,60.173157,-1298.576904,-0.000272,0.003838,0.097476,267.663574,13.635432,0.974760,-1298.576904,0.097606,0.000000
93.950005,60.139641,-1298.532349,-0.000272,0.003838,0.097476,267.514496,13.627837,0.974760,-1298.532349,0.097606,0.000000
94.190002,60.147835,-1298.576904,-0.000280,0.003838,0.097476,267.550934,13.629694,0.974760,-1298.576904,0.097606,0.000000
94.430008,60.119904,-1298.487915,-0.000259,0.003838,0.097476,267.426697,13.623364,0.974760,-1298.487915,0.097606,0.000000
94.670006,60.109482,-1298.532349,-0.000267,0.003838,0.097476,267.380341,13.621003,0.974760,-1298.532349,0.097606,0.000000
94.910004,60.091232,-1298.621338,-0.000263,0.003838,0.097476,267.299164,13.616868,0.974760,-1298.621338,0.097606,0.000000
95.150002,60.082672,-1298.532349,-0.000272,0.003838,0.097476,267.261078,13.614928,0.974760,-1298.532349,0.097606,0.000000
95.390007,60.057724,-1298.621338,-0.000267,0.003838,0.097476,267.150085,13.609275,0.974760,-1298.621338,0.097606,0.000000
95.630005,60.030540,-1298.532349,-0.000276,0.003838,0.097476,267.029175,13.603115,0.974760,-1298.532349,0.097606,0.000000
95.870003,60.027184,-1298.443481,-0.000276,0.003838,0.097476,267.014252,13.602354,0.974760,-1298.443481,0.097606,0.000000
96.110008,60.004845,-1298.576904,-0.000267,0.003838,0.097476,266.914886,13.597292,0.974760,-1298.576904,0.097606,0.000000
96.350006,59.994415,-1298.532349,-0.000267,0.003838,0.097476,266.868500,13.594929,0.974760,-1298.532349,0.097606,0.000000
96.590004,59.976540,-1298.621338,-0.000267,0.003838,0.097476,266.788971,13.590878,0.974760,-1298.621338,0.097606,0.000000
96.830002,59.950104,-1298.532349,-0.000259,0.003838,0.097476,266.671387,13.584888,0.974760,-1298.532349,0.097606,0.000000
97.070007,59.945633,-1298.532349,-0.000276,0.003838,0.097476,266.651489,13.583875,0.974760,-1298.532349,0.097606,0.000000
97.310005,59.927017,-1298.576904,-0.000263,0.003838,0.097476,266.568695,13.579657,0.974760,-1298.576904,0.097606,0.000000
97.550003,59.919571,-1298.532349,-0.000267,0.003838,0.097476,266.535553,13.577969,0.974760,-1298.532349,0.097606,0.000000
97.790001,59.912498,-1298.621338,-0.000272,0.003838,0.097476,266.504089,13.576366,0.974760,-1298.621338,0.097606,0.000000
98.030006,59.892014,-1298.532349,-0.000267,0.003838,0.097476,266.412994,13.571725,0.974760,-1298.532349,0.097606,0.000000
98.270004,59.884193,-1298.621338,-0.000263,0.003838,0.097476,266.378204,13.569953,0.974760,-1298.621338,0.097606,0.000000
98.510002,59.861107,-1298.665894,-0.000267,0.003838,0.097476,266.275513,13.564720,0.974760,-1298.665894,0.097606,0.000000
98.750008,59.846954,-1298.576904,-0.000272,0.003838,0.097476,266.212555,13.561513,0.974760,-1298.576904,0.097606,0.000000
98.990005,59.832062,-1298.621338,-0.000276,0.003838,0.097476,266.146301,13.558139,0.974760,-1298.621338,0.097606,0.000000
99.230003,59.823502,-1298.576904,-0.000259,0.003838,0.097476,266.108215,13.556200,0.974760,-1298.576904,0.097606,0.000000
99.470001,59.811958,-1298.532349,-0.000276,0.003838,0.097476,266.056885,13.553583,0.974760,-1298.532349,0.097606,0.000000
99.710007,59.791100,-1298.576904,-0.000267,0.003838,0.097476,265.964081,13.548857,0.974760,-1298.576904,0.097606,0.000000
99.900002,59.769501,-1298.576904,-0.000272,0.003838,0.097476,265.868011,13.543962,0.974760,-1298.576904,0.097606,0.000000