File: Data/compression 11/AutoNoHeating-14-11-2-240530_05302024_163256.csv
Time (sec),S:Load (lbs),S:HL1 (DIM),S:LVDT (in),S:Position (in),Ch:Position (mm),Ch:Load (N),Ch:Stress (MPa),Ch:Strain (mm/mm),Ch:HL1 (DIM),Set Point (),Cycles ()
0.110000,-0.008934,-171.340622,-0.015728,-0.000000,-0.000000,-0.039741,-0.002024,-0.000000,-171.340622,-0.000182,0.000000
0.370000,-0.044685,-171.429581,-0.015737,0.000002,0.000043,-0.198770,-0.010126,0.000434,-171.429581,0.000702,0.000000
0.630000,-0.050644,-171.385101,-0.015733,0.000157,0.003981,-0.225275,-0.011476,0.039806,-171.385101,0.005039,0.000000
0.890000,0.037613,-171.429581,-0.015612,0.000322,0.008169,0.167311,0.008523,0.081693,-171.429581,0.009375,0.000000
1.150000,0.018623,-171.429581,-0.015440,0.000499,0.012670,0.082841,0.004220,0.126702,-171.429581,0.013693,0.000000
1.410000,0.001862,-171.429581,-0.015267,0.000665,0.016894,0.008281,0.000422,0.168936,-171.429581,0.018030,0.000000
1.670000,0.023460,-171.474060,-0.015090,0.000832,0.021143,0.104357,0.005316,0.211430,-171.474060,0.022366,0.000000
1.930000,-0.000374,-171.518555,-0.014909,0.001006,0.025557,-0.001663,-0.000085,0.255571,-171.518555,0.026702,0.000000
2.190000,-0.017868,-171.563034,-0.014750,0.001176,0.029867,-0.079481,-0.004049,0.298672,-171.563034,0.031021,0.000000
2.450000,0.010803,-171.518555,-0.014582,0.001344,0.034143,0.048055,0.002448,0.341427,-171.518555,0.035357,0.000000
2.710000,-0.015640,-171.607513,-0.014388,0.001519,0.038574,-0.069571,-0.003544,0.385742,-171.607513,0.039693,0.000000
2.970000,-0.000740,-171.607513,-0.014224,0.001687,0.042850,-0.003292,-0.000168,0.428496,-171.607513,0.044029,0.000000
3.230000,0.051765,-171.518555,-0.014051,0.001858,0.047194,0.230264,0.011730,0.471944,-171.518555,0.048348,0.000000
3.490000,0.004845,-171.651993,-0.013879,0.002031,0.051583,0.021550,0.001098,0.515826,-171.651993,0.052684,0.000000
3.750000,0.011177,-171.607513,-0.013693,0.002203,0.055945,0.049718,0.002533,0.559447,-171.607513,0.057020,0.000000
4.010000,0.007080,-171.651993,-0.013538,0.002364,0.060038,0.031494,0.001604,0.600380,-171.651993,0.061356,0.000000
4.270000,-0.014145,-171.651993,-0.013348,0.002544,0.064617,-0.062920,-0.003205,0.646170,-171.651993,0.065675,0.000000
4.530000,-0.023827,-171.696472,-0.013189,0.002709,0.068797,-0.105986,-0.005399,0.687970,-171.696472,0.070011,0.000000
4.790000,-0.002235,-171.740952,-0.013012,0.002878,0.073098,-0.009944,-0.000507,0.730985,-171.740952,0.074347,0.000000
5.050000,0.010056,-171.651993,-0.012840,0.003051,0.077487,0.044729,0.002279,0.774866,-171.651993,0.078666,0.000000
5.310000,0.009682,-171.696472,-0.012659,0.003224,0.081901,0.043066,0.002194,0.819008,-171.696472,0.083002,0.000000
5.570000,0.031654,-171.829910,-0.012495,0.003388,0.086055,0.140806,0.007173,0.860548,-171.829910,0.087338,0.000000
5.830000,0.022346,-171.696472,-0.012314,0.003561,0.090452,0.099402,0.005064,0.904516,-171.696472,0.091674,0.000000
6.090000,-0.000740,-171.740952,-0.012124,0.003735,0.094874,-0.003292,-0.000168,0.948745,-171.740952,0.095993,0.000000
6.350000,0.011177,-171.829910,-0.011973,0.003905,0.099193,0.049718,0.002533,0.991933,-171.829910,0.100329,0.000000
6.610000,-0.046913,-171.785431,-0.011779,0.004077,0.103564,-0.208680,-0.010631,1.035641,-171.785431,0.104665,0.000000
6.870000,-0.006699,-171.874390,-0.011637,0.004247,0.107866,-0.029797,-0.001518,1.078655,-171.874390,0.109002,0.000000
7.130000,0.023834,-171.829910,-0.011451,0.004416,0.112176,0.106020,0.005401,1.121757,-171.829910,0.113320,0.000000
7.390000,-0.013779,-171.918869,-0.011275,0.004585,0.116451,-0.061291,-0.003122,1.164511,-171.918869,0.117657,0.000000
7.650001,0.023834,-171.918869,-0.011102,0.004759,0.120883,0.106020,0.005401,1.208826,-171.918869,0.121993,0.000000
7.910000,0.018250,-171.963364,-0.010930,0.004927,0.125158,0.081178,0.004135,1.251580,-171.963364,0.126329,0.000000
8.170000,-0.006325,-172.007843,-0.010766,0.005097,0.129468,-0.028134,-0.001433,1.294681,-172.007843,0.130648,0.000000
8.430000,0.014526,-171.918869,-0.010580,0.005268,0.133796,0.064617,0.003292,1.337956,-171.918869,0.134984,0.000000
8.690001,-0.001488,-172.007843,-0.010417,0.005439,0.138158,-0.006618,-0.000337,1.381577,-172.007843,0.139320,0.000000
8.950001,-0.061440,-172.007843,-0.010240,0.005607,0.142407,-0.273297,-0.013922,1.424071,-172.007843,0.143656,0.000000
9.210000,0.033516,-172.007843,-0.010054,0.005778,0.146769,0.149086,0.007595,1.467693,-172.007843,0.147975,0.000000
9.470000,0.018250,-172.007843,-0.009908,0.005948,0.151088,0.081178,0.004135,1.510881,-172.007843,0.152311,0.000000
9.730000,-0.004097,-171.918869,-0.009710,0.006122,0.155494,-0.018224,-0.000928,1.554936,-171.918869,0.156647,0.000000
9.990001,0.004845,-172.052322,-0.009533,0.006289,0.159734,0.021550,0.001098,1.597343,-172.052322,0.160966,0.000000
10.250001,0.024208,-172.052322,-0.009378,0.006462,0.164140,0.107683,0.005486,1.641398,-172.052322,0.165302,0.000000
10.510000,0.001495,-172.052322,-0.009192,0.006628,0.168363,0.006652,0.000339,1.683632,-172.052322,0.169638,0.000000
10.770000,0.010056,-172.096802,-0.009037,0.006799,0.172691,0.044729,0.002279,1.726907,-172.096802,0.173974,0.000000
11.030001,-0.000374,-172.096802,-0.008843,0.006974,0.177131,-0.001663,-0.000085,1.771309,-172.096802,0.178293,0.000000
11.290001,-0.023460,-172.230240,-0.008683,0.007141,0.181372,-0.104357,-0.005316,1.813716,-172.230240,0.182629,0.000000
11.550000,0.044685,-172.185760,-0.008507,0.007315,0.185803,0.198770,0.010126,1.858031,-172.185760,0.186965,0.000000
11.810000,0.038727,-172.096802,-0.008326,0.007489,0.190217,0.172265,0.008776,1.902173,-172.096802,0.191301,0.000000
12.070001,0.027184,-172.230240,-0.008162,0.007656,0.194467,0.120918,0.006160,1.944667,-172.230240,0.195620,0.000000
12.330001,0.040588,-172.141281,-0.007985,0.007822,0.198690,0.180546,0.009197,1.986901,-172.141281,0.199956,0.000000
12.590000,0.006706,-172.274719,-0.007808,0.007997,0.203130,0.029831,0.001520,2.031303,-172.274719,0.204292,0.000000
12.850000,-0.013779,-172.230240,-0.007636,0.008167,0.207440,-0.061291,-0.003122,2.074404,-172.230240,0.208628,0.000000
13.110001,0.026810,-172.274719,-0.007463,0.008336,0.211742,0.119255,0.006075,2.117418,-172.274719,0.212947,0.000000
13.370001,0.009308,-172.319199,-0.007278,0.008511,0.216173,0.041403,0.002109,2.161734,-172.319199,0.217283,0.000000
13.630001,0.024582,-172.230240,-0.007101,0.008679,0.220457,0.109346,0.005570,2.204575,-172.230240,0.221620,0.000000
13.890000,0.054367,-172.363678,-0.006929,0.008848,0.224750,0.241837,0.012320,2.247502,-172.363678,0.225956,0.000000
14.150001,0.013405,-172.319199,-0.006765,0.009023,0.229182,0.059628,0.003038,2.291817,-172.319199,0.230274,0.000000
14.410001,0.035004,-172.363678,-0.006588,0.009194,0.233527,0.155704,0.007932,2.335266,-172.363678,0.234611,0.000000
14.670001,0.026070,-172.408173,-0.006420,0.009359,0.237715,0.115964,0.005907,2.377152,-172.408173,0.238947,0.000000
14.930000,0.002235,-172.408173,-0.006247,0.009535,0.242181,0.009944,0.000507,2.421814,-172.408173,0.243265,0.000000
15.190001,0.005959,-172.452652,-0.006071,0.009702,0.246440,0.026505,0.001350,2.464395,-172.452652,0.247602,0.000000
15.450001,0.014153,-172.363678,-0.005902,0.009871,0.250732,0.062954,0.003207,2.507323,-172.363678,0.251938,0.000000
15.710001,0.022346,-172.408173,-0.005730,0.010039,0.254999,0.099402,0.005064,2.549990,-172.408173,0.256274,0.000000
15.970001,0.002235,-172.452652,-0.005558,0.010217,0.259517,0.009944,0.000507,2.595173,-172.452652,0.260593,0.000000
16.230001,0.048035,-172.452652,-0.005385,0.010381,0.263671,0.213669,0.010885,2.636713,-172.452652,0.264929,0.000000
16.490002,0.032768,-172.497131,-0.005221,0.010555,0.268085,0.145760,0.007425,2.680855,-172.497131,0.269265,0.000000
16.750000,0.012665,-172.452652,-0.005040,0.010727,0.272474,0.056336,0.002870,2.724736,-172.452652,0.273601,0.000000
17.010000,0.023087,-172.541611,-0.004872,0.010896,0.276758,0.102694,0.005231,2.767577,-172.541611,0.277920,0.000000
17.270000,-0.020477,-172.586090,-0.004682,0.011069,0.281163,-0.091088,-0.004640,2.811632,-172.586090,0.282256,0.000000
17.530001,0.015266,-172.497131,-0.004514,0.011238,0.285447,0.067908,0.003459,2.854473,-172.497131,0.286592,0.000000
17.790001,0.091232,-172.586090,-0.004363,0.011408,0.289757,0.405822,0.020674,2.897575,-172.586090,0.290928,0.000000
18.050001,0.517601,-172.586090,-0.004174,0.011575,0.294016,2.302404,0.117290,2.940155,-172.586090,0.295247,0.000000
18.310001,0.684792,-172.630569,-0.004143,-0.000006,-0.000156,3.046105,0.155176,-0.001561,-172.630569,0.000113,0.000000
18.570002,0.675858,-172.630569,-0.004148,-0.000006,-0.000156,3.006365,0.153151,-0.001561,-172.630569,0.000113,0.000000
18.830002,0.626335,-172.630569,-0.004148,-0.000006,-0.000156,2.786078,0.141930,-0.001561,-172.630569,0.000503,0.000000
19.090000,0.585373,-172.675049,-0.004156,-0.000002,-0.000052,2.603869,0.132647,-0.000520,-172.675049,0.000937,0.000000
19.350000,0.748100,-172.675049,-0.004130,0.000017,0.000425,3.327716,0.169522,0.004249,-172.675049,0.001370,0.000000
19.610001,0.833374,-172.719528,-0.004126,0.000029,0.000746,3.707033,0.188845,0.007458,-172.719528,0.001795,0.000000
19.870001,1.040413,-172.719528,-0.004113,0.000050,0.001266,4.627988,0.235761,0.012661,-172.719528,0.002229,0.000000
20.130001,1.223244,-172.719528,-0.004087,0.000072,0.001830,5.441260,0.277191,0.018298,-172.719528,0.002662,0.000000
20.390001,1.321548,-172.764008,-0.004079,0.000088,0.002229,5.878541,0.299467,0.022288,-172.764008,0.003096,0.000000
20.650002,1.407570,-172.764008,-0.004057,0.000102,0.002584,6.261184,0.318960,0.025843,-172.764008,0.003530,0.000000
20.910002,1.566574,-172.808502,-0.004044,0.000121,0.003070,6.968470,0.354991,0.030700,-172.808502,0.003963,0.000000
21.170000,1.743820,-172.675049,-0.004031,0.000140,0.003556,7.756900,0.395155,0.035556,-172.675049,0.004397,0.000000
21.430000,1.838036,-172.764008,-0.004010,0.000152,0.003850,8.175991,0.416505,0.038505,-172.764008,0.004830,0.000000
21.690001,1.932617,-172.808502,-0.004005,0.000162,0.004119,8.596710,0.437937,0.041193,-172.808502,0.005264,0.000000
21.950001,2.166466,-172.764008,-0.003984,0.000187,0.004744,9.636921,0.490928,0.047437,-172.764008,0.005698,0.000000
22.210001,2.361214,-172.897461,-0.003967,0.000209,0.005307,10.503203,0.535059,0.053074,-172.897461,0.006131,0.000000
22.470001,2.404411,-172.852982,-0.003967,0.000220,0.005594,10.695355,0.544847,0.055936,-172.852982,0.006565,0.000000
22.730001,2.601021,-172.897461,-0.003928,0.000240,0.006088,11.569919,0.589400,0.060879,-172.897461,0.006999,0.000000
22.990002,2.732841,-172.941940,-0.003919,0.000258,0.006556,12.156286,0.619271,0.065562,-172.941940,0.007432,0.000000
23.250002,2.812531,-172.808502,-0.003898,0.000270,0.006868,12.510760,0.637329,0.068684,-172.808502,0.007866,0.000000
23.510000,2.868011,-172.897461,-0.003893,0.000279,0.007077,12.757552,0.649901,0.070766,-172.897461,0.008299,0.000000
23.770000,3.086967,-172.941940,-0.003867,0.000301,0.007658,13.731517,0.699517,0.076576,-172.941940,0.008733,0.000000
24.030001,3.300339,-172.986420,-0.003837,0.000325,0.008265,14.680640,0.747867,0.082647,-172.986420,0.009167,0.000000
24.290001,3.390457,-172.986420,-0.003837,0.000341,0.008672,15.081507,0.768289,0.086723,-172.986420,0.009600,0.000000
24.550001,3.464554,-172.986420,-0.003824,0.000358,0.009089,15.411105,0.785079,0.090885,-172.986420,0.010034,0.000000
24.810001,3.547592,-173.075378,-0.003798,0.000372,0.009444,15.780478,0.803896,0.094441,-173.075378,0.010467,0.000000
25.070002,3.725586,-173.030899,-0.003790,0.000395,0.010025,16.572233,0.844230,0.100251,-173.030899,0.010901,0.000000
25.330002,3.726707,-173.075378,-0.003764,0.000408,0.010355,16.577223,0.844484,0.103547,-173.075378,0.011335,0.000000
25.590002,3.845123,-172.986420,-0.003755,0.000423,0.010736,17.103962,0.871317,0.107363,-172.986420,0.011768,0.000000
25.850000,4.021996,-173.075378,-0.003729,0.000443,0.011248,17.890730,0.911397,0.112479,-173.075378,0.012202,0.000000
26.110001,4.134827,-173.075378,-0.003725,0.000462,0.011725,18.392628,0.936965,0.117249,-173.075378,0.012635,0.000000
26.370001,4.109505,-173.119858,-0.003695,0.000476,0.012098,18.279989,0.931227,0.120978,-173.119858,0.013069,0.000000
26.630001,4.187332,-173.119858,-0.003678,0.000493,0.012523,18.626184,0.948863,0.125227,-173.119858,0.013503,0.000000
26.890001,4.338142,-173.208817,-0.003669,0.000512,0.013017,19.297022,0.983037,0.130171,-173.208817,0.013936,0.000000
27.150002,4.383202,-173.119858,-0.003652,0.000527,0.013390,19.497454,0.993248,0.133900,-173.119858,0.014370,0.000000
27.410002,4.368301,-173.208817,-0.003648,0.000541,0.013746,19.431175,0.989871,0.137455,-173.208817,0.014804,0.000000
27.670002,4.518745,-173.164337,-0.003613,0.000559,0.014188,20.100384,1.023962,0.141878,-173.164337,0.015237,0.000000
27.930002,4.652054,-173.253311,-0.003604,0.000581,0.014752,20.693369,1.054170,0.147515,-173.253311,0.015671,0.000000
28.190001,4.726524,-173.208817,-0.003591,0.000600,0.015228,21.024630,1.071046,0.152285,-173.208817,0.016104,0.000000
28.450001,4.710884,-173.208817,-0.003574,0.000614,0.015601,20.955059,1.067502,0.156014,-173.208817,0.016538,0.000000
28.710001,4.636040,-173.253311,-0.003566,0.000623,0.015818,20.622135,1.050542,0.158182,-173.253311,0.016963,0.000000
28.970001,4.882179,-173.253311,-0.003544,0.000649,0.016486,21.717018,1.106318,0.164860,-173.253311,0.017397,0.000000
29.230001,4.817757,-173.342270,-0.003523,0.000660,0.016772,21.430452,1.091719,0.167721,-173.342270,0.017830,0.000000
29.490002,4.976013,-173.342270,-0.003518,0.000681,0.017301,22.134413,1.127581,0.173012,-173.342270,0.018264,0.000000
29.750002,4.980110,-173.297791,-0.003479,0.000697,0.017709,22.152636,1.128509,0.177087,-173.297791,0.018697,0.000000
30.010002,5.164062,-173.342270,-0.003475,0.000719,0.018264,22.970898,1.170193,0.182638,-173.342270,0.019131,0.000000
30.270002,5.146561,-173.386749,-0.003445,0.000734,0.018654,22.893045,1.166227,0.186540,-173.386749,0.019565,0.000000
30.530001,5.151031,-173.386749,-0.003432,0.000751,0.019079,22.912933,1.167240,0.190790,-173.386749,0.019998,0.000000
30.790001,5.266090,-173.431229,-0.003415,0.000767,0.019487,23.424740,1.193313,0.194866,-173.431229,0.020432,0.000000
31.050001,5.251198,-173.431229,-0.003406,0.000781,0.019825,23.358494,1.189938,0.198248,-173.431229,0.020865,0.000000
31.310001,5.294395,-173.386749,-0.003385,0.000796,0.020215,23.550648,1.199727,0.202150,-173.386749,0.021299,0.000000
31.570002,5.399033,-173.475708,-0.003363,0.000815,0.020701,24.016096,1.223438,0.207007,-173.475708,0.021733,0.000000
31.830002,5.533829,-173.564667,-0.003350,0.000838,0.021273,24.615700,1.253983,0.212730,-173.564667,0.022166,0.000000
32.090000,5.547607,-173.386749,-0.003328,0.000854,0.021698,24.676991,1.257106,0.216980,-173.386749,0.022600,0.000000
32.350002,5.565857,-173.520187,-0.003307,0.000871,0.022114,24.758167,1.261241,0.221143,-173.520187,0.023034,0.000000
32.610001,5.495850,-173.520187,-0.003311,0.000882,0.022409,24.446760,1.245377,0.224091,-173.520187,0.023467,0.000000
32.870003,5.749802,-173.475708,-0.003285,0.000904,0.022973,25.576395,1.302924,0.229728,-173.475708,0.023901,0.000000
33.130001,5.754646,-173.609146,-0.003255,0.000919,0.023337,25.597944,1.304022,0.233370,-173.609146,0.024334,0.000000
33.390003,5.809387,-173.520187,-0.003242,0.000934,0.023736,25.841444,1.316426,0.237360,-173.520187,0.024768,0.000000
33.650002,5.958336,-173.564667,-0.003234,0.000958,0.024326,26.504002,1.350178,0.243257,-173.564667,0.025202,0.000000
33.910000,5.963173,-173.609146,-0.003225,0.000972,0.024681,26.525518,1.351274,0.246812,-173.609146,0.025635,0.000000
34.170002,5.990356,-173.564667,-0.003195,0.000989,0.025124,26.646437,1.357434,0.251235,-173.564667,0.026069,0.000000
34.430000,5.966896,-173.653625,-0.003182,0.001004,0.025496,26.542080,1.352118,0.254964,-173.653625,0.026502,0.000000
34.690002,6.097603,-173.564667,-0.003173,0.001023,0.025973,27.123491,1.381737,0.259734,-173.564667,0.026936,0.000000
34.950001,6.261070,-173.653625,-0.003143,0.001042,0.026468,27.850632,1.418779,0.264677,-173.653625,0.027370,0.000000
35.210003,6.125900,-173.698120,-0.003134,0.001051,0.026693,27.249365,1.388149,0.266932,-173.698120,0.027803,0.000000
35.470001,6.324005,-173.653625,-0.003100,0.001072,0.027240,28.130579,1.433040,0.272396,-173.653625,0.028237,0.000000
35.730003,6.497154,-173.742599,-0.003091,0.001094,0.027795,28.900785,1.472276,0.277946,-173.742599,0.028670,0.000000
35.990002,6.527695,-173.698120,-0.003078,0.001111,0.028211,29.036636,1.479197,0.282109,-173.698120,0.029104,0.000000
36.250000,6.553757,-173.742599,-0.003070,0.001129,0.028670,29.152565,1.485103,0.286705,-173.742599,0.029538,0.000000
36.510002,6.439064,-173.742599,-0.003061,0.001137,0.028879,28.642387,1.459113,0.288786,-173.742599,0.029971,0.000000
36.770000,6.772339,-173.787079,-0.003022,0.001162,0.029503,30.124868,1.534634,0.295030,-173.787079,0.030405,0.000000
37.030003,6.671425,-173.787079,-0.003014,0.001173,0.029798,29.675980,1.511767,0.297979,-173.787079,0.030839,0.000000
37.290001,6.894478,-173.742599,-0.002997,0.001193,0.030310,30.668169,1.562311,0.303095,-173.742599,0.031272,0.000000
37.550003,6.975655,-173.831558,-0.002979,0.001210,0.030743,31.029261,1.580706,0.307432,-173.831558,0.031706,0.000000
37.810001,6.949593,-173.876038,-0.002971,0.001224,0.031081,30.913332,1.574800,0.310814,-173.876038,0.032131,0.000000
38.070004,7.119019,-173.876038,-0.002936,0.001244,0.031602,31.666977,1.613193,0.316017,-173.876038,0.032564,0.000000
38.330002,7.191635,-173.920517,-0.002936,0.001261,0.032027,31.989990,1.629648,0.320266,-173.920517,0.032998,0.000000
38.590000,7.200195,-173.964996,-0.002906,0.001279,0.032486,32.028069,1.631588,0.324863,-173.964996,0.033432,0.000000
38.850002,7.335739,-173.964996,-0.002906,0.001295,0.032903,32.630997,1.662302,0.329025,-173.964996,0.033865,0.000000
39.110001,7.430321,-173.876038,-0.002876,0.001312,0.033336,33.051716,1.683735,0.333362,-173.876038,0.034299,0.000000
39.370003,7.488785,-173.920517,-0.002854,0.001329,0.033752,33.311779,1.696983,0.337524,-173.920517,0.034732,0.000000
39.630001,7.520065,-174.009476,-0.002859,0.001343,0.034108,33.450920,1.704071,0.341080,-174.009476,0.035166,0.000000
39.890003,7.571823,-173.964996,-0.002828,0.001358,0.034498,33.681152,1.715800,0.344982,-173.964996,0.035600,0.000000
40.150002,7.908073,-174.053955,-0.002815,0.001384,0.035157,35.176868,1.791995,0.351573,-174.053955,0.036033,0.000000
40.410004,7.831367,-173.920517,-0.002794,0.001398,0.035522,34.835663,1.774613,0.355216,-173.920517,0.036467,0.000000
40.670002,8.012711,-174.053955,-0.002772,0.001417,0.035999,35.642315,1.815706,0.359985,-174.053955,0.036900,0.000000
40.930000,7.961700,-174.053955,-0.002768,0.001430,0.036328,35.415413,1.804147,0.363281,-174.053955,0.037334,0.000000
41.190002,8.154587,-174.009476,-0.002742,0.001448,0.036788,36.273415,1.847856,0.367877,-174.009476,0.037768,0.000000
41.450001,8.411896,-174.098450,-0.002742,0.001471,0.037369,37.417980,1.906163,0.373688,-174.098450,0.038201,0.000000
41.710003,8.406685,-174.098450,-0.002712,0.001486,0.037750,37.394802,1.904982,0.377503,-174.098450,0.038635,0.000000
41.970001,8.366470,-174.098450,-0.002682,0.001501,0.038132,37.215919,1.895869,0.381319,-174.098450,0.039069,0.000000
42.230003,8.521004,-174.187408,-0.002677,0.001519,0.038583,37.903316,1.930887,0.385829,-174.187408,0.039502,0.000000
42.490002,8.704208,-174.098450,-0.002673,0.001539,0.039095,38.718254,1.972402,0.390945,-174.098450,0.039936,0.000000
42.750004,8.655426,-174.187408,-0.002639,0.001550,0.039372,38.501259,1.961348,0.393720,-174.187408,0.040369,0.000000
43.010002,8.819275,-174.187408,-0.002643,0.001569,0.039849,39.230095,1.998476,0.398490,-174.187408,0.040803,0.000000
43.270000,8.952209,-174.187408,-0.002608,0.001586,0.040274,39.821415,2.028600,0.402740,-174.187408,0.041237,0.000000
43.530003,9.199089,-174.187408,-0.002587,0.001607,0.040829,40.919590,2.084543,0.408290,-174.187408,0.041670,0.000000
43.790001,9.088867,-174.231888,-0.002583,0.001621,0.041176,40.429302,2.059567,0.411759,-174.231888,0.042104,0.000000
44.050003,9.274307,-174.231888,-0.002570,0.001639,0.041636,41.254181,2.101588,0.416355,-174.231888,0.042537,0.000000
44.310001,9.429214,-174.231888,-0.002548,0.001657,0.042095,41.943241,2.136691,0.420951,-174.231888,0.042971,0.000000
44.570004,9.418793,-174.276367,-0.002531,0.001671,0.042433,41.896881,2.134329,0.424334,-174.276367,0.043405,0.000000
44.830002,9.250481,-174.276367,-0.002531,0.001677,0.042598,41.148193,2.096189,0.425981,-174.276367,0.043838,0.000000
45.090004,9.765839,-174.320847,-0.002509,0.001705,0.043301,43.440620,2.212971,0.433006,-174.320847,0.044272,0.000000
45.350002,10.010490,-174.365326,-0.002488,0.001725,0.043804,44.528885,2.268409,0.438036,-174.365326,0.044705,0.000000
45.610001,10.078636,-174.365326,-0.002470,0.001741,0.044211,44.832012,2.283852,0.442112,-174.365326,0.045139,0.000000
45.870003,10.135605,-174.409805,-0.002449,0.001757,0.044636,45.085423,2.296761,0.446361,-174.409805,0.045573,0.000000
46.130001,10.133377,-174.454285,-0.002436,0.001771,0.044974,45.075512,2.296256,0.449743,-174.454285,0.046006,0.000000
46.390003,10.487503,-174.320847,-0.002427,0.001794,0.045555,46.650742,2.376502,0.455554,-174.320847,0.046440,0.000000
46.650002,10.404465,-174.454285,-0.002406,0.001807,0.045894,46.281372,2.357685,0.458936,-174.454285,0.046874,0.000000
46.910004,10.578362,-174.454285,-0.002406,0.001823,0.046310,47.054901,2.397091,0.463099,-174.454285,0.047298,0.000000
47.170002,10.835670,-174.454285,-0.002367,0.001841,0.046769,48.199471,2.455398,0.467695,-174.454285,0.047732,0.000000
47.430004,11.091492,-174.498764,-0.002363,0.001860,0.047246,49.337418,2.513368,0.472465,-174.498764,0.048166,0.000000
47.690002,11.007706,-174.454285,-0.002345,0.001876,0.047645,48.964722,2.494382,0.476454,-174.454285,0.048599,0.000000
47.950001,11.167084,-174.498764,-0.002333,0.001892,0.048053,49.673668,2.530497,0.480530,-174.498764,0.049033,0.000000
48.210003,11.447105,-174.498764,-0.002315,0.001911,0.048539,50.919270,2.593951,0.485386,-174.498764,0.049467,0.000000
48.470001,11.511894,-174.587738,-0.002294,0.001926,0.048912,51.207462,2.608633,0.489115,-174.587738,0.049900,0.000000
48.730003,11.529396,-174.543259,-0.002281,0.001940,0.049267,51.285316,2.612598,0.492671,-174.543259,0.050334,0.000000
48.990002,11.792664,-174.543259,-0.002264,0.001959,0.049753,52.456387,2.672256,0.497527,-174.543259,0.050767,0.000000
49.250004,12.084236,-174.632217,-0.002246,0.001979,0.050256,53.753368,2.738327,0.502557,-174.632217,0.051201,0.000000
49.510002,12.382507,-174.632217,-0.002238,0.001999,0.050776,55.080143,2.805916,0.507761,-174.632217,0.051635,0.000000
49.770000,12.422348,-174.632217,-0.002220,0.002015,0.051175,55.257362,2.814944,0.511750,-174.632217,0.052068,0.000000
50.030003,12.137482,-174.632217,-0.002212,0.002022,0.051357,53.990215,2.750393,0.513571,-174.632217,0.052502,0.000000
50.290001,12.728065,-174.632217,-0.002173,0.002048,0.052008,56.617264,2.884221,0.520075,-174.632217,0.052935,0.000000
50.550003,12.636086,-174.676697,-0.002169,0.002059,0.052294,56.208115,2.863378,0.522937,-174.676697,0.053369,0.000000
50.810001,13.149216,-174.676697,-0.002151,0.002080,0.052823,58.490631,2.979655,0.528227,-174.676697,0.053803,0.000000
51.070004,13.104530,-174.721176,-0.002126,0.002096,0.053239,58.291862,2.969529,0.532390,-174.721176,0.054236,0.000000
51.330002,13.694374,-174.810135,-0.002121,0.002118,0.053794,60.915619,3.103189,0.537940,-174.810135,0.054670,0.000000
51.590004,13.750229,-174.721176,-0.002091,0.002135,0.054228,61.164074,3.115846,0.542276,-174.721176,0.055104,0.000000
51.850002,13.793427,-174.765656,-0.002087,0.002150,0.054601,61.356224,3.125635,0.546005,-174.765656,0.055537,0.000000
52.110001,13.969925,-174.721176,-0.002065,0.002166,0.055025,62.141331,3.165630,0.550255,-174.721176,0.055971,0.000000
52.370003,13.997482,-174.765656,-0.002057,0.002179,0.055346,62.263912,3.171875,0.553463,-174.765656,0.056404,0.000000
52.630001,14.223145,-174.810135,-0.002035,0.002194,0.055737,63.267708,3.223011,0.557366,-174.810135,0.056838,0.000000
52.890003,14.582481,-174.854614,-0.002035,0.002213,0.056222,64.866119,3.304437,0.562222,-174.854614,0.057272,0.000000
53.150002,15.104919,-174.810135,-0.002009,0.002236,0.056803,67.190041,3.422824,0.568033,-174.810135,0.057705,0.000000
53.410004,15.223709,-174.854614,-0.001996,0.002254,0.057254,67.718437,3.449742,0.572542,-174.854614,0.058139,0.000000
53.670002,15.332809,-174.899094,-0.001970,0.002269,0.057644,68.203743,3.474464,0.576445,-174.899094,0.058572,0.000000
53.930004,15.259827,-174.854614,-0.001966,0.002282,0.057957,67.879097,3.457926,0.579567,-174.854614,0.059006,0.000000
54.190002,15.880196,-174.854614,-0.001953,0.002303,0.058494,70.638641,3.598504,0.584944,-174.854614,0.059440,0.000000
54.450001,15.943130,-174.988068,-0.001932,0.002317,0.058859,70.918587,3.612765,0.588586,-174.988068,0.059873,0.000000
54.710003,16.219055,-174.899094,-0.001910,0.002333,0.059258,72.145958,3.675290,0.592575,-174.899094,0.060307,0.000000
54.970001,16.506905,-174.988068,-0.001901,0.002354,0.059787,73.426376,3.740518,0.597865,-174.988068,0.060740,0.000000
55.230003,16.848366,-174.988068,-0.001880,0.002370,0.060203,74.945274,3.817894,0.602028,-174.988068,0.061174,0.000000
55.490002,17.050934,-174.988068,-0.001867,0.002387,0.060636,75.846344,3.863797,0.606364,-174.988068,0.061608,0.000000
55.750004,17.111633,-175.032547,-0.001863,0.002402,0.061001,76.116348,3.877552,0.610007,-175.032547,0.062033,0.000000
56.010002,17.388680,-174.988068,-0.001841,0.002418,0.061417,77.348709,3.940331,0.614169,-174.988068,0.062466,0.000000
56.270004,18.040703,-175.121506,-0.001828,0.002438,0.061920,80.249054,4.088082,0.619199,-175.121506,0.062900,0.000000
56.530003,17.873505,-175.077026,-0.001815,0.002448,0.062171,79.505318,4.050194,0.621714,-175.077026,0.063333,0.000000
56.790001,18.489784,-175.032547,-0.001789,0.002470,0.062726,82.246666,4.189845,0.627264,-175.032547,0.063767,0.000000
57.050003,19.088928,-175.121506,-0.001776,0.002493,0.063316,84.911797,4.325613,0.633161,-175.121506,0.064201,0.000000
57.310001,19.164520,-175.121506,-0.001763,0.002508,0.063698,85.248047,4.342742,0.636977,-175.121506,0.064634,0.000000
57.570004,19.496307,-175.121506,-0.001750,0.002526,0.064157,86.723907,4.417926,0.641574,-175.121506,0.065068,0.000000
57.830002,19.401726,-175.121506,-0.001738,0.002537,0.064444,86.303185,4.396494,0.644435,-175.121506,0.065502,0.000000
58.090004,20.144981,-175.121506,-0.001716,0.002558,0.064981,89.609352,4.564918,0.649812,-175.121506,0.065935,0.000000
58.350002,20.209030,-175.165985,-0.001707,0.002569,0.065259,89.894257,4.579432,0.652587,-175.165985,0.066369,0.000000
58.610004,20.853607,-175.165985,-0.001694,0.002590,0.065796,92.761475,4.725495,0.657964,-175.165985,0.066802,0.000000
58.870003,21.363380,-175.210464,-0.001669,0.002610,0.066299,95.029060,4.841011,0.662994,-175.210464,0.067236,0.000000
59.130001,21.273643,-175.254944,-0.001673,0.002623,0.066612,94.629890,4.820676,0.666116,-175.254944,0.067670,0.000000
59.390003,21.910767,-175.254944,-0.001634,0.002642,0.067115,97.463959,4.965051,0.671146,-175.254944,0.068103,0.000000
59.650002,22.347191,-175.254944,-0.001638,0.002659,0.067548,99.405266,5.063946,0.675482,-175.254944,0.068537,0.000000
59.910004,22.737808,-175.210464,-0.001617,0.002679,0.068051,101.142822,5.152461,0.680512,-175.210464,0.068970,0.000000
60.170002,23.040176,-175.299423,-0.001591,0.002694,0.068424,102.487823,5.220979,0.684241,-175.299423,0.069404,0.000000
60.430004,23.422974,-175.299423,-0.001591,0.002711,0.068866,104.190590,5.307722,0.688664,-175.299423,0.069838,0.000000
60.690002,23.848969,-175.299423,-0.001565,0.002728,0.069300,106.085510,5.404253,0.693000,-175.299423,0.070271,0.000000
60.950005,24.083565,-175.343903,-0.001556,0.002742,0.069638,107.129044,5.457414,0.696382,-175.343903,0.070705,0.000000
61.210003,24.392258,-175.388397,-0.001552,0.002757,0.070020,108.502182,5.527365,0.700198,-175.388397,0.071139,0.000000
61.470001,25.399155,-175.432877,-0.001531,0.002783,0.070679,112.981079,5.755530,0.706789,-175.432877,0.071572,0.000000
61.730003,25.510498,-175.388397,-0.001522,0.002794,0.070965,113.476364,5.780762,0.709651,-175.388397,0.072006,0.000000
61.990002,26.098099,-175.432877,-0.001496,0.002814,0.071468,116.090141,5.913914,0.714681,-175.432877,0.072439,0.000000
62.250004,26.202362,-175.521835,-0.001500,0.002827,0.071798,116.553925,5.937540,0.717976,-175.521835,0.072873,0.000000
62.510002,27.088982,-175.388397,-0.001475,0.002847,0.072309,120.497810,6.138451,0.723093,-175.388397,0.073307,0.000000
62.770004,27.997574,-175.432877,-0.001453,0.002869,0.072873,124.539429,6.344341,0.728730,-175.432877,0.073740,0.000000
63.030003,28.194557,-175.432877,-0.001444,0.002885,0.073272,125.415657,6.388978,0.732719,-175.432877,0.074174,0.000000
63.290005,28.406059,-175.477356,-0.001431,0.002898,0.073610,126.356461,6.436905,0.736101,-175.477356,0.074607,0.000000
63.550003,29.066277,-175.521835,-0.001427,0.002918,0.074113,129.293259,6.586512,0.741131,-175.521835,0.075041,0.000000
63.810001,29.784210,-175.477356,-0.001397,0.002937,0.074599,132.486786,6.749199,0.745988,-175.477356,0.075475,0.000000
64.070000,29.874329,-175.521835,-0.001397,0.002949,0.074894,132.887650,6.769619,0.748936,-175.521835,0.075908,0.000000
64.330002,29.984177,-175.521835,-0.001388,0.002962,0.075232,133.376282,6.794512,0.752318,-175.521835,0.076342,0.000000
64.590004,30.992561,-175.521835,-0.001362,0.002982,0.075743,137.861801,7.023015,0.757435,-175.521835,0.076775,0.000000
64.850006,32.192345,-175.655273,-0.001354,0.003005,0.076333,143.198700,7.294890,0.763332,-175.655273,0.077200,0.000000
65.110001,32.242989,-175.610794,-0.001341,0.003018,0.076645,143.423981,7.306366,0.766454,-175.610794,0.077634,0.000000
65.370003,33.088646,-175.655273,-0.001324,0.003037,0.077148,147.185654,7.497994,0.771484,-175.655273,0.078068,0.000000
65.630005,33.713860,-175.610794,-0.001311,0.003055,0.077608,149.966736,7.639670,0.776080,-175.610794,0.078501,0.000000
65.889999,33.819244,-175.655273,-0.001298,0.003067,0.077894,150.435516,7.663550,0.778942,-175.655273,0.078935,0.000000
66.150002,33.966331,-175.699753,-0.001289,0.003080,0.078232,151.089783,7.696881,0.782324,-175.699753,0.079368,0.000000
66.410004,35.258461,-175.655273,-0.001285,0.003103,0.078822,156.837463,7.989682,0.788221,-175.655273,0.079802,0.000000
66.670006,36.184921,-175.744232,-0.001272,0.003122,0.079299,160.958572,8.199620,0.792991,-175.744232,0.080236,0.000000
66.930000,36.874184,-175.699753,-0.001259,0.003139,0.079724,164.024567,8.355810,0.797241,-175.699753,0.080669,0.000000
67.190002,37.412636,-175.699753,-0.001242,0.003155,0.080149,166.419708,8.477824,0.801490,-175.699753,0.081103,0.000000
67.450005,37.937683,-175.788712,-0.001233,0.003169,0.080505,168.755249,8.596802,0.805046,-175.788712,0.081537,0.000000
67.710007,39.097252,-175.744232,-0.001212,0.003192,0.081068,173.913269,8.859564,0.810683,-175.744232,0.081970,0.000000
67.970001,39.422333,-175.788712,-0.001212,0.003204,0.081389,175.359299,8.933228,0.813891,-175.788712,0.082404,0.000000
68.230003,39.923172,-175.788712,-0.001199,0.003220,0.081779,177.587143,9.046720,0.817794,-175.788712,0.082837,0.000000
68.490005,40.893204,-175.833206,-0.001181,0.003239,0.082282,181.902054,9.266533,0.822824,-175.833206,0.083271,0.000000
68.750000,42.002129,-175.833206,-0.001181,0.003259,0.082768,186.834793,9.517818,0.827680,-175.833206,0.083705,0.000000
69.010002,42.353645,-175.833206,-0.001168,0.003273,0.083141,188.398422,9.597473,0.831409,-175.833206,0.084138,0.000000
69.270004,43.102112,-175.877686,-0.001151,0.003289,0.083549,191.727768,9.767078,0.835485,-175.877686,0.084572,0.000000
69.530006,43.929901,-175.877686,-0.001147,0.003309,0.084043,195.409958,9.954659,0.840428,-175.877686,0.085005,0.000000
69.790001,44.917801,-175.877686,-0.001125,0.003324,0.084433,199.804352,10.178519,0.844331,-175.877686,0.085439,0.000000
70.050003,45.171761,-175.922165,-0.001121,0.003337,0.084763,200.934021,10.236067,0.847626,-175.922165,0.085873,0.000000
70.310005,46.339523,-175.877686,-0.001112,0.003356,0.085240,206.128494,10.500687,0.852396,-175.877686,0.086306,0.000000
70.570000,47.518822,-175.922165,-0.001087,0.003377,0.085777,211.374283,10.767919,0.857773,-175.922165,0.086740,0.000000
70.830002,48.619926,-175.922165,-0.001078,0.003397,0.086272,216.272232,11.017432,0.862716,-175.922165,0.087174,0.000000
71.090004,49.190033,-176.011124,-0.001078,0.003411,0.086636,218.808197,11.146621,0.866358,-176.011124,0.087607,0.000000
71.350006,49.412338,-176.011124,-0.001069,0.003420,0.086861,219.797058,11.196996,0.868613,-176.011124,0.088041,0.000000
71.610001,50.884323,-176.011124,-0.001065,0.003444,0.087486,226.344772,11.530553,0.874857,-176.011124,0.088474,0.000000
71.870003,51.321861,-176.011124,-0.001052,0.003454,0.087729,228.291046,11.629700,0.877286,-176.011124,0.088908,0.000000
72.130005,52.593887,-176.011124,-0.001043,0.003477,0.088310,233.949295,11.917946,0.883096,-176.011124,0.089342,0.000000
72.390007,53.343475,-176.055603,-0.001026,0.003489,0.088630,237.283630,12.087805,0.886305,-176.055603,0.089775,0.000000
72.650002,54.990105,-176.055603,-0.001026,0.003516,0.089298,244.608200,12.460936,0.892982,-176.055603,0.090209,0.000000
72.910004,55.830551,-176.100082,-0.001000,0.003531,0.089680,248.346695,12.651384,0.896798,-176.100082,0.090642,0.000000
73.170006,56.607323,-176.144562,-0.000996,0.003546,0.090079,251.801941,12.827403,0.900787,-176.144562,0.091076,0.000000
73.430000,57.638794,-176.144562,-0.001005,0.003564,0.090521,256.390167,13.061137,0.905210,-176.144562,0.091510,0.000000
73.690002,58.275551,-176.144562,-0.000974,0.003577,0.090859,259.222595,13.205429,0.908592,-176.144562,0.091943,0.000000
73.950005,59.170357,-176.189041,-0.000974,0.003593,0.091258,263.202881,13.408195,0.912582,-176.189041,0.092368,0.000000
74.210007,60.317635,-176.189041,-0.000953,0.003612,0.091744,268.306244,13.668171,0.917438,-176.189041,0.092802,0.000000
74.470001,61.669350,-176.278015,-0.000953,0.003632,0.092247,274.318970,13.974475,0.922468,-176.278015,0.093235,0.000000
74.730003,62.713112,-176.189041,-0.000953,0.003648,0.092654,278.961853,14.210995,0.926544,-176.189041,0.093669,0.000000
74.990005,63.842140,-176.233521,-0.000931,0.003667,0.093131,283.984009,14.466836,0.931314,-176.233521,0.094103,0.000000
75.250000,64.437569,-176.233521,-0.000936,0.003678,0.093418,286.632629,14.601762,0.934175,-176.233521,0.094536,0.000000
75.510002,65.971748,-176.233521,-0.000905,0.003701,0.093999,293.457001,14.949411,0.939986,-176.233521,0.094970,0.000000
75.770004,66.520241,-176.322495,-0.000914,0.003713,0.094319,295.896820,15.073702,0.943195,-176.322495,0.095403,0.000000
76.030006,67.488792,-176.322495,-0.000901,0.003717,0.094406,300.205139,15.293179,0.944062,-176.322495,0.094666,0.000000
76.290001,66.794319,-176.366974,-0.000892,0.003717,0.094406,297.115967,15.135809,0.944062,-176.366974,0.094666,0.000000
76.550003,66.169472,-176.366974,-0.000888,0.003715,0.094363,294.336517,14.994217,0.943628,-176.366974,0.094406,0.000000
76.810005,65.612770,-176.366974,-0.000880,0.003714,0.094345,291.860168,14.868067,0.943455,-176.366974,0.094406,0.000000
77.070007,65.176353,-176.366974,-0.000875,0.003714,0.094328,289.918915,14.769173,0.943281,-176.366974,0.094406,0.000000
77.330002,64.760048,-176.411453,-0.000880,0.003714,0.094328,288.067078,14.674837,0.943281,-176.411453,0.094406,0.000000
77.590004,64.394005,-176.455933,-0.000867,0.003713,0.094319,286.438843,14.591890,0.943195,-176.455933,0.094406,0.000000
77.850006,64.066307,-176.455933,-0.000880,0.003713,0.094311,284.981171,14.517632,0.943108,-176.455933,0.094406,0.000000
78.110001,63.745323,-176.455933,-0.000858,0.003713,0.094311,283.553345,14.444897,0.943108,-176.455933,0.094406,0.000000
78.370003,63.489510,-176.544891,-0.000867,0.003713,0.094311,282.415436,14.386929,0.943108,-176.544891,0.094406,0.000000
78.630005,63.244865,-176.455933,-0.000858,0.003713,0.094311,281.327209,14.331491,0.943108,-176.455933,0.094406,0.000000
78.890007,62.999092,-176.544891,-0.000862,0.003713,0.094302,280.233948,14.275798,0.943021,-176.544891,0.094406,0.000000
79.150002,62.790939,-176.589371,-0.000884,0.003713,0.094302,279.308044,14.228630,0.943021,-176.589371,0.094406,0.000000
79.410004,62.583527,-176.544891,-0.000854,0.003713,0.094302,278.385437,14.181629,0.943021,-176.544891,0.094406,0.000000
79.670006,62.392494,-176.633850,-0.000867,0.003713,0.094302,277.535675,14.138341,0.943021,-176.633850,0.094406,0.000000
79.930000,62.217484,-176.589371,-0.000845,0.003713,0.094302,276.757202,14.098682,0.943021,-176.589371,0.094406,0.000000
80.190002,62.053642,-176.633850,-0.000849,0.003713,0.094302,276.028381,14.061557,0.943021,-176.633850,0.094406,0.000000
80.450005,61.894264,-176.633850,-0.000867,0.003713,0.094302,275.319427,14.025441,0.943021,-176.633850,0.094406,0.000000
80.710007,61.734146,-176.589371,-0.000854,0.003713,0.094302,274.607208,13.989157,0.943021,-176.589371,0.094406,0.000000
80.970001,61.610886,-176.722824,-0.000858,0.003713,0.094302,274.058899,13.961226,0.943021,-176.722824,0.094406,0.000000
81.230003,61.476463,-176.722824,-0.000849,0.003712,0.094293,273.460968,13.930766,0.942935,-176.722824,0.094406,0.000000
81.490005,61.338684,-176.767303,-0.000858,0.003712,0.094293,272.848083,13.899544,0.942935,-176.767303,0.094406,0.000000
81.750008,61.245216,-176.678345,-0.000862,0.003712,0.094293,272.432343,13.878365,0.942935,-176.678345,0.094406,0.000000
82.010002,61.113396,-176.678345,-0.000845,0.003712,0.094293,271.845947,13.848494,0.942935,-176.678345,0.094406,0.000000
82.270004,61.002434,-176.767303,-0.000858,0.003712,0.094293,271.352386,13.823349,0.942935,-176.767303,0.094406,0.000000
82.530006,60.909340,-176.811783,-0.000858,0.003712,0.094293,270.938263,13.802254,0.942935,-176.811783,0.094406,0.000000
82.790001,60.799492,-176.856262,-0.000849,0.003712,0.094293,270.449646,13.777362,0.942935,-176.856262,0.094406,0.000000
83.050003,60.701927,-176.811783,-0.000841,0.003712,0.094293,270.015656,13.755254,0.942935,-176.811783,0.094406,0.000000
83.310005,60.601761,-176.811783,-0.000854,0.003712,0.094293,269.570099,13.732555,0.942935,-176.811783,0.094406,0.000000
83.570007,60.528030,-176.856262,-0.000849,0.003712,0.094293,269.242126,13.715848,0.942935,-176.856262,0.094406,0.000000
83.830002,60.431587,-176.856262,-0.000854,0.003712,0.094293,268.813110,13.693994,0.942935,-176.856262,0.094406,0.000000
84.090004,60.343704,-176.945221,-0.000849,0.003712,0.094293,268.422211,13.674079,0.942935,-176.945221,0.094406,0.000000
84.350006,60.274445,-176.900742,-0.000845,0.003712,0.094293,268.114105,13.658384,0.942935,-176.900742,0.094406,0.000000
84.610001,60.186188,-176.945221,-0.000841,0.003712,0.094293,267.721527,13.638385,0.942935,-176.945221,0.094406,0.000000
84.870003,60.122513,-176.945221,-0.000854,0.003712,0.094293,267.438293,13.623957,0.942935,-176.945221,0.094406,0.000000
85.130005,60.032776,-176.945221,-0.000841,0.003712,0.094293,267.039124,13.603621,0.942935,-176.945221,0.094406,0.000000
85.390007,59.962395,-177.034180,-0.000841,0.003712,0.094293,266.726044,13.587672,0.942935,-177.034180,0.094406,0.000000
85.650002,59.898720,-176.989700,-0.000862,0.003712,0.094293,266.442810,13.573244,0.942935,-176.989700,0.094406,0.000000
85.910004,59.825737,-177.034180,-0.000832,0.003712,0.094293,266.118164,13.556706,0.942935,-177.034180,0.094406,0.000000
86.170006,59.771370,-176.989700,-0.000841,0.003712,0.094293,265.876343,13.544386,0.942935,-176.989700,0.094406,0.000000
86.430000,59.689819,-177.034180,-0.000836,0.003712,0.094293,265.513580,13.525907,0.942935,-177.034180,0.094406,0.000000
86.690002,59.643646,-177.123154,-0.000841,0.003712,0.094293,265.308197,13.515444,0.942935,-177.123154,0.094406,0.000000
86.950005,59.576614,-177.034180,-0.000836,0.003712,0.094293,265.010010,13.500254,0.942935,-177.034180,0.094406,0.000000
87.210007,59.520020,-177.123154,-0.000836,0.003712,0.094293,264.758270,13.487430,0.942935,-177.123154,0.094406,0.000000
87.470001,59.465652,-177.123154,-0.000845,0.003712,0.094293,264.516418,13.475109,0.942935,-177.123154,0.094406,0.000000
87.730003,59.407936,-177.123154,-0.000836,0.003712,0.094293,264.259705,13.462031,0.942935,-177.123154,0.094406,0.000000
87.990005,59.358406,-177.167633,-0.000841,0.003712,0.094293,264.039368,13.450808,0.942935,-177.167633,0.094406,0.000000
88.250008,59.291756,-177.167633,-0.000849,0.003712,0.094293,263.742889,13.435703,0.942935,-177.167633,0.094406,0.000000
88.510002,59.256378,-177.212112,-0.000836,0.003712,0.094293,263.585541,13.427688,0.942935,-177.212112,0.094406,0.000000
88.770004,59.192329,-177.167633,-0.000841,0.003712,0.094293,263.300629,13.413174,0.942935,-177.167633,0.094406,0.000000
89.030006,59.146156,-177.212112,-0.000828,0.003712,0.094293,263.095245,13.402711,0.942935,-177.212112,0.094406,0.000000
89.290001,59.101845,-177.212112,-0.000832,0.003712,0.094293,262.898132,13.392669,0.942935,-177.212112,0.094406,0.000000
89.550003,59.045990,-177.256592,-0.000841,0.003712,0.094293,262.649689,13.380013,0.942935,-177.256592,0.094406,0.000000
89.810005,59.013214,-177.256592,-0.000836,0.003712,0.094293,262.503876,13.372585,0.942935,-177.256592,0.094406,0.000000
90.070007,58.953262,-177.345551,-0.000841,0.003712,0.094293,262.237213,13.359000,0.942935,-177.345551,0.094406,0.000000
90.330002,58.916771,-177.301071,-0.000845,0.003712,0.094293,262.074890,13.350732,0.942935,-177.301071,0.094406,0.000000
90.590004,58.854584,-177.390030,-0.000832,0.003712,0.094293,261.798279,13.336639,0.942935,-177.390030,0.094406,0.000000
90.850006,58.822937,-177.345551,-0.000854,0.003712,0.094293,261.657501,13.329468,0.942935,-177.345551,0.094406,0.000000
91.110001,58.778252,-177.434509,-0.000841,0.003712,0.094293,261.458710,13.319342,0.942935,-177.434509,0.094406,0.000000
91.370003,58.731705,-177.434509,-0.000832,0.003712,0.094293,261.251678,13.308795,0.942935,-177.434509,0.094406,0.000000
91.630005,58.712715,-177.345551,-0.000836,0.003712,0.094293,261.167206,13.304491,0.942935,-177.345551,0.094406,0.000000
91.890007,58.659836,-177.390030,-0.000836,0.003712,0.094293,260.931976,13.292509,0.942935,-177.390030,0.094406,0.000000
92.150002,58.619995,-177.434509,-0.000836,0.003712,0.094293,260.754761,13.283481,0.942935,-177.434509,0.094406,0.000000
92.410004,58.574562,-177.478989,-0.000836,0.003712,0.094293,260.552673,13.273186,0.942935,-177.478989,0.094406,0.000000
92.670006,58.543282,-177.434509,-0.000849,0.003712,0.094293,260.413513,13.266097,0.942935,-177.434509,0.094406,0.000000
92.930008,58.509399,-177.478989,-0.000823,0.003712,0.094293,260.262817,13.258419,0.942935,-177.478989,0.094406,0.000000
93.190002,58.466949,-177.523483,-0.000845,0.003712,0.094293,260.073975,13.248800,0.942935,-177.523483,0.094406,0.000000
93.450005,58.447586,-177.478989,-0.000828,0.003712,0.094293,259.987854,13.244412,0.942935,-177.478989,0.094406,0.000000
93.710007,58.382050,-177.567963,-0.000836,0.003712,0.094293,259.696320,13.229562,0.942935,-177.567963,0.094406,0.000000
93.970001,58.372368,-177.478989,-0.000832,0.003712,0.094293,259.653259,13.227367,0.942935,-177.478989,0.094406,0.000000
94.230003,58.337364,-177.523483,-0.000841,0.003712,0.094293,259.497559,13.219436,0.942935,-177.523483,0.094406,0.000000
94.490005,58.294540,-177.612442,-0.000828,0.003712,0.094293,259.307068,13.209732,0.942935,-177.612442,0.094406,0.000000
94.750008,58.261398,-177.567963,-0.000828,0.003712,0.094293,259.159637,13.202221,0.942935,-177.567963,0.094406,0.000000
95.010002,58.214104,-177.656921,-0.000828,0.003712,0.094293,258.949280,13.191504,0.942935,-177.656921,0.094406,0.000000
95.270004,58.207405,-177.656921,-0.000828,0.003712,0.094293,258.919464,13.189986,0.942935,-177.656921,0.094406,0.000000
95.530006,58.150429,-177.612442,-0.000836,0.003712,0.094293,258.666016,13.177075,0.942935,-177.612442,0.094406,0.000000
95.790001,58.138145,-177.745880,-0.000832,0.003712,0.094293,258.611389,13.174293,0.942935,-177.745880,0.094406,0.000000
96.050003,58.089737,-177.701401,-0.000823,0.003712,0.094293,258.396057,13.163322,0.942935,-177.701401,0.094406,0.000000
96.310005,58.062553,-177.790359,-0.000823,0.003712,0.094293,258.275146,13.157163,0.942935,-177.790359,0.094406,0.000000
96.570007,58.044304,-177.701401,-0.000823,0.003712,0.094293,258.193970,13.153028,0.942935,-177.701401,0.094406,0.000000
96.830002,58.004463,-177.745880,-0.000819,0.003712,0.094293,258.016724,13.144000,0.942935,-177.745880,0.094406,0.000000
97.090004,57.976158,-177.790359,-0.000836,0.003712,0.094293,257.890839,13.137585,0.942935,-177.790359,0.094406,0.000000
97.350006,57.941528,-177.745880,-0.000832,0.003712,0.094293,257.736786,13.129738,0.942935,-177.745880,0.094406,0.000000
97.610008,57.918816,-177.790359,-0.000832,0.003712,0.094293,257.635773,13.124591,0.942935,-177.790359,0.094406,0.000000
97.870003,57.890884,-177.834839,-0.000832,0.003712,0.094293,257.511505,13.118261,0.942935,-177.834839,0.094406,0.000000
98.130005,57.858864,-177.834839,-0.000832,0.003712,0.094293,257.369080,13.111006,0.942935,-177.834839,0.094406,0.000000
98.390007,57.843224,-177.834839,-0.000828,0.003712,0.094293,257.299500,13.107462,0.942935,-177.834839,0.094406,0.000000
98.650002,57.804123,-177.834839,-0.000841,0.003712,0.094293,257.125580,13.098601,0.942935,-177.834839,0.094406,0.000000
98.910004,57.786995,-177.923798,-0.000832,0.003712,0.094293,257.049377,13.094720,0.942935,-177.923798,0.094406,0.000000
99.170006,57.758324,-177.834839,-0.000836,0.003712,0.094293,256.921844,13.088223,0.942935,-177.834839,0.094406,0.000000
99.430008,57.735237,-177.879318,-0.000832,0.003712,0.094293,256.819153,13.082992,0.942935,-177.879318,0.094406,0.000000
99.690002,57.708054,-177.879318,-0.000828,0.003712,0.094293,256.698242,13.076832,0.942935,-177.879318,0.094406,0.000000
99.950005,57.675659,-177.923798,-0.000828,0.003712,0.094293,256.554138,13.069491,0.942935,-177.923798,0.094406,0.000000
100.210007,57.661133,-178.057251,-0.000836,0.003712,0.094293,256.489532,13.066199,0.942935,-178.057251,0.094406,0.000000
100.470001,57.622406,-177.968292,-0.000832,0.003712,0.094293,256.317261,13.057424,0.942935,-177.968292,0.094406,0.000000
100.730003,57.609001,-178.012772,-0.000828,0.003712,0.094293,256.257629,13.054387,0.942935,-178.012772,0.094406,0.000000
100.990005,57.571388,-177.968292,-0.000828,0.003712,0.094293,256.090332,13.045863,0.942935,-177.968292,0.094406,0.000000
101.250008,57.555748,-178.012772,-0.000832,0.003712,0.094293,256.020752,13.042319,0.942935,-178.012772,0.094406,0.000000
101.510002,57.534523,-178.057251,-0.000841,0.003712,0.094293,255.926346,13.037509,0.942935,-178.057251,0.094406,0.000000
101.770004,57.504738,-178.057251,-0.000828,0.003712,0.094293,255.793854,13.030760,0.942935,-178.057251,0.094406,0.000000
102.030006,57.485374,-178.146210,-0.000819,0.003712,0.094293,255.707718,13.026372,0.942935,-178.146210,0.094406,0.000000
102.290009,57.448135,-178.057251,-0.000832,0.003712,0.094293,255.542068,13.017933,0.942935,-178.057251,0.094406,0.000000
102.550003,57.439201,-178.057251,-0.000836,0.003712,0.094293,255.502335,13.015908,0.942935,-178.057251,0.094406,0.000000
102.810005,57.419464,-178.190689,-0.000832,0.003712,0.094293,255.414536,13.011436,0.942935,-178.190689,0.094406,0.000000
103.070007,57.394890,-178.146210,-0.000836,0.003712,0.094293,255.305222,13.005868,0.942935,-178.146210,0.094406,0.000000
103.330002,57.385948,-178.190689,-0.000828,0.003712,0.094293,255.265442,13.003841,0.942935,-178.190689,0.094406,0.000000
103.590004,57.344986,-178.190689,-0.000815,0.003712,0.094293,255.083237,12.994559,0.942935,-178.190689,0.094406,0.000000
103.850006,57.323395,-178.235168,-0.000836,0.003712,0.094293,254.987198,12.989667,0.942935,-178.235168,0.094406,0.000000
104.110008,57.318924,-178.235168,-0.000828,0.003712,0.094293,254.967300,12.988653,0.942935,-178.235168,0.094406,0.000000
104.370003,57.289131,-178.235168,-0.000823,0.003712,0.094293,254.834778,12.981903,0.942935,-178.235168,0.094406,0.000000
104.630005,57.274239,-178.279648,-0.000823,0.003712,0.094293,254.768539,12.978528,0.942935,-178.279648,0.094406,0.000000
104.890007,57.240723,-178.279648,-0.000828,0.003712,0.094293,254.619446,12.970934,0.942935,-178.279648,0.094406,0.000000
105.150002,57.227318,-178.279648,-0.000819,0.003712,0.094293,254.559830,12.967896,0.942935,-178.279648,0.094406,0.000000
105.410004,57.216896,-178.324127,-0.000823,0.003712,0.094293,254.513458,12.965534,0.942935,-178.324127,0.094406,0.000000
105.670006,57.182632,-178.279648,-0.000823,0.003712,0.094293,254.361053,12.957769,0.942935,-178.279648,0.094406,0.000000
105.930008,57.174446,-178.368607,-0.000836,0.003712,0.094293,254.324631,12.955914,0.942935,-178.368607,0.094406,0.000000
106.190002,57.154335,-178.324127,-0.000828,0.003712,0.094293,254.235184,12.951358,0.942935,-178.324127,0.094406,0.000000
106.450005,57.127899,-178.368607,-0.000828,0.003712,0.094293,254.117584,12.945367,0.942935,-178.368607,0.094406,0.000000
106.500008,57.115234,-178.368607,-0.000819,0.003712,0.094293,254.061249,12.942497,0.942935,-178.368607,0.094406,0.000000