File: Data/compression 11/AutoNoHeating-14-11-1-240530_05302024_163014.csv
Time (sec),S:Load (lbs),S:HL1 (DIM),S:LVDT (in),S:Position (in),Ch:Position (mm),Ch:Load (N),Ch:Stress (MPa),Ch:Strain (mm/mm),Ch:HL1 (DIM),Set Point (),Cycles ()
0.210000,0.004097,-160.620712,-0.010279,-0.000000,-0.000000,0.018224,0.000928,-0.000000,-160.620712,0.000225,0.000000
0.440000,0.014526,-160.620712,-0.010270,0.000001,0.000017,0.064617,0.003292,0.000173,-160.620712,0.000486,0.000000
0.670000,0.024208,-160.709671,-0.010287,0.000126,0.003191,0.107683,0.005486,0.031914,-160.709671,0.004319,0.000000
0.900000,0.039848,-160.665192,-0.010162,0.000272,0.006920,0.177254,0.009030,0.069205,-160.665192,0.008152,0.000000
1.130000,0.053253,-160.620712,-0.010016,0.000427,0.010849,0.236882,0.012067,0.108490,-160.620712,0.011985,0.000000
1.360000,0.022713,-160.709671,-0.009865,0.000577,0.014665,0.101031,0.005147,0.146648,-160.709671,0.015818,0.000000
1.590000,0.027557,-160.754150,-0.009692,0.000730,0.018533,0.122581,0.006245,0.185326,-160.754150,0.019651,0.000000
1.820000,0.029793,-160.709671,-0.009537,0.000880,0.022348,0.132525,0.006751,0.223484,-160.709671,0.023484,0.000000
2.050000,0.056976,-160.798645,-0.009408,0.001025,0.026043,0.253443,0.012911,0.260428,-160.798645,0.027318,0.000000
2.280000,0.033516,-160.709671,-0.009235,0.001177,0.029893,0.149086,0.007595,0.298933,-160.709671,0.031151,0.000000
2.510000,0.037239,-160.754150,-0.009076,0.001333,0.033856,0.165648,0.008438,0.338565,-160.754150,0.034984,0.000000
2.740000,-0.014893,-160.843124,-0.008933,0.001478,0.037542,-0.066245,-0.003375,0.375422,-160.843124,0.038817,0.000000
2.970000,-0.017876,-160.798645,-0.008783,0.001628,0.041349,-0.079515,-0.004051,0.413493,-160.798645,0.042650,0.000000
3.200000,0.044685,-160.843124,-0.008636,0.001783,0.045278,0.198770,0.010126,0.452779,-160.843124,0.046466,0.000000
3.430000,0.065910,-160.843124,-0.008489,0.001931,0.049042,0.293184,0.014935,0.490416,-160.843124,0.050299,0.000000
3.660000,0.066658,-160.887604,-0.008313,0.002093,0.053161,0.296510,0.015105,0.531609,-160.887604,0.054132,0.000000
3.890000,0.026443,-160.932083,-0.008166,0.002240,0.056899,0.117626,0.005992,0.568987,-160.932083,0.057965,0.000000
4.120000,0.055115,-160.932083,-0.008024,0.002390,0.060714,0.245163,0.012489,0.607145,-160.932083,0.061798,0.000000
4.350000,0.037987,-160.932083,-0.007860,0.002539,0.064487,0.168974,0.008608,0.644869,-160.932083,0.065632,0.000000
4.580000,0.056229,-160.887604,-0.007700,0.002685,0.068199,0.250117,0.012742,0.681986,-160.887604,0.069465,0.000000
4.810000,0.028671,-160.976562,-0.007545,0.002840,0.072145,0.127536,0.006497,0.721445,-160.976562,0.073298,0.000000
5.040000,0.005219,-160.976562,-0.007399,0.002994,0.076038,0.023213,0.001183,0.760383,-160.976562,0.077131,0.000000
5.270000,0.011917,-161.021042,-0.007252,0.003141,0.079785,0.053010,0.002700,0.797848,-161.021042,0.080964,0.000000
5.500000,0.048782,-160.976562,-0.007101,0.003293,0.083653,0.216995,0.011054,0.836526,-160.976562,0.084797,0.000000
5.730000,0.062561,-160.976562,-0.006942,0.003440,0.087364,0.278285,0.014177,0.873643,-160.976562,0.088630,0.000000
5.960001,0.077827,-161.021042,-0.006786,0.003592,0.091241,0.346194,0.017636,0.912408,-161.021042,0.092464,0.000000
6.190000,0.055489,-161.065521,-0.006640,0.003749,0.095230,0.246826,0.012574,0.952300,-161.065521,0.096279,0.000000
6.420000,0.028671,-161.065521,-0.006480,0.003896,0.098959,0.127536,0.006497,0.989591,-161.065521,0.100113,0.000000
6.650000,0.040588,-161.065521,-0.006334,0.004046,0.102775,0.180546,0.009197,1.027749,-161.065521,0.103946,0.000000
6.880000,0.032394,-161.110001,-0.006178,0.004194,0.106530,0.144098,0.007341,1.065300,-161.110001,0.107779,0.000000
7.110000,0.041710,-161.065521,-0.006010,0.004347,0.110415,0.185535,0.009452,1.104152,-161.065521,0.111612,0.000000
7.340000,0.029793,-161.198959,-0.005877,0.004504,0.114396,0.132525,0.006751,1.143957,-161.198959,0.115445,0.000000
7.570000,0.041710,-161.154480,-0.005734,0.004647,0.118029,0.185535,0.009452,1.180294,-161.154480,0.119278,0.000000
7.800000,0.036491,-161.110001,-0.005562,0.004805,0.122045,0.162322,0.008269,1.220447,-161.110001,0.123111,0.000000
8.030001,0.055115,-161.110001,-0.005402,0.004954,0.125834,0.245163,0.012489,1.258345,-161.110001,0.126944,0.000000
8.260000,0.066658,-161.154480,-0.005273,0.005101,0.129555,0.296510,0.015105,1.295548,-161.154480,0.130778,0.000000
8.490001,0.056976,-161.287933,-0.005113,0.005253,0.133414,0.253443,0.012911,1.334140,-161.287933,0.134611,0.000000
8.720000,0.027931,-161.198959,-0.004945,0.005409,0.137395,0.124244,0.006329,1.373946,-161.198959,0.138444,0.000000
8.950001,0.024948,-161.154480,-0.004812,0.005555,0.141089,0.110975,0.005653,1.410890,-161.154480,0.142260,0.000000
9.180000,0.027184,-161.243454,-0.004652,0.005704,0.144879,0.120918,0.006160,1.448787,-161.243454,0.146093,0.000000
9.410001,0.058838,-161.243454,-0.004506,0.005853,0.148677,0.261724,0.013333,1.486772,-161.243454,0.149926,0.000000
9.640000,0.087509,-161.243454,-0.004342,0.006008,0.152597,0.389260,0.019830,1.525970,-161.243454,0.153759,0.000000
9.870001,0.152672,-161.243454,-0.004186,0.006161,0.156500,0.679118,0.034596,1.564996,-161.243454,0.157592,0.000000
10.100000,0.737297,-161.243454,-0.004074,0.006269,0.159240,3.279661,0.167074,1.592400,-161.243454,0.159387,0.000000
10.330001,0.681816,-161.332413,-0.004057,-0.000000,-0.000009,3.032870,0.154502,-0.000087,-161.332413,0.000147,0.000000
10.560000,0.642342,-161.332413,-0.004070,-0.000001,-0.000017,2.857278,0.145557,-0.000173,-161.332413,0.000147,0.000000
10.790001,0.635643,-161.376892,-0.004070,-0.000001,-0.000017,2.827481,0.144039,-0.000173,-161.376892,0.000503,0.000000
11.020000,0.646065,-161.376892,-0.004066,-0.000000,-0.000009,2.873840,0.146400,-0.000087,-161.376892,0.000885,0.000000
11.250001,0.744003,-161.332413,-0.004066,0.000015,0.000382,3.309492,0.168594,0.003816,-161.332413,0.001266,0.000000
11.480000,0.830391,-161.421371,-0.004057,0.000029,0.000746,3.693763,0.188169,0.007458,-161.421371,0.001648,0.000000
11.710001,0.962212,-161.421371,-0.004031,0.000045,0.001136,4.280131,0.218040,0.011361,-161.421371,0.002038,0.000000
11.940001,1.129776,-161.465851,-0.004018,0.000061,0.001561,5.025495,0.256011,0.015610,-161.465851,0.002420,0.000000
12.170001,1.244469,-161.421371,-0.004014,0.000075,0.001899,5.535673,0.282001,0.018992,-161.421371,0.002801,0.000000
12.400001,1.361771,-161.465851,-0.004001,0.000087,0.002211,6.057458,0.308582,0.022114,-161.465851,0.003183,0.000000
12.630001,1.447784,-161.332413,-0.003980,0.000101,0.002567,6.440067,0.328073,0.025670,-161.332413,0.003573,0.000000
12.860001,1.760208,-161.465851,-0.003958,0.000127,0.003217,7.829797,0.398869,0.032174,-161.465851,0.003955,0.000000
13.090000,1.837662,-161.554810,-0.003945,0.000137,0.003478,8.174328,0.416420,0.034776,-161.554810,0.004336,0.000000
13.320001,1.897240,-161.554810,-0.003928,0.000149,0.003772,8.439343,0.429921,0.037724,-161.554810,0.004718,0.000000
13.550000,2.076347,-161.510330,-0.003932,0.000167,0.004232,9.236054,0.470507,0.042321,-161.510330,0.005099,0.000000
13.780001,2.185081,-161.599289,-0.003898,0.000181,0.004588,9.719728,0.495147,0.045876,-161.599289,0.005490,0.000000
14.010000,2.364197,-161.599289,-0.003906,0.000196,0.004987,10.516473,0.535735,0.049865,-161.599289,0.005871,0.000000
14.240001,2.447609,-161.643784,-0.003889,0.000208,0.005290,10.887508,0.554636,0.052901,-161.643784,0.006253,0.000000
14.470000,2.592087,-161.599289,-0.003872,0.000224,0.005680,11.530178,0.587375,0.056803,-161.599289,0.006634,0.000000
14.700001,2.704918,-161.554810,-0.003863,0.000237,0.006010,12.032076,0.612943,0.060099,-161.554810,0.007016,0.000000
14.930000,2.943604,-161.643784,-0.003842,0.000259,0.006574,13.093802,0.667030,0.065736,-161.643784,0.007406,0.000000
15.160001,3.009888,-161.643784,-0.003837,0.000271,0.006886,13.388649,0.682050,0.068858,-161.643784,0.007788,0.000000
15.390000,3.098885,-161.643784,-0.003807,0.000286,0.007259,13.784527,0.702217,0.072587,-161.643784,0.008169,0.000000
15.620001,3.217300,-161.732742,-0.003816,0.000300,0.007614,14.311267,0.729051,0.076142,-161.732742,0.008551,0.000000
15.850000,3.371460,-161.643784,-0.003790,0.000319,0.008100,14.997003,0.763984,0.080999,-161.643784,0.008932,0.000000
16.080000,3.439980,-161.732742,-0.003751,0.000332,0.008438,15.301793,0.779510,0.084381,-161.732742,0.009323,0.000000
16.310001,3.418007,-161.777222,-0.003760,0.000340,0.008638,15.204054,0.774531,0.086376,-161.777222,0.009704,0.000000
16.540001,3.610153,-161.732742,-0.003747,0.000356,0.009054,16.058764,0.818072,0.090538,-161.732742,0.010086,0.000000
16.770000,3.717026,-161.732742,-0.003729,0.000374,0.009505,16.534157,0.842290,0.095048,-161.732742,0.010467,0.000000
17.000000,3.883476,-161.732742,-0.003717,0.000393,0.009990,17.274565,0.880008,0.099904,-161.732742,0.010849,0.000000
17.230001,3.881241,-161.821701,-0.003699,0.000406,0.010303,17.264622,0.879502,0.103026,-161.821701,0.011239,0.000000
17.460001,3.929649,-161.777222,-0.003686,0.000420,0.010658,17.479954,0.890471,0.106582,-161.777222,0.011621,0.000000
17.690001,4.040619,-161.910660,-0.003678,0.000435,0.011057,17.973570,0.915617,0.110571,-161.910660,0.012002,0.000000
17.920000,4.178024,-161.821701,-0.003656,0.000453,0.011517,18.584780,0.946754,0.115168,-161.821701,0.012384,0.000000
18.150002,4.145622,-161.910660,-0.003639,0.000463,0.011751,18.440649,0.939411,0.117509,-161.910660,0.012766,0.000000
18.380001,4.264038,-161.910660,-0.003626,0.000479,0.012167,18.967388,0.966245,0.121672,-161.910660,0.013156,0.000000
18.610001,4.317657,-161.910660,-0.003609,0.000492,0.012497,19.205900,0.978395,0.124967,-161.910660,0.013537,0.000000
18.840000,4.510551,-161.910660,-0.003587,0.000513,0.013034,20.063934,1.022106,0.130344,-161.910660,0.013919,0.000000
19.070002,4.563797,-161.910660,-0.003583,0.000529,0.013425,20.300783,1.034171,0.134247,-161.910660,0.014301,0.000000
19.300001,4.534012,-161.910660,-0.003561,0.000541,0.013746,20.168291,1.027422,0.137455,-161.910660,0.014682,0.000000
19.530001,4.515015,-161.955139,-0.003548,0.000551,0.013997,20.083788,1.023117,0.139970,-161.955139,0.015072,0.000000
19.760000,4.718330,-161.955139,-0.003535,0.000572,0.014535,20.988182,1.069189,0.145347,-161.955139,0.015454,0.000000
19.990002,4.759293,-161.955139,-0.003523,0.000585,0.014856,21.170391,1.078471,0.148556,-161.955139,0.015836,0.000000
20.220001,4.812546,-161.955139,-0.003510,0.000600,0.015228,21.407272,1.090538,0.152285,-161.955139,0.016217,0.000000
20.450001,4.906754,-161.999619,-0.003484,0.000618,0.015705,21.826330,1.111886,0.157055,-161.999619,0.016599,0.000000
20.680000,4.916435,-162.044098,-0.003484,0.000629,0.015983,21.869396,1.114080,0.159830,-162.044098,0.016989,0.000000
20.910002,5.069107,-162.044098,-0.003466,0.000649,0.016477,22.548513,1.148676,0.164773,-162.044098,0.017371,0.000000
21.140001,5.059052,-162.088593,-0.003449,0.000663,0.016842,22.503784,1.146397,0.168415,-162.088593,0.017752,0.000000
21.370001,5.057190,-162.044098,-0.003432,0.000677,0.017188,22.495504,1.145976,0.171884,-162.044098,0.018134,0.000000
21.600000,5.093681,-162.088593,-0.003423,0.000692,0.017579,22.657825,1.154245,0.175787,-162.088593,0.018524,0.000000
21.830002,5.221039,-162.088593,-0.003406,0.000707,0.017952,23.224340,1.183104,0.179516,-162.088593,0.018906,0.000000
22.060001,5.230347,-162.088593,-0.003389,0.000719,0.018264,23.265743,1.185213,0.182638,-162.088593,0.019287,0.000000
22.290001,5.297745,-162.088593,-0.003372,0.000734,0.018645,23.565546,1.200486,0.186454,-162.088593,0.019669,0.000000
22.520000,5.409454,-162.088593,-0.003359,0.000753,0.019131,24.062454,1.225800,0.191310,-162.088593,0.020050,0.000000
22.750002,5.466057,-162.177551,-0.003346,0.000769,0.019530,24.314236,1.238626,0.195299,-162.177551,0.020441,0.000000
22.980001,5.500687,-162.222031,-0.003324,0.000783,0.019894,24.468277,1.246473,0.198942,-162.222031,0.020822,0.000000
23.210001,5.461586,-162.266510,-0.003324,0.000797,0.020250,24.294348,1.237613,0.202497,-162.266510,0.021204,0.000000
23.440001,5.462708,-162.222031,-0.003307,0.000808,0.020519,24.299337,1.237867,0.205186,-162.222031,0.021585,0.000000
23.670002,5.589310,-162.177551,-0.003290,0.000826,0.020970,24.862492,1.266556,0.209695,-162.177551,0.021967,0.000000
23.900002,5.675331,-162.266510,-0.003272,0.000839,0.021308,25.245134,1.286048,0.213077,-162.266510,0.022357,0.000000
24.130001,5.839546,-162.310989,-0.003260,0.000858,0.021802,25.975599,1.323260,0.218021,-162.310989,0.022739,0.000000
24.360001,5.780342,-162.266510,-0.003247,0.000871,0.022132,25.712246,1.309844,0.221316,-162.266510,0.023120,0.000000
24.590002,5.969131,-162.266510,-0.003229,0.000891,0.022626,26.552023,1.352625,0.226259,-162.266510,0.023502,0.000000
24.820002,6.020889,-162.266510,-0.003208,0.000906,0.023016,26.782253,1.364353,0.230162,-162.266510,0.023883,0.000000
25.050001,5.930031,-162.310989,-0.003195,0.000918,0.023311,26.378094,1.343764,0.233110,-162.310989,0.024274,0.000000
25.280001,5.916626,-162.399948,-0.003186,0.000931,0.023658,26.318466,1.340727,0.236579,-162.399948,0.024655,0.000000
25.510002,6.017540,-162.310989,-0.003182,0.000946,0.024031,26.767355,1.363594,0.240308,-162.310989,0.025037,0.000000
25.740002,6.220482,-162.266510,-0.003156,0.000964,0.024490,27.670086,1.409581,0.244905,-162.266510,0.025418,0.000000
25.970001,6.168724,-162.399948,-0.003152,0.000976,0.024785,27.439856,1.397853,0.247853,-162.399948,0.025800,0.000000
26.200001,6.332939,-162.444427,-0.003130,0.000993,0.025228,28.170321,1.435064,0.252276,-162.444427,0.026190,0.000000
26.430000,6.456192,-162.488907,-0.003113,0.001012,0.025705,28.718576,1.462994,0.257046,-162.488907,0.026572,0.000000
26.660002,6.484123,-162.488907,-0.003096,0.001027,0.026077,28.842821,1.469323,0.260775,-162.488907,0.026953,0.000000
26.890001,6.450981,-162.533401,-0.003083,0.001041,0.026450,28.695396,1.461813,0.264504,-162.533401,0.027335,0.000000
27.120001,6.523224,-162.444427,-0.003065,0.001057,0.026849,29.016748,1.478184,0.268493,-162.444427,0.027717,0.000000
27.350000,6.442421,-162.533401,-0.003048,0.001066,0.027083,28.657320,1.459873,0.270835,-162.533401,0.028107,0.000000
27.580002,6.724304,-162.622360,-0.003040,0.001087,0.027621,29.911200,1.523749,0.276211,-162.622360,0.028488,0.000000
27.810001,6.642754,-162.488907,-0.003035,0.001096,0.027847,29.548443,1.505270,0.278466,-162.488907,0.028870,0.000000
28.040001,6.758186,-162.533401,-0.003018,0.001114,0.028298,30.061914,1.531427,0.282976,-162.533401,0.029252,0.000000
28.270000,6.947357,-162.577881,-0.002988,0.001132,0.028749,30.903389,1.574294,0.287485,-162.577881,0.029633,0.000000
28.500002,6.850914,-162.622360,-0.002979,0.001144,0.029061,30.474388,1.552439,0.290607,-162.622360,0.030023,0.000000
28.730001,6.949593,-162.622360,-0.002979,0.001157,0.029390,30.913332,1.574800,0.293903,-162.622360,0.030405,0.000000
28.960001,7.068375,-162.622360,-0.002975,0.001175,0.029833,31.441700,1.601717,0.298326,-162.622360,0.030787,0.000000
29.190001,7.158119,-162.622360,-0.002940,0.001190,0.030214,31.840904,1.622053,0.302141,-162.622360,0.031168,0.000000
29.420002,7.186790,-162.577881,-0.002919,0.001203,0.030561,31.968441,1.628550,0.305610,-162.577881,0.031558,0.000000
29.650002,7.319351,-162.666840,-0.002910,0.001221,0.031012,32.558102,1.658589,0.310120,-162.666840,0.031940,0.000000
29.880001,7.394203,-162.755798,-0.002897,0.001236,0.031394,32.891060,1.675550,0.313936,-162.755798,0.032322,0.000000
30.110001,7.367393,-162.711319,-0.002889,0.001248,0.031688,32.771805,1.669475,0.316884,-162.711319,0.032703,0.000000
30.340002,7.516708,-162.577881,-0.002871,0.001265,0.032131,33.435989,1.703310,0.321307,-162.577881,0.033085,0.000000
30.570002,7.696938,-162.755798,-0.002859,0.001282,0.032564,34.237690,1.744151,0.325643,-162.755798,0.033475,0.000000
30.800001,7.512245,-162.711319,-0.002841,0.001291,0.032781,33.416134,1.702299,0.327811,-162.711319,0.033856,0.000000
31.030001,7.894295,-162.800278,-0.002824,0.001314,0.033380,35.115578,1.788873,0.333795,-162.800278,0.034238,0.000000
31.260002,7.820198,-162.755798,-0.002807,0.001327,0.033700,34.785976,1.772082,0.337004,-162.755798,0.034620,0.000000
31.490002,7.956482,-162.755798,-0.002798,0.001344,0.034134,35.392200,1.802965,0.341340,-162.755798,0.035001,0.000000
31.720001,7.868973,-162.711319,-0.002772,0.001353,0.034377,35.002937,1.783135,0.343768,-162.711319,0.035391,0.000000
31.950001,8.169479,-162.844757,-0.002764,0.001374,0.034888,36.339661,1.851231,0.348885,-162.844757,0.035773,0.000000
32.180000,8.278961,-162.844757,-0.002759,0.001392,0.035357,36.826660,1.876040,0.353568,-162.844757,0.036155,0.000000
32.410000,8.301674,-162.844757,-0.002729,0.001405,0.035686,36.927689,1.881186,0.356863,-162.844757,0.036536,0.000000
32.640003,8.272629,-162.844757,-0.002721,0.001416,0.035973,36.798492,1.874605,0.359725,-162.844757,0.036918,0.000000
32.870003,8.386574,-162.889236,-0.002703,0.001434,0.036415,37.305344,1.900425,0.364148,-162.889236,0.037308,0.000000
33.100002,8.494560,-162.933731,-0.002695,0.001449,0.036814,37.785690,1.924895,0.368137,-162.933731,0.037690,0.000000
33.330002,8.661011,-162.933731,-0.002669,0.001466,0.037247,38.526100,1.962613,0.372473,-162.933731,0.038071,0.000000
33.560001,8.674049,-162.933731,-0.002660,0.001478,0.037551,38.584099,1.965568,0.375509,-162.933731,0.038453,0.000000
33.790001,8.640160,-162.933731,-0.002656,0.001488,0.037794,38.433350,1.957888,0.377937,-162.933731,0.038834,0.000000
34.020000,8.437592,-162.933731,-0.002643,0.001491,0.037880,37.532280,1.911986,0.378804,-162.933731,0.039225,0.000000
34.250000,9.330536,-163.067169,-0.002630,0.001530,0.038860,41.504295,2.114330,0.388604,-163.067169,0.039606,0.000000
34.480003,9.135788,-162.978210,-0.002613,0.001539,0.039086,40.638016,2.070199,0.390859,-162.978210,0.039988,0.000000
34.710003,9.209892,-162.933731,-0.002583,0.001556,0.039528,40.967648,2.086992,0.395281,-162.933731,0.040369,0.000000
34.940002,9.230370,-163.022690,-0.002570,0.001569,0.039840,41.058735,2.091632,0.398403,-163.022690,0.040751,0.000000
35.170002,9.439644,-163.111649,-0.002552,0.001586,0.040274,41.989632,2.139054,0.402740,-163.111649,0.041141,0.000000
35.400002,9.361816,-163.022690,-0.002548,0.001597,0.040569,41.643440,2.121418,0.405688,-163.022690,0.041523,0.000000
35.630001,9.312294,-163.111649,-0.002539,0.001605,0.040777,41.423153,2.110196,0.407770,-163.111649,0.041904,0.000000
35.860001,9.607208,-163.067169,-0.002531,0.001625,0.041271,42.734997,2.177024,0.412713,-163.067169,0.042286,0.000000
36.090000,9.875694,-163.111649,-0.002505,0.001643,0.041722,43.929283,2.237864,0.417222,-163.111649,0.042668,0.000000
36.320004,10.211571,-163.156128,-0.002496,0.001662,0.042225,45.423336,2.313975,0.422252,-163.156128,0.043058,0.000000
36.550003,10.050705,-163.156128,-0.002483,0.001672,0.042477,44.707767,2.277522,0.424767,-163.156128,0.043439,0.000000
36.780003,10.153481,-163.156128,-0.002466,0.001688,0.042884,45.164936,2.300812,0.428843,-163.156128,0.043821,0.000000
37.010002,10.158325,-163.111649,-0.002466,0.001703,0.043257,45.186489,2.301909,0.432572,-163.111649,0.044202,0.000000
37.240002,10.478188,-163.111649,-0.002436,0.001721,0.043708,46.609306,2.374391,0.437082,-163.111649,0.044584,0.000000
37.470001,10.383232,-163.200607,-0.002432,0.001731,0.043968,46.186924,2.352874,0.439683,-163.200607,0.044974,0.000000
37.700001,10.413399,-163.245087,-0.002423,0.001743,0.044272,46.321110,2.359710,0.442719,-163.245087,0.045356,0.000000
37.930000,10.614105,-163.200607,-0.002410,0.001760,0.044714,47.213898,2.405190,0.447142,-163.200607,0.045737,0.000000
38.160004,10.986107,-163.245087,-0.002389,0.001780,0.045208,48.868645,2.489487,0.452085,-163.245087,0.046119,0.000000
38.390003,11.104897,-163.245087,-0.002367,0.001795,0.045599,49.397045,2.516406,0.455987,-163.245087,0.046509,0.000000
38.620003,11.202454,-163.289566,-0.002354,0.001811,0.046006,49.831001,2.538512,0.460063,-163.289566,0.046891,0.000000
38.850002,11.047173,-163.289566,-0.002341,0.001820,0.046240,49.140278,2.503325,0.462405,-163.289566,0.047272,0.000000
39.080002,11.456039,-163.289566,-0.002324,0.001840,0.046735,50.959007,2.595976,0.467348,-163.289566,0.047654,0.000000
39.310001,11.602386,-163.334045,-0.002311,0.001855,0.047125,51.609993,2.629138,0.471250,-163.334045,0.048036,0.000000
39.540001,11.459763,-163.334045,-0.002302,0.001866,0.047385,50.975571,2.596819,0.473852,-163.334045,0.048426,0.000000
39.770000,11.783356,-163.423019,-0.002289,0.001882,0.047793,52.414986,2.670146,0.477928,-163.423019,0.048807,0.000000
40.000000,12.058540,-163.378540,-0.002276,0.001901,0.048287,53.639065,2.732504,0.482871,-163.378540,0.049189,0.000000
40.230003,12.205254,-163.378540,-0.002259,0.001917,0.048686,54.291679,2.765750,0.486861,-163.378540,0.049571,0.000000
40.460003,12.324043,-163.423019,-0.002238,0.001932,0.049085,54.820084,2.792668,0.490850,-163.423019,0.049952,0.000000
40.690002,12.347504,-163.423019,-0.002225,0.001945,0.049415,54.924438,2.797984,0.494145,-163.423019,0.050342,0.000000
40.920002,12.408943,-163.423019,-0.002220,0.001961,0.049813,55.197735,2.811907,0.498134,-163.423019,0.050724,0.000000
41.150002,12.796211,-163.423019,-0.002212,0.001976,0.050195,56.920391,2.899663,0.501950,-163.423019,0.051106,0.000000
41.380001,12.594383,-163.511978,-0.002190,0.001983,0.050377,56.022614,2.853928,0.503771,-163.511978,0.051487,0.000000
41.610001,13.066925,-163.511978,-0.002177,0.002005,0.050923,58.124584,2.961007,0.509235,-163.511978,0.051869,0.000000
41.840000,13.240074,-163.467499,-0.002173,0.002019,0.051279,58.894791,3.000244,0.512791,-163.467499,0.052259,0.000000
42.070004,13.288857,-163.556458,-0.002139,0.002034,0.051661,59.111786,3.011298,0.516606,-163.556458,0.052641,0.000000
42.300003,13.717087,-163.511978,-0.002143,0.002055,0.052190,61.016651,3.108336,0.521896,-163.511978,0.053022,0.000000
42.530003,13.713364,-163.600937,-0.002126,0.002067,0.052511,61.000088,3.107493,0.525105,-163.600937,0.053404,0.000000
42.760002,13.679474,-163.556458,-0.002113,0.002079,0.052797,60.849339,3.099813,0.527967,-163.556458,0.053785,0.000000
42.990002,13.943115,-163.556458,-0.002095,0.002094,0.053178,62.022076,3.159555,0.531783,-163.556458,0.054176,0.000000
43.220001,14.083130,-163.645416,-0.002091,0.002107,0.053525,62.644890,3.191283,0.535252,-163.645416,0.054557,0.000000
43.450001,14.304314,-163.689896,-0.002074,0.002123,0.053915,63.628765,3.241404,0.539154,-163.689896,0.054939,0.000000
43.680000,14.517311,-163.645416,-0.002065,0.002139,0.054323,64.576225,3.289670,0.543230,-163.645416,0.055320,0.000000
43.910004,14.910912,-163.600937,-0.002039,0.002156,0.054774,66.327049,3.378861,0.547740,-163.600937,0.055702,0.000000
44.140003,15.214020,-163.734375,-0.002018,0.002174,0.055216,67.675339,3.447546,0.552163,-163.734375,0.056092,0.000000
44.370003,15.076614,-163.689896,-0.002005,0.002183,0.055459,67.064133,3.416409,0.554591,-163.689896,0.056474,0.000000
44.600002,15.261688,-163.734375,-0.002009,0.002199,0.055858,67.887383,3.458348,0.558580,-163.734375,0.056855,0.000000
44.830002,15.238228,-163.734375,-0.001988,0.002210,0.056144,67.783020,3.453032,0.561442,-163.734375,0.057237,0.000000
45.060001,15.897697,-163.734375,-0.001975,0.002230,0.056647,70.716492,3.602470,0.566472,-163.734375,0.057618,0.000000
45.290001,15.869026,-163.734375,-0.001957,0.002244,0.056985,70.588951,3.595973,0.569854,-163.734375,0.058009,0.000000
45.520000,16.228363,-163.778854,-0.001953,0.002259,0.057384,72.187363,3.677400,0.573843,-163.778854,0.058390,0.000000
45.750004,16.407104,-163.778854,-0.001940,0.002273,0.057731,72.982445,3.717903,0.577312,-163.778854,0.058772,0.000000
45.980003,16.936249,-163.823349,-0.001919,0.002293,0.058243,75.336197,3.837809,0.582429,-163.823349,0.059153,0.000000
46.210003,17.089294,-163.778854,-0.001906,0.002307,0.058598,76.016975,3.872490,0.585984,-163.778854,0.059535,0.000000
46.440002,17.058014,-163.823349,-0.001880,0.002319,0.058911,75.877838,3.865401,0.589106,-163.823349,0.059925,0.000000
46.670002,17.192810,-163.867828,-0.001871,0.002333,0.059258,76.477440,3.895947,0.592575,-163.867828,0.060307,0.000000
46.900002,17.313087,-163.867828,-0.001876,0.002347,0.059613,77.012459,3.923202,0.596131,-163.867828,0.060688,0.000000
47.130001,18.068634,-163.867828,-0.001850,0.002365,0.060081,80.373299,4.094411,0.600814,-163.867828,0.061070,0.000000
47.360001,17.986710,-163.823349,-0.001837,0.002376,0.060342,80.008881,4.075847,0.603416,-163.823349,0.061460,0.000000
47.590004,18.532234,-163.912308,-0.001832,0.002397,0.060879,82.435493,4.199464,0.608792,-163.912308,0.061842,0.000000
47.820004,19.158195,-163.956787,-0.001815,0.002417,0.061382,85.219910,4.341309,0.613822,-163.956787,0.062223,0.000000
48.050003,19.067703,-163.956787,-0.001802,0.002429,0.061694,84.817383,4.320803,0.616944,-163.956787,0.062605,0.000000
48.280003,19.330231,-164.001266,-0.001802,0.002445,0.062093,85.985161,4.380293,0.620934,-164.001266,0.062987,0.000000
48.510002,19.462051,-163.912308,-0.001763,0.002457,0.062397,86.571526,4.410164,0.623969,-163.912308,0.063377,0.000000
48.740002,19.333954,-164.001266,-0.001763,0.002467,0.062657,86.001724,4.381136,0.626571,-164.001266,0.063758,0.000000
48.970001,20.318878,-164.001266,-0.001746,0.002489,0.063221,90.382881,4.604323,0.632208,-164.001266,0.064140,0.000000
49.200001,20.319252,-164.001266,-0.001733,0.002501,0.063524,90.384544,4.604408,0.635243,-164.001266,0.064522,0.000000
49.430004,20.865891,-163.956787,-0.001729,0.002517,0.063941,92.816116,4.728278,0.639405,-163.956787,0.064903,0.000000
49.660004,21.249435,-164.001266,-0.001699,0.002535,0.064392,94.522209,4.815191,0.643915,-164.001266,0.065293,0.000000
49.890003,21.508606,-164.045746,-0.001707,0.002548,0.064712,95.675056,4.873919,0.647124,-164.045746,0.065675,0.000000
50.120003,21.291885,-164.045746,-0.001686,0.002555,0.064903,94.711037,4.824811,0.649032,-164.045746,0.066057,0.000000
50.350002,22.029930,-164.090225,-0.001669,0.002577,0.065450,97.994026,4.992054,0.654495,-164.090225,0.066438,0.000000
50.580002,22.418686,-164.045746,-0.001656,0.002592,0.065848,99.723297,5.080147,0.658484,-164.045746,0.066820,0.000000
50.810001,22.973892,-164.134705,-0.001638,0.002611,0.066317,102.192978,5.205958,0.663168,-164.134705,0.067210,0.000000
51.040001,23.123589,-164.134705,-0.001634,0.002624,0.066646,102.858856,5.239880,0.666463,-164.134705,0.067592,0.000000
51.270004,23.346268,-164.179184,-0.001621,0.002637,0.066985,103.849388,5.290340,0.669845,-164.179184,0.067973,0.000000
51.500004,23.818062,-164.179184,-0.001613,0.002655,0.067427,105.948029,5.397250,0.674268,-164.179184,0.068355,0.000000
51.730003,24.561317,-164.179184,-0.001595,0.002674,0.067930,109.254196,5.565674,0.679298,-164.179184,0.068736,0.000000
51.960003,24.491684,-164.179184,-0.001582,0.002683,0.068147,108.944450,5.549895,0.681466,-164.179184,0.069127,0.000000
52.190002,24.665581,-164.223679,-0.001565,0.002699,0.068546,109.717979,5.589300,0.685455,-164.223679,0.069508,0.000000
52.420002,25.470650,-164.268158,-0.001561,0.002716,0.068996,113.299110,5.771732,0.689965,-164.268158,0.069890,0.000000
52.650002,26.098099,-164.179184,-0.001548,0.002735,0.069465,116.090141,5.913914,0.694648,-164.179184,0.070271,0.000000
52.880001,26.211670,-164.179184,-0.001522,0.002745,0.069734,116.595329,5.939650,0.697336,-164.179184,0.070653,0.000000
53.110004,26.175926,-164.223679,-0.001522,0.002756,0.070011,116.436333,5.931550,0.700111,-164.223679,0.071043,0.000000
53.340004,27.120636,-164.312637,-0.001505,0.002775,0.070488,120.638611,6.145624,0.704881,-164.312637,0.071425,0.000000
53.570004,28.011719,-164.268158,-0.001496,0.002797,0.071043,124.602348,6.347546,0.710431,-164.268158,0.071806,0.000000
53.800003,28.091034,-164.312637,-0.001483,0.002810,0.071364,124.955162,6.365519,0.713640,-164.312637,0.072188,0.000000
54.030003,28.320045,-164.223679,-0.001470,0.002822,0.071676,125.973854,6.417414,0.716762,-164.223679,0.072569,0.000000
54.260002,28.681992,-164.357117,-0.001457,0.002835,0.072014,127.583870,6.499432,0.720144,-164.357117,0.072960,0.000000
54.490002,29.404396,-164.401596,-0.001440,0.002855,0.072517,130.797287,6.663131,0.725174,-164.401596,0.073341,0.000000
54.720001,29.789055,-164.357117,-0.001431,0.002868,0.072847,132.508331,6.750296,0.728470,-164.357117,0.073723,0.000000
54.950001,30.013969,-164.357117,-0.001431,0.002879,0.073124,133.508804,6.801263,0.731245,-164.357117,0.074104,0.000000
55.180004,30.073921,-164.357117,-0.001414,0.002890,0.073393,133.775482,6.814848,0.733933,-164.357117,0.074486,0.000000
55.410004,30.918457,-164.401596,-0.001401,0.002908,0.073870,137.532166,7.006223,0.738703,-164.401596,0.074876,0.000000
55.640003,32.296982,-164.401596,-0.001375,0.002931,0.074443,143.664154,7.318601,0.744426,-164.401596,0.075258,0.000000
55.870003,32.251923,-164.446075,-0.001375,0.002941,0.074694,143.463715,7.308390,0.746941,-164.446075,0.075639,0.000000
56.100002,32.826126,-164.446075,-0.001367,0.002958,0.075128,146.017899,7.438507,0.751278,-164.446075,0.076021,0.000000
56.330002,33.045082,-164.446075,-0.001345,0.002969,0.075423,146.991867,7.488123,0.754226,-164.446075,0.076411,0.000000
56.560001,33.822220,-164.490555,-0.001341,0.002988,0.075900,150.448746,7.664225,0.758996,-164.490555,0.076793,0.000000
56.790001,34.093307,-164.535034,-0.001332,0.002999,0.076186,151.654602,7.725654,0.761858,-164.535034,0.077174,0.000000
57.020004,34.370354,-164.490555,-0.001319,0.003010,0.076455,152.886963,7.788434,0.764546,-164.490555,0.077556,0.000000
57.250004,35.138184,-164.490555,-0.001311,0.003028,0.076906,156.302444,7.962426,0.769056,-164.490555,0.077938,0.000000
57.480003,35.795792,-164.535034,-0.001302,0.003041,0.077244,159.227631,8.111443,0.772438,-164.535034,0.078328,0.000000
57.710003,36.967278,-164.579514,-0.001281,0.003064,0.077825,164.438660,8.376904,0.778248,-164.579514,0.078709,0.000000
57.940002,37.110268,-164.579514,-0.001285,0.003075,0.078111,165.074722,8.409307,0.781110,-164.579514,0.079091,0.000000
58.170002,37.809212,-164.668488,-0.001272,0.003090,0.078493,168.183777,8.567690,0.784926,-164.668488,0.079473,0.000000
58.400002,38.612045,-164.579514,-0.001268,0.003109,0.078961,171.754959,8.749614,0.789609,-164.579514,0.079854,0.000000
58.630001,39.173958,-164.579514,-0.001259,0.003123,0.079316,174.254471,8.876946,0.793165,-164.579514,0.080244,0.000000
58.860004,39.545586,-164.623993,-0.001233,0.003134,0.079611,175.907547,8.961158,0.796113,-164.623993,0.080626,0.000000
59.090004,39.676285,-164.623993,-0.001229,0.003147,0.079932,176.488922,8.990775,0.799322,-164.623993,0.081008,0.000000
59.320004,40.804947,-164.623993,-0.001229,0.003165,0.080400,181.509476,9.246532,0.804005,-164.623993,0.081389,0.000000
59.550003,41.729919,-164.668488,-0.001220,0.003182,0.080834,185.623947,9.456136,0.808341,-164.668488,0.081771,0.000000
59.780003,42.313805,-164.668488,-0.001199,0.003196,0.081181,188.221207,9.588445,0.811810,-164.668488,0.082161,0.000000
60.010002,43.065994,-164.757446,-0.001190,0.003211,0.081571,191.567108,9.758894,0.815713,-164.757446,0.082543,0.000000
60.240002,43.357559,-164.757446,-0.001186,0.003223,0.081857,192.864059,9.824963,0.818574,-164.757446,0.082924,0.000000
60.470001,44.617668,-164.757446,-0.001190,0.003244,0.082404,198.469299,10.110508,0.824038,-164.757446,0.083306,0.000000
60.700005,45.102127,-164.757446,-0.001173,0.003256,0.082707,200.624283,10.220288,0.827073,-164.757446,0.083687,0.000000
60.930004,45.358322,-164.757446,-0.001160,0.003266,0.082967,201.763901,10.278342,0.829675,-164.757446,0.084078,0.000000
61.160004,46.403572,-164.757446,-0.001151,0.003285,0.083427,206.413391,10.515200,0.834271,-164.757446,0.084459,0.000000
61.390003,47.602608,-164.846405,-0.001138,0.003303,0.083887,211.746979,10.786905,0.838867,-164.846405,0.084841,0.000000
61.620003,48.409164,-164.801926,-0.001130,0.003318,0.084286,215.334717,10.969674,0.842857,-164.801926,0.085222,0.000000
61.850002,49.131569,-164.801926,-0.001112,0.003334,0.084676,218.548126,11.133373,0.846759,-164.801926,0.085604,0.000000
62.080002,49.527771,-164.846405,-0.001104,0.003345,0.084962,220.310532,11.223153,0.849621,-164.846405,0.085994,0.000000
62.310001,50.403221,-164.890884,-0.001099,0.003361,0.085370,224.204727,11.421534,0.853697,-164.890884,0.086376,0.000000
62.540005,51.249992,-164.935364,-0.001087,0.003375,0.085734,227.971359,11.613414,0.857339,-164.935364,0.086757,0.000000
62.770004,51.546402,-164.846405,-0.001078,0.003387,0.086020,229.289841,11.680581,0.860201,-164.846405,0.087139,0.000000
63.000004,52.930138,-164.935364,-0.001087,0.003406,0.086514,235.445007,11.994141,0.865144,-164.935364,0.087520,0.000000
63.230003,53.555351,-164.935364,-0.001061,0.003418,0.086809,238.226105,12.135816,0.868093,-164.935364,0.087911,0.000000
63.460003,54.549957,-164.979843,-0.001052,0.003438,0.087321,242.650330,12.361197,0.873210,-164.979843,0.088292,0.000000
63.690002,55.825706,-164.979843,-0.001056,0.003454,0.087729,248.325150,12.650286,0.877286,-164.979843,0.088674,0.000000
63.920002,56.487785,-165.024323,-0.001043,0.003469,0.088110,251.270218,12.800316,0.881101,-165.024323,0.089055,0.000000
64.150002,56.908569,-164.979843,-0.001022,0.003481,0.088414,253.141953,12.895666,0.884137,-164.979843,0.089437,0.000000
64.380005,57.881577,-165.024323,-0.001030,0.003496,0.088795,257.470123,13.116153,0.887952,-165.024323,0.089827,0.000000
64.610001,58.756653,-165.024323,-0.001022,0.003510,0.089151,261.362640,13.314447,0.891508,-165.024323,0.090209,0.000000
64.840004,59.537514,-165.068802,-0.001009,0.003525,0.089532,264.836090,13.491393,0.895324,-165.068802,0.090590,0.000000
65.070000,60.637131,-165.068802,-0.001000,0.003540,0.089923,269.727417,13.740570,0.899226,-165.068802,0.090972,0.000000
65.300003,61.623550,-165.024323,-0.001000,0.003556,0.090330,274.115234,13.964096,0.903302,-165.024323,0.091362,0.000000
65.530006,62.847534,-165.113297,-0.000987,0.003574,0.090790,279.559784,14.241454,0.907899,-165.113297,0.091744,0.000000
65.760002,63.603447,-165.068802,-0.000974,0.003589,0.091154,282.922272,14.412747,0.911541,-165.068802,0.092125,0.000000
65.990005,64.268883,-165.113297,-0.000966,0.003600,0.091449,285.882263,14.563537,0.914490,-165.113297,0.092507,0.000000
66.220001,64.824089,-165.113297,-0.000974,0.003613,0.091761,288.351959,14.689349,0.917611,-165.113297,0.092889,0.000000
66.450005,66.471458,-165.157776,-0.000961,0.003632,0.092255,295.679810,15.062648,0.922555,-165.157776,0.093279,0.000000
66.680000,67.222542,-165.157776,-0.000944,0.003645,0.092594,299.020813,15.232845,0.925937,-165.157776,0.093660,0.000000
66.910004,67.103004,-165.202255,-0.000940,0.003639,0.092429,298.489075,15.205758,0.924289,-165.202255,0.092689,0.000000
67.139999,66.513542,-165.246735,-0.000931,0.003639,0.092429,295.867004,15.072184,0.924289,-165.246735,0.092429,0.000000
67.370003,65.974724,-165.246735,-0.000944,0.003638,0.092394,293.470215,14.950087,0.923942,-165.246735,0.092429,0.000000
67.600006,65.507027,-165.291214,-0.000927,0.003637,0.092386,291.389801,14.844105,0.923855,-165.291214,0.092429,0.000000
67.830002,65.090706,-165.246735,-0.000923,0.003637,0.092386,289.537933,14.749764,0.923855,-165.246735,0.092429,0.000000
68.060005,64.730629,-165.335693,-0.000918,0.003637,0.092377,287.936218,14.668170,0.923769,-165.335693,0.092429,0.000000
68.290001,64.407784,-165.335693,-0.000918,0.003637,0.092377,286.500122,14.595013,0.923769,-165.335693,0.092429,0.000000
68.520004,64.096474,-165.291214,-0.000923,0.003637,0.092368,285.115356,14.524468,0.923682,-165.291214,0.092429,0.000000
68.750000,63.801933,-165.246735,-0.000923,0.003637,0.092368,283.805176,14.457725,0.923682,-165.246735,0.092429,0.000000
68.980003,63.542381,-165.335693,-0.000914,0.003637,0.092368,282.650635,14.398910,0.923682,-165.335693,0.092429,0.000000
69.210007,63.309273,-165.424652,-0.000914,0.003637,0.092368,281.613708,14.346086,0.923682,-165.424652,0.092429,0.000000
69.440002,63.091438,-165.335693,-0.000901,0.003637,0.092368,280.644745,14.296724,0.923682,-165.335693,0.092429,0.000000
69.670006,62.896690,-165.380173,-0.000918,0.003636,0.092360,279.778442,14.252594,0.923595,-165.380173,0.092429,0.000000
69.900002,62.684807,-165.380173,-0.000914,0.003636,0.092360,278.835937,14.204580,0.923595,-165.380173,0.092429,0.000000
70.130005,62.506073,-165.380173,-0.000901,0.003636,0.092360,278.040894,14.164079,0.923595,-165.380173,0.092429,0.000000
70.360001,62.331429,-165.424652,-0.000914,0.003636,0.092360,277.264038,14.124504,0.923595,-165.424652,0.092429,0.000000
70.590004,62.171677,-165.469131,-0.000910,0.003636,0.092360,276.553436,14.088304,0.923595,-165.469131,0.092429,0.000000
70.820000,62.032410,-165.513626,-0.000910,0.003636,0.092360,275.933929,14.056746,0.923595,-165.513626,0.092429,0.000000
71.050003,61.886818,-165.424652,-0.000905,0.003636,0.092360,275.286316,14.023753,0.923595,-165.424652,0.092429,0.000000
71.280006,61.745689,-165.469131,-0.000910,0.003636,0.092360,274.658539,13.991774,0.923595,-165.469131,0.092429,0.000000
71.510002,61.594879,-165.513626,-0.000901,0.003636,0.092360,273.987701,13.957599,0.923595,-165.513626,0.092429,0.000000
71.740005,61.469383,-165.558105,-0.000910,0.003636,0.092360,273.429474,13.929162,0.923595,-165.558105,0.092429,0.000000
71.970001,61.371452,-165.513626,-0.000897,0.003636,0.092360,272.993866,13.906969,0.923595,-165.513626,0.092429,0.000000
72.200005,61.254158,-165.513626,-0.000897,0.003636,0.092360,272.472107,13.880390,0.923595,-165.513626,0.092429,0.000000
72.430000,61.144676,-165.558105,-0.000905,0.003636,0.092360,271.985107,13.855582,0.923595,-165.558105,0.092429,0.000000
72.660004,61.040787,-165.558105,-0.000897,0.003636,0.092360,271.522980,13.832040,0.923595,-165.558105,0.092429,0.000000
72.890007,60.922745,-165.691544,-0.000892,0.003636,0.092360,270.997894,13.805291,0.923595,-165.691544,0.092429,0.000000
73.120003,60.831139,-165.558105,-0.000897,0.003636,0.092360,270.590424,13.784534,0.923595,-165.558105,0.092429,0.000000
73.350006,60.730972,-165.558105,-0.000892,0.003636,0.092360,270.144867,13.761835,0.923595,-165.558105,0.092429,0.000000
73.580002,60.649048,-165.647064,-0.000892,0.003636,0.092360,269.780426,13.743270,0.923595,-165.647064,0.092429,0.000000
73.810005,60.564522,-165.647064,-0.000897,0.003636,0.092360,269.404449,13.724116,0.923595,-165.647064,0.092429,0.000000
74.040001,60.480362,-165.736023,-0.000897,0.003636,0.092360,269.030090,13.705046,0.923595,-165.736023,0.092429,0.000000
74.270004,60.386528,-165.691544,-0.000892,0.003636,0.092360,268.612701,13.683783,0.923595,-165.691544,0.092429,0.000000
74.500000,60.309814,-165.691544,-0.000884,0.003636,0.092360,268.271454,13.666399,0.923595,-165.691544,0.092429,0.000000
74.730003,60.218590,-165.691544,-0.000884,0.003636,0.092360,267.865662,13.645727,0.923595,-165.691544,0.092429,0.000000
74.960007,60.154167,-165.736023,-0.000897,0.003636,0.092360,267.579102,13.631129,0.923595,-165.736023,0.092429,0.000000
75.190002,60.076340,-165.824982,-0.000897,0.003636,0.092360,267.232910,13.613494,0.923595,-165.824982,0.092429,0.000000
75.420006,60.017136,-165.824982,-0.000897,0.003636,0.092360,266.969543,13.600078,0.923595,-165.824982,0.092429,0.000000
75.650002,59.948990,-165.736023,-0.000888,0.003636,0.092360,266.666412,13.584635,0.923595,-165.736023,0.092429,0.000000
75.880005,59.879730,-165.824982,-0.000875,0.003636,0.092360,266.358337,13.568941,0.923595,-165.824982,0.092429,0.000000
76.110001,59.819405,-165.824982,-0.000880,0.003636,0.092360,266.089996,13.555271,0.923595,-165.824982,0.092429,0.000000
76.340004,59.749397,-165.824982,-0.000901,0.003636,0.092360,265.778595,13.539408,0.923595,-165.824982,0.092429,0.000000
76.570007,59.687584,-165.824982,-0.000897,0.003636,0.092360,265.503632,13.525400,0.923595,-165.824982,0.092429,0.000000
76.800003,59.625397,-165.869461,-0.000884,0.003636,0.092360,265.227020,13.511308,0.923595,-165.869461,0.092429,0.000000
77.030006,59.581085,-165.869461,-0.000888,0.003636,0.092360,265.029907,13.501267,0.923595,-165.869461,0.092429,0.000000
77.260002,59.517784,-165.913940,-0.000884,0.003636,0.092360,264.748322,13.486923,0.923595,-165.913940,0.092429,0.000000
77.490005,59.452988,-165.913940,-0.000880,0.003636,0.092360,264.460083,13.472239,0.923595,-165.913940,0.092429,0.000000
77.720001,59.397133,-165.913940,-0.000880,0.003636,0.092360,264.211639,13.459582,0.923595,-165.913940,0.092429,0.000000
77.950005,59.340530,-165.913940,-0.000884,0.003636,0.092360,263.959869,13.446756,0.923595,-165.913940,0.092429,0.000000
78.180000,59.297707,-165.869461,-0.000884,0.003636,0.092360,263.769379,13.437053,0.923595,-165.869461,0.092429,0.000000
78.410004,59.250793,-166.047394,-0.000888,0.003636,0.092360,263.560699,13.426422,0.923595,-166.047394,0.092429,0.000000
78.640007,59.203873,-166.002914,-0.000880,0.003636,0.092360,263.351990,13.415790,0.923595,-166.002914,0.092429,0.000000
78.870003,59.142799,-166.047394,-0.000884,0.003636,0.092360,263.080322,13.401950,0.923595,-166.047394,0.092429,0.000000
79.100006,59.097748,-166.002914,-0.000871,0.003636,0.092360,262.879913,13.391742,0.923595,-166.002914,0.092429,0.000000
79.330002,59.050453,-166.002914,-0.000871,0.003636,0.092360,262.669525,13.381024,0.923595,-166.002914,0.092429,0.000000
79.560005,59.008377,-166.047394,-0.000867,0.003636,0.092360,262.482361,13.371490,0.923595,-166.047394,0.092429,0.000000
79.790001,58.958107,-166.047394,-0.000875,0.003636,0.092360,262.258759,13.360098,0.923595,-166.047394,0.092429,0.000000
80.020004,58.914536,-166.091873,-0.000880,0.003636,0.092360,262.064941,13.350225,0.923595,-166.091873,0.092429,0.000000
80.250000,58.879906,-166.047394,-0.000871,0.003636,0.092360,261.910889,13.342378,0.923595,-166.047394,0.092429,0.000000
80.480003,58.844162,-166.047394,-0.000875,0.003636,0.092360,261.751892,13.334278,0.923595,-166.047394,0.092429,0.000000
80.710007,58.795006,-166.091873,-0.000875,0.003636,0.092360,261.533234,13.323138,0.923595,-166.091873,0.092429,0.000000
80.940002,58.748459,-166.180832,-0.000884,0.003636,0.092360,261.326202,13.312592,0.923595,-166.180832,0.092429,0.000000
81.170006,58.706757,-166.180832,-0.000875,0.003636,0.092360,261.140686,13.303142,0.923595,-166.180832,0.092429,0.000000
81.400002,58.659462,-166.091873,-0.000880,0.003636,0.092360,260.930328,13.292423,0.923595,-166.091873,0.092429,0.000000
81.630005,58.612541,-166.136353,-0.000871,0.003636,0.092360,260.721619,13.281792,0.923595,-166.136353,0.092429,0.000000
81.860001,58.589828,-166.269791,-0.000871,0.003636,0.092360,260.620575,13.276646,0.923595,-166.269791,0.092429,0.000000
82.090004,58.551102,-166.269791,-0.000880,0.003636,0.092360,260.448303,13.267869,0.923595,-166.269791,0.092429,0.000000
82.320007,58.522804,-166.269791,-0.000875,0.003636,0.092360,260.322449,13.261457,0.923595,-166.269791,0.092429,0.000000
82.550003,58.491524,-166.180832,-0.000875,0.003636,0.092360,260.183289,13.254369,0.923595,-166.180832,0.092429,0.000000
82.780006,58.437157,-166.225311,-0.000884,0.003636,0.092360,259.941467,13.242049,0.923595,-166.225311,0.092429,0.000000
83.010002,58.402527,-166.269791,-0.000880,0.003636,0.092360,259.787415,13.234202,0.923595,-166.269791,0.092429,0.000000
83.240005,58.364548,-166.225311,-0.000875,0.003636,0.092360,259.618469,13.225595,0.923595,-166.225311,0.092429,0.000000
83.470001,58.338852,-166.314270,-0.000880,0.003636,0.092360,259.504181,13.219772,0.923595,-166.314270,0.092429,0.000000
83.700005,58.318367,-166.269791,-0.000880,0.003636,0.092360,259.413055,13.215131,0.923595,-166.269791,0.092429,0.000000
83.930000,58.280014,-166.314270,-0.000867,0.003636,0.092360,259.242462,13.206440,0.923595,-166.314270,0.092429,0.000000
84.160004,58.242035,-166.358749,-0.000875,0.003636,0.092360,259.073517,13.197834,0.923595,-166.358749,0.092429,0.000000
84.390007,58.221184,-166.358749,-0.000884,0.003636,0.092360,258.980774,13.193109,0.923595,-166.358749,0.092429,0.000000
84.620003,58.170914,-166.358749,-0.000875,0.003636,0.092360,258.757141,13.181718,0.923595,-166.358749,0.092429,0.000000
84.850006,58.140747,-166.358749,-0.000867,0.003636,0.092351,258.622955,13.174882,0.923509,-166.358749,0.092429,0.000000
85.080002,58.115051,-166.403244,-0.000871,0.003636,0.092351,258.508667,13.169059,0.923509,-166.403244,0.092429,0.000000
85.310005,58.078186,-166.403244,-0.000880,0.003636,0.092351,258.344666,13.160705,0.923509,-166.403244,0.092429,0.000000
85.540001,58.058456,-166.403244,-0.000871,0.003636,0.092351,258.256927,13.156235,0.923509,-166.403244,0.092429,0.000000
85.770004,58.030899,-166.447723,-0.000880,0.003636,0.092351,258.134338,13.149990,0.923509,-166.447723,0.092429,0.000000
86.000008,58.008926,-166.403244,-0.000871,0.003636,0.092351,258.036591,13.145010,0.923509,-166.403244,0.092429,0.000000
86.230003,57.975418,-166.403244,-0.000875,0.003636,0.092351,257.887543,13.137418,0.923509,-166.403244,0.092429,0.000000
86.460007,57.948235,-166.447723,-0.000880,0.003636,0.092351,257.766632,13.131257,0.923509,-166.447723,0.092429,0.000000
86.690002,57.908012,-166.492203,-0.000880,0.003636,0.092351,257.587708,13.122144,0.923509,-166.492203,0.092429,0.000000
86.920006,57.894608,-166.447723,-0.000871,0.003636,0.092351,257.528076,13.119106,0.923509,-166.447723,0.092429,0.000000
87.150002,57.875618,-166.536682,-0.000871,0.003636,0.092351,257.443604,13.114802,0.923509,-166.536682,0.092429,0.000000
87.380005,57.832794,-166.581161,-0.000880,0.003636,0.092351,257.253113,13.105099,0.923509,-166.581161,0.092429,0.000000
87.610001,57.811195,-166.581161,-0.000875,0.003636,0.092351,257.157043,13.100204,0.923509,-166.581161,0.092429,0.000000
87.840004,57.792953,-166.536682,-0.000875,0.003636,0.092351,257.075897,13.096070,0.923509,-166.536682,0.092429,0.000000
88.070007,57.760559,-166.581161,-0.000871,0.003636,0.092351,256.931793,13.088729,0.923509,-166.581161,0.092429,0.000000
88.300003,57.734116,-166.536682,-0.000871,0.003636,0.092351,256.814178,13.082738,0.923509,-166.536682,0.092429,0.000000
88.530006,57.715500,-166.625641,-0.000871,0.003636,0.092351,256.731354,13.078519,0.923509,-166.625641,0.092429,0.000000
88.760002,57.682358,-166.670120,-0.000867,0.003636,0.092351,256.583954,13.071010,0.923509,-166.670120,0.092429,0.000000
88.990005,57.662621,-166.625641,-0.000880,0.003636,0.092351,256.496155,13.066536,0.923509,-166.625641,0.092429,0.000000
89.220001,57.653313,-166.670120,-0.000867,0.003636,0.092351,256.454742,13.064427,0.923509,-166.670120,0.092429,0.000000
89.450005,57.613098,-166.670120,-0.000867,0.003636,0.092351,256.275848,13.055314,0.923509,-166.670120,0.092429,0.000000
89.680008,57.596336,-166.625641,-0.000871,0.003636,0.092351,256.201294,13.051517,0.923509,-166.625641,0.092429,0.000000
89.910004,57.562828,-166.714600,-0.000862,0.003636,0.092351,256.052246,13.043922,0.923509,-166.714600,0.092429,0.000000
90.140007,57.528564,-166.714600,-0.000875,0.003636,0.092351,255.899841,13.036160,0.923509,-166.714600,0.092429,0.000000
90.370003,57.520752,-166.714600,-0.000871,0.003636,0.092351,255.865082,13.034389,0.923509,-166.714600,0.092429,0.000000
90.600006,57.506599,-166.714600,-0.000862,0.003636,0.092351,255.802124,13.031181,0.923509,-166.714600,0.092429,0.000000
90.830002,57.475319,-166.714600,-0.000875,0.003636,0.092351,255.662994,13.024094,0.923509,-166.714600,0.092429,0.000000
91.060005,57.444786,-166.848053,-0.000875,0.003636,0.092351,255.527176,13.017175,0.923509,-166.848053,0.092429,0.000000
91.290001,57.430634,-166.803574,-0.000880,0.003636,0.092351,255.464218,13.013968,0.923509,-166.803574,0.092429,0.000000
91.520004,57.399353,-166.803574,-0.000884,0.003636,0.092351,255.325073,13.006880,0.923509,-166.803574,0.092429,0.000000
91.750008,57.391159,-166.848053,-0.000867,0.003636,0.092351,255.288620,13.005023,0.923509,-166.848053,0.092429,0.000000
91.980003,57.376640,-166.848053,-0.000867,0.003636,0.092351,255.224045,13.001733,0.923509,-166.848053,0.092429,0.000000
92.210007,57.356529,-166.892532,-0.000875,0.003636,0.092351,255.134583,12.997175,0.923509,-166.892532,0.092429,0.000000
92.440002,57.333443,-166.892532,-0.000871,0.003636,0.092351,255.031891,12.991943,0.923509,-166.892532,0.092429,0.000000
92.670006,57.296577,-166.848053,-0.000867,0.003636,0.092351,254.867905,12.983589,0.923509,-166.848053,0.092429,0.000000
92.900002,57.282433,-166.892532,-0.000875,0.003636,0.092351,254.804993,12.980385,0.923509,-166.892532,0.092429,0.000000
93.130005,57.271255,-166.892532,-0.000871,0.003636,0.092351,254.755264,12.977852,0.923509,-166.892532,0.092429,0.000000
93.360008,57.252266,-166.981491,-0.000880,0.003636,0.092351,254.670792,12.973549,0.923509,-166.981491,0.092429,0.000000
93.590004,57.232162,-166.981491,-0.000871,0.003636,0.092351,254.581375,12.968993,0.923509,-166.981491,0.092429,0.000000
93.820007,57.217262,-166.981491,-0.000875,0.003636,0.092351,254.515091,12.965617,0.923509,-166.981491,0.092429,0.000000
94.050003,57.199020,-166.937012,-0.000867,0.003636,0.092351,254.433945,12.961484,0.923509,-166.937012,0.092429,0.000000
94.280006,57.162155,-166.981491,-0.000867,0.003636,0.092351,254.269958,12.953130,0.923509,-166.981491,0.092429,0.000000
94.510002,57.153587,-167.070450,-0.000871,0.003636,0.092351,254.231857,12.951188,0.923509,-167.070450,0.092429,0.000000
94.740005,57.134224,-167.114929,-0.000871,0.003636,0.092351,254.145721,12.946800,0.923509,-167.114929,0.092429,0.000000
94.970001,57.123055,-167.070450,-0.000867,0.003636,0.092351,254.096039,12.944269,0.923509,-167.070450,0.092429,0.000000
95.200005,57.115234,-167.025970,-0.000862,0.003636,0.092351,254.061249,12.942497,0.923509,-167.025970,0.092429,0.000000
95.430008,57.088425,-167.025970,-0.000858,0.003636,0.092351,253.942001,12.936421,0.923509,-167.025970,0.092429,0.000000
95.660004,57.055283,-167.114929,-0.000867,0.003636,0.092351,253.794571,12.928912,0.923509,-167.114929,0.092429,0.000000
95.890007,57.045975,-167.070450,-0.000867,0.003636,0.092351,253.753174,12.926803,0.923509,-167.070450,0.092429,0.000000
96.120003,57.028847,-167.114929,-0.000862,0.003636,0.092351,253.676987,12.922921,0.923509,-167.114929,0.092429,0.000000
96.350006,57.022888,-167.070450,-0.000875,0.003636,0.092351,253.650482,12.921572,0.923509,-167.070450,0.092429,0.000000
96.580002,57.005386,-167.159409,-0.000867,0.003636,0.092351,253.572617,12.917605,0.923509,-167.159409,0.092429,0.000000
96.810005,56.962189,-167.159409,-0.000862,0.003636,0.092351,253.380463,12.907817,0.923509,-167.159409,0.092429,0.000000
97.040001,56.960701,-167.203888,-0.000867,0.003636,0.092351,253.373856,12.907479,0.923509,-167.203888,0.092429,0.000000
97.270004,56.946922,-167.159409,-0.000867,0.003636,0.092351,253.312561,12.904357,0.923509,-167.159409,0.092429,0.000000
97.300003,56.948784,-167.114929,-0.000862,0.003636,0.092351,253.320847,12.904779,0.923509,-167.114929,0.092429,0.000000