File: Data/compression 11/AutoNoHeating-14-11-3-240530_05302024_163547.csv
Time (sec),S:Load (lbs),S:HL1 (DIM),S:LVDT (in),S:Position (in),Ch:Position (mm),Ch:Load (N),Ch:Stress (MPa),Ch:Strain (mm/mm),Ch:HL1 (DIM),Set Point (),Cycles ()
0.210000,0.010796,-182.371902,-0.014793,-0.000000,-0.000000,0.048021,0.002446,-0.000000,-182.371902,0.000269,0.000000
0.470000,-0.011177,-182.371902,-0.014801,0.000020,0.000503,-0.049718,-0.002533,0.005030,-182.371902,0.001257,0.000000
0.730000,-0.017128,-182.371902,-0.014801,0.000173,0.004388,-0.076189,-0.003881,0.043882,-182.371902,0.005576,0.000000
0.990000,-0.061073,-182.460861,-0.014629,0.000343,0.008707,-0.271668,-0.013839,0.087070,-182.460861,0.009912,0.000000
1.250000,-0.012665,-182.416382,-0.014457,0.000512,0.013017,-0.056336,-0.002870,0.130171,-182.416382,0.014249,0.000000
1.510000,0.014893,-182.460861,-0.014275,0.000687,0.017457,0.066245,0.003375,0.174573,-182.460861,0.018585,0.000000
1.770000,-0.023834,-182.460861,-0.014090,0.000858,0.021793,-0.106020,-0.005401,0.217934,-182.460861,0.022903,0.000000
2.030000,0.014893,-182.460861,-0.013926,0.001022,0.025965,0.066245,0.003375,0.259647,-182.460861,0.027240,0.000000
2.290000,-0.000000,-182.505341,-0.013754,0.001200,0.030483,-0.000000,-0.000000,0.304830,-182.505341,0.031576,0.000000
2.550000,-0.024948,-182.460861,-0.013594,0.001363,0.034611,-0.110975,-0.005653,0.346110,-182.460861,0.035912,0.000000
2.810000,-0.000374,-182.594299,-0.013409,0.001535,0.038990,-0.001663,-0.000085,0.389905,-182.594299,0.040231,0.000000
3.070000,-0.036865,-182.549820,-0.013232,0.001714,0.043543,-0.163985,-0.008354,0.435434,-182.549820,0.044567,0.000000
3.330000,-0.040962,-182.549820,-0.013047,0.001879,0.047723,-0.182209,-0.009282,0.477234,-182.549820,0.048903,0.000000
3.590000,0.025322,-182.594299,-0.012887,0.002049,0.052042,0.112638,0.005738,0.520422,-182.594299,0.053222,0.000000
3.850000,-0.010429,-182.594299,-0.012697,0.002222,0.056439,-0.046392,-0.002363,0.564391,-182.594299,0.057558,0.000000
4.110000,-0.005219,-182.638779,-0.012516,0.002395,0.060836,-0.023213,-0.001183,0.608359,-182.638779,0.061894,0.000000
4.370000,0.002602,-182.594299,-0.012361,0.002558,0.064964,0.011573,0.000590,0.649639,-182.594299,0.066230,0.000000
4.630000,0.005959,-182.594299,-0.012202,0.002731,0.069369,0.026505,0.001350,0.693694,-182.594299,0.070549,0.000000
4.890000,-0.020485,-182.727753,-0.012016,0.002900,0.073653,-0.091121,-0.004642,0.736535,-182.727753,0.074885,0.000000
5.150000,-0.010803,-182.638779,-0.011848,0.003071,0.077998,-0.048055,-0.002448,0.779983,-182.638779,0.079221,0.000000
5.410000,-0.071129,-182.727753,-0.011650,0.003248,0.082491,-0.316397,-0.016118,0.824905,-182.727753,0.083557,0.000000
5.670000,-0.007080,-182.683273,-0.011499,0.003414,0.086723,-0.031494,-0.001604,0.867226,-182.683273,0.087876,0.000000
5.930000,0.017128,-182.772232,-0.011335,0.003585,0.091050,0.076189,0.003881,0.910500,-182.772232,0.092212,0.000000
6.190000,-0.028305,-182.727753,-0.011163,0.003757,0.095421,-0.125907,-0.006414,0.954208,-182.727753,0.096548,0.000000
6.450000,0.007820,-182.727753,-0.010964,0.003928,0.099766,0.034786,0.001772,0.997657,-182.727753,0.100884,0.000000
6.710001,0.002602,-182.772232,-0.010796,0.004094,0.103980,0.011573,0.000590,1.039804,-182.772232,0.105203,0.000000
6.970000,-0.016388,-182.816711,-0.010632,0.004270,0.108464,-0.072897,-0.003714,1.084639,-182.816711,0.109539,0.000000
7.230000,-0.005219,-182.772232,-0.010447,0.004435,0.112661,-0.023213,-0.001183,1.126613,-182.772232,0.113875,0.000000
7.490000,-0.011177,-182.816711,-0.010279,0.004607,0.117006,-0.049718,-0.002533,1.170061,-182.816711,0.118194,0.000000
7.750000,-0.043571,-182.816711,-0.010111,0.004781,0.121438,-0.193816,-0.009873,1.214376,-182.816711,0.122530,0.000000
8.010000,-0.009682,-182.861191,-0.009934,0.004952,0.125774,-0.043066,-0.002194,1.257738,-182.861191,0.126866,0.000000
8.270000,0.034630,-182.861191,-0.009774,0.005123,0.130127,0.154041,0.007847,1.301272,-182.861191,0.131203,0.000000
8.530001,-0.004097,-182.905670,-0.009572,0.005292,0.134420,-0.018224,-0.000928,1.344200,-182.905670,0.135521,0.000000
8.790000,0.010422,-182.950150,-0.009408,0.005462,0.138730,0.046358,0.002362,1.387301,-182.950150,0.139858,0.000000
9.050000,-0.007080,-182.861191,-0.009235,0.005631,0.143023,-0.031494,-0.001604,1.430229,-182.861191,0.144194,0.000000
9.310000,-0.035751,-182.950150,-0.009067,0.005803,0.147394,-0.159030,-0.008101,1.473937,-182.950150,0.148530,0.000000
9.570001,-0.001862,-182.905670,-0.008886,0.005971,0.151660,-0.008281,-0.000422,1.516604,-182.905670,0.152849,0.000000
9.830001,-0.011177,-182.950150,-0.008714,0.006144,0.156066,-0.049718,-0.002533,1.560659,-182.950150,0.157185,0.000000
10.090000,-0.004097,-182.994629,-0.008532,0.006315,0.160402,-0.018224,-0.000928,1.604021,-182.994629,0.161521,0.000000
10.350000,0.021599,-182.950150,-0.008377,0.006480,0.164582,0.096076,0.004894,1.645821,-182.950150,0.165857,0.000000
10.610001,0.032021,-182.994629,-0.008201,0.006660,0.169170,0.142435,0.007256,1.691697,-182.994629,0.170176,0.000000
10.870001,0.000740,-183.039108,-0.008032,0.006823,0.173298,0.003292,0.000168,1.732977,-183.039108,0.174512,0.000000
11.130000,-0.004845,-183.039108,-0.007864,0.006991,0.177573,-0.021550,-0.001098,1.775731,-183.039108,0.178848,0.000000
11.390000,0.007446,-183.083588,-0.007675,0.007166,0.182022,0.033123,0.001687,1.820220,-183.083588,0.183184,0.000000
11.650001,-0.036125,-183.039108,-0.007515,0.007335,0.186297,-0.160693,-0.008186,1.862974,-183.039108,0.187503,0.000000
11.910001,0.008560,-183.083588,-0.007325,0.007505,0.190625,0.038078,0.001940,1.906249,-183.083588,0.191839,0.000000
12.170001,0.023827,-183.128082,-0.007161,0.007675,0.194952,0.105986,0.005399,1.949523,-183.128082,0.196175,0.000000
12.430000,0.002235,-183.128082,-0.006972,0.007849,0.199367,0.009944,0.000507,1.993665,-183.128082,0.200494,0.000000
12.690001,0.028297,-183.172562,-0.006817,0.008013,0.203529,0.125873,0.006412,2.035292,-183.172562,0.204830,0.000000
12.950001,0.034256,-183.083588,-0.006631,0.008191,0.208039,0.152378,0.007763,2.080388,-183.083588,0.209166,0.000000
13.210001,-0.021973,-183.261520,-0.006467,0.008355,0.212210,-0.097739,-0.004979,2.122101,-183.261520,0.213502,0.000000
13.470000,0.022339,-183.261520,-0.006295,0.008527,0.216590,0.099368,0.005062,2.165896,-183.261520,0.217821,0.000000
13.730000,0.007446,-183.172562,-0.006105,0.008705,0.221108,0.033123,0.001687,2.211079,-183.172562,0.222157,0.000000
13.990001,-0.041710,-183.350479,-0.005954,0.008870,0.225297,-0.185535,-0.009452,2.252966,-183.350479,0.226493,0.000000
14.250001,0.043564,-183.217041,-0.005790,0.009041,0.229633,0.193782,0.009872,2.296327,-183.217041,0.230829,0.000000
14.510000,0.021599,-183.261520,-0.005601,0.009213,0.234012,0.096076,0.004894,2.340122,-183.261520,0.235148,0.000000
14.770000,0.011169,-183.306000,-0.005433,0.009386,0.238400,0.049684,0.002531,2.384004,-183.306000,0.239484,0.000000
15.030001,0.033508,-183.350479,-0.005251,0.009550,0.242563,0.149052,0.007593,2.425630,-183.350479,0.243821,0.000000
15.290001,0.033508,-183.394958,-0.005083,0.009723,0.246960,0.149052,0.007593,2.469599,-183.394958,0.248157,0.000000
15.550001,0.011917,-183.350479,-0.004919,0.009892,0.251253,0.053010,0.002700,2.512526,-183.350479,0.252475,0.000000
15.810000,0.025688,-183.350479,-0.004738,0.010061,0.255545,0.114267,0.005821,2.555454,-183.350479,0.256812,0.000000
16.070002,-0.017502,-183.394958,-0.004562,0.010238,0.260046,-0.077852,-0.003966,2.600463,-183.394958,0.261148,0.000000
16.330000,0.322472,-183.394958,-0.004393,0.010404,0.264252,1.434425,0.073073,2.642524,-183.394958,0.265484,0.000000
16.590000,0.624092,-183.439438,-0.004324,0.000008,0.000208,2.776100,0.141421,0.002081,-183.439438,0.000408,0.000000
16.850000,0.596909,-183.394958,-0.004320,0.000008,0.000199,2.655182,0.135261,0.001995,-183.394958,0.000408,0.000000
17.110001,0.614037,-183.483917,-0.004320,0.000008,0.000199,2.731371,0.139143,0.001995,-183.483917,0.000650,0.000000
17.370001,0.584625,-183.483917,-0.004324,0.000008,0.000208,2.600543,0.132478,0.002081,-183.483917,0.001084,0.000000
17.630001,0.561905,-183.439438,-0.004316,0.000009,0.000225,2.499478,0.127329,0.002255,-183.439438,0.001518,0.000000
17.890001,0.754425,-183.483917,-0.004294,0.000039,0.000989,3.355850,0.170955,0.009886,-183.483917,0.001951,0.000000
18.150002,0.889595,-183.528397,-0.004299,0.000056,0.001422,3.957116,0.201585,0.014223,-183.528397,0.002385,0.000000
18.410002,1.052696,-183.572891,-0.004273,0.000079,0.002003,4.682627,0.238544,0.020033,-183.572891,0.002818,0.000000
18.670000,1.117859,-183.528397,-0.004260,0.000089,0.002255,4.972485,0.253310,0.022548,-183.528397,0.003252,0.000000
18.930000,1.272018,-183.528397,-0.004243,0.000106,0.002697,5.658221,0.288244,0.026971,-183.528397,0.003686,0.000000
19.190001,1.430283,-183.572891,-0.004225,0.000125,0.003165,6.362215,0.324107,0.031654,-183.572891,0.004119,0.000000
19.450001,1.581833,-183.572891,-0.004212,0.000145,0.003694,7.036344,0.358448,0.036944,-183.572891,0.004553,0.000000
19.710001,1.666740,-183.661850,-0.004195,0.000156,0.003972,7.414032,0.377689,0.039719,-183.661850,0.004987,0.000000
19.970001,1.869682,-183.617371,-0.004178,0.000180,0.004562,8.316762,0.423676,0.045616,-183.617371,0.005420,0.000000
20.230001,1.976181,-183.706329,-0.004156,0.000195,0.004943,8.790492,0.447809,0.049432,-183.706329,0.005854,0.000000
20.490002,2.132950,-183.750809,-0.004143,0.000210,0.005325,9.487835,0.483333,0.053248,-183.750809,0.006287,0.000000
20.750002,2.206680,-183.706329,-0.004130,0.000223,0.005672,9.815804,0.500041,0.056717,-183.706329,0.006721,0.000000
21.010000,2.462868,-183.706329,-0.004109,0.000244,0.006209,10.955383,0.558094,0.062093,-183.706329,0.007155,0.000000
21.270000,2.662834,-183.706329,-0.004092,0.000266,0.006764,11.844878,0.603407,0.067644,-183.706329,0.007588,0.000000
21.530001,2.752579,-183.795288,-0.004070,0.000280,0.007111,12.244081,0.623743,0.071113,-183.795288,0.008022,0.000000
21.790001,2.825935,-183.706329,-0.004066,0.000296,0.007528,12.570388,0.640366,0.075275,-183.706329,0.008455,0.000000
22.050001,2.973389,-183.750809,-0.004049,0.000314,0.007978,13.226294,0.673779,0.079785,-183.750809,0.008889,0.000000
22.310001,3.166656,-183.750809,-0.004023,0.000334,0.008490,14.085992,0.717575,0.084901,-183.750809,0.009323,0.000000
22.570002,3.209473,-183.795288,-0.004023,0.000346,0.008776,14.276447,0.727277,0.087763,-183.795288,0.009756,0.000000
22.830002,3.352837,-183.839767,-0.004005,0.000362,0.009193,14.914162,0.759764,0.091926,-183.839767,0.010181,0.000000
23.090000,3.607170,-183.839767,-0.003980,0.000385,0.009782,16.045494,0.817396,0.097823,-183.839767,0.010615,0.000000
23.350000,3.692070,-183.884247,-0.003954,0.000403,0.010225,16.423147,0.836635,0.102246,-183.884247,0.011048,0.000000
23.610001,3.655205,-183.884247,-0.003945,0.000413,0.010502,16.259163,0.828281,0.105021,-183.884247,0.011482,0.000000
23.870001,3.848839,-183.839767,-0.003923,0.000434,0.011022,17.120489,0.872159,0.110224,-183.839767,0.011916,0.000000
24.130001,3.994438,-183.928726,-0.003906,0.000453,0.011499,17.768148,0.905153,0.114994,-183.928726,0.012349,0.000000
24.390001,4.029068,-183.884247,-0.003898,0.000465,0.011812,17.922190,0.913000,0.118116,-183.884247,0.012783,0.000000
24.650002,4.113220,-183.928726,-0.003872,0.000480,0.012202,18.296516,0.932069,0.122019,-183.928726,0.013217,0.000000
24.910002,4.201477,-184.017700,-0.003859,0.000499,0.012670,18.689104,0.952068,0.126702,-184.017700,0.013650,0.000000
25.170002,4.371651,-183.973221,-0.003842,0.000517,0.013130,19.446074,0.990630,0.131298,-183.973221,0.014084,0.000000
25.430000,4.425270,-184.017700,-0.003820,0.000534,0.013572,19.684584,1.002781,0.135721,-184.017700,0.014517,0.000000
25.690001,4.490807,-184.062180,-0.003811,0.000551,0.014006,19.976105,1.017631,0.140057,-184.062180,0.014951,0.000000
25.950001,4.587997,-184.017700,-0.003794,0.000569,0.014448,20.408432,1.039655,0.144480,-184.017700,0.015385,0.000000
26.210001,4.710136,-184.062180,-0.003773,0.000586,0.014890,20.951733,1.067332,0.148903,-184.062180,0.015818,0.000000
26.470001,4.704178,-184.017700,-0.003755,0.000601,0.015254,20.925228,1.065982,0.152545,-184.017700,0.016252,0.000000
26.730001,4.789078,-184.151138,-0.003734,0.000617,0.015662,21.302881,1.085221,0.156621,-184.151138,0.016685,0.000000
26.990002,4.924622,-184.151138,-0.003725,0.000637,0.016182,21.905811,1.115935,0.161824,-184.151138,0.017119,0.000000
27.250002,4.936539,-184.106659,-0.003708,0.000651,0.016529,21.958820,1.118636,0.165293,-184.106659,0.017553,0.000000
27.510002,4.999840,-184.151138,-0.003691,0.000672,0.017058,22.240398,1.132980,0.170583,-184.151138,0.017986,0.000000
27.770000,5.012505,-184.151138,-0.003673,0.000685,0.017397,22.296734,1.135850,0.173965,-184.151138,0.018420,0.000000
28.030001,5.149162,-184.195618,-0.003656,0.000704,0.017891,22.904617,1.166817,0.178909,-184.195618,0.018853,0.000000
28.290001,5.221405,-184.195618,-0.003643,0.000720,0.018290,23.225969,1.183187,0.182898,-184.195618,0.019287,0.000000
28.550001,5.220657,-184.195618,-0.003626,0.000733,0.018628,23.222643,1.183018,0.186280,-184.195618,0.019721,0.000000
28.810001,5.334976,-184.284576,-0.003613,0.000751,0.019088,23.731159,1.208923,0.190876,-184.284576,0.020154,0.000000
29.070002,5.453392,-184.240097,-0.003591,0.000774,0.019669,24.257898,1.235756,0.196687,-184.240097,0.020588,0.000000
29.330002,5.534195,-184.284576,-0.003561,0.000793,0.020137,24.617329,1.254066,0.201370,-184.284576,0.021022,0.000000
29.590002,5.521538,-184.240097,-0.003553,0.000808,0.020519,24.561028,1.251198,0.205186,-184.240097,0.021455,0.000000
29.850002,5.523399,-184.329056,-0.003531,0.000821,0.020865,24.569307,1.251620,0.208655,-184.329056,0.021889,0.000000
30.110001,5.622452,-184.329056,-0.003527,0.000839,0.021308,25.009914,1.274066,0.213077,-184.329056,0.022322,0.000000
30.370001,5.622826,-184.329056,-0.003510,0.000853,0.021663,25.011578,1.274150,0.216633,-184.329056,0.022756,0.000000
30.630001,5.816452,-184.373535,-0.003488,0.000874,0.022210,25.872871,1.318027,0.222097,-184.373535,0.023190,0.000000
30.890001,5.824272,-184.329056,-0.003466,0.000891,0.022626,25.907656,1.319799,0.226259,-184.329056,0.023623,0.000000
31.150002,5.973595,-184.373535,-0.003445,0.000912,0.023164,26.571877,1.353636,0.231636,-184.373535,0.024057,0.000000
31.410002,5.977318,-184.329056,-0.003428,0.000929,0.023597,26.588438,1.354480,0.235972,-184.329056,0.024490,0.000000
31.670002,5.961678,-184.373535,-0.003402,0.000944,0.023970,26.518866,1.350935,0.239701,-184.373535,0.024915,0.000000
31.930002,6.045090,-184.462509,-0.003393,0.000960,0.024395,26.889902,1.369837,0.243951,-184.462509,0.025349,0.000000
32.190002,6.054405,-184.373535,-0.003376,0.000974,0.024742,26.931339,1.371948,0.247420,-184.373535,0.025783,0.000000
32.450001,6.109886,-184.418030,-0.003380,0.000992,0.025193,27.178131,1.384520,0.251929,-184.418030,0.026216,0.000000
32.710003,6.214149,-184.462509,-0.003354,0.001008,0.025609,27.641918,1.408146,0.256092,-184.462509,0.026650,0.000000
32.970001,6.404060,-184.462509,-0.003328,0.001033,0.026234,28.486683,1.451181,0.262336,-184.462509,0.027083,0.000000
33.230003,6.407036,-184.506989,-0.003328,0.001048,0.026615,28.499918,1.451855,0.266152,-184.506989,0.027517,0.000000
33.490002,6.383209,-184.506989,-0.003290,0.001064,0.027031,28.393932,1.446456,0.270314,-184.506989,0.027951,0.000000
33.750000,6.343361,-184.595947,-0.003281,0.001076,0.027335,28.216679,1.437426,0.273350,-184.595947,0.028384,0.000000
34.010002,6.644241,-184.551468,-0.003255,0.001099,0.027925,29.555061,1.505607,0.279247,-184.551468,0.028818,0.000000
34.270000,6.602165,-184.551468,-0.003238,0.001113,0.028263,29.367897,1.496072,0.282629,-184.551468,0.029252,0.000000
34.530003,6.663231,-184.595947,-0.003242,0.001128,0.028662,29.639532,1.509910,0.286618,-184.595947,0.029685,0.000000
34.790001,6.892982,-184.595947,-0.003212,0.001152,0.029252,30.661518,1.561972,0.292515,-184.595947,0.030119,0.000000
35.050003,6.920540,-184.640427,-0.003186,0.001169,0.029685,30.784100,1.568217,0.296851,-184.640427,0.030552,0.000000
35.310001,6.878464,-184.640427,-0.003178,0.001184,0.030075,30.596935,1.558682,0.300754,-184.640427,0.030986,0.000000
35.570004,6.861702,-184.640427,-0.003173,0.001198,0.030422,30.522375,1.554884,0.304223,-184.640427,0.031420,0.000000
35.830002,7.090340,-184.640427,-0.003152,0.001218,0.030943,31.539406,1.606694,0.309426,-184.640427,0.031853,0.000000
36.090000,7.167793,-184.684906,-0.003122,0.001236,0.031402,31.883936,1.624245,0.314022,-184.684906,0.032287,0.000000
36.350002,7.149918,-184.729385,-0.003117,0.001251,0.031766,31.804422,1.620195,0.317665,-184.729385,0.032720,0.000000
36.610001,7.186783,-184.729385,-0.003091,0.001266,0.032148,31.968407,1.628548,0.321481,-184.729385,0.033154,0.000000
36.870003,7.396057,-184.729385,-0.003074,0.001287,0.032686,32.899303,1.675970,0.326857,-184.729385,0.033588,0.000000
37.130001,7.434784,-184.818344,-0.003074,0.001303,0.033102,33.071571,1.684746,0.331020,-184.818344,0.034021,0.000000
37.390003,7.472023,-184.729385,-0.003040,0.001320,0.033536,33.237217,1.693185,0.335356,-184.729385,0.034455,0.000000
37.650002,7.376694,-184.818344,-0.003035,0.001332,0.033822,32.813171,1.671583,0.338218,-184.818344,0.034888,0.000000
37.910004,7.766945,-184.773865,-0.003009,0.001356,0.034446,34.549095,1.760015,0.344462,-184.773865,0.035322,0.000000
38.170002,7.676453,-184.862839,-0.002992,0.001369,0.034767,34.146568,1.739509,0.347671,-184.862839,0.035756,0.000000
38.430000,7.898766,-184.862839,-0.002984,0.001389,0.035270,35.135464,1.789886,0.352701,-184.862839,0.036189,0.000000
38.690002,7.929672,-184.818344,-0.002966,0.001405,0.035678,35.272945,1.796889,0.356777,-184.818344,0.036623,0.000000
38.950001,7.854080,-184.907318,-0.002949,0.001417,0.035999,34.936695,1.779760,0.359985,-184.907318,0.037057,0.000000
39.210003,8.139313,-184.862839,-0.002928,0.001439,0.036562,36.205471,1.844395,0.365622,-184.862839,0.037490,0.000000
39.470001,8.128143,-184.951797,-0.002910,0.001454,0.036935,36.155788,1.841864,0.369351,-184.951797,0.037924,0.000000
39.730003,8.403702,-184.907318,-0.002889,0.001478,0.037534,37.381531,1.904306,0.375335,-184.907318,0.038357,0.000000
39.990002,8.257729,-184.907318,-0.002876,0.001487,0.037776,36.732212,1.871228,0.377764,-184.907318,0.038791,0.000000
40.250004,8.421944,-184.996277,-0.002867,0.001505,0.038236,37.462677,1.908440,0.382360,-184.996277,0.039225,0.000000
40.510002,8.530304,-184.907318,-0.002841,0.001523,0.038678,37.944687,1.932994,0.386783,-184.907318,0.039658,0.000000
40.770000,8.623772,-184.951797,-0.002828,0.001541,0.039129,38.360451,1.954175,0.391292,-184.951797,0.040083,0.000000
41.030003,8.659889,-184.996277,-0.002811,0.001555,0.039502,38.521111,1.962359,0.395021,-184.996277,0.040517,0.000000
41.290001,8.943642,-185.040756,-0.002785,0.001578,0.040083,39.783306,2.026658,0.400832,-185.040756,0.040950,0.000000
41.550003,8.974922,-185.040756,-0.002790,0.001596,0.040534,39.922447,2.033746,0.405341,-185.040756,0.041384,0.000000
41.810001,9.026306,-185.040756,-0.002764,0.001610,0.040898,40.151016,2.045390,0.408984,-185.040756,0.041818,0.000000
42.070004,8.989815,-185.129715,-0.002746,0.001623,0.041228,39.988693,2.037121,0.412279,-185.129715,0.042251,0.000000
42.330002,9.227760,-185.040756,-0.002721,0.001643,0.041740,41.047127,2.091040,0.417396,-185.040756,0.042685,0.000000
42.590000,9.517464,-185.085236,-0.002695,0.001665,0.042303,42.335793,2.156688,0.423033,-185.085236,0.043118,0.000000
42.850002,9.473900,-185.085236,-0.002695,0.001679,0.042641,42.142010,2.146816,0.426415,-185.085236,0.043552,0.000000
43.110001,9.505920,-185.129715,-0.002669,0.001695,0.043058,42.284447,2.154073,0.430578,-185.129715,0.043986,0.000000
43.370003,9.651146,-185.218674,-0.002660,0.001713,0.043500,42.930443,2.186981,0.435000,-185.218674,0.044419,0.000000
43.630001,9.886856,-185.129715,-0.002643,0.001733,0.044020,43.978931,2.240394,0.440204,-185.129715,0.044853,0.000000
43.890003,9.773285,-185.218674,-0.002617,0.001744,0.044298,43.473743,2.214658,0.442979,-185.218674,0.045287,0.000000
44.150002,9.934525,-185.218674,-0.002613,0.001761,0.044740,44.190971,2.251195,0.447402,-185.218674,0.045720,0.000000
44.410004,10.323654,-185.218674,-0.002591,0.001784,0.045313,45.921906,2.339373,0.453125,-185.218674,0.046154,0.000000
44.670002,10.414886,-185.307648,-0.002570,0.001802,0.045772,46.327728,2.360047,0.457722,-185.307648,0.046587,0.000000
44.930000,10.360519,-185.263168,-0.002557,0.001817,0.046162,46.085892,2.347727,0.461624,-185.263168,0.047021,0.000000
45.190002,10.491219,-185.263168,-0.002548,0.001832,0.046544,46.667271,2.377344,0.465440,-185.263168,0.047455,0.000000
45.450001,10.703102,-185.263168,-0.002527,0.001853,0.047064,47.609776,2.425358,0.470643,-185.263168,0.047888,0.000000
45.710003,10.619690,-185.263168,-0.002509,0.001864,0.047342,47.238739,2.406456,0.473419,-185.263168,0.048322,0.000000
45.970001,10.716507,-185.352127,-0.002496,0.001879,0.047723,47.669403,2.428395,0.477234,-185.352127,0.048755,0.000000
46.230003,10.857635,-185.352127,-0.002475,0.001897,0.048183,48.297176,2.460375,0.481831,-185.352127,0.049189,0.000000
46.490002,11.205803,-185.396606,-0.002462,0.001917,0.048686,49.845901,2.539271,0.486861,-185.396606,0.049623,0.000000
46.750004,11.294052,-185.396606,-0.002453,0.001934,0.049111,50.238453,2.559269,0.491110,-185.396606,0.050056,0.000000
47.010002,11.492531,-185.396606,-0.002427,0.001951,0.049553,51.121330,2.604245,0.495533,-185.396606,0.050490,0.000000
47.270000,11.527161,-185.396606,-0.002427,0.001967,0.049970,51.275372,2.612092,0.499695,-185.396606,0.050923,0.000000
47.530003,11.814262,-185.396606,-0.002393,0.001985,0.050421,52.552464,2.677150,0.504205,-185.396606,0.051357,0.000000
47.790001,11.775536,-185.485565,-0.002397,0.001999,0.050776,52.380199,2.668374,0.507761,-185.485565,0.051791,0.000000
48.050003,12.024651,-185.441086,-0.002376,0.002019,0.051279,53.488316,2.724825,0.512791,-185.441086,0.052224,0.000000
48.310001,12.245094,-185.485565,-0.002345,0.002036,0.051704,54.468899,2.774778,0.517040,-185.485565,0.052658,0.000000
48.570004,12.418617,-185.485565,-0.002341,0.002054,0.052164,55.240768,2.814099,0.521636,-185.485565,0.053092,0.000000
48.830002,12.579109,-185.441086,-0.002315,0.002071,0.052606,55.954674,2.850467,0.526059,-185.441086,0.053525,0.000000
49.090004,12.538521,-185.530045,-0.002298,0.002084,0.052927,55.774128,2.841269,0.529268,-185.530045,0.053959,0.000000
49.350002,12.851692,-185.530045,-0.002285,0.002104,0.053430,57.167183,2.912235,0.534298,-185.530045,0.054392,0.000000
49.610001,12.998779,-185.574524,-0.002259,0.002119,0.053820,57.821457,2.945565,0.538200,-185.574524,0.054826,0.000000
49.870003,12.990585,-185.574524,-0.002268,0.002132,0.054150,57.785011,2.943709,0.541496,-185.574524,0.055251,0.000000
50.130001,13.244171,-185.574524,-0.002233,0.002150,0.054609,58.913017,3.001172,0.546092,-185.574524,0.055685,0.000000
50.390003,13.663086,-185.707977,-0.002220,0.002173,0.055182,60.776443,3.096100,0.551816,-185.707977,0.056118,0.000000
50.650002,13.969925,-185.619003,-0.002203,0.002191,0.055659,62.141331,3.165630,0.556585,-185.619003,0.056552,0.000000
50.910004,13.947578,-185.663483,-0.002182,0.002207,0.056057,62.041927,3.160567,0.560575,-185.663483,0.056985,0.000000
51.170002,13.948326,-185.663483,-0.002173,0.002220,0.056387,62.045254,3.160736,0.563870,-185.663483,0.057419,0.000000
51.430004,14.228348,-185.574524,-0.002151,0.002238,0.056855,63.290852,3.224190,0.568553,-185.574524,0.057853,0.000000
51.690002,14.211967,-185.707977,-0.002139,0.002251,0.057185,63.217987,3.220478,0.571849,-185.707977,0.058286,0.000000
51.950001,14.747810,-185.619003,-0.002134,0.002273,0.057723,65.601540,3.341902,0.577225,-185.619003,0.058720,0.000000
52.210003,14.865852,-185.707977,-0.002104,0.002290,0.058156,66.126617,3.368650,0.581562,-185.707977,0.059153,0.000000
52.470001,15.358871,-185.707977,-0.002095,0.002311,0.058703,68.319672,3.480370,0.587025,-185.707977,0.059587,0.000000
52.730003,15.453827,-185.796936,-0.002065,0.002329,0.059145,68.742058,3.501887,0.591448,-185.796936,0.060021,0.000000
52.990002,15.438560,-185.752457,-0.002057,0.002342,0.059492,68.674149,3.498428,0.594917,-185.752457,0.060454,0.000000
53.250004,15.675758,-185.752457,-0.002048,0.002359,0.059925,69.729256,3.552178,0.599253,-185.752457,0.060888,0.000000
53.510002,15.720444,-185.841415,-0.002026,0.002372,0.060246,69.928024,3.562304,0.602462,-185.841415,0.061322,0.000000
53.770004,15.981476,-185.752457,-0.002022,0.002390,0.060714,71.089157,3.621454,0.607145,-185.752457,0.061755,0.000000
54.030003,16.348640,-185.885895,-0.001996,0.002406,0.061113,72.722382,3.704655,0.611134,-185.885895,0.062189,0.000000
54.290001,17.032310,-185.885895,-0.001979,0.002432,0.061764,75.763504,3.859577,0.617638,-185.885895,0.062622,0.000000
54.550003,17.082954,-185.885895,-0.001970,0.002446,0.062137,75.988777,3.871053,0.621367,-185.885895,0.063056,0.000000
54.810001,17.183495,-185.930374,-0.001957,0.002463,0.062553,76.436005,3.893836,0.625530,-185.930374,0.063490,0.000000
55.070004,17.142166,-185.885895,-0.001932,0.002476,0.062883,76.252167,3.884470,0.628825,-185.885895,0.063923,0.000000
55.330002,17.862335,-185.974854,-0.001919,0.002498,0.063455,79.455635,4.047663,0.634549,-185.974854,0.064357,0.000000
55.590004,17.863075,-185.930374,-0.001923,0.002511,0.063767,79.458931,4.047831,0.637671,-185.930374,0.064790,0.000000
55.850002,18.124855,-185.930374,-0.001897,0.002526,0.064157,80.623383,4.107151,0.641574,-185.930374,0.065224,0.000000
56.110004,18.582870,-186.063812,-0.001880,0.002549,0.064738,82.660736,4.210938,0.647384,-186.063812,0.065658,0.000000
56.370003,19.071426,-185.974854,-0.001871,0.002567,0.065189,84.833939,4.321647,0.651894,-185.974854,0.066091,0.000000
56.630001,19.126534,-186.063812,-0.001845,0.002582,0.065580,85.079071,4.334135,0.655796,-186.063812,0.066525,0.000000
56.890003,19.234154,-186.019333,-0.001845,0.002596,0.065935,85.557793,4.358521,0.659352,-186.019333,0.066959,0.000000
57.150002,19.716003,-186.063812,-0.001811,0.002615,0.066429,87.701164,4.467710,0.664295,-186.063812,0.067392,0.000000
57.410004,20.116302,-186.063812,-0.001807,0.002632,0.066863,89.481781,4.558419,0.668631,-186.063812,0.067826,0.000000
57.670002,20.133057,-186.019333,-0.001798,0.002647,0.067245,89.556305,4.562216,0.672447,-186.019333,0.068259,0.000000
57.930004,20.565758,-186.152786,-0.001772,0.002663,0.067644,91.481056,4.660267,0.676436,-186.152786,0.068693,0.000000
58.190002,21.230438,-186.108292,-0.001768,0.002685,0.068207,94.437706,4.810886,0.682073,-186.108292,0.069127,0.000000
58.450005,21.469879,-186.197266,-0.001746,0.002702,0.068624,95.502792,4.865144,0.686236,-186.197266,0.069560,0.000000
58.710003,21.753250,-186.108292,-0.001733,0.002719,0.069057,96.763290,4.929357,0.690572,-186.108292,0.069985,0.000000
58.970001,21.714523,-186.152786,-0.001707,0.002730,0.069352,96.591026,4.920581,0.693520,-186.152786,0.070419,0.000000
59.230003,22.582901,-186.197266,-0.001694,0.002753,0.069924,100.453758,5.117359,0.699244,-186.197266,0.070852,0.000000
59.490002,22.514381,-186.152786,-0.001699,0.002763,0.070185,100.148972,5.101832,0.701846,-186.152786,0.071286,0.000000
59.750004,23.239021,-186.241745,-0.001669,0.002785,0.070731,103.372330,5.266037,0.707309,-186.241745,0.071720,0.000000
60.010002,23.775978,-186.286224,-0.001656,0.002803,0.071208,105.760834,5.387714,0.712079,-186.286224,0.072153,0.000000
60.270004,23.723473,-186.241745,-0.001638,0.002817,0.071546,105.527275,5.375815,0.715461,-186.241745,0.072587,0.000000
60.530003,24.473808,-186.286224,-0.001617,0.002838,0.072084,108.864937,5.545844,0.720838,-186.286224,0.073020,0.000000
60.790005,24.773941,-186.286224,-0.001613,0.002853,0.072465,110.199997,5.613855,0.724654,-186.286224,0.073454,0.000000
61.050003,25.546982,-186.330704,-0.001591,0.002876,0.073038,113.638649,5.789029,0.730377,-186.330704,0.073888,0.000000
61.310001,25.527992,-186.286224,-0.001578,0.002886,0.073298,113.554184,5.784726,0.732979,-186.286224,0.074321,0.000000
61.570004,25.999046,-186.330704,-0.001565,0.002904,0.073766,115.649536,5.891468,0.737662,-186.330704,0.074755,0.000000
61.830002,26.543076,-186.375183,-0.001565,0.002922,0.074217,118.069496,6.014747,0.742172,-186.375183,0.075188,0.000000
62.090004,27.131058,-186.330704,-0.001535,0.002942,0.074729,120.684975,6.147985,0.747288,-186.330704,0.075622,0.000000
62.350002,27.261383,-186.375183,-0.001526,0.002954,0.075024,121.264687,6.177517,0.750237,-186.375183,0.076056,0.000000
62.610004,28.183006,-186.419662,-0.001505,0.002977,0.075605,125.364273,6.386361,0.756047,-186.419662,0.076489,0.000000
62.870003,28.231415,-186.419662,-0.001487,0.002992,0.075995,125.579605,6.397330,0.759950,-186.419662,0.076923,0.000000
63.130005,28.859238,-186.419662,-0.001475,0.003008,0.076403,128.372299,6.539597,0.764026,-186.419662,0.077357,0.000000
63.390003,28.868172,-186.419662,-0.001466,0.003020,0.076715,128.412048,6.541621,0.767148,-186.419662,0.077790,0.000000
63.650002,29.865013,-186.553116,-0.001466,0.003040,0.077209,132.846207,6.767509,0.772091,-186.553116,0.078224,0.000000
63.910004,30.928513,-186.464142,-0.001440,0.003063,0.077807,137.576889,7.008502,0.778075,-186.464142,0.078657,0.000000
64.170006,31.109482,-186.508621,-0.001423,0.003077,0.078154,138.381882,7.049510,0.781544,-186.508621,0.079091,0.000000
64.430000,31.235718,-186.508621,-0.001414,0.003091,0.078510,138.943405,7.078115,0.785099,-186.508621,0.079525,0.000000
64.690002,32.044510,-186.553116,-0.001401,0.003111,0.079022,142.541092,7.261390,0.790216,-186.553116,0.079958,0.000000
64.950005,32.852562,-186.597595,-0.001384,0.003131,0.079525,146.135498,7.444497,0.795246,-186.597595,0.080392,0.000000
65.210007,32.952728,-186.553116,-0.001380,0.003142,0.079802,146.581055,7.467195,0.798021,-186.553116,0.080825,0.000000
65.470001,33.369041,-186.597595,-0.001375,0.003158,0.080201,148.432907,7.561533,0.802010,-186.597595,0.081259,0.000000
65.730003,34.040802,-186.686554,-0.001354,0.003177,0.080687,151.421051,7.713756,0.806867,-186.686554,0.081693,0.000000
65.990005,35.493797,-186.642075,-0.001324,0.003199,0.081259,157.884293,8.043010,0.812591,-186.642075,0.082126,0.000000
66.250000,35.571625,-186.686554,-0.001328,0.003213,0.081615,158.230484,8.060645,0.816146,-186.686554,0.082560,0.000000
66.510002,36.373711,-186.642075,-0.001311,0.003231,0.082066,161.798340,8.242400,0.820656,-186.642075,0.082993,0.000000
66.770004,37.189209,-186.686554,-0.001302,0.003250,0.082560,165.425858,8.427196,0.825599,-186.686554,0.083427,0.000000
67.030006,37.470352,-186.686554,-0.001293,0.003262,0.082855,166.676453,8.490903,0.828547,-186.686554,0.083861,0.000000
67.290001,37.947731,-186.642075,-0.001281,0.003278,0.083254,168.799942,8.599079,0.832537,-186.642075,0.084294,0.000000
67.550003,38.423622,-186.731033,-0.001276,0.003291,0.083592,170.916809,8.706918,0.835919,-186.731033,0.084728,0.000000
67.810005,39.658035,-186.686554,-0.001255,0.003315,0.084208,176.407745,8.986639,0.842076,-186.686554,0.085153,0.000000
68.070000,40.319374,-186.819992,-0.001242,0.003332,0.084633,179.349533,9.136500,0.846326,-186.819992,0.085587,0.000000
68.330002,40.974747,-186.731033,-0.001233,0.003349,0.085066,182.264771,9.285010,0.850662,-186.731033,0.086020,0.000000
68.590004,41.549690,-186.775513,-0.001229,0.003365,0.085465,184.822250,9.415295,0.854651,-186.775513,0.086454,0.000000
68.850006,42.626221,-186.819992,-0.001212,0.003383,0.085933,189.610901,9.659240,0.859334,-186.819992,0.086887,0.000000
69.110001,43.088707,-186.775513,-0.001194,0.003398,0.086298,191.668137,9.764041,0.862976,-186.775513,0.087321,0.000000
69.370003,43.804779,-186.908951,-0.001190,0.003415,0.086731,194.853394,9.926305,0.867312,-186.908951,0.087755,0.000000
69.630005,44.689163,-186.864471,-0.001177,0.003433,0.087208,198.787323,10.126710,0.872082,-186.864471,0.088188,0.000000
69.890007,45.625679,-186.908951,-0.001160,0.003452,0.087685,202.953156,10.338926,0.876852,-186.908951,0.088622,0.000000
70.150002,46.285149,-186.908951,-0.001151,0.003469,0.088119,205.886627,10.488364,0.881188,-186.908951,0.089055,0.000000
70.410004,46.849297,-186.908951,-0.001147,0.003482,0.088431,208.396072,10.616202,0.884310,-186.908951,0.089489,0.000000
70.670006,47.748947,-186.953430,-0.001138,0.003501,0.088925,212.397919,10.820066,0.889253,-186.953430,0.089923,0.000000
70.930000,48.695518,-186.953430,-0.001117,0.003517,0.089333,216.608490,11.034562,0.893329,-186.953430,0.090356,0.000000
71.190002,49.177742,-186.953430,-0.001112,0.003530,0.089671,218.753525,11.143836,0.896711,-186.953430,0.090790,0.000000
71.450005,50.309006,-186.908951,-0.001108,0.003548,0.090131,223.785629,11.400184,0.901308,-186.908951,0.091223,0.000000
71.710007,51.486076,-186.997925,-0.001087,0.003570,0.090668,229.021500,11.666911,0.906685,-186.997925,0.091657,0.000000
71.970001,52.649742,-186.997925,-0.001082,0.003590,0.091180,234.197754,11.930602,0.911801,-186.997925,0.092091,0.000000
72.230003,53.246284,-186.997925,-0.001061,0.003604,0.091536,236.851303,12.065781,0.915357,-186.997925,0.092524,0.000000
72.490005,53.607483,-187.042404,-0.001048,0.003617,0.091865,238.457993,12.147630,0.918652,-187.042404,0.092958,0.000000
72.750000,54.274773,-187.042404,-0.001043,0.003634,0.092299,241.426239,12.298840,0.922988,-187.042404,0.093392,0.000000
73.010002,55.460777,-187.042404,-0.001022,0.003648,0.092672,246.701859,12.567592,0.926717,-187.042404,0.093825,0.000000
73.270004,56.856056,-187.086884,-0.001030,0.003671,0.093235,252.908371,12.883766,0.932354,-187.086884,0.094259,0.000000
73.530006,57.874496,-187.042404,-0.001005,0.003687,0.093660,257.438629,13.114549,0.936604,-187.042404,0.094692,0.000000
73.790001,59.311111,-187.086884,-0.001005,0.003709,0.094207,263.829010,13.440090,0.942067,-187.086884,0.095126,0.000000
74.050003,60.112831,-187.086884,-0.001000,0.003725,0.094623,267.395233,13.621762,0.946230,-187.086884,0.095560,0.000000
74.310005,60.889969,-187.220322,-0.000983,0.003740,0.094996,270.852112,13.797864,0.949959,-187.220322,0.095993,0.000000
74.570007,61.958305,-187.131363,-0.000983,0.003756,0.095412,275.604309,14.039953,0.954122,-187.131363,0.096427,0.000000
74.830002,62.674377,-187.175842,-0.000953,0.003770,0.095759,278.789551,14.202217,0.957591,-187.175842,0.096860,0.000000
75.090004,63.440346,-187.264801,-0.000970,0.003786,0.096167,282.196747,14.375788,0.961667,-187.264801,0.097294,0.000000
75.350006,64.799889,-187.175842,-0.000949,0.003805,0.096635,288.244293,14.683865,0.966350,-187.175842,0.097728,0.000000
75.610001,66.519875,-187.220322,-0.000944,0.003828,0.097242,295.895172,15.073619,0.972420,-187.220322,0.098161,0.000000
75.870003,67.488045,-187.175842,-0.000944,0.003844,0.097632,300.201813,15.293010,0.976323,-187.175842,0.098586,0.000000
76.130005,66.701958,-187.220322,-0.000931,0.003836,0.097424,296.705139,15.114880,0.974241,-187.220322,0.097650,0.000000
76.390007,66.086800,-187.309280,-0.000923,0.003835,0.097407,293.968781,14.975483,0.974068,-187.309280,0.097424,0.000000
76.650002,65.521538,-187.220322,-0.000910,0.003834,0.097389,291.454346,14.847392,0.973894,-187.220322,0.097424,0.000000
76.910004,64.989784,-187.353760,-0.000914,0.003834,0.097381,289.088989,14.726895,0.973808,-187.353760,0.097424,0.000000
77.170006,64.561928,-187.309280,-0.000905,0.003834,0.097372,287.185791,14.629942,0.973721,-187.309280,0.097424,0.000000
77.430000,64.154182,-187.353760,-0.000897,0.003834,0.097372,285.372070,14.537545,0.973721,-187.353760,0.097424,0.000000
77.690002,63.793724,-187.353760,-0.000918,0.003834,0.097372,283.768646,14.455864,0.973721,-187.353760,0.097424,0.000000
77.950005,63.472374,-187.353760,-0.000905,0.003834,0.097372,282.339233,14.383045,0.973721,-187.353760,0.097424,0.000000
78.210007,63.165916,-187.398254,-0.000901,0.003833,0.097363,280.976044,14.313601,0.973634,-187.398254,0.097424,0.000000
78.470001,62.903015,-187.353760,-0.000901,0.003833,0.097363,279.806580,14.254027,0.973634,-187.353760,0.097424,0.000000
78.730003,62.653526,-187.398254,-0.000901,0.003833,0.097363,278.696808,14.197493,0.973634,-187.398254,0.097424,0.000000
78.990005,62.430473,-187.442734,-0.000901,0.003833,0.097363,277.704620,14.146948,0.973634,-187.442734,0.097424,0.000000
79.250000,62.212639,-187.398254,-0.000901,0.003833,0.097363,276.735626,14.097586,0.973634,-187.398254,0.097424,0.000000
79.510002,62.012672,-187.442734,-0.000892,0.003833,0.097363,275.846130,14.052272,0.973634,-187.442734,0.097424,0.000000
79.770004,61.840263,-187.487213,-0.000875,0.003833,0.097363,275.079224,14.013205,0.973634,-187.487213,0.097424,0.000000
80.030006,61.652214,-187.531693,-0.000897,0.003833,0.097363,274.242737,13.970592,0.973634,-187.531693,0.097424,0.000000
80.290001,61.515930,-187.487213,-0.000888,0.003833,0.097363,273.636536,13.939709,0.973634,-187.487213,0.097424,0.000000
80.550003,61.330856,-187.531693,-0.000884,0.003833,0.097363,272.813263,13.897771,0.973634,-187.531693,0.097424,0.000000
80.810005,61.199409,-187.576172,-0.000884,0.003833,0.097363,272.228577,13.867984,0.973634,-187.576172,0.097424,0.000000
81.070007,61.059402,-187.531693,-0.000875,0.003833,0.097363,271.605774,13.836259,0.973634,-187.531693,0.097424,0.000000
81.330002,60.932793,-187.531693,-0.000884,0.003833,0.097363,271.042603,13.807569,0.973634,-187.531693,0.097424,0.000000
81.590004,60.803581,-187.531693,-0.000880,0.003833,0.097363,270.467834,13.778289,0.973634,-187.531693,0.097424,0.000000
81.850006,60.677719,-187.620651,-0.000888,0.003833,0.097363,269.907990,13.749767,0.973634,-187.620651,0.097424,0.000000
82.110001,60.574944,-187.576172,-0.000875,0.003833,0.097363,269.450806,13.726478,0.973634,-187.576172,0.097424,0.000000
82.370003,60.447594,-187.576172,-0.000875,0.003833,0.097363,268.884338,13.697620,0.973634,-187.576172,0.097424,0.000000
82.630005,60.349655,-187.709610,-0.000888,0.003833,0.097363,268.448669,13.675427,0.973634,-187.709610,0.097424,0.000000
82.890007,60.248001,-187.576172,-0.000875,0.003833,0.097363,267.996490,13.652391,0.973634,-187.576172,0.097424,0.000000
83.150002,60.149323,-187.754089,-0.000888,0.003833,0.097363,267.557556,13.630032,0.973634,-187.754089,0.097424,0.000000
83.410004,60.074104,-187.709610,-0.000875,0.003833,0.097363,267.222961,13.612987,0.973634,-187.709610,0.097424,0.000000
83.670006,59.956436,-187.665131,-0.000871,0.003833,0.097363,266.699554,13.586323,0.973634,-187.665131,0.097424,0.000000
83.930000,59.886055,-187.709610,-0.000884,0.003833,0.097363,266.386475,13.570374,0.973634,-187.709610,0.097424,0.000000
84.190002,59.789612,-187.665131,-0.000875,0.003833,0.097363,265.957489,13.548519,0.973634,-187.665131,0.097424,0.000000
84.450005,59.722580,-187.798569,-0.000880,0.003833,0.097363,265.659302,13.533330,0.973634,-187.798569,0.097424,0.000000
84.710007,59.633217,-187.754089,-0.000871,0.003833,0.097363,265.261810,13.513080,0.973634,-187.754089,0.097424,0.000000
84.970001,59.561714,-187.843063,-0.000871,0.003833,0.097363,264.943726,13.496878,0.973634,-187.843063,0.097424,0.000000
85.230003,59.476074,-187.843063,-0.000880,0.003833,0.097363,264.562805,13.477470,0.973634,-187.843063,0.097424,0.000000
85.490005,59.414627,-187.798569,-0.000875,0.003833,0.097363,264.289459,13.463548,0.973634,-187.798569,0.097424,0.000000
85.750008,59.355423,-187.932022,-0.000875,0.003833,0.097363,264.026123,13.450131,0.973634,-187.932022,0.097424,0.000000
86.010002,59.266426,-187.843063,-0.000862,0.003833,0.097363,263.630219,13.429964,0.973634,-187.843063,0.097424,0.000000
86.270004,59.205727,-187.843063,-0.000875,0.003833,0.097363,263.360229,13.416210,0.973634,-187.843063,0.097424,0.000000
86.530006,59.150620,-187.887543,-0.000867,0.003833,0.097363,263.115082,13.403722,0.973634,-187.887543,0.097424,0.000000
86.790001,59.083595,-187.843063,-0.000867,0.003833,0.097363,262.816956,13.388534,0.973634,-187.843063,0.097424,0.000000
87.050003,59.030716,-188.020981,-0.000875,0.003833,0.097363,262.581726,13.376552,0.973634,-188.020981,0.097424,0.000000
87.310005,58.963318,-187.887543,-0.000871,0.003833,0.097355,262.281952,13.361279,0.973548,-187.887543,0.097424,0.000000
87.570007,58.919373,-187.976501,-0.000862,0.003833,0.097355,262.086456,13.351321,0.973548,-187.976501,0.097424,0.000000
87.830002,58.841919,-187.976501,-0.000867,0.003833,0.097355,261.741913,13.333770,0.973548,-187.976501,0.097424,0.000000
88.090004,58.797981,-187.976501,-0.000867,0.003833,0.097355,261.546478,13.323813,0.973548,-187.976501,0.097424,0.000000
88.350006,58.741379,-188.109940,-0.000871,0.003833,0.097355,261.294708,13.310987,0.973548,-188.109940,0.097424,0.000000
88.610001,58.684410,-188.020981,-0.000862,0.003833,0.097355,261.041290,13.298078,0.973548,-188.020981,0.097424,0.000000
88.870003,58.646423,-188.065460,-0.000867,0.003833,0.097355,260.872314,13.289470,0.973548,-188.065460,0.097424,0.000000
89.130005,58.585358,-188.065460,-0.000867,0.003833,0.097355,260.600677,13.275632,0.973548,-188.065460,0.097424,0.000000
89.390007,58.555199,-188.065460,-0.000862,0.003833,0.097355,260.466522,13.268798,0.973548,-188.065460,0.097424,0.000000
89.650002,58.493011,-188.109940,-0.000871,0.003833,0.097355,260.189911,13.254705,0.973548,-188.109940,0.097424,0.000000
89.910004,58.459122,-188.109940,-0.000858,0.003833,0.097355,260.039154,13.247026,0.973548,-188.109940,0.097424,0.000000
90.170006,58.405128,-188.154419,-0.000862,0.003833,0.097355,259.798981,13.234791,0.973548,-188.154419,0.097424,0.000000
90.430008,58.339592,-188.154419,-0.000875,0.003833,0.097355,259.507477,13.219941,0.973548,-188.154419,0.097424,0.000000
90.690002,58.317245,-188.109940,-0.000871,0.003833,0.097355,259.408051,13.214877,0.973548,-188.109940,0.097424,0.000000
90.950005,58.269958,-188.198898,-0.000871,0.003833,0.097355,259.197723,13.204162,0.973548,-188.198898,0.097424,0.000000
91.210007,58.223038,-188.154419,-0.000862,0.003833,0.097355,258.989014,13.193529,0.973548,-188.154419,0.097424,0.000000
91.470001,58.192505,-188.243378,-0.000867,0.003833,0.097355,258.853180,13.186610,0.973548,-188.243378,0.097424,0.000000
91.730003,58.132927,-188.198898,-0.000867,0.003833,0.097355,258.588165,13.173110,0.973548,-188.198898,0.097424,0.000000
91.990005,58.117661,-188.243378,-0.000858,0.003833,0.097355,258.520264,13.169650,0.973548,-188.243378,0.097424,0.000000
92.250008,58.059937,-188.287872,-0.000880,0.003833,0.097355,258.263489,13.156569,0.973548,-188.287872,0.097424,0.000000
92.510002,58.027168,-188.287872,-0.000862,0.003833,0.097355,258.117737,13.149144,0.973548,-188.287872,0.097424,0.000000
92.770004,57.989937,-188.287872,-0.000858,0.003833,0.097355,257.952118,13.140708,0.973548,-188.287872,0.097424,0.000000
93.030006,57.933708,-188.332352,-0.000858,0.003833,0.097355,257.701996,13.127966,0.973548,-188.332352,0.097424,0.000000
93.290001,57.915085,-188.287872,-0.000854,0.003833,0.097355,257.619171,13.123746,0.973548,-188.287872,0.097424,0.000000
93.550003,57.875244,-188.332352,-0.000862,0.003833,0.097355,257.441956,13.114717,0.973548,-188.332352,0.097424,0.000000
93.810005,57.840240,-188.376831,-0.000854,0.003833,0.097355,257.286224,13.106786,0.973548,-188.376831,0.097424,0.000000
94.070007,57.802628,-188.421310,-0.000867,0.003833,0.097355,257.118927,13.098263,0.973548,-188.421310,0.097424,0.000000
94.330002,57.760551,-188.332352,-0.000854,0.003833,0.097355,256.931763,13.088728,0.973548,-188.332352,0.097424,0.000000
94.590004,57.734856,-188.421310,-0.000849,0.003833,0.097355,256.817474,13.082905,0.973548,-188.421310,0.097424,0.000000
94.850006,57.685333,-188.421310,-0.000867,0.003833,0.097355,256.597168,13.071683,0.973548,-188.421310,0.097424,0.000000
95.110008,57.673042,-188.376831,-0.000854,0.003833,0.097355,256.542511,13.068898,0.973548,-188.376831,0.097424,0.000000
95.370003,57.635811,-188.465790,-0.000867,0.003833,0.097355,256.376892,13.060461,0.973548,-188.465790,0.097424,0.000000
95.630005,57.601173,-188.421310,-0.000854,0.003833,0.097355,256.222809,13.052613,0.973548,-188.421310,0.097424,0.000000
95.890007,57.575111,-188.510269,-0.000854,0.003833,0.097355,256.106873,13.046706,0.973548,-188.510269,0.097424,0.000000
96.150002,57.528564,-188.510269,-0.000862,0.003833,0.097355,255.899841,13.036160,0.973548,-188.510269,0.097424,0.000000
96.410004,57.507713,-188.510269,-0.000849,0.003833,0.097355,255.807083,13.031434,0.973548,-188.510269,0.097424,0.000000
96.670006,57.468987,-188.599228,-0.000862,0.003833,0.097355,255.634827,13.022658,0.973548,-188.599228,0.097424,0.000000
96.930008,57.437332,-188.510269,-0.000867,0.003833,0.097355,255.494019,13.015486,0.973548,-188.510269,0.097424,0.000000
97.190002,57.414619,-188.599228,-0.000862,0.003833,0.097355,255.392990,13.010338,0.973548,-188.599228,0.097424,0.000000
97.450005,57.374405,-188.554749,-0.000871,0.003833,0.097355,255.214096,13.001226,0.973548,-188.554749,0.097424,0.000000
97.710007,57.365837,-188.554749,-0.000849,0.003833,0.097355,255.175995,12.999285,0.973548,-188.554749,0.097424,0.000000
97.970001,57.327858,-188.599228,-0.000862,0.003833,0.097355,255.007050,12.990678,0.973548,-188.599228,0.097424,0.000000
98.230003,57.304398,-188.554749,-0.000854,0.003833,0.097355,254.902695,12.985362,0.973548,-188.554749,0.097424,0.000000
98.490005,57.282425,-188.643707,-0.000858,0.003833,0.097355,254.804947,12.980383,0.973548,-188.643707,0.097424,0.000000
98.750008,57.239601,-188.599228,-0.000862,0.003833,0.097355,254.614456,12.970679,0.973548,-188.599228,0.097424,0.000000
99.010002,57.219124,-188.688202,-0.000862,0.003833,0.097355,254.523376,12.966039,0.973548,-188.688202,0.097424,0.000000
99.270004,57.186356,-188.643707,-0.000854,0.003833,0.097355,254.377609,12.958613,0.973548,-188.643707,0.097424,0.000000
99.530006,57.166992,-188.688202,-0.000849,0.003833,0.097355,254.291489,12.954226,0.973548,-188.688202,0.097424,0.000000
99.790009,57.134598,-188.732681,-0.000858,0.003833,0.097355,254.147385,12.946885,0.973548,-188.732681,0.097424,0.000000
100.050003,57.117462,-188.732681,-0.000858,0.003833,0.097355,254.071167,12.943002,0.973548,-188.732681,0.097424,0.000000
100.310005,57.102570,-188.688202,-0.000845,0.003833,0.097355,254.004913,12.939628,0.973548,-188.688202,0.097424,0.000000
100.570007,57.056023,-188.732681,-0.000858,0.003833,0.097355,253.797867,12.929079,0.973548,-188.732681,0.097424,0.000000
100.830002,57.039642,-188.777161,-0.000854,0.003833,0.097355,253.725006,12.925368,0.973548,-188.777161,0.097424,0.000000
101.090004,57.020645,-188.732681,-0.000875,0.003833,0.097355,253.640503,12.921063,0.973548,-188.732681,0.097424,0.000000
101.350006,56.986763,-188.777161,-0.000849,0.003833,0.097355,253.489777,12.913385,0.973548,-188.777161,0.097424,0.000000
101.610008,56.967773,-188.777161,-0.000849,0.003833,0.097355,253.405319,12.909082,0.973548,-188.777161,0.097424,0.000000
101.870003,56.940964,-188.821640,-0.000858,0.003833,0.097355,253.286057,12.903007,0.973548,-188.821640,0.097424,0.000000
102.130005,56.923828,-188.777161,-0.000854,0.003833,0.097355,253.209839,12.899124,0.973548,-188.777161,0.097424,0.000000
102.390007,56.902603,-188.866119,-0.000858,0.003833,0.097355,253.115417,12.894315,0.973548,-188.866119,0.097424,0.000000
102.650002,56.875420,-188.910599,-0.000849,0.003833,0.097355,252.994507,12.888155,0.973548,-188.910599,0.097424,0.000000
102.910004,56.851967,-188.866119,-0.000849,0.003833,0.097355,252.890182,12.882840,0.973548,-188.866119,0.097424,0.000000
103.170006,56.834831,-188.866119,-0.000858,0.003833,0.097355,252.813950,12.878957,0.973548,-188.866119,0.097424,0.000000
103.430008,56.821060,-188.910599,-0.000849,0.003833,0.097355,252.752701,12.875836,0.973548,-188.910599,0.097424,0.000000
103.690002,56.810257,-188.955078,-0.000858,0.003833,0.097355,252.704651,12.873388,0.973548,-188.955078,0.097424,0.000000
103.950005,56.755516,-188.866119,-0.000845,0.003833,0.097355,252.461151,12.860984,0.973548,-188.866119,0.097424,0.000000
104.210007,56.756264,-188.955078,-0.000862,0.003833,0.097355,252.464478,12.861153,0.973548,-188.955078,0.097424,0.000000
104.470001,56.724243,-188.910599,-0.000854,0.003833,0.097355,252.322037,12.853897,0.973548,-188.910599,0.097424,0.000000
104.730003,56.708603,-188.999557,-0.000849,0.003833,0.097355,252.252457,12.850353,0.973548,-188.999557,0.097424,0.000000
104.990005,56.692215,-188.999557,-0.000862,0.003833,0.097355,252.179565,12.846639,0.973548,-188.999557,0.097424,0.000000
105.250008,56.668015,-188.955078,-0.000858,0.003833,0.097355,252.071915,12.841156,0.973548,-188.955078,0.097424,0.000000
105.510002,56.649765,-189.133011,-0.000867,0.003833,0.097355,251.990738,12.837021,0.973548,-189.133011,0.097424,0.000000
105.770004,56.617744,-188.999557,-0.000862,0.003833,0.097355,251.848312,12.829764,0.973548,-188.999557,0.097424,0.000000
106.030006,56.609924,-189.044037,-0.000845,0.003833,0.097355,251.813522,12.827992,0.973548,-189.044037,0.097424,0.000000
106.290009,56.585716,-189.133011,-0.000858,0.003833,0.097355,251.705841,12.822507,0.973548,-189.133011,0.097424,0.000000
106.400002,56.573425,-189.088516,-0.000858,0.003833,0.097355,251.651169,12.819721,0.973548,-189.088516,0.097424,0.000000