File: Data/compression 11/AutoNoHeating-16-11-1-240530_05302024_172602.csv
Time (sec),S:Load (lbs),S:HL1 (DIM),S:LVDT (in),S:Position (in),Ch:Position (mm),Ch:Load (N),Ch:Stress (MPa),Ch:Strain (mm/mm),Ch:HL1 (DIM),Set Point (),Cycles ()
0.110000,-0.004097,-335.653259,-0.009860,-0.000000,-0.000000,-0.018224,-0.000928,-0.000000,-335.653259,-0.000165,0.000000
0.340000,-0.004837,-335.697723,-0.009856,-0.000000,-0.000000,-0.021516,-0.001096,-0.000000,-335.697723,0.000182,0.000000
0.570000,0.018250,-335.653259,-0.009878,0.000121,0.003061,0.081178,0.004135,0.030613,-335.653259,0.004015,0.000000
0.800000,-0.006332,-335.608765,-0.009817,0.000262,0.006652,-0.028168,-0.001435,0.066516,-335.608765,0.007831,0.000000
1.030000,0.010429,-335.653259,-0.009641,0.000417,0.010580,0.046392,0.002363,0.105802,-335.653259,0.011664,0.000000
1.260000,0.020851,-335.653259,-0.009503,0.000564,0.014335,0.092750,0.004725,0.143352,-335.653259,0.015497,0.000000
1.490000,0.018990,-335.697723,-0.009360,0.000709,0.018021,0.084470,0.004303,0.180209,-335.697723,0.019330,0.000000
1.720000,0.003349,-335.742218,-0.009218,0.000864,0.021958,0.014898,0.000759,0.219582,-335.742218,0.023164,0.000000
1.950000,-0.051010,-335.697723,-0.009041,0.001022,0.025947,-0.226904,-0.011559,0.259474,-335.697723,0.026997,0.000000
2.180000,-0.066284,-335.742218,-0.008899,0.001164,0.029555,-0.294847,-0.015020,0.295550,-335.742218,0.030830,0.000000
2.410000,-0.007446,-335.742218,-0.008739,0.001314,0.033371,-0.033123,-0.001687,0.333708,-335.742218,0.034663,0.000000
2.640000,0.039101,-335.786713,-0.008589,0.001466,0.037247,0.173928,0.008860,0.372473,-335.786713,0.038496,0.000000
2.870000,0.030907,-335.742218,-0.008429,0.001625,0.041280,0.137480,0.007004,0.412799,-335.742218,0.042329,0.000000
3.100000,0.016388,-335.786713,-0.008274,0.001774,0.045070,0.072897,0.003714,0.450697,-335.786713,0.046162,0.000000
3.330000,0.014153,-335.786713,-0.008127,0.001922,0.048825,0.062954,0.003207,0.488248,-335.786713,0.049996,0.000000
3.560000,-0.007820,-335.786713,-0.007976,0.002072,0.052632,-0.034786,-0.001772,0.526319,-335.786713,0.053829,0.000000
3.790000,0.015266,-335.831177,-0.007838,0.002218,0.056335,0.067908,0.003459,0.563350,-335.831177,0.057644,0.000000
4.020000,-0.008194,-335.875671,-0.007692,0.002372,0.060255,-0.036449,-0.001857,0.602548,-335.875671,0.061478,0.000000
4.250000,-0.004837,-335.786713,-0.007528,0.002527,0.064175,-0.021516,-0.001096,0.641747,-335.786713,0.065311,0.000000
4.480000,-0.027184,-335.831177,-0.007360,0.002675,0.067938,-0.120918,-0.006160,0.679385,-335.831177,0.069144,0.000000
4.710000,0.002235,-335.875671,-0.007226,0.002824,0.071728,0.009944,0.000507,0.717282,-335.875671,0.072977,0.000000
4.940000,0.018623,-335.875671,-0.007062,0.002976,0.075596,0.082841,0.004220,0.755961,-335.875671,0.076810,0.000000
5.170000,0.040215,-335.875671,-0.006924,0.003125,0.079368,0.178883,0.009113,0.793685,-335.875671,0.080643,0.000000
5.400000,0.033890,-335.831177,-0.006765,0.003279,0.083297,0.150749,0.007680,0.832970,-335.831177,0.084476,0.000000
5.630000,0.004845,-335.875671,-0.006605,0.003431,0.087139,0.021550,0.001098,0.871388,-335.875671,0.088310,0.000000
5.860000,0.007446,-335.920135,-0.006450,0.003578,0.090877,0.033123,0.001687,0.908766,-335.920135,0.092143,0.000000
6.090000,0.021973,-335.920135,-0.006321,0.003730,0.094753,0.097739,0.004979,0.947531,-335.920135,0.095976,0.000000
6.320000,0.021973,-335.875671,-0.006153,0.003880,0.098560,0.097739,0.004979,0.985602,-335.875671,0.099809,0.000000
6.550000,-0.000740,-335.920135,-0.006010,0.004034,0.102454,-0.003292,-0.000168,1.024540,-335.920135,0.103625,0.000000
6.780000,0.044685,-335.920135,-0.005846,0.004181,0.106192,0.198770,0.010126,1.061918,-335.920135,0.107458,0.000000
7.010000,0.004097,-335.964630,-0.005691,0.004336,0.110138,0.018224,0.000928,1.101377,-335.964630,0.111291,0.000000
7.240000,0.021973,-335.964630,-0.005545,0.004489,0.114014,0.097739,0.004979,1.140142,-335.964630,0.115124,0.000000
7.470000,0.013405,-335.964630,-0.005407,0.004634,0.117700,0.059628,0.003038,1.176999,-335.964630,0.118957,0.000000
7.700000,0.038353,-335.920135,-0.005247,0.004786,0.121559,0.170603,0.008691,1.215590,-335.920135,0.122790,0.000000
7.930000,0.021225,-335.964630,-0.005075,0.004939,0.125453,0.094413,0.004810,1.254529,-335.964630,0.126624,0.000000
8.160001,-0.011169,-336.053589,-0.004924,0.005093,0.129364,-0.049684,-0.002531,1.293640,-336.053589,0.130457,0.000000
8.390000,-0.018616,-336.098053,-0.004786,0.005239,0.133076,-0.082807,-0.004218,1.330758,-336.098053,0.134290,0.000000
8.620001,0.024208,-335.920135,-0.004631,0.005392,0.136952,0.107683,0.005486,1.369523,-335.920135,0.138123,0.000000
8.850000,0.080063,-336.053589,-0.004475,0.005538,0.140673,0.356137,0.018143,1.406727,-336.053589,0.141956,0.000000
9.080001,0.162354,-336.098053,-0.004320,0.005693,0.144593,0.722184,0.036790,1.445925,-336.098053,0.145789,0.000000
9.310000,0.639366,-336.098053,-0.004230,-0.000004,-0.000104,2.844043,0.144882,-0.001041,-336.098053,0.000139,0.000000
9.540001,0.599518,-336.053589,-0.004230,-0.000004,-0.000104,2.666789,0.135853,-0.001041,-336.053589,0.000139,0.000000
9.770000,0.651657,-336.009094,-0.004217,-0.000004,-0.000104,2.898715,0.147668,-0.001041,-336.009094,0.000173,0.000000
10.000000,0.618515,-336.009094,-0.004221,-0.000004,-0.000104,2.751292,0.140158,-0.001041,-336.009094,0.000555,0.000000
10.230000,0.597656,-336.098053,-0.004221,-0.000004,-0.000095,2.658508,0.135431,-0.000954,-336.098053,0.000937,0.000000
10.460000,0.608086,-336.142548,-0.004230,-0.000004,-0.000095,2.704900,0.137794,-0.000954,-336.142548,0.001318,0.000000
10.690001,0.596916,-336.098053,-0.004230,-0.000004,-0.000095,2.655216,0.135263,-0.000954,-336.098053,0.001708,0.000000
10.920000,1.229202,-336.098053,-0.004195,0.000048,0.001223,5.467765,0.278541,0.012228,-336.098053,0.002090,0.000000
11.150001,1.391556,-336.098053,-0.004182,0.000060,0.001535,6.189950,0.315331,0.015350,-336.098053,0.002472,0.000000
11.380000,1.490608,-336.187042,-0.004156,0.000074,0.001882,6.630557,0.337777,0.018819,-336.187042,0.002853,0.000000
11.610001,1.766533,-336.187042,-0.004169,0.000091,0.002307,7.857931,0.400302,0.023068,-336.187042,0.003235,0.000000
11.840000,1.998528,-336.142548,-0.004139,0.000109,0.002766,8.889894,0.452873,0.027664,-336.142548,0.003625,0.000000
12.070001,2.145241,-336.187042,-0.004135,0.000120,0.003053,9.542507,0.486119,0.030526,-336.187042,0.004007,0.000000
12.300000,2.346695,-336.142548,-0.004118,0.000132,0.003365,10.438621,0.531769,0.033648,-336.142548,0.004388,0.000000
12.530001,2.626717,-336.187042,-0.004109,0.000149,0.003772,11.684219,0.595223,0.037724,-336.187042,0.004770,0.000000
12.760000,3.046379,-336.231506,-0.004092,0.000173,0.004397,13.550971,0.690319,0.043968,-336.231506,0.005151,0.000000
12.990001,3.146919,-336.187042,-0.004074,0.000183,0.004657,13.998196,0.713102,0.046570,-336.187042,0.005542,0.000000
13.220000,3.326035,-336.187042,-0.004079,0.000199,0.005056,14.794941,0.753690,0.050559,-336.187042,0.005923,0.000000
13.450001,3.526741,-336.187042,-0.004057,0.000212,0.005394,15.687728,0.799171,0.053941,-336.187042,0.006305,0.000000
13.680000,3.717400,-336.320465,-0.004044,0.000228,0.005793,16.535820,0.842375,0.057931,-336.320465,0.006686,0.000000
13.910001,3.949387,-336.276001,-0.004036,0.000240,0.006105,17.567749,0.894944,0.061053,-336.276001,0.007077,0.000000
14.140000,4.028328,-336.320465,-0.004023,0.000251,0.006365,17.918898,0.912832,0.063654,-336.320465,0.007458,0.000000
14.370001,4.359741,-336.231506,-0.004001,0.000269,0.006834,19.393097,0.987931,0.068337,-336.231506,0.007840,0.000000
14.600000,4.442780,-336.320465,-0.003992,0.000281,0.007129,19.762470,1.006748,0.071286,-336.320465,0.008221,0.000000
14.830001,4.834885,-336.320465,-0.003971,0.000302,0.007675,21.506641,1.095600,0.076749,-336.320465,0.008603,0.000000
15.060000,5.000221,-336.276001,-0.003967,0.000317,0.008039,22.242094,1.133066,0.080392,-336.276001,0.008993,0.000000
15.290001,5.146187,-336.320465,-0.003945,0.000332,0.008421,22.891382,1.166143,0.084208,-336.320465,0.009375,0.000000
15.520000,5.264229,-336.320465,-0.003932,0.000345,0.008759,23.416460,1.192891,0.087590,-336.320465,0.009756,0.000000
15.750001,5.555428,-336.364960,-0.003923,0.000364,0.009253,24.711777,1.258878,0.092533,-336.364960,0.010138,0.000000
15.980000,5.694321,-336.364960,-0.003906,0.000378,0.009592,25.329603,1.290352,0.095915,-336.364960,0.010519,0.000000
16.210001,5.743843,-336.320465,-0.003902,0.000389,0.009869,25.549891,1.301573,0.098690,-336.320465,0.010910,0.000000
16.440001,5.872314,-336.320465,-0.003885,0.000403,0.010225,26.121359,1.330685,0.102246,-336.320465,0.011291,0.000000
16.670000,6.185852,-336.364960,-0.003863,0.000423,0.010745,27.516045,1.401734,0.107449,-336.364960,0.011673,0.000000
16.900002,6.348953,-336.364960,-0.003859,0.000438,0.011127,28.241554,1.438693,0.111265,-336.364960,0.012054,0.000000
17.130001,6.395500,-336.453918,-0.003850,0.000453,0.011517,28.448606,1.449241,0.115168,-336.453918,0.012436,0.000000
17.360001,6.412254,-336.364960,-0.003820,0.000465,0.011820,28.523132,1.453038,0.118203,-336.364960,0.012826,0.000000
17.590000,6.491196,-336.320465,-0.003820,0.000476,0.012098,28.874281,1.470926,0.120978,-336.320465,0.013208,0.000000
17.820002,6.783882,-336.409424,-0.003794,0.000497,0.012618,30.176214,1.537250,0.126181,-336.409424,0.013589,0.000000
18.050001,6.718719,-336.453918,-0.003781,0.000507,0.012870,29.886356,1.522484,0.128696,-336.453918,0.013971,0.000000
18.280001,6.946609,-336.498383,-0.003773,0.000525,0.013338,30.900063,1.574124,0.133379,-336.498383,0.014353,0.000000
18.510000,7.027786,-336.409424,-0.003760,0.000539,0.013685,31.261154,1.592519,0.136848,-336.409424,0.014743,0.000000
18.740002,7.251953,-336.453918,-0.003742,0.000556,0.014118,32.258297,1.643316,0.141184,-336.453918,0.015124,0.000000
18.970001,7.323448,-336.498383,-0.003721,0.000573,0.014543,32.576324,1.659517,0.145434,-336.498383,0.015506,0.000000
19.200001,7.378563,-336.498383,-0.003708,0.000589,0.014960,32.821487,1.672006,0.149596,-336.498383,0.015888,0.000000
19.430000,7.393829,-336.587372,-0.003712,0.000601,0.015254,32.889397,1.675466,0.152545,-336.587372,0.016269,0.000000
19.660002,7.476120,-336.498383,-0.003695,0.000617,0.015662,33.255444,1.694113,0.156621,-336.498383,0.016659,0.000000
19.890001,7.524902,-336.498383,-0.003669,0.000628,0.015957,33.472439,1.705167,0.159570,-336.498383,0.017041,0.000000
20.120001,7.742744,-336.542877,-0.003660,0.000647,0.016425,34.441448,1.754531,0.164253,-336.542877,0.017423,0.000000
20.350000,7.787056,-336.587372,-0.003643,0.000662,0.016816,34.638554,1.764572,0.168155,-336.587372,0.017804,0.000000
20.580002,7.835091,-336.542877,-0.003639,0.000677,0.017188,34.852222,1.775457,0.171884,-336.542877,0.018186,0.000000
20.810001,8.058517,-336.587372,-0.003609,0.000696,0.017674,35.846077,1.826086,0.176741,-336.587372,0.018576,0.000000
21.040001,8.028351,-336.542877,-0.003591,0.000711,0.018047,35.711887,1.819250,0.180470,-336.542877,0.018958,0.000000
21.270000,8.014572,-336.676331,-0.003583,0.000723,0.018359,35.650597,1.816128,0.183592,-336.676331,0.019339,0.000000
21.500002,8.197784,-336.587372,-0.003579,0.000740,0.018784,36.465565,1.857645,0.187841,-336.587372,0.019721,0.000000
21.730001,8.208580,-336.587372,-0.003570,0.000752,0.019105,36.513588,1.860091,0.191050,-336.587372,0.020102,0.000000
21.960001,8.246933,-336.631836,-0.003557,0.000767,0.019469,36.684189,1.868782,0.194692,-336.631836,0.020493,0.000000
22.190001,8.278587,-336.631836,-0.003535,0.000779,0.019781,36.824997,1.875955,0.197814,-336.631836,0.020874,0.000000
22.420002,8.545204,-336.631836,-0.003518,0.000802,0.020362,38.010967,1.936371,0.203625,-336.631836,0.021256,0.000000
22.650002,8.658035,-336.720795,-0.003501,0.000819,0.020813,38.512863,1.961939,0.208134,-336.720795,0.021637,0.000000
22.880001,8.575737,-336.676331,-0.003484,0.000833,0.021169,38.146782,1.943290,0.211690,-336.676331,0.022028,0.000000
23.110001,8.557495,-336.676331,-0.003479,0.000845,0.021455,38.065639,1.939156,0.214552,-336.676331,0.022409,0.000000
23.340002,8.537758,-336.676331,-0.003458,0.000858,0.021785,37.977844,1.934684,0.217847,-336.676331,0.022791,0.000000
23.570002,8.927628,-336.720795,-0.003449,0.000878,0.022314,39.712070,2.023029,0.223137,-336.720795,0.023172,0.000000
23.800001,8.814430,-336.676331,-0.003436,0.000889,0.022591,39.208546,1.997378,0.225912,-336.676331,0.023554,0.000000
24.030001,8.938431,-336.720795,-0.003419,0.000904,0.022964,39.760124,2.025477,0.229641,-336.720795,0.023944,0.000000
24.260000,8.969711,-336.765289,-0.003410,0.000918,0.023311,39.899269,2.032566,0.233110,-336.765289,0.024326,0.000000
24.490002,9.221062,-336.765289,-0.003380,0.000938,0.023823,41.017330,2.089523,0.238227,-336.765289,0.024707,0.000000
24.720001,9.218079,-336.765289,-0.003367,0.000953,0.024213,41.004063,2.088846,0.242129,-336.765289,0.025089,0.000000
24.950001,9.122383,-336.765289,-0.003354,0.000964,0.024482,40.578388,2.067162,0.244818,-336.765289,0.025470,0.000000
25.180000,9.020355,-336.809753,-0.003367,0.000976,0.024794,40.124542,2.044042,0.247940,-336.809753,0.025861,0.000000
25.410002,9.454536,-336.720795,-0.003333,0.000998,0.025349,42.055878,2.142429,0.253490,-336.720795,0.026242,0.000000
25.640001,9.511139,-336.720795,-0.003316,0.001011,0.025679,42.307659,2.155255,0.256785,-336.720795,0.026624,0.000000
25.870001,9.394211,-336.898712,-0.003311,0.001021,0.025921,41.787537,2.128759,0.259214,-336.898712,0.027005,0.000000
26.100000,9.564758,-336.854248,-0.003294,0.001040,0.026407,42.546169,2.167405,0.264070,-336.854248,0.027387,0.000000
26.330002,9.825424,-336.809753,-0.003281,0.001058,0.026884,43.705669,2.226473,0.268840,-336.809753,0.027777,0.000000
26.560001,9.857445,-336.765289,-0.003264,0.001073,0.027266,43.848103,2.233729,0.272656,-336.765289,0.028159,0.000000
26.790001,9.828026,-336.854248,-0.003247,0.001087,0.027621,43.717243,2.227063,0.276211,-336.854248,0.028540,0.000000
27.020000,9.892075,-336.898712,-0.003229,0.001101,0.027968,44.002144,2.241576,0.279680,-336.898712,0.028922,0.000000
27.250002,9.851112,-336.898712,-0.003216,0.001115,0.028332,43.819935,2.232294,0.283323,-336.898712,0.029304,0.000000
27.480001,10.086082,-336.854248,-0.003208,0.001131,0.028723,44.865135,2.285539,0.287225,-336.854248,0.029694,0.000000
27.710001,10.057411,-336.854248,-0.003186,0.001141,0.028983,44.737598,2.279042,0.289827,-336.854248,0.030075,0.000000
27.940001,10.320305,-336.898712,-0.003165,0.001161,0.029494,45.907009,2.338614,0.294943,-336.898712,0.030457,0.000000
28.170002,10.513939,-336.898712,-0.003160,0.001179,0.029954,46.768337,2.382493,0.299540,-336.898712,0.030839,0.000000
28.400002,10.434998,-336.898712,-0.003152,0.001191,0.030240,46.417187,2.364604,0.302402,-336.898712,0.031220,0.000000
28.630001,10.426056,-336.854248,-0.003130,0.001202,0.030535,46.377415,2.362578,0.305350,-336.854248,0.031610,0.000000
28.860001,10.635330,-336.943207,-0.003126,0.001221,0.031003,47.308311,2.410000,0.310033,-336.943207,0.031992,0.000000
29.090002,10.670708,-336.987671,-0.003104,0.001235,0.031368,47.465679,2.418017,0.313676,-336.987671,0.032374,0.000000
29.320002,10.888542,-336.987671,-0.003096,0.001254,0.031862,48.434654,2.467379,0.318619,-336.987671,0.032755,0.000000
29.550001,10.954079,-336.987671,-0.003083,0.001266,0.032165,48.726177,2.482230,0.321654,-336.987671,0.033137,0.000000
29.780001,11.014778,-336.987671,-0.003065,0.001283,0.032582,48.996181,2.495985,0.325817,-336.987671,0.033527,0.000000
30.010002,10.967117,-336.987671,-0.003053,0.001295,0.032885,48.784176,2.485184,0.328852,-336.987671,0.033909,0.000000
30.240002,11.087395,-337.032166,-0.003040,0.001310,0.033284,49.319195,2.512439,0.332841,-337.032166,0.034290,0.000000
30.470001,11.305977,-336.987671,-0.003027,0.001326,0.033683,50.291496,2.561971,0.336830,-336.987671,0.034672,0.000000
30.700001,11.208412,-337.032166,-0.003018,0.001338,0.033995,49.857506,2.539862,0.339952,-337.032166,0.035053,0.000000
30.930002,11.550247,-337.076660,-0.003001,0.001357,0.034472,51.378067,2.617323,0.344722,-337.076660,0.035444,0.000000
31.160002,11.629196,-337.076660,-0.002975,0.001376,0.034941,51.729248,2.635213,0.349405,-337.076660,0.035825,0.000000
31.390001,11.684677,-337.121124,-0.002966,0.001387,0.035235,51.976040,2.647786,0.352354,-337.121124,0.036207,0.000000
31.620001,11.714470,-337.076660,-0.002958,0.001402,0.035600,52.108566,2.654537,0.355996,-337.076660,0.036588,0.000000
31.850002,12.004921,-337.121124,-0.002953,0.001420,0.036068,53.400555,2.720354,0.360679,-337.121124,0.036978,0.000000
32.080002,12.210464,-337.076660,-0.002928,0.001439,0.036545,54.314857,2.766931,0.365449,-337.076660,0.037360,0.000000
32.310001,12.159081,-337.076660,-0.002906,0.001451,0.036857,54.086292,2.755287,0.368571,-337.076660,0.037742,0.000000
32.540001,12.148651,-337.121124,-0.002893,0.001464,0.037195,54.039898,2.752924,0.371953,-337.121124,0.038123,0.000000
32.770000,12.158707,-337.121124,-0.002893,0.001477,0.037525,54.084629,2.755202,0.375249,-337.121124,0.038505,0.000000
33.000000,12.448410,-337.165619,-0.002880,0.001496,0.038011,55.373295,2.820850,0.380105,-337.165619,0.038895,0.000000
33.230003,12.614494,-337.165619,-0.002846,0.001511,0.038375,56.112072,2.858485,0.383747,-337.165619,0.039277,0.000000
33.460003,12.620819,-337.165619,-0.002841,0.001523,0.038696,56.140205,2.859919,0.386956,-337.165619,0.039658,0.000000
33.690002,12.574272,-337.210083,-0.002828,0.001535,0.038990,55.933155,2.849371,0.389905,-337.210083,0.040040,0.000000
33.920002,12.824135,-337.165619,-0.002815,0.001550,0.039372,57.044601,2.905991,0.393720,-337.165619,0.040421,0.000000
34.150002,13.405785,-337.210083,-0.002802,0.001576,0.040031,59.631908,3.037794,0.400311,-337.210083,0.040812,0.000000
34.380001,13.199120,-337.165619,-0.002772,0.001586,0.040291,58.712616,2.990963,0.402913,-337.165619,0.041193,0.000000
34.610001,13.316414,-337.210083,-0.002768,0.001603,0.040725,59.234367,3.017543,0.407249,-337.210083,0.041575,0.000000
34.840000,13.250504,-337.254578,-0.002759,0.001614,0.040985,58.941185,3.002607,0.409851,-337.254578,0.041956,0.000000
35.070004,13.590103,-337.210083,-0.002755,0.001632,0.041462,60.451797,3.079561,0.414621,-337.210083,0.042338,0.000000
35.300003,13.407272,-337.210083,-0.002729,0.001642,0.041705,59.638527,3.038131,0.417049,-337.210083,0.042728,0.000000
35.530003,13.590103,-337.210083,-0.002712,0.001656,0.042069,60.451797,3.079561,0.420691,-337.210083,0.043110,0.000000
35.760002,13.787094,-337.254578,-0.002703,0.001672,0.042468,61.328056,3.124200,0.424680,-337.254578,0.043491,0.000000
35.990002,14.223137,-337.299042,-0.002703,0.001692,0.042980,63.267673,3.223009,0.429797,-337.299042,0.043873,0.000000
36.220001,14.362778,-337.254578,-0.002686,0.001707,0.043361,63.888824,3.254652,0.433613,-337.254578,0.044255,0.000000
36.450001,14.235054,-337.299042,-0.002677,0.001719,0.043665,63.320683,3.225709,0.436648,-337.299042,0.044645,0.000000
36.680000,14.457733,-337.299042,-0.002643,0.001734,0.044055,64.311211,3.276169,0.440551,-337.299042,0.045026,0.000000
36.910000,14.560883,-337.299042,-0.002639,0.001749,0.044419,64.770042,3.299543,0.444193,-337.299042,0.045408,0.000000
37.140003,14.799202,-337.343536,-0.002617,0.001766,0.044844,65.830139,3.353547,0.448442,-337.343536,0.045790,0.000000
37.370003,14.807022,-337.343536,-0.002604,0.001777,0.045139,65.864922,3.355319,0.451391,-337.343536,0.046171,0.000000
37.600002,15.028206,-337.343536,-0.002604,0.001793,0.045547,66.848801,3.405440,0.455467,-337.343536,0.046561,0.000000
37.830002,15.235619,-337.388000,-0.002578,0.001810,0.045980,67.771416,3.452441,0.459803,-337.388000,0.046943,0.000000
38.060001,15.396111,-337.388000,-0.002570,0.001825,0.046362,68.485321,3.488809,0.463619,-337.388000,0.047325,0.000000
38.290001,15.511177,-337.476990,-0.002552,0.001840,0.046743,68.997162,3.514883,0.467435,-337.476990,0.047706,0.000000
38.520000,15.756943,-337.388000,-0.002548,0.001857,0.047160,70.090385,3.570574,0.471597,-337.388000,0.048088,0.000000
38.750000,15.668694,-337.299042,-0.002531,0.001868,0.047437,69.697830,3.550577,0.474372,-337.299042,0.048478,0.000000
38.980003,16.100273,-337.388000,-0.002514,0.001887,0.047940,71.617592,3.648374,0.479402,-337.388000,0.048859,0.000000
39.210003,16.061546,-337.432495,-0.002505,0.001898,0.048209,71.445328,3.639598,0.482091,-337.432495,0.049241,0.000000
39.440002,16.113304,-337.432495,-0.002496,0.001909,0.048478,71.675560,3.651327,0.484779,-337.432495,0.049623,0.000000
39.670002,16.589943,-337.432495,-0.002479,0.001929,0.048990,73.795753,3.759335,0.489896,-337.432495,0.050004,0.000000
39.900002,16.657715,-337.432495,-0.002458,0.001944,0.049371,74.097214,3.774692,0.493712,-337.432495,0.050394,0.000000
40.130001,17.088921,-337.432495,-0.002440,0.001961,0.049805,76.015312,3.872405,0.498048,-337.432495,0.050776,0.000000
40.360001,17.325378,-337.476990,-0.002432,0.001979,0.050264,77.067131,3.925987,0.502644,-337.476990,0.051158,0.000000
40.590000,17.244202,-337.476990,-0.002427,0.001992,0.050585,76.706039,3.907592,0.505853,-337.476990,0.051539,0.000000
40.820004,17.479164,-337.476990,-0.002406,0.002006,0.050941,77.751205,3.960835,0.509408,-337.476990,0.051929,0.000000
41.050003,17.634071,-337.521454,-0.002389,0.002021,0.051322,78.440269,3.995938,0.513224,-337.521454,0.052311,0.000000
41.280003,17.382347,-337.565948,-0.002380,0.002027,0.051479,77.320541,3.938896,0.514785,-337.565948,0.052693,0.000000
41.510002,18.058205,-337.565948,-0.002367,0.002048,0.052025,80.326904,4.092048,0.520249,-337.565948,0.053074,0.000000
41.740002,18.203430,-337.476990,-0.002350,0.002064,0.052424,80.972900,4.124957,0.524238,-337.476990,0.053456,0.000000
41.970001,18.659210,-337.521454,-0.002341,0.002085,0.052961,83.000313,4.228238,0.529615,-337.521454,0.053846,0.000000
42.200001,18.989510,-337.521454,-0.002315,0.002100,0.053352,84.469559,4.303084,0.533517,-337.521454,0.054228,0.000000
42.430000,19.015572,-337.565948,-0.002307,0.002114,0.053707,84.585487,4.308990,0.537073,-337.565948,0.054609,0.000000
42.660004,18.971260,-337.610413,-0.002302,0.002126,0.054011,84.388382,4.298949,0.540108,-337.610413,0.054991,0.000000
42.890003,19.116112,-337.565948,-0.002294,0.002140,0.054349,85.032715,4.331773,0.543490,-337.565948,0.055372,0.000000
43.120003,19.400238,-337.565948,-0.002272,0.002155,0.054731,86.296570,4.396157,0.547306,-337.565948,0.055763,0.000000
43.350002,19.467262,-337.565948,-0.002259,0.002168,0.055060,86.594704,4.411345,0.550602,-337.565948,0.056144,0.000000
43.580002,20.169556,-337.565948,-0.002259,0.002187,0.055546,89.718666,4.570487,0.555458,-337.565948,0.056526,0.000000
43.810001,20.641350,-337.610413,-0.002233,0.002208,0.056083,91.817307,4.677397,0.560835,-337.610413,0.056907,0.000000
44.040001,20.819717,-337.610413,-0.002216,0.002222,0.056430,92.610725,4.717815,0.564304,-337.610413,0.057289,0.000000
44.270000,20.887489,-337.610413,-0.002203,0.002237,0.056821,92.912193,4.733173,0.568206,-337.610413,0.057679,0.000000
44.500004,20.863655,-337.610413,-0.002186,0.002249,0.057115,92.806175,4.727772,0.571155,-337.610413,0.058061,0.000000
44.730003,21.238266,-337.699371,-0.002186,0.002263,0.057488,94.472527,4.812660,0.574884,-337.699371,0.058442,0.000000
44.960003,21.574142,-337.654907,-0.002169,0.002280,0.057913,95.966576,4.888771,0.579133,-337.654907,0.058824,0.000000
45.190002,21.493340,-337.610413,-0.002156,0.002289,0.058147,95.607147,4.870460,0.581475,-337.610413,0.059205,0.000000
45.420002,21.829964,-337.654907,-0.002147,0.002304,0.058529,97.104530,4.946740,0.585291,-337.654907,0.059596,0.000000
45.650002,22.354263,-337.743866,-0.002134,0.002322,0.058989,99.436729,5.065548,0.589887,-337.743866,0.059977,0.000000
45.880001,22.838722,-337.654907,-0.002108,0.002339,0.059414,101.591713,5.175328,0.594136,-337.654907,0.060359,0.000000
46.110001,22.983574,-337.699371,-0.002104,0.002353,0.059778,102.236046,5.208152,0.597779,-337.699371,0.060740,0.000000
46.340004,22.935913,-337.743866,-0.002082,0.002365,0.060081,102.024040,5.197352,0.600814,-337.743866,0.061122,0.000000
46.570004,23.385368,-337.699371,-0.002082,0.002381,0.060472,104.023315,5.299200,0.604717,-337.699371,0.061512,0.000000
46.800003,23.969986,-337.743866,-0.002061,0.002398,0.060914,106.623825,5.431676,0.609139,-337.743866,0.061894,0.000000
47.030003,24.068298,-337.788330,-0.002052,0.002413,0.061296,107.061134,5.453954,0.612955,-337.788330,0.062275,0.000000
47.260002,24.093987,-337.788330,-0.002044,0.002425,0.061590,107.175407,5.459775,0.615904,-337.788330,0.062657,0.000000
47.490002,24.737823,-337.788330,-0.002031,0.002441,0.061998,110.039337,5.605671,0.619980,-337.788330,0.063039,0.000000
47.720001,25.431175,-337.743866,-0.002013,0.002461,0.062518,113.123520,5.762786,0.625183,-337.743866,0.063429,0.000000
47.950001,25.568581,-337.788330,-0.002001,0.002475,0.062865,113.734726,5.793923,0.628652,-337.788330,0.063810,0.000000
48.180004,25.801315,-337.832825,-0.001992,0.002489,0.063221,114.769981,5.846662,0.632208,-337.832825,0.064192,0.000000
48.410004,25.870209,-337.788330,-0.001975,0.002503,0.063576,115.076439,5.862273,0.635763,-337.788330,0.064574,0.000000
48.640003,26.114113,-337.832825,-0.001975,0.002514,0.063854,116.161377,5.917542,0.638538,-337.832825,0.064964,0.000000
48.870003,26.774696,-337.832825,-0.001944,0.002533,0.064348,119.099800,6.067233,0.643481,-337.832825,0.065345,0.000000
49.100002,26.858856,-337.921783,-0.001940,0.002546,0.064660,119.474159,6.086304,0.646603,-337.921783,0.065727,0.000000
49.330002,27.662804,-337.877319,-0.001940,0.002563,0.065111,123.050293,6.268481,0.651113,-337.877319,0.066109,0.000000
49.560001,28.225464,-337.832825,-0.001919,0.002581,0.065545,125.553131,6.395982,0.655449,-337.832825,0.066490,0.000000
49.790001,28.261208,-337.877319,-0.001919,0.002592,0.065840,125.712128,6.404081,0.658398,-337.877319,0.066880,0.000000
50.020004,28.228065,-337.832825,-0.001888,0.002601,0.066065,125.564705,6.396571,0.660653,-337.832825,0.067262,0.000000
50.250004,28.939674,-337.877319,-0.001876,0.002621,0.066586,128.730103,6.557824,0.665856,-337.877319,0.067644,0.000000
50.480003,29.430084,-337.921783,-0.001867,0.002637,0.066985,130.911560,6.668952,0.669845,-337.921783,0.068025,0.000000
50.710003,30.463051,-337.877319,-0.001871,0.002659,0.067540,135.506424,6.903026,0.675395,-337.877319,0.068407,0.000000
50.940002,30.311119,-337.877319,-0.001845,0.002667,0.067748,134.830597,6.868598,0.677477,-337.877319,0.068797,0.000000
51.170002,30.838402,-337.877319,-0.001832,0.002684,0.068173,137.176056,6.988081,0.681726,-337.877319,0.069179,0.000000
51.400002,31.409248,-337.966278,-0.001824,0.002701,0.068606,139.715317,7.117437,0.686062,-337.966278,0.069560,0.000000
51.630001,31.847527,-338.010742,-0.001819,0.002717,0.069014,141.664871,7.216753,0.690138,-338.010742,0.069942,0.000000
51.860001,32.156967,-337.966278,-0.001807,0.002730,0.069335,143.041336,7.286873,0.693347,-337.966278,0.070323,0.000000
52.090004,32.278732,-337.966278,-0.001789,0.002744,0.069708,143.582977,7.314465,0.697076,-337.966278,0.070714,0.000000
52.320004,33.105400,-338.010742,-0.001772,0.002760,0.070098,147.260178,7.501791,0.700979,-338.010742,0.071095,0.000000
52.550003,33.814774,-338.010742,-0.001776,0.002778,0.070549,150.415619,7.662537,0.705488,-338.010742,0.071477,0.000000
52.780003,33.928719,-338.099701,-0.001755,0.002788,0.070818,150.922485,7.688358,0.708176,-338.099701,0.071858,0.000000
53.010002,34.460464,-338.010742,-0.001746,0.002805,0.071251,153.287796,7.808853,0.712513,-338.010742,0.072240,0.000000
53.240002,35.336288,-338.099701,-0.001729,0.002823,0.071702,157.183655,8.007318,0.717022,-338.099701,0.072630,0.000000
53.470001,36.071724,-338.144196,-0.001725,0.002840,0.072145,160.455048,8.173969,0.721445,-338.144196,0.073012,0.000000
53.700001,36.345047,-338.055237,-0.001707,0.002854,0.072491,161.670837,8.235906,0.724914,-338.055237,0.073393,0.000000
53.930004,36.482452,-338.055237,-0.001707,0.002865,0.072778,162.282059,8.267042,0.727776,-338.055237,0.073775,0.000000
54.160004,36.886848,-338.144196,-0.001694,0.002879,0.073116,164.080902,8.358680,0.731158,-338.144196,0.074156,0.000000
54.390003,37.776070,-338.055237,-0.001673,0.002899,0.073636,168.036346,8.560180,0.736361,-338.055237,0.074547,0.000000
54.620003,38.251961,-338.099701,-0.001660,0.002911,0.073940,170.153214,8.668018,0.739397,-338.099701,0.074928,0.000000
54.850002,38.619125,-338.144196,-0.001656,0.002926,0.074313,171.786453,8.751219,0.743126,-338.144196,0.075310,0.000000
55.080002,39.139328,-338.144196,-0.001651,0.002940,0.074668,174.100433,8.869099,0.746681,-338.144196,0.075691,0.000000
55.310001,39.666237,-338.099701,-0.001643,0.002957,0.075102,176.444229,8.988498,0.751018,-338.099701,0.076073,0.000000
55.540001,41.216789,-338.144196,-0.001630,0.002977,0.075613,183.341431,9.339858,0.756134,-338.144196,0.076463,0.000000
55.770004,41.178436,-338.144196,-0.001604,0.002986,0.075848,183.170837,9.331167,0.758476,-338.144196,0.076845,0.000000
56.000004,42.032661,-338.188660,-0.001617,0.003004,0.076290,186.970612,9.524737,0.762898,-338.188660,0.077226,0.000000
56.230003,42.351036,-338.188660,-0.001600,0.003017,0.076637,188.386810,9.596882,0.766367,-338.188660,0.077608,0.000000
56.460003,43.156479,-338.188660,-0.001582,0.003034,0.077062,191.969604,9.779398,0.770617,-338.188660,0.077990,0.000000
56.690002,43.308037,-338.233154,-0.001574,0.003045,0.077339,192.643768,9.813741,0.773392,-338.233154,0.078380,0.000000
56.920002,44.065445,-338.233154,-0.001556,0.003060,0.077729,196.012894,9.985373,0.777294,-338.233154,0.078761,0.000000
57.150002,44.823967,-338.233154,-0.001556,0.003074,0.078085,199.386963,10.157256,0.780850,-338.233154,0.079143,0.000000
57.380001,45.891556,-338.188660,-0.001535,0.003094,0.078597,204.135834,10.399176,0.785967,-338.188660,0.079525,0.000000
57.610004,46.690292,-338.233154,-0.001531,0.003110,0.079004,207.688797,10.580172,0.790043,-338.233154,0.079915,0.000000
57.840004,46.972923,-338.277618,-0.001518,0.003123,0.079316,208.945999,10.644217,0.793165,-338.277618,0.080296,0.000000
58.070004,47.572449,-338.322113,-0.001518,0.003137,0.079681,211.612823,10.780071,0.796807,-338.322113,0.080678,0.000000
58.300003,48.615463,-338.366608,-0.001496,0.003154,0.080106,216.252380,11.016421,0.801056,-338.366608,0.081060,0.000000
58.530003,49.157265,-338.277618,-0.001492,0.003167,0.080444,218.662430,11.139195,0.804439,-338.277618,0.081441,0.000000
58.760002,49.580276,-338.277618,-0.001483,0.003179,0.080756,220.544083,11.235051,0.807561,-338.277618,0.081831,0.000000
58.990002,50.539879,-338.277618,-0.001470,0.003196,0.081190,224.812607,11.452500,0.811897,-338.277618,0.082213,0.000000
59.220001,51.324844,-338.322113,-0.001479,0.003211,0.081563,228.304306,11.630376,0.815626,-338.322113,0.082595,0.000000
59.450005,52.335464,-338.322113,-0.001457,0.003230,0.082040,232.799774,11.859386,0.820396,-338.322113,0.082976,0.000000
59.680004,52.898117,-338.366608,-0.001453,0.003242,0.082352,235.302582,11.986884,0.823518,-338.366608,0.083358,0.000000
59.910004,53.659988,-338.322113,-0.001440,0.003258,0.082742,238.691544,12.159527,0.827420,-338.322113,0.083748,0.000000
60.140003,54.065880,-338.322113,-0.001423,0.003267,0.082993,240.497040,12.251504,0.829935,-338.322113,0.084130,0.000000
60.370003,55.420937,-338.366608,-0.001423,0.003289,0.083531,246.524643,12.558564,0.835312,-338.366608,0.084511,0.000000
60.600002,55.701706,-338.411072,-0.001423,0.003298,0.083757,247.773560,12.622188,0.837567,-338.411072,0.084893,0.000000
60.830002,56.178719,-338.411072,-0.001410,0.003310,0.084078,249.895416,12.730279,0.840775,-338.411072,0.085274,0.000000
61.060001,57.471222,-338.411072,-0.001397,0.003328,0.084520,255.644760,13.023165,0.845198,-338.411072,0.085665,0.000000
61.290005,58.641960,-338.366608,-0.001397,0.003349,0.085066,260.852478,13.288458,0.850662,-338.366608,0.086046,0.000000
61.520004,59.615715,-338.455566,-0.001384,0.003365,0.085474,265.183929,13.509114,0.854738,-338.455566,0.086428,0.000000
61.750004,60.587982,-338.500031,-0.001375,0.003378,0.085812,269.508820,13.729433,0.858120,-338.500031,0.086809,0.000000
61.980003,61.214310,-338.455566,-0.001362,0.003391,0.086124,272.294861,13.871362,0.861242,-338.455566,0.087191,0.000000
62.210003,62.159019,-338.500031,-0.001358,0.003410,0.086610,276.497131,14.085435,0.866098,-338.500031,0.087581,0.000000
62.440002,62.939140,-338.500031,-0.001354,0.003422,0.086922,279.967285,14.262213,0.869220,-338.500031,0.087963,0.000000
62.670002,63.016586,-338.500031,-0.001341,0.003431,0.087139,280.311768,14.279763,0.871388,-338.500031,0.088344,0.000000
62.900002,64.711639,-338.500031,-0.001341,0.003451,0.087650,287.851746,14.663868,0.876505,-338.500031,0.088726,0.000000
63.130005,65.671234,-338.500031,-0.001328,0.003466,0.088041,292.120239,14.881314,0.880408,-338.500031,0.089107,0.000000
63.360004,67.143219,-338.544525,-0.001324,0.003487,0.088570,298.667969,15.214871,0.885698,-338.544525,0.089498,0.000000
63.590004,66.984222,-338.500031,-0.001302,0.003482,0.088448,297.960693,15.178842,0.884484,-338.500031,0.088682,0.000000
63.820004,66.354919,-338.588989,-0.001302,0.003482,0.088440,295.161438,15.036240,0.884397,-338.588989,0.088448,0.000000
64.050003,65.725983,-338.500031,-0.001293,0.003481,0.088422,292.363770,14.893720,0.884223,-338.500031,0.088448,0.000000
64.280006,65.171509,-338.544525,-0.001293,0.003481,0.088414,289.897339,14.768075,0.884137,-338.544525,0.088448,0.000000
64.510002,64.637909,-338.588989,-0.001281,0.003481,0.088414,287.523773,14.647160,0.884137,-338.588989,0.088448,0.000000
64.740005,64.151581,-338.588989,-0.001285,0.003481,0.088405,285.360474,14.536956,0.884050,-338.588989,0.088448,0.000000
64.970001,63.726334,-338.633484,-0.001293,0.003481,0.088405,283.468903,14.440593,0.884050,-338.633484,0.088448,0.000000
65.200005,63.334976,-338.588989,-0.001281,0.003481,0.088405,281.728058,14.351911,0.884050,-338.588989,0.088448,0.000000
65.430000,62.970795,-338.633484,-0.001276,0.003481,0.088405,280.108093,14.269386,0.884050,-338.633484,0.088448,0.000000
65.660004,62.626350,-338.588989,-0.001268,0.003481,0.088405,278.575928,14.191334,0.884050,-338.588989,0.088448,0.000000
65.889999,62.304619,-338.722443,-0.001272,0.003481,0.088405,277.144775,14.118428,0.884050,-338.722443,0.088448,0.000000
66.120003,62.003738,-338.677948,-0.001281,0.003481,0.088405,275.806396,14.050248,0.884050,-338.677948,0.088448,0.000000
66.350006,61.730415,-338.677948,-0.001276,0.003481,0.088405,274.590607,13.988312,0.884050,-338.677948,0.088448,0.000000
66.580002,61.471992,-338.677948,-0.001272,0.003481,0.088405,273.441071,13.929752,0.884050,-338.677948,0.088448,0.000000
66.810005,61.222504,-338.722443,-0.001255,0.003481,0.088405,272.331299,13.873218,0.884050,-338.722443,0.088448,0.000000
67.040001,60.975990,-338.722443,-0.001263,0.003481,0.088405,271.234741,13.817356,0.884050,-338.722443,0.088448,0.000000
67.270004,60.767090,-338.722443,-0.001259,0.003481,0.088405,270.305511,13.770019,0.884050,-338.722443,0.088448,0.000000
67.500000,60.563400,-338.677948,-0.001268,0.003481,0.088405,269.399445,13.723863,0.884050,-338.677948,0.088448,0.000000
67.730003,60.360458,-338.722443,-0.001263,0.003481,0.088405,268.496735,13.677876,0.884050,-338.722443,0.088448,0.000000
67.960007,60.174271,-338.766937,-0.001263,0.003480,0.088396,267.668518,13.635685,0.883963,-338.766937,0.088448,0.000000
68.190002,59.986595,-338.811401,-0.001255,0.003480,0.088396,266.833710,13.593157,0.883963,-338.811401,0.088448,0.000000
68.420006,59.816422,-338.766937,-0.001250,0.003480,0.088396,266.076721,13.554595,0.883963,-338.766937,0.088448,0.000000
68.650002,59.673058,-338.766937,-0.001259,0.003480,0.088396,265.439026,13.522108,0.883963,-338.766937,0.088448,0.000000
68.880005,59.515549,-338.811401,-0.001259,0.003480,0.088396,264.738373,13.486417,0.883963,-338.811401,0.088448,0.000000
69.110001,59.368462,-338.766937,-0.001237,0.003480,0.088396,264.084106,13.453086,0.883963,-338.766937,0.088448,0.000000
69.340004,59.215790,-338.811401,-0.001255,0.003480,0.088396,263.404999,13.418490,0.883963,-338.811401,0.088448,0.000000
69.570000,59.083969,-338.855896,-0.001250,0.003480,0.088396,262.818634,13.388618,0.883963,-338.855896,0.088448,0.000000
69.800003,58.964066,-338.766937,-0.001246,0.003480,0.088396,262.285248,13.361448,0.883963,-338.766937,0.088448,0.000000
70.030006,58.832985,-338.855896,-0.001242,0.003480,0.088396,261.702179,13.331745,0.883963,-338.855896,0.088448,0.000000
70.260002,58.700050,-338.855896,-0.001246,0.003480,0.088396,261.110870,13.301621,0.883963,-338.855896,0.088448,0.000000
70.490005,58.582008,-338.900360,-0.001246,0.003480,0.088396,260.585785,13.274873,0.883963,-338.900360,0.088448,0.000000
70.720001,58.470673,-338.811401,-0.001242,0.003480,0.088396,260.090546,13.249643,0.883963,-338.811401,0.088448,0.000000
70.950005,58.370132,-338.855896,-0.001242,0.003480,0.088396,259.643311,13.226861,0.883963,-338.855896,0.088448,0.000000
71.180000,58.251717,-338.900360,-0.001246,0.003480,0.088396,259.116577,13.200028,0.883963,-338.900360,0.088448,0.000000
71.410004,58.144470,-338.944855,-0.001246,0.003480,0.088396,258.639526,13.175725,0.883963,-338.944855,0.088448,0.000000
71.640007,58.042442,-338.944855,-0.001250,0.003480,0.088396,258.185669,13.152605,0.883963,-338.944855,0.088448,0.000000
71.870003,57.950836,-338.944855,-0.001246,0.003480,0.088396,257.778198,13.131847,0.883963,-338.944855,0.088448,0.000000
72.100006,57.867058,-338.900360,-0.001237,0.003480,0.088396,257.405518,13.112863,0.883963,-338.900360,0.088448,0.000000
72.330002,57.760925,-338.944855,-0.001233,0.003480,0.088396,256.933441,13.088813,0.883963,-338.944855,0.088448,0.000000
72.560005,57.670815,-338.989319,-0.001242,0.003480,0.088396,256.532593,13.068394,0.883963,-338.989319,0.088448,0.000000
72.790001,57.597458,-338.989319,-0.001242,0.003480,0.088396,256.206299,13.051770,0.883963,-338.989319,0.088448,0.000000
73.020004,57.518517,-338.944855,-0.001250,0.003480,0.088396,255.855133,13.033882,0.883963,-338.944855,0.088448,0.000000
73.250000,57.420952,-338.944855,-0.001255,0.003480,0.088396,255.421158,13.011773,0.883963,-338.944855,0.088448,0.000000
73.480003,57.339401,-338.989319,-0.001229,0.003480,0.088396,255.058395,12.993295,0.883963,-338.989319,0.088448,0.000000
73.710007,57.266792,-339.033813,-0.001233,0.003480,0.088396,254.735413,12.976841,0.883963,-339.033813,0.088448,0.000000
73.940002,57.197159,-338.989319,-0.001237,0.003480,0.088396,254.425674,12.961061,0.883963,-338.989319,0.088448,0.000000
74.170006,57.131989,-338.989319,-0.001242,0.003480,0.088396,254.135773,12.946294,0.883963,-338.989319,0.088448,0.000000
74.400002,57.042625,-338.989319,-0.001233,0.003480,0.088396,253.738266,12.926044,0.883963,-338.989319,0.088448,0.000000
74.630005,56.976715,-339.033813,-0.001233,0.003480,0.088396,253.445084,12.911108,0.883963,-339.033813,0.088448,0.000000
74.860001,56.912292,-339.078278,-0.001229,0.003480,0.088396,253.158524,12.896509,0.883963,-339.078278,0.088448,0.000000
75.090004,56.846008,-339.033813,-0.001246,0.003480,0.088396,252.863678,12.881489,0.883963,-339.033813,0.088448,0.000000
75.320007,56.765579,-339.078278,-0.001229,0.003480,0.088396,252.505905,12.863264,0.883963,-339.078278,0.088448,0.000000
75.550003,56.712700,-339.078278,-0.001237,0.003480,0.088396,252.270691,12.851282,0.883963,-339.078278,0.088448,0.000000
75.780006,56.655724,-339.078278,-0.001233,0.003480,0.088396,252.017242,12.838370,0.883963,-339.078278,0.088448,0.000000
76.010002,56.582741,-339.122772,-0.001237,0.003480,0.088396,251.692596,12.821833,0.883963,-339.122772,0.088448,0.000000
76.240005,56.518318,-339.167267,-0.001229,0.003480,0.088396,251.406036,12.807234,0.883963,-339.167267,0.088448,0.000000
76.470001,56.466934,-339.078278,-0.001224,0.003480,0.088396,251.177475,12.795590,0.883963,-339.078278,0.088448,0.000000
76.700005,56.419640,-339.078278,-0.001224,0.003480,0.088396,250.967087,12.784873,0.883963,-339.078278,0.088448,0.000000
76.930000,56.361549,-339.211731,-0.001224,0.003480,0.088396,250.708694,12.771709,0.883963,-339.211731,0.088448,0.000000
77.160004,56.286705,-339.211731,-0.001233,0.003480,0.088396,250.375763,12.754750,0.883963,-339.211731,0.088448,0.000000
77.390007,56.246864,-339.167267,-0.001224,0.003480,0.088396,250.198547,12.745722,0.883963,-339.167267,0.088448,0.000000
77.620003,56.205902,-339.122772,-0.001224,0.003480,0.088396,250.016342,12.736440,0.883963,-339.122772,0.088448,0.000000
77.850006,56.148552,-339.167267,-0.001233,0.003480,0.088396,249.761230,12.723444,0.883963,-339.167267,0.088448,0.000000
78.080002,56.085999,-339.256226,-0.001237,0.003480,0.088396,249.482986,12.709269,0.883963,-339.256226,0.088448,0.000000
78.310005,56.046524,-339.122772,-0.001237,0.003480,0.088396,249.307388,12.700324,0.883963,-339.122772,0.088448,0.000000
78.540001,56.002960,-339.211731,-0.001229,0.003480,0.088396,249.113602,12.690453,0.883963,-339.211731,0.088448,0.000000
78.770004,55.944122,-339.211731,-0.001220,0.003480,0.088396,248.851883,12.677119,0.883963,-339.211731,0.088448,0.000000
79.000000,55.887520,-339.211731,-0.001220,0.003480,0.088396,248.600098,12.664293,0.883963,-339.211731,0.088448,0.000000
79.230003,55.859970,-339.256226,-0.001220,0.003480,0.088396,248.477554,12.658051,0.883963,-339.256226,0.088448,0.000000
79.460007,55.816772,-339.211731,-0.001224,0.003480,0.088396,248.285400,12.648261,0.883963,-339.211731,0.088448,0.000000
79.690002,55.768738,-339.300690,-0.001237,0.003480,0.088396,248.071732,12.637376,0.883963,-339.300690,0.088448,0.000000
79.920006,55.721069,-339.300690,-0.001220,0.003480,0.088396,247.859695,12.626575,0.883963,-339.300690,0.088448,0.000000
80.150002,55.682716,-339.256226,-0.001220,0.003480,0.088396,247.689087,12.617884,0.883963,-339.256226,0.088448,0.000000
80.380005,55.631332,-339.345184,-0.001233,0.003480,0.088396,247.460526,12.606240,0.883963,-339.345184,0.088448,0.000000
80.610001,55.585159,-339.300690,-0.001233,0.003480,0.088396,247.255142,12.595777,0.883963,-339.300690,0.088448,0.000000
80.840004,55.546799,-339.256226,-0.001242,0.003480,0.088396,247.084503,12.587085,0.883963,-339.256226,0.088448,0.000000
81.070007,55.523712,-339.300690,-0.001216,0.003480,0.088396,246.981812,12.581853,0.883963,-339.300690,0.088448,0.000000
81.300003,55.474937,-339.345184,-0.001233,0.003480,0.088396,246.764847,12.570801,0.883963,-339.345184,0.088448,0.000000
81.530006,55.413490,-339.389648,-0.001216,0.003480,0.088396,246.491516,12.556876,0.883963,-339.389648,0.088448,0.000000
81.760002,55.385941,-339.345184,-0.001233,0.003480,0.088396,246.368973,12.550633,0.883963,-339.345184,0.088448,0.000000
81.990005,55.358757,-339.389648,-0.001224,0.003480,0.088396,246.248047,12.544474,0.883963,-339.389648,0.088448,0.000000
82.220001,55.317047,-339.345184,-0.001220,0.003480,0.088396,246.062515,12.535022,0.883963,-339.345184,0.088448,0.000000
82.450005,55.268639,-339.389648,-0.001237,0.003480,0.088396,245.847183,12.524053,0.883963,-339.389648,0.088448,0.000000
82.680000,55.231033,-339.434143,-0.001220,0.003480,0.088396,245.679901,12.515532,0.883963,-339.434143,0.088448,0.000000
82.910004,55.201988,-339.345184,-0.001229,0.003480,0.088396,245.550705,12.508949,0.883963,-339.345184,0.088448,0.000000
83.140007,55.172569,-339.434143,-0.001233,0.003480,0.088396,245.419846,12.502283,0.883963,-339.434143,0.088448,0.000000
83.370003,55.116341,-339.434143,-0.001216,0.003480,0.088396,245.169724,12.489541,0.883963,-339.434143,0.088448,0.000000
83.600006,55.083572,-339.478607,-0.001216,0.003480,0.088396,245.023972,12.482117,0.883963,-339.478607,0.088448,0.000000
83.830002,55.066071,-339.478607,-0.001216,0.003480,0.088396,244.946121,12.478149,0.883963,-339.478607,0.088448,0.000000
84.060005,55.023247,-339.478607,-0.001220,0.003480,0.088396,244.755630,12.468446,0.883963,-339.478607,0.088448,0.000000
84.290001,54.978935,-339.434143,-0.001224,0.003480,0.088396,244.558517,12.458405,0.883963,-339.434143,0.088448,0.000000
84.520004,54.958824,-339.434143,-0.001220,0.003480,0.088396,244.469055,12.453848,0.883963,-339.434143,0.088448,0.000000
84.750008,54.927544,-339.478607,-0.001216,0.003480,0.088396,244.329910,12.446759,0.883963,-339.478607,0.088448,0.000000
84.980003,54.892914,-339.478607,-0.001229,0.003480,0.088396,244.175873,12.438912,0.883963,-339.478607,0.088448,0.000000
85.210007,54.857910,-339.523102,-0.001229,0.003480,0.088396,244.020172,12.430981,0.883963,-339.523102,0.088448,0.000000
85.440002,54.828865,-339.478607,-0.001224,0.003480,0.088396,243.890976,12.424398,0.883963,-339.478607,0.088448,0.000000
85.670006,54.813972,-339.478607,-0.001220,0.003480,0.088396,243.824722,12.421024,0.883963,-339.478607,0.088448,0.000000
85.900002,54.773758,-339.656555,-0.001229,0.003480,0.088396,243.645844,12.411911,0.883963,-339.656555,0.088448,0.000000
86.130005,54.728325,-339.567566,-0.001229,0.003480,0.088396,243.443741,12.401615,0.883963,-339.567566,0.088448,0.000000
86.360001,54.693695,-339.567566,-0.001229,0.003480,0.088396,243.289703,12.393769,0.883963,-339.567566,0.088448,0.000000
86.590004,54.676567,-339.567566,-0.001220,0.003480,0.088396,243.213516,12.389887,0.883963,-339.567566,0.088448,0.000000
86.820007,54.664650,-339.612061,-0.001212,0.003480,0.088396,243.160507,12.387187,0.883963,-339.612061,0.088448,0.000000
87.050003,54.622200,-339.612061,-0.001220,0.003480,0.088396,242.971680,12.377567,0.883963,-339.612061,0.088448,0.000000
87.280006,54.583473,-339.612061,-0.001220,0.003480,0.088396,242.799408,12.368792,0.883963,-339.612061,0.088448,0.000000
87.510002,54.551453,-339.567566,-0.001229,0.003480,0.088396,242.656982,12.361536,0.883963,-339.567566,0.088448,0.000000
87.740005,54.546982,-339.567566,-0.001216,0.003480,0.088396,242.637100,12.360522,0.883963,-339.567566,0.088448,0.000000
87.970001,54.506393,-339.656555,-0.001216,0.003480,0.088396,242.456543,12.351325,0.883963,-339.656555,0.088448,0.000000
88.200005,54.464317,-339.612061,-0.001207,0.003480,0.088396,242.269379,12.341790,0.883963,-339.612061,0.088448,0.000000
88.430008,54.447929,-339.612061,-0.001224,0.003480,0.088396,242.196487,12.338078,0.883963,-339.612061,0.088448,0.000000
88.660004,54.431915,-339.612061,-0.001229,0.003480,0.088396,242.125259,12.334449,0.883963,-339.612061,0.088448,0.000000
88.890007,54.401009,-339.701019,-0.001207,0.003480,0.088396,241.987778,12.327445,0.883963,-339.701019,0.088448,0.000000
89.120003,54.367126,-339.612061,-0.001212,0.003480,0.088396,241.837051,12.319767,0.883963,-339.612061,0.088448,0.000000
89.350006,54.336220,-339.701019,-0.001224,0.003480,0.088396,241.699570,12.312763,0.883963,-339.701019,0.088448,0.000000
89.580002,54.315735,-339.701019,-0.001212,0.003480,0.088396,241.608459,12.308122,0.883963,-339.701019,0.088448,0.000000
89.810005,54.294510,-339.656555,-0.001216,0.003480,0.088396,241.514038,12.303311,0.883963,-339.656555,0.088448,0.000000
90.040001,54.258766,-339.656555,-0.001224,0.003480,0.088396,241.355042,12.295212,0.883963,-339.656555,0.088448,0.000000
90.270004,54.240891,-339.745514,-0.001216,0.003480,0.088396,241.275528,12.291162,0.883963,-339.745514,0.088448,0.000000
90.500008,54.217430,-339.701019,-0.001220,0.003480,0.088396,241.171173,12.285846,0.883963,-339.701019,0.088448,0.000000
90.730003,54.190994,-339.745514,-0.001212,0.003480,0.088396,241.053589,12.279855,0.883963,-339.745514,0.088448,0.000000
90.960007,54.174980,-339.701019,-0.001212,0.003480,0.088396,240.982346,12.276226,0.883963,-339.701019,0.088448,0.000000
91.190002,54.143333,-339.745514,-0.001212,0.003480,0.088396,240.841568,12.269055,0.883963,-339.745514,0.088448,0.000000
91.420006,54.122108,-339.789978,-0.001207,0.003480,0.088396,240.747162,12.264245,0.883963,-339.789978,0.088448,0.000000
91.650002,54.106468,-339.834473,-0.001216,0.003480,0.088396,240.677597,12.260701,0.883963,-339.834473,0.088448,0.000000
91.880005,54.081146,-339.834473,-0.001220,0.003480,0.088396,240.564957,12.254963,0.883963,-339.834473,0.088448,0.000000
92.110001,54.057686,-339.745514,-0.001212,0.003480,0.088396,240.460602,12.249647,0.883963,-339.745514,0.088448,0.000000
92.340004,54.027153,-339.789978,-0.001216,0.003480,0.088396,240.324783,12.242727,0.883963,-339.789978,0.088448,0.000000
92.570007,54.001831,-339.834473,-0.001229,0.003480,0.088396,240.212143,12.236990,0.883963,-339.834473,0.088448,0.000000
92.800003,53.993263,-339.834473,-0.001220,0.003480,0.088396,240.174026,12.235048,0.883963,-339.834473,0.088448,0.000000
93.030006,53.970551,-339.834473,-0.001224,0.003480,0.088396,240.072998,12.229901,0.883963,-339.834473,0.088448,0.000000
93.260002,53.938522,-339.789978,-0.001207,0.003480,0.088396,239.930527,12.222644,0.883963,-339.789978,0.088448,0.000000
93.490005,53.923630,-339.834473,-0.001203,0.003480,0.088396,239.864288,12.219269,0.883963,-339.834473,0.088448,0.000000
93.720001,53.899796,-339.878937,-0.001216,0.003480,0.088396,239.758270,12.213868,0.883963,-339.878937,0.088448,0.000000
93.900002,53.899055,-339.878937,-0.001212,0.003480,0.088396,239.754974,12.213700,0.883963,-339.878937,0.088448,0.000000