File: Data/compression 11/AutoNoHeating-12-11-1-240530_05302024_161031.csv
Time (sec),S:Load (lbs),S:HL1 (DIM),S:LVDT (in),S:Position (in),Ch:Position (mm),Ch:Load (N),Ch:Stress (MPa),Ch:Strain (mm/mm),Ch:HL1 (DIM),Set Point (),Cycles ()
0.110000,0.004097,-67.744492,-0.007226,-0.000000,-0.000000,0.018224,0.000928,-0.000000,-67.744492,0.000278,0.000000
0.340000,0.035378,-67.833450,-0.007209,0.000001,0.000017,0.157367,0.008017,0.000173,-67.833450,0.000590,0.000000
0.570000,0.034630,-67.833450,-0.007209,0.000128,0.003252,0.154041,0.007847,0.032521,-67.833450,0.004423,0.000000
0.800000,0.077454,-67.877930,-0.007097,0.000278,0.007068,0.344531,0.017551,0.070679,-67.877930,0.008256,0.000000
1.030000,0.061066,-67.922409,-0.006950,0.000434,0.011031,0.271634,0.013838,0.110311,-67.922409,0.012089,0.000000
1.260000,0.033882,-67.922409,-0.006804,0.000583,0.014821,0.150715,0.007678,0.148209,-67.922409,0.015922,0.000000
1.490000,0.044312,-67.877930,-0.006648,0.000732,0.018602,0.197107,0.010041,0.186020,-67.877930,0.019755,0.000000
1.720000,0.037979,-67.877930,-0.006510,0.000882,0.022400,0.168940,0.008606,0.224004,-67.877930,0.023589,0.000000
1.950000,0.051384,-67.966896,-0.006342,0.001030,0.026173,0.228567,0.011644,0.261729,-67.966896,0.027422,0.000000
2.180000,0.032021,-68.011375,-0.006196,0.001181,0.030006,0.142435,0.007256,0.300060,-68.011375,0.031255,0.000000
2.410000,0.021965,-68.055855,-0.006071,0.001333,0.033848,0.097705,0.004977,0.338478,-68.055855,0.035071,0.000000
2.640000,0.000740,-68.011375,-0.005898,0.001484,0.037698,0.003292,0.000168,0.376983,-68.011375,0.038904,0.000000
2.870000,0.032768,-68.055855,-0.005760,0.001635,0.041540,0.145760,0.007425,0.415401,-68.055855,0.042737,0.000000
3.100000,0.065536,-68.055855,-0.005614,0.001787,0.045391,0.291521,0.014851,0.453906,-68.055855,0.046570,0.000000
3.330000,0.086014,-68.189301,-0.005471,0.001935,0.049146,0.382608,0.019491,0.491457,-68.189301,0.050403,0.000000
3.560000,0.079315,-68.144814,-0.005316,0.002088,0.053031,0.352812,0.017973,0.530308,-68.144814,0.054236,0.000000
3.790000,0.039467,-68.100334,-0.005161,0.002242,0.056959,0.175557,0.008943,0.569594,-68.100334,0.058069,0.000000
4.020000,0.040215,-68.100334,-0.004997,0.002388,0.060645,0.178883,0.009113,0.606451,-68.100334,0.061903,0.000000
4.250000,0.058830,-68.233780,-0.004855,0.002537,0.064435,0.261690,0.013331,0.644349,-68.233780,0.065736,0.000000
4.480000,0.062553,-68.278259,-0.004712,0.002690,0.068320,0.278251,0.014175,0.683200,-68.278259,0.069569,0.000000
4.710000,0.035378,-68.278259,-0.004557,0.002839,0.072101,0.157367,0.008017,0.721011,-68.278259,0.073402,0.000000
4.940000,0.070747,-68.278259,-0.004398,0.002991,0.075969,0.314700,0.016032,0.759690,-68.278259,0.077235,0.000000
5.170000,0.140007,-68.189301,-0.004238,0.003148,0.079958,0.622782,0.031726,0.799582,-68.189301,0.081068,0.000000
5.400000,0.456154,-68.322739,-0.004100,0.003298,0.083774,2.029074,0.103366,0.837740,-68.322739,0.084884,0.000000
5.630000,0.643829,-68.411705,-0.004010,-0.000008,-0.000199,2.863896,0.145894,-0.001995,-68.411705,-0.000026,0.000000
5.860000,0.598770,-68.322739,-0.004010,-0.000008,-0.000199,2.663463,0.135683,-0.001995,-68.322739,-0.000026,0.000000
6.090000,0.588348,-68.367218,-0.004018,-0.000008,-0.000199,2.617104,0.133322,-0.001995,-68.367218,0.000130,0.000000
6.320000,0.592445,-68.411705,-0.004010,-0.000008,-0.000199,2.635329,0.134250,-0.001995,-68.411705,0.000512,0.000000
6.550000,0.600266,-68.456184,-0.004014,-0.000002,-0.000061,2.670114,0.136022,-0.000607,-68.456184,0.000893,0.000000
6.780000,0.627815,-68.500664,-0.004018,0.000010,0.000251,2.792662,0.142265,0.002515,-68.500664,0.001275,0.000000
7.010000,0.727242,-68.456184,-0.004010,0.000030,0.000763,3.234932,0.164795,0.007632,-68.456184,0.001665,0.000000
7.240000,0.814751,-68.411705,-0.003988,0.000047,0.001197,3.624192,0.184625,0.011968,-68.411705,0.002047,0.000000
7.470000,0.854591,-68.500664,-0.003967,0.000058,0.001474,3.801412,0.193653,0.014743,-68.500664,0.002428,0.000000
7.700000,0.926460,-68.545143,-0.003962,0.000072,0.001830,4.121101,0.209939,0.018298,-68.545143,0.002810,0.000000
7.930000,0.999443,-68.589630,-0.003954,0.000088,0.002229,4.445745,0.226477,0.022288,-68.589630,0.003191,0.000000
8.160001,1.078392,-68.545143,-0.003932,0.000104,0.002645,4.796927,0.244367,0.026450,-68.545143,0.003582,0.000000
8.390000,1.108925,-68.589630,-0.003911,0.000117,0.002975,4.932744,0.251286,0.029746,-68.589630,0.003963,0.000000
8.620001,1.135361,-68.634109,-0.003906,0.000130,0.003313,5.050337,0.257276,0.033128,-68.634109,0.004345,0.000000
8.850000,1.195686,-68.678589,-0.003880,0.000149,0.003772,5.318678,0.270946,0.037724,-68.678589,0.004726,0.000000
9.080001,1.246704,-68.723068,-0.003872,0.000163,0.004137,5.545617,0.282507,0.041367,-68.723068,0.005117,0.000000
9.310000,1.274254,-68.678589,-0.003867,0.000175,0.004458,5.668164,0.288750,0.044575,-68.678589,0.005498,0.000000
9.540001,1.327881,-68.678589,-0.003846,0.000192,0.004874,5.906709,0.300902,0.048738,-68.678589,0.005880,0.000000
9.770000,1.388573,-68.723068,-0.003829,0.000206,0.005238,6.176680,0.314655,0.052380,-68.723068,0.006261,0.000000
10.000000,1.445549,-68.767548,-0.003820,0.000222,0.005628,6.430123,0.327566,0.056283,-68.767548,0.006643,0.000000
10.230000,1.532310,-68.767548,-0.003807,0.000241,0.006123,6.816058,0.347227,0.061226,-68.767548,0.007033,0.000000
10.460000,1.547577,-68.723068,-0.003790,0.000254,0.006443,6.883966,0.350686,0.064435,-68.723068,0.007415,0.000000
10.690001,1.572525,-68.723068,-0.003764,0.000272,0.006912,6.994941,0.356339,0.069118,-68.723068,0.007796,0.000000
10.920000,1.598221,-68.900993,-0.003747,0.000284,0.007224,7.109241,0.362162,0.072240,-68.900993,0.008178,0.000000
11.150001,1.615723,-68.856514,-0.003747,0.000296,0.007510,7.187093,0.366128,0.075102,-68.856514,0.008560,0.000000
11.380000,1.701370,-68.856514,-0.003738,0.000314,0.007970,7.568073,0.385536,0.079698,-68.856514,0.008950,0.000000
11.610001,1.692062,-68.945473,-0.003712,0.000325,0.008256,7.526670,0.383427,0.082560,-68.945473,0.009331,0.000000
11.840000,1.794090,-68.945473,-0.003699,0.000343,0.008724,7.980512,0.406547,0.087243,-68.945473,0.009713,0.000000
12.070001,1.768768,-68.989952,-0.003673,0.000353,0.008967,7.867875,0.400809,0.089671,-68.989952,0.010095,0.000000
12.300000,1.865585,-69.034439,-0.003669,0.000374,0.009496,8.298538,0.422748,0.094961,-69.034439,0.010476,0.000000
12.530001,1.896118,-68.945473,-0.003648,0.000392,0.009956,8.434355,0.429667,0.099557,-68.945473,0.010866,0.000000
12.760000,1.909149,-68.945473,-0.003626,0.000407,0.010329,8.492320,0.432619,0.103287,-68.945473,0.011248,0.000000
12.990001,1.883461,-69.034439,-0.003622,0.000417,0.010580,8.378053,0.426798,0.105802,-69.034439,0.011629,0.000000
13.220000,1.927399,-69.078918,-0.003622,0.000430,0.010927,8.573498,0.436755,0.109270,-69.078918,0.012011,0.000000
13.450001,1.989960,-69.078918,-0.003609,0.000447,0.011343,8.851783,0.450931,0.113433,-69.078918,0.012393,0.000000
13.680000,2.049164,-69.078918,-0.003591,0.000464,0.011786,9.115136,0.464347,0.117856,-69.078918,0.012783,0.000000
13.910001,2.082680,-69.078918,-0.003566,0.000481,0.012228,9.264222,0.471942,0.122279,-69.078918,0.013164,0.000000
14.140000,2.074860,-69.212357,-0.003548,0.000490,0.012445,9.229437,0.470170,0.124447,-69.212357,0.013546,0.000000
14.370001,2.156776,-69.212357,-0.003531,0.000512,0.013008,9.593821,0.488733,0.130084,-69.212357,0.013928,0.000000
14.600000,2.135551,-69.212357,-0.003523,0.000526,0.013373,9.499408,0.483923,0.133726,-69.212357,0.014309,0.000000
14.830001,2.158638,-69.167877,-0.003505,0.000540,0.013711,9.602101,0.489154,0.137108,-69.167877,0.014699,0.000000
15.060000,2.171677,-69.212357,-0.003492,0.000551,0.013997,9.660100,0.492109,0.139970,-69.212357,0.015081,0.000000
15.290001,2.231628,-69.212357,-0.003484,0.000569,0.014448,9.926779,0.505694,0.144480,-69.212357,0.015463,0.000000
15.520000,2.271469,-69.256844,-0.003458,0.000585,0.014847,10.103999,0.514722,0.148469,-69.256844,0.015844,0.000000
15.750001,2.320625,-69.345802,-0.003454,0.000601,0.015255,10.322657,0.525861,0.152545,-69.345802,0.016226,0.000000
15.980000,2.334404,-69.301323,-0.003441,0.000615,0.015619,10.383947,0.528984,0.156187,-69.301323,0.016616,0.000000
16.210001,2.385414,-69.345802,-0.003423,0.000632,0.016044,10.610852,0.540543,0.160437,-69.345802,0.016998,0.000000
16.440001,2.413345,-69.434761,-0.003393,0.000647,0.016425,10.735096,0.546872,0.164253,-69.434761,0.017379,0.000000
16.670000,2.393982,-69.390282,-0.003402,0.000662,0.016824,10.648964,0.542484,0.168242,-69.390282,0.017761,0.000000
16.900002,2.379829,-69.390282,-0.003385,0.000671,0.017050,10.586010,0.539277,0.170497,-69.390282,0.018142,0.000000
17.130001,2.469200,-69.434761,-0.003367,0.000690,0.017518,10.983551,0.559529,0.175180,-69.434761,0.018533,0.000000
17.360001,2.507553,-69.434761,-0.003346,0.000703,0.017848,11.154153,0.568220,0.178475,-69.434761,0.018914,0.000000
17.590000,2.604744,-69.479248,-0.003333,0.000721,0.018316,11.586480,0.590243,0.183158,-69.479248,0.019296,0.000000
17.820002,2.568626,-69.612686,-0.003320,0.000730,0.018541,11.425821,0.582059,0.185413,-69.612686,0.019677,0.000000
18.050001,2.613312,-69.479248,-0.003303,0.000751,0.019070,11.624591,0.592185,0.190703,-69.479248,0.020068,0.000000
18.280001,2.665810,-69.523727,-0.003281,0.000767,0.019478,11.858113,0.604081,0.194779,-69.523727,0.020449,0.000000
18.510000,2.650543,-69.568207,-0.003268,0.000782,0.019859,11.790205,0.600622,0.198595,-69.568207,0.020831,0.000000
18.740002,2.634903,-69.612686,-0.003251,0.000795,0.020180,11.720634,0.597078,0.201803,-69.612686,0.021212,0.000000
18.970001,2.668419,-69.568207,-0.003251,0.000808,0.020519,11.869720,0.604672,0.205186,-69.568207,0.021594,0.000000
19.200001,2.808434,-69.612686,-0.003242,0.000828,0.021022,12.492537,0.636400,0.210216,-69.612686,0.021984,0.000000
19.430000,2.786835,-69.612686,-0.003212,0.000840,0.021334,12.396460,0.631506,0.213338,-69.612686,0.022366,0.000000
19.660002,2.855721,-69.657173,-0.003195,0.000855,0.021715,12.702879,0.647115,0.217153,-69.657173,0.022747,0.000000
19.890001,2.914932,-69.790611,-0.003182,0.000871,0.022114,12.966267,0.660533,0.221143,-69.790611,0.023129,0.000000
20.120001,2.948441,-69.746132,-0.003182,0.000889,0.022574,13.115318,0.668126,0.225739,-69.746132,0.023510,0.000000
20.350000,2.986053,-69.746132,-0.003156,0.000905,0.022999,13.282629,0.676649,0.229988,-69.746132,0.023901,0.000000
20.580002,2.975258,-69.701653,-0.003134,0.000919,0.023346,13.234608,0.674203,0.233457,-69.701653,0.024282,0.000000
20.810001,2.936157,-69.746132,-0.003122,0.000927,0.023545,13.060679,0.665343,0.235452,-69.746132,0.024664,0.000000
21.040001,3.104843,-69.790611,-0.003122,0.000949,0.024100,13.811032,0.703568,0.241002,-69.790611,0.025045,0.000000
21.270000,3.113777,-69.790611,-0.003104,0.000961,0.024404,13.850773,0.705592,0.244037,-69.790611,0.025427,0.000000
21.500002,3.221390,-69.790611,-0.003083,0.000980,0.024898,14.329457,0.729977,0.248981,-69.790611,0.025817,0.000000
21.730001,3.265709,-69.790611,-0.003065,0.000996,0.025288,14.526599,0.740020,0.252883,-69.790611,0.026199,0.000000
21.960001,3.188622,-69.879578,-0.003057,0.001006,0.025548,14.183697,0.722552,0.255485,-69.879578,0.026580,0.000000
22.190001,3.263840,-69.924057,-0.003053,0.001020,0.025904,14.518284,0.739597,0.259040,-69.924057,0.026962,0.000000
22.420002,3.362152,-69.879578,-0.003014,0.001040,0.026416,14.955600,0.761875,0.264157,-69.879578,0.027344,0.000000
22.650002,3.319702,-69.879578,-0.003018,0.001052,0.026728,14.766772,0.752255,0.267279,-69.879578,0.027734,0.000000
22.880001,3.331985,-69.968536,-0.002992,0.001063,0.027005,14.821412,0.755039,0.270054,-69.968536,0.028115,0.000000
23.110001,3.443703,-69.968536,-0.002971,0.001082,0.027491,15.318355,0.780354,0.274911,-69.968536,0.028497,0.000000
23.340002,3.548332,-69.968536,-0.002966,0.001101,0.027968,15.783770,0.804064,0.279680,-69.968536,0.028879,0.000000
23.570002,3.519287,-70.013016,-0.002949,0.001113,0.028280,15.654571,0.797482,0.282802,-70.013016,0.029260,0.000000
23.800001,3.540146,-70.013016,-0.002940,0.001126,0.028592,15.747355,0.802208,0.285924,-70.013016,0.029650,0.000000
24.030001,3.632866,-70.013016,-0.002919,0.001144,0.029061,16.159794,0.823219,0.290607,-70.013016,0.030032,0.000000
24.260000,3.600471,-70.146461,-0.002915,0.001158,0.029408,16.015697,0.815878,0.294076,-70.146461,0.030414,0.000000
24.490002,3.758354,-70.146461,-0.002884,0.001176,0.029876,16.717995,0.851655,0.298759,-70.146461,0.030795,0.000000
24.720001,3.730797,-70.101982,-0.002871,0.001190,0.030231,16.595413,0.845411,0.302315,-70.101982,0.031177,0.000000
24.950001,3.821655,-70.101982,-0.002867,0.001206,0.030630,16.999571,0.865999,0.306304,-70.101982,0.031567,0.000000
25.180000,3.871925,-70.146461,-0.002841,0.001222,0.031038,17.223185,0.877391,0.310380,-70.146461,0.031949,0.000000
25.410002,3.955338,-70.235420,-0.002828,0.001239,0.031472,17.594219,0.896292,0.314716,-70.235420,0.032330,0.000000
25.640001,4.034279,-70.235420,-0.002824,0.001257,0.031931,17.945368,0.914181,0.319313,-70.235420,0.032712,0.000000
25.870001,4.017151,-70.190941,-0.002811,0.001268,0.032209,17.869179,0.910299,0.322088,-70.190941,0.033093,0.000000
26.100000,4.014915,-70.279900,-0.002781,0.001280,0.032504,17.859236,0.909793,0.325036,-70.279900,0.033484,0.000000
26.330002,4.036140,-70.279900,-0.002764,0.001295,0.032885,17.953650,0.914602,0.328852,-70.279900,0.033865,0.000000
26.560001,4.154556,-70.279900,-0.002768,0.001312,0.033336,18.480389,0.941436,0.333362,-70.279900,0.034247,0.000000
26.790001,4.181740,-70.324387,-0.002746,0.001326,0.033674,18.601307,0.947596,0.336744,-70.324387,0.034628,0.000000
27.020000,4.240204,-70.324387,-0.002729,0.001339,0.034021,18.861368,0.960844,0.340213,-70.324387,0.035019,0.000000
27.250002,4.266273,-70.324387,-0.002712,0.001352,0.034342,18.977333,0.966751,0.343421,-70.324387,0.035400,0.000000
27.480001,4.315422,-70.368866,-0.002695,0.001366,0.034689,19.195955,0.977889,0.346890,-70.368866,0.035782,0.000000
27.710001,4.588745,-70.413345,-0.002682,0.001393,0.035374,20.411758,1.039824,0.353741,-70.413345,0.036163,0.000000
27.940001,4.476288,-70.457825,-0.002665,0.001401,0.035582,19.911522,1.014341,0.355823,-70.457825,0.036545,0.000000
28.170002,4.483360,-70.457825,-0.002660,0.001417,0.035981,19.942982,1.015944,0.359812,-70.457825,0.036935,0.000000
28.400002,4.573105,-70.457825,-0.002643,0.001432,0.036371,20.342186,1.036280,0.363714,-70.457825,0.037317,0.000000
28.630001,4.655396,-70.502304,-0.002630,0.001450,0.036822,20.708233,1.054928,0.368224,-70.502304,0.037698,0.000000
28.860001,4.674393,-70.546791,-0.002626,0.001462,0.037126,20.792738,1.059232,0.371259,-70.546791,0.038080,0.000000
29.090002,4.686310,-70.591270,-0.002600,0.001474,0.037438,20.845747,1.061933,0.374381,-70.591270,0.038461,0.000000
29.320002,4.791313,-70.546791,-0.002583,0.001489,0.037828,21.312826,1.085727,0.378284,-70.546791,0.038852,0.000000
29.550001,4.883667,-70.546791,-0.002578,0.001505,0.038236,21.723637,1.106655,0.382360,-70.546791,0.039233,0.000000
29.780001,4.959625,-70.635750,-0.002561,0.001523,0.038687,22.061516,1.123867,0.386869,-70.635750,0.039615,0.000000
30.010002,5.008408,-70.635750,-0.002548,0.001536,0.039016,22.278509,1.134921,0.390165,-70.635750,0.039996,0.000000
30.240002,5.105598,-70.680229,-0.002535,0.001552,0.039424,22.710836,1.156945,0.394241,-70.680229,0.040378,0.000000
30.470001,5.075806,-70.635750,-0.002514,0.001565,0.039754,22.578312,1.150194,0.397536,-70.635750,0.040768,0.000000
30.700001,5.119377,-70.724709,-0.002496,0.001576,0.040031,22.772127,1.160067,0.400311,-70.724709,0.041150,0.000000
30.930002,5.342796,-70.724709,-0.002492,0.001596,0.040543,23.765945,1.210695,0.405428,-70.724709,0.041531,0.000000
31.160002,5.374077,-70.813675,-0.002488,0.001611,0.040916,23.905088,1.217783,0.409157,-70.813675,0.041913,0.000000
31.390001,5.365883,-70.680229,-0.002466,0.001625,0.041263,23.868639,1.215926,0.412626,-70.680229,0.042295,0.000000
31.620001,5.534569,-70.724709,-0.002445,0.001644,0.041748,24.618992,1.254151,0.417482,-70.724709,0.042685,0.000000
31.850002,5.540154,-70.813675,-0.002423,0.001658,0.042112,24.643833,1.255417,0.421125,-70.813675,0.043066,0.000000
32.080002,5.706604,-70.947121,-0.002406,0.001676,0.042563,25.384243,1.293135,0.425634,-70.947121,0.043448,0.000000
32.310001,5.641815,-70.902634,-0.002414,0.001687,0.042850,25.096046,1.278454,0.428496,-70.902634,0.043830,0.000000
32.540001,5.799324,-70.858154,-0.002402,0.001704,0.043283,25.796682,1.314146,0.432832,-70.858154,0.044211,0.000000
32.770000,5.749802,-70.902634,-0.002367,0.001714,0.043543,25.576395,1.302924,0.435434,-70.902634,0.044601,0.000000
33.000000,5.852951,-70.902634,-0.002363,0.001730,0.043942,26.035227,1.326298,0.439423,-70.902634,0.044983,0.000000
33.230003,6.001152,-71.036079,-0.002341,0.001746,0.044359,26.694458,1.359881,0.443586,-71.036079,0.045365,0.000000
33.460003,6.089409,-70.991600,-0.002333,0.001760,0.044697,27.087044,1.379880,0.446968,-70.991600,0.045746,0.000000
33.690002,6.256599,-70.947121,-0.002320,0.001780,0.045208,27.830744,1.417766,0.452085,-70.947121,0.046128,0.000000
33.920002,6.387306,-70.991600,-0.002294,0.001799,0.045685,28.412157,1.447384,0.456855,-70.991600,0.046518,0.000000
34.150002,6.321396,-71.036079,-0.002285,0.001810,0.045972,28.118973,1.432449,0.459716,-71.036079,0.046900,0.000000
34.380001,6.262932,-71.125038,-0.002272,0.001820,0.046232,27.858912,1.419201,0.462318,-71.125038,0.047281,0.000000
34.610001,6.475929,-71.125038,-0.002276,0.001837,0.046665,28.806372,1.467467,0.466654,-71.125038,0.047663,0.000000
34.840000,6.522476,-71.080559,-0.002251,0.001847,0.046926,29.013424,1.478014,0.469256,-71.080559,0.048044,0.000000
35.070004,6.843086,-71.125038,-0.002233,0.001869,0.047481,30.439568,1.550665,0.474806,-71.125038,0.048435,0.000000
35.300003,6.816277,-71.169525,-0.002212,0.001883,0.047827,30.320312,1.544590,0.478275,-71.169525,0.048816,0.000000
35.530003,6.856117,-71.214005,-0.002195,0.001897,0.048183,30.497532,1.553618,0.481831,-71.214005,0.049198,0.000000
35.760002,7.039703,-71.214005,-0.002186,0.001913,0.048599,31.314165,1.595220,0.485993,-71.214005,0.049579,0.000000
35.990002,7.168167,-71.214005,-0.002169,0.001932,0.049068,31.885599,1.624330,0.490676,-71.214005,0.049970,0.000000
36.220001,7.145081,-71.214005,-0.002151,0.001944,0.049389,31.782906,1.619098,0.493885,-71.214005,0.050351,0.000000
36.450001,7.176361,-71.302963,-0.002139,0.001956,0.049683,31.922049,1.626187,0.496834,-71.302963,0.050733,0.000000
36.680000,7.380791,-71.302963,-0.002134,0.001973,0.050117,32.831398,1.672511,0.501170,-71.302963,0.051114,0.000000
36.910000,7.461967,-71.258484,-0.002126,0.001986,0.050455,33.192490,1.690906,0.504552,-71.258484,0.051496,0.000000
37.140003,7.607941,-71.302963,-0.002104,0.002000,0.050811,33.841812,1.723984,0.508108,-71.302963,0.051886,0.000000
37.370003,7.689117,-71.302963,-0.002082,0.002017,0.051244,34.202904,1.742379,0.512444,-71.302963,0.052268,0.000000
37.600002,7.963928,-71.391930,-0.002070,0.002036,0.051721,35.425323,1.804652,0.517213,-71.391930,0.052649,0.000000
37.830002,8.072289,-71.347443,-0.002061,0.002052,0.052129,35.907333,1.829207,0.521289,-71.347443,0.053031,0.000000
38.060001,8.019043,-71.436409,-0.002048,0.002064,0.052415,35.670486,1.817141,0.524151,-71.436409,0.053412,0.000000
38.290001,7.978455,-71.391930,-0.002026,0.002074,0.052675,35.489937,1.807944,0.526753,-71.391930,0.053803,0.000000
38.520000,8.410774,-71.391930,-0.002018,0.002095,0.053204,37.412991,1.905909,0.532043,-71.391930,0.054184,0.000000
38.750000,8.476685,-71.525368,-0.002009,0.002108,0.053534,37.706177,1.920844,0.535338,-71.525368,0.054566,0.000000
38.980003,8.646484,-71.525368,-0.001992,0.002122,0.053907,38.461483,1.959321,0.539067,-71.525368,0.054947,0.000000
39.210003,8.481895,-71.480888,-0.001979,0.002128,0.054063,37.729355,1.922025,0.540628,-71.480888,0.055329,0.000000
39.440002,9.030777,-71.525368,-0.001975,0.002154,0.054713,40.170902,2.046403,0.547133,-71.525368,0.055719,0.000000
39.670002,9.124985,-71.569847,-0.001940,0.002171,0.055138,40.589958,2.067751,0.551382,-71.569847,0.056101,0.000000
39.900002,9.122375,-71.703293,-0.001927,0.002184,0.055468,40.578354,2.067160,0.554678,-71.703293,0.056482,0.000000
40.130001,9.139511,-71.614334,-0.001923,0.002196,0.055780,40.654575,2.071043,0.557800,-71.614334,0.056864,0.000000
40.360001,9.347664,-71.658813,-0.001919,0.002211,0.056162,41.580486,2.118211,0.561615,-71.658813,0.057246,0.000000
40.590000,9.706261,-71.614334,-0.001901,0.002229,0.056612,43.175602,2.199470,0.566125,-71.614334,0.057636,0.000000
40.820004,9.797119,-71.703293,-0.001884,0.002245,0.057020,43.579762,2.220059,0.570201,-71.703293,0.058017,0.000000
41.050003,10.000809,-71.658813,-0.001880,0.002260,0.057402,44.485821,2.266216,0.574017,-71.658813,0.058399,0.000000
41.280003,10.071182,-71.747772,-0.001863,0.002274,0.057766,44.798855,2.282162,0.577659,-71.747772,0.058781,0.000000
41.510002,10.368340,-71.747772,-0.001837,0.002291,0.058182,46.120678,2.349499,0.581822,-71.747772,0.059162,0.000000
41.740002,10.497177,-71.792252,-0.001828,0.002308,0.058616,46.693775,2.378694,0.586158,-71.792252,0.059552,0.000000
41.970001,10.537766,-71.792252,-0.001807,0.002321,0.058954,46.874321,2.387892,0.589540,-71.792252,0.059934,0.000000
42.200001,10.655067,-71.792252,-0.001794,0.002334,0.059284,47.396107,2.414473,0.592835,-71.792252,0.060316,0.000000
42.430000,11.026321,-71.836739,-0.001785,0.002350,0.059700,49.047527,2.498600,0.596998,-71.836739,0.060697,0.000000
42.660004,11.240433,-71.836739,-0.001781,0.002366,0.060090,49.999943,2.547118,0.600901,-71.836739,0.061079,0.000000
42.890003,11.535355,-71.836739,-0.001742,0.002381,0.060480,51.311821,2.613949,0.604803,-71.836739,0.061469,0.000000
43.120003,11.740906,-71.881218,-0.001738,0.002398,0.060897,52.226158,2.660527,0.608966,-71.881218,0.061851,0.000000
43.350002,11.514870,-71.970177,-0.001729,0.002407,0.061139,51.220699,2.609307,0.611394,-71.970177,0.062232,0.000000
43.580002,12.084976,-72.014656,-0.001725,0.002427,0.061634,53.756660,2.738495,0.616337,-72.014656,0.062614,0.000000
43.810001,12.258499,-72.014656,-0.001707,0.002442,0.062033,54.528526,2.777816,0.620327,-72.014656,0.062995,0.000000
44.040001,12.326271,-72.014656,-0.001694,0.002456,0.062380,54.829990,2.793173,0.623795,-72.014656,0.063386,0.000000
44.270000,12.808495,-72.014656,-0.001677,0.002476,0.062883,56.975029,2.902446,0.628825,-72.014656,0.063767,0.000000
44.500004,12.831207,-72.103622,-0.001664,0.002487,0.063177,57.076061,2.907593,0.631774,-72.103622,0.064149,0.000000
44.730003,13.107880,-72.059143,-0.001647,0.002502,0.063550,58.306759,2.970288,0.635503,-72.059143,0.064530,0.000000
44.960003,13.386787,-72.059143,-0.001647,0.002519,0.063984,59.547405,3.033489,0.639839,-72.059143,0.064921,0.000000
45.190002,13.436317,-72.059143,-0.001630,0.002533,0.064331,59.767727,3.044713,0.643308,-72.059143,0.065302,0.000000
45.420002,13.773308,-72.192581,-0.001608,0.002546,0.064660,61.266731,3.121076,0.646603,-72.192581,0.065684,0.000000
45.650002,14.007164,-72.192581,-0.001617,0.002564,0.065120,62.306976,3.174069,0.651200,-72.192581,0.066065,0.000000
45.880001,14.352348,-72.148102,-0.001582,0.002580,0.065528,63.842434,3.252289,0.655276,-72.148102,0.066447,0.000000
46.110001,14.846863,-72.192581,-0.001578,0.002597,0.065961,66.042145,3.364347,0.659612,-72.192581,0.066837,0.000000
46.340004,14.787285,-72.192581,-0.001552,0.002608,0.066239,65.777130,3.350847,0.662387,-72.192581,0.067219,0.000000
46.570004,15.209923,-72.237068,-0.001539,0.002626,0.066707,67.657112,3.446618,0.667070,-72.237068,0.067600,0.000000
46.800003,15.485481,-72.326027,-0.001535,0.002640,0.067054,68.882858,3.509060,0.670539,-72.326027,0.067982,0.000000
47.030003,15.965843,-72.326027,-0.001526,0.002659,0.067540,71.019615,3.617912,0.675395,-72.326027,0.068363,0.000000
47.260002,16.042549,-72.281548,-0.001505,0.002672,0.067860,71.360825,3.635294,0.678604,-72.281548,0.068754,0.000000
47.490002,15.888756,-72.370506,-0.001496,0.002678,0.068025,70.676712,3.600444,0.680252,-72.370506,0.069135,0.000000
47.720001,16.444336,-72.370506,-0.001479,0.002699,0.068554,73.148056,3.726340,0.685542,-72.370506,0.069517,0.000000
47.950001,16.993958,-72.414986,-0.001470,0.002716,0.068996,75.592896,3.850886,0.689965,-72.414986,0.069898,0.000000
48.180004,17.202492,-72.414986,-0.001466,0.002729,0.069317,76.520508,3.898140,0.693173,-72.414986,0.070280,0.000000
48.410004,17.276588,-72.414986,-0.001457,0.002741,0.069612,76.850105,3.914931,0.696122,-72.414986,0.070670,0.000000
48.640003,17.892120,-72.370506,-0.001440,0.002758,0.070046,79.588127,4.054412,0.700458,-72.370506,0.071052,0.000000
48.870003,18.233215,-72.503952,-0.001414,0.002773,0.070445,81.105392,4.131706,0.704447,-72.503952,0.071433,0.000000
49.100002,19.053551,-72.503952,-0.001423,0.002794,0.070956,84.754425,4.317596,0.709564,-72.503952,0.071815,0.000000
49.330002,18.820450,-72.503952,-0.001393,0.002801,0.071156,83.717545,4.264775,0.711559,-72.503952,0.072197,0.000000
49.560001,19.578972,-72.503952,-0.001393,0.002823,0.071694,87.091614,4.436658,0.716936,-72.503952,0.072587,0.000000
49.790001,19.801651,-72.503952,-0.001367,0.002837,0.072049,88.082146,4.487118,0.720491,-72.503952,0.072968,0.000000
50.020004,20.250359,-72.548431,-0.001362,0.002852,0.072448,90.078094,4.588797,0.724480,-72.548431,0.073350,0.000000
50.250004,20.330421,-72.681877,-0.001358,0.002864,0.072734,90.434235,4.606939,0.727342,-72.681877,0.073732,0.000000
50.480003,20.595917,-72.592911,-0.001345,0.002877,0.073064,91.615211,4.667102,0.730638,-72.592911,0.074113,0.000000
50.710003,20.937759,-72.637390,-0.001341,0.002890,0.073411,93.135803,4.744564,0.734107,-72.637390,0.074503,0.000000
50.940002,21.764427,-72.637390,-0.001319,0.002911,0.073948,96.813004,4.931890,0.739483,-72.637390,0.074885,0.000000
51.170002,22.102165,-72.770836,-0.001311,0.002923,0.074243,98.315338,5.008422,0.742432,-72.770836,0.075267,0.000000
51.400002,22.428734,-72.770836,-0.001302,0.002937,0.074599,99.767990,5.082424,0.745988,-72.770836,0.075648,0.000000
51.630001,23.070709,-72.681877,-0.001293,0.002956,0.075084,102.623642,5.227897,0.750844,-72.681877,0.076030,0.000000
51.860001,23.285194,-72.726357,-0.001285,0.002968,0.075379,103.577721,5.276500,0.753793,-72.726357,0.076420,0.000000
52.090004,23.370094,-72.726357,-0.001255,0.002977,0.075622,103.955368,5.295739,0.756221,-72.726357,0.076802,0.000000
52.320004,24.208305,-72.770836,-0.001246,0.002995,0.076064,107.683922,5.485680,0.760644,-72.770836,0.077183,0.000000
52.550003,24.996986,-72.815315,-0.001242,0.003015,0.076585,111.192146,5.664398,0.765847,-72.815315,0.077565,0.000000
52.780003,25.282600,-72.770836,-0.001229,0.003028,0.076914,112.462624,5.729119,0.769142,-72.770836,0.077955,0.000000
53.010002,26.147621,-72.859795,-0.001212,0.003048,0.077417,116.310425,5.925136,0.774172,-72.859795,0.078336,0.000000
53.240002,26.502861,-72.904282,-0.001207,0.003063,0.077790,117.890617,6.005634,0.777901,-72.904282,0.078718,0.000000
53.470001,27.072220,-72.904282,-0.001186,0.003078,0.078172,120.423248,6.134653,0.781717,-72.904282,0.079100,0.000000
53.700001,27.129936,-72.948761,-0.001190,0.003088,0.078423,120.679985,6.147731,0.784232,-72.948761,0.079481,0.000000
53.930004,28.025124,-72.948761,-0.001173,0.003106,0.078892,124.661972,6.350584,0.788915,-72.948761,0.079871,0.000000
54.160004,28.292488,-72.948761,-0.001164,0.003117,0.079160,125.851273,6.411170,0.791604,-72.948761,0.080253,0.000000
54.390003,28.722572,-72.948761,-0.001151,0.003129,0.079481,127.764381,6.508628,0.794812,-72.948761,0.080635,0.000000
54.620003,29.519081,-73.037720,-0.001143,0.003148,0.079967,131.307434,6.689120,0.799669,-73.037720,0.081016,0.000000
54.850002,30.715515,-73.082199,-0.001138,0.003169,0.080487,136.629440,6.960235,0.804872,-73.082199,0.081398,0.000000
55.080002,31.271469,-73.037720,-0.001130,0.003186,0.080912,139.102448,7.086216,0.809122,-73.037720,0.081788,0.000000
55.310001,31.891464,-72.993240,-0.001117,0.003199,0.081259,141.860321,7.226709,0.812590,-72.993240,0.082170,0.000000
55.540001,32.038925,-73.082199,-0.001104,0.003208,0.081493,142.516251,7.260124,0.814932,-73.082199,0.082551,0.000000
55.770004,32.559128,-73.082199,-0.001099,0.003223,0.081857,144.830231,7.378004,0.818574,-73.082199,0.082933,0.000000
56.000004,33.472557,-73.171165,-0.001091,0.003242,0.082343,148.893372,7.584990,0.823431,-73.171165,0.083314,0.000000
56.230003,33.697845,-73.171165,-0.001091,0.003253,0.082629,149.895508,7.636041,0.826293,-73.171165,0.083705,0.000000
56.460003,34.911781,-73.171165,-0.001074,0.003272,0.083098,155.295364,7.911123,0.830976,-73.171165,0.084086,0.000000
56.690002,35.539970,-73.171165,-0.001056,0.003285,0.083427,158.089691,8.053473,0.834271,-73.171165,0.084468,0.000000
56.920002,36.102257,-73.215645,-0.001061,0.003302,0.083878,160.590866,8.180888,0.838781,-73.215645,0.084849,0.000000
57.150002,36.887962,-73.215645,-0.001056,0.003317,0.084260,164.085846,8.358932,0.842597,-73.215645,0.085231,0.000000
57.380001,37.860596,-73.215645,-0.001039,0.003334,0.084676,168.412338,8.579334,0.846759,-73.215645,0.085621,0.000000
57.610004,38.284729,-73.304604,-0.001035,0.003347,0.085005,170.298981,8.675444,0.850055,-73.304604,0.086003,0.000000
57.840004,38.868607,-73.304604,-0.001018,0.003359,0.085326,172.896194,8.807753,0.853263,-73.304604,0.086384,0.000000
58.070004,39.844971,-73.304604,-0.001018,0.003377,0.085769,177.239288,9.028999,0.857686,-73.304604,0.086766,0.000000
58.300003,40.550613,-73.349091,-0.001000,0.003390,0.086107,180.378143,9.188900,0.861068,-73.349091,0.087148,0.000000
58.530003,40.910698,-73.304604,-0.000996,0.003399,0.086341,181.979874,9.270496,0.863410,-73.304604,0.087538,0.000000
58.760002,42.199478,-73.393570,-0.000983,0.003422,0.086922,187.712646,9.562539,0.869220,-73.393570,0.087919,0.000000
58.990002,43.149399,-73.438049,-0.000970,0.003437,0.087304,191.938110,9.777794,0.873036,-73.438049,0.088301,0.000000
59.220001,43.967880,-73.438049,-0.000961,0.003454,0.087729,195.578903,9.963264,0.877286,-73.438049,0.088683,0.000000
59.450005,44.444511,-73.482529,-0.000974,0.003466,0.088032,197.699066,10.071270,0.880321,-73.482529,0.089064,0.000000
59.680004,44.866783,-73.438049,-0.000953,0.003477,0.088327,199.577423,10.166959,0.883269,-73.438049,0.089454,0.000000
59.910004,46.265045,-73.527016,-0.000940,0.003496,0.088804,205.797195,10.483809,0.888039,-73.527016,0.089836,0.000000
60.140003,46.884300,-73.482529,-0.000940,0.003509,0.089116,208.551788,10.624135,0.891161,-73.482529,0.090217,0.000000
60.370003,47.901993,-73.571495,-0.000927,0.003526,0.089567,213.078705,10.854747,0.895671,-73.571495,0.090599,0.000000
60.600002,48.866806,-73.571495,-0.000927,0.003539,0.089897,217.370407,11.073377,0.898966,-73.571495,0.090981,0.000000
60.830002,49.782471,-73.527016,-0.000914,0.003557,0.090339,221.443497,11.280869,0.903389,-73.527016,0.091371,0.000000
61.060001,50.829208,-73.527016,-0.000910,0.003572,0.090729,226.099609,11.518064,0.907291,-73.527016,0.091752,0.000000
61.290005,51.692001,-73.660454,-0.000897,0.003587,0.091119,229.937500,11.713575,0.911194,-73.660454,0.092134,0.000000
61.520004,52.239014,-73.704933,-0.000892,0.003598,0.091380,232.370743,11.837530,0.913796,-73.704933,0.092516,0.000000
61.750004,53.613441,-73.660454,-0.000901,0.003618,0.091891,238.484497,12.148979,0.918912,-73.660454,0.092906,0.000000
61.980003,54.605438,-73.660454,-0.000880,0.003632,0.092247,242.897125,12.373769,0.922468,-73.660454,0.093287,0.000000
62.210003,55.609360,-73.660454,-0.000862,0.003645,0.092594,247.362793,12.601261,0.925937,-73.660454,0.093669,0.000000
62.440002,56.434532,-73.749420,-0.000858,0.003660,0.092958,251.033340,12.788248,0.929579,-73.749420,0.094051,0.000000
62.670002,57.058258,-73.749420,-0.000862,0.003673,0.093296,253.807800,12.929585,0.932961,-73.749420,0.094432,0.000000
62.900002,58.844902,-73.749420,-0.000862,0.003694,0.093825,261.755188,13.334446,0.938251,-73.749420,0.094822,0.000000
63.130005,59.976913,-73.749420,-0.000849,0.003710,0.094233,266.790649,13.590962,0.942327,-73.749420,0.095204,0.000000
63.360004,60.628937,-73.838379,-0.000832,0.003720,0.094493,269.690979,13.738714,0.944929,-73.838379,0.095586,0.000000
63.590004,61.444061,-73.793900,-0.000828,0.003733,0.094814,273.316833,13.923423,0.948138,-73.793900,0.095967,0.000000
63.820004,62.813278,-73.882858,-0.000823,0.003750,0.095256,279.407410,14.233692,0.952561,-73.882858,0.096349,0.000000
64.050003,63.874916,-73.882858,-0.000841,0.003765,0.095638,284.129822,14.474263,0.956376,-73.882858,0.096739,0.000000
64.280006,65.141716,-73.882858,-0.000819,0.003781,0.096037,289.764832,14.761324,0.960366,-73.882858,0.097121,0.000000
64.510002,66.417091,-73.927338,-0.000806,0.003798,0.096470,295.437988,15.050327,0.964702,-73.927338,0.097502,0.000000
64.740005,67.088860,-73.971825,-0.000806,0.003811,0.096791,298.426147,15.202553,0.967911,-73.971825,0.097884,0.000000
64.970001,67.052361,-73.927338,-0.000802,0.003804,0.096626,298.263794,15.194283,0.966263,-73.927338,0.096878,0.000000
65.200005,66.537743,-73.971825,-0.000802,0.003804,0.096609,295.974670,15.077668,0.966089,-73.971825,0.096626,0.000000
65.430000,66.112129,-73.971825,-0.000793,0.003802,0.096583,294.081451,14.981222,0.965829,-73.971825,0.096626,0.000000
65.660004,65.743095,-73.971825,-0.000772,0.003802,0.096566,292.439880,14.897599,0.965656,-73.971825,0.096626,0.000000
65.889999,65.396049,-74.060783,-0.000780,0.003801,0.096557,290.896149,14.818957,0.965569,-74.060783,0.096626,0.000000
66.120003,65.111931,-74.060783,-0.000785,0.003801,0.096557,289.632324,14.754575,0.965569,-74.060783,0.096626,0.000000
66.350006,64.838982,-74.060783,-0.000785,0.003801,0.096548,288.418182,14.692723,0.965482,-74.060783,0.096626,0.000000
66.580002,64.597313,-74.105263,-0.000772,0.003801,0.096548,287.343201,14.637960,0.965482,-74.105263,0.096626,0.000000
66.810005,64.395851,-74.105263,-0.000767,0.003801,0.096548,286.447052,14.592308,0.965482,-74.105263,0.096626,0.000000
67.040001,64.197762,-74.194229,-0.000763,0.003801,0.096540,285.565918,14.547421,0.965396,-74.194229,0.096626,0.000000
67.270004,64.007103,-74.194229,-0.000776,0.003801,0.096540,284.717804,14.504216,0.965396,-74.194229,0.096626,0.000000
67.500000,63.837303,-74.194229,-0.000767,0.003801,0.096540,283.962494,14.465739,0.965396,-74.194229,0.096626,0.000000
67.730003,63.684258,-74.238708,-0.000767,0.003801,0.096540,283.281738,14.431059,0.965396,-74.238708,0.096626,0.000000
67.960007,63.532326,-74.238708,-0.000776,0.003801,0.096540,282.605896,14.396631,0.965396,-74.238708,0.096626,0.000000
68.190002,63.400139,-74.283188,-0.000785,0.003801,0.096540,282.017914,14.366676,0.965396,-74.283188,0.096626,0.000000
68.420006,63.282097,-74.283188,-0.000776,0.003801,0.096540,281.492828,14.339928,0.965396,-74.283188,0.096626,0.000000
68.650002,63.159203,-74.238708,-0.000780,0.003801,0.096540,280.946167,14.312080,0.965396,-74.238708,0.096626,0.000000
68.880005,63.039299,-74.327667,-0.000767,0.003801,0.096540,280.412811,14.284909,0.965396,-74.327667,0.096626,0.000000
69.110001,62.932060,-74.372147,-0.000763,0.003801,0.096540,279.935791,14.260610,0.965396,-74.372147,0.096626,0.000000
69.340004,62.830032,-74.372147,-0.000763,0.003801,0.096540,279.481934,14.237489,0.965396,-74.372147,0.096626,0.000000
69.570000,62.730980,-74.416634,-0.000755,0.003801,0.096540,279.041321,14.215044,0.965396,-74.416634,0.096626,0.000000
69.800003,62.644218,-74.372147,-0.000772,0.003801,0.096540,278.655396,14.195382,0.965396,-74.372147,0.096626,0.000000
70.030006,62.557083,-74.416634,-0.000755,0.003801,0.096540,278.267792,14.175638,0.965396,-74.416634,0.096626,0.000000
70.260002,62.458778,-74.461113,-0.000759,0.003801,0.096540,277.830536,14.153361,0.965396,-74.461113,0.096626,0.000000
70.490005,62.372383,-74.461113,-0.000755,0.003801,0.096540,277.446228,14.133783,0.965396,-74.461113,0.096626,0.000000
70.720001,62.299774,-74.461113,-0.000767,0.003801,0.096540,277.123230,14.117331,0.965396,-74.461113,0.096626,0.000000
70.950005,62.234978,-74.505592,-0.000750,0.003801,0.096540,276.835022,14.102648,0.965396,-74.505592,0.096626,0.000000
71.180000,62.166840,-74.505592,-0.000746,0.003801,0.096540,276.531921,14.087207,0.965396,-74.505592,0.096626,0.000000
71.410004,62.090874,-74.550072,-0.000755,0.003801,0.096540,276.194000,14.069993,0.965396,-74.550072,0.096626,0.000000
71.640007,62.011559,-74.594559,-0.000772,0.003801,0.096540,275.841187,14.052020,0.965396,-74.594559,0.096626,0.000000
71.870003,61.943787,-74.550072,-0.000772,0.003801,0.096540,275.539734,14.036663,0.965396,-74.550072,0.096626,0.000000
72.100006,61.893143,-74.594559,-0.000759,0.003800,0.096531,275.314453,14.025187,0.965309,-74.594559,0.096626,0.000000
72.330002,61.835800,-74.639038,-0.000755,0.003800,0.096531,275.059387,14.012193,0.965309,-74.639038,0.096626,0.000000
72.560005,61.779572,-74.594559,-0.000759,0.003800,0.096531,274.809265,13.999452,0.965309,-74.594559,0.096626,0.000000
72.790001,61.716637,-74.639038,-0.000750,0.003800,0.096531,274.529297,13.985190,0.965309,-74.639038,0.096626,0.000000
73.020004,61.644402,-74.683517,-0.000755,0.003800,0.096531,274.208008,13.968821,0.965309,-74.683517,0.096626,0.000000
73.250000,61.599342,-74.772476,-0.000763,0.003800,0.096531,274.007568,13.958611,0.965309,-74.772476,0.096626,0.000000
73.480003,61.572533,-74.727997,-0.000750,0.003800,0.096531,273.888306,13.952535,0.965309,-74.727997,0.096626,0.000000
73.710007,61.512581,-74.727997,-0.000763,0.003800,0.096531,273.621613,13.938950,0.965309,-74.727997,0.096626,0.000000
73.940002,61.456718,-74.772476,-0.000759,0.003800,0.096531,273.373138,13.926291,0.965309,-74.772476,0.096626,0.000000
74.170006,61.408684,-74.772476,-0.000759,0.003800,0.096531,273.159454,13.915407,0.965309,-74.772476,0.096626,0.000000
74.400002,61.357674,-74.772476,-0.000763,0.003800,0.096531,272.932556,13.903848,0.965309,-74.772476,0.096626,0.000000
74.630005,61.320435,-74.861443,-0.000750,0.003800,0.096531,272.766907,13.895409,0.965309,-74.861443,0.096626,0.000000
74.860001,61.292503,-74.905922,-0.000750,0.003800,0.096531,272.642670,13.889080,0.965309,-74.905922,0.096626,0.000000
75.090004,61.228088,-74.905922,-0.000763,0.003800,0.096531,272.356140,13.874483,0.965309,-74.905922,0.096626,0.000000
75.320007,61.190475,-74.861443,-0.000755,0.003800,0.096531,272.188843,13.865959,0.965309,-74.861443,0.096626,0.000000
75.550003,61.138344,-74.816963,-0.000750,0.003800,0.096531,271.956940,13.854147,0.965309,-74.816963,0.096626,0.000000
75.780006,61.100731,-74.905922,-0.000746,0.003800,0.096531,271.789612,13.845623,0.965309,-74.905922,0.096626,0.000000
76.010002,61.064987,-74.950401,-0.000759,0.003800,0.096531,271.630615,13.837524,0.965309,-74.950401,0.096626,0.000000
76.240005,61.037056,-75.039368,-0.000759,0.003800,0.096531,271.506378,13.831195,0.965309,-75.039368,0.096626,0.000000
76.470001,61.000565,-75.039368,-0.000755,0.003800,0.096531,271.344055,13.822926,0.965309,-75.039368,0.096626,0.000000
76.700005,60.957741,-74.994881,-0.000750,0.003800,0.096531,271.153564,13.813221,0.965309,-74.994881,0.096626,0.000000
76.930000,60.918640,-75.039368,-0.000742,0.003800,0.096531,270.979645,13.804360,0.965309,-75.039368,0.096626,0.000000
77.160004,60.879921,-75.128326,-0.000763,0.003800,0.096531,270.807404,13.795588,0.965309,-75.128326,0.096626,0.000000
77.390007,60.855713,-75.083847,-0.000763,0.003800,0.096531,270.699738,13.790101,0.965309,-75.083847,0.096626,0.000000
77.620003,60.822945,-75.128326,-0.000759,0.003800,0.096531,270.553955,13.782676,0.965309,-75.128326,0.096626,0.000000
77.850006,60.778633,-75.128326,-0.000759,0.003800,0.096531,270.356873,13.772635,0.965309,-75.128326,0.096626,0.000000
78.080002,60.744743,-75.172806,-0.000750,0.003800,0.096531,270.206116,13.764956,0.965309,-75.172806,0.096626,0.000000
78.310005,60.708252,-75.172806,-0.000750,0.003800,0.096531,270.043793,13.756686,0.965309,-75.172806,0.096626,0.000000
78.540001,60.692238,-75.172806,-0.000763,0.003800,0.096531,269.972565,13.753057,0.965309,-75.172806,0.096626,0.000000
78.770004,60.660591,-75.172806,-0.000759,0.003800,0.096531,269.831787,13.745887,0.965309,-75.172806,0.096626,0.000000
79.000000,60.625214,-75.261772,-0.000759,0.003800,0.096531,269.674408,13.737869,0.965309,-75.261772,0.096626,0.000000
79.230003,60.590210,-75.261772,-0.000750,0.003800,0.096531,269.518707,13.729938,0.965309,-75.261772,0.096626,0.000000
79.460007,60.557816,-75.306252,-0.000750,0.003800,0.096531,269.374603,13.722597,0.965309,-75.306252,0.096626,0.000000
79.690002,60.529884,-75.306252,-0.000759,0.003800,0.096531,269.250366,13.716268,0.965309,-75.306252,0.096626,0.000000
79.920006,60.526535,-75.306252,-0.000746,0.003800,0.096531,269.235474,13.715508,0.965309,-75.306252,0.096626,0.000000
80.150002,60.491158,-75.261772,-0.000750,0.003800,0.096531,269.078094,13.707493,0.965309,-75.261772,0.096626,0.000000
80.380005,60.446106,-75.395210,-0.000759,0.003800,0.096531,268.877716,13.697284,0.965309,-75.395210,0.096626,0.000000
80.610001,60.420410,-75.350731,-0.000750,0.003800,0.096531,268.763397,13.691461,0.965309,-75.350731,0.096626,0.000000
80.840004,60.398437,-75.395210,-0.000746,0.003800,0.096531,268.665680,13.686481,0.965309,-75.395210,0.096626,0.000000
81.070007,60.374977,-75.439690,-0.000750,0.003800,0.096531,268.561310,13.681165,0.965309,-75.439690,0.096626,0.000000
81.300003,60.361572,-75.439690,-0.000746,0.003800,0.096531,268.501678,13.678128,0.965309,-75.439690,0.096626,0.000000
81.530006,60.330666,-75.484177,-0.000750,0.003800,0.096531,268.364197,13.671124,0.965309,-75.484177,0.096626,0.000000
81.760002,60.288963,-75.528656,-0.000746,0.003800,0.096531,268.178711,13.661674,0.965309,-75.528656,0.096626,0.000000
81.990005,60.240181,-75.484177,-0.000750,0.003800,0.096531,267.961700,13.650620,0.965309,-75.484177,0.096626,0.000000
82.220001,60.254333,-75.484177,-0.000742,0.003800,0.096531,268.024658,13.653827,0.965309,-75.484177,0.096626,0.000000
82.450005,60.244652,-75.528656,-0.000746,0.003800,0.096531,267.981598,13.651632,0.965309,-75.528656,0.096626,0.000000
82.680000,60.209274,-75.617615,-0.000750,0.003800,0.096531,267.824219,13.643617,0.965309,-75.617615,0.096626,0.000000
82.910004,60.179115,-75.662094,-0.000759,0.003800,0.096531,267.690063,13.636783,0.965309,-75.662094,0.096626,0.000000
83.140007,60.150810,-75.573135,-0.000746,0.003800,0.096531,267.564178,13.630368,0.965309,-75.573135,0.096626,0.000000
83.370003,60.138527,-75.617615,-0.000759,0.003800,0.096531,267.509521,13.627585,0.965309,-75.617615,0.096626,0.000000
83.600006,60.112083,-75.662094,-0.000750,0.003800,0.096531,267.391907,13.621593,0.965309,-75.662094,0.096626,0.000000
83.830002,60.103889,-75.751060,-0.000750,0.003800,0.096531,267.355438,13.619736,0.965309,-75.751060,0.096626,0.000000
84.060005,60.069260,-75.751060,-0.000746,0.003800,0.096531,267.201416,13.611889,0.965309,-75.751060,0.096626,0.000000
84.290001,60.051018,-75.706581,-0.000759,0.003800,0.096531,267.120270,13.607755,0.965309,-75.706581,0.096626,0.000000
84.520004,60.019737,-75.795540,-0.000746,0.003800,0.096531,266.981140,13.600667,0.965309,-75.795540,0.096626,0.000000
84.750008,60.008568,-75.795540,-0.000759,0.003800,0.096531,266.931427,13.598136,0.965309,-75.795540,0.096626,0.000000
84.980003,59.992554,-75.795540,-0.000759,0.003800,0.096531,266.860199,13.594507,0.965309,-75.795540,0.096626,0.000000
85.210007,59.977661,-75.840019,-0.000750,0.003800,0.096531,266.793976,13.591132,0.965309,-75.840019,0.096626,0.000000
85.440002,59.943771,-75.884506,-0.000746,0.003800,0.096531,266.643219,13.583453,0.965309,-75.884506,0.096626,0.000000
85.670006,59.924782,-75.840019,-0.000750,0.003800,0.096531,266.558746,13.579150,0.965309,-75.840019,0.096626,0.000000
85.900002,59.899086,-75.884506,-0.000750,0.003800,0.096531,266.444427,13.573327,0.965309,-75.884506,0.096626,0.000000
86.130005,59.887543,-75.928986,-0.000742,0.003800,0.096531,266.393097,13.570711,0.965309,-75.928986,0.096626,0.000000
86.360001,59.870789,-75.884506,-0.000750,0.003800,0.096531,266.318573,13.566915,0.965309,-75.884506,0.096626,0.000000
86.590004,59.855896,-75.928986,-0.000746,0.003800,0.096531,266.252319,13.563540,0.965309,-75.928986,0.096626,0.000000
86.820007,59.819031,-75.928986,-0.000746,0.003800,0.096531,266.088348,13.555186,0.965309,-75.928986,0.096626,0.000000
87.050003,59.804131,-75.973465,-0.000733,0.003800,0.096531,266.022064,13.551809,0.965309,-75.973465,0.096626,0.000000
87.280006,59.796684,-76.062424,-0.000737,0.003800,0.096531,265.988922,13.550122,0.965309,-76.062424,0.096626,0.000000
87.510002,59.774345,-76.062424,-0.000746,0.003800,0.096531,265.889557,13.545060,0.965309,-76.062424,0.096626,0.000000
87.740005,59.773598,-76.017944,-0.000750,0.003800,0.096531,265.886230,13.544890,0.965309,-76.017944,0.096626,0.000000
87.970001,59.754982,-76.062424,-0.000755,0.003800,0.096531,265.803436,13.540673,0.965309,-76.062424,0.096626,0.000000
88.200005,59.715881,-76.062424,-0.000733,0.003800,0.096531,265.629517,13.531813,0.965309,-76.062424,0.096626,0.000000
88.430008,59.706200,-76.106911,-0.000742,0.003800,0.096531,265.586426,13.529618,0.965309,-76.106911,0.096626,0.000000
88.660004,59.693909,-76.195869,-0.000746,0.003800,0.096531,265.531769,13.526833,0.965309,-76.195869,0.096626,0.000000
88.890007,59.683113,-76.151390,-0.000746,0.003800,0.096531,265.483734,13.524387,0.965309,-76.151390,0.096626,0.000000
89.120003,59.653320,-76.151390,-0.000755,0.003800,0.096531,265.351227,13.517635,0.965309,-76.151390,0.096626,0.000000
89.350006,59.642899,-76.151390,-0.000755,0.003800,0.096531,265.304871,13.515274,0.965309,-76.151390,0.096626,0.000000
89.580002,59.619064,-76.195869,-0.000746,0.003800,0.096531,265.198853,13.509873,0.965309,-76.195869,0.096626,0.000000
89.810005,59.592628,-76.240349,-0.000746,0.003800,0.096531,265.081238,13.503882,0.965309,-76.240349,0.096626,0.000000
90.040001,59.596725,-76.284828,-0.000755,0.003800,0.096531,265.099487,13.504811,0.965309,-76.284828,0.096626,0.000000
90.270004,59.591133,-76.195869,-0.000742,0.003800,0.096531,265.074585,13.503544,0.965309,-76.195869,0.096626,0.000000
90.500008,59.543472,-76.284828,-0.000750,0.003800,0.096531,264.862579,13.492743,0.965309,-76.284828,0.096626,0.000000
90.730003,59.531929,-76.373795,-0.000750,0.003800,0.096531,264.811249,13.490128,0.965309,-76.373795,0.096626,0.000000
90.960007,59.521873,-76.373795,-0.000759,0.003800,0.096531,264.766510,13.487849,0.965309,-76.373795,0.096626,0.000000
91.190002,59.515175,-76.373795,-0.000742,0.003800,0.096531,264.736725,13.486331,0.965309,-76.373795,0.096626,0.000000
91.420006,59.511078,-76.329315,-0.000750,0.003800,0.096531,264.718506,13.485403,0.965309,-76.329315,0.096626,0.000000
91.650002,59.479424,-76.418274,-0.000746,0.003800,0.096531,264.577698,13.478230,0.965309,-76.418274,0.096626,0.000000
91.880005,59.450752,-76.418274,-0.000755,0.003800,0.096531,264.450165,13.471733,0.965309,-76.418274,0.096626,0.000000
92.110001,59.447769,-76.418274,-0.000742,0.003800,0.096531,264.436890,13.471057,0.965309,-76.418274,0.096626,0.000000
92.340004,59.436974,-76.418274,-0.000750,0.003800,0.096531,264.388855,13.468611,0.965309,-76.418274,0.096626,0.000000
92.570007,59.441444,-76.418274,-0.000746,0.003800,0.096531,264.408752,13.469625,0.965309,-76.418274,0.096626,0.000000
92.800003,59.404953,-76.507233,-0.000750,0.003800,0.096531,264.246429,13.461354,0.965309,-76.507233,0.096626,0.000000
93.030006,59.372551,-76.551720,-0.000746,0.003800,0.096531,264.102295,13.454012,0.965309,-76.551720,0.096626,0.000000
93.260002,59.378136,-76.551720,-0.000750,0.003800,0.096531,264.127136,13.455277,0.965309,-76.551720,0.096626,0.000000
93.490005,59.356911,-76.551720,-0.000742,0.003800,0.096531,264.032715,13.450468,0.965309,-76.551720,0.096626,0.000000
93.720001,59.356911,-76.507233,-0.000737,0.003800,0.096531,264.032715,13.450468,0.965309,-76.507233,0.096626,0.000000
93.950005,59.334946,-76.596199,-0.000746,0.003800,0.096531,263.935028,13.445491,0.965309,-76.596199,0.096626,0.000000
94.180008,59.307014,-76.685158,-0.000750,0.003800,0.096531,263.810791,13.439161,0.965309,-76.685158,0.096626,0.000000
94.410004,59.302177,-76.596199,-0.000755,0.003800,0.096531,263.789246,13.438066,0.965309,-76.596199,0.096626,0.000000
94.640007,59.298080,-76.640678,-0.000750,0.003800,0.096531,263.771027,13.437138,0.965309,-76.640678,0.096626,0.000000
94.870003,59.287651,-76.640678,-0.000733,0.003800,0.096531,263.724640,13.434774,0.965309,-76.640678,0.096626,0.000000
95.100006,59.273872,-76.685158,-0.000746,0.003800,0.096531,263.663361,13.431651,0.965309,-76.685158,0.096626,0.000000
95.300003,59.251907,-76.774124,-0.000742,0.003800,0.096531,263.565643,13.426674,0.965309,-76.774124,0.096626,0.000000