File: Data/compression 11/AutoNoHeating-12-11-3-240530_05302024_161603.csv
Time (sec),S:Load (lbs),S:HL1 (DIM),S:LVDT (in),S:Position (in),Ch:Position (mm),Ch:Load (N),Ch:Stress (MPa),Ch:Strain (mm/mm),Ch:HL1 (DIM),Set Point (),Cycles ()
0.210000,-0.017494,-97.413284,-0.011839,0.000000,0.000009,-0.077818,-0.003964,0.000087,-97.413284,0.000278,0.000000
0.450000,-0.010048,-97.502243,-0.011822,0.000000,0.000009,-0.044695,-0.002277,0.000087,-97.502243,0.000312,0.000000
0.690000,-0.064041,-97.502243,-0.011839,0.000126,0.003191,-0.284869,-0.014512,0.031914,-97.502243,0.004301,0.000000
0.930000,-0.042816,-97.546722,-0.011745,0.000277,0.007042,-0.190456,-0.009702,0.070419,-97.546722,0.008308,0.000000
1.170000,-0.028671,-97.502243,-0.011576,0.000437,0.011100,-0.127536,-0.006497,0.111005,-97.502243,0.012297,0.000000
1.410000,-0.011169,-97.546722,-0.011426,0.000591,0.015003,-0.049684,-0.002531,0.150030,-97.546722,0.016304,0.000000
1.650000,-0.048035,-97.546722,-0.011249,0.000758,0.019244,-0.213669,-0.010885,0.192437,-97.546722,0.020293,0.000000
1.890000,-0.024948,-97.591209,-0.011094,0.000916,0.023259,-0.110975,-0.005653,0.232590,-97.591209,0.024300,0.000000
2.130000,-0.016380,-97.680168,-0.010951,0.001064,0.027031,-0.072863,-0.003712,0.270314,-97.680168,0.028289,0.000000
2.370000,-0.017494,-97.635689,-0.010792,0.001225,0.031125,-0.077818,-0.003964,0.311247,-97.635689,0.032295,0.000000
2.610000,-0.035744,-97.680168,-0.010606,0.001386,0.035201,-0.158996,-0.008100,0.352007,-97.680168,0.036302,0.000000
2.850000,-0.036118,-97.680168,-0.010455,0.001536,0.039025,-0.160659,-0.008184,0.390252,-97.680168,0.040291,0.000000
3.090000,-0.026810,-97.591209,-0.010300,0.001695,0.043058,-0.119255,-0.006075,0.430578,-97.591209,0.044298,0.000000
3.330000,-0.022339,-97.769127,-0.010149,0.001857,0.047168,-0.099368,-0.005062,0.471684,-97.769127,0.048287,0.000000
3.570000,-0.027550,-97.680168,-0.009985,0.002011,0.051088,-0.122547,-0.006243,0.510883,-97.680168,0.052294,0.000000
3.810000,-0.031647,-97.724648,-0.009809,0.002174,0.055225,-0.140772,-0.007171,0.552249,-97.724648,0.056283,0.000000
4.050000,0.003357,-97.769127,-0.009662,0.002324,0.059023,0.014932,0.000761,0.590234,-97.769127,0.060290,0.000000
4.290000,-0.005585,-97.769127,-0.009507,0.002482,0.063039,-0.024842,-0.001266,0.630386,-97.769127,0.064279,0.000000
4.530000,-0.024200,-97.813614,-0.009334,0.002645,0.067184,-0.107649,-0.005484,0.671840,-97.813614,0.068285,0.000000
4.770000,-0.029785,-97.813614,-0.009175,0.002798,0.071060,-0.132491,-0.006749,0.710605,-97.813614,0.072275,0.000000
5.010000,-0.026436,-97.858093,-0.009020,0.002954,0.075024,-0.117593,-0.005990,0.750237,-97.858093,0.076281,0.000000
5.250000,-0.048035,-97.858093,-0.008852,0.003112,0.079039,-0.213669,-0.010885,0.790389,-97.858093,0.080270,0.000000
5.490000,-0.036858,-97.858093,-0.008692,0.003275,0.083193,-0.163951,-0.008352,0.831930,-97.858093,0.084277,0.000000
5.730000,-0.020851,-97.947052,-0.008528,0.003431,0.087139,-0.092750,-0.004725,0.871388,-97.947052,0.088266,0.000000
5.970000,-0.008186,-97.902573,-0.008364,0.003586,0.091093,-0.036415,-0.001855,0.910934,-97.902573,0.092273,0.000000
6.210001,0.021599,-97.947052,-0.008213,0.003742,0.095048,0.096076,0.004894,0.950479,-97.947052,0.096262,0.000000
6.450000,0.003357,-98.036018,-0.008050,0.003905,0.099193,0.014932,0.000761,0.991933,-98.036018,0.100269,0.000000
6.690001,-0.024948,-97.991531,-0.007894,0.004059,0.103096,-0.110975,-0.005653,1.030958,-97.991531,0.104258,0.000000
6.930000,-0.018242,-97.991531,-0.007743,0.004215,0.107050,-0.081144,-0.004134,1.070503,-97.991531,0.108264,0.000000
7.170001,-0.006699,-98.036018,-0.007575,0.004372,0.111057,-0.029797,-0.001518,1.110569,-98.036018,0.112271,0.000000
7.410000,-0.030907,-98.080498,-0.007411,0.004529,0.115037,-0.137480,-0.007004,1.150375,-98.080498,0.116260,0.000000
7.650001,-0.059578,-98.124977,-0.007252,0.004691,0.119157,-0.265016,-0.013501,1.191568,-98.124977,0.120267,0.000000
7.890000,-0.009682,-98.080498,-0.007088,0.004848,0.123146,-0.043066,-0.002194,1.231461,-98.080498,0.124256,0.000000
8.130000,0.033890,-98.124977,-0.006929,0.005005,0.127127,0.150749,0.007680,1.271266,-98.124977,0.128263,0.000000
8.370001,0.025322,-98.124977,-0.006765,0.005167,0.131246,0.112638,0.005738,1.312459,-98.124977,0.132252,0.000000
8.610001,0.005592,-98.080498,-0.006605,0.005320,0.135122,0.024876,0.001267,1.351224,-98.080498,0.136258,0.000000
8.850000,-0.015266,-98.213943,-0.006463,0.005475,0.139060,-0.067908,-0.003459,1.390596,-98.213943,0.140248,0.000000
9.090000,-0.000366,-98.169456,-0.006291,0.005630,0.143014,-0.001629,-0.000083,1.430142,-98.169456,0.144254,0.000000
9.330001,-0.015266,-98.124977,-0.006140,0.005791,0.147081,-0.067908,-0.003459,1.470815,-98.124977,0.148244,0.000000
9.570001,-0.037979,-98.258423,-0.005976,0.005946,0.151036,-0.168940,-0.008606,1.510360,-98.258423,0.152250,0.000000
9.810000,-0.047287,-98.302902,-0.005833,0.006103,0.155008,-0.210343,-0.010715,1.550079,-98.302902,0.156239,0.000000
10.050000,0.003357,-98.302902,-0.005674,0.006264,0.159101,0.014932,0.000761,1.591012,-98.302902,0.160246,0.000000
10.290001,0.016388,-98.302902,-0.005493,0.006425,0.163203,0.072897,0.003714,1.632032,-98.302902,0.164235,0.000000
10.530001,-0.001862,-98.258423,-0.005342,0.006582,0.167192,-0.008281,-0.000422,1.671924,-98.258423,0.168242,0.000000
10.770000,0.014900,-98.391861,-0.005178,0.006735,0.171060,0.066279,0.003376,1.710603,-98.391861,0.172231,0.000000
11.010000,0.009682,-98.391861,-0.005014,0.006893,0.175084,0.043066,0.002194,1.750842,-98.391861,0.176238,0.000000
11.250001,0.008942,-98.436348,-0.004863,0.007049,0.179047,0.039774,0.002026,1.790474,-98.436348,0.180227,0.000000
11.490001,-0.009308,-98.347382,-0.004695,0.007209,0.183097,-0.041403,-0.002109,1.830974,-98.347382,0.184233,0.000000
11.730000,-0.070747,-98.391861,-0.004544,0.007361,0.186974,-0.314700,-0.016032,1.869739,-98.391861,0.188240,0.000000
11.970000,-0.000740,-98.436348,-0.004381,0.007522,0.191067,-0.003292,-0.000168,1.910672,-98.436348,0.192229,0.000000
12.210001,0.030907,-98.480827,-0.004238,0.007678,0.195013,0.137480,0.007004,1.950130,-98.480827,0.196236,0.000000
12.450001,0.052505,-98.480827,-0.004061,0.007845,0.199254,0.233556,0.011898,1.992538,-98.480827,0.200225,0.000000
12.690001,0.370514,-98.525307,-0.003919,0.007999,0.203182,1.648128,0.083960,2.031823,-98.525307,0.204232,0.000000
12.930000,0.663940,-98.525307,-0.003829,-0.000000,-0.000009,2.953355,0.150451,-0.000087,-98.525307,0.000156,0.000000
13.170001,0.630432,-98.569786,-0.003829,-0.000001,-0.000017,2.804302,0.142858,-0.000173,-98.569786,0.000156,0.000000
13.410001,0.583138,-98.525307,-0.003824,-0.000001,-0.000017,2.593925,0.132141,-0.000173,-98.525307,0.000234,0.000000
13.650001,0.624474,-98.614265,-0.003837,-0.000001,-0.000017,2.777797,0.141508,-0.000173,-98.614265,0.000633,0.000000
13.890000,0.624847,-98.614265,-0.003829,0.000004,0.000095,2.779460,0.141592,0.000954,-98.614265,0.001041,0.000000
14.130001,0.714584,-98.614265,-0.003811,0.000022,0.000546,3.178630,0.161927,0.005464,-98.614265,0.001440,0.000000
14.370001,0.796509,-98.658752,-0.003798,0.000037,0.000937,3.543048,0.180491,0.009366,-98.658752,0.001839,0.000000
14.610001,0.866142,-98.614265,-0.003777,0.000053,0.001344,3.852793,0.196271,0.013442,-98.614265,0.002237,0.000000
14.850000,0.908218,-98.747711,-0.003777,0.000066,0.001682,4.039957,0.205805,0.016824,-98.747711,0.002636,0.000000
15.090001,1.011368,-98.747711,-0.003751,0.000084,0.002142,4.498789,0.229179,0.021420,-98.747711,0.003035,0.000000
15.330001,1.080254,-98.703232,-0.003738,0.000100,0.002541,4.805208,0.244789,0.025410,-98.703232,0.003434,0.000000
15.570001,1.125313,-98.836670,-0.003729,0.000113,0.002871,5.005641,0.255000,0.028705,-98.836670,0.003833,0.000000
15.810000,1.165154,-98.747711,-0.003704,0.000127,0.003226,5.182862,0.264028,0.032261,-98.747711,0.004241,0.000000
16.050001,1.258621,-98.792191,-0.003695,0.000147,0.003738,5.598627,0.285208,0.037377,-98.792191,0.004640,0.000000
16.290001,1.308891,-98.881157,-0.003673,0.000163,0.004128,5.822239,0.296599,0.041280,-98.881157,0.005039,0.000000
16.530001,1.341286,-98.792191,-0.003665,0.000179,0.004536,5.966337,0.303940,0.045356,-98.792191,0.005438,0.000000
16.770000,1.349480,-98.881157,-0.003656,0.000189,0.004813,6.002785,0.305796,0.048131,-98.881157,0.005836,0.000000
17.010000,1.456726,-98.792191,-0.003635,0.000209,0.005316,6.479841,0.330099,0.053161,-98.792191,0.006235,0.000000
17.250000,1.488747,-98.881157,-0.003626,0.000224,0.005689,6.622276,0.337355,0.056890,-98.881157,0.006634,0.000000
17.490002,1.515556,-98.970116,-0.003596,0.000233,0.005914,6.741531,0.343430,0.059145,-98.970116,0.007033,0.000000
17.730001,1.564713,-98.881157,-0.003596,0.000251,0.006383,6.960189,0.354569,0.063828,-98.881157,0.007441,0.000000
17.970001,1.671585,-98.970116,-0.003566,0.000272,0.006920,7.435582,0.378787,0.069205,-98.970116,0.007840,0.000000
18.210001,1.709564,-98.970116,-0.003548,0.000289,0.007345,7.604521,0.387393,0.073454,-98.970116,0.008239,0.000000
18.450001,1.718506,-99.059074,-0.003544,0.000304,0.007718,7.644296,0.389419,0.077183,-99.059074,0.008638,0.000000
18.690001,1.693184,-99.014595,-0.003523,0.000315,0.008004,7.531658,0.383681,0.080045,-99.014595,0.009036,0.000000
18.930000,1.781433,-98.970116,-0.003505,0.000331,0.008403,7.924210,0.403679,0.084034,-98.970116,0.009435,0.000000
19.170000,1.845482,-99.059074,-0.003492,0.000348,0.008837,8.209113,0.418192,0.088370,-99.059074,0.009834,0.000000
19.410002,1.894264,-99.148041,-0.003471,0.000364,0.009236,8.426108,0.429246,0.092360,-99.148041,0.010233,0.000000
19.650002,1.934105,-99.103561,-0.003462,0.000382,0.009696,8.603329,0.438274,0.096956,-99.103561,0.010641,0.000000
19.890001,1.953842,-99.192520,-0.003441,0.000396,0.010051,8.691124,0.442747,0.100511,-99.192520,0.011040,0.000000
20.130001,2.001877,-99.103561,-0.003432,0.000413,0.010493,8.904793,0.453632,0.104934,-99.103561,0.011439,0.000000
20.370001,2.018631,-99.237000,-0.003410,0.000429,0.010901,8.979319,0.457428,0.109010,-99.237000,0.011838,0.000000
20.610001,2.021988,-99.148041,-0.003397,0.000443,0.011248,8.994251,0.458189,0.112479,-99.148041,0.012237,0.000000
20.850000,2.071136,-99.148041,-0.003380,0.000459,0.011656,9.212875,0.469326,0.116555,-99.148041,0.012635,0.000000
21.090000,2.116196,-99.237000,-0.003363,0.000473,0.012011,9.413308,0.479537,0.120111,-99.237000,0.013034,0.000000
21.330002,2.164230,-99.192520,-0.003350,0.000489,0.012427,9.626977,0.490422,0.124273,-99.192520,0.013442,0.000000
21.570002,2.206314,-99.281487,-0.003328,0.000506,0.012861,9.814176,0.499958,0.128610,-99.281487,0.013841,0.000000
21.810001,2.258446,-99.237000,-0.003307,0.000525,0.013329,10.046068,0.511771,0.133293,-99.237000,0.014240,0.000000
22.050001,2.291214,-99.325966,-0.003298,0.000541,0.013746,10.191829,0.519197,0.137455,-99.325966,0.014639,0.000000
22.290001,2.279297,-99.325966,-0.003277,0.000557,0.014144,10.138819,0.516496,0.141445,-99.325966,0.015038,0.000000
22.530001,2.248390,-99.325966,-0.003268,0.000569,0.014457,10.001339,0.509493,0.144567,-99.325966,0.015437,0.000000
22.770000,2.338127,-99.370445,-0.003251,0.000584,0.014838,10.400509,0.529827,0.148382,-99.370445,0.015836,0.000000
23.010000,2.382446,-99.370445,-0.003229,0.000599,0.015211,10.597651,0.539870,0.152111,-99.370445,0.016234,0.000000
23.250002,2.394730,-99.370445,-0.003221,0.000615,0.015619,10.652289,0.542654,0.156187,-99.370445,0.016642,0.000000
23.490002,2.441277,-99.503891,-0.003195,0.000631,0.016035,10.859341,0.553201,0.160350,-99.503891,0.017041,0.000000
23.730001,2.446861,-99.414925,-0.003191,0.000643,0.016330,10.884183,0.554467,0.163299,-99.414925,0.017440,0.000000
23.970001,2.533257,-99.548370,-0.003173,0.000664,0.016876,11.268488,0.574044,0.168762,-99.548370,0.017839,0.000000
24.210001,2.514633,-99.459404,-0.003143,0.000680,0.017266,11.185647,0.569824,0.172665,-99.459404,0.018238,0.000000
24.450001,2.526176,-99.459404,-0.003130,0.000694,0.017639,11.236994,0.572440,0.176394,-99.459404,0.018637,0.000000
24.690001,2.533623,-99.548370,-0.003126,0.000707,0.017952,11.270117,0.574127,0.179516,-99.548370,0.019036,0.000000
24.930000,2.693001,-99.548370,-0.003104,0.000727,0.018472,11.979066,0.610243,0.184719,-99.548370,0.019435,0.000000
25.170002,2.657257,-99.503891,-0.003087,0.000741,0.018827,11.820070,0.602143,0.188275,-99.503891,0.019842,0.000000
25.410002,2.728378,-99.548370,-0.003070,0.000760,0.019296,12.136433,0.618259,0.192958,-99.548370,0.020241,0.000000
25.650002,2.790192,-99.637329,-0.003053,0.000778,0.019764,12.411392,0.632266,0.197641,-99.637329,0.020640,0.000000
25.890001,2.803970,-99.681808,-0.003048,0.000793,0.020154,12.472683,0.635389,0.201543,-99.681808,0.021039,0.000000
26.130001,2.808434,-99.637329,-0.003027,0.000811,0.020588,12.492537,0.636400,0.205879,-99.637329,0.021438,0.000000
26.370001,2.811790,-99.681808,-0.003014,0.000823,0.020900,12.507468,0.637161,0.209001,-99.681808,0.021837,0.000000
26.610001,2.898926,-99.681808,-0.002988,0.000839,0.021316,12.895066,0.656906,0.213164,-99.681808,0.022236,0.000000
26.850000,2.987923,-99.726295,-0.002979,0.000857,0.021759,13.290944,0.677073,0.217587,-99.726295,0.022635,0.000000
27.090002,2.980843,-99.726295,-0.002958,0.000868,0.022054,13.259450,0.675469,0.220536,-99.726295,0.023042,0.000000
27.330002,3.070587,-99.726295,-0.002949,0.000888,0.022548,13.658654,0.695805,0.225479,-99.726295,0.023441,0.000000
27.570002,3.087341,-99.770775,-0.002928,0.000901,0.022895,13.733180,0.699602,0.228948,-99.770775,0.023840,0.000000
27.810001,3.047127,-99.770775,-0.002915,0.000914,0.023216,13.554296,0.690489,0.232156,-99.770775,0.024239,0.000000
28.050001,3.153252,-99.815254,-0.002915,0.000933,0.023701,14.026364,0.714537,0.237013,-99.815254,0.024638,0.000000
28.290001,3.197563,-99.859734,-0.002880,0.000950,0.024118,14.223472,0.724578,0.241175,-99.859734,0.025037,0.000000
28.530001,3.252304,-99.815254,-0.002876,0.000965,0.024508,14.466971,0.736983,0.245078,-99.815254,0.025436,0.000000
28.770000,3.298477,-99.904213,-0.002859,0.000982,0.024933,14.672359,0.747446,0.249327,-99.904213,0.025835,0.000000
29.010002,3.340187,-99.859734,-0.002824,0.000997,0.025314,14.857894,0.756897,0.253143,-99.859734,0.026242,0.000000
29.250002,3.355453,-99.859734,-0.002828,0.001011,0.025679,14.925802,0.760357,0.256786,-99.859734,0.026641,0.000000
29.490002,3.422104,-99.948700,-0.002802,0.001027,0.026095,15.222279,0.775460,0.260948,-99.948700,0.027040,0.000000
29.730001,3.485039,-99.859734,-0.002785,0.001046,0.026572,15.502227,0.789721,0.265718,-99.859734,0.027439,0.000000
29.970001,3.476471,-99.993179,-0.002777,0.001061,0.026945,15.464115,0.787780,0.269447,-99.993179,0.027838,0.000000
30.210001,3.542007,-100.037659,-0.002759,0.001078,0.027378,15.755636,0.802630,0.273783,-100.037659,0.028237,0.000000
30.450001,3.585953,-99.993179,-0.002751,0.001095,0.027821,15.951115,0.812589,0.278206,-99.993179,0.028636,0.000000
30.690001,3.648506,-100.082138,-0.002725,0.001110,0.028194,16.229366,0.826763,0.281935,-100.082138,0.029035,0.000000
30.930002,3.577385,-99.993179,-0.002708,0.001120,0.028445,15.913003,0.810647,0.284450,-99.993179,0.029442,0.000000
31.170002,3.766922,-100.082138,-0.002703,0.001140,0.028948,16.756105,0.853597,0.289480,-100.082138,0.029841,0.000000
31.410002,3.877144,-100.082138,-0.002673,0.001161,0.029477,17.246397,0.878573,0.294770,-100.082138,0.030240,0.000000
31.650002,3.872307,-100.037659,-0.002660,0.001176,0.029859,17.224880,0.877477,0.298586,-100.037659,0.030639,0.000000
31.890001,3.852570,-100.082138,-0.002660,0.001189,0.030197,17.137085,0.873005,0.301968,-100.082138,0.031038,0.000000
32.130001,3.899490,-100.082138,-0.002626,0.001205,0.030604,17.345798,0.883637,0.306044,-100.082138,0.031437,0.000000
32.370003,3.981407,-100.171104,-0.002608,0.001220,0.030995,17.710184,0.902200,0.309946,-100.171104,0.031836,0.000000
32.610001,3.994072,-100.215584,-0.002596,0.001233,0.031324,17.766520,0.905070,0.313242,-100.215584,0.032235,0.000000
32.850002,4.020508,-100.171104,-0.002574,0.001246,0.031645,17.884111,0.911060,0.316451,-100.171104,0.032642,0.000000
33.090000,4.125893,-100.260063,-0.002583,0.001264,0.032096,18.352886,0.934941,0.320960,-100.260063,0.033041,0.000000
33.330002,4.316544,-100.171104,-0.002552,0.001288,0.032712,19.200945,0.978143,0.327118,-100.171104,0.033440,0.000000
33.570000,4.275581,-100.215584,-0.002535,0.001300,0.033033,19.018736,0.968861,0.330326,-100.215584,0.033839,0.000000
33.810001,4.297180,-100.304543,-0.002509,0.001316,0.033423,19.114813,0.973755,0.334229,-100.304543,0.034238,0.000000
34.050003,4.316917,-100.304543,-0.002505,0.001330,0.033787,19.202608,0.978227,0.337871,-100.304543,0.034637,0.000000
34.290001,4.418945,-100.349022,-0.002496,0.001347,0.034221,19.656450,1.001347,0.342207,-100.349022,0.035036,0.000000
34.530003,4.426392,-100.304543,-0.002466,0.001358,0.034498,19.689573,1.003035,0.344982,-100.304543,0.035444,0.000000
34.770000,4.492676,-100.393509,-0.002462,0.001373,0.034880,19.984421,1.018055,0.348798,-100.393509,0.035842,0.000000
35.010002,4.537735,-100.349022,-0.002440,0.001387,0.035227,20.184853,1.028265,0.352267,-100.349022,0.036241,0.000000
35.250000,4.681099,-100.349022,-0.002427,0.001405,0.035695,20.822569,1.060752,0.356950,-100.349022,0.036640,0.000000
35.490002,4.833023,-100.437988,-0.002406,0.001426,0.036215,21.498360,1.095179,0.362153,-100.437988,0.037039,0.000000
35.730003,4.757805,-100.437988,-0.002393,0.001437,0.036510,21.163773,1.078134,0.365102,-100.437988,0.037438,0.000000
35.970001,4.829674,-100.526947,-0.002389,0.001454,0.036926,21.483461,1.094420,0.369265,-100.526947,0.037837,0.000000
36.210003,4.827812,-100.526947,-0.002380,0.001468,0.037291,21.475182,1.093998,0.372907,-100.526947,0.038236,0.000000
36.450001,5.001709,-100.482468,-0.002358,0.001486,0.037750,22.248713,1.133403,0.377503,-100.482468,0.038644,0.000000
36.690002,5.035599,-100.571434,-0.002345,0.001501,0.038115,22.399462,1.141083,0.381146,-100.571434,0.039042,0.000000
36.930000,5.086609,-100.571434,-0.002311,0.001515,0.038479,22.626366,1.152642,0.384788,-100.571434,0.039441,0.000000
37.170002,5.098152,-100.571434,-0.002311,0.001527,0.038782,22.677713,1.155258,0.387823,-100.571434,0.039840,0.000000
37.410004,5.378922,-100.615913,-0.002285,0.001552,0.039424,23.926638,1.218881,0.394241,-100.615913,0.040239,0.000000
37.650002,5.339455,-100.571434,-0.002276,0.001563,0.039710,23.751080,1.209938,0.397103,-100.571434,0.040638,0.000000
37.890003,5.386742,-100.660393,-0.002268,0.001580,0.040135,23.961424,1.220653,0.401352,-100.660393,0.041037,0.000000
38.130001,5.311897,-100.660393,-0.002242,0.001590,0.040395,23.628500,1.203693,0.403954,-100.660393,0.041436,0.000000
38.370003,5.555428,-100.615913,-0.002225,0.001611,0.040907,24.711777,1.258878,0.409070,-100.615913,0.041844,0.000000
38.610001,5.590057,-100.704872,-0.002220,0.001624,0.041254,24.865818,1.266725,0.412539,-100.704872,0.042243,0.000000
38.850002,5.740494,-100.704872,-0.002203,0.001643,0.041722,25.534992,1.300815,0.417222,-100.704872,0.042641,0.000000
39.090000,5.656715,-100.704872,-0.002190,0.001650,0.041922,25.162327,1.281830,0.419217,-100.704872,0.043040,0.000000
39.330002,5.947906,-100.704872,-0.002164,0.001673,0.042503,26.457609,1.347815,0.425027,-100.704872,0.043439,0.000000
39.570004,5.985893,-100.749352,-0.002139,0.001690,0.042936,26.626583,1.356423,0.429363,-100.749352,0.043838,0.000000
39.810001,6.040627,-100.793839,-0.002130,0.001706,0.043344,26.870049,1.368826,0.433439,-100.793839,0.044237,0.000000
40.050003,5.948280,-100.793839,-0.002117,0.001717,0.043604,26.459272,1.347900,0.436041,-100.793839,0.044636,0.000000
40.290001,6.173943,-100.838318,-0.002104,0.001734,0.044046,27.463068,1.399035,0.440464,-100.838318,0.045044,0.000000
40.530003,6.189575,-100.793839,-0.002074,0.001747,0.044367,27.532606,1.402578,0.443673,-100.793839,0.045443,0.000000
40.770000,6.447258,-100.882797,-0.002070,0.001767,0.044879,28.678837,1.460969,0.448789,-100.882797,0.045842,0.000000
41.010002,6.505722,-100.971756,-0.002065,0.001782,0.045261,28.938896,1.474218,0.452605,-100.971756,0.046240,0.000000
41.250004,6.611107,-100.927277,-0.002044,0.001798,0.045677,29.407673,1.498098,0.456768,-100.927277,0.046639,0.000000
41.490002,6.668823,-100.927277,-0.002035,0.001814,0.046084,29.664408,1.511177,0.460844,-100.927277,0.047038,0.000000
41.730003,6.766014,-100.927277,-0.002013,0.001832,0.046527,30.096733,1.533201,0.465267,-100.927277,0.047437,0.000000
41.970001,6.712761,-100.971756,-0.001996,0.001844,0.046839,29.859852,1.521133,0.468389,-100.971756,0.047836,0.000000
42.210003,6.894852,-101.016243,-0.001975,0.001860,0.047246,30.669832,1.562396,0.472465,-101.016243,0.048244,0.000000
42.450001,6.943260,-101.060722,-0.001975,0.001871,0.047533,30.885164,1.573365,0.475326,-101.060722,0.048643,0.000000
42.690002,7.262383,-101.060722,-0.001949,0.001893,0.048070,32.304691,1.645679,0.480703,-101.060722,0.049042,0.000000
42.930000,7.253448,-101.060722,-0.001940,0.001905,0.048391,32.264950,1.643655,0.483912,-101.060722,0.049441,0.000000
43.170002,7.497353,-101.016243,-0.001919,0.001926,0.048929,33.349892,1.698924,0.489289,-101.016243,0.049839,0.000000
43.410004,7.571083,-101.194160,-0.001906,0.001942,0.049319,33.677860,1.715632,0.493191,-101.194160,0.050238,0.000000
43.650002,7.648903,-101.149681,-0.001884,0.001958,0.049735,34.024021,1.733266,0.497354,-101.149681,0.050637,0.000000
43.890003,7.597145,-101.060722,-0.001880,0.001969,0.050013,33.793789,1.721538,0.500129,-101.060722,0.051036,0.000000
44.130001,7.806793,-101.194160,-0.001863,0.001986,0.050447,34.726349,1.769045,0.504465,-101.194160,0.051444,0.000000
44.370003,7.738647,-101.149681,-0.001850,0.001993,0.050620,34.423222,1.753603,0.506200,-101.149681,0.051843,0.000000
44.610001,8.164268,-101.194160,-0.001837,0.002019,0.051288,36.316479,1.850050,0.512877,-101.194160,0.052242,0.000000
44.850002,8.242844,-101.238647,-0.001815,0.002033,0.051643,36.666000,1.867855,0.516433,-101.238647,0.052641,0.000000
45.090004,8.162407,-101.238647,-0.001802,0.002041,0.051843,36.308201,1.849628,0.518427,-101.238647,0.053040,0.000000
45.330002,8.643517,-101.283127,-0.001781,0.002066,0.052467,38.448280,1.958649,0.524671,-101.283127,0.053438,0.000000
45.570004,8.618935,-101.283127,-0.001768,0.002081,0.052849,38.338936,1.953079,0.528487,-101.283127,0.053837,0.000000
45.810001,8.728783,-101.327606,-0.001759,0.002094,0.053187,38.827564,1.977970,0.531870,-101.327606,0.054236,0.000000
46.050003,8.837151,-101.238647,-0.001742,0.002109,0.053577,39.309608,2.002527,0.535772,-101.238647,0.054644,0.000000
46.290001,9.211006,-101.372086,-0.001720,0.002128,0.054063,40.972603,2.087244,0.540628,-101.372086,0.055043,0.000000
46.530003,9.240051,-101.416565,-0.001716,0.002142,0.054410,41.101799,2.093826,0.544097,-101.416565,0.055442,0.000000
46.770000,9.537209,-101.327606,-0.001690,0.002161,0.054878,42.423622,2.161162,0.548780,-101.327606,0.055841,0.000000
47.010002,9.778503,-101.416565,-0.001681,0.002181,0.055390,43.496956,2.215841,0.553897,-101.416565,0.056240,0.000000
47.250004,9.702171,-101.372086,-0.001656,0.002194,0.055728,43.157413,2.198544,0.557279,-101.372086,0.056639,0.000000
47.490002,9.969528,-101.416565,-0.001651,0.002212,0.056179,44.346676,2.259127,0.561789,-101.416565,0.057037,0.000000
47.730003,9.919632,-101.461052,-0.001621,0.002223,0.056456,44.124725,2.247821,0.564564,-101.461052,0.057445,0.000000
47.970001,10.210457,-101.505531,-0.001625,0.002239,0.056881,45.418381,2.313723,0.568813,-101.505531,0.057844,0.000000
48.210003,10.532928,-101.461052,-0.001608,0.002255,0.057280,46.852806,2.386796,0.572803,-101.461052,0.058243,0.000000
48.450001,10.562347,-101.505531,-0.001587,0.002267,0.057592,46.983669,2.393462,0.575925,-101.505531,0.058642,0.000000
48.690002,11.039726,-101.550011,-0.001569,0.002289,0.058147,49.107155,2.501638,0.581475,-101.550011,0.059041,0.000000
48.930004,10.981636,-101.550011,-0.001552,0.002301,0.058434,48.848759,2.488474,0.584337,-101.550011,0.059440,0.000000
49.170002,11.276184,-101.550011,-0.001552,0.002318,0.058885,50.158974,2.555220,0.588846,-101.550011,0.059839,0.000000
49.410004,11.510780,-101.638969,-0.001535,0.002335,0.059310,51.202507,2.608380,0.593096,-101.638969,0.060237,0.000000
49.650002,11.750214,-101.594490,-0.001522,0.002350,0.059700,52.267559,2.662637,0.596998,-101.594490,0.060645,0.000000
49.890003,11.807938,-101.638969,-0.001513,0.002363,0.060029,52.524330,2.675717,0.600294,-101.638969,0.061044,0.000000
50.130001,12.172112,-101.683456,-0.001483,0.002382,0.060506,54.144257,2.758240,0.605063,-101.683456,0.061443,0.000000
50.370003,12.344894,-101.683456,-0.001470,0.002397,0.060888,54.912834,2.797393,0.608879,-101.683456,0.061842,0.000000
50.610001,12.454376,-101.727936,-0.001462,0.002412,0.061252,55.399834,2.822202,0.612521,-101.727936,0.062241,0.000000
50.850002,12.636459,-101.772415,-0.001436,0.002426,0.061625,56.209778,2.863463,0.616251,-101.772415,0.062640,0.000000
51.090004,13.113472,-101.727936,-0.001436,0.002446,0.062119,58.331638,2.971555,0.621194,-101.727936,0.063039,0.000000
51.330002,13.397591,-101.816895,-0.001410,0.002463,0.062553,59.595459,3.035938,0.625530,-101.816895,0.063438,0.000000
51.570004,13.568512,-101.816895,-0.001401,0.002479,0.062969,60.355755,3.074669,0.629692,-101.816895,0.063845,0.000000
51.810001,13.983704,-101.861382,-0.001380,0.002497,0.063412,62.202621,3.168752,0.634115,-101.861382,0.064244,0.000000
52.050003,14.016846,-101.861382,-0.001375,0.002509,0.063724,62.350044,3.176263,0.637237,-101.861382,0.064643,0.000000
52.290001,14.135635,-101.861382,-0.001367,0.002522,0.064062,62.878445,3.203181,0.640620,-101.861382,0.065042,0.000000
52.530003,14.630142,-101.905861,-0.001337,0.002539,0.064478,65.078125,3.315238,0.644782,-101.905861,0.065441,0.000000
52.770004,15.227806,-101.861382,-0.001319,0.002560,0.065033,67.736664,3.450670,0.650332,-101.861382,0.065840,0.000000
53.010002,15.408775,-101.905861,-0.001315,0.002576,0.065441,68.541656,3.491678,0.654408,-101.905861,0.066239,0.000000
53.250004,15.390533,-101.905861,-0.001293,0.002588,0.065736,68.460510,3.487545,0.657357,-101.905861,0.066638,0.000000
53.490002,15.775932,-101.950340,-0.001281,0.002604,0.066143,70.174850,3.574877,0.661433,-101.950340,0.067045,0.000000
53.730003,16.240280,-101.950340,-0.001268,0.002624,0.066638,72.240372,3.680100,0.666376,-101.950340,0.067444,0.000000
53.970001,16.257782,-101.950340,-0.001246,0.002635,0.066924,72.318230,3.684066,0.669238,-101.950340,0.067843,0.000000
54.210003,16.388489,-101.994820,-0.001242,0.002645,0.067184,72.899635,3.713685,0.671840,-101.994820,0.068242,0.000000
54.450001,16.983910,-102.039299,-0.001237,0.002663,0.067652,75.548203,3.848609,0.676523,-102.039299,0.068641,0.000000
54.690002,18.131561,-102.039299,-0.001212,0.002690,0.068320,80.653214,4.108671,0.683200,-102.039299,0.069040,0.000000
54.930004,18.008308,-102.039299,-0.001199,0.002701,0.068606,80.104958,4.080741,0.686062,-102.039299,0.069439,0.000000
55.170002,18.265617,-102.128265,-0.001186,0.002717,0.069005,81.249527,4.139048,0.690051,-102.128265,0.069838,0.000000
55.410004,18.543037,-102.083786,-0.001181,0.002730,0.069352,82.483551,4.201912,0.693520,-102.083786,0.070245,0.000000
55.650002,18.961212,-102.128265,-0.001164,0.002746,0.069742,84.343681,4.296672,0.697423,-102.128265,0.070644,0.000000
55.890003,19.049088,-102.083786,-0.001147,0.002757,0.070037,84.734573,4.316585,0.700371,-102.083786,0.071043,0.000000
56.130001,19.416252,-102.261703,-0.001134,0.002772,0.070410,86.367805,4.399786,0.704100,-102.261703,0.071442,0.000000
56.370003,19.883949,-102.217224,-0.001125,0.002787,0.070800,88.448227,4.505767,0.708003,-102.217224,0.071841,0.000000
56.610004,20.422028,-102.128265,-0.001104,0.002803,0.071208,90.841713,4.627697,0.712079,-102.128265,0.072240,0.000000
56.850002,21.295609,-102.261703,-0.001108,0.002826,0.071780,94.727600,4.825654,0.717803,-102.261703,0.072639,0.000000
57.090004,21.437859,-102.261703,-0.001078,0.002840,0.072127,95.360359,4.857888,0.721272,-102.261703,0.073038,0.000000
57.330002,21.843002,-102.306190,-0.001069,0.002856,0.072535,97.162529,4.949695,0.725348,-102.306190,0.073445,0.000000
57.570004,22.296181,-102.261703,-0.001065,0.002872,0.072942,99.178368,5.052387,0.729424,-102.261703,0.073844,0.000000
57.810001,22.893463,-102.217224,-0.001039,0.002890,0.073393,101.835213,5.187733,0.733933,-102.217224,0.074243,0.000000
58.050003,23.095657,-102.306190,-0.001035,0.002900,0.073653,102.734612,5.233551,0.736535,-102.306190,0.074642,0.000000
58.290001,23.516441,-102.306190,-0.001018,0.002916,0.074061,104.606354,5.328902,0.740611,-102.306190,0.075041,0.000000
58.530003,23.640068,-102.395149,-0.001030,0.002927,0.074347,105.156273,5.356916,0.743473,-102.395149,0.075440,0.000000
58.770004,25.056198,-102.395149,-0.001000,0.002952,0.074972,111.455536,5.677816,0.749717,-102.395149,0.075839,0.000000
59.010002,25.299362,-102.395149,-0.000992,0.002966,0.075345,112.537186,5.732917,0.753446,-102.395149,0.076238,0.000000
59.250004,25.761848,-102.484108,-0.000983,0.002980,0.075700,114.594421,5.837718,0.757001,-102.484108,0.076645,0.000000
59.490002,26.083946,-102.395149,-0.000961,0.002993,0.076030,116.027191,5.910707,0.760297,-102.395149,0.077044,0.000000
59.730003,26.852158,-102.484108,-0.000957,0.003012,0.076507,119.444359,6.084786,0.765067,-102.484108,0.077443,0.000000
59.970001,27.158241,-102.573074,-0.000949,0.003023,0.076784,120.805893,6.154146,0.767842,-102.573074,0.077842,0.000000
60.210003,28.081352,-102.439629,-0.000936,0.003042,0.077278,124.912094,6.363325,0.772785,-102.439629,0.078241,0.000000
60.450005,28.311852,-102.528595,-0.000936,0.003055,0.077599,125.937408,6.415557,0.775993,-102.528595,0.078640,0.000000
60.690002,29.369766,-102.528595,-0.000901,0.003075,0.078111,130.643250,6.655284,0.781110,-102.528595,0.079039,0.000000
60.930004,30.000191,-102.528595,-0.000905,0.003092,0.078536,133.447510,6.798141,0.785360,-102.528595,0.079447,0.000000
61.170002,30.542740,-102.617554,-0.000888,0.003106,0.078900,135.860886,6.921084,0.789002,-102.617554,0.079845,0.000000
61.410004,30.705833,-102.617554,-0.000875,0.003118,0.079195,136.586365,6.958041,0.791950,-102.617554,0.080244,0.000000
61.650002,31.496758,-102.662033,-0.000871,0.003133,0.079577,140.104568,7.137267,0.795766,-102.662033,0.080643,0.000000
61.890003,31.988663,-102.617554,-0.000867,0.003145,0.079889,142.292679,7.248734,0.798888,-102.617554,0.081042,0.000000
62.130001,33.090141,-102.617554,-0.000849,0.003167,0.080453,147.192307,7.498333,0.804525,-102.617554,0.081441,0.000000
62.370003,33.729874,-102.662033,-0.000849,0.003180,0.080782,150.037964,7.643299,0.807821,-102.662033,0.081840,0.000000
62.610004,34.438499,-102.617554,-0.000819,0.003198,0.081224,153.190094,7.803875,0.812244,-102.617554,0.082239,0.000000
62.850002,35.162392,-102.706512,-0.000832,0.003215,0.081658,156.410126,7.967912,0.816580,-102.706512,0.082647,0.000000
63.090004,36.044914,-102.706512,-0.000798,0.003232,0.082092,160.335785,8.167894,0.820916,-102.706512,0.083046,0.000000
63.330002,36.435532,-102.795479,-0.000798,0.003244,0.082386,162.073334,8.256410,0.823864,-102.795479,0.083444,0.000000
63.570004,37.243584,-102.795479,-0.000789,0.003260,0.082811,165.667740,8.439516,0.828114,-102.795479,0.083843,0.000000
63.810001,37.587654,-102.750999,-0.000780,0.003271,0.083080,167.198242,8.517485,0.830802,-102.750999,0.084242,0.000000
64.050003,38.968781,-102.839958,-0.000776,0.003293,0.083653,173.341797,8.830452,0.836526,-102.839958,0.084641,0.000000
64.290001,39.444672,-102.839958,-0.000755,0.003307,0.083991,175.458664,8.938291,0.839908,-102.839958,0.085040,0.000000
64.530006,40.829903,-102.795479,-0.000759,0.003326,0.084485,181.620483,9.252189,0.844851,-102.795479,0.085439,0.000000
64.770004,41.569427,-102.884438,-0.000742,0.003342,0.084893,184.910049,9.419767,0.848927,-102.884438,0.085847,0.000000
65.010002,42.437805,-102.884438,-0.000724,0.003359,0.085309,188.772781,9.616545,0.853090,-102.884438,0.086246,0.000000
65.250000,42.721550,-102.839958,-0.000720,0.003368,0.085552,190.034943,9.680841,0.855518,-102.839958,0.086645,0.000000
65.490005,43.767174,-102.884438,-0.000716,0.003388,0.086063,194.686111,9.917784,0.860635,-102.884438,0.087043,0.000000
65.730003,44.391640,-102.928925,-0.000703,0.003400,0.086367,197.463882,10.059290,0.863670,-102.928925,0.087442,0.000000
65.970001,45.698669,-102.973404,-0.000703,0.003419,0.086835,203.277832,10.355466,0.868353,-102.973404,0.087841,0.000000
66.210007,46.615822,-103.017883,-0.000681,0.003434,0.087226,207.357529,10.563296,0.872256,-103.017883,0.088240,0.000000
66.450005,47.358330,-102.928925,-0.000690,0.003447,0.087555,210.660370,10.731550,0.875551,-102.928925,0.088639,0.000000
66.690002,48.524979,-102.973404,-0.000668,0.003466,0.088041,215.849884,10.995917,0.880408,-102.973404,0.089047,0.000000
66.930000,49.265625,-103.062363,-0.000660,0.003480,0.088388,219.144440,11.163750,0.883876,-103.062363,0.089446,0.000000
67.170006,50.049095,-103.106842,-0.000655,0.003493,0.088717,222.629501,11.341287,0.887172,-103.106842,0.089845,0.000000
67.410004,50.954704,-103.062363,-0.000642,0.003509,0.089116,226.657852,11.546501,0.891161,-103.062363,0.090243,0.000000
67.650002,52.368980,-103.017883,-0.000642,0.003527,0.089593,232.948853,11.866981,0.895931,-103.017883,0.090642,0.000000
67.890007,53.184471,-103.106842,-0.000642,0.003543,0.090001,236.576340,12.051773,0.900007,-103.106842,0.091041,0.000000
68.130005,54.444206,-103.151329,-0.000625,0.003560,0.090417,242.179932,12.337234,0.904169,-103.151329,0.091440,0.000000
68.370003,55.883430,-103.151329,-0.000617,0.003580,0.090929,248.581909,12.663366,0.909286,-103.151329,0.091839,0.000000
68.610001,56.816597,-103.151329,-0.000612,0.003594,0.091293,252.732849,12.874825,0.912928,-103.151329,0.092247,0.000000
68.850006,57.851791,-103.106842,-0.000599,0.003610,0.091700,257.337616,13.109404,0.917004,-103.106842,0.092646,0.000000
69.090004,58.518333,-103.240288,-0.000591,0.003621,0.091969,260.302551,13.260444,0.919693,-103.240288,0.093045,0.000000
69.330002,59.531563,-103.240288,-0.000591,0.003637,0.092386,264.809631,13.490046,0.923855,-103.240288,0.093444,0.000000
69.570000,60.964447,-103.284767,-0.000595,0.003654,0.092802,271.183411,13.814741,0.928018,-103.284767,0.093842,0.000000
69.810005,61.750160,-103.284767,-0.000565,0.003666,0.093105,274.678436,13.992786,0.931054,-103.284767,0.094241,0.000000
70.050003,63.523026,-103.284767,-0.000573,0.003689,0.093704,282.564545,14.394524,0.937037,-103.284767,0.094640,0.000000
70.290001,64.306122,-103.329247,-0.000573,0.003699,0.093947,286.047913,14.571976,0.939466,-103.329247,0.095039,0.000000
70.530006,65.550583,-103.373734,-0.000556,0.003716,0.094398,291.583557,14.853974,0.943975,-103.373734,0.095447,0.000000
70.770004,66.770477,-103.373734,-0.000560,0.003734,0.094848,297.009918,15.130406,0.948485,-103.373734,0.095846,0.000000
71.010002,67.340591,-103.373734,-0.000526,0.003732,0.094788,299.545898,15.259597,0.947878,-103.373734,0.095083,0.000000
71.250000,66.786865,-103.373734,-0.000539,0.003732,0.094788,297.082825,15.134120,0.947878,-103.373734,0.095083,0.000000
71.490005,66.328110,-103.373734,-0.000535,0.003731,0.094762,295.042175,15.030164,0.947618,-103.373734,0.094788,0.000000
71.730003,65.932648,-103.373734,-0.000526,0.003730,0.094744,293.283051,14.940551,0.947444,-103.373734,0.094788,0.000000
71.970001,65.568832,-103.462692,-0.000530,0.003730,0.094736,291.664734,14.858110,0.947357,-103.462692,0.094788,0.000000
72.210007,65.268326,-103.551651,-0.000530,0.003729,0.094727,290.328003,14.790014,0.947271,-103.551651,0.094788,0.000000
72.450005,65.003571,-103.462692,-0.000517,0.003729,0.094727,289.150330,14.730020,0.947271,-103.462692,0.094788,0.000000
72.690002,64.753708,-103.551651,-0.000517,0.003729,0.094718,288.038879,14.673400,0.947184,-103.551651,0.094788,0.000000
72.930000,64.533646,-103.507172,-0.000513,0.003729,0.094718,287.059998,14.623533,0.947184,-103.507172,0.094788,0.000000
73.170006,64.321762,-103.507172,-0.000513,0.003729,0.094718,286.117493,14.575521,0.947184,-103.507172,0.094788,0.000000
73.410004,64.141525,-103.596138,-0.000509,0.003729,0.094718,285.315765,14.534678,0.947184,-103.596138,0.094788,0.000000
73.650002,63.977310,-103.596138,-0.000530,0.003729,0.094718,284.585297,14.497466,0.947184,-103.596138,0.094788,0.000000
73.890007,63.803787,-103.640617,-0.000509,0.003729,0.094710,283.813416,14.458144,0.947097,-103.640617,0.094788,0.000000
74.130005,63.670853,-103.596138,-0.000509,0.003729,0.094710,283.222107,14.428021,0.947097,-103.596138,0.094788,0.000000
74.370003,63.526749,-103.640617,-0.000513,0.003729,0.094710,282.581085,14.395367,0.947097,-103.640617,0.094788,0.000000
74.610001,63.394547,-103.640617,-0.000513,0.003729,0.094710,281.993011,14.365410,0.947097,-103.640617,0.094788,0.000000
74.850006,63.286560,-103.640617,-0.000513,0.003729,0.094710,281.512665,14.340940,0.947097,-103.640617,0.094788,0.000000
75.090004,63.170380,-103.729576,-0.000517,0.003729,0.094710,280.995880,14.314613,0.947097,-103.729576,0.094788,0.000000
75.330002,63.065369,-103.774055,-0.000513,0.003729,0.094710,280.528778,14.290816,0.947097,-103.774055,0.094788,0.000000
75.570007,62.959251,-103.774055,-0.000513,0.003729,0.094710,280.056732,14.266770,0.947097,-103.774055,0.094788,0.000000
75.810005,62.868019,-103.774055,-0.000504,0.003729,0.094710,279.650909,14.246098,0.947097,-103.774055,0.094788,0.000000
76.050003,62.761147,-103.729576,-0.000509,0.003729,0.094710,279.175537,14.221879,0.947097,-103.729576,0.094788,0.000000
76.290001,62.692635,-103.818542,-0.000500,0.003729,0.094710,278.870758,14.206353,0.947097,-103.818542,0.094788,0.000000
76.530006,62.603264,-103.818542,-0.000513,0.003729,0.094710,278.473236,14.186103,0.947097,-103.818542,0.094788,0.000000
76.770004,62.507187,-103.863022,-0.000496,0.003729,0.094710,278.045868,14.164330,0.947097,-103.863022,0.094788,0.000000
77.010002,62.446121,-103.907501,-0.000513,0.003729,0.094710,277.774231,14.150494,0.947097,-103.907501,0.094788,0.000000
77.250000,62.369041,-103.863022,-0.000500,0.003729,0.094710,277.431366,14.133026,0.947097,-103.863022,0.094788,0.000000
77.490005,62.287491,-103.907501,-0.000517,0.003729,0.094710,277.068604,14.114548,0.947097,-103.907501,0.094788,0.000000
77.730003,62.232010,-103.951981,-0.000500,0.003729,0.094710,276.821808,14.101974,0.947097,-103.951981,0.094788,0.000000
77.970001,62.162743,-103.907501,-0.000500,0.003729,0.094710,276.513702,14.086279,0.947097,-103.907501,0.094788,0.000000
78.210007,62.104652,-103.907501,-0.000509,0.003728,0.094701,276.255280,14.073115,0.947010,-103.907501,0.094788,0.000000
78.450005,62.034279,-103.951981,-0.000500,0.003728,0.094701,275.942261,14.057168,0.947010,-103.951981,0.094788,0.000000
78.690002,61.981026,-104.040947,-0.000509,0.003728,0.094701,275.705383,14.045101,0.947010,-104.040947,0.094788,0.000000
78.930000,61.922195,-104.085426,-0.000492,0.003728,0.094701,275.443695,14.031771,0.947010,-104.085426,0.094788,0.000000
79.170006,61.878998,-103.996460,-0.000492,0.003728,0.094701,275.251526,14.021981,0.947010,-103.996460,0.094788,0.000000
79.410004,61.805641,-104.040947,-0.000492,0.003728,0.094701,274.925232,14.005359,0.947010,-104.040947,0.094788,0.000000
79.650002,61.761330,-104.085426,-0.000492,0.003728,0.094701,274.728119,13.995317,0.947010,-104.085426,0.094788,0.000000
79.890007,61.696159,-104.129906,-0.000504,0.003728,0.094701,274.438232,13.980549,0.947010,-104.129906,0.094788,0.000000
80.130005,61.660042,-104.129906,-0.000504,0.003728,0.094701,274.277557,13.972364,0.947010,-104.129906,0.094788,0.000000
80.370003,61.617966,-104.129906,-0.000504,0.003728,0.094701,274.090393,13.962831,0.947010,-104.129906,0.094788,0.000000
80.610001,61.572906,-104.174385,-0.000492,0.003728,0.094701,273.889954,13.952621,0.947010,-104.174385,0.094788,0.000000
80.850006,61.527107,-104.174385,-0.000504,0.003728,0.094701,273.686249,13.942242,0.947010,-104.174385,0.094788,0.000000
81.090004,61.479073,-104.218872,-0.000500,0.003728,0.094701,273.472565,13.931356,0.947010,-104.218872,0.094788,0.000000
81.330002,61.436989,-104.218872,-0.000496,0.003728,0.094701,273.285370,13.921821,0.947010,-104.218872,0.094788,0.000000
81.570007,61.382622,-104.218872,-0.000492,0.003728,0.094701,273.043549,13.909500,0.947010,-104.218872,0.094788,0.000000
81.810005,61.345390,-104.307831,-0.000487,0.003728,0.094701,272.877930,13.901064,0.947010,-104.307831,0.094788,0.000000
82.050003,61.305916,-104.307831,-0.000496,0.003728,0.094701,272.702332,13.892119,0.947010,-104.307831,0.094788,0.000000
82.290001,61.264954,-104.263351,-0.000492,0.003728,0.094701,272.520111,13.882837,0.947010,-104.263351,0.094788,0.000000
82.530006,61.248573,-104.352310,-0.000492,0.003728,0.094701,272.447266,13.879125,0.947010,-104.352310,0.094788,0.000000
82.770004,61.198303,-104.352310,-0.000496,0.003728,0.094701,272.223663,13.867733,0.947010,-104.352310,0.094788,0.000000
83.010002,61.158455,-104.396790,-0.000504,0.003728,0.094701,272.046387,13.858705,0.947010,-104.396790,0.094788,0.000000
83.250008,61.123825,-104.352310,-0.000483,0.003728,0.094701,271.892365,13.850857,0.947010,-104.352310,0.094788,0.000000
83.490005,61.093666,-104.396790,-0.000492,0.003728,0.094701,271.758209,13.844023,0.947010,-104.396790,0.094788,0.000000
83.730003,61.045998,-104.441277,-0.000487,0.003728,0.094701,271.546173,13.833221,0.947010,-104.441277,0.094788,0.000000
83.970001,61.019562,-104.485756,-0.000492,0.003728,0.094701,271.428558,13.827230,0.947010,-104.485756,0.094788,0.000000
84.210007,60.997589,-104.441277,-0.000487,0.003728,0.094701,271.330841,13.822251,0.947010,-104.441277,0.094788,0.000000
84.450005,60.957375,-104.530235,-0.000487,0.003728,0.094701,271.151947,13.813139,0.947010,-104.530235,0.094788,0.000000
84.690002,60.917534,-104.485756,-0.000504,0.003728,0.094701,270.974731,13.804111,0.947010,-104.485756,0.094788,0.000000
84.930000,60.900032,-104.574715,-0.000496,0.003728,0.094701,270.896881,13.800144,0.947010,-104.574715,0.094788,0.000000
85.170006,60.875450,-104.485756,-0.000483,0.003728,0.094701,270.787537,13.794574,0.947010,-104.485756,0.094788,0.000000
85.410004,60.836723,-104.574715,-0.000504,0.003728,0.094701,270.615265,13.785798,0.947010,-104.574715,0.094788,0.000000
85.650002,60.803215,-104.619194,-0.000479,0.003728,0.094701,270.466217,13.778206,0.947010,-104.619194,0.094788,0.000000
85.890007,60.771187,-104.619194,-0.000492,0.003728,0.094701,270.323730,13.770947,0.947010,-104.619194,0.094788,0.000000
86.130005,60.739906,-104.619194,-0.000496,0.003728,0.094701,270.184601,13.763859,0.947010,-104.619194,0.094788,0.000000
86.370003,60.722038,-104.663681,-0.000483,0.003728,0.094701,270.105103,13.759810,0.947010,-104.663681,0.094788,0.000000
86.610001,60.682564,-104.708160,-0.000496,0.003728,0.094701,269.929535,13.750865,0.947010,-104.708160,0.094788,0.000000
86.850006,60.668045,-104.797119,-0.000487,0.003728,0.094701,269.864929,13.747575,0.947010,-104.797119,0.094788,0.000000
87.090004,60.636765,-104.663681,-0.000487,0.003728,0.094701,269.725800,13.740488,0.947010,-104.663681,0.094788,0.000000
87.330002,60.622612,-104.752640,-0.000483,0.003728,0.094701,269.662842,13.737280,0.947010,-104.752640,0.094788,0.000000
87.570007,60.582024,-104.752640,-0.000483,0.003728,0.094701,269.482300,13.728083,0.947010,-104.752640,0.094788,0.000000
87.810005,60.556328,-104.752640,-0.000500,0.003728,0.094701,269.368011,13.722260,0.947010,-104.752640,0.094788,0.000000
88.050003,60.535851,-104.797119,-0.000496,0.003728,0.094701,269.276917,13.717620,0.947010,-104.797119,0.094788,0.000000
88.290001,60.506432,-104.752640,-0.000487,0.003728,0.094701,269.146057,13.710953,0.947010,-104.752640,0.094788,0.000000
88.530006,60.481857,-104.797119,-0.000487,0.003728,0.094701,269.036743,13.705385,0.947010,-104.797119,0.094788,0.000000
88.770004,60.459145,-104.841599,-0.000483,0.003728,0.094701,268.935699,13.700237,0.947010,-104.841599,0.094788,0.000000
89.010002,60.443130,-104.886086,-0.000487,0.003728,0.094701,268.864471,13.696609,0.947010,-104.886086,0.094788,0.000000
89.250008,60.412964,-104.886086,-0.000487,0.003728,0.094701,268.730286,13.689773,0.947010,-104.886086,0.094788,0.000000
89.490005,60.391739,-104.797119,-0.000487,0.003728,0.094701,268.635864,13.684963,0.947010,-104.797119,0.094788,0.000000
89.730003,60.370148,-104.975044,-0.000504,0.003728,0.094701,268.539825,13.680071,0.947010,-104.975044,0.094788,0.000000
89.970001,60.351898,-104.930565,-0.000483,0.003728,0.094701,268.458649,13.675936,0.947010,-104.930565,0.094788,0.000000
90.210007,60.330299,-104.975044,-0.000492,0.003728,0.094701,268.362579,13.671041,0.947010,-104.975044,0.094788,0.000000
90.450005,60.310196,-104.975044,-0.000492,0.003728,0.094701,268.273163,13.666486,0.947010,-104.975044,0.094788,0.000000
90.690002,60.277054,-104.975044,-0.000483,0.003728,0.094701,268.125732,13.658976,0.947010,-104.975044,0.094788,0.000000
90.930008,60.260292,-105.064003,-0.000496,0.003728,0.094701,268.051178,13.655177,0.947010,-105.064003,0.094788,0.000000
91.170006,60.238693,-105.019524,-0.000487,0.003728,0.094701,267.955078,13.650283,0.947010,-105.019524,0.094788,0.000000
91.410004,60.228645,-104.975044,-0.000487,0.003728,0.094701,267.910400,13.648005,0.947010,-104.975044,0.094788,0.000000
91.650002,60.188797,-105.108490,-0.000487,0.003728,0.094701,267.733154,13.638976,0.947010,-105.108490,0.094788,0.000000
91.890007,60.178001,-105.064003,-0.000483,0.003728,0.094701,267.685120,13.636530,0.947010,-105.064003,0.094788,0.000000
92.130005,60.169434,-105.152969,-0.000492,0.003728,0.094701,267.647003,13.634589,0.947010,-105.152969,0.094788,0.000000
92.370003,60.142624,-105.064003,-0.000483,0.003728,0.094701,267.527740,13.628513,0.947010,-105.064003,0.094788,0.000000
92.610001,60.126984,-105.108490,-0.000483,0.003728,0.094701,267.458191,13.624969,0.947010,-105.108490,0.094788,0.000000
92.850006,60.107620,-105.152969,-0.000487,0.003728,0.094701,267.372040,13.620582,0.947010,-105.152969,0.094788,0.000000
93.090004,60.105759,-105.152969,-0.000483,0.003728,0.094701,267.363770,13.620160,0.947010,-105.152969,0.094788,0.000000
93.330002,60.083046,-105.286407,-0.000487,0.003728,0.094701,267.262726,13.615013,0.947010,-105.286407,0.094788,0.000000
93.570007,60.061821,-105.197449,-0.000483,0.003728,0.094701,267.168335,13.610204,0.947010,-105.197449,0.094788,0.000000
93.810005,60.034264,-105.241928,-0.000492,0.003728,0.094701,267.045746,13.603958,0.947010,-105.241928,0.094788,0.000000
94.050003,60.023834,-105.286407,-0.000492,0.003728,0.094701,266.999359,13.601595,0.947010,-105.286407,0.094788,0.000000
94.290001,59.991440,-105.286407,-0.000487,0.003728,0.094701,266.855255,13.594254,0.947010,-105.286407,0.094788,0.000000
94.530006,59.980270,-105.330894,-0.000483,0.003728,0.094701,266.805573,13.591723,0.947010,-105.330894,0.094788,0.000000
94.770004,59.948250,-105.330894,-0.000487,0.003728,0.094701,266.663147,13.584468,0.947010,-105.330894,0.094788,0.000000
95.010002,59.958298,-105.330894,-0.000487,0.003728,0.094701,266.707825,13.586745,0.947010,-105.330894,0.094788,0.000000
95.250008,59.927391,-105.464333,-0.000483,0.003728,0.094701,266.570343,13.579741,0.947010,-105.464333,0.094788,0.000000
95.490005,59.911011,-105.375374,-0.000483,0.003728,0.094701,266.497498,13.576030,0.947010,-105.375374,0.094788,0.000000
95.730003,59.889786,-105.419853,-0.000492,0.003728,0.094701,266.403076,13.571219,0.947010,-105.419853,0.094788,0.000000
95.970001,59.872284,-105.464333,-0.000496,0.003728,0.094701,266.325226,13.567253,0.947010,-105.464333,0.094788,0.000000
96.210007,59.860741,-105.464333,-0.000487,0.003728,0.094701,266.273865,13.564638,0.947010,-105.464333,0.094788,0.000000
96.450005,59.844353,-105.508820,-0.000483,0.003728,0.094701,266.200989,13.560924,0.947010,-105.508820,0.094788,0.000000
96.690002,59.832436,-105.464333,-0.000479,0.003728,0.094701,266.147980,13.558224,0.947010,-105.464333,0.094788,0.000000
96.930008,59.807114,-105.508820,-0.000487,0.003728,0.094701,266.035339,13.552485,0.947010,-105.508820,0.094788,0.000000
97.170006,59.799294,-105.553299,-0.000479,0.003728,0.094701,266.000549,13.550714,0.947010,-105.553299,0.094788,0.000000
97.410004,59.787010,-105.553299,-0.000483,0.003728,0.094701,265.945892,13.547930,0.947010,-105.553299,0.094788,0.000000
97.650002,59.773979,-105.597778,-0.000483,0.003728,0.094701,265.887939,13.544978,0.947010,-105.597778,0.094788,0.000000
97.890007,59.752007,-105.597778,-0.000470,0.003728,0.094701,265.790192,13.539998,0.947010,-105.597778,0.094788,0.000000
98.130005,59.742325,-105.597778,-0.000479,0.003728,0.094701,265.747131,13.537804,0.947010,-105.597778,0.094788,0.000000
98.370003,59.726311,-105.642258,-0.000492,0.003728,0.094701,265.675903,13.534175,0.947010,-105.642258,0.094788,0.000000
98.610008,59.712166,-105.597778,-0.000496,0.003728,0.094701,265.612976,13.530971,0.947010,-105.597778,0.094788,0.000000
98.850006,59.690933,-105.686737,-0.000492,0.003728,0.094701,265.518524,13.526159,0.947010,-105.686737,0.094788,0.000000
99.090004,59.684982,-105.642258,-0.000474,0.003728,0.094701,265.492065,13.524810,0.947010,-105.642258,0.094788,0.000000
99.330002,59.658165,-105.686737,-0.000487,0.003728,0.094701,265.372772,13.518733,0.947010,-105.686737,0.094788,0.000000
99.570007,59.651093,-105.686737,-0.000492,0.003728,0.094701,265.341309,13.517131,0.947010,-105.686737,0.094788,0.000000
99.810005,59.626144,-105.686737,-0.000487,0.003728,0.094701,265.230347,13.511477,0.947010,-105.686737,0.094788,0.000000
100.050003,59.621300,-105.820183,-0.000496,0.003728,0.094701,265.208801,13.510380,0.947010,-105.820183,0.094788,0.000000
100.290009,59.607155,-105.775703,-0.000483,0.003728,0.094701,265.145874,13.507174,0.947010,-105.775703,0.094788,0.000000
100.530006,59.588531,-105.731224,-0.000487,0.003728,0.094701,265.063019,13.502954,0.947010,-105.731224,0.094788,0.000000
100.770004,59.567680,-105.820183,-0.000483,0.003728,0.094701,264.970276,13.498229,0.947010,-105.820183,0.094788,0.000000
101.010002,59.565819,-105.775703,-0.000479,0.003728,0.094701,264.962006,13.497808,0.947010,-105.775703,0.094788,0.000000
101.250008,59.539757,-105.909142,-0.000492,0.003728,0.094701,264.846069,13.491901,0.947010,-105.909142,0.094788,0.000000
101.400002,59.541985,-105.909142,-0.000492,0.003728,0.094701,264.855988,13.492407,0.947010,-105.909142,0.094788,0.000000