File: Data/compression 11/AutoNoHeating-12-11-2-240530_05302024_161322.csv
Time (sec),S:Load (lbs),S:HL1 (DIM),S:LVDT (in),S:Position (in),Ch:Position (mm),Ch:Load (N),Ch:Stress (MPa),Ch:Strain (mm/mm),Ch:HL1 (DIM),Set Point (),Cycles ()
0.210000,-0.002235,-83.535225,-0.013305,-0.000000,-0.000000,-0.009944,-0.000507,-0.000000,-83.535225,0.000199,0.000000
0.460000,-0.022713,-83.579704,-0.013323,0.000008,0.000191,-0.101031,-0.005147,0.001908,-83.579704,0.000737,0.000000
0.710000,-0.020477,-83.535225,-0.013297,0.000148,0.003755,-0.091088,-0.004640,0.037551,-83.535225,0.004900,0.000000
0.960000,-0.014519,-83.535225,-0.013154,0.000305,0.007753,-0.064583,-0.003290,0.077530,-83.535225,0.009063,0.000000
1.210000,-0.008186,-83.535225,-0.012986,0.000475,0.012063,-0.036415,-0.001855,0.120631,-83.535225,0.013243,0.000000
1.460000,0.011917,-83.624191,-0.012827,0.000635,0.016139,0.053010,0.002700,0.161391,-83.624191,0.017405,0.000000
1.710000,-0.012283,-83.668671,-0.012650,0.000805,0.020458,-0.054639,-0.002783,0.204579,-83.668671,0.021568,0.000000
1.960000,0.022346,-83.668671,-0.012482,0.000964,0.024473,0.099402,0.005064,0.244731,-83.668671,0.025731,0.000000
2.210000,0.020485,-83.713150,-0.012331,0.001129,0.028670,0.091121,0.004642,0.286705,-83.713150,0.029893,0.000000
2.460000,-0.008934,-83.713150,-0.012154,0.001296,0.032929,-0.039741,-0.002024,0.329286,-83.713150,0.034056,0.000000
2.710000,-0.002975,-83.757629,-0.011977,0.001457,0.037013,-0.013236,-0.000674,0.370132,-83.757629,0.038219,0.000000
2.960000,-0.013405,-83.713150,-0.011818,0.001623,0.041219,-0.059628,-0.003038,0.412192,-83.713150,0.042381,0.000000
3.210000,-0.015640,-83.802109,-0.011645,0.001785,0.045339,-0.069571,-0.003544,0.453386,-83.802109,0.046561,0.000000
3.460000,-0.038727,-83.802109,-0.011490,0.001946,0.049432,-0.172265,-0.008776,0.494319,-83.802109,0.050724,0.000000
3.710000,0.036865,-83.802109,-0.011305,0.002115,0.053716,0.163985,0.008354,0.537160,-83.802109,0.054887,0.000000
3.960000,0.023460,-83.891075,-0.011154,0.002286,0.058061,0.104357,0.005316,0.580608,-83.891075,0.059049,0.000000
4.210000,-0.004463,-83.891075,-0.010981,0.002446,0.062119,-0.019853,-0.001011,0.621194,-83.891075,0.063212,0.000000
4.460000,0.012291,-83.891075,-0.010822,0.002608,0.066239,0.054673,0.002785,0.662387,-83.891075,0.067375,0.000000
4.710000,-0.004097,-83.891075,-0.010649,0.002767,0.070271,-0.018224,-0.000928,0.702713,-83.891075,0.071537,0.000000
4.960000,-0.019730,-83.980034,-0.010477,0.002935,0.074538,-0.087762,-0.004471,0.745381,-83.980034,0.075717,0.000000
5.210000,-0.024574,-83.935555,-0.010313,0.003092,0.078545,-0.109312,-0.005569,0.785446,-83.935555,0.079880,0.000000
5.460000,0.017502,-84.024513,-0.010154,0.003261,0.082837,0.077852,0.003966,0.828374,-84.024513,0.084043,0.000000
5.710000,0.010056,-83.980034,-0.009981,0.003422,0.086931,0.044729,0.002279,0.869307,-83.980034,0.088206,0.000000
5.960001,-0.004097,-84.024513,-0.009822,0.003594,0.091293,-0.018224,-0.000928,0.912928,-84.024513,0.092368,0.000000
6.210001,0.029793,-84.024513,-0.009662,0.003754,0.095343,0.132525,0.006751,0.953428,-84.024513,0.096531,0.000000
6.460001,0.019737,-84.069000,-0.009494,0.003915,0.099453,0.087796,0.004473,0.994534,-84.069000,0.100694,0.000000
6.710001,-0.012283,-84.069000,-0.009313,0.004086,0.103790,-0.054639,-0.002783,1.037896,-84.069000,0.104856,0.000000
6.960001,0.007446,-84.069000,-0.009162,0.004245,0.107831,0.033123,0.001687,1.078309,-84.069000,0.109036,0.000000
7.210001,0.021225,-84.113480,-0.008994,0.004407,0.111950,0.094413,0.004810,1.119502,-84.113480,0.113199,0.000000
7.460001,-0.018616,-84.157959,-0.008817,0.004570,0.116078,-0.082807,-0.004218,1.160782,-84.157959,0.117362,0.000000
7.710001,-0.035004,-84.157959,-0.008653,0.004734,0.120232,-0.155704,-0.007932,1.202322,-84.157959,0.121524,0.000000
7.960001,0.022720,-84.202438,-0.008476,0.004904,0.124551,0.101065,0.005149,1.245510,-84.202438,0.125687,0.000000
8.210000,0.037239,-84.246918,-0.008313,0.005073,0.128852,0.165648,0.008438,1.288524,-84.246918,0.129850,0.000000
8.460000,-0.004837,-84.246918,-0.008140,0.005236,0.132989,-0.021516,-0.001096,1.329891,-84.246918,0.134012,0.000000
8.710000,0.025696,-84.291405,-0.007976,0.005397,0.137074,0.114301,0.005823,1.370737,-84.291405,0.138175,0.000000
8.960000,0.020485,-84.291405,-0.007808,0.005554,0.141063,0.091121,0.004642,1.410629,-84.291405,0.142355,0.000000
9.210000,-0.004097,-84.335884,-0.007640,0.005721,0.145304,-0.018224,-0.000928,1.453037,-84.335884,0.146518,0.000000
9.460000,-0.032021,-84.335884,-0.007476,0.005882,0.149406,-0.142435,-0.007256,1.494056,-84.335884,0.150680,0.000000
9.710000,0.006332,-84.335884,-0.007304,0.006048,0.153620,0.028168,0.001435,1.536204,-84.335884,0.154843,0.000000
9.960000,0.034264,-84.380363,-0.007140,0.006212,0.157792,0.152412,0.007764,1.577917,-84.380363,0.159006,0.000000
10.210000,-0.000000,-84.424843,-0.006976,0.006381,0.162076,-0.000000,-0.000000,1.620758,-84.424843,0.163169,0.000000
10.460000,0.028679,-84.424843,-0.006808,0.006544,0.166230,0.127570,0.006499,1.662298,-84.424843,0.167331,0.000000
10.710000,0.035751,-84.424843,-0.006657,0.006703,0.170254,0.159030,0.008101,1.702538,-84.424843,0.171511,0.000000
10.960001,0.026070,-84.558289,-0.006476,0.006872,0.174555,0.115964,0.005907,1.745552,-84.558289,0.175674,0.000000
11.210001,-0.001114,-84.469330,-0.006316,0.007032,0.178605,-0.004955,-0.000252,1.786051,-84.469330,0.179837,0.000000
11.460001,0.022720,-84.513809,-0.006148,0.007196,0.182776,0.101065,0.005149,1.827765,-84.513809,0.183999,0.000000
11.710001,0.004471,-84.602768,-0.005984,0.007359,0.186930,0.019887,0.001013,1.869305,-84.602768,0.188162,0.000000
11.960001,-0.024948,-84.558289,-0.005816,0.007526,0.191154,-0.110975,-0.005653,1.911539,-84.558289,0.192325,0.000000
12.210001,0.031281,-84.513809,-0.005639,0.007692,0.195377,0.139143,0.007088,1.953773,-84.513809,0.196487,0.000000
12.460001,0.042824,-84.558289,-0.005484,0.007859,0.199609,0.190490,0.009704,1.996094,-84.558289,0.200650,0.000000
12.710001,0.007446,-84.602768,-0.005307,0.008021,0.203737,0.033123,0.001687,2.037373,-84.602768,0.204830,0.000000
12.960001,0.034630,-84.647247,-0.005148,0.008184,0.207874,0.154041,0.007847,2.078740,-84.647247,0.208993,0.000000
13.210001,0.033142,-84.602768,-0.004988,0.008342,0.211898,0.147423,0.007510,2.118979,-84.602768,0.213155,0.000000
13.460001,0.024208,-84.647247,-0.004825,0.008506,0.216043,0.107683,0.005486,2.160433,-84.647247,0.217318,0.000000
13.710001,-0.020477,-84.691734,-0.004661,0.008674,0.220319,-0.091088,-0.004640,2.203187,-84.691734,0.221481,0.000000
13.960001,0.008194,-84.691734,-0.004484,0.008835,0.224421,0.036449,0.001857,2.244207,-84.691734,0.225643,0.000000
14.210001,0.039474,-84.736214,-0.004329,0.009002,0.228661,0.175591,0.008945,2.286614,-84.736214,0.229806,0.000000
14.460001,0.055855,-84.736214,-0.004156,0.009167,0.232850,0.248455,0.012657,2.328501,-84.736214,0.233969,0.000000
14.710001,0.252472,-84.780693,-0.003980,0.009335,0.237100,1.123051,0.057211,2.370995,-84.780693,0.238149,0.000000
14.960001,0.568985,-84.825172,-0.003863,-0.000007,-0.000173,2.530972,0.128934,-0.001734,-84.825172,0.000113,0.000000
15.210001,0.525795,-84.780693,-0.003872,-0.000007,-0.000173,2.338853,0.119147,-0.001734,-84.780693,0.000113,0.000000
15.460001,0.609947,-84.825172,-0.003867,-0.000007,-0.000173,2.713181,0.138216,-0.001734,-84.825172,0.000217,0.000000
15.710001,0.586487,-84.869652,-0.003854,-0.000007,-0.000173,2.608824,0.132900,-0.001734,-84.869652,0.000633,0.000000
15.960001,0.638618,-84.869652,-0.003876,0.000008,0.000199,2.840717,0.144713,0.001995,-84.869652,0.001049,0.000000
16.210001,0.730598,-84.914139,-0.003854,0.000019,0.000486,3.249864,0.165556,0.004856,-84.914139,0.001466,0.000000
16.460001,0.802467,-84.914139,-0.003837,0.000035,0.000893,3.569553,0.181842,0.008932,-84.914139,0.001882,0.000000
16.710001,0.854973,-84.958618,-0.003820,0.000048,0.001214,3.803109,0.193740,0.012141,-84.958618,0.002307,0.000000
16.960001,0.967422,-84.958618,-0.003811,0.000072,0.001830,4.303310,0.219221,0.018298,-84.958618,0.002723,0.000000
17.210001,1.024025,-85.047577,-0.003798,0.000088,0.002246,4.555090,0.232047,0.022461,-85.047577,0.003139,0.000000
17.460001,1.078392,-85.003098,-0.003764,0.000105,0.002671,4.796927,0.244367,0.026711,-85.003098,0.003556,0.000000
17.710001,1.119728,-85.047577,-0.003760,0.000119,0.003018,4.980799,0.253734,0.030179,-85.047577,0.003972,0.000000
17.960001,1.187874,-85.047577,-0.003742,0.000135,0.003426,5.283927,0.269176,0.034255,-85.047577,0.004388,0.000000
18.210001,1.241867,-85.092056,-0.003729,0.000154,0.003911,5.524101,0.281411,0.039112,-85.092056,0.004804,0.000000
18.460001,1.281334,-85.136543,-0.003725,0.000167,0.004249,5.699658,0.290354,0.042494,-85.136543,0.005221,0.000000
18.710001,1.339424,-85.136543,-0.003686,0.000183,0.004657,5.958056,0.303518,0.046570,-85.136543,0.005637,0.000000
18.960001,1.419113,-85.136543,-0.003686,0.000203,0.005160,6.312531,0.321576,0.051600,-85.136543,0.006053,0.000000
19.210001,1.450020,-85.225502,-0.003660,0.000220,0.005576,6.450010,0.328579,0.055763,-85.225502,0.006470,0.000000
19.460001,1.471992,-85.225502,-0.003643,0.000236,0.006001,6.547750,0.333558,0.060012,-85.225502,0.006886,0.000000
19.710001,1.458214,-85.269981,-0.003626,0.000246,0.006253,6.486459,0.330436,0.062527,-85.269981,0.007302,0.000000
19.960001,1.571785,-85.269981,-0.003617,0.000268,0.006808,6.991649,0.356172,0.068077,-85.269981,0.007718,0.000000
20.210001,1.572159,-85.269981,-0.003613,0.000281,0.007137,6.993312,0.356256,0.071373,-85.269981,0.008135,0.000000
20.460001,1.656319,-85.269981,-0.003587,0.000298,0.007571,7.367673,0.375327,0.075709,-85.269981,0.008551,0.000000
20.710001,1.646637,-85.269981,-0.003566,0.000310,0.007883,7.324607,0.373133,0.078831,-85.269981,0.008967,0.000000
20.960001,1.750153,-85.358948,-0.003544,0.000331,0.008403,7.785068,0.396590,0.084034,-85.358948,0.009383,0.000000
21.210001,1.769890,-85.358948,-0.003535,0.000350,0.008898,7.872863,0.401063,0.088977,-85.358948,0.009800,0.000000
21.460001,1.778450,-85.269981,-0.003505,0.000366,0.009288,7.910941,0.403003,0.092880,-85.269981,0.010216,0.000000
21.710001,1.769142,-85.447906,-0.003505,0.000376,0.009557,7.869537,0.400893,0.095568,-85.447906,0.010641,0.000000
21.960001,1.894630,-85.447906,-0.003492,0.000398,0.010121,8.427737,0.429329,0.101205,-85.447906,0.011057,0.000000
22.210001,1.861122,-85.447906,-0.003479,0.000408,0.010363,8.278685,0.421736,0.103633,-85.447906,0.011473,0.000000
22.460001,1.963898,-85.492386,-0.003445,0.000429,0.010892,8.735853,0.445026,0.108924,-85.492386,0.011890,0.000000
22.710001,1.960915,-85.536865,-0.003445,0.000445,0.011300,8.722584,0.444350,0.113000,-85.536865,0.012306,0.000000
22.960001,1.996666,-85.536865,-0.003423,0.000463,0.011768,8.881614,0.452451,0.117682,-85.536865,0.012722,0.000000
23.210001,2.024216,-85.492386,-0.003402,0.000480,0.012193,9.004161,0.458694,0.121932,-85.492386,0.013138,0.000000
23.460001,2.029434,-85.581352,-0.003393,0.000496,0.012601,9.027374,0.459876,0.126008,-85.581352,0.013555,0.000000
23.710001,2.013794,-85.581352,-0.003385,0.000509,0.012930,8.957803,0.456332,0.129303,-85.581352,0.013971,0.000000
23.960001,2.088638,-85.581352,-0.003354,0.000526,0.013373,9.290728,0.473292,0.133726,-85.581352,0.014387,0.000000
24.210001,2.131088,-85.625832,-0.003341,0.000541,0.013746,9.479554,0.482911,0.137455,-85.625832,0.014804,0.000000
24.460001,2.175034,-85.625832,-0.003328,0.000561,0.014249,9.675033,0.492870,0.142485,-85.625832,0.015220,0.000000
24.710001,2.228279,-85.670311,-0.003307,0.000579,0.014699,9.911880,0.504935,0.146995,-85.670311,0.015636,0.000000
24.960001,2.239822,-85.714790,-0.003277,0.000596,0.015133,9.963227,0.507551,0.151331,-85.714790,0.016052,0.000000
25.210001,2.250252,-85.714790,-0.003268,0.000613,0.015567,10.009620,0.509914,0.155667,-85.714790,0.016469,0.000000
25.460001,2.243172,-85.759277,-0.003255,0.000626,0.015896,9.978126,0.508310,0.158962,-85.759277,0.016885,0.000000
25.710001,2.279297,-85.759277,-0.003238,0.000640,0.016252,10.138819,0.516496,0.162518,-85.759277,0.017301,0.000000
25.960001,2.375740,-85.759277,-0.003216,0.000658,0.016703,10.567820,0.538350,0.167028,-85.759277,0.017717,0.000000
26.210001,2.428246,-85.848236,-0.003208,0.000677,0.017188,10.801375,0.550248,0.171884,-85.848236,0.018134,0.000000
26.460001,2.431595,-85.759277,-0.003203,0.000692,0.017579,10.816274,0.551007,0.175787,-85.759277,0.018550,0.000000
26.710001,2.446114,-85.848236,-0.003178,0.000706,0.017934,10.880857,0.554297,0.179342,-85.848236,0.018975,0.000000
26.960001,2.512772,-85.848236,-0.003147,0.000724,0.018394,11.177366,0.569402,0.183939,-85.848236,0.019391,0.000000
27.210001,2.478889,-85.848236,-0.003143,0.000741,0.018810,11.026651,0.561724,0.188101,-85.848236,0.019807,0.000000
27.460001,2.475159,-85.892715,-0.003134,0.000753,0.019131,11.010056,0.560879,0.191310,-85.892715,0.020224,0.000000
27.710001,2.568626,-85.981682,-0.003104,0.000773,0.019634,11.425821,0.582059,0.196340,-85.981682,0.020640,0.000000
27.960001,2.643471,-85.981682,-0.003087,0.000791,0.020102,11.758745,0.599019,0.201023,-85.981682,0.021056,0.000000
28.210001,2.690765,-85.937195,-0.003074,0.000808,0.020519,11.969122,0.609736,0.205186,-85.937195,0.021473,0.000000
28.460001,2.755188,-86.026161,-0.003061,0.000828,0.021022,12.255689,0.624335,0.210215,-86.026161,0.021889,0.000000
28.710001,2.790565,-86.026161,-0.003031,0.000844,0.021438,12.413055,0.632351,0.214378,-86.026161,0.022305,0.000000
28.960001,2.766731,-85.981682,-0.003031,0.000859,0.021828,12.307035,0.626950,0.218281,-85.981682,0.022721,0.000000
29.210001,2.784607,-86.070641,-0.003018,0.000876,0.022244,12.386550,0.631001,0.222443,-86.070641,0.023138,0.000000
29.460001,2.720558,-86.026161,-0.003005,0.000884,0.022444,12.101647,0.616487,0.224438,-86.026161,0.023554,0.000000
29.710001,2.905251,-86.070641,-0.002979,0.000907,0.023042,12.923200,0.658339,0.230422,-86.070641,0.023970,0.000000
29.960001,2.900414,-86.159599,-0.002966,0.000920,0.023380,12.901684,0.657243,0.233804,-86.159599,0.024386,0.000000
30.210001,3.039307,-86.115120,-0.002945,0.000939,0.023857,13.519511,0.688717,0.238574,-86.115120,0.024803,0.000000
30.460001,3.037819,-86.159599,-0.002932,0.000957,0.024300,13.512894,0.688380,0.242997,-86.159599,0.025219,0.000000
30.710001,3.018082,-86.204086,-0.002906,0.000968,0.024586,13.425097,0.683907,0.245858,-86.204086,0.025635,0.000000
30.960001,3.073189,-86.204086,-0.002910,0.000987,0.025071,13.670226,0.696395,0.250715,-86.204086,0.026051,0.000000
31.210001,3.136124,-86.248566,-0.002884,0.001006,0.025548,13.950174,0.710656,0.255485,-86.248566,0.026468,0.000000
31.460001,3.182297,-86.204086,-0.002863,0.001021,0.025921,14.155563,0.721119,0.259214,-86.204086,0.026884,0.000000
31.710001,3.234428,-86.293045,-0.002837,0.001039,0.026381,14.387456,0.732932,0.263810,-86.293045,0.027300,0.000000
31.960001,3.303322,-86.337524,-0.002828,0.001055,0.026789,14.693910,0.748543,0.267886,-86.337524,0.027725,0.000000
32.210003,3.276878,-86.337524,-0.002815,0.001068,0.027118,14.576283,0.742551,0.271181,-86.337524,0.028141,0.000000
32.460003,3.314117,-86.382004,-0.002807,0.001082,0.027491,14.741931,0.750990,0.274911,-86.382004,0.028558,0.000000
32.710003,3.448174,-86.337524,-0.002772,0.001104,0.028046,15.338242,0.781367,0.280461,-86.337524,0.028974,0.000000
32.960003,3.473862,-86.382004,-0.002768,0.001121,0.028480,15.452509,0.787188,0.284797,-86.382004,0.029390,0.000000
33.210003,3.503654,-86.426491,-0.002755,0.001138,0.028913,15.585033,0.793939,0.289133,-86.426491,0.029807,0.000000
33.460003,3.565468,-86.470970,-0.002738,0.001156,0.029356,15.859993,0.807947,0.293556,-86.470970,0.030223,0.000000
33.710003,3.578499,-86.515450,-0.002721,0.001169,0.029694,15.917958,0.810899,0.296938,-86.515450,0.030639,0.000000
33.960003,3.722237,-86.515450,-0.002703,0.001191,0.030240,16.557335,0.843471,0.302402,-86.515450,0.031055,0.000000
34.210003,3.707344,-86.515450,-0.002682,0.001206,0.030622,16.491091,0.840096,0.306217,-86.515450,0.031472,0.000000
34.460003,3.776604,-86.559929,-0.002665,0.001224,0.031081,16.799171,0.855791,0.310814,-86.559929,0.031888,0.000000
34.710003,3.797455,-86.559929,-0.002647,0.001236,0.031394,16.891922,0.860516,0.313936,-86.559929,0.032304,0.000000
34.960003,3.816444,-86.559929,-0.002639,0.001254,0.031853,16.976393,0.864819,0.318532,-86.559929,0.032720,0.000000
35.210003,3.874535,-86.604408,-0.002621,0.001270,0.032252,17.234791,0.877982,0.322521,-86.604408,0.033137,0.000000
35.460003,3.923317,-86.559929,-0.002600,0.001288,0.032712,17.451786,0.889036,0.327118,-86.559929,0.033553,0.000000
35.710003,3.972847,-86.648895,-0.002587,0.001300,0.033015,17.672106,0.900260,0.330153,-86.648895,0.033969,0.000000
35.960003,3.945663,-86.693375,-0.002583,0.001310,0.033284,17.551188,0.894100,0.332841,-86.693375,0.034385,0.000000
36.210003,4.138924,-86.648895,-0.002552,0.001332,0.033839,18.410852,0.937894,0.338391,-86.648895,0.034802,0.000000
36.460003,4.233131,-86.737854,-0.002548,0.001354,0.034403,18.829908,0.959241,0.344028,-86.737854,0.035218,0.000000
36.710003,4.187706,-86.737854,-0.002522,0.001369,0.034776,18.627846,0.948948,0.347758,-86.737854,0.035634,0.000000
36.960003,4.267387,-86.782333,-0.002518,0.001385,0.035183,18.982286,0.967004,0.351833,-86.782333,0.036059,0.000000
37.210003,4.367935,-86.782333,-0.002488,0.001403,0.035634,19.429546,0.989788,0.356343,-86.782333,0.036476,0.000000
37.460003,4.354897,-86.826813,-0.002470,0.001415,0.035929,19.371548,0.986834,0.359292,-86.826813,0.036892,0.000000
37.710003,4.385803,-86.826813,-0.002466,0.001430,0.036311,19.509027,0.993837,0.363107,-86.826813,0.037308,0.000000
37.960003,4.474060,-86.826813,-0.002440,0.001445,0.036692,19.901613,1.013837,0.366923,-86.826813,0.037724,0.000000
38.210003,4.586517,-86.826813,-0.002440,0.001461,0.037117,20.401848,1.039320,0.371173,-86.826813,0.038141,0.000000
38.460003,4.728760,-86.960258,-0.002414,0.001484,0.037698,21.034575,1.071552,0.376983,-86.960258,0.038557,0.000000
38.710003,4.720940,-86.915779,-0.002397,0.001499,0.038063,20.999788,1.069780,0.380625,-86.915779,0.038973,0.000000
38.960003,4.803238,-86.960258,-0.002389,0.001516,0.038505,21.365870,1.088429,0.385048,-86.960258,0.039389,0.000000
39.210003,4.867287,-86.960258,-0.002376,0.001532,0.038904,21.650772,1.102943,0.389037,-86.960258,0.039806,0.000000
39.460003,4.956650,-87.004738,-0.002363,0.001547,0.039303,22.048279,1.123193,0.393027,-87.004738,0.040222,0.000000
39.710003,4.856483,-87.004738,-0.002337,0.001557,0.039545,21.602716,1.100495,0.395455,-87.004738,0.040638,0.000000
39.960003,5.008415,-86.960258,-0.002320,0.001577,0.040048,22.278543,1.134923,0.400485,-86.960258,0.041054,0.000000
40.210003,5.182686,-87.004738,-0.002307,0.001597,0.040569,23.053738,1.174413,0.405688,-87.004738,0.041471,0.000000
40.460003,5.149910,-87.049225,-0.002281,0.001612,0.040933,22.907944,1.166986,0.409331,-87.049225,0.041887,0.000000
40.710003,5.334984,-87.138184,-0.002264,0.001632,0.041445,23.731194,1.208925,0.414447,-87.138184,0.042303,0.000000
40.960003,5.250458,-87.182663,-0.002264,0.001643,0.041740,23.355202,1.189771,0.417396,-87.182663,0.042720,0.000000
41.210003,5.469040,-87.138184,-0.002229,0.001663,0.042234,24.327505,1.239302,0.422339,-87.138184,0.043136,0.000000
41.460003,5.469780,-87.138184,-0.002225,0.001677,0.042589,24.330797,1.239470,0.425895,-87.138184,0.043552,0.000000
41.710003,5.481323,-87.227142,-0.002216,0.001690,0.042919,24.382143,1.242086,0.429190,-87.227142,0.043968,0.000000
41.960003,5.610909,-87.227142,-0.002199,0.001706,0.043335,24.958567,1.271450,0.433353,-87.227142,0.044393,0.000000
42.210003,5.853699,-87.271629,-0.002160,0.001728,0.043899,26.038553,1.326467,0.438990,-87.271629,0.044810,0.000000
42.460003,5.895401,-87.227142,-0.002156,0.001744,0.044289,26.224052,1.335917,0.442892,-87.227142,0.045226,0.000000
42.710003,5.951256,-87.271629,-0.002143,0.001761,0.044740,26.472507,1.348574,0.447402,-87.271629,0.045642,0.000000
42.960003,5.870827,-87.316109,-0.002126,0.001773,0.045035,26.114742,1.330348,0.450350,-87.316109,0.046058,0.000000
43.210003,6.009720,-87.316109,-0.002100,0.001790,0.045469,26.732569,1.361822,0.454686,-87.316109,0.046475,0.000000
43.460003,6.090157,-87.316109,-0.002104,0.001802,0.045781,27.090370,1.380049,0.457808,-87.316109,0.046891,0.000000
43.710003,6.309853,-87.360588,-0.002082,0.001823,0.046301,28.067627,1.429833,0.463012,-87.360588,0.047307,0.000000
43.960003,6.357147,-87.405067,-0.002070,0.001838,0.046683,28.278004,1.440550,0.466828,-87.405067,0.047723,0.000000
44.210003,6.467369,-87.360588,-0.002048,0.001855,0.047116,28.768295,1.465527,0.471164,-87.360588,0.048140,0.000000
44.460003,6.710526,-87.405067,-0.002031,0.001875,0.047637,29.849909,1.520627,0.476367,-87.405067,0.048556,0.000000
44.710003,6.742180,-87.449547,-0.002018,0.001892,0.048062,29.990713,1.527800,0.480616,-87.449547,0.048972,0.000000
44.960003,6.643127,-87.494034,-0.002001,0.001902,0.048322,29.550106,1.505354,0.483218,-87.494034,0.049389,0.000000
45.210003,6.855377,-87.449547,-0.001988,0.001921,0.048799,30.494242,1.553451,0.487988,-87.449547,0.049805,0.000000
45.460003,7.011032,-87.538513,-0.001966,0.001939,0.049250,31.186628,1.588723,0.492497,-87.538513,0.050221,0.000000
45.710003,7.122002,-87.494034,-0.001949,0.001955,0.049657,31.680246,1.613869,0.496573,-87.494034,0.050637,0.000000
45.960003,7.275787,-87.538513,-0.001936,0.001973,0.050126,32.364319,1.648717,0.501256,-87.538513,0.051054,0.000000
46.210003,7.376701,-87.627472,-0.001927,0.001989,0.050533,32.813206,1.671584,0.505332,-87.627472,0.051470,0.000000
46.460003,7.468307,-87.627472,-0.001906,0.002007,0.050984,33.220692,1.692343,0.509842,-87.627472,0.051886,0.000000
46.710003,7.492882,-87.627472,-0.001888,0.002020,0.051305,33.330002,1.697911,0.513051,-87.627472,0.052302,0.000000
46.960003,7.563629,-87.716438,-0.001880,0.002033,0.051643,33.644703,1.713943,0.516433,-87.716438,0.052727,0.000000
47.210003,7.673485,-87.627472,-0.001863,0.002048,0.052016,34.133366,1.738837,0.520162,-87.627472,0.053144,0.000000
47.460003,7.925209,-87.716438,-0.001858,0.002067,0.052493,35.253090,1.795878,0.524932,-87.716438,0.053560,0.000000
47.710003,8.176186,-87.760918,-0.001828,0.002085,0.052961,36.369492,1.852750,0.529615,-87.760918,0.053976,0.000000
47.960003,8.140808,-87.760918,-0.001819,0.002097,0.053256,36.212124,1.844733,0.532563,-87.760918,0.054392,0.000000
48.210003,8.369072,-87.805397,-0.001807,0.002118,0.053785,37.227489,1.896459,0.537853,-87.805397,0.054809,0.000000
48.460003,8.559357,-87.760918,-0.001789,0.002134,0.054202,38.073921,1.939578,0.542016,-87.760918,0.055225,0.000000
48.710003,8.552284,-87.805397,-0.001776,0.002149,0.054592,38.042461,1.937975,0.545919,-87.805397,0.055641,0.000000
48.960003,8.746284,-87.849876,-0.001755,0.002163,0.054939,38.905415,1.981936,0.549388,-87.849876,0.056057,0.000000
49.210003,9.145844,-87.849876,-0.001738,0.002184,0.055485,40.682743,2.072478,0.554851,-87.849876,0.056474,0.000000
49.460003,9.196114,-87.849876,-0.001712,0.002201,0.055901,40.906357,2.083869,0.559014,-87.849876,0.056890,0.000000
49.710003,9.410225,-87.894356,-0.001694,0.002217,0.056318,41.858772,2.132387,0.563176,-87.894356,0.057306,0.000000
49.960003,9.702911,-87.938843,-0.001690,0.002239,0.056864,43.160706,2.198711,0.568640,-87.938843,0.057723,0.000000
50.210003,9.804573,-87.938843,-0.001677,0.002256,0.057298,43.612919,2.221748,0.572976,-87.938843,0.058139,0.000000
50.460003,9.864525,-88.027802,-0.001651,0.002270,0.057671,43.879597,2.235333,0.576705,-88.027802,0.058555,0.000000
50.710003,9.722275,-87.983322,-0.001634,0.002279,0.057896,43.246838,2.203099,0.578960,-87.983322,0.058971,0.000000
50.960003,10.153481,-87.983322,-0.001638,0.002300,0.058425,45.164936,2.300812,0.584250,-87.983322,0.059388,0.000000
51.210003,10.295731,-88.027802,-0.001621,0.002313,0.058755,45.797695,2.333046,0.587545,-88.027802,0.059804,0.000000
51.460003,10.801407,-88.027802,-0.001608,0.002335,0.059301,48.047058,2.447634,0.593009,-88.027802,0.060220,0.000000
51.710003,10.983131,-88.161247,-0.001578,0.002352,0.059743,48.855408,2.488813,0.597432,-88.161247,0.060636,0.000000
51.960003,10.968979,-88.072281,-0.001569,0.002365,0.060073,48.792454,2.485606,0.600727,-88.072281,0.061053,0.000000
52.210003,11.199104,-88.116760,-0.001561,0.002381,0.060489,49.816105,2.537753,0.604890,-88.116760,0.061478,0.000000
52.460003,11.378212,-88.116760,-0.001548,0.002395,0.060845,50.612816,2.578340,0.608446,-88.116760,0.061894,0.000000
52.710003,11.668297,-88.205727,-0.001518,0.002414,0.061313,51.903175,2.644074,0.613129,-88.205727,0.062310,0.000000
52.960003,12.139717,-88.205727,-0.001500,0.002435,0.061851,54.000160,2.750899,0.618505,-88.205727,0.062726,0.000000
53.210003,12.118118,-88.250206,-0.001492,0.002448,0.062189,53.904083,2.746005,0.621888,-88.250206,0.063143,0.000000
53.460003,12.328140,-88.205727,-0.001466,0.002464,0.062579,54.838306,2.793597,0.625790,-88.205727,0.063559,0.000000
53.710003,12.610771,-88.250206,-0.001470,0.002480,0.062995,56.095512,2.857641,0.629953,-88.250206,0.063975,0.000000
53.960003,13.112350,-88.339172,-0.001444,0.002501,0.063516,58.326649,2.971301,0.635156,-88.339172,0.064392,0.000000
54.210003,13.103790,-88.339172,-0.001427,0.002515,0.063880,58.288570,2.969362,0.638798,-88.339172,0.064808,0.000000
54.460003,13.480629,-88.294685,-0.001431,0.002532,0.064322,59.964832,3.054754,0.643221,-88.294685,0.065224,0.000000
54.710003,13.850395,-88.383652,-0.001397,0.002552,0.064825,61.609634,3.138545,0.648251,-88.383652,0.065640,0.000000
54.960003,13.866783,-88.383652,-0.001384,0.002563,0.065111,61.682533,3.142258,0.651113,-88.383652,0.066057,0.000000
55.210003,14.184418,-88.428131,-0.001362,0.002581,0.065562,63.095440,3.214235,0.655623,-88.428131,0.066473,0.000000
55.460003,14.525505,-88.428131,-0.001350,0.002597,0.065961,64.612671,3.291526,0.659612,-88.428131,0.066889,0.000000
55.710003,15.014809,-88.472610,-0.001328,0.002617,0.066482,66.789207,3.402404,0.664815,-88.472610,0.067305,0.000000
55.960003,15.235252,-88.472610,-0.001315,0.002633,0.066889,67.769791,3.452358,0.668891,-88.472610,0.067722,0.000000
56.210003,15.385315,-88.472610,-0.001302,0.002648,0.067253,68.437302,3.486362,0.672534,-88.472610,0.068138,0.000000
56.460003,15.599426,-88.472610,-0.001293,0.002663,0.067652,69.389717,3.534881,0.676523,-88.472610,0.068554,0.000000
56.710003,16.144958,-88.561577,-0.001276,0.002682,0.068112,71.816360,3.658500,0.681119,-88.561577,0.068970,0.000000
56.960003,16.223526,-88.517090,-0.001263,0.002694,0.068424,72.165848,3.676304,0.684241,-88.517090,0.069387,0.000000
57.210003,16.329277,-88.561577,-0.001263,0.002705,0.068702,72.636253,3.700267,0.687016,-88.561577,0.069812,0.000000
57.460003,17.002525,-88.606056,-0.001246,0.002724,0.069196,75.631012,3.852827,0.691959,-88.606056,0.070228,0.000000
57.710003,18.032143,-88.606056,-0.001220,0.002750,0.069855,80.210976,4.086142,0.698550,-88.606056,0.070644,0.000000
57.960003,17.741692,-88.606056,-0.001216,0.002760,0.070115,78.918983,4.020325,0.701152,-88.606056,0.071060,0.000000
58.210003,18.353867,-88.650536,-0.001190,0.002780,0.070601,81.642075,4.159045,0.706008,-88.650536,0.071477,0.000000
58.460003,18.547874,-88.695015,-0.001181,0.002793,0.070948,82.505066,4.203009,0.709477,-88.695015,0.071893,0.000000
58.710003,19.035309,-88.695015,-0.001164,0.002812,0.071416,84.673279,4.313462,0.714160,-88.695015,0.072309,0.000000
58.960003,19.236389,-88.739494,-0.001160,0.002825,0.071754,85.567734,4.359028,0.717543,-88.739494,0.072726,0.000000
59.210003,19.760323,-88.695015,-0.001138,0.002841,0.072153,87.898308,4.477753,0.721532,-88.695015,0.073142,0.000000
59.460003,20.140137,-88.739494,-0.001138,0.002857,0.072569,89.587799,4.563820,0.725694,-88.739494,0.073558,0.000000
59.710003,20.615662,-88.783981,-0.001121,0.002871,0.072916,91.703041,4.671576,0.729163,-88.783981,0.073974,0.000000
59.960003,21.259117,-88.828461,-0.001104,0.002891,0.073437,94.565277,4.817385,0.734367,-88.828461,0.074391,0.000000
60.210003,21.683250,-88.783981,-0.001087,0.002908,0.073870,96.451912,4.913495,0.738703,-88.783981,0.074807,0.000000
60.460003,22.162865,-88.783981,-0.001078,0.002926,0.074330,98.585342,5.022177,0.743299,-88.783981,0.075223,0.000000
60.710003,22.576942,-88.917419,-0.001061,0.002942,0.074720,100.427254,5.116008,0.747202,-88.917419,0.075639,0.000000
60.960003,22.902023,-88.872940,-0.001052,0.002955,0.075050,101.873291,5.189672,0.750497,-88.872940,0.076056,0.000000
61.210003,23.387230,-88.917419,-0.001039,0.002971,0.075475,104.031593,5.299622,0.754747,-88.917419,0.076472,0.000000
61.460003,24.165115,-88.917419,-0.001030,0.002991,0.075960,107.491798,5.475893,0.759603,-88.917419,0.076888,0.000000
61.710003,24.746384,-88.961899,-0.001009,0.003008,0.076394,110.077415,5.607611,0.763939,-88.961899,0.077304,0.000000
61.960003,25.354843,-89.006386,-0.001000,0.003026,0.076862,112.783974,5.745489,0.768622,-89.006386,0.077721,0.000000
62.210003,25.593910,-88.917419,-0.000996,0.003038,0.077174,113.847397,5.799663,0.771744,-88.917419,0.078146,0.000000
62.460003,25.819191,-89.050865,-0.000974,0.003052,0.077513,114.849495,5.850712,0.775126,-89.050865,0.078562,0.000000
62.710003,26.885666,-89.050865,-0.000970,0.003071,0.078016,119.593414,6.092379,0.780156,-89.050865,0.078978,0.000000
62.960003,27.107597,-89.050865,-0.000966,0.003084,0.078345,120.580612,6.142670,0.783452,-89.050865,0.079395,0.000000
63.210003,27.836708,-89.050865,-0.000944,0.003100,0.078735,123.823860,6.307889,0.787354,-89.050865,0.079811,0.000000
63.460003,28.893501,-89.139824,-0.000927,0.003123,0.079316,128.524719,6.547361,0.793165,-89.139824,0.080227,0.000000
63.710003,29.497490,-89.139824,-0.000923,0.003138,0.079707,131.211395,6.684227,0.797067,-89.139824,0.080643,0.000000
63.960003,30.236649,-89.095345,-0.000905,0.003155,0.080149,134.499329,6.851723,0.801490,-89.095345,0.081060,0.000000
64.210007,30.410172,-89.139824,-0.000905,0.003167,0.080435,135.271194,6.891043,0.804352,-89.139824,0.081476,0.000000
64.460007,31.141884,-89.184303,-0.000884,0.003184,0.080877,138.526016,7.056852,0.808775,-89.184303,0.081892,0.000000
64.710007,31.972275,-89.228790,-0.000875,0.003201,0.081294,142.219788,7.245021,0.812937,-89.228790,0.082308,0.000000
64.960007,32.364754,-89.184303,-0.000862,0.003216,0.081693,143.965622,7.333958,0.816927,-89.184303,0.082725,0.000000
65.210007,33.512779,-89.273270,-0.000867,0.003236,0.082196,149.072281,7.594104,0.821956,-89.273270,0.083141,0.000000
65.460007,33.656517,-89.273270,-0.000845,0.003244,0.082386,149.711670,7.626676,0.823864,-89.273270,0.083557,0.000000
65.710007,35.080467,-89.273270,-0.000841,0.003267,0.082985,156.045715,7.949347,0.829848,-89.273270,0.083973,0.000000
65.960007,35.806969,-89.273270,-0.000836,0.003285,0.083436,159.277359,8.113976,0.834358,-89.273270,0.084390,0.000000
66.210007,36.187157,-89.317749,-0.000806,0.003299,0.083783,160.968506,8.200128,0.837827,-89.317749,0.084806,0.000000
66.460007,37.015686,-89.362228,-0.000806,0.003313,0.084138,164.653992,8.387874,0.841382,-89.362228,0.085222,0.000000
66.710007,37.932098,-89.406715,-0.000806,0.003333,0.084650,168.730408,8.595536,0.846499,-89.406715,0.085639,0.000000
66.960007,38.740517,-89.406715,-0.000772,0.003347,0.085005,172.326431,8.778727,0.850055,-89.406715,0.086055,0.000000
67.210007,39.822632,-89.451195,-0.000759,0.003367,0.085517,177.139908,9.023937,0.855171,-89.451195,0.086471,0.000000
67.460007,40.543175,-89.406715,-0.000755,0.003382,0.085899,180.345047,9.187215,0.858987,-89.406715,0.086896,0.000000
67.710007,41.318077,-89.540154,-0.000746,0.003399,0.086341,183.791992,9.362810,0.863410,-89.540154,0.087312,0.000000
67.960007,42.238953,-89.540154,-0.000737,0.003416,0.086766,187.888245,9.571484,0.867659,-89.540154,0.087729,0.000000
68.210007,42.646706,-89.540154,-0.000737,0.003426,0.087026,189.702026,9.663882,0.870261,-89.540154,0.088145,0.000000
68.460007,43.311386,-89.540154,-0.000729,0.003442,0.087416,192.658661,9.814500,0.874164,-89.540154,0.088561,0.000000
68.710007,44.737946,-89.584633,-0.000716,0.003462,0.087937,199.004318,10.137763,0.879367,-89.584633,0.088977,0.000000
68.960007,45.777237,-89.584633,-0.000711,0.003478,0.088353,203.627319,10.373270,0.883529,-89.584633,0.089394,0.000000
69.210007,46.664604,-89.629120,-0.000690,0.003496,0.088787,207.574524,10.574350,0.887866,-89.629120,0.089810,0.000000
69.460007,47.598885,-89.673599,-0.000694,0.003509,0.089125,211.730408,10.786062,0.891248,-89.673599,0.090226,0.000000
69.710007,48.583435,-89.673599,-0.000677,0.003527,0.089593,216.109909,11.009164,0.895931,-89.673599,0.090642,0.000000
69.960007,49.431702,-89.673599,-0.000686,0.003543,0.089992,219.883194,11.201384,0.899920,-89.673599,0.091059,0.000000
70.210007,50.287041,-89.718079,-0.000673,0.003555,0.090304,223.687927,11.395206,0.903042,-89.718079,0.091475,0.000000
70.460007,51.782120,-89.718079,-0.000668,0.003579,0.090894,230.338379,11.733996,0.908939,-89.718079,0.091891,0.000000
70.710007,52.658684,-89.718079,-0.000655,0.003590,0.091197,234.237518,11.932628,0.911975,-89.718079,0.092308,0.000000
70.960007,54.051727,-89.718079,-0.000642,0.003610,0.091692,240.434097,12.248297,0.916918,-89.718079,0.092724,0.000000
71.210007,55.090645,-89.807037,-0.000651,0.003627,0.092117,245.055420,12.483719,0.921167,-89.807037,0.093140,0.000000
71.460007,56.502686,-89.807037,-0.000629,0.003645,0.092594,251.336502,12.803692,0.925937,-89.807037,0.093556,0.000000
71.710007,57.515533,-89.851524,-0.000634,0.003663,0.093036,255.841873,13.033206,0.930360,-89.851524,0.093973,0.000000
71.960007,58.223045,-89.896004,-0.000621,0.003674,0.093322,258.989044,13.193531,0.933222,-89.896004,0.094389,0.000000
72.210007,59.050827,-89.851524,-0.000608,0.003689,0.093695,262.671204,13.381109,0.936951,-89.851524,0.094805,0.000000
72.460007,60.566757,-89.940483,-0.000586,0.003707,0.094163,269.414398,13.724623,0.941634,-89.940483,0.095230,0.000000
72.710007,61.658928,-89.851524,-0.000569,0.003721,0.094519,274.272614,13.972113,0.945189,-89.851524,0.095646,0.000000
72.960007,63.191605,-89.940483,-0.000569,0.003743,0.095083,281.090302,14.319423,0.950826,-89.940483,0.096063,0.000000
73.210007,64.223083,-89.984962,-0.000565,0.003756,0.095403,285.678558,14.553159,0.954035,-89.984962,0.096479,0.000000
73.460007,64.933563,-89.984962,-0.000565,0.003767,0.095690,288.838928,14.714156,0.956897,-89.984962,0.096895,0.000000
73.710007,66.621536,-89.984962,-0.000552,0.003790,0.096262,296.347382,15.096657,0.962621,-89.984962,0.097311,0.000000
73.960007,67.666031,-89.984962,-0.000539,0.003792,0.096305,300.993530,15.333342,0.963054,-89.984962,0.096635,0.000000
74.210007,67.089600,-90.073929,-0.000526,0.003792,0.096305,298.429443,15.202721,0.963054,-90.073929,0.096635,0.000000
74.460007,66.586533,-90.118408,-0.000526,0.003791,0.096279,296.191681,15.088723,0.962794,-90.118408,0.096305,0.000000
74.710007,66.156815,-90.162888,-0.000543,0.003790,0.096271,294.280212,14.991348,0.962707,-90.162888,0.096305,0.000000
74.960007,65.784805,-90.118408,-0.000535,0.003790,0.096262,292.625427,14.907050,0.962621,-90.118408,0.096305,0.000000
75.210007,65.429947,-90.118408,-0.000530,0.003790,0.096253,291.046936,14.826638,0.962534,-90.118408,0.096305,0.000000
75.460007,65.184174,-90.162888,-0.000548,0.003790,0.096253,289.953674,14.770945,0.962534,-90.162888,0.096305,0.000000
75.710007,64.923141,-90.207367,-0.000535,0.003790,0.096253,288.792542,14.711794,0.962534,-90.207367,0.096305,0.000000
75.960007,64.703064,-90.251846,-0.000526,0.003789,0.096245,287.813599,14.661924,0.962447,-90.251846,0.096305,0.000000
76.210007,64.482620,-90.207367,-0.000535,0.003789,0.096245,286.833008,14.611971,0.962447,-90.207367,0.096305,0.000000
76.460007,64.287872,-90.251846,-0.000539,0.003789,0.096245,285.966736,14.567840,0.962447,-90.251846,0.096305,0.000000
76.710007,64.128128,-90.251846,-0.000539,0.003789,0.096245,285.256165,14.531641,0.962447,-90.251846,0.096305,0.000000
76.960007,63.984024,-90.340813,-0.000513,0.003789,0.096245,284.615143,14.498987,0.962447,-90.340813,0.096305,0.000000
77.210007,63.807892,-90.296333,-0.000492,0.003789,0.096245,283.831665,14.459075,0.962447,-90.296333,0.096305,0.000000
77.460007,63.654846,-90.429771,-0.000492,0.003789,0.096245,283.150909,14.424395,0.962447,-90.429771,0.096305,0.000000
77.710007,63.537918,-90.385292,-0.000496,0.003789,0.096245,282.630768,14.397899,0.962447,-90.385292,0.096305,0.000000
77.960007,63.429184,-90.385292,-0.000496,0.003789,0.096245,282.147095,14.373259,0.962447,-90.385292,0.096305,0.000000
78.210007,63.299973,-90.385292,-0.000487,0.003789,0.096245,281.572327,14.343979,0.962447,-90.385292,0.096305,0.000000
78.460007,63.200546,-90.429771,-0.000496,0.003789,0.096245,281.130066,14.321449,0.962447,-90.429771,0.096305,0.000000
78.710007,63.085480,-90.429771,-0.000492,0.003789,0.096245,280.618225,14.295374,0.962447,-90.429771,0.096305,0.000000
78.960007,62.994255,-90.518738,-0.000492,0.003789,0.096245,280.212433,14.274702,0.962447,-90.518738,0.096305,0.000000
79.210007,62.904137,-90.518738,-0.000487,0.003789,0.096245,279.811584,14.254281,0.962447,-90.518738,0.096305,0.000000
79.460007,62.812164,-90.518738,-0.000492,0.003789,0.096245,279.402466,14.233440,0.962447,-90.518738,0.096305,0.000000
79.710007,62.731728,-90.563217,-0.000483,0.003789,0.096245,279.044647,14.215213,0.962447,-90.563217,0.096305,0.000000
79.960007,62.645340,-90.607697,-0.000487,0.003789,0.096245,278.660400,14.195637,0.962447,-90.607697,0.096305,0.000000
80.210007,62.562302,-90.607697,-0.000492,0.003789,0.096245,278.291016,14.176820,0.962447,-90.607697,0.096305,0.000000
80.460007,62.488945,-90.652176,-0.000492,0.003789,0.096245,277.964722,14.160197,0.962447,-90.652176,0.096305,0.000000
80.710007,62.426758,-90.652176,-0.000496,0.003789,0.096245,277.688080,14.146106,0.962447,-90.652176,0.096305,0.000000
80.960007,62.362709,-90.741142,-0.000496,0.003789,0.096236,277.403198,14.131592,0.962360,-90.741142,0.096305,0.000000
81.210007,62.278923,-90.696663,-0.000496,0.003789,0.096236,277.030487,14.112605,0.962360,-90.696663,0.096305,0.000000
81.460007,62.219345,-90.741142,-0.000487,0.003789,0.096236,276.765472,14.099105,0.962360,-90.741142,0.096305,0.000000
81.710007,62.173172,-90.741142,-0.000492,0.003789,0.096236,276.560089,14.088642,0.962360,-90.741142,0.096305,0.000000
81.960007,62.115082,-90.741142,-0.000487,0.003789,0.096236,276.301697,14.075479,0.962360,-90.741142,0.096305,0.000000
82.210007,62.047684,-90.785622,-0.000487,0.003789,0.096236,276.001892,14.060205,0.962360,-90.785622,0.096305,0.000000
82.460007,61.988846,-90.785622,-0.000487,0.003789,0.096236,275.740143,14.046873,0.962360,-90.785622,0.096305,0.000000
82.710007,61.934105,-90.874580,-0.000483,0.003789,0.096236,275.496643,14.034469,0.962360,-90.874580,0.096305,0.000000
82.960007,61.877136,-90.830101,-0.000487,0.003789,0.096236,275.243256,14.021560,0.962360,-90.830101,0.096305,0.000000
83.210007,61.841385,-90.874580,-0.000496,0.003789,0.096236,275.084229,14.013458,0.962360,-90.874580,0.096305,0.000000
83.460007,61.782181,-90.919067,-0.000496,0.003789,0.096236,274.820862,14.000042,0.962360,-90.919067,0.096305,0.000000
83.710007,61.720741,-90.963547,-0.000500,0.003789,0.096236,274.547577,13.986119,0.962360,-90.963547,0.096305,0.000000
83.960007,61.687973,-90.963547,-0.000496,0.003789,0.096236,274.401794,13.978694,0.962360,-90.963547,0.096305,0.000000
84.210007,61.636581,-90.963547,-0.000492,0.003789,0.096236,274.173218,13.967049,0.962360,-90.963547,0.096305,0.000000
84.460007,61.603813,-90.963547,-0.000496,0.003789,0.096236,274.027435,13.959623,0.962360,-90.963547,0.096305,0.000000
84.710007,61.550568,-91.008026,-0.000492,0.003789,0.096236,273.790588,13.947558,0.962360,-91.008026,0.096305,0.000000
84.960007,61.502159,-91.008026,-0.000496,0.003789,0.096236,273.575256,13.936588,0.962360,-91.008026,0.096305,0.000000
85.210007,61.468643,-91.008026,-0.000487,0.003789,0.096236,273.426178,13.928993,0.962360,-91.008026,0.096305,0.000000
85.460007,61.448532,-91.052505,-0.000487,0.003789,0.096236,273.336731,13.924437,0.962360,-91.052505,0.096305,0.000000
85.710007,61.402359,-91.052505,-0.000487,0.003789,0.096236,273.131348,13.913974,0.962360,-91.052505,0.096305,0.000000
85.960007,61.350601,-91.052505,-0.000487,0.003789,0.096236,272.901093,13.902245,0.962360,-91.052505,0.096305,0.000000
86.210007,61.302567,-91.096985,-0.000496,0.003789,0.096236,272.687439,13.891360,0.962360,-91.096985,0.096305,0.000000
86.460007,61.274261,-91.096985,-0.000487,0.003789,0.096236,272.561523,13.884946,0.962360,-91.096985,0.096305,0.000000
86.710007,61.245216,-91.096985,-0.000492,0.003789,0.096236,272.432343,13.878365,0.962360,-91.096985,0.096305,0.000000
86.960007,61.210587,-91.141472,-0.000487,0.003789,0.096236,272.278290,13.870517,0.962360,-91.141472,0.096305,0.000000
87.210007,61.151009,-91.230431,-0.000496,0.003789,0.096236,272.013275,13.857017,0.962360,-91.230431,0.096305,0.000000
87.460007,61.144302,-91.141472,-0.000487,0.003789,0.096236,271.983429,13.855496,0.962360,-91.141472,0.096305,0.000000
87.710007,61.110794,-91.185951,-0.000492,0.003789,0.096236,271.834381,13.847903,0.962360,-91.185951,0.096305,0.000000
87.960007,61.078766,-91.230431,-0.000483,0.003789,0.096236,271.691925,13.840646,0.962360,-91.230431,0.096305,0.000000
88.210007,61.040413,-91.274910,-0.000496,0.003789,0.096236,271.521332,13.831956,0.962360,-91.274910,0.096305,0.000000
88.460007,60.996475,-91.274910,-0.000500,0.003789,0.096236,271.325867,13.822000,0.962360,-91.274910,0.096305,0.000000
88.710007,60.977852,-91.319389,-0.000492,0.003789,0.096236,271.243042,13.817779,0.962360,-91.319389,0.096305,0.000000
88.960007,60.956627,-91.319389,-0.000496,0.003789,0.096236,271.148621,13.812969,0.962360,-91.319389,0.096305,0.000000
89.210007,60.933914,-91.363876,-0.000487,0.003789,0.096236,271.047577,13.807822,0.962360,-91.363876,0.096305,0.000000
89.460007,60.894447,-91.319389,-0.000496,0.003789,0.096236,270.872040,13.798879,0.962360,-91.319389,0.096305,0.000000
89.710007,60.859810,-91.319389,-0.000500,0.003789,0.096236,270.717957,13.791030,0.962360,-91.319389,0.096305,0.000000
89.960007,60.845665,-91.363876,-0.000487,0.003789,0.096236,270.655029,13.787825,0.962360,-91.363876,0.096305,0.000000
90.210007,60.825180,-91.452835,-0.000496,0.003789,0.096236,270.563904,13.783182,0.962360,-91.452835,0.096305,0.000000
90.460007,60.788689,-91.452835,-0.000487,0.003789,0.096236,270.401581,13.774914,0.962360,-91.452835,0.096305,0.000000
90.710007,60.760017,-91.497314,-0.000483,0.003789,0.096236,270.274048,13.768416,0.962360,-91.497314,0.096305,0.000000
90.960007,60.722038,-91.497314,-0.000487,0.003789,0.096236,270.105103,13.759810,0.962360,-91.497314,0.096305,0.000000
91.210007,60.756294,-91.497314,-0.000487,0.003789,0.096236,270.257507,13.767573,0.962360,-91.497314,0.096305,0.000000
91.460007,60.678093,-91.541794,-0.000500,0.003789,0.096236,269.909637,13.749852,0.962360,-91.541794,0.096305,0.000000
91.710007,60.667671,-91.586281,-0.000492,0.003789,0.096236,269.863281,13.747491,0.962360,-91.586281,0.096305,0.000000
91.960007,60.631180,-91.586281,-0.000487,0.003789,0.096236,269.700958,13.739223,0.962360,-91.586281,0.096305,0.000000
92.210007,60.602501,-91.586281,-0.000483,0.003789,0.096236,269.573395,13.732723,0.962360,-91.586281,0.096305,0.000000
92.460007,60.597664,-91.675240,-0.000492,0.003789,0.096236,269.551880,13.731627,0.962360,-91.675240,0.096305,0.000000
92.710007,60.557449,-91.675240,-0.000479,0.003789,0.096236,269.372986,13.722514,0.962360,-91.675240,0.096305,0.000000
92.960007,60.514999,-91.675240,-0.000487,0.003789,0.096236,269.184174,13.712894,0.962360,-91.675240,0.096305,0.000000
93.210007,60.507545,-91.675240,-0.000496,0.003789,0.096236,269.151001,13.711205,0.962360,-91.675240,0.096305,0.000000
93.460007,60.483719,-91.630760,-0.000492,0.003789,0.096236,269.045013,13.705807,0.962360,-91.630760,0.096305,0.000000
93.710007,60.482971,-91.764198,-0.000483,0.003789,0.096236,269.041687,13.705638,0.962360,-91.764198,0.096305,0.000000
93.960007,60.434563,-91.764198,-0.000479,0.003789,0.096236,268.826355,13.694668,0.962360,-91.764198,0.096305,0.000000
94.210007,60.407005,-91.764198,-0.000492,0.003789,0.096236,268.703766,13.688423,0.962360,-91.764198,0.096305,0.000000
94.460007,60.408501,-91.808685,-0.000483,0.003789,0.096236,268.710419,13.688762,0.962360,-91.808685,0.096305,0.000000
94.710007,60.381317,-91.808685,-0.000479,0.003789,0.096236,268.589508,13.682602,0.962360,-91.808685,0.096305,0.000000
94.960007,60.364555,-91.853165,-0.000496,0.003789,0.096236,268.514954,13.678803,0.962360,-91.853165,0.096305,0.000000
95.210007,60.336632,-91.808685,-0.000483,0.003789,0.096236,268.390747,13.672476,0.962360,-91.808685,0.096305,0.000000
95.460007,60.303116,-91.897644,-0.000487,0.003789,0.096236,268.241669,13.664882,0.962360,-91.897644,0.096305,0.000000
95.710007,60.290459,-91.897644,-0.000479,0.003789,0.096236,268.185364,13.662013,0.962360,-91.897644,0.096305,0.000000
95.960007,60.281891,-91.897644,-0.000487,0.003789,0.096236,268.147247,13.660072,0.962360,-91.897644,0.096305,0.000000
96.210007,60.252846,-92.031090,-0.000496,0.003789,0.096236,268.018036,13.653490,0.962360,-92.031090,0.096305,0.000000
96.460007,60.231247,-91.986610,-0.000487,0.003789,0.096236,267.921967,13.648596,0.962360,-91.986610,0.096305,0.000000
96.710007,60.226410,-91.986610,-0.000487,0.003789,0.096236,267.900452,13.647499,0.962360,-91.986610,0.096305,0.000000
96.960007,60.202576,-91.986610,-0.000483,0.003789,0.096236,267.794434,13.642098,0.962360,-91.986610,0.096305,0.000000
97.210007,60.184700,-92.031090,-0.000496,0.003789,0.096236,267.714905,13.638048,0.962360,-92.031090,0.096305,0.000000
97.460007,60.145973,-92.031090,-0.000483,0.003789,0.096236,267.542664,13.629272,0.962360,-92.031090,0.096305,0.000000
97.710007,60.139275,-92.075569,-0.000483,0.003789,0.096236,267.512848,13.627755,0.962360,-92.075569,0.096305,0.000000
97.960007,60.122147,-92.120049,-0.000487,0.003789,0.096236,267.436676,13.623873,0.962360,-92.120049,0.096305,0.000000
98.210007,60.115067,-92.164528,-0.000479,0.003789,0.096236,267.405182,13.622269,0.962360,-92.164528,0.096305,0.000000
98.460007,60.079323,-92.164528,-0.000483,0.003789,0.096236,267.246185,13.614169,0.962360,-92.164528,0.096305,0.000000
98.710007,60.066284,-92.164528,-0.000487,0.003789,0.096236,267.188171,13.611215,0.962360,-92.164528,0.096305,0.000000
98.960007,60.062195,-92.209015,-0.000483,0.003789,0.096236,267.169983,13.610288,0.962360,-92.209015,0.096305,0.000000
99.210007,60.041710,-92.209015,-0.000479,0.003789,0.096236,267.078857,13.605646,0.962360,-92.209015,0.096305,0.000000
99.460007,60.020485,-92.209015,-0.000483,0.003789,0.096236,266.984436,13.600837,0.962360,-92.209015,0.096305,0.000000
99.710007,59.993675,-92.253494,-0.000483,0.003789,0.096236,266.865204,13.594761,0.962360,-92.253494,0.096305,0.000000
99.960007,60.002983,-92.209015,-0.000496,0.003789,0.096236,266.906586,13.596870,0.962360,-92.209015,0.096305,0.000000
100.210007,59.974312,-92.297974,-0.000487,0.003789,0.096236,266.779053,13.590373,0.962360,-92.297974,0.096305,0.000000
100.460007,59.951599,-92.297974,-0.000483,0.003789,0.096236,266.678040,13.585227,0.962360,-92.297974,0.096305,0.000000
100.710007,59.948990,-92.386932,-0.000483,0.003789,0.096236,266.666412,13.584635,0.962360,-92.386932,0.096305,0.000000
100.960007,59.926651,-92.342453,-0.000492,0.003789,0.096236,266.567047,13.579573,0.962360,-92.342453,0.096305,0.000000
101.210007,59.922180,-92.431419,-0.000487,0.003789,0.096236,266.547180,13.578560,0.962360,-92.431419,0.096305,0.000000
101.460007,59.890526,-92.386932,-0.000487,0.003789,0.096236,266.406372,13.571387,0.962360,-92.386932,0.096305,0.000000
101.710007,59.868187,-92.431419,-0.000479,0.003789,0.096236,266.307007,13.566324,0.962360,-92.431419,0.096305,0.000000
101.960007,59.868187,-92.475899,-0.000492,0.003789,0.096236,266.307007,13.566324,0.962360,-92.475899,0.096305,0.000000
102.210007,59.851799,-92.475899,-0.000487,0.003789,0.096236,266.234100,13.562612,0.962360,-92.475899,0.096305,0.000000
102.460007,59.834671,-92.520378,-0.000479,0.003789,0.096236,266.157898,13.558731,0.962360,-92.520378,0.096305,0.000000
102.710007,59.816422,-92.564857,-0.000487,0.003789,0.096236,266.076721,13.554595,0.962360,-92.564857,0.096305,0.000000
102.960007,59.802277,-92.520378,-0.000487,0.003789,0.096236,266.013824,13.551390,0.962360,-92.520378,0.096305,0.000000
103.210007,59.810471,-92.564857,-0.000483,0.003789,0.096236,266.050262,13.553246,0.962360,-92.564857,0.096305,0.000000
103.460007,59.782166,-92.609337,-0.000487,0.003789,0.096236,265.924347,13.546832,0.962360,-92.609337,0.096305,0.000000
103.710007,59.756844,-92.609337,-0.000487,0.003789,0.096236,265.811707,13.541094,0.962360,-92.609337,0.096305,0.000000
103.960007,59.751259,-92.698303,-0.000492,0.003789,0.096236,265.786865,13.539828,0.962360,-92.698303,0.096305,0.000000
104.210007,59.734131,-92.609337,-0.000483,0.003789,0.096236,265.710693,13.535948,0.962360,-92.609337,0.096305,0.000000
104.400002,59.737106,-92.609337,-0.000483,0.003789,0.096236,265.723907,13.536622,0.962360,-92.609337,0.096305,0.000000