File: Data/compression 11/AutoNoHeating-10-11-2-240529_05292024_160237.csv
Time (sec),S:Load (lbs),S:HL1 (DIM),S:LVDT (in),S:Position (in),Ch:Position (mm),Ch:Load (N),Ch:Stress (MPa),Ch:Strain (mm/mm),Ch:HL1 (DIM),Set Point (),Cycles ()
0.110000,0.004471,-1298.888306,-0.010442,-0.006878,-0.174711,0.019887,0.001013,-1.747113,-1298.888306,-0.174529,0.000000
0.350000,0.012291,-1298.843750,-0.010442,-0.006878,-0.174711,0.054673,0.002785,-1.747113,-1298.843750,-0.174425,0.000000
0.590000,0.006706,-1298.843750,-0.010451,-0.006749,-0.171425,0.029831,0.001520,-1.714245,-1298.843750,-0.170419,0.000000
0.830000,0.039474,-1298.843750,-0.010335,-0.006600,-0.167635,0.175591,0.008945,-1.676349,-1298.843750,-0.166429,0.000000
1.070000,0.010429,-1298.843750,-0.010175,-0.006437,-0.163507,0.046392,0.002363,-1.635069,-1298.843750,-0.162423,0.000000
1.310000,-0.043938,-1298.888306,-0.010011,-0.006279,-0.159474,-0.195445,-0.009956,-1.594743,-1298.888306,-0.158434,0.000000
1.550000,-0.004097,-1298.799316,-0.009873,-0.006127,-0.155615,-0.018224,-0.000928,-1.556150,-1298.799316,-0.154427,0.000000
1.790000,0.049156,-1298.888306,-0.009722,-0.005968,-0.151582,0.218658,0.011139,-1.515824,-1298.888306,-0.150438,0.000000
2.030000,0.059204,-1298.799316,-0.009554,-0.005811,-0.147602,0.263353,0.013416,-1.476018,-1298.799316,-0.146431,0.000000
2.270000,0.044312,-1298.843750,-0.009403,-0.005652,-0.143552,0.197107,0.010041,-1.435520,-1298.843750,-0.142442,0.000000
2.510000,0.048782,-1298.888306,-0.009253,-0.005496,-0.139606,0.216995,0.011054,-1.396060,-1298.888306,-0.138435,0.000000
2.750000,0.026436,-1298.799316,-0.009080,-0.005337,-0.135547,0.117593,0.005990,-1.355475,-1298.799316,-0.134446,0.000000
2.990000,0.036865,-1298.799316,-0.008925,-0.005187,-0.131749,0.163985,0.008354,-1.317490,-1298.799316,-0.130440,0.000000
3.230000,0.014526,-1298.799316,-0.008752,-0.005019,-0.127474,0.064617,0.003292,-1.274736,-1298.799316,-0.126450,0.000000
3.470000,-0.042824,-1298.843750,-0.008601,-0.004863,-0.123528,-0.190490,-0.009704,-1.235276,-1298.843750,-0.122444,0.000000
3.710000,0.039101,-1298.843750,-0.008446,-0.004709,-0.119599,0.173928,0.008860,-1.195991,-1298.843750,-0.118455,0.000000
3.950000,0.060326,-1298.754761,-0.008291,-0.004555,-0.115697,0.268342,0.013670,-1.156967,-1298.754761,-0.114448,0.000000
4.190000,0.043938,-1298.799316,-0.008127,-0.004389,-0.111491,0.195445,0.009956,-1.114907,-1298.799316,-0.110459,0.000000
4.430000,0.024948,-1298.799316,-0.007959,-0.004234,-0.107536,0.110975,0.005653,-1.075361,-1298.799316,-0.106452,0.000000
4.670000,0.046173,-1298.799316,-0.007804,-0.004073,-0.103460,0.205388,0.010463,-1.034601,-1298.799316,-0.102463,0.000000
4.910000,0.045059,-1298.888306,-0.007666,-0.003925,-0.099688,0.200433,0.010211,-0.996877,-1298.888306,-0.098456,0.000000
5.150000,0.030533,-1298.799316,-0.007489,-0.003762,-0.095551,0.135817,0.006919,-0.955510,-1298.799316,-0.094467,0.000000
5.390000,-0.032021,-1298.888306,-0.007312,-0.003603,-0.091518,-0.142435,-0.007256,-0.915184,-1298.888306,-0.090460,0.000000
5.630000,0.017502,-1298.799316,-0.007166,-0.003449,-0.087599,0.077852,0.003966,-0.875986,-1298.799316,-0.086454,0.000000
5.870000,0.060326,-1298.843750,-0.007011,-0.003294,-0.083670,0.268342,0.013670,-0.836700,-1298.843750,-0.082465,0.000000
6.110000,0.056976,-1298.843750,-0.006851,-0.003132,-0.079559,0.253443,0.012911,-0.795594,-1298.843750,-0.078458,0.000000
6.350000,0.028671,-1298.799316,-0.006687,-0.002975,-0.075561,0.127536,0.006497,-0.755615,-1298.799316,-0.074469,0.000000
6.590000,0.046921,-1298.843750,-0.006510,-0.002811,-0.071390,0.208714,0.010632,-0.713901,-1298.843750,-0.070462,0.000000
6.830000,0.064049,-1298.754761,-0.006364,-0.002659,-0.067548,0.284903,0.014514,-0.675483,-1298.754761,-0.066473,0.000000
7.070000,0.044312,-1298.888306,-0.006213,-0.002502,-0.063542,0.197107,0.010041,-0.635418,-1298.888306,-0.062466,0.000000
7.310000,0.027557,-1298.888306,-0.006049,-0.002342,-0.059474,0.122581,0.006245,-0.594743,-1298.888306,-0.058477,0.000000
7.550000,0.002983,-1298.799316,-0.005907,-0.002188,-0.055581,0.013269,0.000676,-0.555806,-1298.799316,-0.054471,0.000000
7.790000,0.031281,-1298.888306,-0.005734,-0.002031,-0.051591,0.139143,0.007088,-0.515913,-1298.888306,-0.050481,0.000000
8.030001,0.070747,-1298.799316,-0.005583,-0.001875,-0.047628,0.314700,0.016032,-0.476282,-1298.799316,-0.046475,0.000000
8.270000,0.054741,-1298.843750,-0.005420,-0.001713,-0.043517,0.243500,0.012404,-0.435174,-1298.843750,-0.042485,0.000000
8.510000,0.036118,-1298.843750,-0.005269,-0.001561,-0.039658,0.160659,0.008184,-0.396583,-1298.843750,-0.038479,0.000000
8.750000,0.069633,-1298.754761,-0.005101,-0.001394,-0.035400,0.309745,0.015779,-0.354003,-1298.754761,-0.034490,0.000000
8.990001,0.076340,-1298.888306,-0.004937,-0.001248,-0.031697,0.339576,0.017299,-0.316972,-1298.888306,-0.030483,0.000000
9.230000,0.046921,-1298.754761,-0.004786,-0.001080,-0.027439,0.208714,0.010632,-0.274392,-1298.754761,-0.026494,0.000000
9.470000,0.004097,-1298.888306,-0.004626,-0.000928,-0.023580,0.018224,0.000928,-0.235799,-1298.888306,-0.022487,0.000000
9.710000,0.033516,-1298.799316,-0.004467,-0.000768,-0.019513,0.149086,0.007595,-0.195126,-1298.799316,-0.018498,0.000000
9.950001,0.057716,-1298.843750,-0.004324,-0.000621,-0.015766,0.256735,0.013079,-0.157662,-1298.843750,-0.014491,0.000000
10.190001,0.072617,-1298.843750,-0.004161,-0.000453,-0.011508,0.323015,0.016455,-0.115082,-1298.843750,-0.010485,0.000000
10.430000,0.051018,-1298.799316,-0.003992,-0.000299,-0.007588,0.226938,0.011561,-0.075883,-1298.799316,-0.006496,0.000000
10.670000,0.072617,-1298.932739,-0.003833,-0.000134,-0.003408,0.323015,0.016455,-0.034083,-1298.932739,-0.002489,0.000000
10.910001,0.269226,-1298.843750,-0.003665,0.000018,0.000451,1.197577,0.061007,0.004510,-1298.843750,0.001500,0.000000
11.150001,0.663193,-1298.799316,-0.003535,0.000174,0.004423,2.950029,0.150282,0.044228,-1298.799316,0.005507,0.000000
11.390000,0.617767,-1298.888306,-0.003488,-0.000000,-0.000009,2.747966,0.139988,-0.000085,-1298.888306,0.000165,0.000000
11.630000,0.598030,-1298.799316,-0.003492,-0.000000,-0.000009,2.660171,0.135516,-0.000085,-1298.799316,0.000165,0.000000
11.870001,0.571220,-1298.888306,-0.003488,-0.000000,-0.000009,2.540915,0.129440,-0.000085,-1298.888306,0.000468,0.000000
12.110001,0.591331,-1298.843750,-0.003484,-0.000000,-0.000009,2.630374,0.133998,-0.000085,-1298.843750,0.000867,0.000000
12.350000,0.581650,-1298.843750,-0.003497,-0.000000,-0.000000,2.587307,0.131804,-0.000000,-1298.843750,0.001275,0.000000
12.590000,0.683678,-1298.843750,-0.003484,0.000032,0.000815,3.041150,0.154924,0.008153,-1298.843750,0.001674,0.000000
12.830001,0.709000,-1298.932739,-0.003484,0.000043,0.001101,3.153788,0.160662,0.011014,-1298.932739,0.002073,0.000000
13.070001,0.776024,-1298.888306,-0.003458,0.000061,0.001561,3.451926,0.175850,0.015611,-1298.888306,0.002472,0.000000
13.310000,0.810654,-1298.888306,-0.003441,0.000077,0.001960,3.605968,0.183697,0.019600,-1298.888306,0.002871,0.000000
13.550000,0.838211,-1298.888306,-0.003436,0.000089,0.002255,3.728549,0.189941,0.022549,-1298.888306,0.003270,0.000000
13.790001,0.895554,-1298.888306,-0.003410,0.000104,0.002636,3.983621,0.202935,0.026364,-1298.888306,0.003669,0.000000
14.030001,0.955139,-1298.888306,-0.003393,0.000130,0.003296,4.248671,0.216438,0.032955,-1298.888306,0.004067,0.000000
14.270000,0.985672,-1298.888306,-0.003376,0.000144,0.003660,4.384488,0.223356,0.036598,-1298.888306,0.004475,0.000000
14.510000,0.989395,-1298.799316,-0.003359,0.000157,0.003998,4.401050,0.224200,0.039980,-1298.799316,0.004874,0.000000
14.750001,1.031845,-1298.888306,-0.003363,0.000170,0.004319,4.589876,0.233819,0.043189,-1298.888306,0.005273,0.000000
14.990001,1.085838,-1298.977173,-0.003341,0.000189,0.004796,4.830050,0.246054,0.047958,-1298.977173,0.005672,0.000000
15.230000,1.130150,-1298.843750,-0.003316,0.000205,0.005212,5.027158,0.256096,0.052122,-1298.843750,0.006071,0.000000
15.470000,1.143555,-1298.932739,-0.003307,0.000216,0.005490,5.086785,0.259133,0.054896,-1298.932739,0.006470,0.000000
15.710001,1.171112,-1298.843750,-0.003294,0.000228,0.005793,5.209367,0.265378,0.057932,-1298.843750,0.006868,0.000000
15.950001,1.225105,-1298.977173,-0.003285,0.000253,0.006435,5.449541,0.277613,0.064349,-1298.977173,0.007267,0.000000
16.190001,1.246704,-1298.888306,-0.003255,0.000268,0.006808,5.545617,0.282507,0.068077,-1298.888306,0.007675,0.000000
16.430000,1.243721,-1298.799316,-0.003247,0.000283,0.007189,5.532347,0.281831,0.071894,-1298.799316,0.008074,0.000000
16.670000,1.264580,-1298.888306,-0.003216,0.000297,0.007554,5.625132,0.286558,0.075535,-1298.888306,0.008473,0.000000
16.910002,1.320061,-1298.843750,-0.003216,0.000314,0.007979,5.871923,0.299130,0.079786,-1298.843750,0.008872,0.000000
17.150002,1.356552,-1298.888306,-0.003195,0.000332,0.008430,6.034245,0.307399,0.084295,-1298.888306,0.009271,0.000000
17.390001,1.353203,-1298.888306,-0.003173,0.000343,0.008707,6.019347,0.306640,0.087070,-1298.888306,0.009670,0.000000
17.630001,1.391182,-1298.888306,-0.003169,0.000360,0.009132,6.188286,0.315246,0.091320,-1298.888306,0.010069,0.000000
17.870001,1.419113,-1298.888306,-0.003143,0.000380,0.009652,6.312531,0.321576,0.096522,-1298.888306,0.010468,0.000000
18.110001,1.433632,-1298.843750,-0.003134,0.000395,0.010034,6.377113,0.324866,0.100339,-1298.843750,0.010875,0.000000
18.350000,1.424698,-1298.932739,-0.003122,0.000411,0.010433,6.337373,0.322841,0.104329,-1298.932739,0.011274,0.000000
18.590000,1.439217,-1298.888306,-0.003100,0.000423,0.010745,6.401955,0.326131,0.107449,-1298.888306,0.011673,0.000000
18.830002,1.493958,-1298.843750,-0.003096,0.000440,0.011187,6.645455,0.338536,0.111872,-1298.843750,0.012072,0.000000
19.070002,1.550186,-1298.888306,-0.003065,0.000457,0.011612,6.895572,0.351277,0.116122,-1298.888306,0.012471,0.000000
19.310001,1.531570,-1298.888306,-0.003057,0.000468,0.011890,6.812766,0.347059,0.118897,-1298.888306,0.012870,0.000000
19.550001,1.566574,-1298.977173,-0.003048,0.000480,0.012193,6.968470,0.354991,0.121932,-1298.977173,0.013269,0.000000
19.790001,1.633598,-1298.888306,-0.003014,0.000506,0.012861,7.266608,0.370179,0.128611,-1298.888306,0.013668,0.000000
20.030001,1.634712,-1298.888306,-0.003014,0.000521,0.013234,7.271563,0.370431,0.132339,-1298.888306,0.014075,0.000000
20.270000,1.618332,-1298.977173,-0.002988,0.000538,0.013659,7.198700,0.366719,0.136589,-1298.977173,0.014474,0.000000
20.510000,1.636208,-1298.799316,-0.002975,0.000552,0.014032,7.278215,0.370770,0.140317,-1298.799316,0.014873,0.000000
20.750002,1.639931,-1298.888306,-0.002971,0.000565,0.014361,7.294776,0.371614,0.143614,-1298.888306,0.015272,0.000000
20.990002,1.726318,-1298.888306,-0.002953,0.000581,0.014760,7.679048,0.391189,0.147603,-1298.888306,0.015671,0.000000
21.230001,1.728554,-1298.888306,-0.002928,0.000595,0.015107,7.688991,0.391696,0.151072,-1298.888306,0.016070,0.000000
21.470001,1.749405,-1298.977173,-0.002915,0.000608,0.015437,7.781742,0.396421,0.154367,-1298.977173,0.016469,0.000000
21.710001,1.819038,-1298.888306,-0.002897,0.000631,0.016035,8.091487,0.412200,0.160351,-1298.888306,0.016868,0.000000
21.950001,1.832443,-1298.932739,-0.002884,0.000648,0.016469,8.151114,0.415238,0.164686,-1298.932739,0.017275,0.000000
22.190001,1.809731,-1298.888306,-0.002854,0.000664,0.016859,8.050083,0.410091,0.168589,-1298.888306,0.017674,0.000000
22.430000,1.856277,-1298.932739,-0.002863,0.000676,0.017180,8.257134,0.420639,0.171798,-1298.932739,0.018073,0.000000
22.670002,1.865959,-1298.932739,-0.002837,0.000691,0.017561,8.300200,0.422832,0.175613,-1298.932739,0.018472,0.000000
22.910002,1.934845,-1298.843750,-0.002815,0.000708,0.017978,8.606620,0.438442,0.179777,-1298.843750,0.018871,0.000000
23.150002,1.964638,-1298.932739,-0.002790,0.000722,0.018342,8.739145,0.445193,0.183420,-1298.932739,0.019270,0.000000
23.390001,2.027199,-1298.888306,-0.002785,0.000738,0.018749,9.017430,0.459370,0.187494,-1298.888306,0.019669,0.000000
23.630001,2.069275,-1298.932739,-0.002768,0.000760,0.019313,9.204595,0.468904,0.193132,-1298.932739,0.020076,0.000000
23.870001,2.047676,-1298.932739,-0.002742,0.000772,0.019599,9.108519,0.464010,0.195993,-1298.932739,0.020475,0.000000
24.110001,2.058105,-1298.932739,-0.002738,0.000787,0.019998,9.154910,0.466373,0.199982,-1298.932739,0.020874,0.000000
24.350000,2.070763,-1298.977173,-0.002729,0.000800,0.020319,9.211212,0.469242,0.203192,-1298.977173,0.021273,0.000000
24.590002,2.091614,-1298.888306,-0.002708,0.000816,0.020718,9.303963,0.473966,0.207181,-1298.888306,0.021672,0.000000
24.830002,2.180611,-1298.932739,-0.002686,0.000836,0.021247,9.699841,0.494133,0.212471,-1298.932739,0.022071,0.000000
25.070002,2.182846,-1298.932739,-0.002660,0.000847,0.021525,9.709785,0.494640,0.215247,-1298.932739,0.022470,0.000000
25.310001,2.198860,-1298.888306,-0.002673,0.000860,0.021845,9.781018,0.498269,0.218455,-1298.888306,0.022869,0.000000
25.550001,2.267746,-1298.932739,-0.002643,0.000880,0.022357,10.087438,0.513879,0.223572,-1298.932739,0.023276,0.000000
25.790001,2.302750,-1298.843750,-0.002630,0.000898,0.022817,10.243142,0.521811,0.228169,-1298.843750,0.023675,0.000000
26.030001,2.293816,-1298.932739,-0.002613,0.000915,0.023233,10.203402,0.519786,0.232330,-1298.932739,0.024074,0.000000
26.270000,2.315788,-1298.932739,-0.002587,0.000927,0.023537,10.301141,0.524765,0.235366,-1298.932739,0.024473,0.000000
26.510002,2.344086,-1298.932739,-0.002583,0.000942,0.023927,10.427014,0.531177,0.239268,-1298.932739,0.024872,0.000000
26.750002,2.434944,-1298.977173,-0.002565,0.000964,0.024482,10.831173,0.551766,0.244818,-1298.977173,0.025271,0.000000
26.990002,2.425262,-1298.888306,-0.002539,0.000974,0.024742,10.788106,0.549572,0.247420,-1298.888306,0.025670,0.000000
27.230001,2.497871,-1298.888306,-0.002535,0.000993,0.025210,11.111087,0.566026,0.252102,-1298.888306,0.026069,0.000000
27.470001,2.513145,-1298.843750,-0.002505,0.001008,0.025592,11.179029,0.569487,0.255919,-1298.843750,0.026476,0.000000
27.710001,2.557823,-1298.888306,-0.002505,0.001026,0.026060,11.377766,0.579611,0.260601,-1298.888306,0.026875,0.000000
27.950001,2.540695,-1298.888306,-0.002471,0.001041,0.026433,11.301577,0.575730,0.264331,-1298.888306,0.027274,0.000000
28.190001,2.533997,-1298.843750,-0.002453,0.001053,0.026745,11.271780,0.574212,0.267454,-1298.843750,0.027673,0.000000
28.430002,2.650177,-1298.932739,-0.002449,0.001075,0.027309,11.788576,0.600539,0.273090,-1298.932739,0.028072,0.000000
28.670002,2.706406,-1298.799316,-0.002423,0.001092,0.027743,12.038693,0.613280,0.277427,-1298.799316,0.028471,0.000000
28.910002,2.695976,-1298.888306,-0.002406,0.001104,0.028046,11.992301,0.610917,0.280461,-1298.888306,0.028870,0.000000
29.150002,2.736191,-1298.843750,-0.002397,0.001118,0.028393,12.171185,0.620030,0.283930,-1298.843750,0.029269,0.000000
29.390001,2.834503,-1298.799316,-0.002380,0.001140,0.028948,12.608500,0.642308,0.289480,-1298.799316,0.029677,0.000000
29.630001,2.829285,-1298.888306,-0.002363,0.001153,0.029286,12.585287,0.641125,0.292862,-1298.888306,0.030076,0.000000
29.870001,2.820351,-1298.843750,-0.002350,0.001166,0.029625,12.545547,0.639101,0.296246,-1298.843750,0.030474,0.000000
30.110001,2.844551,-1298.843750,-0.002337,0.001181,0.029997,12.653195,0.644585,0.299974,-1298.843750,0.030873,0.000000
30.350002,2.957756,-1298.888306,-0.002315,0.001202,0.030527,13.156756,0.670237,0.305265,-1298.888306,0.031272,0.000000
30.590002,3.007278,-1298.799316,-0.002302,0.001219,0.030951,13.377043,0.681459,0.309514,-1298.799316,0.031671,0.000000
30.830002,2.980843,-1298.843750,-0.002281,0.001231,0.031264,13.259450,0.675469,0.312636,-1298.843750,0.032070,0.000000
31.070002,3.043770,-1298.888306,-0.002281,0.001246,0.031636,13.539365,0.689728,0.316364,-1298.888306,0.032469,0.000000
31.310001,3.171127,-1298.843750,-0.002251,0.001267,0.032174,14.105879,0.718588,0.321741,-1298.843750,0.032877,0.000000
31.550001,3.156975,-1298.888306,-0.002242,0.001280,0.032521,14.042925,0.715381,0.325210,-1298.888306,0.033275,0.000000
31.790001,3.168144,-1298.754761,-0.002233,0.001292,0.032825,14.092609,0.717912,0.328245,-1298.754761,0.033674,0.000000
32.030003,3.205009,-1298.888306,-0.002216,0.001308,0.033232,14.256594,0.726265,0.332321,-1298.888306,0.034073,0.000000
32.270000,3.209854,-1298.843750,-0.002199,0.001320,0.033518,14.278144,0.727363,0.335183,-1298.843750,0.034472,0.000000
32.510002,3.327148,-1298.888306,-0.002186,0.001339,0.034021,14.799895,0.753943,0.340213,-1298.888306,0.034871,0.000000
32.750000,3.384125,-1298.799316,-0.002169,0.001356,0.034446,15.053339,0.766854,0.344463,-1298.799316,0.035270,0.000000
32.990002,3.378906,-1298.843750,-0.002156,0.001368,0.034741,15.030126,0.765671,0.347412,-1298.843750,0.035669,0.000000
33.230003,3.413910,-1298.888306,-0.002147,0.001384,0.035166,15.185830,0.773603,0.351660,-1298.888306,0.036077,0.000000
33.470001,3.552803,-1298.888306,-0.002113,0.001404,0.035669,15.803658,0.805077,0.356690,-1298.888306,0.036476,0.000000
33.710003,3.550201,-1298.843750,-0.002113,0.001417,0.035999,15.792085,0.804487,0.359987,-1298.843750,0.036875,0.000000
33.950001,3.587807,-1298.843750,-0.002091,0.001434,0.036424,15.959361,0.813009,0.364236,-1298.843750,0.037273,0.000000
34.190002,3.556900,-1298.843750,-0.002078,0.001446,0.036718,15.821881,0.806005,0.367184,-1298.843750,0.037672,0.000000
34.430000,3.706970,-1298.843750,-0.002057,0.001463,0.037161,16.489428,0.840011,0.371607,-1298.843750,0.038071,0.000000
34.670002,3.781815,-1298.843750,-0.002044,0.001480,0.037603,16.822351,0.856971,0.376029,-1298.843750,0.038470,0.000000
34.910000,3.719627,-1298.843750,-0.002026,0.001490,0.037854,16.545729,0.842880,0.378544,-1298.843750,0.038869,0.000000
35.150002,3.973961,-1298.843750,-0.002018,0.001515,0.038470,17.677061,0.900512,0.384702,-1298.843750,0.039277,0.000000
35.390003,4.004494,-1298.843750,-0.002009,0.001531,0.038895,17.812878,0.907431,0.388951,-1298.843750,0.039676,0.000000
35.630001,4.036514,-1298.888306,-0.001970,0.001546,0.039277,17.955313,0.914687,0.392768,-1298.888306,0.040075,0.000000
35.870003,4.031303,-1298.799316,-0.001975,0.001560,0.039632,17.932133,0.913506,0.396322,-1298.799316,0.040474,0.000000
36.110001,4.022743,-1298.932739,-0.001957,0.001572,0.039919,17.894056,0.911567,0.399185,-1298.932739,0.040873,0.000000
36.350002,4.197014,-1298.843750,-0.001949,0.001591,0.040413,18.669250,0.951057,0.404128,-1298.843750,0.041271,0.000000
36.590000,4.239830,-1298.888306,-0.001923,0.001605,0.040760,18.859705,0.960759,0.407597,-1298.888306,0.041670,0.000000
36.830002,4.233871,-1298.888306,-0.001910,0.001618,0.041089,18.833200,0.959409,0.410892,-1298.888306,0.042078,0.000000
37.070004,4.262177,-1298.888306,-0.001893,0.001629,0.041375,18.959108,0.965823,0.413753,-1298.888306,0.042477,0.000000
37.310001,4.538101,-1298.932739,-0.001880,0.001656,0.042052,20.186481,1.028348,0.420519,-1298.932739,0.042876,0.000000
37.550003,4.495277,-1298.799316,-0.001854,0.001668,0.042364,19.995993,1.018644,0.423641,-1298.799316,0.043275,0.000000
37.790001,4.543686,-1298.888306,-0.001845,0.001687,0.042850,20.211325,1.029614,0.428497,-1298.888306,0.043674,0.000000
38.030003,4.518738,-1298.888306,-0.001828,0.001697,0.043110,20.100349,1.023961,0.431100,-1298.888306,0.044072,0.000000
38.270000,4.681839,-1298.843750,-0.001824,0.001714,0.043544,20.825859,1.060920,0.435435,-1298.843750,0.044471,0.000000
38.510002,4.805466,-1298.888306,-0.001802,0.001734,0.044055,21.375778,1.088934,0.440552,-1298.888306,0.044870,0.000000
38.750000,4.760780,-1298.888306,-0.001802,0.001744,0.044298,21.177008,1.078808,0.442980,-1298.888306,0.045278,0.000000
38.990002,4.939896,-1298.932739,-0.001772,0.001762,0.044758,21.973753,1.119396,0.447575,-1298.932739,0.045677,0.000000
39.230003,5.134644,-1298.888306,-0.001746,0.001783,0.045278,22.840034,1.163527,0.452779,-1298.888306,0.046076,0.000000
39.470001,5.083260,-1298.888306,-0.001746,0.001795,0.045599,22.611467,1.151883,0.455987,-1298.888306,0.046475,0.000000
39.710003,5.140228,-1298.888306,-0.001725,0.001812,0.046015,22.864878,1.164792,0.460151,-1298.888306,0.046874,0.000000
39.950001,5.118263,-1298.799316,-0.001712,0.001822,0.046275,22.767172,1.159815,0.462753,-1298.799316,0.047273,0.000000
40.190002,5.407967,-1298.888306,-0.001707,0.001844,0.046839,24.055838,1.225463,0.468390,-1298.888306,0.047672,0.000000
40.430000,5.445946,-1298.888306,-0.001669,0.001857,0.047177,24.224777,1.234069,0.471772,-1298.888306,0.048070,0.000000
40.670002,5.387482,-1298.888306,-0.001669,0.001867,0.047420,23.964716,1.220821,0.474200,-1298.888306,0.048478,0.000000
40.910004,5.529732,-1298.932739,-0.001664,0.001884,0.047854,24.597475,1.253055,0.478536,-1298.932739,0.048877,0.000000
41.150002,5.886833,-1298.843750,-0.001638,0.001907,0.048435,26.185942,1.333976,0.484345,-1298.843750,0.049276,0.000000
41.390003,5.882744,-1298.888306,-0.001621,0.001922,0.048808,26.167751,1.333049,0.488075,-1298.888306,0.049675,0.000000
41.630001,5.928917,-1298.932739,-0.001604,0.001938,0.049232,26.373140,1.343512,0.492324,-1298.932739,0.050074,0.000000
41.870003,5.991104,-1298.888306,-0.001582,0.001952,0.049579,26.649761,1.357604,0.495793,-1298.888306,0.050473,0.000000
42.110001,6.075630,-1298.932739,-0.001574,0.001967,0.049970,27.025753,1.376758,0.499697,-1298.932739,0.050871,0.000000
42.350002,6.264793,-1298.888306,-0.001561,0.001983,0.050369,27.867193,1.419622,0.503686,-1298.888306,0.051270,0.000000
42.590000,6.201866,-1298.932739,-0.001548,0.001995,0.050663,27.587278,1.405363,0.506635,-1298.932739,0.051678,0.000000
42.830002,6.348953,-1298.932739,-0.001522,0.002010,0.051054,28.241554,1.438693,0.510537,-1298.932739,0.052077,0.000000
43.070004,6.663605,-1298.932739,-0.001513,0.002033,0.051626,29.641193,1.509994,0.516260,-1298.932739,0.052476,0.000000
43.310001,6.760422,-1298.932739,-0.001483,0.002048,0.052008,30.071857,1.531933,0.520077,-1298.932739,0.052875,0.000000
43.550003,6.854263,-1298.888306,-0.001492,0.002065,0.052441,30.489286,1.553198,0.524412,-1298.888306,0.053274,0.000000
43.790001,6.808830,-1298.888306,-0.001475,0.002076,0.052727,30.287189,1.542903,0.527274,-1298.888306,0.053673,0.000000
44.030003,6.960014,-1298.888306,-0.001449,0.002090,0.053092,30.959690,1.577162,0.530917,-1298.888306,0.054072,0.000000
44.270000,7.238922,-1298.888306,-0.001453,0.002108,0.053543,32.200333,1.640363,0.535426,-1298.888306,0.054471,0.000000
44.510002,7.336853,-1298.888306,-0.001423,0.002122,0.053907,32.635952,1.662555,0.539067,-1298.888306,0.054878,0.000000
44.750004,7.518944,-1298.888306,-0.001414,0.002137,0.054280,33.445930,1.703817,0.542797,-1298.888306,0.055277,0.000000
44.990002,7.933395,-1298.932739,-0.001393,0.002161,0.054896,35.289505,1.797733,0.548956,-1298.932739,0.055676,0.000000
45.230003,7.786682,-1298.888306,-0.001371,0.002173,0.055199,34.636890,1.764487,0.551989,-1298.888306,0.056075,0.000000
45.470001,7.916267,-1298.932739,-0.001371,0.002188,0.055563,35.213318,1.793852,0.555632,-1298.932739,0.056474,0.000000
45.710003,7.982918,-1298.977173,-0.001337,0.002203,0.055945,35.509792,1.808955,0.559447,-1298.977173,0.056873,0.000000
45.950001,8.200760,-1298.888306,-0.001358,0.002217,0.056309,36.478802,1.858319,0.563090,-1298.888306,0.057272,0.000000
46.190002,8.546692,-1298.977173,-0.001311,0.002237,0.056812,38.017586,1.936708,0.568120,-1298.977173,0.057671,0.000000
46.430000,8.498657,-1298.932739,-0.001302,0.002250,0.057150,37.803917,1.925823,0.571502,-1298.932739,0.058078,0.000000
46.670002,8.557495,-1298.977173,-0.001306,0.002262,0.057462,38.065639,1.939156,0.574625,-1298.977173,0.058477,0.000000
46.910004,8.979019,-1298.932739,-0.001281,0.002282,0.057957,39.940674,2.034675,0.579568,-1298.932739,0.058876,0.000000
47.150002,9.203186,-1298.977173,-0.001268,0.002299,0.058390,40.937817,2.085472,0.583903,-1298.977173,0.059275,0.000000
47.390003,9.383041,-1298.977173,-0.001250,0.002316,0.058824,41.737854,2.126228,0.588241,-1298.977173,0.059674,0.000000
47.630001,9.297394,-1298.932739,-0.001224,0.002328,0.059127,41.356873,2.106819,0.591274,-1298.932739,0.060073,0.000000
47.870003,9.438896,-1299.021729,-0.001220,0.002341,0.059466,41.986309,2.138885,0.594658,-1299.021729,0.060472,0.000000
48.110001,10.064110,-1299.021729,-0.001216,0.002364,0.060038,44.767395,2.280560,0.600381,-1299.021729,0.060871,0.000000
48.350002,9.992989,-1298.977173,-0.001203,0.002376,0.060342,44.451035,2.264444,0.603416,-1298.977173,0.061278,0.000000
48.590004,10.346741,-1298.977173,-0.001168,0.002392,0.060749,46.024601,2.344605,0.607493,-1298.977173,0.061677,0.000000
48.830002,10.498672,-1298.932739,-0.001168,0.002407,0.061139,46.700428,2.379033,0.611395,-1298.932739,0.062076,0.000000
49.070004,10.918709,-1299.021729,-0.001151,0.002428,0.061677,48.568844,2.474215,0.616771,-1299.021729,0.062475,0.000000
49.310001,10.968979,-1298.932739,-0.001130,0.002442,0.062015,48.792454,2.485606,0.620153,-1298.932739,0.062874,0.000000
49.550003,10.974937,-1299.021729,-0.001134,0.002453,0.062319,48.818958,2.486956,0.623189,-1299.021729,0.063273,0.000000
49.790001,11.688400,-1299.021729,-0.001108,0.002477,0.062926,51.992599,2.648629,0.629260,-1299.021729,0.063672,0.000000
50.030003,11.860809,-1298.977173,-0.001095,0.002492,0.063307,52.759514,2.687698,0.633075,-1298.977173,0.064079,0.000000
50.270004,11.832138,-1299.021729,-0.001087,0.002504,0.063602,52.631977,2.681201,0.636023,-1299.021729,0.064478,0.000000
50.510002,12.077530,-1298.932739,-0.001069,0.002518,0.063967,53.723537,2.736808,0.639666,-1298.932739,0.064877,0.000000
50.750004,12.724342,-1299.021729,-0.001061,0.002541,0.064530,56.600700,2.883377,0.645304,-1299.021729,0.065276,0.000000
50.990002,12.774979,-1298.977173,-0.001035,0.002553,0.064843,56.825943,2.894852,0.648426,-1298.977173,0.065675,0.000000
51.230003,12.919464,-1299.021729,-0.001026,0.002567,0.065198,57.468647,2.927592,0.651980,-1299.021729,0.066074,0.000000
51.470001,13.170067,-1299.110596,-0.001013,0.002581,0.065545,58.583382,2.984380,0.655449,-1299.110596,0.066473,0.000000
51.710003,13.864548,-1299.021729,-0.001000,0.002603,0.066126,61.672588,3.141751,0.661261,-1299.021729,0.066872,0.000000
51.950001,14.153877,-1299.066162,-0.000987,0.002619,0.066525,62.959591,3.207314,0.665250,-1299.066162,0.067280,0.000000
52.190002,14.168404,-1299.021729,-0.000970,0.002631,0.066820,63.024208,3.210606,0.668199,-1299.021729,0.067678,0.000000
52.430004,14.483055,-1299.021729,-0.000961,0.002646,0.067201,64.423843,3.281907,0.672014,-1299.021729,0.068077,0.000000
52.670002,15.233757,-1299.066162,-0.000949,0.002668,0.067765,67.763138,3.452019,0.677651,-1299.066162,0.068476,0.000000
52.910004,15.314194,-1299.021729,-0.000936,0.002680,0.068060,68.120934,3.470246,0.680600,-1299.021729,0.068875,0.000000
53.150002,15.441170,-1299.066162,-0.000923,0.002693,0.068398,68.685753,3.499019,0.683982,-1299.066162,0.069274,0.000000
53.390003,15.872375,-1298.977173,-0.000905,0.002708,0.068788,70.603851,3.596732,0.687884,-1298.977173,0.069673,0.000000
53.630001,16.242889,-1299.021729,-0.000897,0.002725,0.069222,72.251984,3.680691,0.692219,-1299.021729,0.070072,0.000000
53.870003,16.921722,-1299.066162,-0.000892,0.002742,0.069647,75.271584,3.834517,0.696470,-1299.066162,0.070479,0.000000
54.110004,17.304893,-1299.021729,-0.000871,0.002758,0.070046,76.976013,3.921345,0.700459,-1299.021729,0.070878,0.000000
54.350002,17.328354,-1299.110596,-0.000862,0.002767,0.070271,77.080368,3.926661,0.702713,-1299.110596,0.071277,0.000000
54.590004,18.173264,-1299.021729,-0.000841,0.002790,0.070878,80.838715,4.118121,0.708784,-1299.021729,0.071676,0.000000
54.830002,18.677460,-1299.066162,-0.000828,0.002806,0.071260,83.081490,4.232373,0.712599,-1299.066162,0.072075,0.000000
55.070004,18.791779,-1299.110596,-0.000819,0.002818,0.071572,83.590004,4.258278,0.715722,-1299.110596,0.072474,0.000000
55.310001,19.217026,-1299.021729,-0.000815,0.002834,0.071980,85.481598,4.354640,0.719798,-1299.021729,0.072873,0.000000
55.550003,19.541359,-1299.110596,-0.000793,0.002849,0.072361,86.924309,4.428135,0.723613,-1299.110596,0.073272,0.000000
55.790001,20.291695,-1299.110596,-0.000785,0.002867,0.072812,90.261963,4.598164,0.728123,-1299.110596,0.073680,0.000000
56.030003,20.678215,-1299.066162,-0.000780,0.002881,0.073177,91.981293,4.685750,0.731766,-1299.066162,0.074079,0.000000
56.270004,20.993240,-1299.066162,-0.000767,0.002894,0.073497,93.382599,4.757136,0.734974,-1299.066162,0.074477,0.000000
56.510002,22.087646,-1299.021729,-0.000750,0.002915,0.074035,98.250755,5.005132,0.740352,-1299.021729,0.074876,0.000000
56.750004,22.661102,-1299.066162,-0.000750,0.002933,0.074503,100.801620,5.135079,0.745034,-1299.066162,0.075275,0.000000
56.990002,22.954903,-1299.021729,-0.000729,0.002945,0.074807,102.108505,5.201655,0.748069,-1299.021729,0.075674,0.000000
57.230003,23.298599,-1299.066162,-0.000711,0.002960,0.075180,103.637344,5.279538,0.751799,-1299.066162,0.076073,0.000000
57.470001,23.481064,-1299.110596,-0.000698,0.002971,0.075457,104.448990,5.320885,0.754574,-1299.110596,0.076472,0.000000
57.710003,24.573235,-1299.021729,-0.000703,0.002993,0.076030,109.307205,5.568375,0.760298,-1299.021729,0.076880,0.000000
57.950005,24.906502,-1299.110596,-0.000681,0.003003,0.076281,110.789650,5.643894,0.762812,-1299.110596,0.077278,0.000000
58.190002,25.308296,-1299.110596,-0.000677,0.003018,0.076663,112.576927,5.734942,0.766629,-1299.110596,0.077677,0.000000
58.430004,25.635612,-1299.110596,-0.000668,0.003032,0.077018,114.032898,5.809113,0.770185,-1299.110596,0.078076,0.000000
58.670002,27.252823,-1299.199585,-0.000668,0.003056,0.077634,121.226608,6.175578,0.776341,-1299.199585,0.078475,0.000000
58.910004,27.570831,-1299.066162,-0.000642,0.003071,0.078007,122.641182,6.247640,0.780071,-1299.066162,0.078874,0.000000
59.150002,28.376274,-1299.155151,-0.000629,0.003088,0.078432,126.223969,6.430156,0.784319,-1299.155151,0.079273,0.000000
59.390003,28.591499,-1299.110596,-0.000621,0.003098,0.078692,127.181343,6.478926,0.786921,-1299.110596,0.079672,0.000000
59.630001,29.547012,-1299.155151,-0.000621,0.003118,0.079195,131.431671,6.695448,0.791951,-1299.155151,0.080080,0.000000
59.870003,30.512573,-1299.066162,-0.000604,0.003134,0.079594,135.726700,6.914248,0.795941,-1299.066162,0.080479,0.000000
60.110004,30.687218,-1299.066162,-0.000599,0.003145,0.079889,136.503555,6.953823,0.798889,-1299.066162,0.080878,0.000000
60.350002,31.633041,-1299.155151,-0.000586,0.003165,0.080392,140.710800,7.168149,0.803919,-1299.155151,0.081276,0.000000
60.590004,32.776222,-1299.110596,-0.000586,0.003183,0.080852,145.795914,7.427198,0.808516,-1299.110596,0.081675,0.000000
60.830002,33.338135,-1299.110596,-0.000573,0.003197,0.081198,148.295425,7.554529,0.811985,-1299.110596,0.082074,0.000000
61.070004,34.118256,-1299.110596,-0.000556,0.003214,0.081623,151.765579,7.731307,0.816233,-1299.110596,0.082473,0.000000
61.310001,34.345032,-1299.155151,-0.000543,0.003224,0.081884,152.774338,7.782696,0.818836,-1299.155151,0.082872,0.000000
61.550003,35.742546,-1299.110596,-0.000530,0.003244,0.082404,158.990784,8.099377,0.824038,-1299.110596,0.083280,0.000000
61.790005,36.402016,-1299.110596,-0.000535,0.003257,0.082733,161.924255,8.248815,0.827335,-1299.110596,0.083679,0.000000
62.030003,36.645546,-1299.110596,-0.000513,0.003266,0.082959,163.007523,8.303999,0.829588,-1299.110596,0.084078,0.000000
62.270004,37.776070,-1299.155151,-0.000522,0.003285,0.083436,168.036346,8.560180,0.834359,-1299.155151,0.084477,0.000000
62.510002,39.345993,-1299.066162,-0.000513,0.003309,0.084043,175.019714,8.915930,0.840428,-1299.066162,0.084876,0.000000
62.750004,40.138771,-1299.244141,-0.000509,0.003323,0.084407,178.546173,9.095575,0.844071,-1299.244141,0.085274,0.000000
62.990002,41.007515,-1299.110596,-0.000492,0.003338,0.084780,182.410538,9.292436,0.847801,-1299.110596,0.085673,0.000000
63.230003,41.721359,-1299.110596,-0.000483,0.003351,0.085118,185.585876,9.454195,0.851183,-1299.110596,0.086081,0.000000
63.470001,42.714470,-1299.199585,-0.000470,0.003369,0.085578,190.003448,9.679237,0.855780,-1299.199585,0.086480,0.000000
63.710003,43.614128,-1299.110596,-0.000461,0.003384,0.085960,194.005325,9.883103,0.859595,-1299.110596,0.086879,0.000000
63.950005,44.122787,-1299.244141,-0.000457,0.003394,0.086202,196.267960,9.998367,0.862023,-1299.244141,0.087278,0.000000
64.190002,44.996742,-1299.110596,-0.000453,0.003410,0.086610,200.155502,10.196407,0.866099,-1299.110596,0.087677,0.000000
64.430000,46.722687,-1299.199585,-0.000440,0.003432,0.087182,207.832886,10.587513,0.871822,-1299.199585,0.088075,0.000000
64.670006,47.841293,-1299.199585,-0.000427,0.003446,0.087538,212.808701,10.840992,0.875378,-1299.199585,0.088474,0.000000
64.910004,48.835159,-1299.110596,-0.000427,0.003463,0.087963,217.229645,11.066205,0.879629,-1299.110596,0.088873,0.000000
65.150002,49.502075,-1299.155151,-0.000431,0.003475,0.088266,220.196228,11.217331,0.882662,-1299.155151,0.089281,0.000000
65.389999,50.440826,-1299.110596,-0.000405,0.003489,0.088622,224.372009,11.430055,0.886218,-1299.110596,0.089680,0.000000
65.630005,51.761261,-1299.288574,-0.000414,0.003506,0.089064,230.245590,11.729269,0.890641,-1299.288574,0.090079,0.000000
65.870003,52.811722,-1299.199585,-0.000405,0.003521,0.089428,234.918274,11.967307,0.894284,-1299.199585,0.090478,0.000000
66.110001,53.872986,-1299.244141,-0.000401,0.003536,0.089810,239.639008,12.207793,0.898099,-1299.244141,0.090877,0.000000
66.350006,55.813416,-1299.199585,-0.000397,0.003560,0.090426,248.270477,12.647500,0.904257,-1299.199585,0.091276,0.000000
66.590004,56.484810,-1299.110596,-0.000371,0.003571,0.090703,251.256989,12.799641,0.907031,-1299.110596,0.091675,0.000000
66.830002,57.560219,-1299.199585,-0.000371,0.003587,0.091102,256.040649,13.043332,0.911020,-1299.199585,0.092073,0.000000
67.070000,58.547005,-1299.199585,-0.000371,0.003603,0.091510,260.430084,13.266940,0.915097,-1299.199585,0.092481,0.000000
67.310005,59.730408,-1299.155151,-0.000358,0.003615,0.091831,265.694122,13.535104,0.918306,-1299.155151,0.092880,0.000000
67.550003,61.411293,-1299.199585,-0.000362,0.003636,0.092360,273.171082,13.915998,0.923596,-1299.199585,0.093279,0.000000
67.790001,62.218224,-1299.110596,-0.000358,0.003649,0.092681,276.760468,14.098851,0.926805,-1299.110596,0.093678,0.000000
68.030006,63.133522,-1299.199585,-0.000341,0.003662,0.093019,280.831940,14.306261,0.930187,-1299.199585,0.094077,0.000000
68.270004,64.732491,-1299.244141,-0.000332,0.003681,0.093496,287.944489,14.668591,0.934956,-1299.244141,0.094476,0.000000
68.510002,66.157555,-1299.155151,-0.000341,0.003697,0.093895,294.283508,14.991517,0.938945,-1299.155151,0.094875,0.000000
68.750000,67.413567,-1299.199585,-0.000341,0.003714,0.094328,299.870514,15.276132,0.943283,-1299.199585,0.095274,0.000000
68.990005,67.065392,-1299.155151,-0.000315,0.003705,0.094111,298.321747,15.197235,0.941114,-1299.155151,0.094328,0.000000
69.230003,66.579445,-1299.288574,-0.000310,0.003704,0.094085,296.160156,15.087118,0.940853,-1299.288574,0.094111,0.000000
69.470001,66.176552,-1299.244141,-0.000315,0.003703,0.094059,294.368011,14.995821,0.940594,-1299.244141,0.094111,0.000000
69.710007,65.829124,-1299.244141,-0.000302,0.003703,0.094051,292.822571,14.917092,0.940507,-1299.244141,0.094111,0.000000
69.950005,65.520058,-1299.199585,-0.000315,0.003702,0.094042,291.447784,14.847057,0.940420,-1299.199585,0.094111,0.000000
70.190002,65.237801,-1299.110596,-0.000302,0.003702,0.094042,290.192230,14.783097,0.940420,-1299.110596,0.094111,0.000000
70.430000,64.985329,-1299.244141,-0.000306,0.003702,0.094033,289.069183,14.725885,0.940334,-1299.244141,0.094111,0.000000
70.670006,64.757439,-1299.244141,-0.000297,0.003702,0.094033,288.055481,14.674245,0.940334,-1299.244141,0.094111,0.000000
70.910004,64.539589,-1299.244141,-0.000310,0.003702,0.094033,287.086426,14.624880,0.940334,-1299.244141,0.094111,0.000000
71.150002,64.363457,-1299.244141,-0.000302,0.003702,0.094025,286.302948,14.584969,0.940247,-1299.244141,0.094111,0.000000
71.390007,64.177650,-1299.199585,-0.000297,0.003702,0.094025,285.476440,14.542863,0.940247,-1299.199585,0.094111,0.000000
71.630005,64.029442,-1299.244141,-0.000302,0.003702,0.094025,284.817169,14.509278,0.940247,-1299.244141,0.094111,0.000000
71.870003,63.871925,-1299.244141,-0.000297,0.003702,0.094025,284.116516,14.473585,0.940247,-1299.244141,0.094111,0.000000
72.110001,63.746071,-1299.199585,-0.000297,0.003702,0.094025,283.556671,14.445066,0.940247,-1299.199585,0.094111,0.000000
72.350006,63.605309,-1299.333008,-0.000293,0.003702,0.094025,282.930542,14.413169,0.940247,-1299.333008,0.094111,0.000000
72.590004,63.497704,-1299.199585,-0.000297,0.003702,0.094025,282.451904,14.388785,0.940247,-1299.199585,0.094111,0.000000
72.830002,63.382256,-1299.244141,-0.000293,0.003702,0.094025,281.938354,14.362624,0.940247,-1299.244141,0.094111,0.000000
73.070000,63.271660,-1299.155151,-0.000293,0.003702,0.094025,281.446411,14.337564,0.940247,-1299.155151,0.094111,0.000000
73.310005,63.171867,-1299.244141,-0.000302,0.003702,0.094025,281.002502,14.314950,0.940247,-1299.244141,0.094111,0.000000
73.550003,63.069466,-1299.244141,-0.000293,0.003702,0.094025,280.546997,14.291745,0.940247,-1299.244141,0.094111,0.000000
73.790001,62.980476,-1299.244141,-0.000293,0.003702,0.094025,280.151154,14.271581,0.940247,-1299.244141,0.094111,0.000000
74.030006,62.882164,-1299.244141,-0.000297,0.003702,0.094025,279.713837,14.249302,0.940247,-1299.244141,0.094111,0.000000
74.270004,62.781250,-1299.155151,-0.000293,0.003701,0.094016,279.264954,14.226435,0.940160,-1299.155151,0.094111,0.000000
74.510002,62.717201,-1299.288574,-0.000297,0.003701,0.094016,278.980042,14.211921,0.940160,-1299.288574,0.094111,0.000000
74.750000,62.636024,-1299.244141,-0.000285,0.003701,0.094016,278.618958,14.193526,0.940160,-1299.244141,0.094111,0.000000
74.990005,62.552246,-1299.244141,-0.000297,0.003701,0.094016,278.246277,14.174541,0.940160,-1299.244141,0.094111,0.000000
75.230003,62.474419,-1299.333008,-0.000293,0.003701,0.094016,277.900085,14.156905,0.940160,-1299.333008,0.094111,0.000000
75.470001,62.441650,-1299.244141,-0.000293,0.003701,0.094016,277.754333,14.149480,0.940160,-1299.244141,0.094111,0.000000
75.710007,62.354889,-1299.288574,-0.000293,0.003701,0.094016,277.368408,14.129820,0.940160,-1299.288574,0.094111,0.000000
75.950005,62.304245,-1299.288574,-0.000289,0.003701,0.094016,277.143127,14.118344,0.940160,-1299.288574,0.094111,0.000000
76.190002,62.233490,-1299.288574,-0.000293,0.003701,0.094016,276.828400,14.102311,0.940160,-1299.288574,0.094111,0.000000
76.430000,62.187317,-1299.333008,-0.000293,0.003701,0.094016,276.623016,14.091847,0.940160,-1299.333008,0.094111,0.000000
76.670006,62.128487,-1299.244141,-0.000280,0.003701,0.094016,276.361298,14.078516,0.940160,-1299.244141,0.094111,0.000000
76.910004,62.068161,-1299.288574,-0.000293,0.003701,0.094016,276.092957,14.064847,0.940160,-1299.288574,0.094111,0.000000
77.150002,62.008583,-1299.333008,-0.000285,0.003701,0.094016,275.827942,14.051346,0.940160,-1299.333008,0.094111,0.000000
77.390007,61.957565,-1299.199585,-0.000293,0.003701,0.094016,275.601013,14.039784,0.940160,-1299.199585,0.094111,0.000000
77.630005,61.896492,-1299.288574,-0.000289,0.003701,0.094016,275.329346,14.025946,0.940160,-1299.288574,0.094111,0.000000
77.870003,61.845856,-1299.199585,-0.000272,0.003701,0.094016,275.104095,14.014471,0.940160,-1299.199585,0.094111,0.000000
78.110001,61.804146,-1299.377563,-0.000289,0.003701,0.094016,274.918579,14.005020,0.940160,-1299.377563,0.094111,0.000000
78.350006,61.760582,-1299.333008,-0.000289,0.003701,0.094016,274.724792,13.995148,0.940160,-1299.333008,0.094111,0.000000
78.590004,61.708076,-1299.333008,-0.000280,0.003701,0.094016,274.491241,13.983250,0.940160,-1299.333008,0.094111,0.000000
78.830002,61.677170,-1299.377563,-0.000285,0.003701,0.094016,274.353760,13.976247,0.940160,-1299.377563,0.094111,0.000000
79.070007,61.632111,-1299.244141,-0.000280,0.003701,0.094016,274.153320,13.966036,0.940160,-1299.244141,0.094111,0.000000
79.310005,61.587799,-1299.288574,-0.000280,0.003701,0.094016,273.956207,13.955995,0.940160,-1299.288574,0.094111,0.000000
79.550003,61.554657,-1299.333008,-0.000280,0.003701,0.094016,273.808777,13.948485,0.940160,-1299.333008,0.094111,0.000000
79.790001,61.515930,-1299.333008,-0.000285,0.003701,0.094016,273.636536,13.939709,0.940160,-1299.333008,0.094111,0.000000
80.030006,61.482788,-1299.333008,-0.000280,0.003701,0.094016,273.489105,13.932199,0.940160,-1299.333008,0.094111,0.000000
80.270004,61.452255,-1299.333008,-0.000285,0.003701,0.094016,273.353271,13.925280,0.940160,-1299.333008,0.094111,0.000000
80.510002,61.393417,-1299.377563,-0.000280,0.003701,0.094016,273.091553,13.911947,0.940160,-1299.377563,0.094111,0.000000
80.750008,61.361397,-1299.333008,-0.000280,0.003701,0.094016,272.949127,13.904691,0.940160,-1299.333008,0.094111,0.000000
80.990005,61.329002,-1299.333008,-0.000289,0.003701,0.094016,272.805023,13.897351,0.940160,-1299.333008,0.094111,0.000000
81.230003,61.285431,-1299.377563,-0.000285,0.003701,0.094016,272.611206,13.887477,0.940160,-1299.377563,0.094111,0.000000
81.470001,61.261230,-1299.199585,-0.000285,0.003701,0.094016,272.503571,13.881993,0.940160,-1299.199585,0.094111,0.000000
81.710007,61.232185,-1299.333008,-0.000285,0.003701,0.094016,272.374359,13.875411,0.940160,-1299.333008,0.094111,0.000000
81.950005,61.198669,-1299.377563,-0.000280,0.003701,0.094016,272.225281,13.867817,0.940160,-1299.377563,0.094111,0.000000
82.190002,61.169624,-1299.333008,-0.000276,0.003701,0.094016,272.096069,13.861236,0.940160,-1299.333008,0.094111,0.000000
82.430000,61.137970,-1299.377563,-0.000285,0.003701,0.094016,271.955261,13.854062,0.940160,-1299.377563,0.094111,0.000000
82.670006,61.113396,-1299.244141,-0.000285,0.003701,0.094016,271.845947,13.848494,0.940160,-1299.244141,0.094111,0.000000
82.910004,61.079880,-1299.333008,-0.000280,0.003701,0.094016,271.696869,13.840899,0.940160,-1299.333008,0.094111,0.000000
83.150002,61.060890,-1299.288574,-0.000280,0.003701,0.094016,271.612396,13.836596,0.940160,-1299.288574,0.094111,0.000000
83.390007,61.044876,-1299.288574,-0.000276,0.003701,0.094016,271.541168,13.832967,0.940160,-1299.288574,0.094111,0.000000
83.630005,61.004662,-1299.377563,-0.000280,0.003701,0.094016,271.362274,13.823853,0.940160,-1299.377563,0.094111,0.000000
83.870003,60.982697,-1299.244141,-0.000280,0.003701,0.094016,271.264587,13.818876,0.940160,-1299.244141,0.094111,0.000000
84.110001,60.931305,-1299.377563,-0.000276,0.003701,0.094016,271.035980,13.807231,0.940160,-1299.377563,0.094111,0.000000
84.350006,60.919388,-1299.333008,-0.000267,0.003701,0.094016,270.982971,13.804530,0.940160,-1299.333008,0.094111,0.000000
84.590004,60.886246,-1299.288574,-0.000280,0.003701,0.094016,270.835541,13.797021,0.940160,-1299.288574,0.094111,0.000000
84.830002,60.876938,-1299.333008,-0.000276,0.003701,0.094016,270.794159,13.794911,0.940160,-1299.333008,0.094111,0.000000
85.070007,60.839333,-1299.244141,-0.000289,0.003701,0.094016,270.626862,13.786390,0.940160,-1299.244141,0.094111,0.000000
85.310005,60.822571,-1299.377563,-0.000285,0.003701,0.094016,270.552307,13.782592,0.940160,-1299.377563,0.094111,0.000000
85.550003,60.796509,-1299.288574,-0.000280,0.003701,0.094016,270.436371,13.776686,0.940160,-1299.288574,0.094111,0.000000
85.790001,60.774536,-1299.288574,-0.000289,0.003701,0.094016,270.338654,13.771707,0.940160,-1299.288574,0.094111,0.000000
86.030006,60.746239,-1299.333008,-0.000272,0.003701,0.094016,270.212769,13.765294,0.940160,-1299.333008,0.094111,0.000000
86.270004,60.734322,-1299.333008,-0.000280,0.003701,0.094016,270.159760,13.762593,0.940160,-1299.333008,0.094111,0.000000
86.510002,60.687401,-1299.421997,-0.000285,0.003701,0.094016,269.951050,13.751962,0.940160,-1299.421997,0.094111,0.000000
86.750008,60.693359,-1299.288574,-0.000285,0.003701,0.094016,269.977539,13.753312,0.940160,-1299.288574,0.094111,0.000000
86.990005,60.650162,-1299.333008,-0.000276,0.003701,0.094016,269.785400,13.743523,0.940160,-1299.333008,0.094111,0.000000
87.230003,60.646072,-1299.333008,-0.000276,0.003701,0.094016,269.767212,13.742597,0.940160,-1299.333008,0.094111,0.000000
87.470001,60.602875,-1299.288574,-0.000280,0.003701,0.094016,269.575043,13.732807,0.940160,-1299.288574,0.094111,0.000000
87.710007,60.600639,-1299.333008,-0.000285,0.003701,0.094016,269.565094,13.732301,0.940160,-1299.333008,0.094111,0.000000
87.950005,60.578300,-1299.333008,-0.000289,0.003701,0.094016,269.465729,13.727239,0.940160,-1299.333008,0.094111,0.000000
88.190002,60.574944,-1299.333008,-0.000285,0.003701,0.094016,269.450806,13.726478,0.940160,-1299.333008,0.094111,0.000000
88.430008,60.540314,-1299.288574,-0.000276,0.003701,0.094016,269.296753,13.718632,0.940160,-1299.288574,0.094111,0.000000
88.670006,60.525795,-1299.244141,-0.000289,0.003701,0.094016,269.232178,13.715342,0.940160,-1299.244141,0.094111,0.000000
88.910004,60.494514,-1299.333008,-0.000285,0.003701,0.094016,269.093048,13.708253,0.940160,-1299.333008,0.094111,0.000000
89.150002,60.497490,-1299.288574,-0.000289,0.003701,0.094016,269.106262,13.708927,0.940160,-1299.288574,0.094111,0.000000
89.390007,60.452065,-1299.288574,-0.000280,0.003701,0.094016,268.904205,13.698633,0.940160,-1299.288574,0.094111,0.000000
89.630005,60.447594,-1299.333008,-0.000272,0.003701,0.094016,268.884338,13.697620,0.940160,-1299.333008,0.094111,0.000000
89.870003,60.417801,-1299.333008,-0.000285,0.003701,0.094016,268.751801,13.690869,0.940160,-1299.333008,0.094111,0.000000
90.110001,60.398811,-1299.377563,-0.000276,0.003701,0.094016,268.667328,13.686566,0.940160,-1299.377563,0.094111,0.000000
90.350006,60.380943,-1299.288574,-0.000280,0.003701,0.094016,268.587860,13.682517,0.940160,-1299.288574,0.094111,0.000000
90.590004,60.354126,-1299.333008,-0.000285,0.003701,0.094016,268.468567,13.676440,0.940160,-1299.333008,0.094111,0.000000
90.830002,60.345566,-1299.288574,-0.000272,0.003701,0.094016,268.430481,13.674500,0.940160,-1299.288574,0.094111,0.000000
91.070007,60.331787,-1299.288574,-0.000285,0.003701,0.094016,268.369202,13.671378,0.940160,-1299.288574,0.094111,0.000000
91.310005,60.305717,-1299.377563,-0.000272,0.003701,0.094016,268.253235,13.665471,0.940160,-1299.377563,0.094111,0.000000
91.550003,60.297531,-1299.288574,-0.000276,0.003701,0.094016,268.216827,13.663616,0.940160,-1299.288574,0.094111,0.000000
91.790001,60.272583,-1299.288574,-0.000285,0.003701,0.094016,268.105835,13.657962,0.940160,-1299.288574,0.094111,0.000000
92.030006,60.257683,-1299.333008,-0.000285,0.003701,0.094016,268.039551,13.654586,0.940160,-1299.333008,0.094111,0.000000
92.270004,60.243904,-1299.288574,-0.000272,0.003701,0.094016,267.978271,13.651464,0.940160,-1299.288574,0.094111,0.000000
92.510002,60.212997,-1299.377563,-0.000280,0.003701,0.094016,267.840790,13.644460,0.940160,-1299.377563,0.094111,0.000000
92.750008,60.197357,-1299.244141,-0.000276,0.003701,0.094016,267.771210,13.640916,0.940160,-1299.244141,0.094111,0.000000
92.990005,60.185814,-1299.288574,-0.000280,0.003701,0.094016,267.719879,13.638300,0.940160,-1299.288574,0.094111,0.000000
93.230003,60.164589,-1299.377563,-0.000276,0.003701,0.094016,267.625458,13.633491,0.940160,-1299.377563,0.094111,0.000000
93.470001,60.147835,-1299.333008,-0.000276,0.003701,0.094016,267.550934,13.629694,0.940160,-1299.333008,0.094111,0.000000
93.710007,60.138527,-1299.288574,-0.000280,0.003701,0.094016,267.509521,13.627585,0.940160,-1299.288574,0.094111,0.000000
93.950005,60.129959,-1299.244141,-0.000285,0.003701,0.094016,267.471405,13.625643,0.940160,-1299.244141,0.094111,0.000000
94.190002,60.113579,-1299.288574,-0.000276,0.003701,0.094016,267.398560,13.621932,0.940160,-1299.288574,0.094111,0.000000
94.430008,60.088257,-1299.333008,-0.000280,0.003701,0.094016,267.285919,13.616194,0.940160,-1299.333008,0.094111,0.000000
94.670006,60.072243,-1299.288574,-0.000276,0.003701,0.094016,267.214691,13.612565,0.940160,-1299.288574,0.094111,0.000000
94.910004,60.059952,-1299.377563,-0.000276,0.003701,0.094016,267.160004,13.609779,0.940160,-1299.377563,0.094111,0.000000
95.150002,60.042450,-1299.244141,-0.000267,0.003701,0.094016,267.082153,13.605813,0.940160,-1299.244141,0.094111,0.000000
95.390007,60.020859,-1299.377563,-0.000276,0.003701,0.094016,266.986115,13.600921,0.940160,-1299.377563,0.094111,0.000000
95.630005,60.009682,-1299.377563,-0.000276,0.003701,0.094016,266.936401,13.598388,0.940160,-1299.377563,0.094111,0.000000
95.870003,59.989204,-1299.288574,-0.000272,0.003701,0.094016,266.845306,13.593748,0.940160,-1299.288574,0.094111,0.000000
96.110008,59.977287,-1299.288574,-0.000280,0.003701,0.094016,266.792297,13.591047,0.940160,-1299.288574,0.094111,0.000000
96.350006,59.966858,-1299.288574,-0.000276,0.003701,0.094016,266.745911,13.588684,0.940160,-1299.288574,0.094111,0.000000
96.590004,59.952339,-1299.244141,-0.000276,0.003701,0.094016,266.681335,13.585394,0.940160,-1299.244141,0.094111,0.000000
96.830002,59.948616,-1299.333008,-0.000280,0.003701,0.094016,266.664764,13.584551,0.940160,-1299.333008,0.094111,0.000000
97.070007,59.918449,-1299.244141,-0.000276,0.003701,0.094016,266.530579,13.577715,0.940160,-1299.244141,0.094111,0.000000
97.310005,59.927017,-1299.377563,-0.000285,0.003701,0.094016,266.568695,13.579657,0.940160,-1299.377563,0.094111,0.000000
97.550003,59.910637,-1299.377563,-0.000280,0.003701,0.094016,266.495819,13.575944,0.940160,-1299.377563,0.094111,0.000000
97.790001,59.897224,-1299.333008,-0.000276,0.003701,0.094016,266.436157,13.572905,0.940160,-1299.333008,0.094111,0.000000
98.030006,59.861855,-1299.333008,-0.000267,0.003701,0.094016,266.278839,13.564890,0.940160,-1299.333008,0.094111,0.000000
98.270004,59.863342,-1299.288574,-0.000289,0.003701,0.094016,266.285431,13.565228,0.940160,-1299.288574,0.094111,0.000000
98.510002,59.831688,-1299.288574,-0.000267,0.003701,0.094016,266.144653,13.558054,0.940160,-1299.288574,0.094111,0.000000
98.750008,59.824615,-1299.288574,-0.000272,0.003701,0.094016,266.113190,13.556452,0.940160,-1299.288574,0.094111,0.000000
98.990005,59.792961,-1299.421997,-0.000285,0.003701,0.094016,265.972382,13.549278,0.940160,-1299.421997,0.094111,0.000000
99.230003,59.797432,-1299.333008,-0.000263,0.003701,0.094016,265.992249,13.550291,0.940160,-1299.333008,0.094111,0.000000
99.300003,59.792221,-1299.288574,-0.000289,0.003701,0.094016,265.969086,13.549111,0.940160,-1299.288574,0.094111,0.000000