File: Data/compression 11/AutoNoHeating-16-11-3-240530_05302024_173048.csv
Time (sec),S:Load (lbs),S:HL1 (DIM),S:LVDT (in),S:Position (in),Ch:Position (mm),Ch:Load (N),Ch:Stress (MPa),Ch:Strain (mm/mm),Ch:HL1 (DIM),Set Point (),Cycles ()
0.110000,-0.005211,-348.285858,-0.006058,-0.001893,-0.048079,-0.023179,-0.001181,-0.480790,-348.285858,-0.047845,0.000000
0.320000,-0.005211,-348.196899,-0.006049,-0.001893,-0.048079,-0.023179,-0.001181,-0.480790,-348.196899,-0.047793,0.000000
0.530000,0.048409,-348.285858,-0.006053,-0.001790,-0.045469,0.215332,0.010970,-0.454686,-348.285858,-0.044307,0.000000
0.740000,0.056229,-348.285858,-0.005980,-0.001656,-0.042060,0.250117,0.012742,-0.420604,-348.285858,-0.040803,0.000000
0.950000,0.104263,-348.285858,-0.005851,-0.001517,-0.038540,0.463786,0.023626,-0.385395,-348.285858,-0.037299,0.000000
1.160000,0.104263,-348.330322,-0.005713,-0.001376,-0.034958,0.463786,0.023626,-0.349579,-348.330322,-0.033796,0.000000
1.370000,0.127350,-348.241364,-0.005570,-0.001242,-0.031550,0.566480,0.028858,-0.315497,-348.241364,-0.030310,0.000000
1.580000,0.109108,-348.330322,-0.005428,-0.001105,-0.028072,0.485336,0.024724,-0.280721,-348.330322,-0.026806,0.000000
1.790000,0.101662,-348.330322,-0.005286,-0.000967,-0.024569,0.452214,0.023037,-0.245685,-348.330322,-0.023302,0.000000
2.000000,0.090118,-348.374817,-0.005157,-0.000828,-0.021030,0.400867,0.020421,-0.210302,-348.374817,-0.019816,0.000000
2.210000,0.110596,-348.330322,-0.005010,-0.000686,-0.017423,0.491954,0.025061,-0.174226,-348.330322,-0.016313,0.000000
2.420000,0.055855,-348.374817,-0.004863,-0.000546,-0.013876,0.248455,0.012657,-0.138756,-348.374817,-0.012809,0.000000
2.630000,0.051018,-348.419281,-0.004734,-0.000415,-0.010545,0.226938,0.011561,-0.105455,-348.419281,-0.009305,0.000000
2.840000,0.079689,-348.419281,-0.004592,-0.000275,-0.006990,0.354474,0.018058,-0.069898,-348.419281,-0.005819,0.000000
3.050000,0.154167,-348.374817,-0.004458,-0.000139,-0.003538,0.685770,0.034935,-0.035383,-348.374817,-0.002315,0.000000
3.260000,0.719055,-348.463776,-0.004337,-0.000009,-0.000217,3.198517,0.162940,-0.002168,-348.463776,0.000035,0.000000
3.470000,0.661339,-348.463776,-0.004342,-0.000009,-0.000217,2.941782,0.149862,-0.002168,-348.463776,0.000035,0.000000
3.680000,0.649422,-348.508240,-0.004350,-0.000009,-0.000217,2.888772,0.147161,-0.002168,-348.508240,0.000035,0.000000
3.890000,0.636757,-348.463776,-0.004355,-0.000009,-0.000217,2.832436,0.144291,-0.002168,-348.463776,0.000278,0.000000
4.100000,0.627075,-348.463776,-0.004333,-0.000009,-0.000217,2.789370,0.142097,-0.002168,-348.463776,0.000633,0.000000
4.310000,0.631920,-348.463776,-0.004350,-0.000009,-0.000217,2.810920,0.143195,-0.002168,-348.463776,0.000980,0.000000
4.520000,0.835602,-348.463776,-0.004329,0.000015,0.000373,3.716943,0.189350,0.003729,-348.463776,0.001327,0.000000
4.730000,1.025146,-348.508240,-0.004324,0.000031,0.000781,4.560079,0.232302,0.007805,-348.508240,0.001682,0.000000
4.940000,1.214310,-348.419281,-0.004312,0.000044,0.001110,5.401519,0.275167,0.011101,-348.419281,0.002029,0.000000
5.150000,1.352455,-348.508240,-0.004303,0.000053,0.001353,6.016021,0.306471,0.013529,-348.508240,0.002376,0.000000
5.360000,1.559494,-348.508240,-0.004299,0.000068,0.001726,6.936976,0.353386,0.017258,-348.508240,0.002732,0.000000
5.570000,1.707329,-348.419281,-0.004277,0.000081,0.002064,7.594578,0.386886,0.020640,-348.419281,0.003079,0.000000
5.780000,2.056618,-348.552734,-0.004273,0.000101,0.002567,9.148293,0.466036,0.025670,-348.552734,0.003434,0.000000
5.990000,2.245781,-348.552734,-0.004247,0.000116,0.002949,9.989733,0.508901,0.029486,-348.552734,0.003781,0.000000
6.200000,2.336639,-348.552734,-0.004238,0.000125,0.003165,10.393891,0.529490,0.031654,-348.552734,0.004128,0.000000
6.410000,2.580170,-348.597198,-0.004238,0.000140,0.003564,11.477168,0.584675,0.035643,-348.597198,0.004484,0.000000
6.620000,2.863922,-348.552734,-0.004221,0.000156,0.003972,12.739362,0.648974,0.039719,-348.552734,0.004830,0.000000
6.830000,3.027763,-348.597198,-0.004212,0.000168,0.004275,13.468164,0.686101,0.042754,-348.597198,0.005177,0.000000
7.040000,3.215813,-348.552734,-0.004191,0.000182,0.004614,14.304649,0.728714,0.046136,-348.552734,0.005533,0.000000
7.250000,3.399017,-348.552734,-0.004191,0.000194,0.004926,15.119584,0.770228,0.049258,-348.552734,0.005880,0.000000
7.460001,3.574036,-348.552734,-0.004182,0.000205,0.005203,15.898105,0.809888,0.052034,-348.552734,0.006227,0.000000
7.670001,3.974335,-348.552734,-0.004148,0.000227,0.005767,17.678724,0.900597,0.057671,-348.552734,0.006582,0.000000
7.880001,4.090141,-348.597198,-0.004139,0.000238,0.006036,18.193857,0.926839,0.060359,-348.597198,0.006929,0.000000
8.090000,4.281166,-348.641693,-0.004135,0.000254,0.006443,19.043577,0.970126,0.064435,-348.641693,0.007285,0.000000
8.300000,4.464745,-348.597198,-0.004118,0.000265,0.006721,19.860176,1.011726,0.067210,-348.597198,0.007632,0.000000
8.510000,4.542572,-348.552734,-0.004109,0.000277,0.007033,20.206369,1.029362,0.070332,-348.552734,0.007978,0.000000
8.720000,4.851273,-348.641693,-0.004092,0.000292,0.007415,21.579538,1.099314,0.074148,-348.641693,0.008334,0.000000
8.930000,4.989044,-348.641693,-0.004083,0.000304,0.007710,22.192377,1.130534,0.077096,-348.641693,0.008681,0.000000
9.140000,5.131294,-348.597198,-0.004066,0.000318,0.008065,22.825136,1.162768,0.080652,-348.597198,0.009028,0.000000
9.350000,5.347267,-348.686188,-0.004049,0.000329,0.008360,23.785831,1.211708,0.083601,-348.686188,0.009383,0.000000
9.560000,5.692085,-348.686188,-0.004049,0.000349,0.008863,25.319660,1.289845,0.088630,-348.686188,0.009730,0.000000
9.770000,5.755020,-348.686188,-0.004018,0.000360,0.009141,25.599607,1.304106,0.091406,-348.686188,0.010077,0.000000
9.980000,5.789276,-348.775146,-0.004027,0.000371,0.009418,25.751986,1.311869,0.094181,-348.775146,0.010433,0.000000
10.190001,6.084198,-348.686188,-0.004001,0.000389,0.009869,27.063864,1.378699,0.098690,-348.686188,0.010780,0.000000
10.400001,6.150475,-348.686188,-0.003997,0.000402,0.010207,27.358677,1.393717,0.102072,-348.686188,0.011127,0.000000
10.610001,6.362358,-348.775146,-0.003988,0.000417,0.010580,28.301182,1.441731,0.105802,-348.775146,0.011482,0.000000
10.820001,6.488594,-348.775146,-0.003971,0.000429,0.010892,28.862707,1.470336,0.108924,-348.775146,0.011829,0.000000
11.030001,6.415237,-348.775146,-0.003971,0.000438,0.011118,28.536402,1.453714,0.111178,-348.775146,0.012185,0.000000
11.240001,6.707916,-348.686188,-0.003945,0.000454,0.011543,29.838303,1.520036,0.115428,-348.686188,0.012531,0.000000
11.450001,6.878090,-348.864105,-0.003928,0.000469,0.011924,30.595272,1.558597,0.119244,-348.864105,0.012878,0.000000
11.660001,7.018105,-348.730652,-0.003911,0.000485,0.012323,31.218088,1.590325,0.123233,-348.730652,0.013234,0.000000
11.870001,7.048271,-348.775146,-0.003915,0.000496,0.012601,31.352276,1.597161,0.126008,-348.775146,0.013581,0.000000
12.080001,7.130562,-348.775146,-0.003902,0.000511,0.012974,31.718323,1.615808,0.129737,-348.775146,0.013928,0.000000
12.290001,7.142853,-348.730652,-0.003872,0.000522,0.013251,31.772997,1.618594,0.132512,-348.730652,0.014283,0.000000
12.500001,7.352493,-348.864105,-0.003854,0.000538,0.013659,32.705524,1.666099,0.136588,-348.864105,0.014630,0.000000
12.710001,7.462349,-348.819611,-0.003854,0.000552,0.014014,33.194187,1.690992,0.140144,-348.819611,0.014977,0.000000
12.920001,7.380051,-348.819611,-0.003837,0.000560,0.014231,32.828106,1.672343,0.142312,-348.819611,0.015333,0.000000
13.130001,7.447449,-348.908569,-0.003833,0.000574,0.014587,33.127907,1.687616,0.145867,-348.908569,0.015679,0.000000
13.340001,7.643318,-348.819611,-0.003820,0.000588,0.014942,33.999176,1.732001,0.149423,-348.819611,0.016035,0.000000
13.550000,8.009361,-348.953064,-0.003790,0.000611,0.015515,35.627419,1.814947,0.155147,-348.953064,0.016382,0.000000
13.760000,7.963188,-348.908569,-0.003803,0.000623,0.015827,35.422031,1.804484,0.158269,-348.908569,0.016729,0.000000
13.970000,8.023514,-348.953064,-0.003768,0.000636,0.016165,35.690372,1.818154,0.161651,-348.953064,0.017084,0.000000
14.180000,7.982178,-348.953064,-0.003747,0.000647,0.016434,35.506500,1.808787,0.164339,-348.953064,0.017431,0.000000
14.390000,8.122192,-348.908569,-0.003734,0.000663,0.016833,36.129314,1.840515,0.168329,-348.908569,0.017778,0.000000
14.600000,8.173950,-348.953064,-0.003729,0.000676,0.017171,36.359547,1.852244,0.171711,-348.953064,0.018134,0.000000
14.810000,8.058144,-348.953064,-0.003725,0.000681,0.017292,35.844414,1.826001,0.172925,-348.953064,0.018481,0.000000
15.020000,8.404076,-348.908569,-0.003695,0.000702,0.017830,37.383194,1.904391,0.178302,-348.908569,0.018827,0.000000
15.230000,8.470734,-348.997528,-0.003695,0.000716,0.018177,37.679707,1.919496,0.181771,-348.997528,0.019183,0.000000
15.440001,8.634575,-348.953064,-0.003673,0.000734,0.018637,38.408508,1.956623,0.186367,-348.953064,0.019530,0.000000
15.650001,8.645744,-349.042023,-0.003652,0.000747,0.018984,38.458191,1.959154,0.189836,-349.042023,0.019885,0.000000
15.860001,8.651703,-348.953064,-0.003643,0.000761,0.019330,38.484695,1.960504,0.193305,-348.953064,0.020232,0.000000
16.070002,8.560844,-348.953064,-0.003626,0.000772,0.019617,38.080540,1.939915,0.196166,-348.953064,0.020579,0.000000
16.280001,8.759315,-348.997528,-0.003622,0.000789,0.020042,38.963383,1.984889,0.200416,-348.997528,0.020935,0.000000
16.490002,8.738838,-348.908569,-0.003596,0.000799,0.020284,38.872295,1.980249,0.202844,-348.908569,0.021282,0.000000
16.700001,8.664368,-349.042023,-0.003600,0.000806,0.020475,38.541031,1.963374,0.204752,-349.042023,0.021629,0.000000
16.910002,8.938805,-349.042023,-0.003579,0.000826,0.020978,39.761787,2.025562,0.209782,-349.042023,0.021984,0.000000
17.120001,9.049767,-348.997528,-0.003566,0.000841,0.021368,40.255371,2.050706,0.213684,-348.997528,0.022331,0.000000
17.330000,9.191269,-349.086517,-0.003557,0.000858,0.021802,40.884808,2.082771,0.218021,-349.086517,0.022678,0.000000
17.540001,9.235214,-349.042023,-0.003535,0.000872,0.022158,41.080284,2.092730,0.221576,-349.042023,0.023034,0.000000
17.750000,9.225159,-349.042023,-0.003535,0.000887,0.022522,41.035557,2.090451,0.225218,-349.042023,0.023380,0.000000
17.960001,9.173767,-349.042023,-0.003514,0.000896,0.022765,40.806953,2.078805,0.227647,-349.042023,0.023727,0.000000
18.170000,9.116425,-349.130981,-0.003501,0.000908,0.023051,40.551880,2.065811,0.230509,-349.130981,0.024083,0.000000
18.380001,9.389374,-349.086517,-0.003488,0.000924,0.023476,41.766022,2.127663,0.234758,-349.086517,0.024430,0.000000
18.590000,9.387512,-349.086517,-0.003458,0.000934,0.023727,41.757740,2.127241,0.237273,-349.086517,0.024785,0.000000
18.800001,9.381554,-349.130981,-0.003466,0.000945,0.024005,41.731236,2.125890,0.240048,-349.130981,0.025132,0.000000
19.010000,9.597160,-349.130981,-0.003454,0.000965,0.024499,42.690300,2.174748,0.244991,-349.130981,0.025479,0.000000
19.220001,9.623970,-349.130981,-0.003423,0.000975,0.024768,42.809555,2.180823,0.247680,-349.130981,0.025835,0.000000
19.430000,9.825424,-349.219940,-0.003432,0.000994,0.025245,43.705669,2.226473,0.252449,-349.219940,0.026182,0.000000
19.640001,9.909950,-349.130981,-0.003402,0.001008,0.025601,44.081661,2.245627,0.256005,-349.130981,0.026528,0.000000
19.850000,9.831383,-349.175476,-0.003402,0.001020,0.025913,43.732174,2.227823,0.259127,-349.175476,0.026884,0.000000
20.060001,9.805687,-349.130981,-0.003376,0.001032,0.026208,43.617874,2.222000,0.262076,-349.130981,0.027231,0.000000
20.270000,9.964317,-349.264435,-0.003367,0.001046,0.026580,44.323498,2.257947,0.265805,-349.264435,0.027578,0.000000
20.480001,10.134117,-349.219940,-0.003341,0.001063,0.026988,45.078804,2.296424,0.269881,-349.219940,0.027933,0.000000
20.690001,10.101723,-349.175476,-0.003328,0.001072,0.027240,44.934708,2.289083,0.272396,-349.175476,0.028280,0.000000
20.900002,10.203011,-349.264435,-0.003324,0.001087,0.027621,45.385258,2.312035,0.276211,-349.264435,0.028636,0.000000
21.110001,10.449142,-349.175476,-0.003303,0.001106,0.028089,46.480106,2.367810,0.280894,-349.175476,0.028983,0.000000
21.320002,10.496811,-349.264435,-0.003298,0.001120,0.028436,46.692146,2.378611,0.284363,-349.264435,0.029330,0.000000
21.530001,10.553040,-349.219940,-0.003272,0.001135,0.028818,46.942265,2.391353,0.288179,-349.219940,0.029685,0.000000
21.740002,10.518776,-349.219940,-0.003268,0.001145,0.029087,46.789852,2.383589,0.290867,-349.219940,0.030032,0.000000
21.950001,10.514687,-349.308899,-0.003255,0.001157,0.029390,46.771664,2.382662,0.293903,-349.308899,0.030379,0.000000
22.160002,10.595116,-349.308899,-0.003238,0.001172,0.029763,47.129429,2.400887,0.297632,-349.308899,0.030734,0.000000
22.370001,10.779816,-349.308899,-0.003225,0.001187,0.030145,47.951015,2.442741,0.301448,-349.308899,0.031081,0.000000
22.580002,10.813698,-349.308899,-0.003221,0.001199,0.030457,48.101730,2.450419,0.304570,-349.308899,0.031428,0.000000
22.790001,10.984619,-349.219940,-0.003195,0.001214,0.030830,48.862026,2.489150,0.308299,-349.219940,0.031784,0.000000
23.000002,11.038239,-349.353394,-0.003191,0.001227,0.031168,49.100536,2.501301,0.311681,-349.353394,0.032131,0.000000
23.210001,11.099678,-349.308899,-0.003178,0.001239,0.031480,49.373833,2.515223,0.314803,-349.308899,0.032486,0.000000
23.420002,11.027443,-349.353394,-0.003165,0.001250,0.031749,49.052517,2.498854,0.317491,-349.353394,0.032833,0.000000
23.630001,11.301506,-349.219940,-0.003160,0.001268,0.032200,50.271610,2.560958,0.322001,-349.219940,0.033180,0.000000
23.840002,11.317520,-349.308899,-0.003134,0.001282,0.032556,50.342842,2.564587,0.325557,-349.308899,0.033536,0.000000
24.050001,11.484711,-349.353394,-0.003130,0.001294,0.032877,51.086544,2.602473,0.328765,-349.353394,0.033883,0.000000
24.260000,11.681702,-349.308899,-0.003104,0.001311,0.033301,51.962803,2.647111,0.333015,-349.308899,0.034229,0.000000
24.470001,11.676109,-349.397858,-0.003096,0.001323,0.033614,51.937927,2.645844,0.336137,-349.397858,0.034585,0.000000
24.680000,11.801605,-349.353394,-0.003087,0.001336,0.033943,52.496162,2.674282,0.339432,-349.353394,0.034932,0.000000
24.890001,11.860435,-349.353394,-0.003074,0.001350,0.034290,52.757851,2.687613,0.342901,-349.353394,0.035279,0.000000
25.100000,11.889107,-349.353394,-0.003065,0.001365,0.034663,52.885387,2.694110,0.346630,-349.353394,0.035634,0.000000
25.310001,11.970284,-349.397858,-0.003040,0.001377,0.034967,53.246479,2.712505,0.349665,-349.397858,0.035981,0.000000
25.520000,12.121468,-349.486847,-0.003035,0.001394,0.035418,53.918980,2.746764,0.354175,-349.486847,0.036337,0.000000
25.730001,12.340424,-349.442352,-0.003018,0.001409,0.035799,54.892944,2.796380,0.357991,-349.442352,0.036684,0.000000
25.940001,12.276375,-349.486847,-0.003005,0.001421,0.036085,54.608044,2.781866,0.360853,-349.486847,0.037031,0.000000
26.150002,12.496078,-349.442352,-0.002979,0.001437,0.036493,55.585335,2.831652,0.364929,-349.442352,0.037386,0.000000
26.360001,12.502411,-349.442352,-0.002971,0.001449,0.036796,55.613503,2.833087,0.367964,-349.442352,0.037733,0.000000
26.570002,12.685242,-349.531311,-0.002962,0.001463,0.037169,56.426773,2.874517,0.371693,-349.531311,0.038080,0.000000
26.780001,12.668114,-349.397858,-0.002940,0.001475,0.037455,56.350586,2.870636,0.374555,-349.397858,0.038435,0.000000
26.990002,13.100807,-349.531311,-0.002932,0.001495,0.037984,58.275299,2.968685,0.379845,-349.531311,0.038782,0.000000
27.200001,13.012558,-349.486847,-0.002923,0.001507,0.038279,57.882748,2.948688,0.382793,-349.486847,0.039129,0.000000
27.410002,12.986122,-349.442352,-0.002902,0.001519,0.038583,57.765156,2.942698,0.385829,-349.442352,0.039485,0.000000
27.620001,13.068787,-349.575806,-0.002889,0.001532,0.038904,58.132866,2.961429,0.389037,-349.575806,0.039832,0.000000
27.830002,13.153313,-349.531311,-0.002876,0.001545,0.039233,58.508858,2.980583,0.392333,-349.531311,0.040179,0.000000
28.040001,13.424400,-349.575806,-0.002854,0.001562,0.039667,59.714714,3.042013,0.396669,-349.575806,0.040534,0.000000
28.250002,13.438553,-349.531311,-0.002846,0.001574,0.039979,59.777668,3.045219,0.399791,-349.531311,0.040881,0.000000
28.460001,13.452705,-349.575806,-0.002837,0.001584,0.040231,59.840622,3.048427,0.402306,-349.575806,0.041237,0.000000
28.670002,13.639633,-349.620270,-0.002833,0.001599,0.040621,60.672119,3.090785,0.406208,-349.620270,0.041583,0.000000
28.880001,14.072327,-349.531311,-0.002807,0.001620,0.041150,62.596836,3.188835,0.411499,-349.531311,0.041930,0.000000
29.090002,14.130417,-349.575806,-0.002798,0.001633,0.041471,62.855232,3.201998,0.414707,-349.575806,0.042286,0.000000
29.300001,13.890236,-349.620270,-0.002790,0.001642,0.041714,61.786854,3.147572,0.417136,-349.620270,0.042633,0.000000
29.510002,14.173615,-349.620270,-0.002764,0.001658,0.042104,63.047386,3.211787,0.421038,-349.620270,0.042980,0.000000
29.720001,14.080894,-349.620270,-0.002755,0.001670,0.042407,62.634945,3.190776,0.424073,-349.620270,0.043335,0.000000
29.930002,14.423477,-349.531311,-0.002738,0.001685,0.042789,64.158829,3.268407,0.427889,-349.531311,0.043682,0.000000
30.140001,14.370972,-349.709229,-0.002734,0.001697,0.043092,63.925274,3.256509,0.430924,-349.709229,0.044029,0.000000
30.350002,14.468903,-349.709229,-0.002721,0.001709,0.043405,64.360893,3.278700,0.434046,-349.709229,0.044385,0.000000
30.560001,14.581734,-349.664764,-0.002712,0.001721,0.043726,64.862793,3.304268,0.437255,-349.664764,0.044731,0.000000
30.770002,14.753029,-349.664764,-0.002712,0.001738,0.044133,65.624748,3.343084,0.441331,-349.664764,0.045087,0.000000
30.980001,15.274719,-349.664764,-0.002690,0.001756,0.044601,67.945343,3.461301,0.446014,-349.664764,0.045434,0.000000
31.190001,15.274345,-349.753723,-0.002673,0.001767,0.044879,67.943680,3.461216,0.448789,-349.753723,0.045781,0.000000
31.400002,15.314568,-349.664764,-0.002673,0.001781,0.045226,68.122597,3.470331,0.452258,-349.664764,0.046136,0.000000
31.610001,15.511925,-349.709229,-0.002643,0.001794,0.045564,69.000488,3.515052,0.455640,-349.709229,0.046483,0.000000
31.820002,15.484367,-349.709229,-0.002639,0.001805,0.045850,68.877907,3.508808,0.458502,-349.709229,0.046830,0.000000
32.030003,15.587143,-349.709229,-0.002608,0.001820,0.046232,69.335075,3.532097,0.462318,-349.709229,0.047186,0.000000
32.240002,15.787102,-349.709229,-0.002608,0.001833,0.046561,70.224533,3.577408,0.465613,-349.709229,0.047533,0.000000
32.450001,15.902916,-349.753723,-0.002600,0.001846,0.046882,70.739700,3.603652,0.468822,-349.753723,0.047880,0.000000
32.660000,16.095428,-349.798187,-0.002578,0.001860,0.047255,71.596039,3.647276,0.472551,-349.798187,0.048235,0.000000
32.870003,16.322205,-349.709229,-0.002570,0.001875,0.047637,72.604790,3.698664,0.476367,-349.709229,0.048582,0.000000
33.080002,16.508766,-349.753723,-0.002548,0.001889,0.047984,73.434662,3.740940,0.479836,-349.753723,0.048938,0.000000
33.290001,16.643562,-349.887146,-0.002544,0.001904,0.048357,74.034264,3.771485,0.483565,-349.887146,0.049284,0.000000
33.500000,16.629036,-349.709229,-0.002539,0.001915,0.048634,73.969643,3.768193,0.486340,-349.709229,0.049631,0.000000
33.710003,16.574669,-349.842682,-0.002514,0.001927,0.048946,73.727806,3.755874,0.489462,-349.842682,0.049987,0.000000
33.920002,17.148872,-349.842682,-0.002514,0.001944,0.049380,76.281998,3.885990,0.493798,-349.842682,0.050334,0.000000
34.130001,17.160042,-349.798187,-0.002488,0.001956,0.049675,76.331680,3.888521,0.496747,-349.798187,0.050681,0.000000
34.340000,17.049072,-349.887146,-0.002501,0.001963,0.049865,75.838058,3.863375,0.498655,-349.887146,0.051036,0.000000
34.550003,17.550659,-349.798187,-0.002479,0.001981,0.050316,78.069229,3.977036,0.503164,-349.798187,0.051383,0.000000
34.760002,17.969208,-349.887146,-0.002453,0.002001,0.050819,79.931030,4.071881,0.508194,-349.887146,0.051730,0.000000
34.970001,18.000488,-349.842682,-0.002453,0.002011,0.051071,80.070168,4.078969,0.510709,-349.842682,0.052086,0.000000
35.180000,18.266357,-349.842682,-0.002427,0.002029,0.051548,81.252815,4.139216,0.515479,-349.842682,0.052432,0.000000
35.390003,18.336739,-349.931641,-0.002423,0.002041,0.051843,81.565887,4.155164,0.518427,-349.931641,0.052779,0.000000
35.600002,18.321472,-349.842682,-0.002393,0.002051,0.052103,81.497978,4.151705,0.521029,-349.842682,0.053135,0.000000
35.810001,18.651764,-349.887146,-0.002389,0.002069,0.052563,82.967186,4.226550,0.525626,-349.887146,0.053482,0.000000
36.020000,18.651024,-349.887146,-0.002389,0.002078,0.052788,82.963898,4.226382,0.527880,-349.887146,0.053837,0.000000
36.230003,18.844284,-349.887146,-0.002371,0.002094,0.053178,83.823563,4.270175,0.531783,-349.887146,0.054184,0.000000
36.440002,19.091911,-349.931641,-0.002363,0.002105,0.053456,84.925064,4.326289,0.534558,-349.931641,0.054531,0.000000
36.650002,19.354431,-349.931641,-0.002354,0.002121,0.053872,86.092812,4.385777,0.538721,-349.931641,0.054887,0.000000
36.860001,19.947250,-349.976135,-0.002324,0.002140,0.054366,88.729797,4.520112,0.543664,-349.976135,0.055234,0.000000
37.070004,19.992310,-349.931641,-0.002324,0.002155,0.054731,88.930237,4.530322,0.547306,-349.931641,0.055580,0.000000
37.280003,20.039223,-349.887146,-0.002298,0.002167,0.055034,89.138916,4.540953,0.550341,-349.887146,0.055936,0.000000
37.490002,20.096573,-350.020599,-0.002289,0.002178,0.055312,89.394020,4.553948,0.553117,-350.020599,0.056283,0.000000
37.700001,20.198975,-349.976135,-0.002289,0.002190,0.055615,89.849525,4.577153,0.556152,-349.976135,0.056630,0.000000
37.910004,20.371384,-350.020599,-0.002259,0.002202,0.055927,90.616440,4.616221,0.559274,-350.020599,0.056985,0.000000
38.120003,20.558311,-349.976135,-0.002276,0.002217,0.056309,91.447937,4.658580,0.563090,-349.976135,0.057332,0.000000
38.330002,20.942230,-349.976135,-0.002242,0.002232,0.056699,93.155693,4.745577,0.566992,-349.976135,0.057688,0.000000
38.540001,21.634842,-350.020599,-0.002238,0.002250,0.057142,96.236580,4.902525,0.571415,-350.020599,0.058035,0.000000
38.750000,21.916725,-350.020599,-0.002220,0.002266,0.057549,97.490463,4.966401,0.575491,-350.020599,0.058382,0.000000
38.960003,21.847466,-350.154053,-0.002207,0.002276,0.057818,97.182381,4.950706,0.578179,-350.154053,0.058737,0.000000
39.170002,22.071632,-350.065094,-0.002190,0.002291,0.058182,98.179527,5.001503,0.581822,-350.065094,0.059084,0.000000
39.380001,21.978539,-350.109558,-0.002177,0.002300,0.058408,97.765419,4.980408,0.584076,-350.109558,0.059431,0.000000
39.590000,22.429115,-350.065094,-0.002169,0.002315,0.058798,99.769691,5.082510,0.587979,-350.065094,0.059787,0.000000
39.800003,22.834999,-350.020599,-0.002160,0.002330,0.059171,101.575150,5.174485,0.591708,-350.020599,0.060133,0.000000
40.010002,22.835747,-350.065094,-0.002156,0.002342,0.059474,101.578476,5.174654,0.594743,-350.065094,0.060480,0.000000
40.220001,23.224869,-350.065094,-0.002134,0.002355,0.059821,103.309380,5.262831,0.598212,-350.065094,0.060836,0.000000
40.430000,23.305679,-350.109558,-0.002121,0.002366,0.060090,103.668839,5.281143,0.600901,-350.109558,0.061183,0.000000
40.640003,24.096596,-350.154053,-0.002117,0.002387,0.060636,107.187012,5.460367,0.606364,-350.154053,0.061538,0.000000
40.850002,24.184105,-350.154053,-0.002091,0.002399,0.060923,107.576271,5.480196,0.609226,-350.154053,0.061885,0.000000
41.060001,24.408272,-350.154053,-0.002087,0.002413,0.061287,108.573418,5.530993,0.612868,-350.154053,0.062232,0.000000
41.270000,24.370659,-350.109558,-0.002078,0.002422,0.061512,108.406105,5.522470,0.615123,-350.109558,0.062588,0.000000
41.480003,24.554611,-350.154053,-0.002061,0.002434,0.061825,109.224365,5.564155,0.618245,-350.154053,0.062935,0.000000
41.690002,25.111687,-350.154053,-0.002057,0.002450,0.062241,111.702362,5.690390,0.622408,-350.154053,0.063281,0.000000
41.900002,25.409950,-350.154053,-0.002039,0.002465,0.062622,113.029106,5.757977,0.626224,-350.154053,0.063637,0.000000
42.110001,25.456131,-350.198517,-0.002035,0.002477,0.062917,113.234528,5.768442,0.629172,-350.198517,0.063984,0.000000
42.320004,26.185982,-350.198517,-0.002018,0.002493,0.063316,116.481064,5.933828,0.633161,-350.198517,0.064331,0.000000
42.530003,26.793320,-350.243011,-0.002001,0.002512,0.063793,119.182640,6.071453,0.637931,-350.243011,0.064686,0.000000
42.740002,26.809326,-350.243011,-0.001996,0.002522,0.064053,119.253838,6.075080,0.640533,-350.243011,0.065033,0.000000
42.950001,27.234207,-350.198517,-0.001983,0.002538,0.064470,121.143806,6.171360,0.644696,-350.198517,0.065380,0.000000
43.160004,27.508644,-350.243011,-0.001970,0.002551,0.064808,122.364563,6.233548,0.648078,-350.243011,0.065736,0.000000
43.370003,27.371239,-350.198517,-0.001970,0.002561,0.065042,121.753349,6.202411,0.650419,-350.198517,0.066083,0.000000
43.580002,27.951767,-350.243011,-0.001936,0.002576,0.065432,124.335670,6.333961,0.654322,-350.243011,0.066438,0.000000
43.790001,28.350204,-350.287476,-0.001940,0.002589,0.065762,126.108009,6.424248,0.657617,-350.287476,0.066785,0.000000
44.000004,28.446281,-350.243011,-0.001932,0.002600,0.066031,126.535378,6.446020,0.660306,-350.243011,0.067132,0.000000
44.210003,29.132187,-350.331970,-0.001914,0.002617,0.066473,129.586441,6.601448,0.664729,-350.331970,0.067488,0.000000
44.420002,29.644943,-350.243011,-0.001901,0.002633,0.066872,131.867294,6.717640,0.668718,-350.243011,0.067834,0.000000
44.630001,29.656120,-350.331970,-0.001897,0.002644,0.067149,131.917007,6.720173,0.671493,-350.331970,0.068181,0.000000
44.840004,29.799110,-350.287476,-0.001888,0.002653,0.067392,132.553070,6.752575,0.673921,-350.287476,0.068537,0.000000
45.050003,30.394905,-350.243011,-0.001876,0.002671,0.067852,135.203293,6.887584,0.678517,-350.243011,0.068884,0.000000
45.260002,30.939316,-350.376465,-0.001863,0.002687,0.068242,137.624954,7.010949,0.682420,-350.376465,0.069231,0.000000
45.470001,31.312057,-350.287476,-0.001858,0.002700,0.068589,139.282990,7.095413,0.685889,-350.287476,0.069586,0.000000
45.680000,31.707886,-350.331970,-0.001850,0.002712,0.068892,141.043716,7.185110,0.688924,-350.331970,0.069933,0.000000
45.890003,32.163300,-350.287476,-0.001832,0.002728,0.069291,143.069504,7.288308,0.692913,-350.287476,0.070289,0.000000
46.100002,32.462685,-350.331970,-0.001828,0.002741,0.069621,144.401230,7.356150,0.696209,-350.331970,0.070636,0.000000
46.310001,32.964645,-350.376465,-0.001811,0.002756,0.070002,146.634064,7.469895,0.700025,-350.376465,0.070982,0.000000
46.520000,33.626724,-350.331970,-0.001802,0.002773,0.070436,149.579147,7.619925,0.704361,-350.331970,0.071338,0.000000
46.730003,33.786476,-350.376465,-0.001785,0.002784,0.070705,150.289749,7.656125,0.707049,-350.376465,0.071685,0.000000
46.940002,34.204277,-350.376465,-0.001776,0.002798,0.071069,152.148224,7.750800,0.710692,-350.376465,0.072032,0.000000
47.150002,34.709587,-350.376465,-0.001763,0.002812,0.071425,154.395950,7.865305,0.714247,-350.376465,0.072387,0.000000
47.360001,35.315804,-350.420929,-0.001763,0.002828,0.071832,157.092545,8.002675,0.718323,-350.420929,0.072734,0.000000
47.570004,35.519119,-350.331970,-0.001738,0.002839,0.072110,157.996933,8.048747,0.721098,-350.331970,0.073081,0.000000
47.780003,35.866173,-350.420929,-0.001742,0.002851,0.072422,159.540710,8.127391,0.724220,-350.420929,0.073437,0.000000
47.990002,36.675713,-350.376465,-0.001729,0.002868,0.072847,163.141724,8.310835,0.728470,-350.376465,0.073784,0.000000
48.200001,36.883492,-350.420929,-0.001707,0.002881,0.073177,164.065964,8.357919,0.731765,-350.420929,0.074139,0.000000
48.410004,37.856873,-350.420929,-0.001707,0.002897,0.073593,168.395782,8.578489,0.735928,-350.420929,0.074486,0.000000
48.620003,38.317871,-350.420929,-0.001686,0.002912,0.073966,170.446396,8.682954,0.739657,-350.420929,0.074833,0.000000
48.830002,38.339844,-350.465424,-0.001677,0.002921,0.074200,170.544144,8.687933,0.741998,-350.465424,0.075188,0.000000
49.040001,38.855949,-350.465424,-0.001673,0.002936,0.074581,172.839890,8.804885,0.745814,-350.465424,0.075535,0.000000
49.250004,39.714272,-350.465424,-0.001664,0.002953,0.075006,176.657898,8.999383,0.750064,-350.465424,0.075882,0.000000
49.460003,40.040840,-350.509888,-0.001651,0.002964,0.075284,178.110550,9.073384,0.752839,-350.509888,0.076238,0.000000
49.670002,40.391243,-350.420929,-0.001634,0.002978,0.075631,179.669220,9.152786,0.756308,-350.420929,0.076585,0.000000
49.880001,40.739410,-350.554382,-0.001634,0.002989,0.075917,181.217941,9.231683,0.759169,-350.554382,0.076932,0.000000
50.090004,41.365738,-350.465424,-0.001621,0.003001,0.076220,184.003998,9.373610,0.762205,-350.465424,0.077287,0.000000
50.300003,42.805702,-350.509888,-0.001600,0.003023,0.076793,190.409271,9.699910,0.767928,-350.509888,0.077634,0.000000
50.510002,43.077538,-350.509888,-0.001613,0.003035,0.077079,191.618454,9.761510,0.770790,-350.509888,0.077990,0.000000
50.720001,43.544495,-350.554382,-0.001591,0.003048,0.077426,193.695587,9.867324,0.774259,-350.554382,0.078336,0.000000
50.930004,44.082573,-350.598846,-0.001591,0.003062,0.077764,196.089081,9.989254,0.777641,-350.598846,0.078683,0.000000
51.140003,44.243065,-350.509888,-0.001569,0.003071,0.078016,196.802979,10.025622,0.780156,-350.509888,0.079039,0.000000
51.350002,45.223145,-350.554382,-0.001574,0.003088,0.078441,201.162598,10.247711,0.784406,-350.554382,0.079386,0.000000
51.560001,45.521049,-350.554382,-0.001561,0.003101,0.078753,202.487747,10.315217,0.787528,-350.554382,0.079733,0.000000
51.770004,45.858040,-350.598846,-0.001535,0.003111,0.079013,203.986755,10.391581,0.790129,-350.598846,0.080088,0.000000
51.980003,46.729767,-350.643341,-0.001539,0.003126,0.079412,207.864380,10.589116,0.794119,-350.643341,0.080435,0.000000
52.190002,47.807785,-350.554382,-0.001522,0.003145,0.079889,212.659653,10.833399,0.798888,-350.554382,0.080782,0.000000
52.400002,48.416245,-350.643341,-0.001509,0.003156,0.080175,215.366211,10.971278,0.801750,-350.643341,0.081138,0.000000
52.610001,48.661636,-350.554382,-0.001518,0.003168,0.080461,216.457764,11.026885,0.804612,-350.554382,0.081485,0.000000
52.820004,49.635391,-350.643341,-0.001500,0.003185,0.080895,220.789246,11.247540,0.808948,-350.643341,0.081831,0.000000
53.030003,50.221504,-350.643341,-0.001505,0.003199,0.081250,223.396408,11.380356,0.812504,-350.643341,0.082187,0.000000
53.240002,50.889168,-350.598846,-0.001487,0.003214,0.081623,226.366318,11.531650,0.816233,-350.598846,0.082534,0.000000
53.450001,51.614174,-350.687805,-0.001470,0.003225,0.081927,229.591309,11.695939,0.819268,-350.687805,0.082889,0.000000
53.660004,51.659981,-350.598846,-0.001466,0.003233,0.082109,229.795074,11.706319,0.821089,-350.598846,0.083236,0.000000
53.870003,52.620697,-350.643341,-0.001462,0.003250,0.082560,234.068558,11.924020,0.825599,-350.643341,0.083583,0.000000
54.080002,53.466728,-350.687805,-0.001466,0.003266,0.082959,237.831879,12.115733,0.829588,-350.687805,0.083939,0.000000
54.290001,54.404366,-350.776794,-0.001449,0.003282,0.083358,242.002701,12.328205,0.833577,-350.776794,0.084286,0.000000
54.500004,54.679550,-350.732300,-0.001444,0.003292,0.083627,243.226791,12.390563,0.836266,-350.732300,0.084633,0.000000
54.710003,55.490570,-350.643341,-0.001436,0.003306,0.083973,246.834381,12.574343,0.839735,-350.643341,0.084988,0.000000
54.920002,56.071472,-350.732300,-0.001423,0.003318,0.084268,249.418365,12.705977,0.842683,-350.732300,0.085335,0.000000
55.130001,56.944687,-350.776794,-0.001414,0.003334,0.084676,253.302612,12.903851,0.846759,-350.776794,0.085682,0.000000
55.340004,57.625755,-350.687805,-0.001410,0.003347,0.085005,256.332153,13.058183,0.850055,-350.687805,0.086037,0.000000
55.550003,58.140007,-350.776794,-0.001406,0.003356,0.085240,258.619659,13.174714,0.852396,-350.776794,0.086384,0.000000
55.760002,58.339226,-350.732300,-0.001393,0.003368,0.085543,259.505829,13.219857,0.855431,-350.732300,0.086740,0.000000
55.970001,59.849937,-350.732300,-0.001384,0.003385,0.085977,266.225830,13.562189,0.859768,-350.732300,0.087087,0.000000
56.180004,61.472740,-350.776794,-0.001384,0.003406,0.086514,273.444397,13.929922,0.865144,-350.776794,0.087434,0.000000
56.390003,61.651848,-350.776794,-0.001371,0.003414,0.086714,274.241119,13.970509,0.867139,-350.776794,0.087789,0.000000
56.600002,62.860939,-350.865753,-0.001362,0.003432,0.087174,279.619415,14.244493,0.871735,-350.865753,0.088136,0.000000
56.810001,63.446686,-350.776794,-0.001362,0.003443,0.087460,282.224945,14.377225,0.874597,-350.776794,0.088483,0.000000
57.020004,64.301285,-350.821259,-0.001354,0.003458,0.087841,286.026398,14.570879,0.878413,-350.821259,0.088839,0.000000
57.230003,65.129807,-350.865753,-0.001345,0.003470,0.088136,289.711853,14.758625,0.881362,-350.865753,0.089185,0.000000
57.440002,65.415787,-350.776794,-0.001328,0.003478,0.088344,290.983948,14.823429,0.883443,-350.776794,0.089532,0.000000
57.650002,66.757080,-350.865753,-0.001332,0.003498,0.088847,296.950317,15.127371,0.888473,-350.865753,0.089888,0.000000
57.860004,67.737900,-350.821259,-0.001324,0.003503,0.088969,301.313232,15.349627,0.889687,-350.821259,0.089212,0.000000
58.070004,66.947723,-350.821259,-0.001315,0.003503,0.088969,297.798340,15.170571,0.889687,-350.821259,0.089212,0.000000
58.280003,66.404068,-350.821259,-0.001306,0.003501,0.088925,295.380035,15.047377,0.889253,-350.821259,0.088969,0.000000
58.490002,65.845139,-350.910217,-0.001298,0.003499,0.088882,292.893799,14.920721,0.888820,-350.910217,0.088969,0.000000
58.700005,65.300354,-350.910217,-0.001298,0.003498,0.088856,290.470490,14.797272,0.888559,-350.910217,0.088969,0.000000
58.910004,64.857224,-350.865753,-0.001298,0.003498,0.088839,288.499329,14.696856,0.888386,-350.865753,0.088969,0.000000
59.120003,64.407410,-350.865753,-0.001289,0.003497,0.088830,286.498474,14.594928,0.888299,-350.865753,0.088969,0.000000
59.330002,64.011948,-350.954712,-0.001285,0.003497,0.088821,284.739349,14.505315,0.888213,-350.954712,0.088969,0.000000
59.540005,63.658936,-350.910217,-0.001298,0.003497,0.088821,283.169098,14.425322,0.888213,-350.910217,0.088969,0.000000
59.750004,63.298111,-350.999176,-0.001289,0.003497,0.088821,281.564056,14.343556,0.888213,-350.999176,0.088969,0.000000
59.960003,62.997231,-350.910217,-0.001289,0.003497,0.088813,280.225677,14.275377,0.888126,-350.910217,0.088969,0.000000
60.170002,62.678848,-350.954712,-0.001285,0.003497,0.088813,278.809448,14.203230,0.888126,-350.954712,0.088969,0.000000
60.380001,62.413353,-350.954712,-0.001289,0.003497,0.088813,277.628448,14.143068,0.888126,-350.954712,0.088969,0.000000
60.590004,62.156784,-350.865753,-0.001272,0.003497,0.088813,276.487183,14.084929,0.888126,-350.865753,0.088969,0.000000
60.800003,61.886444,-350.999176,-0.001281,0.003497,0.088813,275.284637,14.023669,0.888126,-350.999176,0.088969,0.000000
61.010002,61.675308,-350.954712,-0.001272,0.003497,0.088813,274.345459,13.975824,0.888126,-350.954712,0.088969,0.000000
61.220001,61.444435,-350.999176,-0.001268,0.003497,0.088813,273.318512,13.923508,0.888126,-350.999176,0.088969,0.000000
61.430004,61.235535,-350.999176,-0.001272,0.003497,0.088813,272.389252,13.876170,0.888126,-350.999176,0.088969,0.000000
61.640003,61.045998,-350.999176,-0.001255,0.003497,0.088813,271.546173,13.833221,0.888126,-350.999176,0.088969,0.000000
61.850002,60.844170,-351.088135,-0.001272,0.003496,0.088804,270.648376,13.787486,0.888039,-351.088135,0.088969,0.000000
62.060001,60.676979,-350.999176,-0.001259,0.003496,0.088804,269.904694,13.749599,0.888039,-350.999176,0.088969,0.000000
62.270004,60.496750,-351.088135,-0.001268,0.003496,0.088804,269.102997,13.708759,0.888039,-351.088135,0.088969,0.000000
62.480003,60.324341,-351.088135,-0.001272,0.003496,0.088804,268.336060,13.669691,0.888039,-351.088135,0.088969,0.000000
62.690002,60.186562,-351.177094,-0.001263,0.003496,0.088804,267.723206,13.638470,0.888039,-351.177094,0.088969,0.000000
62.900002,60.013412,-351.088135,-0.001259,0.003496,0.088804,266.953003,13.599234,0.888039,-351.088135,0.088969,0.000000
63.110004,59.897232,-351.043671,-0.001268,0.003496,0.088804,266.436188,13.572906,0.888039,-351.043671,0.088969,0.000000
63.320004,59.743439,-351.088135,-0.001268,0.003496,0.088804,265.752075,13.538056,0.888039,-351.088135,0.088969,0.000000
63.530003,59.614967,-351.132629,-0.001268,0.003496,0.088804,265.180634,13.508945,0.888039,-351.132629,0.088969,0.000000
63.740002,59.488365,-351.088135,-0.001255,0.003496,0.088804,264.617462,13.480256,0.888039,-351.088135,0.088969,0.000000
63.950005,59.353195,-351.132629,-0.001255,0.003496,0.088804,264.016205,13.449626,0.888039,-351.132629,0.088969,0.000000
64.160004,59.245949,-351.132629,-0.001268,0.003496,0.088804,263.539154,13.425324,0.888039,-351.132629,0.088969,0.000000
64.370003,59.121574,-351.221588,-0.001255,0.003496,0.088804,262.985901,13.397141,0.888039,-351.221588,0.088969,0.000000
64.580002,59.013588,-351.132629,-0.001263,0.003496,0.088804,262.505554,13.372670,0.888039,-351.132629,0.088969,0.000000
64.790001,58.908951,-351.177094,-0.001255,0.003496,0.088804,262.040100,13.348960,0.888039,-351.177094,0.088969,0.000000
65.000000,58.783463,-351.177094,-0.001263,0.003496,0.088804,261.481903,13.320523,0.888039,-351.177094,0.088969,0.000000
65.210007,58.703773,-351.177094,-0.001250,0.003496,0.088804,261.127441,13.302465,0.888039,-351.177094,0.088969,0.000000
65.420006,58.601746,-351.266083,-0.001259,0.003496,0.088804,260.673584,13.279346,0.888039,-351.266083,0.088969,0.000000
65.630005,58.499344,-351.177094,-0.001263,0.003496,0.088804,260.218079,13.256141,0.888039,-351.177094,0.088969,0.000000
65.840004,58.423004,-351.221588,-0.001242,0.003496,0.088804,259.878510,13.238842,0.888039,-351.221588,0.088969,0.000000
66.050003,58.316879,-351.221588,-0.001255,0.003496,0.088804,259.406433,13.214794,0.888039,-351.221588,0.088969,0.000000
66.260002,58.242775,-351.177094,-0.001246,0.003496,0.088804,259.076813,13.198002,0.888039,-351.177094,0.088969,0.000000
66.470001,58.151917,-351.266083,-0.001246,0.003496,0.088804,258.672638,13.177413,0.888039,-351.266083,0.088969,0.000000
66.680000,58.068138,-351.221588,-0.001255,0.003496,0.088804,258.299988,13.158428,0.888039,-351.221588,0.088969,0.000000
66.889999,57.985466,-351.266083,-0.001255,0.003496,0.088804,257.932220,13.139695,0.888039,-351.266083,0.088969,0.000000
67.100006,57.900192,-351.266083,-0.001263,0.003496,0.088804,257.552917,13.120372,0.888039,-351.266083,0.088969,0.000000
67.310005,57.834656,-351.310547,-0.001246,0.003496,0.088804,257.261383,13.105520,0.888039,-351.310547,0.088969,0.000000
67.520004,57.750130,-351.310547,-0.001242,0.003496,0.088804,256.885406,13.086367,0.888039,-351.310547,0.088969,0.000000
67.730003,57.676025,-351.266083,-0.001255,0.003496,0.088804,256.555786,13.069574,0.888039,-351.266083,0.088969,0.000000
67.940002,57.608253,-351.310547,-0.001237,0.003496,0.088804,256.254303,13.054217,0.888039,-351.310547,0.088969,0.000000
68.150002,57.534897,-351.310547,-0.001246,0.003496,0.088804,255.928009,13.037595,0.888039,-351.310547,0.088969,0.000000
68.360001,57.471222,-351.310547,-0.001246,0.003496,0.088804,255.644760,13.023165,0.888039,-351.310547,0.088969,0.000000
68.570000,57.396378,-351.355042,-0.001246,0.003496,0.088804,255.311844,13.006205,0.888039,-351.355042,0.088969,0.000000
68.780006,57.339027,-351.310547,-0.001242,0.003496,0.088804,255.056732,12.993209,0.888039,-351.310547,0.088969,0.000000
68.990005,57.285408,-351.310547,-0.001246,0.003496,0.088804,254.818222,12.981058,0.888039,-351.310547,0.088969,0.000000
69.200005,57.207581,-351.310547,-0.001237,0.003496,0.088804,254.472031,12.963423,0.888039,-351.310547,0.088969,0.000000
69.410004,57.171463,-351.355042,-0.001246,0.003496,0.088804,254.311371,12.955238,0.888039,-351.355042,0.088969,0.000000
69.620003,57.090660,-351.399506,-0.001255,0.003496,0.088804,253.951935,12.936929,0.888039,-351.399506,0.088969,0.000000
69.830002,57.040390,-351.355042,-0.001242,0.003496,0.088804,253.728333,12.925537,0.888039,-351.355042,0.088969,0.000000
70.040001,56.976715,-351.444000,-0.001237,0.003496,0.088804,253.445084,12.911108,0.888039,-351.444000,0.088969,0.000000
70.250000,56.915642,-351.399506,-0.001246,0.003496,0.088804,253.173416,12.897268,0.888039,-351.399506,0.088969,0.000000
70.460007,56.869469,-351.399506,-0.001237,0.003496,0.088804,252.968033,12.886806,0.888039,-351.399506,0.088969,0.000000
70.670006,56.808403,-351.399506,-0.001250,0.003496,0.088804,252.696396,12.872969,0.888039,-351.399506,0.088969,0.000000
70.880005,56.753662,-351.399506,-0.001237,0.003496,0.088804,252.452896,12.860563,0.888039,-351.399506,0.088969,0.000000
71.090004,56.690361,-351.444000,-0.001246,0.003496,0.088804,252.171326,12.846220,0.888039,-351.444000,0.088969,0.000000
71.300003,56.653496,-351.444000,-0.001242,0.003496,0.088804,252.007339,12.837866,0.888039,-351.444000,0.088969,0.000000
71.510002,56.596146,-351.444000,-0.001242,0.003496,0.088804,251.752228,12.824870,0.888039,-351.444000,0.088969,0.000000
71.720001,56.546997,-351.488464,-0.001242,0.003496,0.088804,251.533600,12.813732,0.888039,-351.488464,0.088969,0.000000
71.930000,56.498215,-351.399506,-0.001242,0.003496,0.088804,251.316605,12.802679,0.888039,-351.399506,0.088969,0.000000
72.140007,56.451668,-351.532959,-0.001229,0.003496,0.088804,251.109558,12.792130,0.888039,-351.532959,0.088969,0.000000
72.350006,56.398788,-351.444000,-0.001237,0.003496,0.088795,250.874344,12.780148,0.887952,-351.444000,0.088969,0.000000
72.560005,56.354851,-351.488464,-0.001237,0.003496,0.088795,250.678894,12.770191,0.887952,-351.488464,0.088969,0.000000
72.770004,56.307190,-351.532959,-0.001233,0.003496,0.088795,250.466888,12.759392,0.887952,-351.532959,0.088969,0.000000
72.980003,56.266968,-351.488464,-0.001224,0.003496,0.088795,250.287979,12.750278,0.887952,-351.488464,0.088969,0.000000
73.190002,56.207390,-351.532959,-0.001237,0.003496,0.088795,250.022964,12.736776,0.887952,-351.532959,0.088969,0.000000
73.400002,56.180206,-351.532959,-0.001233,0.003496,0.088795,249.902039,12.730617,0.887952,-351.532959,0.088969,0.000000
73.610001,56.112061,-351.532959,-0.001229,0.003496,0.088795,249.598907,12.715175,0.887952,-351.532959,0.088969,0.000000
73.820000,56.085999,-351.577423,-0.001237,0.003496,0.088795,249.482986,12.709269,0.887952,-351.577423,0.088969,0.000000
74.030006,56.037216,-351.532959,-0.001233,0.003496,0.088795,249.265991,12.698215,0.887952,-351.532959,0.088969,0.000000
74.240005,56.002213,-351.621918,-0.001233,0.003496,0.088795,249.110275,12.690283,0.887952,-351.621918,0.088969,0.000000
74.450005,55.966469,-351.577423,-0.001233,0.003496,0.088795,248.951294,12.682183,0.887952,-351.577423,0.088969,0.000000
74.660004,55.913589,-351.577423,-0.001242,0.003496,0.088795,248.716064,12.670200,0.887952,-351.577423,0.088969,0.000000
74.870003,55.881935,-351.666412,-0.001229,0.003496,0.088795,248.575256,12.663027,0.887952,-351.666412,0.088969,0.000000
75.080002,55.832413,-351.621918,-0.001229,0.003496,0.088795,248.354980,12.651805,0.887952,-351.621918,0.088969,0.000000
75.290001,55.817146,-351.666412,-0.001242,0.003496,0.088795,248.287064,12.648347,0.887952,-351.666412,0.088969,0.000000
75.500000,55.753838,-351.666412,-0.001233,0.003496,0.088795,248.005463,12.634000,0.887952,-351.666412,0.088969,0.000000
75.710007,55.734108,-351.621918,-0.001229,0.003496,0.088795,247.917694,12.629530,0.887952,-351.621918,0.088969,0.000000
75.920006,55.696121,-351.621918,-0.001229,0.003496,0.088795,247.748718,12.620921,0.887952,-351.621918,0.088969,0.000000
76.130005,55.658890,-351.621918,-0.001233,0.003496,0.088795,247.583099,12.612485,0.887952,-351.621918,0.088969,0.000000
76.340004,55.615318,-351.666412,-0.001229,0.003496,0.088795,247.389297,12.602612,0.887952,-351.666412,0.088969,0.000000
76.550003,55.570633,-351.666412,-0.001237,0.003496,0.088795,247.190521,12.592485,0.887952,-351.666412,0.088969,0.000000
76.760002,55.546432,-351.710876,-0.001229,0.003496,0.088795,247.082870,12.587002,0.887952,-351.710876,0.088969,0.000000
76.970001,55.512543,-351.621918,-0.001224,0.003496,0.088795,246.932129,12.579322,0.887952,-351.621918,0.088969,0.000000
77.180000,55.468979,-351.710876,-0.001216,0.003496,0.088795,246.738342,12.569450,0.887952,-351.710876,0.088969,0.000000
77.390007,55.437698,-351.710876,-0.001220,0.003496,0.088795,246.599197,12.562362,0.887952,-351.710876,0.088969,0.000000
77.600006,55.411629,-351.666412,-0.001250,0.003496,0.088795,246.483231,12.556455,0.887952,-351.666412,0.088969,0.000000
77.810005,55.379608,-351.799835,-0.001220,0.003496,0.088795,246.340805,12.549198,0.887952,-351.799835,0.088969,0.000000
78.020004,55.352798,-351.755371,-0.001237,0.003496,0.088795,246.221542,12.543123,0.887952,-351.755371,0.088969,0.000000
78.230003,55.322632,-351.710876,-0.001216,0.003496,0.088795,246.087357,12.536287,0.887952,-351.710876,0.088969,0.000000
78.440002,55.273483,-351.799835,-0.001237,0.003496,0.088795,245.868729,12.525150,0.887952,-351.799835,0.088969,0.000000
78.650002,55.260445,-351.710876,-0.001224,0.003496,0.088795,245.810730,12.522196,0.887952,-351.710876,0.088969,0.000000
78.860001,55.213531,-351.710876,-0.001233,0.003496,0.088795,245.602051,12.511565,0.887952,-351.710876,0.088969,0.000000
79.070007,55.183739,-351.799835,-0.001237,0.003496,0.088795,245.469528,12.504814,0.887952,-351.799835,0.088969,0.000000
79.280006,55.146126,-351.799835,-0.001216,0.003496,0.088795,245.302216,12.496290,0.887952,-351.799835,0.088969,0.000000
79.490005,55.137939,-351.844330,-0.001229,0.003496,0.088795,245.265808,12.494435,0.887952,-351.844330,0.088969,0.000000
79.700005,55.101074,-351.799835,-0.001224,0.003496,0.088795,245.101822,12.486082,0.887952,-351.799835,0.088969,0.000000
79.910004,55.073891,-351.844330,-0.001242,0.003496,0.088795,244.980896,12.479922,0.887952,-351.844330,0.088969,0.000000
80.120003,55.044472,-351.799835,-0.001233,0.003496,0.088795,244.850037,12.473256,0.887952,-351.799835,0.088969,0.000000
80.330002,55.005745,-351.799835,-0.001233,0.003496,0.088795,244.677780,12.464479,0.887952,-351.799835,0.088969,0.000000
80.540001,54.982658,-351.844330,-0.001237,0.003496,0.088795,244.575073,12.459249,0.887952,-351.844330,0.088969,0.000000
80.750008,54.952492,-351.844330,-0.001224,0.003496,0.088795,244.440887,12.452413,0.887952,-351.844330,0.088969,0.000000
80.960007,54.929779,-351.844330,-0.001229,0.003496,0.088795,244.339859,12.447267,0.887952,-351.844330,0.088969,0.000000
81.170006,54.902222,-351.799835,-0.001224,0.003496,0.088795,244.217285,12.441021,0.887952,-351.799835,0.088969,0.000000
81.380005,54.871315,-351.933289,-0.001220,0.003496,0.088795,244.079803,12.434018,0.887952,-351.933289,0.088969,0.000000
81.590004,54.844131,-351.977753,-0.001233,0.003496,0.088795,243.958878,12.427857,0.887952,-351.977753,0.088969,0.000000
81.800003,54.815460,-351.888794,-0.001220,0.003496,0.088795,243.831345,12.421361,0.887952,-351.888794,0.088969,0.000000
82.010002,54.796844,-351.933289,-0.001220,0.003496,0.088795,243.748535,12.417142,0.887952,-351.933289,0.088969,0.000000
82.220001,54.763702,-351.844330,-0.001224,0.003496,0.088795,243.601120,12.409633,0.887952,-351.844330,0.088969,0.000000
82.430000,54.738007,-351.933289,-0.001224,0.003496,0.088795,243.486816,12.403810,0.887952,-351.933289,0.088969,0.000000
82.640007,54.721626,-351.933289,-0.001229,0.003496,0.088795,243.413956,12.400097,0.887952,-351.933289,0.088969,0.000000
82.850006,54.691093,-351.933289,-0.001216,0.003496,0.088795,243.278137,12.393179,0.887952,-351.933289,0.088969,0.000000
83.060005,54.666512,-351.977753,-0.001237,0.003496,0.088795,243.168793,12.387609,0.887952,-351.977753,0.088969,0.000000
83.270004,54.640076,-351.933289,-0.001220,0.003496,0.088795,243.051193,12.381618,0.887952,-351.933289,0.088969,0.000000
83.480003,54.619225,-351.977753,-0.001220,0.003496,0.088795,242.958450,12.376893,0.887952,-351.977753,0.088969,0.000000
83.690002,54.598366,-351.977753,-0.001224,0.003496,0.088795,242.865662,12.372167,0.887952,-351.977753,0.088969,0.000000
83.900002,54.574539,-351.933289,-0.001216,0.003496,0.088795,242.759674,12.366768,0.887952,-351.933289,0.088969,0.000000
84.110001,54.536186,-352.066742,-0.001216,0.003496,0.088795,242.589066,12.358076,0.887952,-352.066742,0.088969,0.000000
84.320007,54.524269,-352.022247,-0.001220,0.003496,0.088795,242.536057,12.355376,0.887952,-352.022247,0.088969,0.000000
84.530006,54.501923,-351.977753,-0.001224,0.003496,0.088795,242.436661,12.350312,0.887952,-351.977753,0.088969,0.000000
84.740005,54.470276,-352.022247,-0.001229,0.003496,0.088795,242.295883,12.343142,0.887952,-352.022247,0.088969,0.000000
84.950005,54.456497,-351.977753,-0.001224,0.003496,0.088795,242.234604,12.340018,0.887952,-351.977753,0.088969,0.000000
85.160004,54.422234,-352.066742,-0.001220,0.003496,0.088795,242.082184,12.332254,0.887952,-352.066742,0.088969,0.000000
85.370003,54.402504,-352.111206,-0.001220,0.003496,0.088795,241.994431,12.327784,0.887952,-352.111206,0.088969,0.000000
85.580002,54.380905,-352.022247,-0.001229,0.003496,0.088795,241.898346,12.322889,0.887952,-352.022247,0.088969,0.000000
85.790001,54.359306,-352.066742,-0.001224,0.003496,0.088795,241.802277,12.317995,0.887952,-352.066742,0.088969,0.000000
86.000008,54.349998,-352.066742,-0.001224,0.003496,0.088795,241.760864,12.315886,0.887952,-352.066742,0.088969,0.000000
86.210007,54.306801,-352.022247,-0.001229,0.003496,0.088795,241.568710,12.306097,0.887952,-352.022247,0.088969,0.000000
86.420006,54.305313,-352.066742,-0.001224,0.003496,0.088795,241.562103,12.305760,0.887952,-352.066742,0.088969,0.000000
86.630005,54.268448,-352.066742,-0.001216,0.003496,0.088795,241.398117,12.297406,0.887952,-352.066742,0.088969,0.000000
86.840004,54.258018,-352.111206,-0.001229,0.003496,0.088795,241.351715,12.295043,0.887952,-352.111206,0.088969,0.000000
87.050003,54.239777,-352.111206,-0.001216,0.003496,0.088795,241.270569,12.290910,0.887952,-352.111206,0.088969,0.000000
87.260002,54.206261,-352.155701,-0.001224,0.003496,0.088795,241.121490,12.283315,0.887952,-352.155701,0.088969,0.000000
87.470001,54.193230,-352.155701,-0.001224,0.003496,0.088795,241.063522,12.280361,0.887952,-352.155701,0.088969,0.000000
87.680008,54.151154,-352.200165,-0.001220,0.003496,0.088795,240.876358,12.270827,0.887952,-352.200165,0.088969,0.000000
87.890007,54.152641,-352.200165,-0.001237,0.003496,0.088795,240.882980,12.271164,0.887952,-352.200165,0.088969,0.000000
88.100006,54.115028,-352.066742,-0.001224,0.003496,0.088795,240.715668,12.262641,0.887952,-352.066742,0.088969,0.000000
88.300003,54.110558,-352.155701,-0.001224,0.003496,0.088795,240.695786,12.261628,0.887952,-352.155701,0.088969,0.000000