File: Data/compression 11/AutoNoHeating-14-11-4-240530_05302024_163822.csv
Time (sec),S:Load (lbs),S:HL1 (DIM),S:LVDT (in),S:Position (in),Ch:Position (mm),Ch:Load (N),Ch:Stress (MPa),Ch:Strain (mm/mm),Ch:HL1 (DIM),Set Point (),Cycles ()
0.110000,-0.003349,-192.202194,-0.007558,-0.000000,-0.000000,-0.014898,-0.000759,-0.000000,-192.202194,0.000191,0.000000
0.340000,-0.024200,-192.157715,-0.007567,0.000001,0.000017,-0.107649,-0.005484,0.000173,-192.157715,0.000434,0.000000
0.570000,-0.023827,-192.157715,-0.007554,0.000125,0.003174,-0.105986,-0.005399,0.031740,-192.157715,0.004267,0.000000
0.800000,-0.018990,-192.157715,-0.007429,0.000275,0.006972,-0.084470,-0.004303,0.069725,-192.157715,0.008083,0.000000
1.030000,-0.055855,-192.246674,-0.007265,0.000426,0.010814,-0.248455,-0.012657,0.108143,-192.246674,0.011916,0.000000
1.260000,-0.008934,-192.246674,-0.007123,0.000574,0.014587,-0.039741,-0.002024,0.145867,-192.246674,0.015749,0.000000
1.490000,0.004471,-192.246674,-0.006963,0.000727,0.018455,0.019887,0.001013,0.184546,-192.246674,0.019582,0.000000
1.720000,0.027557,-192.246674,-0.006808,0.000870,0.022106,0.122581,0.006245,0.221056,-192.246674,0.023415,0.000000
1.950000,0.017502,-192.291153,-0.006674,0.001027,0.026077,0.077852,0.003966,0.260775,-192.291153,0.027248,0.000000
2.180000,0.016762,-192.246674,-0.006510,0.001179,0.029937,0.074560,0.003798,0.299366,-192.246674,0.031081,0.000000
2.410000,-0.005585,-192.335632,-0.006364,0.001325,0.033666,-0.024842,-0.001266,0.336657,-192.335632,0.034915,0.000000
2.640000,-0.021965,-192.291153,-0.006204,0.001476,0.037481,-0.097705,-0.004977,0.374815,-192.291153,0.038748,0.000000
2.870000,-0.005951,-192.246674,-0.006049,0.001627,0.041332,-0.026471,-0.001348,0.413320,-192.246674,0.042581,0.000000
3.100000,-0.015266,-192.291153,-0.005890,0.001781,0.045243,-0.067908,-0.003459,0.452432,-192.291153,0.046414,0.000000
3.330000,0.019737,-192.335632,-0.005743,0.001931,0.049059,0.087796,0.004473,0.490590,-192.335632,0.050247,0.000000
3.560000,0.000374,-192.380112,-0.005601,0.002083,0.052909,0.001663,0.000085,0.529094,-192.380112,0.054063,0.000000
3.790000,0.001495,-192.335632,-0.005433,0.002237,0.056829,0.006652,0.000339,0.568293,-192.335632,0.057896,0.000000
4.020000,0.009315,-192.380112,-0.005295,0.002385,0.060567,0.041437,0.002111,0.605670,-192.380112,0.061729,0.000000
4.250000,0.021599,-192.380112,-0.005135,0.002532,0.064322,0.096076,0.004894,0.643221,-192.380112,0.065562,0.000000
4.480000,0.002609,-192.469070,-0.004975,0.002687,0.068251,0.011607,0.000591,0.682507,-192.469070,0.069395,0.000000
4.710000,-0.024948,-192.424591,-0.004825,0.002841,0.072162,-0.110975,-0.005653,0.721618,-192.424591,0.073229,0.000000
4.940000,-0.033508,-192.380112,-0.004678,0.002986,0.075839,-0.149052,-0.007593,0.758389,-192.380112,0.077062,0.000000
5.170000,0.001495,-192.424591,-0.004523,0.003139,0.079724,0.006652,0.000339,0.797241,-192.424591,0.080895,0.000000
5.400000,0.157143,-192.469070,-0.004372,0.003286,0.083453,0.699005,0.035609,0.834531,-192.469070,0.084728,0.000000
5.630000,0.608459,-192.424591,-0.004247,-0.000004,-0.000104,2.706563,0.137879,-0.001041,-192.424591,0.000130,0.000000
5.860000,0.540314,-192.469070,-0.004264,-0.000004,-0.000104,2.403435,0.122437,-0.001041,-192.469070,0.000130,0.000000
6.090000,0.524307,-192.469070,-0.004255,-0.000004,-0.000104,2.332235,0.118810,-0.001041,-192.469070,0.000130,0.000000
6.320000,0.582024,-192.513550,-0.004247,-0.000004,-0.000104,2.588970,0.131888,-0.001041,-192.513550,0.000468,0.000000
6.550000,0.593941,-192.558044,-0.004247,-0.000004,-0.000104,2.641980,0.134589,-0.001041,-192.558044,0.000859,0.000000
6.780000,0.575317,-192.558044,-0.004247,-0.000004,-0.000104,2.559139,0.130369,-0.001041,-192.558044,0.001240,0.000000
7.010000,0.807678,-192.602524,-0.004230,0.000027,0.000676,3.592732,0.183022,0.006764,-192.602524,0.001622,0.000000
7.240000,0.974876,-192.602524,-0.004208,0.000043,0.001101,4.336467,0.220910,0.011014,-192.602524,0.002003,0.000000
7.470000,1.041901,-192.558044,-0.004199,0.000054,0.001379,4.634605,0.236098,0.013789,-192.558044,0.002385,0.000000
7.700000,1.211334,-192.558044,-0.004195,0.000076,0.001925,5.388284,0.274492,0.019252,-192.558044,0.002775,0.000000
7.930000,1.325653,-192.691483,-0.004165,0.000087,0.002203,5.896800,0.300397,0.022028,-192.691483,0.003157,0.000000
8.160001,1.502525,-192.691483,-0.004156,0.000106,0.002688,6.683567,0.340477,0.026884,-192.691483,0.003538,0.000000
8.390000,1.593758,-192.602524,-0.004139,0.000115,0.002923,7.089388,0.361151,0.029226,-192.602524,0.003920,0.000000
8.620001,1.683502,-192.691483,-0.004122,0.000127,0.003217,7.488592,0.381487,0.032174,-192.691483,0.004301,0.000000
8.850000,1.969109,-192.691483,-0.004113,0.000150,0.003798,8.759032,0.446206,0.037984,-192.691483,0.004692,0.000000
9.080001,2.160881,-192.691483,-0.004096,0.000168,0.004267,9.612079,0.489663,0.042668,-192.691483,0.005073,0.000000
9.310000,2.272217,-192.735962,-0.004079,0.000182,0.004622,10.107326,0.514892,0.046223,-192.735962,0.005455,0.000000
9.540001,2.348183,-192.691483,-0.004070,0.000194,0.004935,10.445238,0.532106,0.049345,-192.691483,0.005836,0.000000
9.770000,2.529533,-192.735962,-0.004057,0.000210,0.005333,11.251926,0.573200,0.053334,-192.735962,0.006218,0.000000
10.000000,2.687042,-192.780441,-0.004031,0.000227,0.005776,11.952560,0.608893,0.057757,-192.780441,0.006608,0.000000
10.230000,2.832268,-192.735962,-0.004023,0.000241,0.006131,12.598557,0.641801,0.061313,-192.735962,0.006990,0.000000
10.460000,2.891106,-192.735962,-0.004010,0.000251,0.006383,12.860280,0.655134,0.063828,-192.735962,0.007371,0.000000
10.690001,3.067238,-192.735962,-0.004001,0.000266,0.006764,13.643755,0.695046,0.067644,-192.735962,0.007753,0.000000
10.920000,3.336830,-192.824921,-0.003975,0.000290,0.007363,14.842961,0.756137,0.073627,-192.824921,0.008143,0.000000
11.150001,3.436256,-192.824921,-0.003967,0.000303,0.007701,15.285232,0.778667,0.077010,-192.824921,0.008525,0.000000
11.380000,3.448547,-192.869400,-0.003971,0.000314,0.007978,15.339905,0.781452,0.079785,-192.869400,0.008906,0.000000
11.610001,3.600471,-192.869400,-0.003945,0.000329,0.008360,16.015697,0.815878,0.083601,-192.869400,0.009288,0.000000
11.840000,3.676437,-192.913879,-0.003928,0.000342,0.008698,16.353611,0.833093,0.086983,-192.913879,0.009670,0.000000
12.070001,3.858902,-192.869400,-0.003898,0.000360,0.009149,17.165253,0.874440,0.091492,-192.869400,0.010060,0.000000
12.300000,3.975449,-192.913879,-0.003893,0.000375,0.009522,17.683678,0.900850,0.095221,-192.913879,0.010441,0.000000
12.530001,4.058861,-192.913879,-0.003885,0.000388,0.009843,18.054714,0.919751,0.098430,-192.913879,0.010823,0.000000
12.760000,4.183609,-192.913879,-0.003885,0.000404,0.010268,18.609623,0.948019,0.102680,-192.913879,0.011205,0.000000
12.990001,4.373894,-192.869400,-0.003854,0.000422,0.010728,19.456051,0.991138,0.107276,-192.869400,0.011586,0.000000
13.220000,4.453949,-192.913879,-0.003829,0.000437,0.011100,19.812155,1.009279,0.111005,-192.913879,0.011976,0.000000
13.450001,4.409637,-193.047333,-0.003820,0.000448,0.011378,19.615047,0.999238,0.113780,-193.047333,0.012358,0.000000
13.680000,4.617424,-193.002853,-0.003803,0.000467,0.011855,20.539328,1.046323,0.118550,-193.002853,0.012740,0.000000
13.910001,4.698601,-192.958359,-0.003790,0.000481,0.012211,20.900419,1.064718,0.122105,-192.958359,0.013121,0.000000
14.140000,4.806961,-192.958359,-0.003768,0.000498,0.012653,21.382431,1.089273,0.126528,-192.958359,0.013503,0.000000
14.370001,4.749985,-193.002853,-0.003764,0.000507,0.012870,21.128988,1.076362,0.128696,-193.002853,0.013893,0.000000
14.600000,4.890747,-193.047333,-0.003760,0.000522,0.013251,21.755129,1.108259,0.132512,-193.047333,0.014275,0.000000
14.830001,5.081024,-193.047333,-0.003738,0.000541,0.013746,22.601524,1.151377,0.137455,-193.047333,0.014656,0.000000
15.060000,5.082886,-193.002853,-0.003721,0.000556,0.014110,22.609804,1.151798,0.141098,-193.002853,0.015038,0.000000
15.290001,5.154755,-193.047333,-0.003695,0.000571,0.014500,22.929493,1.168084,0.145000,-193.047333,0.015419,0.000000
15.520000,5.171143,-193.047333,-0.003686,0.000583,0.014821,23.002392,1.171798,0.148209,-193.047333,0.015810,0.000000
15.750001,5.230347,-193.136292,-0.003669,0.000598,0.015185,23.265743,1.185213,0.151851,-193.136292,0.016191,0.000000
15.980000,5.401268,-193.091812,-0.003665,0.000616,0.015645,24.026039,1.223945,0.156448,-193.091812,0.016573,0.000000
16.210001,5.367752,-193.091812,-0.003643,0.000627,0.015931,23.876953,1.216350,0.159309,-193.091812,0.016954,0.000000
16.440001,5.419144,-193.091812,-0.003630,0.000642,0.016304,24.105555,1.227996,0.163038,-193.091812,0.017336,0.000000
16.670000,5.563248,-193.136292,-0.003604,0.000657,0.016694,24.746561,1.260650,0.166941,-193.136292,0.017726,0.000000
16.900002,5.613518,-193.180771,-0.003591,0.000674,0.017110,24.970175,1.272041,0.171104,-193.180771,0.018108,0.000000
17.130001,5.782578,-193.136292,-0.003570,0.000694,0.017622,25.722189,1.310351,0.176220,-193.136292,0.018489,0.000000
17.360001,5.713318,-193.180771,-0.003566,0.000705,0.017908,25.414106,1.294656,0.179082,-193.180771,0.018871,0.000000
17.590000,5.719643,-193.225250,-0.003544,0.000716,0.018194,25.442242,1.296090,0.181944,-193.225250,0.019252,0.000000
17.820002,5.887955,-193.180771,-0.003540,0.000736,0.018689,26.190931,1.334230,0.186887,-193.180771,0.019643,0.000000
18.050001,5.890564,-193.225250,-0.003531,0.000749,0.019018,26.202538,1.334821,0.190183,-193.225250,0.020024,0.000000
18.280001,5.937859,-193.225250,-0.003514,0.000762,0.019356,26.412914,1.345538,0.193565,-193.225250,0.020406,0.000000
18.510000,6.130745,-193.225250,-0.003479,0.000784,0.019912,27.270916,1.389247,0.199115,-193.225250,0.020787,0.000000
18.740002,6.053665,-193.269730,-0.003462,0.000793,0.020137,26.928047,1.371780,0.201370,-193.269730,0.021169,0.000000
18.970001,6.251022,-193.314209,-0.003466,0.000814,0.020666,27.805937,1.416502,0.206660,-193.314209,0.021559,0.000000
19.200001,6.232033,-193.314209,-0.003441,0.000830,0.021082,27.721466,1.412199,0.210823,-193.314209,0.021941,0.000000
19.430000,6.218994,-193.314209,-0.003423,0.000843,0.021403,27.663467,1.409244,0.214031,-193.314209,0.022322,0.000000
19.660002,6.269264,-193.269730,-0.003415,0.000857,0.021767,27.887079,1.420636,0.217674,-193.269730,0.022704,0.000000
19.890001,6.260330,-193.314209,-0.003389,0.000868,0.022045,27.847340,1.418611,0.220449,-193.314209,0.023094,0.000000
20.120001,6.328102,-193.403168,-0.003385,0.000883,0.022435,28.148804,1.433968,0.224351,-193.403168,0.023476,0.000000
20.350000,6.444656,-193.358688,-0.003376,0.000897,0.022791,28.667263,1.460380,0.227907,-193.358688,0.023857,0.000000
20.580002,6.603661,-193.403168,-0.003359,0.000918,0.023311,29.374550,1.496411,0.233110,-193.403168,0.024239,0.000000
20.810001,6.706062,-193.403168,-0.003328,0.000935,0.023753,29.830055,1.519616,0.237533,-193.403168,0.024621,0.000000
21.040001,6.716484,-193.403168,-0.003311,0.000949,0.024100,29.876413,1.521977,0.241002,-193.403168,0.025011,0.000000
21.270000,6.672920,-193.447662,-0.003307,0.000964,0.024482,29.682632,1.512105,0.244818,-193.447662,0.025392,0.000000
21.500002,6.619667,-193.403168,-0.003303,0.000974,0.024742,29.445749,1.500038,0.247419,-193.403168,0.025774,0.000000
21.730001,6.879211,-193.403168,-0.003277,0.000994,0.025254,30.600260,1.558852,0.252536,-193.403168,0.026156,0.000000
21.960001,6.809952,-193.447662,-0.003255,0.001002,0.025453,30.292179,1.543157,0.254531,-193.447662,0.026537,0.000000
22.190001,6.891502,-193.447662,-0.003229,0.001021,0.025930,30.654934,1.561637,0.259301,-193.447662,0.026927,0.000000
22.420002,6.982361,-193.492142,-0.003221,0.001037,0.026338,31.059092,1.582226,0.263376,-193.492142,0.027309,0.000000
22.650002,7.127960,-193.447662,-0.003212,0.001054,0.026763,31.706751,1.615219,0.267626,-193.447662,0.027691,0.000000
22.880001,7.191261,-193.492142,-0.003195,0.001069,0.027162,31.988327,1.629563,0.271615,-193.492142,0.028072,0.000000
23.110001,7.122002,-193.492142,-0.003178,0.001082,0.027491,31.680246,1.613869,0.274911,-193.492142,0.028454,0.000000
23.340002,7.110458,-193.492142,-0.003165,0.001094,0.027777,31.628899,1.611253,0.277772,-193.492142,0.028844,0.000000
23.570002,7.196472,-193.536621,-0.003147,0.001110,0.028194,32.011505,1.630744,0.281935,-193.536621,0.029226,0.000000
23.800001,7.498093,-193.581100,-0.003134,0.001130,0.028705,33.353184,1.699092,0.287052,-193.581100,0.029607,0.000000
24.030001,7.427719,-193.581100,-0.003113,0.001142,0.029009,33.040146,1.683145,0.290087,-193.581100,0.029989,0.000000
24.260000,7.505547,-193.625580,-0.003104,0.001157,0.029399,33.386337,1.700781,0.293990,-193.625580,0.030370,0.000000
24.490002,7.675720,-193.625580,-0.003074,0.001176,0.029859,34.143311,1.739343,0.298586,-193.625580,0.030760,0.000000
24.720001,7.699547,-193.625580,-0.003070,0.001192,0.030275,34.249294,1.744742,0.302748,-193.625580,0.031142,0.000000
24.950001,7.732315,-193.625580,-0.003057,0.001206,0.030639,34.395054,1.752168,0.306391,-193.625580,0.031524,0.000000
25.180000,7.781471,-193.670059,-0.003040,0.001222,0.031029,34.613712,1.763307,0.310293,-193.670059,0.031905,0.000000
25.410002,7.688377,-193.625580,-0.003027,0.001231,0.031255,34.199612,1.742211,0.312548,-193.625580,0.032287,0.000000
25.640001,7.977715,-193.714539,-0.003014,0.001251,0.031766,35.486645,1.807776,0.317665,-193.714539,0.032677,0.000000
25.870001,7.947174,-193.714539,-0.003001,0.001263,0.032070,35.350796,1.800855,0.320700,-193.714539,0.033059,0.000000
26.100000,7.995583,-193.759018,-0.002984,0.001277,0.032434,35.566128,1.811825,0.324342,-193.759018,0.033440,0.000000
26.330002,8.324760,-193.670059,-0.002958,0.001298,0.032981,37.030384,1.886418,0.329806,-193.670059,0.033822,0.000000
26.560001,8.278214,-193.714539,-0.002958,0.001310,0.033267,36.823334,1.875870,0.332668,-193.714539,0.034203,0.000000
26.790001,8.290504,-193.714539,-0.002940,0.001324,0.033631,36.878006,1.878655,0.336310,-193.714539,0.034594,0.000000
27.020000,8.433868,-193.803497,-0.002940,0.001340,0.034047,37.515720,1.911142,0.340473,-193.803497,0.034975,0.000000
27.250002,8.498291,-193.803497,-0.002906,0.001354,0.034403,37.802288,1.925740,0.344028,-193.803497,0.035357,0.000000
27.480001,8.604042,-193.759018,-0.002897,0.001372,0.034854,38.272690,1.949704,0.348538,-193.759018,0.035738,0.000000
27.710001,8.718735,-193.803497,-0.002876,0.001387,0.035235,38.782867,1.975693,0.352354,-193.803497,0.036120,0.000000
27.940001,8.675911,-193.892471,-0.002880,0.001399,0.035539,38.592381,1.965989,0.355389,-193.892471,0.036510,0.000000
28.170002,8.762299,-193.892471,-0.002850,0.001413,0.035894,38.976650,1.985565,0.358945,-193.892471,0.036892,0.000000
28.400002,8.944016,-193.803497,-0.002837,0.001431,0.036337,39.784969,2.026743,0.363368,-193.803497,0.037273,0.000000
28.630001,9.037483,-193.847992,-0.002811,0.001446,0.036736,40.200733,2.047923,0.367357,-193.847992,0.037655,0.000000
28.860001,8.914230,-193.892471,-0.002820,0.001456,0.036970,39.652477,2.019994,0.369698,-193.892471,0.038045,0.000000
29.090002,9.314156,-193.936951,-0.002781,0.001479,0.037577,41.431435,2.110618,0.375769,-193.936951,0.038427,0.000000
29.320002,9.208778,-193.936951,-0.002777,0.001490,0.037846,40.962692,2.086739,0.378457,-193.936951,0.038808,0.000000
29.550001,9.376717,-193.936951,-0.002746,0.001508,0.038305,41.709717,2.124794,0.383054,-193.936951,0.039190,0.000000
29.780001,9.291817,-193.847992,-0.002734,0.001518,0.038557,41.332066,2.105556,0.385569,-193.847992,0.039572,0.000000
30.010002,9.597534,-193.981430,-0.002738,0.001537,0.039042,42.691963,2.174832,0.390425,-193.981430,0.039962,0.000000
30.240002,9.706635,-193.981430,-0.002712,0.001555,0.039485,43.177265,2.199555,0.394848,-193.981430,0.040343,0.000000
30.470001,9.804939,-194.025909,-0.002699,0.001570,0.039866,43.614548,2.221831,0.398664,-194.025909,0.040725,0.000000
30.700001,9.851486,-194.025909,-0.002686,0.001584,0.040239,43.821598,2.232379,0.402393,-194.025909,0.041106,0.000000
30.930002,9.888725,-194.025909,-0.002660,0.001598,0.040595,43.987247,2.240817,0.405948,-194.025909,0.041488,0.000000
31.160002,9.988152,-194.070389,-0.002652,0.001614,0.040994,44.429516,2.263348,0.409938,-194.070389,0.041878,0.000000
31.390001,10.210457,-194.070389,-0.002626,0.001631,0.041436,45.418381,2.313723,0.414360,-194.070389,0.042260,0.000000
31.620001,10.218277,-194.070389,-0.002630,0.001644,0.041748,45.453167,2.315495,0.417482,-194.070389,0.042641,0.000000
31.850002,10.119598,-194.070389,-0.002604,0.001653,0.041982,45.014221,2.293134,0.419824,-194.070389,0.043023,0.000000
32.080002,10.377655,-194.114868,-0.002587,0.001669,0.042399,46.162113,2.351610,0.423987,-194.114868,0.043405,0.000000
32.310001,10.834923,-194.114868,-0.002583,0.001693,0.043014,48.196144,2.455229,0.430144,-194.114868,0.043795,0.000000
32.540001,10.727310,-194.159348,-0.002570,0.001705,0.043318,47.717461,2.430843,0.433179,-194.159348,0.044176,0.000000
32.770000,10.768646,-194.070389,-0.002548,0.001720,0.043682,47.901329,2.440210,0.436822,-194.070389,0.044558,0.000000
33.000000,10.806625,-194.070389,-0.002531,0.001733,0.044029,48.070271,2.448816,0.440291,-194.070389,0.044940,0.000000
33.230003,11.060959,-194.159348,-0.002509,0.001752,0.044497,49.201603,2.506449,0.444973,-194.159348,0.045321,0.000000
33.460003,11.078827,-194.248306,-0.002509,0.001763,0.044792,49.281082,2.510498,0.447922,-194.248306,0.045711,0.000000
33.690002,11.064682,-194.203827,-0.002501,0.001774,0.045070,49.218163,2.507293,0.450697,-194.203827,0.046093,0.000000
33.920002,11.229637,-194.203827,-0.002475,0.001789,0.045443,49.951920,2.544672,0.454426,-194.203827,0.046475,0.000000
34.150002,11.519348,-194.159348,-0.002466,0.001808,0.045920,51.240620,2.610322,0.459196,-194.159348,0.046856,0.000000
34.380001,11.823570,-194.203827,-0.002440,0.001828,0.046423,52.593868,2.679259,0.464226,-194.203827,0.047238,0.000000
34.610001,11.700691,-194.337280,-0.002453,0.001837,0.046657,52.047276,2.651415,0.466567,-194.337280,0.047628,0.000000
34.840000,11.809799,-194.292801,-0.002423,0.001853,0.047056,52.532612,2.676139,0.470557,-194.292801,0.048010,0.000000
35.070004,12.026146,-194.248306,-0.002406,0.001869,0.047481,53.494968,2.725164,0.474806,-194.248306,0.048391,0.000000
35.300003,12.200043,-194.292801,-0.002397,0.001886,0.047897,54.268501,2.764569,0.478969,-194.292801,0.048773,0.000000
35.530003,12.301697,-194.381760,-0.002380,0.001899,0.048244,54.720680,2.787604,0.482438,-194.381760,0.049154,0.000000
35.760002,12.189613,-194.337280,-0.002376,0.001909,0.048478,54.222107,2.762206,0.484779,-194.337280,0.049545,0.000000
35.990002,12.347878,-194.381760,-0.002367,0.001926,0.048912,54.926102,2.798069,0.489115,-194.381760,0.049926,0.000000
36.220001,12.697906,-194.292801,-0.002341,0.001942,0.049336,56.483109,2.877387,0.493365,-194.292801,0.050308,0.000000
36.450001,12.886322,-194.337280,-0.002315,0.001958,0.049744,57.321224,2.920082,0.497441,-194.337280,0.050689,0.000000
36.680000,13.038254,-194.381760,-0.002298,0.001974,0.050143,57.997051,2.954510,0.501430,-194.381760,0.051071,0.000000
36.910000,12.952232,-194.381760,-0.002298,0.001986,0.050438,57.614407,2.935018,0.504378,-194.381760,0.051461,0.000000
37.140003,13.214012,-194.426239,-0.002281,0.002003,0.050871,58.778862,2.994338,0.508715,-194.426239,0.051843,0.000000
37.370003,13.406532,-194.381760,-0.002255,0.002018,0.051262,59.635235,3.037964,0.512617,-194.381760,0.052224,0.000000
37.600002,13.400948,-194.470718,-0.002242,0.002030,0.051565,59.610394,3.036698,0.515652,-194.470718,0.052606,0.000000
37.830002,13.121292,-194.426239,-0.002233,0.002033,0.051635,58.366421,2.973327,0.516346,-194.426239,0.052996,0.000000
38.060001,14.099144,-194.470718,-0.002225,0.002062,0.052372,62.716125,3.194911,0.523718,-194.470718,0.053378,0.000000
38.290001,14.330009,-194.515198,-0.002207,0.002081,0.052857,63.743065,3.247226,0.528574,-194.515198,0.053759,0.000000
38.520000,14.498695,-194.470718,-0.002190,0.002097,0.053274,64.493416,3.285451,0.532737,-194.470718,0.054141,0.000000
38.750000,14.429436,-194.515198,-0.002186,0.002110,0.053586,64.185333,3.269757,0.535859,-194.515198,0.054522,0.000000
38.980003,14.483429,-194.515198,-0.002173,0.002125,0.053985,64.425507,3.281992,0.539848,-194.515198,0.054913,0.000000
39.210003,14.703133,-194.515198,-0.002147,0.002138,0.054306,65.402802,3.331778,0.543057,-194.515198,0.055294,0.000000
39.440002,14.713181,-194.515198,-0.002139,0.002149,0.054575,65.447495,3.334054,0.545745,-194.515198,0.055676,0.000000
39.670002,15.146996,-194.559677,-0.002117,0.002169,0.055104,67.377205,3.432358,0.551035,-194.559677,0.056057,0.000000
39.900002,15.432610,-194.559677,-0.002100,0.002184,0.055476,68.647675,3.497079,0.554764,-194.559677,0.056439,0.000000
40.130001,15.413986,-194.648636,-0.002087,0.002199,0.055849,68.564835,3.492859,0.558493,-194.648636,0.056829,0.000000
40.360001,15.863441,-194.604156,-0.002078,0.002220,0.056378,70.564110,3.594707,0.563783,-194.604156,0.057211,0.000000
40.590000,15.990425,-194.515198,-0.002070,0.002234,0.056734,71.128960,3.623482,0.567339,-194.515198,0.057592,0.000000
40.820004,15.871262,-194.515198,-0.002052,0.002244,0.056994,70.598900,3.596479,0.569941,-194.515198,0.057974,0.000000
41.050003,16.137878,-194.693115,-0.002044,0.002259,0.057384,71.784866,3.656895,0.573843,-194.693115,0.058356,0.000000
41.280003,16.263374,-194.693115,-0.002026,0.002272,0.057705,72.343102,3.685333,0.577052,-194.693115,0.058746,0.000000
41.510002,16.521797,-194.693115,-0.002022,0.002287,0.058087,73.492622,3.743893,0.580868,-194.693115,0.059127,0.000000
41.740002,16.834221,-194.693115,-0.001996,0.002305,0.058538,74.882355,3.814689,0.585377,-194.693115,0.059509,0.000000
41.970001,17.253510,-194.693115,-0.001975,0.002321,0.058963,76.747444,3.909701,0.589627,-194.693115,0.059891,0.000000
42.200001,17.688438,-194.693115,-0.001966,0.002340,0.059440,78.682106,4.008257,0.594396,-194.693115,0.060272,0.000000
42.430000,17.663864,-194.782089,-0.001962,0.002354,0.059795,78.572792,4.002689,0.597952,-194.782089,0.060662,0.000000
42.660004,17.693657,-194.782089,-0.001940,0.002366,0.060099,78.705315,4.009440,0.600987,-194.782089,0.061044,0.000000
42.890003,17.696259,-194.737610,-0.001940,0.002378,0.060402,78.716888,4.010029,0.604023,-194.737610,0.061426,0.000000
43.120003,18.423500,-194.737610,-0.001914,0.002399,0.060931,81.951820,4.174825,0.609313,-194.737610,0.061807,0.000000
43.350002,18.238808,-194.737610,-0.001901,0.002409,0.061191,81.130272,4.132973,0.611914,-194.737610,0.062189,0.000000
43.580002,18.638359,-194.782089,-0.001888,0.002423,0.061547,82.907562,4.223513,0.615470,-194.782089,0.062579,0.000000
43.810001,18.947807,-194.826569,-0.001884,0.002438,0.061929,84.284058,4.293634,0.619286,-194.826569,0.062961,0.000000
44.040001,19.525352,-194.871048,-0.001854,0.002458,0.062432,86.853104,4.424508,0.624316,-194.871048,0.063342,0.000000
44.270000,19.599457,-194.871048,-0.001841,0.002472,0.062787,87.182739,4.441300,0.627871,-194.871048,0.063724,0.000000
44.500004,19.625519,-194.826569,-0.001828,0.002484,0.063082,87.298668,4.447206,0.630820,-194.826569,0.064105,0.000000
44.730003,19.772606,-194.871048,-0.001828,0.002497,0.063429,87.952942,4.480536,0.634289,-194.871048,0.064496,0.000000
44.960003,20.202698,-194.915527,-0.001811,0.002515,0.063880,89.866089,4.577997,0.638798,-194.915527,0.064877,0.000000
45.190002,20.824936,-194.871048,-0.001781,0.002531,0.064287,92.633942,4.718998,0.642874,-194.871048,0.065259,0.000000
45.420002,20.701675,-194.871048,-0.001781,0.002541,0.064539,92.085648,4.691067,0.645389,-194.871048,0.065640,0.000000
45.650002,21.256142,-194.915527,-0.001772,0.002562,0.065068,94.552040,4.816710,0.650679,-194.915527,0.066022,0.000000
45.880001,21.923058,-195.004486,-0.001742,0.002581,0.065562,97.518631,4.967836,0.655623,-195.004486,0.066412,0.000000
46.110001,21.963646,-195.004486,-0.001738,0.002594,0.065883,97.699173,4.977033,0.658831,-195.004486,0.066794,0.000000
46.340004,22.153183,-194.871048,-0.001720,0.002608,0.066239,98.542282,5.019983,0.662387,-194.871048,0.067175,0.000000
46.570004,22.391129,-195.004486,-0.001707,0.002621,0.066577,99.600716,5.073902,0.665769,-195.004486,0.067557,0.000000
46.800003,22.515503,-195.004486,-0.001703,0.002636,0.066959,100.153961,5.102086,0.669585,-195.004486,0.067947,0.000000
47.030003,23.163429,-194.915527,-0.001686,0.002654,0.067418,103.036079,5.248908,0.674181,-194.915527,0.068329,0.000000
47.260002,23.191360,-195.004486,-0.001677,0.002663,0.067652,103.160324,5.255238,0.676523,-195.004486,0.068710,0.000000
47.490002,23.797585,-195.004486,-0.001656,0.002682,0.068121,105.856941,5.392610,0.681206,-195.004486,0.069092,0.000000
47.720001,24.358376,-195.048965,-0.001638,0.002700,0.068589,108.351463,5.519687,0.685889,-195.048965,0.069473,0.000000
47.950001,24.423172,-195.093445,-0.001630,0.002712,0.068892,108.639694,5.534370,0.688924,-195.093445,0.069864,0.000000
48.180004,24.552010,-195.048965,-0.001621,0.002723,0.069161,109.212791,5.563565,0.691612,-195.048965,0.070245,0.000000
48.410004,25.185043,-195.093445,-0.001613,0.002742,0.069647,112.028671,5.707012,0.696469,-195.093445,0.070627,0.000000
48.640003,25.525017,-195.093445,-0.001587,0.002757,0.070037,113.540947,5.784051,0.700371,-195.093445,0.071008,0.000000
48.870003,26.327484,-195.137939,-0.001578,0.002778,0.070566,117.110497,5.965893,0.705662,-195.137939,0.071390,0.000000
49.100002,26.298065,-195.137939,-0.001569,0.002787,0.070792,116.979637,5.959227,0.707916,-195.137939,0.071780,0.000000
49.330002,26.571014,-195.226898,-0.001565,0.002802,0.071182,118.193771,6.021078,0.711819,-195.226898,0.072162,0.000000
49.560001,27.075203,-195.137939,-0.001544,0.002820,0.071624,120.436516,6.135329,0.716242,-195.137939,0.072543,0.000000
49.790001,27.596527,-195.182419,-0.001526,0.002836,0.072023,122.755486,6.253462,0.720231,-195.182419,0.072925,0.000000
50.020004,27.920120,-195.182419,-0.001518,0.002849,0.072361,124.194901,6.326789,0.723613,-195.182419,0.073307,0.000000
50.250004,27.806175,-195.226898,-0.001500,0.002860,0.072647,123.688042,6.300969,0.726475,-195.226898,0.073697,0.000000
50.480003,28.864830,-195.226898,-0.001500,0.002879,0.073124,128.397171,6.540864,0.731245,-195.226898,0.074078,0.000000
50.710003,29.390991,-195.315857,-0.001483,0.002899,0.073627,130.737656,6.660094,0.736275,-195.315857,0.074460,0.000000
50.940002,29.737671,-195.226898,-0.001466,0.002910,0.073914,132.279770,6.738653,0.739136,-195.226898,0.074842,0.000000
51.170002,29.583504,-195.315857,-0.001453,0.002918,0.074113,131.593994,6.703718,0.741131,-195.315857,0.075223,0.000000
51.400002,30.723709,-195.271378,-0.001449,0.002940,0.074685,136.665878,6.962092,0.746855,-195.271378,0.075613,0.000000
51.630001,31.589851,-195.315857,-0.001436,0.002961,0.075214,140.518677,7.158363,0.752145,-195.315857,0.075995,0.000000
51.860001,31.775665,-195.360336,-0.001427,0.002973,0.075509,141.345215,7.200469,0.755093,-195.360336,0.076377,0.000000
52.090004,31.975258,-195.271378,-0.001406,0.002984,0.075804,142.233047,7.245697,0.758042,-195.271378,0.076758,0.000000
52.320004,32.539024,-195.315857,-0.001406,0.003001,0.076220,144.740814,7.373448,0.762205,-195.315857,0.077140,0.000000
52.550003,33.061836,-195.404816,-0.001406,0.003019,0.076671,147.066391,7.491919,0.766714,-195.404816,0.077530,0.000000
52.780003,33.645714,-195.315857,-0.001371,0.003033,0.077027,149.663605,7.624228,0.770270,-195.315857,0.077912,0.000000
53.010002,33.852013,-195.404816,-0.001362,0.003043,0.077304,150.581268,7.670976,0.773045,-195.404816,0.078293,0.000000
53.240002,33.922394,-195.449295,-0.001362,0.003054,0.077565,150.894348,7.686924,0.775647,-195.449295,0.078675,0.000000
53.470001,35.039505,-195.493774,-0.001345,0.003075,0.078102,155.863510,7.940065,0.781023,-195.493774,0.079056,0.000000
53.700001,36.195724,-195.493774,-0.001332,0.003096,0.078631,161.006622,8.202068,0.786314,-195.493774,0.079447,0.000000
53.930004,36.320099,-195.493774,-0.001324,0.003106,0.078883,161.559875,8.230251,0.788828,-195.493774,0.079828,0.000000
54.160004,36.887962,-195.449295,-0.001311,0.003122,0.079308,164.085846,8.358932,0.793078,-195.449295,0.080210,0.000000
54.390003,37.131866,-195.493774,-0.001298,0.003133,0.079585,165.170792,8.414202,0.795853,-195.493774,0.080591,0.000000
54.620003,38.144348,-195.538254,-0.001289,0.003153,0.080080,169.674530,8.643633,0.800796,-195.538254,0.080982,0.000000
54.850002,38.250847,-195.493774,-0.001276,0.003162,0.080314,170.148270,8.667766,0.803138,-195.493774,0.081363,0.000000
55.080002,38.759506,-195.538254,-0.001268,0.003178,0.080730,172.410889,8.783030,0.807300,-195.538254,0.081745,0.000000
55.310001,39.401848,-195.538254,-0.001255,0.003192,0.081068,175.268173,8.928586,0.810683,-195.538254,0.082126,0.000000
55.540001,40.348053,-195.582748,-0.001246,0.003212,0.081597,179.477097,9.143000,0.815973,-195.582748,0.082508,0.000000
55.770004,41.217537,-195.627228,-0.001233,0.003228,0.081996,183.344757,9.340028,0.819962,-195.627228,0.082898,0.000000
56.000004,41.273026,-195.582748,-0.001224,0.003236,0.082187,183.591583,9.352601,0.821870,-195.582748,0.083280,0.000000
56.230003,42.130966,-195.627228,-0.001212,0.003254,0.082664,187.407898,9.547014,0.826640,-195.627228,0.083661,0.000000
56.460003,42.999710,-195.582748,-0.001212,0.003274,0.083150,191.272263,9.743874,0.831496,-195.582748,0.084043,0.000000
56.690002,43.611519,-195.716187,-0.001190,0.003287,0.083488,193.993729,9.882511,0.834878,-195.716187,0.084424,0.000000
56.920002,44.135452,-195.716187,-0.001186,0.003299,0.083791,196.324295,10.001237,0.837913,-195.716187,0.084815,0.000000
57.150002,44.593468,-195.671707,-0.001177,0.003314,0.084164,198.361649,10.105023,0.841643,-195.671707,0.085196,0.000000
57.380001,45.273422,-195.671707,-0.001160,0.003329,0.084555,201.386246,10.259105,0.845545,-195.671707,0.085578,0.000000
57.610004,46.184990,-195.716187,-0.001160,0.003346,0.084988,205.441101,10.465669,0.849881,-195.716187,0.085959,0.000000
57.840004,46.827332,-195.760666,-0.001143,0.003360,0.085335,208.298370,10.611225,0.853350,-195.760666,0.086341,0.000000
58.070004,47.563881,-195.760666,-0.001134,0.003375,0.085734,211.574707,10.778130,0.857339,-195.760666,0.086731,0.000000
58.300003,48.040146,-195.760666,-0.001130,0.003387,0.086029,213.693237,10.886052,0.860288,-195.760666,0.087113,0.000000
58.530003,48.979271,-195.760666,-0.001112,0.003404,0.086462,217.870682,11.098861,0.864624,-195.760666,0.087494,0.000000
58.760002,49.729225,-195.760666,-0.001117,0.003418,0.086818,221.206635,11.268804,0.868180,-195.760666,0.087876,0.000000
58.990002,50.194321,-195.760666,-0.001091,0.003431,0.087156,223.275482,11.374196,0.871562,-195.760666,0.088258,0.000000
59.220001,51.120781,-195.849625,-0.001099,0.003448,0.087590,227.396591,11.584134,0.875898,-195.849625,0.088648,0.000000
59.450005,52.277000,-195.760666,-0.001082,0.003466,0.088041,232.539719,11.846138,0.880408,-195.760666,0.089029,0.000000
59.680004,53.151329,-195.760666,-0.001074,0.003481,0.088422,236.428925,12.044264,0.884223,-195.760666,0.089411,0.000000
59.910004,54.028267,-195.760666,-0.001056,0.003497,0.088821,240.329727,12.242980,0.888213,-195.760666,0.089793,0.000000
60.140003,54.575653,-195.849625,-0.001069,0.003510,0.089151,242.764633,12.367021,0.891508,-195.849625,0.090174,0.000000
60.370003,55.430626,-195.894104,-0.001052,0.003526,0.089567,246.567734,12.560760,0.895671,-195.894104,0.090564,0.000000
60.600002,55.995140,-195.849625,-0.001043,0.003538,0.089862,249.078827,12.688680,0.898619,-195.849625,0.090946,0.000000
60.830002,56.462097,-195.805145,-0.001030,0.003547,0.090105,251.155945,12.794495,0.901048,-195.805145,0.091328,0.000000
61.060001,57.824982,-195.894104,-0.001018,0.003569,0.090642,257.218353,13.103329,0.906424,-195.894104,0.091709,0.000000
61.290005,58.754791,-195.983063,-0.001018,0.003583,0.091015,261.354370,13.314026,0.910153,-195.983063,0.092091,0.000000
61.520004,59.653328,-195.983063,-0.001009,0.003602,0.091501,265.351257,13.517637,0.915010,-195.983063,0.092481,0.000000
61.750004,61.060150,-195.894104,-0.000996,0.003621,0.091969,271.609100,13.836428,0.919693,-195.894104,0.092863,0.000000
61.980003,61.771385,-195.894104,-0.000987,0.003634,0.092308,274.772858,13.997596,0.923075,-195.894104,0.093244,0.000000
62.210003,62.274086,-195.983063,-0.000974,0.003646,0.092602,277.008972,14.111509,0.926024,-195.983063,0.093626,0.000000
62.440002,63.185287,-196.027557,-0.000983,0.003659,0.092949,281.062195,14.317991,0.929493,-196.027557,0.094007,0.000000
62.670002,63.716278,-196.027557,-0.000970,0.003671,0.093235,283.424164,14.438315,0.932354,-196.027557,0.094398,0.000000
62.900002,64.765259,-195.983063,-0.000957,0.003688,0.093686,288.090271,14.676017,0.936864,-195.983063,0.094779,0.000000
63.130005,66.046585,-195.983063,-0.000949,0.003706,0.094120,293.789886,14.966371,0.941200,-195.983063,0.095161,0.000000
63.360004,67.164078,-196.072037,-0.000936,0.003724,0.094580,298.760742,15.219597,0.945796,-196.072037,0.095542,0.000000
63.590004,67.012527,-196.072037,-0.000927,0.003719,0.094458,298.086609,15.185256,0.944582,-196.072037,0.094675,0.000000
63.820004,66.397369,-196.072037,-0.000936,0.003719,0.094458,295.350250,15.045859,0.944582,-196.072037,0.094458,0.000000
64.050003,65.850723,-196.072037,-0.000918,0.003718,0.094441,292.918640,14.921987,0.944409,-196.072037,0.094458,0.000000
64.280006,65.351364,-196.072037,-0.000910,0.003718,0.094432,290.697388,14.808831,0.944322,-196.072037,0.094458,0.000000
64.510002,64.924637,-196.160995,-0.000918,0.003718,0.094432,288.799194,14.712132,0.944322,-196.160995,0.094458,0.000000
64.740005,64.542953,-196.205475,-0.000914,0.003717,0.094424,287.101410,14.625642,0.944235,-196.205475,0.094458,0.000000
64.970001,64.184723,-196.116516,-0.000910,0.003717,0.094424,285.507904,14.544467,0.944235,-196.116516,0.094458,0.000000
65.200005,63.855927,-196.116516,-0.000910,0.003717,0.094415,284.045349,14.469960,0.944149,-196.116516,0.094458,0.000000
65.430000,63.568451,-196.160995,-0.000901,0.003717,0.094415,282.766602,14.404817,0.944149,-196.160995,0.094458,0.000000
65.660004,63.279861,-196.205475,-0.000901,0.003717,0.094415,281.482880,14.339421,0.944149,-196.205475,0.094458,0.000000
65.889999,63.033356,-196.205475,-0.000901,0.003717,0.094415,280.386383,14.283563,0.944149,-196.205475,0.094458,0.000000
66.120003,62.814766,-196.205475,-0.000905,0.003717,0.094415,279.414032,14.234030,0.944149,-196.205475,0.094458,0.000000
66.350006,62.604378,-196.160995,-0.000910,0.003717,0.094415,278.478180,14.186355,0.944149,-196.160995,0.094458,0.000000
66.580002,62.390640,-196.160995,-0.000884,0.003717,0.094415,277.527435,14.137921,0.944149,-196.160995,0.094458,0.000000
66.810005,62.207054,-196.294434,-0.000888,0.003717,0.094406,276.710785,14.096320,0.944062,-196.294434,0.094458,0.000000
67.040001,62.023476,-196.294434,-0.000892,0.003717,0.094406,275.894196,14.054721,0.944062,-196.294434,0.094458,0.000000
67.270004,61.850327,-196.249954,-0.000901,0.003717,0.094406,275.123993,14.015485,0.944062,-196.249954,0.094458,0.000000
67.500000,61.707336,-196.249954,-0.000892,0.003717,0.094406,274.487946,13.983082,0.944062,-196.249954,0.094458,0.000000
67.730003,61.557266,-196.294434,-0.000884,0.003717,0.094406,273.820404,13.949076,0.944062,-196.294434,0.094458,0.000000
67.960007,61.419121,-196.383392,-0.000880,0.003717,0.094406,273.205902,13.917771,0.944062,-196.383392,0.094458,0.000000
68.190002,61.283943,-196.383392,-0.000888,0.003717,0.094406,272.604584,13.887140,0.944062,-196.383392,0.094458,0.000000
68.420006,61.149895,-196.294434,-0.000888,0.003717,0.094406,272.008331,13.856764,0.944062,-196.294434,0.094458,0.000000
68.650002,61.018814,-196.338913,-0.000892,0.003717,0.094406,271.425232,13.827062,0.944062,-196.338913,0.094458,0.000000
68.880005,60.913437,-196.294434,-0.000888,0.003717,0.094406,270.956512,13.803183,0.944062,-196.294434,0.094458,0.000000
69.110001,60.805077,-196.427887,-0.000884,0.003717,0.094406,270.474487,13.778627,0.944062,-196.427887,0.094458,0.000000
69.340004,60.691872,-196.427887,-0.000888,0.003717,0.094406,269.970917,13.752975,0.944062,-196.427887,0.094458,0.000000
69.570000,60.592079,-196.427887,-0.000880,0.003717,0.094406,269.527039,13.730362,0.944062,-196.427887,0.094458,0.000000
69.800003,60.480370,-196.383392,-0.000884,0.003717,0.094406,269.030121,13.705048,0.944062,-196.383392,0.094458,0.000000
70.030006,60.374237,-196.516846,-0.000875,0.003717,0.094406,268.558014,13.680998,0.944062,-196.516846,0.094458,0.000000
70.260002,60.296043,-196.516846,-0.000884,0.003717,0.094406,268.210205,13.663279,0.944062,-196.516846,0.094458,0.000000
70.490005,60.208534,-196.516846,-0.000884,0.003717,0.094406,267.820923,13.643449,0.944062,-196.516846,0.094458,0.000000
70.720001,60.129967,-196.472366,-0.000892,0.003717,0.094406,267.471436,13.625645,0.944062,-196.472366,0.094458,0.000000
70.950005,60.020485,-196.516846,-0.000884,0.003717,0.094406,266.984436,13.600837,0.944062,-196.516846,0.094458,0.000000
71.180000,59.951225,-196.516846,-0.000880,0.003717,0.094406,266.676361,13.585141,0.944062,-196.516846,0.094458,0.000000
71.410004,59.867065,-196.605804,-0.000884,0.003717,0.094406,266.302002,13.566071,0.944062,-196.605804,0.094458,0.000000
71.640007,59.801529,-196.605804,-0.000880,0.003717,0.094406,266.010498,13.551220,0.944062,-196.605804,0.094458,0.000000
71.870003,59.736366,-196.605804,-0.000871,0.003717,0.094406,265.720642,13.536454,0.944062,-196.605804,0.094458,0.000000
72.100006,59.660400,-196.516846,-0.000875,0.003717,0.094406,265.382721,13.519239,0.944062,-196.516846,0.094458,0.000000
72.330002,59.587044,-196.650284,-0.000875,0.003717,0.094406,265.056396,13.502617,0.944062,-196.650284,0.094458,0.000000
72.560005,59.519646,-196.650284,-0.000884,0.003717,0.094406,264.756592,13.487345,0.944062,-196.650284,0.094458,0.000000
72.790001,59.438843,-196.694763,-0.000888,0.003717,0.094406,264.397186,13.469034,0.944062,-196.694763,0.094458,0.000000
73.020004,59.381493,-196.605804,-0.000875,0.003717,0.094406,264.142059,13.456038,0.944062,-196.605804,0.094458,0.000000
73.250000,59.352448,-196.650284,-0.000880,0.003717,0.094406,264.012878,13.449456,0.944062,-196.650284,0.094458,0.000000
73.480003,59.261589,-196.739243,-0.000871,0.003717,0.094406,263.608704,13.428867,0.944062,-196.739243,0.094458,0.000000
73.710007,59.203873,-196.739243,-0.000888,0.003717,0.094406,263.351990,13.415790,0.944062,-196.739243,0.094458,0.000000
73.940002,59.137589,-196.739243,-0.000884,0.003717,0.094406,263.057129,13.400769,0.944062,-196.739243,0.094458,0.000000
74.170006,59.091415,-196.739243,-0.000875,0.003717,0.094406,262.851746,13.390306,0.944062,-196.739243,0.094458,0.000000
74.400002,59.040031,-196.694763,-0.000875,0.003717,0.094406,262.623169,13.378662,0.944062,-196.694763,0.094458,0.000000
74.630005,58.990875,-196.783722,-0.000871,0.003717,0.094406,262.404510,13.367524,0.944062,-196.783722,0.094458,0.000000
74.860001,58.923851,-196.739243,-0.000875,0.003717,0.094406,262.106384,13.352336,0.944062,-196.739243,0.094458,0.000000
75.090004,58.866501,-196.828201,-0.000867,0.003717,0.094406,261.851288,13.339340,0.944062,-196.828201,0.094458,0.000000
75.320007,58.818092,-196.828201,-0.000875,0.003717,0.094406,261.635956,13.328370,0.944062,-196.828201,0.094458,0.000000
75.550003,58.787186,-196.783722,-0.000862,0.003717,0.094406,261.498474,13.321366,0.944062,-196.783722,0.094458,0.000000
75.780006,58.725372,-196.917175,-0.000871,0.003717,0.094406,261.223511,13.307360,0.944062,-196.917175,0.094458,0.000000
76.010002,58.680321,-196.872696,-0.000867,0.003717,0.094406,261.023102,13.297151,0.944062,-196.872696,0.094458,0.000000
76.240005,58.610687,-196.872696,-0.000862,0.003717,0.094406,260.713348,13.281371,0.944062,-196.872696,0.094458,0.000000
76.470001,58.565254,-196.828201,-0.000880,0.003717,0.094406,260.511261,13.271076,0.944062,-196.828201,0.094458,0.000000
76.700005,58.533600,-196.917175,-0.000867,0.003717,0.094406,260.370453,13.263903,0.944062,-196.917175,0.094458,0.000000
76.930000,58.498230,-196.917175,-0.000867,0.003717,0.094406,260.213135,13.255888,0.944062,-196.917175,0.094458,0.000000
77.160004,58.439018,-196.917175,-0.000867,0.003717,0.094406,259.949738,13.242471,0.944062,-196.917175,0.094458,0.000000
77.390007,58.387634,-196.917175,-0.000871,0.003717,0.094406,259.721161,13.230827,0.944062,-196.917175,0.094458,0.000000
77.620003,58.351143,-196.961655,-0.000862,0.003717,0.094406,259.558838,13.222558,0.944062,-196.961655,0.094458,0.000000
77.850006,58.317253,-197.006134,-0.000862,0.003717,0.094406,259.408112,13.214878,0.944062,-197.006134,0.094458,0.000000
78.080002,58.279648,-196.961655,-0.000867,0.003717,0.094406,259.240814,13.206356,0.944062,-196.961655,0.094458,0.000000
78.310005,58.226395,-197.050613,-0.000867,0.003717,0.094406,259.003937,13.194289,0.944062,-197.050613,0.094458,0.000000
78.540001,58.187668,-197.050613,-0.000871,0.003717,0.094406,258.831665,13.185514,0.944062,-197.050613,0.094458,0.000000
78.770004,58.140381,-197.006134,-0.000862,0.003717,0.094406,258.621338,13.174799,0.944062,-197.006134,0.094458,0.000000
79.000000,58.118408,-197.006134,-0.000862,0.003717,0.094406,258.523590,13.169820,0.944062,-197.006134,0.094458,0.000000
79.230003,58.085640,-197.050613,-0.000858,0.003717,0.094406,258.377838,13.162395,0.944062,-197.050613,0.094458,0.000000
79.460007,58.033882,-197.095093,-0.000867,0.003717,0.094406,258.147614,13.150666,0.944062,-197.095093,0.094458,0.000000
79.690002,57.995155,-197.095093,-0.000875,0.003717,0.094406,257.975342,13.141890,0.944062,-197.095093,0.094458,0.000000
79.920006,57.967972,-197.050613,-0.000862,0.003717,0.094406,257.854431,13.135730,0.944062,-197.050613,0.094458,0.000000
80.150002,57.941528,-197.139572,-0.000875,0.003717,0.094406,257.736786,13.129738,0.944062,-197.139572,0.094458,0.000000
80.380005,57.896477,-197.184052,-0.000858,0.003717,0.094406,257.536377,13.119529,0.944062,-197.184052,0.094458,0.000000
80.610001,57.847321,-197.139572,-0.000867,0.003717,0.094406,257.317719,13.108391,0.944062,-197.139572,0.094458,0.000000
80.840004,57.828705,-197.184052,-0.000871,0.003717,0.094406,257.234924,13.104172,0.944062,-197.184052,0.094458,0.000000
81.070007,57.800400,-197.184052,-0.000871,0.003717,0.094406,257.109009,13.097758,0.944062,-197.184052,0.094458,0.000000
81.300003,57.767258,-197.228531,-0.000862,0.003717,0.094406,256.961609,13.090247,0.944062,-197.228531,0.094458,0.000000
81.530006,57.727043,-197.228531,-0.000862,0.003717,0.094406,256.782715,13.081136,0.944062,-197.228531,0.094458,0.000000
81.760002,57.681244,-197.228531,-0.000871,0.003717,0.094406,256.578979,13.070757,0.944062,-197.228531,0.094458,0.000000
81.990005,57.655548,-197.228531,-0.000858,0.003717,0.094406,256.464691,13.064934,0.944062,-197.228531,0.094458,0.000000
82.220001,57.648102,-197.273026,-0.000871,0.003717,0.094406,256.431549,13.063247,0.944062,-197.273026,0.094458,0.000000
82.450005,57.607887,-197.273026,-0.000875,0.003717,0.094406,256.252686,13.054134,0.944062,-197.273026,0.094458,0.000000
82.680000,57.571022,-197.317505,-0.000862,0.003717,0.094406,256.088684,13.045780,0.944062,-197.317505,0.094458,0.000000
82.910004,57.537880,-197.317505,-0.000862,0.003717,0.094406,255.941269,13.038270,0.944062,-197.317505,0.094458,0.000000
83.140007,57.520004,-197.317505,-0.000862,0.003717,0.094406,255.861755,13.034219,0.944062,-197.317505,0.094458,0.000000
83.370003,57.489098,-197.317505,-0.000862,0.003717,0.094406,255.724274,13.027216,0.944062,-197.317505,0.094458,0.000000
83.600006,57.460800,-197.361984,-0.000858,0.003717,0.094406,255.598404,13.020803,0.944062,-197.361984,0.094458,0.000000
83.830002,57.428772,-197.361984,-0.000854,0.003717,0.094406,255.455933,13.013546,0.944062,-197.361984,0.094458,0.000000
84.060005,57.384087,-197.406464,-0.000871,0.003717,0.094406,255.257172,13.003420,0.944062,-197.406464,0.094458,0.000000
84.290001,57.370308,-197.361984,-0.000862,0.003717,0.094406,255.195877,13.000298,0.944062,-197.361984,0.094458,0.000000
84.520004,57.343132,-197.361984,-0.000867,0.003717,0.094406,255.074997,12.994140,0.944062,-197.361984,0.094458,0.000000
84.750008,57.322647,-197.406464,-0.000854,0.003717,0.094406,254.983871,12.989498,0.944062,-197.406464,0.094458,0.000000
84.980003,57.279449,-197.450943,-0.000854,0.003717,0.094406,254.791718,12.979709,0.944062,-197.450943,0.094458,0.000000
85.210007,57.267906,-197.450943,-0.000858,0.003717,0.094406,254.740372,12.977093,0.944062,-197.450943,0.094458,0.000000
85.440002,57.248543,-197.450943,-0.000858,0.003717,0.094406,254.654236,12.972706,0.944062,-197.450943,0.094458,0.000000
85.670006,57.222107,-197.450943,-0.000862,0.003717,0.094406,254.536652,12.966715,0.944062,-197.450943,0.094458,0.000000
85.900002,57.189713,-197.495422,-0.000854,0.003717,0.094406,254.392548,12.959373,0.944062,-197.495422,0.094458,0.000000
86.130005,57.165504,-197.539902,-0.000858,0.003717,0.094406,254.284866,12.953889,0.944062,-197.539902,0.094458,0.000000
86.360001,57.137207,-197.539902,-0.000858,0.003717,0.094406,254.158997,12.947476,0.944062,-197.539902,0.094458,0.000000
86.590004,57.124916,-197.539902,-0.000867,0.003717,0.094406,254.104324,12.944692,0.944062,-197.539902,0.094458,0.000000
86.820007,57.099228,-197.584381,-0.000862,0.003717,0.094406,253.990051,12.938870,0.944062,-197.584381,0.094458,0.000000
87.050003,57.062363,-197.584381,-0.000858,0.003717,0.094406,253.826065,12.930516,0.944062,-197.584381,0.094458,0.000000
87.280006,57.044487,-197.584381,-0.000862,0.003717,0.094406,253.746552,12.926465,0.944062,-197.584381,0.094458,0.000000
87.510002,57.029961,-197.539902,-0.000867,0.003717,0.094406,253.681931,12.923174,0.944062,-197.539902,0.094458,0.000000
87.740005,57.018791,-197.584381,-0.000849,0.003717,0.094406,253.632248,12.920643,0.944062,-197.584381,0.094458,0.000000
87.970001,56.984535,-197.628860,-0.000854,0.003717,0.094406,253.479874,12.912881,0.944062,-197.628860,0.094458,0.000000
88.200005,56.960327,-197.628860,-0.000849,0.003717,0.094406,253.372192,12.907394,0.944062,-197.628860,0.094458,0.000000
88.430008,56.936501,-197.628860,-0.000862,0.003717,0.094406,253.266205,12.901996,0.944062,-197.628860,0.094458,0.000000
88.660004,56.931282,-197.628860,-0.000867,0.003717,0.094406,253.242996,12.900813,0.944062,-197.628860,0.094458,0.000000
88.890007,56.910805,-197.628860,-0.000867,0.003717,0.094406,253.151901,12.896173,0.944062,-197.628860,0.094458,0.000000
89.120003,56.871330,-197.673340,-0.000858,0.003717,0.094406,252.976318,12.887228,0.944062,-197.673340,0.094458,0.000000
89.350006,56.864258,-197.717834,-0.000858,0.003717,0.094406,252.944855,12.885625,0.944062,-197.717834,0.094458,0.000000
89.580002,56.853088,-197.673340,-0.000849,0.003717,0.094406,252.895172,12.883094,0.944062,-197.673340,0.094458,0.000000
89.810005,56.828880,-197.673340,-0.000867,0.003717,0.094406,252.787491,12.877608,0.944062,-197.673340,0.094458,0.000000
90.040001,56.821060,-197.717834,-0.000854,0.003717,0.094406,252.752701,12.875836,0.944062,-197.717834,0.094458,0.000000
90.270004,56.787918,-197.762314,-0.000858,0.003717,0.094406,252.605270,12.868326,0.944062,-197.762314,0.094458,0.000000
90.500008,56.763718,-197.851273,-0.000858,0.003717,0.094406,252.497620,12.862843,0.944062,-197.851273,0.094458,0.000000
90.730003,56.748825,-197.806793,-0.000854,0.003717,0.094406,252.431381,12.859468,0.944062,-197.806793,0.094458,0.000000
90.960007,56.746964,-197.806793,-0.000862,0.003717,0.094406,252.423096,12.859045,0.944062,-197.806793,0.094458,0.000000
91.190002,56.706001,-197.851273,-0.000862,0.003717,0.094406,252.240891,12.849764,0.944062,-197.851273,0.094458,0.000000
91.420006,56.687378,-197.806793,-0.000862,0.003717,0.094406,252.158051,12.845543,0.944062,-197.806793,0.094458,0.000000
91.650002,56.680679,-197.851273,-0.000862,0.003717,0.094406,252.128250,12.844026,0.944062,-197.851273,0.094458,0.000000
91.880005,56.662430,-197.851273,-0.000854,0.003717,0.094406,252.047073,12.839890,0.944062,-197.851273,0.094458,0.000000
92.110001,56.646049,-197.895752,-0.000862,0.003717,0.094406,251.974213,12.836178,0.944062,-197.895752,0.094458,0.000000
92.340004,56.627060,-197.806793,-0.000867,0.003717,0.094406,251.889740,12.831876,0.944062,-197.806793,0.094458,0.000000
92.570007,56.611420,-197.940231,-0.000858,0.003717,0.094406,251.820175,12.828331,0.944062,-197.940231,0.094458,0.000000
92.800003,56.598381,-197.984711,-0.000862,0.003717,0.094406,251.762177,12.825377,0.944062,-197.984711,0.094458,0.000000
93.030006,56.582001,-197.895752,-0.000858,0.003717,0.094406,251.689316,12.821664,0.944062,-197.895752,0.094458,0.000000
93.260002,56.570084,-197.895752,-0.000867,0.003717,0.094406,251.636307,12.818964,0.944062,-197.895752,0.094458,0.000000
93.490005,56.533218,-197.940231,-0.000845,0.003717,0.094406,251.472321,12.810611,0.944062,-197.940231,0.094458,0.000000
93.720001,56.520561,-198.029190,-0.000854,0.003717,0.094406,251.416016,12.807742,0.944062,-198.029190,0.094458,0.000000
93.900002,56.503799,-197.940231,-0.000867,0.003717,0.094406,251.341446,12.803945,0.944062,-197.940231,0.094458,0.000000