File: Data/compression 11/AutoNoHeating-16-11-2-240530_05302024_172818.csv
Time (sec),S:Load (lbs),S:HL1 (DIM),S:LVDT (in),S:Position (in),Ch:Position (mm),Ch:Load (N),Ch:Stress (MPa),Ch:Strain (mm/mm),Ch:HL1 (DIM),Set Point (),Cycles ()
0.110000,-0.020103,-341.702667,-0.010731,-0.000000,-0.000000,-0.089425,-0.004556,-0.000000,-341.702667,0.000269,0.000000
0.340000,-0.002228,-341.658173,-0.010705,-0.000000,-0.000000,-0.009910,-0.000505,-0.000000,-341.658173,0.000269,0.000000
0.570000,-0.043938,-341.791626,-0.010723,0.000121,0.003079,-0.195445,-0.009956,0.030787,-341.791626,0.004050,0.000000
0.800000,-0.058090,-341.747162,-0.010615,0.000263,0.006678,-0.258398,-0.013163,0.066776,-341.747162,0.007883,0.000000
1.030000,-0.039093,-341.791626,-0.010468,0.000413,0.010493,-0.173894,-0.008859,0.104934,-341.791626,0.011716,0.000000
1.260000,-0.034256,-341.747162,-0.010322,0.000560,0.014231,-0.152378,-0.007763,0.142312,-341.747162,0.015532,0.000000
1.490000,-0.014893,-341.702667,-0.010154,0.000716,0.018194,-0.066245,-0.003375,0.181944,-341.702667,0.019365,0.000000
1.720000,-0.039467,-341.791626,-0.010007,0.000867,0.022010,-0.175557,-0.008943,0.220102,-341.791626,0.023198,0.000000
1.950000,-0.045425,-341.747162,-0.009856,0.001020,0.025913,-0.202062,-0.010294,0.259127,-341.747162,0.027031,0.000000
2.180000,-0.030907,-341.836121,-0.009701,0.001168,0.029676,-0.137480,-0.007004,0.296765,-341.836121,0.030865,0.000000
2.410000,-0.022713,-341.747162,-0.009554,0.001314,0.033388,-0.101031,-0.005147,0.333882,-341.747162,0.034698,0.000000
2.640000,-0.045052,-341.880585,-0.009399,0.001468,0.037291,-0.200399,-0.010209,0.372907,-341.880585,0.038531,0.000000
2.870000,-0.028297,-341.836121,-0.009231,0.001625,0.041263,-0.125873,-0.006412,0.412626,-341.836121,0.042364,0.000000
3.100000,-0.085274,-341.880585,-0.009097,0.001773,0.045026,-0.379317,-0.019323,0.450264,-341.880585,0.046197,0.000000
3.330000,-0.064415,-341.836121,-0.008946,0.001923,0.048833,-0.286532,-0.014597,0.488335,-341.836121,0.050030,0.000000
3.560000,-0.042450,-341.791626,-0.008783,0.002071,0.052606,-0.188827,-0.009619,0.526059,-341.791626,0.053863,0.000000
3.790000,-0.016380,-341.836121,-0.008627,0.002225,0.056508,-0.072863,-0.003712,0.565084,-341.836121,0.057697,0.000000
4.020000,-0.010048,-341.836121,-0.008468,0.002381,0.060480,-0.044695,-0.002277,0.604803,-341.836121,0.061530,0.000000
4.250000,-0.043938,-341.880585,-0.008321,0.002530,0.064253,-0.195445,-0.009956,0.642528,-341.880585,0.065345,0.000000
4.480000,-0.022713,-341.836121,-0.008170,0.002680,0.068060,-0.101031,-0.005147,0.680599,-341.836121,0.069179,0.000000
4.710000,-0.023087,-341.880585,-0.008024,0.002826,0.071789,-0.102694,-0.005231,0.717889,-341.880585,0.073012,0.000000
4.940000,-0.011909,-341.836121,-0.007869,0.002977,0.075613,-0.052976,-0.002699,0.756134,-341.836121,0.076845,0.000000
5.170000,-0.043190,-341.969543,-0.007700,0.003138,0.079698,-0.192119,-0.009787,0.796981,-341.969543,0.080678,0.000000
5.400000,-0.081917,-341.925079,-0.007562,0.003284,0.083410,-0.364384,-0.018563,0.834098,-341.925079,0.084511,0.000000
5.630000,-0.062927,-341.925079,-0.007420,0.003432,0.087165,-0.279914,-0.014260,0.871649,-341.925079,0.088344,0.000000
5.860000,-0.033142,-341.880585,-0.007256,0.003584,0.091033,-0.147423,-0.007510,0.910327,-341.880585,0.092177,0.000000
6.090000,0.001495,-341.969543,-0.007110,0.003732,0.094788,0.006652,0.000339,0.947878,-341.969543,0.096011,0.000000
6.320000,0.002609,-341.969543,-0.006972,0.003886,0.098699,0.011607,0.000591,0.986990,-341.969543,0.099844,0.000000
6.550000,-0.014519,-341.925079,-0.006799,0.004038,0.102575,-0.064583,-0.003290,1.025755,-341.925079,0.103677,0.000000
6.780000,-0.035004,-341.925079,-0.006640,0.004185,0.106287,-0.155704,-0.007932,1.062872,-341.925079,0.107510,0.000000
7.010000,-0.018990,-342.014038,-0.006485,0.004338,0.110181,-0.084470,-0.004303,1.101810,-342.014038,0.111326,0.000000
7.240000,-0.042076,-341.969543,-0.006342,0.004483,0.113858,-0.187164,-0.009535,1.138581,-341.969543,0.115159,0.000000
7.470000,-0.049896,-342.014038,-0.006187,0.004637,0.117778,-0.221950,-0.011307,1.177779,-342.014038,0.118992,0.000000
7.700000,-0.030907,-342.014038,-0.006036,0.004792,0.121706,-0.137480,-0.007004,1.217064,-342.014038,0.122825,0.000000
7.930000,-0.034256,-341.925079,-0.005890,0.004938,0.125436,-0.152378,-0.007763,1.254355,-341.925079,0.126658,0.000000
8.160001,-0.026810,-342.014038,-0.005730,0.005095,0.129416,-0.119255,-0.006075,1.294161,-342.014038,0.130491,0.000000
8.390000,-0.012657,-342.058502,-0.005588,0.005244,0.133206,-0.056302,-0.002868,1.332059,-342.058502,0.134325,0.000000
8.620001,-0.009682,-342.102997,-0.005437,0.005390,0.136900,-0.043066,-0.002194,1.369003,-342.102997,0.138158,0.000000
8.850000,-0.010422,-342.014038,-0.005277,0.005545,0.140837,-0.046358,-0.002362,1.408375,-342.014038,0.141991,0.000000
9.080001,-0.026436,-342.058502,-0.005126,0.005697,0.144714,-0.117593,-0.005990,1.447140,-342.058502,0.145824,0.000000
9.310000,-0.049896,-342.058502,-0.004971,0.005846,0.148486,-0.221950,-0.011307,1.484864,-342.058502,0.149657,0.000000
9.540001,-0.023087,-342.147461,-0.004825,0.005999,0.152380,-0.102694,-0.005231,1.523802,-342.147461,0.153490,0.000000
9.770000,-0.010422,-342.102997,-0.004674,0.006143,0.156040,-0.046358,-0.002362,1.560399,-342.102997,0.157323,0.000000
10.000000,0.008568,-342.147461,-0.004523,0.006298,0.159968,0.038112,0.001941,1.599685,-342.147461,0.161139,0.000000
10.230000,0.292686,-342.147461,-0.004363,0.006449,0.163810,1.301934,0.066324,1.638103,-342.147461,0.164972,0.000000
10.460000,0.608833,-342.147461,-0.004307,-0.000006,-0.000156,2.708226,0.137964,-0.001561,-342.147461,0.000078,0.000000
10.690001,0.558189,-342.147461,-0.004294,-0.000006,-0.000156,2.482950,0.126488,-0.001561,-342.147461,0.000078,0.000000
10.920000,0.542923,-342.191956,-0.004299,-0.000006,-0.000156,2.415042,0.123028,-0.001561,-342.191956,0.000078,0.000000
11.150001,0.627449,-342.147461,-0.004299,-0.000006,-0.000156,2.791033,0.142182,-0.001561,-342.147461,0.000434,0.000000
11.380000,0.619255,-342.191956,-0.004303,-0.000006,-0.000147,2.754584,0.140325,-0.001474,-342.191956,0.000824,0.000000
11.610001,0.596542,-342.191956,-0.004303,-0.000006,-0.000147,2.653553,0.135178,-0.001474,-342.191956,0.001205,0.000000
11.840000,0.967056,-342.236450,-0.004281,0.000024,0.000598,4.301681,0.219138,0.005984,-342.236450,0.001587,0.000000
12.070001,1.206490,-342.236450,-0.004286,0.000043,0.001093,5.366734,0.273394,0.010927,-342.236450,0.001969,0.000000
12.300000,1.442200,-342.191956,-0.004251,0.000061,0.001561,6.415225,0.326807,0.015610,-342.191956,0.002350,0.000000
12.530001,1.606049,-342.236450,-0.004243,0.000075,0.001899,7.144061,0.363936,0.018992,-342.236450,0.002740,0.000000
12.760000,1.731537,-342.325409,-0.004230,0.000086,0.002185,7.702260,0.392372,0.021854,-342.325409,0.003122,0.000000
12.990001,1.966873,-342.280914,-0.004208,0.000102,0.002602,8.749089,0.445700,0.026017,-342.280914,0.003504,0.000000
13.220000,2.239822,-342.191956,-0.004208,0.000121,0.003061,9.963227,0.507551,0.030613,-342.191956,0.003885,0.000000
13.450001,2.441277,-342.280914,-0.004195,0.000133,0.003391,10.859341,0.553201,0.033909,-342.280914,0.004267,0.000000
13.680000,2.595070,-342.280914,-0.004178,0.000145,0.003694,11.543447,0.588051,0.036944,-342.280914,0.004657,0.000000
13.910001,2.857216,-342.280914,-0.004182,0.000161,0.004102,12.709531,0.647454,0.041020,-342.280914,0.005039,0.000000
14.140000,3.207993,-342.369873,-0.004152,0.000183,0.004648,14.269863,0.726942,0.046483,-342.369873,0.005420,0.000000
14.370001,3.400879,-342.325409,-0.004130,0.000196,0.004978,15.127865,0.770650,0.049779,-342.325409,0.005802,0.000000
14.600000,3.499184,-342.280914,-0.004135,0.000208,0.005273,15.565146,0.792926,0.052727,-342.280914,0.006183,0.000000
14.830001,3.733040,-342.280914,-0.004118,0.000223,0.005654,16.605391,0.845919,0.056543,-342.280914,0.006574,0.000000
15.060000,3.921455,-342.414368,-0.004092,0.000235,0.005975,17.443504,0.888615,0.059752,-342.414368,0.006955,0.000000
15.290001,4.195152,-342.369873,-0.004087,0.000251,0.006374,18.660969,0.950635,0.063741,-342.369873,0.007337,0.000000
15.520000,4.355270,-342.325409,-0.004074,0.000265,0.006721,19.373211,0.986918,0.067210,-342.325409,0.007718,0.000000
15.750001,4.565292,-342.369873,-0.004074,0.000280,0.007120,20.307434,1.034510,0.071199,-342.369873,0.008100,0.000000
15.980000,4.745888,-342.414368,-0.004057,0.000292,0.007423,21.110764,1.075433,0.074235,-342.414368,0.008490,0.000000
16.210001,5.138000,-342.414368,-0.004036,0.000316,0.008022,22.854967,1.164288,0.080218,-342.414368,0.008872,0.000000
16.440001,5.272423,-342.458832,-0.004018,0.000329,0.008369,23.452908,1.194748,0.083687,-342.458832,0.009253,0.000000
16.670000,5.386002,-342.414368,-0.004010,0.000342,0.008698,23.958132,1.220485,0.086983,-342.414368,0.009635,0.000000
16.900002,5.615753,-342.414368,-0.003988,0.000358,0.009089,24.980118,1.272548,0.090885,-342.414368,0.010016,0.000000
17.130001,5.766937,-342.503326,-0.003980,0.000372,0.009461,25.652618,1.306807,0.094614,-342.503326,0.010407,0.000000
17.360001,5.871201,-342.503326,-0.003971,0.000388,0.009852,26.116404,1.330433,0.098517,-342.503326,0.010788,0.000000
17.590000,5.951630,-342.458832,-0.003954,0.000397,0.010095,26.474171,1.348659,0.100945,-342.458832,0.011170,0.000000
17.820002,6.218994,-342.414368,-0.003936,0.000414,0.010528,27.663467,1.409244,0.105281,-342.414368,0.011551,0.000000
18.050001,6.436836,-342.458832,-0.003923,0.000434,0.011014,28.632477,1.458608,0.110138,-342.458832,0.011933,0.000000
18.280001,6.583176,-342.547791,-0.003902,0.000449,0.011395,29.283428,1.491769,0.113953,-342.547791,0.012323,0.000000
18.510000,6.577965,-342.503326,-0.003893,0.000461,0.011716,29.260248,1.490588,0.117162,-342.503326,0.012705,0.000000
18.740002,6.694511,-342.503326,-0.003876,0.000476,0.012089,29.778673,1.516998,0.120891,-342.503326,0.013086,0.000000
18.970001,6.713875,-342.503326,-0.003859,0.000490,0.012436,29.864807,1.521386,0.124360,-342.503326,0.013468,0.000000
19.200001,6.981239,-342.503326,-0.003854,0.000508,0.012896,31.054104,1.581972,0.128956,-342.503326,0.013850,0.000000
19.430000,7.008423,-342.547791,-0.003842,0.000519,0.013182,31.175022,1.588131,0.131818,-342.547791,0.014240,0.000000
19.660002,7.217323,-342.636780,-0.003824,0.000536,0.013624,32.104256,1.635469,0.136241,-342.636780,0.014621,0.000000
19.890001,7.306320,-342.503326,-0.003820,0.000551,0.013997,32.500134,1.655636,0.139970,-342.503326,0.015003,0.000000
20.120001,7.537193,-342.592285,-0.003794,0.000570,0.014465,33.527111,1.707952,0.144653,-342.592285,0.015385,0.000000
20.350000,7.597893,-342.592285,-0.003773,0.000586,0.014873,33.797115,1.721707,0.148729,-342.592285,0.015775,0.000000
20.580002,7.660080,-342.636780,-0.003760,0.000600,0.015237,34.073738,1.735799,0.152372,-342.636780,0.016156,0.000000
20.810001,7.610550,-342.592285,-0.003755,0.000613,0.015567,33.853416,1.724575,0.155667,-342.592285,0.016538,0.000000
21.040001,7.613533,-342.592285,-0.003729,0.000622,0.015792,33.866688,1.725251,0.157922,-342.592285,0.016920,0.000000
21.270000,7.854828,-342.592285,-0.003712,0.000641,0.016286,34.940018,1.779929,0.162865,-342.592285,0.017301,0.000000
21.500002,7.926323,-342.681244,-0.003712,0.000657,0.016694,35.258045,1.796131,0.166941,-342.681244,0.017691,0.000000
21.730001,8.078247,-342.681244,-0.003699,0.000674,0.017119,35.933838,1.830557,0.171190,-342.681244,0.018073,0.000000
21.960001,8.014946,-342.725739,-0.003678,0.000685,0.017397,35.652260,1.816213,0.173966,-342.725739,0.018455,0.000000
22.190001,8.324387,-342.681244,-0.003665,0.000707,0.017952,37.028721,1.886333,0.179516,-342.681244,0.018836,0.000000
22.420002,8.312103,-342.681244,-0.003639,0.000722,0.018333,36.974083,1.883550,0.183332,-342.681244,0.019218,0.000000
22.650002,8.265182,-342.770203,-0.003630,0.000733,0.018628,36.765369,1.872917,0.186280,-342.770203,0.019608,0.000000
22.880001,8.335564,-342.725739,-0.003617,0.000747,0.018984,37.078438,1.888866,0.189836,-342.725739,0.019990,0.000000
23.110001,8.392159,-342.725739,-0.003613,0.000761,0.019322,37.330185,1.901690,0.193218,-342.725739,0.020371,0.000000
23.340002,8.461052,-342.725739,-0.003604,0.000775,0.019677,37.636639,1.917302,0.196774,-342.725739,0.020753,0.000000
23.570002,8.569786,-342.681244,-0.003570,0.000790,0.020068,38.120312,1.941941,0.200676,-342.681244,0.021134,0.000000
23.800001,8.876991,-342.725739,-0.003570,0.000814,0.020666,39.486828,2.011555,0.206660,-342.725739,0.021525,0.000000
24.030001,8.887047,-342.770203,-0.003548,0.000830,0.021091,39.531559,2.013834,0.210909,-342.770203,0.021906,0.000000
24.260000,8.858368,-342.770203,-0.003540,0.000842,0.021377,39.403988,2.007335,0.213771,-342.770203,0.022288,0.000000
24.490002,8.872520,-342.770203,-0.003527,0.000857,0.021776,39.466942,2.010542,0.217760,-342.770203,0.022669,0.000000
24.720001,8.802887,-342.814697,-0.003510,0.000868,0.022054,39.157196,1.994763,0.220536,-342.814697,0.023051,0.000000
24.950001,9.111214,-342.814697,-0.003492,0.000887,0.022539,40.528702,2.064631,0.225392,-342.814697,0.023441,0.000000
25.180000,9.123131,-342.814697,-0.003479,0.000900,0.022860,40.581711,2.067331,0.228601,-342.814697,0.023823,0.000000
25.410002,9.078819,-342.814697,-0.003466,0.000913,0.023190,40.384605,2.057290,0.231896,-342.814697,0.024204,0.000000
25.640001,9.228508,-342.859161,-0.003458,0.000930,0.023623,41.050453,2.091210,0.236232,-342.859161,0.024586,0.000000
25.870001,9.428848,-342.859161,-0.003423,0.000948,0.024092,41.941612,2.136607,0.240915,-342.859161,0.024967,0.000000
26.100000,9.518959,-342.859161,-0.003410,0.000965,0.024499,42.342445,2.157027,0.244991,-342.859161,0.025358,0.000000
26.330002,9.477997,-342.903656,-0.003402,0.000978,0.024837,42.160236,2.147745,0.248373,-342.903656,0.025739,0.000000
26.560001,9.355118,-342.859161,-0.003397,0.000986,0.025054,41.613644,2.119900,0.250542,-342.859161,0.026121,0.000000
26.790001,9.548752,-342.903656,-0.003376,0.001005,0.025531,42.474968,2.163778,0.255311,-342.903656,0.026502,0.000000
27.020000,9.800842,-342.903656,-0.003350,0.001023,0.025982,43.596325,2.220903,0.259821,-342.903656,0.026884,0.000000
27.250002,9.776268,-342.903656,-0.003346,0.001035,0.026286,43.487011,2.215334,0.262856,-342.903656,0.027274,0.000000
27.480001,9.835480,-342.992615,-0.003333,0.001049,0.026641,43.750401,2.228751,0.266412,-342.992615,0.027656,0.000000
27.710001,10.146034,-342.948120,-0.003316,0.001070,0.027179,45.131813,2.299124,0.271789,-342.948120,0.028037,0.000000
27.940001,10.197792,-342.948120,-0.003298,0.001085,0.027552,45.362045,2.310853,0.275518,-342.948120,0.028419,0.000000
28.170002,10.195190,-342.948120,-0.003281,0.001098,0.027881,45.350471,2.310263,0.278813,-342.948120,0.028801,0.000000
28.400002,10.290512,-343.037109,-0.003281,0.001116,0.028341,45.774483,2.331863,0.283409,-343.037109,0.029191,0.000000
28.630001,10.110291,-342.948120,-0.003260,0.001123,0.028514,44.972816,2.291025,0.285144,-342.948120,0.029572,0.000000
28.860001,10.404091,-342.948120,-0.003242,0.001143,0.029035,46.279709,2.357601,0.290347,-342.948120,0.029954,0.000000
29.090002,10.400368,-342.992615,-0.003229,0.001155,0.029330,46.263145,2.356757,0.293296,-342.992615,0.030336,0.000000
29.320002,10.518784,-343.037109,-0.003216,0.001171,0.029746,46.789886,2.383590,0.297458,-343.037109,0.030726,0.000000
29.550001,10.821144,-342.992615,-0.003199,0.001190,0.030231,48.134853,2.452106,0.302315,-342.992615,0.031107,0.000000
29.780001,10.777580,-343.037109,-0.003182,0.001201,0.030518,47.941071,2.442235,0.305177,-343.037109,0.031489,0.000000
30.010002,10.728424,-342.992615,-0.003186,0.001215,0.030856,47.722412,2.431096,0.308559,-342.992615,0.031871,0.000000
30.240002,10.885941,-343.126068,-0.003156,0.001231,0.031272,48.423080,2.466789,0.312722,-343.126068,0.032252,0.000000
30.470001,11.069519,-343.126068,-0.003139,0.001248,0.031697,49.239681,2.508389,0.316971,-343.126068,0.032642,0.000000
30.700001,11.064308,-343.126068,-0.003130,0.001260,0.032009,49.216499,2.507208,0.320093,-343.126068,0.033024,0.000000
30.930002,11.356247,-343.081573,-0.003122,0.001280,0.032521,50.515110,2.573362,0.325210,-343.081573,0.033406,0.000000
31.160002,11.320869,-343.081573,-0.003100,0.001293,0.032833,50.357742,2.565346,0.328332,-343.081573,0.033787,0.000000
31.390001,11.300758,-343.081573,-0.003087,0.001306,0.033171,50.268284,2.560788,0.331714,-343.081573,0.034169,0.000000
31.620001,11.513016,-343.126068,-0.003074,0.001323,0.033596,51.212452,2.608887,0.335963,-343.126068,0.034559,0.000000
31.850002,11.702927,-343.170532,-0.003057,0.001339,0.034004,52.057217,2.651921,0.340039,-343.170532,0.034941,0.000000
32.080002,11.603500,-343.126068,-0.003057,0.001352,0.034333,51.614948,2.629391,0.343335,-343.126068,0.035322,0.000000
32.310001,11.967308,-343.126068,-0.003022,0.001372,0.034845,53.233246,2.711831,0.348451,-343.126068,0.035704,0.000000
32.540001,11.886131,-343.170532,-0.003018,0.001384,0.035149,52.872154,2.693436,0.351487,-343.170532,0.036085,0.000000
32.770000,12.038429,-343.215027,-0.002997,0.001400,0.035565,53.549606,2.727947,0.355649,-343.215027,0.036476,0.000000
33.000000,12.011993,-343.215027,-0.002997,0.001412,0.035860,53.432014,2.721956,0.358598,-343.215027,0.036857,0.000000
33.230003,12.411919,-343.170532,-0.002971,0.001433,0.036389,55.210972,2.812581,0.363888,-343.170532,0.037239,0.000000
33.460003,12.530334,-343.215027,-0.002962,0.001449,0.036814,55.737713,2.839414,0.368137,-343.215027,0.037620,0.000000
33.690002,12.531456,-343.215027,-0.002945,0.001462,0.037135,55.742699,2.839669,0.371346,-343.215027,0.038002,0.000000
33.920002,12.573532,-343.303986,-0.002932,0.001476,0.037499,55.929863,2.849203,0.374988,-343.303986,0.038392,0.000000
34.150002,12.450279,-343.303986,-0.002919,0.001488,0.037802,55.381607,2.821274,0.378024,-343.303986,0.038774,0.000000
34.380001,12.632736,-343.259491,-0.002893,0.001504,0.038210,56.193218,2.862619,0.382100,-343.259491,0.039155,0.000000
34.610001,13.011810,-343.259491,-0.002880,0.001524,0.038704,57.879421,2.948518,0.387043,-343.259491,0.039537,0.000000
34.840000,12.982765,-343.348450,-0.002884,0.001536,0.039016,57.750225,2.941937,0.390165,-343.348450,0.039918,0.000000
35.070004,12.922447,-343.303986,-0.002854,0.001547,0.039285,57.481915,2.928268,0.392853,-343.303986,0.040309,0.000000
35.300003,13.171188,-343.259491,-0.002850,0.001563,0.039710,58.588371,2.984634,0.397103,-343.259491,0.040690,0.000000
35.530003,13.749481,-343.303986,-0.002828,0.001587,0.040309,61.160748,3.115677,0.403086,-343.303986,0.041072,0.000000
35.760002,13.648567,-343.348450,-0.002811,0.001599,0.040621,60.711861,3.092809,0.406209,-343.348450,0.041453,0.000000
35.990002,13.660484,-343.392944,-0.002802,0.001614,0.040985,60.764870,3.095510,0.409851,-343.392944,0.041835,0.000000
36.220001,13.677612,-343.437408,-0.002794,0.001626,0.041297,60.841057,3.099391,0.412973,-343.437408,0.042225,0.000000
36.450001,13.730118,-343.392944,-0.002777,0.001642,0.041696,61.074615,3.111289,0.416962,-343.392944,0.042607,0.000000
36.680000,13.969925,-343.303986,-0.002755,0.001656,0.042069,62.141331,3.165630,0.420691,-343.303986,0.042988,0.000000
36.910000,14.018333,-343.392944,-0.002751,0.001668,0.042373,62.356663,3.176600,0.423726,-343.392944,0.043370,0.000000
37.140003,14.131912,-343.392944,-0.002734,0.001682,0.042711,62.861885,3.202337,0.427109,-343.392944,0.043752,0.000000
37.370003,14.529976,-343.437408,-0.002721,0.001702,0.043223,64.632561,3.292540,0.432225,-343.437408,0.044142,0.000000
37.600002,14.858040,-343.437408,-0.002721,0.001720,0.043682,66.091866,3.366880,0.436822,-343.437408,0.044523,0.000000
37.830002,14.688980,-343.481903,-0.002690,0.001730,0.043942,65.339844,3.328570,0.439423,-343.481903,0.044905,0.000000
38.060001,14.812981,-343.437408,-0.002686,0.001746,0.044359,65.891426,3.356669,0.443586,-343.437408,0.045287,0.000000
38.290001,14.793617,-343.481903,-0.002669,0.001757,0.044619,65.805298,3.352282,0.446188,-343.481903,0.045677,0.000000
38.520000,15.283661,-343.481903,-0.002652,0.001778,0.045165,67.985123,3.463327,0.451651,-343.481903,0.046058,0.000000
38.750000,15.283661,-343.481903,-0.002639,0.001789,0.045451,67.985123,3.463327,0.454513,-343.481903,0.046440,0.000000
38.980003,15.237854,-343.437408,-0.002617,0.001801,0.045755,67.781357,3.452947,0.457548,-343.437408,0.046822,0.000000
39.210003,15.604271,-343.481903,-0.002617,0.001821,0.046249,69.411263,3.535978,0.462491,-343.481903,0.047203,0.000000
39.440002,15.820244,-343.615356,-0.002587,0.001836,0.046639,70.371956,3.584918,0.466394,-343.615356,0.047593,0.000000
39.670002,16.046646,-343.481903,-0.002583,0.001852,0.047047,71.379044,3.636222,0.470470,-343.481903,0.047975,0.000000
39.900002,16.147560,-343.481903,-0.002574,0.001867,0.047429,71.827934,3.659089,0.474286,-343.481903,0.048357,0.000000
40.130001,16.098412,-343.526398,-0.002548,0.001878,0.047706,71.609314,3.647952,0.477061,-343.526398,0.048738,0.000000
40.360001,16.425728,-343.570862,-0.002535,0.001896,0.048166,73.065285,3.722123,0.481657,-343.570862,0.049120,0.000000
40.590000,16.623825,-343.570862,-0.002522,0.001910,0.048521,73.946465,3.767013,0.485213,-343.570862,0.049510,0.000000
40.820004,16.599991,-343.526398,-0.002522,0.001921,0.048799,73.840446,3.761612,0.487988,-343.526398,0.049891,0.000000
41.050003,17.015564,-343.615356,-0.002496,0.001940,0.049267,75.689011,3.855782,0.492671,-343.615356,0.050273,0.000000
41.280003,17.154083,-343.570862,-0.002475,0.001955,0.049649,76.305176,3.887171,0.496487,-343.570862,0.050655,0.000000
41.510002,17.579704,-343.615356,-0.002458,0.001973,0.050126,78.198433,3.983618,0.501256,-343.615356,0.051036,0.000000
41.740002,17.622528,-343.659821,-0.002453,0.001988,0.050490,78.388924,3.993322,0.504899,-343.659821,0.051426,0.000000
41.970001,17.848557,-343.615356,-0.002436,0.002003,0.050889,79.394348,4.044541,0.508888,-343.615356,0.051808,0.000000
42.200001,17.782280,-343.570862,-0.002427,0.002018,0.051253,79.099533,4.029522,0.512530,-343.570862,0.052190,0.000000
42.430000,18.263382,-343.659821,-0.002402,0.002035,0.051687,81.239578,4.138541,0.516867,-343.659821,0.052571,0.000000
42.660004,17.984474,-343.704315,-0.002406,0.002041,0.051851,79.998940,4.075340,0.518514,-343.704315,0.052953,0.000000
42.890003,18.576546,-343.704315,-0.002393,0.002062,0.052380,82.632599,4.209506,0.523804,-343.704315,0.053343,0.000000
43.120003,18.802948,-343.615356,-0.002367,0.002077,0.052762,83.639687,4.260809,0.527620,-343.615356,0.053725,0.000000
43.350002,19.075897,-343.615356,-0.002354,0.002095,0.053204,84.853828,4.322660,0.532043,-343.615356,0.054106,0.000000
43.580002,19.294853,-343.659821,-0.002337,0.002111,0.053621,85.827797,4.372276,0.536206,-343.659821,0.054488,0.000000
43.810001,19.415131,-343.748779,-0.002337,0.002126,0.053993,86.362816,4.399532,0.539935,-343.748779,0.054869,0.000000
44.040001,19.449387,-343.748779,-0.002315,0.002138,0.054306,86.515190,4.407294,0.543057,-343.748779,0.055260,0.000000
44.270000,19.323524,-343.704315,-0.002311,0.002146,0.054514,85.955330,4.378773,0.545138,-343.704315,0.055641,0.000000
44.500004,19.811333,-343.704315,-0.002294,0.002165,0.054982,88.125206,4.489312,0.549821,-343.704315,0.056023,0.000000
44.730003,19.913368,-343.793274,-0.002276,0.002180,0.055372,88.579086,4.512434,0.553724,-343.793274,0.056404,0.000000
44.960003,20.167694,-343.748779,-0.002268,0.002191,0.055659,89.710381,4.570065,0.556585,-343.748779,0.056786,0.000000
45.190002,21.090065,-343.793274,-0.002259,0.002217,0.056309,93.813293,4.779077,0.563090,-343.793274,0.057176,0.000000
45.420002,21.367104,-343.748779,-0.002246,0.002233,0.056717,95.045624,4.841855,0.567166,-343.748779,0.057558,0.000000
45.650002,21.415146,-343.748779,-0.002225,0.002248,0.057107,95.259323,4.852741,0.571068,-343.748779,0.057939,0.000000
45.880001,21.369339,-343.793274,-0.002220,0.002259,0.057384,95.055565,4.842361,0.573843,-343.793274,0.058321,0.000000
46.110001,21.473976,-343.882233,-0.002212,0.002272,0.057705,95.521019,4.866073,0.577052,-343.882233,0.058703,0.000000
46.340004,22.264526,-343.793274,-0.002190,0.002292,0.058208,99.037560,5.045214,0.582082,-343.793274,0.059093,0.000000
46.570004,22.251122,-343.793274,-0.002182,0.002303,0.058503,98.977928,5.042176,0.585030,-343.793274,0.059474,0.000000
46.800003,22.459648,-343.837738,-0.002156,0.002316,0.058833,99.905502,5.089429,0.588326,-343.837738,0.059856,0.000000
47.030003,22.871117,-343.882233,-0.002143,0.002334,0.059275,101.735809,5.182669,0.592749,-343.882233,0.060238,0.000000
47.260002,23.502663,-343.837738,-0.002139,0.002353,0.059761,104.545067,5.325779,0.597605,-343.837738,0.060628,0.000000
47.490002,23.709702,-343.926727,-0.002134,0.002367,0.060125,105.466019,5.372695,0.601248,-343.926727,0.061009,0.000000
47.720001,23.659431,-343.837738,-0.002108,0.002379,0.060420,105.242409,5.361304,0.604196,-343.837738,0.061391,0.000000
47.950001,23.735771,-343.882233,-0.002100,0.002392,0.060758,105.581985,5.378603,0.607578,-343.882233,0.061772,0.000000
48.180004,24.333427,-343.926727,-0.002095,0.002409,0.061183,108.240494,5.514033,0.611828,-343.926727,0.062154,0.000000
48.410004,24.791817,-343.882233,-0.002082,0.002424,0.061564,110.279510,5.617906,0.615644,-343.882233,0.062544,0.000000
48.640003,24.744896,-343.837738,-0.002057,0.002434,0.061816,110.070793,5.607274,0.618159,-343.837738,0.062926,0.000000
48.870003,25.263985,-343.926727,-0.002052,0.002453,0.062310,112.379814,5.724901,0.623102,-343.926727,0.063307,0.000000
49.100002,26.127144,-343.971191,-0.002039,0.002474,0.062839,116.219337,5.920496,0.628392,-343.971191,0.063689,0.000000
49.330002,26.056763,-343.971191,-0.002022,0.002483,0.063073,115.906273,5.904547,0.630733,-343.971191,0.064071,0.000000
49.560001,26.430252,-343.971191,-0.002022,0.002501,0.063524,117.567635,5.989181,0.635243,-343.971191,0.064461,0.000000
49.790001,26.739700,-343.971191,-0.002005,0.002515,0.063871,118.944130,6.059303,0.638712,-343.971191,0.064842,0.000000
50.020004,26.786240,-343.971191,-0.001983,0.002526,0.064166,119.151146,6.069849,0.641660,-343.971191,0.065224,0.000000
50.250004,27.431564,-343.971191,-0.001966,0.002545,0.064643,122.021690,6.216081,0.646430,-343.971191,0.065606,0.000000
50.480003,27.584984,-344.060150,-0.001970,0.002556,0.064912,122.704140,6.250847,0.649118,-344.060150,0.065987,0.000000
50.710003,28.269028,-344.060150,-0.001949,0.002574,0.065389,125.746918,6.405853,0.653888,-344.060150,0.066377,0.000000
50.940002,28.897964,-343.971191,-0.001944,0.002593,0.065857,128.544571,6.548372,0.658571,-343.971191,0.066759,0.000000
51.170002,28.808228,-344.060150,-0.001910,0.002603,0.066126,128.145401,6.528038,0.661260,-344.060150,0.067141,0.000000
51.400002,28.934090,-344.060150,-0.001901,0.002615,0.066412,128.705261,6.556558,0.664121,-344.060150,0.067522,0.000000
51.630001,29.582016,-344.149109,-0.001901,0.002633,0.066880,131.587372,6.703381,0.668805,-344.149109,0.067904,0.000000
51.860001,30.258247,-344.104645,-0.001893,0.002650,0.067305,134.595413,6.856616,0.673054,-344.104645,0.068294,0.000000
52.090004,30.518532,-344.060150,-0.001871,0.002667,0.067730,135.753204,6.915598,0.677303,-344.060150,0.068676,0.000000
52.320004,31.167580,-344.104645,-0.001850,0.002682,0.068112,138.640320,7.062675,0.681119,-344.104645,0.069057,0.000000
52.550003,31.422653,-344.149109,-0.001854,0.002696,0.068485,139.774948,7.120475,0.684848,-344.149109,0.069439,0.000000
52.780003,32.142448,-344.104645,-0.001841,0.002714,0.068927,142.976746,7.283583,0.689271,-344.104645,0.069820,0.000000
53.010002,32.299591,-344.149109,-0.001837,0.002726,0.069239,143.675751,7.319192,0.692393,-344.149109,0.070211,0.000000
53.240002,32.717766,-344.104645,-0.001811,0.002739,0.069578,145.535889,7.413952,0.695775,-344.104645,0.070592,0.000000
53.470001,33.204086,-344.193604,-0.001819,0.002756,0.070011,147.699158,7.524154,0.700111,-344.193604,0.070974,0.000000
53.700001,33.850525,-344.149109,-0.001789,0.002772,0.070410,150.574661,7.670639,0.704101,-344.149109,0.071355,0.000000
53.930004,34.432167,-344.149109,-0.001785,0.002790,0.070870,153.161926,7.802441,0.708697,-344.149109,0.071737,0.000000
54.160004,34.642929,-344.193604,-0.001785,0.002800,0.071121,154.099442,7.850200,0.711212,-344.193604,0.072127,0.000000
54.390003,34.919975,-344.104645,-0.001768,0.002813,0.071442,155.331802,7.912980,0.714421,-344.104645,0.072509,0.000000
54.620003,36.110077,-344.238068,-0.001750,0.002835,0.071997,160.625641,8.182660,0.719971,-344.238068,0.072890,0.000000
54.850002,36.880516,-344.282562,-0.001738,0.002853,0.072474,164.052734,8.357244,0.724741,-344.282562,0.073272,0.000000
55.080002,36.961319,-344.238068,-0.001733,0.002864,0.072734,164.412155,8.375554,0.727342,-344.238068,0.073662,0.000000
55.310001,37.364975,-344.149109,-0.001716,0.002878,0.073107,166.207703,8.467024,0.731071,-344.149109,0.074044,0.000000
55.540001,37.558975,-344.193604,-0.001699,0.002892,0.073445,167.070663,8.510985,0.734454,-344.193604,0.074425,0.000000
55.770004,38.356232,-344.282562,-0.001694,0.002909,0.073879,170.617035,8.691647,0.738790,-344.282562,0.074807,0.000000
56.000004,39.158318,-344.282562,-0.001694,0.002923,0.074252,174.184891,8.873402,0.742519,-344.282562,0.075188,0.000000
56.230003,39.491219,-344.238068,-0.001673,0.002937,0.074590,175.665710,8.948838,0.745901,-344.238068,0.075579,0.000000
56.460003,39.788376,-344.238068,-0.001660,0.002950,0.074928,176.987534,9.016174,0.749283,-344.238068,0.075960,0.000000
56.690002,40.509659,-344.238068,-0.001647,0.002963,0.075267,180.195969,9.179620,0.752665,-344.238068,0.076342,0.000000
56.920002,42.034897,-344.327057,-0.001638,0.002988,0.075900,186.980560,9.525244,0.758996,-344.327057,0.076723,0.000000
57.150002,42.335030,-344.371521,-0.001638,0.002999,0.076186,188.315613,9.593255,0.761858,-344.371521,0.077105,0.000000
57.380001,42.805710,-344.282562,-0.001625,0.003014,0.076567,190.409302,9.699912,0.765674,-344.282562,0.077495,0.000000
57.610004,43.109192,-344.327057,-0.001604,0.003026,0.076862,191.759262,9.768682,0.768622,-344.327057,0.077877,0.000000
57.840004,44.099327,-344.327057,-0.001604,0.003046,0.077357,196.163605,9.993051,0.773565,-344.327057,0.078258,0.000000
58.070004,44.377121,-344.416016,-0.001587,0.003055,0.077608,197.399292,10.056000,0.776080,-344.416016,0.078640,0.000000
58.300003,44.842583,-344.416016,-0.001587,0.003070,0.077981,199.469772,10.161474,0.779809,-344.416016,0.079022,0.000000
58.530003,45.604462,-344.371521,-0.001574,0.003085,0.078371,202.858780,10.334119,0.783712,-344.371521,0.079412,0.000000
58.760002,46.688431,-344.371521,-0.001565,0.003106,0.078892,207.680511,10.579749,0.788915,-344.371521,0.079793,0.000000
58.990002,47.556061,-344.460480,-0.001548,0.003120,0.079256,211.539917,10.776357,0.792558,-344.460480,0.080175,0.000000
59.220001,47.737038,-344.504974,-0.001548,0.003132,0.079542,212.344955,10.817368,0.795419,-344.504974,0.080557,0.000000
59.450005,48.610619,-344.371521,-0.001535,0.003148,0.079950,216.230835,11.015324,0.799495,-344.371521,0.080938,0.000000
59.680004,49.019485,-344.460480,-0.001518,0.003162,0.080314,218.049561,11.107974,0.803138,-344.460480,0.081328,0.000000
59.910004,50.113518,-344.460480,-0.001509,0.003177,0.080704,222.916061,11.355886,0.807040,-344.460480,0.081710,0.000000
60.140003,50.697021,-344.504974,-0.001500,0.003191,0.081042,225.511612,11.488109,0.810422,-344.504974,0.082092,0.000000
60.370003,51.225792,-344.549438,-0.001505,0.003206,0.081424,227.863708,11.607930,0.814238,-344.549438,0.082473,0.000000
60.600002,52.233429,-344.504974,-0.001505,0.003223,0.081875,232.345901,11.836265,0.818748,-344.504974,0.082855,0.000000
60.830002,53.025467,-344.504974,-0.001483,0.003238,0.082239,235.869064,12.015743,0.822390,-344.504974,0.083245,0.000000
61.060001,53.804848,-344.504974,-0.001466,0.003252,0.082612,239.335922,12.192352,0.826119,-344.504974,0.083627,0.000000
61.290005,54.504158,-344.549438,-0.001462,0.003266,0.082967,242.446609,12.350819,0.829675,-344.549438,0.084008,0.000000
61.520004,55.030693,-344.549438,-0.001457,0.003280,0.083314,244.788742,12.470134,0.833144,-344.549438,0.084390,0.000000
61.750004,56.116158,-344.549438,-0.001462,0.003298,0.083765,249.617142,12.716104,0.837653,-344.549438,0.084771,0.000000
61.980003,56.839684,-344.549438,-0.001436,0.003310,0.084078,252.835541,12.880056,0.840775,-344.549438,0.085162,0.000000
62.210003,57.336052,-344.549438,-0.001423,0.003322,0.084390,255.043503,12.992536,0.843897,-344.549438,0.085543,0.000000
62.440002,58.602119,-344.549438,-0.001423,0.003342,0.084875,260.675232,13.279429,0.848754,-344.549438,0.085925,0.000000
62.670002,59.586296,-344.593933,-0.001414,0.003358,0.085283,265.053070,13.502447,0.852830,-344.593933,0.086306,0.000000
62.900002,60.651657,-344.593933,-0.001401,0.003373,0.085682,269.792053,13.743862,0.856819,-344.593933,0.086688,0.000000
63.130005,61.594879,-344.593933,-0.001406,0.003390,0.086116,273.987701,13.957599,0.861155,-344.593933,0.087078,0.000000
63.360004,62.331055,-344.682892,-0.001393,0.003404,0.086462,277.262390,14.124419,0.864624,-344.682892,0.087460,0.000000
63.590004,63.225494,-344.638397,-0.001384,0.003418,0.086818,281.241058,14.327102,0.868180,-344.638397,0.087841,0.000000
63.820004,64.277817,-344.682892,-0.001375,0.003434,0.087226,285.921997,14.565561,0.872256,-344.682892,0.088223,0.000000
64.050003,64.399963,-344.638397,-0.001375,0.003441,0.087390,286.465332,14.593240,0.873903,-344.638397,0.088613,0.000000
64.280006,65.874924,-344.593933,-0.001354,0.003461,0.087919,293.026306,14.927471,0.879193,-344.593933,0.088995,0.000000
64.510002,66.840485,-344.682892,-0.001350,0.003477,0.088310,297.321320,15.146270,0.883096,-344.682892,0.089376,0.000000
64.740005,67.413574,-344.682892,-0.001345,0.003481,0.088414,299.870544,15.276134,0.884137,-344.682892,0.088648,0.000000
64.970001,66.684097,-344.682892,-0.001337,0.003481,0.088414,296.625671,15.110832,0.884137,-344.682892,0.088648,0.000000
65.200005,66.107651,-344.638397,-0.001328,0.003480,0.088396,294.061523,14.980207,0.883963,-344.638397,0.088414,0.000000
65.430000,65.525269,-344.682892,-0.001324,0.003480,0.088388,291.470947,14.848238,0.883876,-344.682892,0.088414,0.000000
65.660004,64.983093,-344.682892,-0.001319,0.003479,0.088379,289.059235,14.725379,0.883790,-344.682892,0.088414,0.000000
65.889999,64.504227,-344.727356,-0.001311,0.003479,0.088379,286.929138,14.616867,0.883790,-344.727356,0.088414,0.000000
66.120003,64.058868,-344.727356,-0.001319,0.003479,0.088370,284.948090,14.515947,0.883703,-344.727356,0.088414,0.000000
66.350006,63.643677,-344.682892,-0.001311,0.003479,0.088370,283.101227,14.421864,0.883703,-344.682892,0.088414,0.000000
66.580002,63.281723,-344.727356,-0.001311,0.003479,0.088370,281.491150,14.339844,0.883703,-344.727356,0.088414,0.000000
66.810005,62.942490,-344.816345,-0.001306,0.003479,0.088370,279.982178,14.262972,0.883703,-344.816345,0.088414,0.000000
67.040001,62.594322,-344.816345,-0.001315,0.003479,0.088370,278.433441,14.184076,0.883703,-344.816345,0.088414,0.000000
67.270004,62.288231,-344.771851,-0.001306,0.003479,0.088370,277.071899,14.114715,0.883703,-344.771851,0.088414,0.000000
67.500000,62.003372,-344.816345,-0.001306,0.003479,0.088370,275.804779,14.050165,0.883703,-344.816345,0.088414,0.000000
67.730003,61.740845,-344.816345,-0.001298,0.003479,0.088370,274.636993,13.990675,0.883703,-344.816345,0.088414,0.000000
67.960007,61.489494,-344.860809,-0.001293,0.003479,0.088370,273.518921,13.933719,0.883703,-344.860809,0.088414,0.000000
68.190002,61.255646,-344.816345,-0.001293,0.003479,0.088362,272.478729,13.880728,0.883616,-344.816345,0.088414,0.000000
68.420006,61.011368,-344.771851,-0.001293,0.003479,0.088362,271.392120,13.825374,0.883616,-344.771851,0.088414,0.000000
68.650002,60.824814,-344.816345,-0.001293,0.003479,0.088362,270.562286,13.783100,0.883616,-344.816345,0.088414,0.000000
68.880005,60.639366,-344.771851,-0.001289,0.003479,0.088362,269.737366,13.741077,0.883616,-344.771851,0.088414,0.000000
69.110001,60.437912,-344.860809,-0.001293,0.003479,0.088362,268.841248,13.695426,0.883616,-344.860809,0.088414,0.000000
69.340004,60.241676,-344.860809,-0.001281,0.003479,0.088362,267.968353,13.650959,0.883616,-344.860809,0.088414,0.000000
69.570000,60.058098,-344.860809,-0.001298,0.003479,0.088362,267.151764,13.609359,0.883616,-344.860809,0.088414,0.000000
69.800003,59.905426,-344.860809,-0.001293,0.003479,0.088362,266.472656,13.574764,0.883616,-344.860809,0.088414,0.000000
70.030006,59.747910,-344.860809,-0.001276,0.003479,0.088362,265.771973,13.539069,0.883616,-344.860809,0.088414,0.000000
70.260002,59.603432,-344.994263,-0.001289,0.003479,0.088362,265.129303,13.506330,0.883616,-344.994263,0.088414,0.000000
70.490005,59.457832,-344.905304,-0.001276,0.003479,0.088362,264.481659,13.473337,0.883616,-344.905304,0.088414,0.000000
70.720001,59.297714,-344.905304,-0.001281,0.003479,0.088362,263.769409,13.437055,0.883616,-344.905304,0.088414,0.000000
70.950005,59.175575,-344.860809,-0.001272,0.003479,0.088362,263.226105,13.409377,0.883616,-344.860809,0.088414,0.000000
71.180000,59.063492,-344.949768,-0.001272,0.003479,0.088362,262.727539,13.383979,0.883616,-344.949768,0.088414,0.000000
71.410004,58.945816,-344.994263,-0.001276,0.003479,0.088362,262.204071,13.357312,0.883616,-344.994263,0.088414,0.000000
71.640007,58.808784,-344.949768,-0.001276,0.003479,0.088362,261.594543,13.326261,0.883616,-344.949768,0.088414,0.000000
71.870003,58.684044,-344.949768,-0.001281,0.003479,0.088362,261.039673,13.297994,0.883616,-344.949768,0.088414,0.000000
72.100006,58.590950,-344.949768,-0.001285,0.003479,0.088362,260.625549,13.276899,0.883616,-344.949768,0.088414,0.000000
72.330002,58.469551,-344.994263,-0.001272,0.003479,0.088362,260.085541,13.249390,0.883616,-344.994263,0.088414,0.000000
72.560005,58.381676,-345.038727,-0.001289,0.003479,0.088362,259.694672,13.229477,0.883616,-345.038727,0.088414,0.000000
72.790001,58.258049,-344.994263,-0.001276,0.003479,0.088362,259.144745,13.201463,0.883616,-344.994263,0.088414,0.000000
73.020004,58.156013,-344.994263,-0.001276,0.003479,0.088362,258.690857,13.178341,0.883616,-344.994263,0.088414,0.000000
73.250000,58.078560,-344.994263,-0.001272,0.003479,0.088362,258.346344,13.160789,0.883616,-344.994263,0.088414,0.000000
73.480003,57.989563,-345.083221,-0.001272,0.003479,0.088362,257.950470,13.140622,0.883616,-345.083221,0.088414,0.000000
73.710007,57.897964,-345.083221,-0.001268,0.003479,0.088362,257.542999,13.119866,0.883616,-345.083221,0.088414,0.000000
73.940002,57.797424,-345.083221,-0.001263,0.003479,0.088362,257.095795,13.097083,0.883616,-345.083221,0.088414,0.000000
74.170006,57.721832,-345.127686,-0.001263,0.003479,0.088362,256.759521,13.079954,0.883616,-345.127686,0.088414,0.000000
74.400002,57.662621,-345.083221,-0.001250,0.003479,0.088362,256.496155,13.066536,0.883616,-345.083221,0.088414,0.000000
74.630005,57.568787,-345.083221,-0.001250,0.003479,0.088362,256.078766,13.045274,0.883616,-345.083221,0.088414,0.000000
74.860001,57.468987,-345.216675,-0.001255,0.003479,0.088362,255.634827,13.022658,0.883616,-345.216675,0.088414,0.000000
75.090004,57.402336,-345.083221,-0.001250,0.003479,0.088362,255.338348,13.007556,0.883616,-345.083221,0.088414,0.000000
75.320007,57.350204,-345.083221,-0.001246,0.003479,0.088362,255.106445,12.995742,0.883616,-345.083221,0.088414,0.000000
75.550003,57.279083,-345.083221,-0.001255,0.003479,0.088362,254.790085,12.979626,0.883616,-345.083221,0.088414,0.000000
75.780006,57.194923,-345.172180,-0.001255,0.003479,0.088362,254.415726,12.960555,0.883616,-345.172180,0.088414,0.000000
76.010002,57.112999,-345.261139,-0.001250,0.003479,0.088362,254.051300,12.941991,0.883616,-345.261139,0.088414,0.000000
76.240005,57.048584,-345.172180,-0.001255,0.003479,0.088362,253.764771,12.927394,0.883616,-345.172180,0.088414,0.000000
76.470001,56.983414,-345.172180,-0.001263,0.003479,0.088362,253.474884,12.912626,0.883616,-345.172180,0.088414,0.000000
76.700005,56.932404,-345.172180,-0.001250,0.003479,0.088362,253.247986,12.901067,0.883616,-345.172180,0.088414,0.000000
76.930000,56.856438,-345.261139,-0.001250,0.003479,0.088362,252.910065,12.883853,0.883616,-345.261139,0.088414,0.000000
77.160004,56.771164,-345.261139,-0.001263,0.003479,0.088362,252.530746,12.864530,0.883616,-345.261139,0.088414,0.000000
77.390007,56.735046,-345.216675,-0.001259,0.003479,0.088362,252.370087,12.856345,0.883616,-345.216675,0.088414,0.000000
77.620003,56.681053,-345.216675,-0.001246,0.003479,0.088362,252.129913,12.844110,0.883616,-345.216675,0.088414,0.000000
77.850006,56.613281,-345.261139,-0.001246,0.003479,0.088362,251.828445,12.828753,0.883616,-345.261139,0.088414,0.000000
78.080002,56.561516,-345.305634,-0.001250,0.003479,0.088362,251.598190,12.817022,0.883616,-345.305634,0.088414,0.000000
78.310005,56.497101,-345.261139,-0.001255,0.003479,0.088362,251.311661,12.802426,0.883616,-345.261139,0.088414,0.000000
78.540001,56.428207,-345.261139,-0.001255,0.003479,0.088362,251.005203,12.786814,0.883616,-345.261139,0.088414,0.000000
78.770004,56.395065,-345.350098,-0.001255,0.003479,0.088362,250.857773,12.779305,0.883616,-345.350098,0.088414,0.000000
79.000000,56.344795,-345.261139,-0.001259,0.003479,0.088362,250.634171,12.767913,0.883616,-345.261139,0.088414,0.000000
79.230003,56.289314,-345.350098,-0.001242,0.003479,0.088362,250.387375,12.755342,0.883616,-345.350098,0.088414,0.000000
79.460007,56.221169,-345.305634,-0.001250,0.003479,0.088362,250.084244,12.739899,0.883616,-345.305634,0.088414,0.000000
79.690002,56.189888,-345.305634,-0.001255,0.003479,0.088362,249.945099,12.732810,0.883616,-345.305634,0.088414,0.000000
79.920006,56.156746,-345.305634,-0.001255,0.003479,0.088362,249.797684,12.725301,0.883616,-345.305634,0.088414,0.000000
80.150002,56.084885,-345.350098,-0.001255,0.003479,0.088362,249.478027,12.709017,0.883616,-345.350098,0.088414,0.000000
80.380005,56.041687,-345.350098,-0.001255,0.003479,0.088362,249.285873,12.699227,0.883616,-345.350098,0.088414,0.000000
80.610001,55.993279,-345.350098,-0.001263,0.003479,0.088362,249.070541,12.688258,0.883616,-345.350098,0.088414,0.000000
80.840004,55.953804,-345.350098,-0.001255,0.003479,0.088362,248.894958,12.679313,0.883616,-345.350098,0.088414,0.000000
81.070007,55.900558,-345.394592,-0.001250,0.003479,0.088362,248.658096,12.667248,0.883616,-345.394592,0.088414,0.000000
81.300003,55.864067,-345.394592,-0.001242,0.003479,0.088362,248.495789,12.658978,0.883616,-345.394592,0.088414,0.000000
81.530006,55.825340,-345.439056,-0.001255,0.003479,0.088362,248.323517,12.650203,0.883616,-345.439056,0.088414,0.000000
81.760002,55.775070,-345.439056,-0.001255,0.003479,0.088362,248.099899,12.638811,0.883616,-345.439056,0.088414,0.000000
81.990005,55.723679,-345.350098,-0.001259,0.003479,0.088362,247.871307,12.627166,0.883616,-345.350098,0.088414,0.000000
82.220001,55.691284,-345.394592,-0.001242,0.003479,0.088362,247.727203,12.619825,0.883616,-345.394592,0.088414,0.000000
82.450005,55.655907,-345.528015,-0.001259,0.003479,0.088362,247.569839,12.611809,0.883616,-345.528015,0.088414,0.000000
82.680000,55.623512,-345.483551,-0.001255,0.003479,0.088362,247.425735,12.604467,0.883616,-345.483551,0.088414,0.000000
82.910004,55.571381,-345.394592,-0.001250,0.003479,0.088362,247.193848,12.592655,0.883616,-345.394592,0.088414,0.000000
83.140007,55.517014,-345.439056,-0.001242,0.003479,0.088362,246.952011,12.580335,0.883616,-345.439056,0.088414,0.000000
83.370003,55.492065,-345.483551,-0.001255,0.003479,0.088362,246.841034,12.574681,0.883616,-345.483551,0.088414,0.000000
83.600006,55.463394,-345.572510,-0.001250,0.003479,0.088362,246.713501,12.568185,0.883616,-345.572510,0.088414,0.000000
83.830002,55.428017,-345.528015,-0.001250,0.003479,0.088362,246.556137,12.560168,0.883616,-345.528015,0.088414,0.000000
84.060005,55.390404,-345.483551,-0.001250,0.003479,0.088362,246.388824,12.551645,0.883616,-345.483551,0.088414,0.000000
84.290001,55.340881,-345.483551,-0.001246,0.003479,0.088362,246.168533,12.540423,0.883616,-345.483551,0.088414,0.000000
84.520004,55.296196,-345.528015,-0.001246,0.003479,0.088362,245.969757,12.530297,0.883616,-345.528015,0.088414,0.000000
84.750008,55.261192,-345.528015,-0.001246,0.003479,0.088362,245.814056,12.522366,0.883616,-345.528015,0.088414,0.000000
84.980003,55.252632,-345.528015,-0.001255,0.003479,0.088362,245.775986,12.520425,0.883616,-345.528015,0.088414,0.000000
85.210007,55.212410,-345.528015,-0.001250,0.003479,0.088362,245.597061,12.511311,0.883616,-345.528015,0.088414,0.000000
85.440002,55.169220,-345.528015,-0.001250,0.003479,0.088362,245.404953,12.501524,0.883616,-345.528015,0.088414,0.000000
85.670006,55.142036,-345.572510,-0.001242,0.003479,0.088362,245.284027,12.495364,0.883616,-345.572510,0.088414,0.000000
85.900002,55.090645,-345.617004,-0.001250,0.003479,0.088362,245.055420,12.483719,0.883616,-345.617004,0.088414,0.000000
86.130005,55.062347,-345.617004,-0.001250,0.003479,0.088362,244.929550,12.477306,0.883616,-345.617004,0.088414,0.000000
86.360001,55.031441,-345.572510,-0.001246,0.003479,0.088362,244.792068,12.470303,0.883616,-345.572510,0.088414,0.000000
86.590004,55.009094,-345.617004,-0.001250,0.003479,0.088362,244.692673,12.465239,0.883616,-345.617004,0.088414,0.000000
86.820007,54.982285,-345.617004,-0.001255,0.003479,0.088362,244.573410,12.459164,0.883616,-345.617004,0.088414,0.000000
87.050003,54.948402,-345.617004,-0.001250,0.003479,0.088362,244.422699,12.451486,0.883616,-345.617004,0.088414,0.000000
87.280006,54.912277,-345.617004,-0.001246,0.003479,0.088362,244.262009,12.443299,0.883616,-345.617004,0.088414,0.000000
87.510002,54.873184,-345.617004,-0.001255,0.003479,0.088362,244.088120,12.434441,0.883616,-345.617004,0.088414,0.000000
87.740005,54.833336,-345.661469,-0.001242,0.003479,0.088362,243.910858,12.425411,0.883616,-345.661469,0.088414,0.000000
87.970001,54.803917,-345.661469,-0.001246,0.003479,0.088362,243.779999,12.418745,0.883616,-345.661469,0.088414,0.000000
88.200005,54.786049,-345.750427,-0.001250,0.003479,0.088362,243.700516,12.414697,0.883616,-345.750427,0.088414,0.000000
88.430008,54.754395,-345.705963,-0.001246,0.003479,0.088362,243.559708,12.407523,0.883616,-345.705963,0.088414,0.000000
88.660004,54.741737,-345.661469,-0.001250,0.003479,0.088362,243.503403,12.404655,0.883616,-345.661469,0.088414,0.000000
88.890007,54.710457,-345.617004,-0.001242,0.003479,0.088362,243.364273,12.397567,0.883616,-345.617004,0.088414,0.000000
89.120003,54.670609,-345.705963,-0.001246,0.003479,0.088362,243.187012,12.388536,0.883616,-345.705963,0.088414,0.000000
89.350006,54.645287,-345.839386,-0.001237,0.003479,0.088362,243.074371,12.382799,0.883616,-345.839386,0.088414,0.000000
89.580002,54.608795,-345.750427,-0.001246,0.003479,0.088362,242.912048,12.374530,0.883616,-345.750427,0.088414,0.000000
89.810005,54.582359,-345.705963,-0.001246,0.003479,0.088362,242.794464,12.368540,0.883616,-345.705963,0.088414,0.000000
90.040001,54.566719,-345.750427,-0.001246,0.003479,0.088362,242.724884,12.364996,0.883616,-345.750427,0.088414,0.000000
90.270004,54.543259,-345.750427,-0.001237,0.003479,0.088362,242.620529,12.359679,0.883616,-345.750427,0.088414,0.000000
90.500008,54.509003,-345.750427,-0.001250,0.003479,0.088362,242.468155,12.351916,0.883616,-345.750427,0.088414,0.000000
90.730003,54.491127,-345.794922,-0.001246,0.003479,0.088362,242.388641,12.347866,0.883616,-345.794922,0.088414,0.000000
90.960007,54.475113,-345.794922,-0.001246,0.003479,0.088362,242.317398,12.344237,0.883616,-345.794922,0.088414,0.000000
91.190002,54.444206,-345.794922,-0.001246,0.003479,0.088362,242.179932,12.337234,0.883616,-345.794922,0.088414,0.000000
91.420006,54.416649,-345.839386,-0.001237,0.003479,0.088362,242.057343,12.330989,0.883616,-345.839386,0.088414,0.000000
91.650002,54.386116,-345.839386,-0.001255,0.003479,0.088362,241.921524,12.324070,0.883616,-345.839386,0.088414,0.000000
91.880005,54.364517,-345.839386,-0.001237,0.003479,0.088362,241.825455,12.319176,0.883616,-345.839386,0.088414,0.000000
92.110001,54.337708,-345.839386,-0.001237,0.003479,0.088362,241.706192,12.313101,0.883616,-345.839386,0.088414,0.000000
92.340004,54.314247,-345.839386,-0.001233,0.003479,0.088362,241.601837,12.307784,0.883616,-345.839386,0.088414,0.000000
92.570007,54.288925,-345.928345,-0.001237,0.003479,0.088362,241.489197,12.302046,0.883616,-345.928345,0.088414,0.000000
92.800003,54.272171,-346.017303,-0.001250,0.003479,0.088362,241.414673,12.298249,0.883616,-346.017303,0.088414,0.000000
93.030006,54.262115,-345.839386,-0.001237,0.003479,0.088362,241.369949,12.295971,0.883616,-345.839386,0.088414,0.000000
93.260002,54.243500,-345.883881,-0.001246,0.003479,0.088362,241.287140,12.291753,0.883616,-345.883881,0.088414,0.000000
93.490005,54.201424,-345.883881,-0.001237,0.003479,0.088362,241.099976,12.282218,0.883616,-345.883881,0.088414,0.000000
93.720001,54.174980,-345.972839,-0.001250,0.003479,0.088362,240.982346,12.276226,0.883616,-345.972839,0.088414,0.000000
93.950005,54.164558,-345.972839,-0.001250,0.003479,0.088362,240.935989,12.273865,0.883616,-345.972839,0.088414,0.000000
94.180008,54.141838,-345.883881,-0.001250,0.003479,0.088362,240.834930,12.268716,0.883616,-345.883881,0.088414,0.000000
94.410004,54.122108,-345.928345,-0.001246,0.003479,0.088362,240.747162,12.264245,0.883616,-345.928345,0.088414,0.000000
94.640007,54.092316,-345.972839,-0.001242,0.003479,0.088362,240.614639,12.257494,0.883616,-345.972839,0.088414,0.000000
94.870003,54.068481,-345.972839,-0.001246,0.003479,0.088362,240.508621,12.252093,0.883616,-345.972839,0.088414,0.000000
95.100006,54.045769,-345.972839,-0.001242,0.003479,0.088362,240.407593,12.246946,0.883616,-345.972839,0.088414,0.000000
95.200005,54.039070,-345.972839,-0.001242,0.003479,0.088362,240.377792,12.245428,0.883616,-345.972839,0.088414,0.000000