File: Data/compression 11/AutoNoHeating-12-11-4-240530_05302024_161848.csv
Time (sec),S:Load (lbs),S:HL1 (DIM),S:LVDT (in),S:Position (in),Ch:Position (mm),Ch:Load (N),Ch:Stress (MPa),Ch:Strain (mm/mm),Ch:HL1 (DIM),Set Point (),Cycles ()
0.110000,0.004471,-110.891014,-0.008528,-0.000000,-0.000000,0.019887,0.001013,-0.000000,-110.891014,0.000199,0.000000
0.340000,-0.004097,-110.846527,-0.008528,0.000000,0.000009,-0.018224,-0.000928,0.000087,-110.846527,0.000373,0.000000
0.570000,0.018250,-110.935493,-0.008524,0.000123,0.003131,0.081178,0.004135,0.031307,-110.935493,0.004206,0.000000
0.800000,-0.012283,-110.891014,-0.008420,0.000275,0.006990,-0.054639,-0.002783,0.069898,-110.891014,0.008039,0.000000
1.030000,-0.000740,-111.024452,-0.008278,0.000425,0.010806,-0.003292,-0.000168,0.108056,-111.024452,0.011872,0.000000
1.260000,0.011169,-110.979973,-0.008140,0.000572,0.014535,0.049684,0.002531,0.145347,-110.979973,0.015705,0.000000
1.490000,0.030533,-110.979973,-0.007972,0.000721,0.018324,0.135817,0.006919,0.183245,-110.979973,0.019539,0.000000
1.720000,0.009682,-110.979973,-0.007821,0.000874,0.022192,0.043066,0.002194,0.221923,-110.979973,0.023372,0.000000
1.950000,-0.011917,-111.068932,-0.007666,0.001026,0.026069,-0.053010,-0.002700,0.260688,-111.068932,0.027205,0.000000
2.180000,-0.032021,-111.068932,-0.007515,0.001173,0.029807,-0.142435,-0.007256,0.298065,-111.068932,0.031038,0.000000
2.410000,-0.011543,-111.068932,-0.007386,0.001323,0.033614,-0.051347,-0.002616,0.336137,-111.068932,0.034871,0.000000
2.640000,0.050644,-111.113419,-0.007222,0.001476,0.037490,0.225275,0.011476,0.374902,-111.113419,0.038687,0.000000
2.870000,0.030533,-111.113419,-0.007049,0.001625,0.041280,0.135817,0.006919,0.412799,-111.113419,0.042520,0.000000
3.100000,0.003349,-111.113419,-0.006894,0.001784,0.045321,0.014898,0.000759,0.453212,-111.113419,0.046353,0.000000
3.330000,0.002609,-111.202377,-0.006748,0.001934,0.049120,0.011607,0.000591,0.491197,-111.202377,0.050186,0.000000
3.560000,0.021225,-111.157898,-0.006605,0.002084,0.052935,0.094413,0.004810,0.529355,-111.157898,0.054019,0.000000
3.790000,0.022346,-111.157898,-0.006446,0.002231,0.056673,0.099402,0.005064,0.566732,-111.157898,0.057853,0.000000
4.020000,0.032394,-111.246857,-0.006291,0.002383,0.060532,0.144098,0.007341,0.605323,-111.246857,0.061686,0.000000
4.250000,0.002983,-111.246857,-0.006140,0.002536,0.064426,0.013269,0.000676,0.644262,-111.246857,0.065519,0.000000
4.480000,-0.032021,-111.291336,-0.005989,0.002683,0.068155,-0.142435,-0.007256,0.681553,-111.291336,0.069352,0.000000
4.710000,-0.035744,-111.246857,-0.005851,0.002829,0.071850,-0.158996,-0.008100,0.718497,-111.246857,0.073185,0.000000
4.940000,0.024574,-111.246857,-0.005691,0.002987,0.075882,0.109312,0.005569,0.758823,-111.246857,0.077018,0.000000
5.170000,0.051758,-111.291336,-0.005540,0.003139,0.079733,0.230230,0.011728,0.797327,-111.291336,0.080851,0.000000
5.400000,0.047668,-111.335823,-0.005376,0.003293,0.083653,0.212040,0.010802,0.836526,-111.335823,0.084685,0.000000
5.630000,0.029045,-111.335823,-0.005230,0.003440,0.087364,0.129199,0.006582,0.873643,-111.335823,0.088500,0.000000
5.860000,0.012291,-111.246857,-0.005079,0.003589,0.091171,0.054673,0.002785,0.911714,-111.246857,0.092334,0.000000
6.090000,0.024574,-111.335823,-0.004919,0.003738,0.094953,0.109312,0.005569,0.949525,-111.335823,0.096167,0.000000
6.320000,0.018623,-111.380302,-0.004777,0.003889,0.098768,0.082841,0.004220,0.987683,-111.380302,0.100000,0.000000
6.550000,0.010056,-111.380302,-0.004635,0.004040,0.102619,0.044729,0.002279,1.026188,-111.380302,0.103833,0.000000
6.780000,0.012665,-111.380302,-0.004462,0.004193,0.106504,0.056336,0.002870,1.065040,-111.380302,0.107666,0.000000
7.010000,0.012665,-111.424782,-0.004312,0.004340,0.110224,0.056336,0.002870,1.102244,-111.424782,0.111499,0.000000
7.240000,0.034256,-111.424782,-0.004165,0.004499,0.114274,0.152378,0.007763,1.142743,-111.424782,0.115332,0.000000
7.470000,0.150070,-111.469261,-0.004018,0.004645,0.117986,0.667546,0.034006,1.179861,-111.469261,0.119165,0.000000
7.700000,0.575691,-111.513741,-0.003867,0.004795,0.121785,2.560802,0.130453,1.217845,-111.513741,0.122999,0.000000
7.930000,0.635269,-111.558228,-0.003824,-0.000000,-0.000009,2.825818,0.143954,-0.000087,-111.558228,0.000139,0.000000
8.160001,0.619255,-111.424782,-0.003816,-0.000001,-0.000017,2.754584,0.140325,-0.000173,-111.424782,0.000139,0.000000
8.390000,0.615906,-111.513741,-0.003820,-0.000001,-0.000017,2.739686,0.139566,-0.000173,-111.513741,0.000330,0.000000
8.620001,0.593559,-111.558228,-0.003824,-0.000000,-0.000009,2.640284,0.134502,-0.000087,-111.558228,0.000711,0.000000
8.850000,0.611809,-111.558228,-0.003816,0.000007,0.000173,2.721461,0.138638,0.001734,-111.558228,0.001093,0.000000
9.080001,0.668037,-111.558228,-0.003820,0.000021,0.000529,2.971579,0.151379,0.005290,-111.558228,0.001474,0.000000
9.310000,0.776772,-111.558228,-0.003794,0.000039,0.000997,3.455252,0.176019,0.009973,-111.558228,0.001856,0.000000
9.540001,0.844543,-111.602707,-0.003773,0.000052,0.001318,3.756717,0.191376,0.013182,-111.602707,0.002246,0.000000
9.770000,0.933914,-111.691666,-0.003764,0.000070,0.001778,4.154258,0.211628,0.017778,-111.691666,0.002628,0.000000
10.000000,0.979713,-111.691666,-0.003760,0.000082,0.002090,4.357983,0.222006,0.020900,-111.691666,0.003009,0.000000
10.230000,1.046371,-111.647186,-0.003742,0.000096,0.002437,4.654493,0.237111,0.024369,-111.647186,0.003391,0.000000
10.460000,1.126801,-111.647186,-0.003725,0.000113,0.002879,5.012259,0.255337,0.028792,-111.647186,0.003772,0.000000
10.690001,1.175957,-111.691666,-0.003708,0.000129,0.003287,5.230917,0.266476,0.032868,-111.691666,0.004163,0.000000
10.920000,1.229950,-111.691666,-0.003686,0.000142,0.003616,5.471091,0.278711,0.036163,-111.691666,0.004544,0.000000
11.150001,1.268677,-111.780632,-0.003682,0.000158,0.004024,5.643356,0.287486,0.040239,-111.780632,0.004926,0.000000
11.380000,1.288040,-111.691666,-0.003660,0.000170,0.004327,5.729489,0.291874,0.043275,-111.691666,0.005307,0.000000
11.610001,1.406082,-111.780632,-0.003643,0.000190,0.004822,6.254566,0.318623,0.048218,-111.780632,0.005689,0.000000
11.840000,1.418365,-111.825111,-0.003630,0.000200,0.005091,6.309205,0.321406,0.050906,-111.825111,0.006079,0.000000
12.070001,1.467896,-111.825111,-0.003626,0.000213,0.005403,6.529525,0.332630,0.054028,-111.825111,0.006461,0.000000
12.300000,1.539017,-111.869591,-0.003613,0.000230,0.005845,6.845888,0.348746,0.058451,-111.869591,0.006842,0.000000
12.530001,1.626900,-111.825111,-0.003591,0.000249,0.006331,7.236811,0.368661,0.063307,-111.825111,0.007224,0.000000
12.760000,1.660034,-111.869591,-0.003574,0.000264,0.006712,7.384201,0.376169,0.067123,-111.869591,0.007606,0.000000
12.990001,1.689079,-111.914070,-0.003557,0.000280,0.007120,7.513400,0.382751,0.071199,-111.914070,0.007996,0.000000
13.220000,1.729301,-111.914070,-0.003540,0.000293,0.007432,7.692317,0.391865,0.074321,-111.914070,0.008377,0.000000
13.450001,1.766533,-111.914070,-0.003535,0.000307,0.007796,7.857931,0.400302,0.077964,-111.914070,0.008759,0.000000
13.680000,1.822762,-111.914070,-0.003518,0.000322,0.008169,8.108048,0.413044,0.081693,-111.914070,0.009141,0.000000
13.910001,1.822021,-111.914070,-0.003505,0.000333,0.008464,8.104756,0.412876,0.084641,-111.914070,0.009522,0.000000
14.140000,1.936714,-111.958557,-0.003488,0.000353,0.008958,8.614935,0.438866,0.089584,-111.958557,0.009912,0.000000
14.370001,1.963150,-111.958557,-0.003479,0.000368,0.009357,8.732528,0.444856,0.093574,-111.958557,0.010294,0.000000
14.600000,1.952721,-112.003036,-0.003462,0.000381,0.009670,8.686135,0.442493,0.096696,-112.003036,0.010676,0.000000
14.830001,2.038742,-112.047516,-0.003445,0.000401,0.010181,9.068778,0.461986,0.101812,-112.047516,0.011057,0.000000
15.060000,2.023476,-112.003036,-0.003419,0.000414,0.010519,9.000869,0.458526,0.105195,-112.003036,0.011439,0.000000
15.290001,2.057358,-112.091995,-0.003415,0.000427,0.010840,9.151585,0.466204,0.108403,-112.091995,0.011829,0.000000
15.520000,2.052521,-112.180962,-0.003397,0.000438,0.011127,9.130068,0.465108,0.111265,-112.180962,0.012211,0.000000
15.750001,2.126991,-112.091995,-0.003376,0.000454,0.011525,9.461329,0.481983,0.115254,-112.091995,0.012592,0.000000
15.980000,2.172050,-112.091995,-0.003359,0.000470,0.011942,9.661763,0.492194,0.119417,-112.091995,0.012974,0.000000
16.210001,2.244659,-112.136475,-0.003346,0.000490,0.012436,9.984744,0.508647,0.124360,-112.136475,0.013364,0.000000
16.440001,2.297165,-112.225441,-0.003316,0.000507,0.012870,10.218300,0.520545,0.128696,-112.225441,0.013746,0.000000
16.670000,2.334404,-112.180962,-0.003311,0.000522,0.013269,10.383947,0.528984,0.132686,-112.180962,0.014127,0.000000
16.900002,2.316902,-112.269920,-0.003298,0.000537,0.013650,10.306095,0.525017,0.136501,-112.269920,0.014509,0.000000
17.130001,2.307968,-112.225441,-0.003285,0.000549,0.013945,10.266355,0.522993,0.139450,-112.225441,0.014890,0.000000
17.360001,2.347061,-112.225441,-0.003260,0.000563,0.014301,10.440249,0.531852,0.143006,-112.225441,0.015281,0.000000
17.590000,2.481491,-112.269920,-0.003242,0.000579,0.014699,11.038223,0.562314,0.146995,-112.269920,0.015662,0.000000
17.820002,2.470322,-112.314400,-0.003229,0.000592,0.015046,10.988540,0.559783,0.150464,-112.314400,0.016044,0.000000
18.050001,2.544426,-112.180962,-0.003229,0.000608,0.015437,11.318172,0.576575,0.154366,-112.180962,0.016425,0.000000
18.280001,2.509422,-112.269920,-0.003212,0.000621,0.015784,11.162468,0.568643,0.157835,-112.269920,0.016807,0.000000
18.510000,2.606606,-112.314400,-0.003182,0.000641,0.016269,11.594761,0.590665,0.162692,-112.314400,0.017197,0.000000
18.740002,2.643845,-112.403366,-0.003160,0.000655,0.016633,11.760408,0.599104,0.166334,-112.403366,0.017579,0.000000
18.970001,2.597298,-112.358879,-0.003160,0.000669,0.016980,11.553357,0.588556,0.169803,-112.358879,0.017960,0.000000
19.200001,2.646454,-112.358879,-0.003143,0.000683,0.017336,11.772015,0.599695,0.173358,-112.358879,0.018342,0.000000
19.430000,2.715714,-112.403366,-0.003122,0.000698,0.017735,12.080097,0.615389,0.177348,-112.403366,0.018723,0.000000
19.660002,2.744385,-112.403366,-0.003113,0.000712,0.018090,12.207633,0.621886,0.180903,-112.403366,0.019114,0.000000
19.890001,2.850510,-112.447845,-0.003091,0.000730,0.018533,12.679700,0.645935,0.185326,-112.447845,0.019495,0.000000
20.120001,2.856468,-112.447845,-0.003078,0.000743,0.018880,12.706205,0.647285,0.188795,-112.447845,0.019877,0.000000
20.350000,2.941002,-112.492325,-0.003070,0.000763,0.019374,13.082230,0.666441,0.193738,-112.492325,0.020258,0.000000
20.580002,2.932060,-112.492325,-0.003048,0.000776,0.019721,13.042456,0.664414,0.197207,-112.492325,0.020640,0.000000
20.810001,2.941368,-112.492325,-0.003022,0.000792,0.020120,13.083858,0.666524,0.201196,-112.492325,0.021030,0.000000
21.040001,2.910095,-112.581284,-0.003027,0.000804,0.020423,12.944750,0.659437,0.204232,-112.581284,0.021412,0.000000
21.270000,3.044891,-112.581284,-0.003005,0.000821,0.020857,13.544353,0.689982,0.208568,-112.581284,0.021793,0.000000
21.500002,3.132401,-112.536804,-0.002992,0.000838,0.021290,13.933614,0.709812,0.212904,-112.536804,0.022175,0.000000
21.730001,3.125320,-112.581284,-0.002971,0.000849,0.021559,13.902120,0.708208,0.215592,-112.581284,0.022557,0.000000
21.960001,3.202774,-112.670250,-0.002953,0.000867,0.022028,14.246651,0.725759,0.220275,-112.670250,0.022947,0.000000
22.190001,3.230705,-112.670250,-0.002936,0.000882,0.022392,14.370894,0.732088,0.223918,-112.670250,0.023328,0.000000
22.420002,3.201660,-112.670250,-0.002932,0.000891,0.022643,14.241695,0.725507,0.226433,-112.670250,0.023710,0.000000
22.650002,3.152878,-112.670250,-0.002932,0.000903,0.022947,14.024701,0.714452,0.229468,-112.670250,0.024092,0.000000
22.880001,3.337578,-112.581284,-0.002893,0.000924,0.023458,14.846288,0.756306,0.234585,-112.581284,0.024473,0.000000
23.110001,3.376305,-112.670250,-0.002871,0.000939,0.023857,15.018553,0.765082,0.238574,-112.670250,0.024863,0.000000
23.340002,3.497322,-112.714729,-0.002876,0.000960,0.024378,15.556866,0.792504,0.243777,-112.714729,0.025245,0.000000
23.570002,3.430672,-112.759209,-0.002850,0.000971,0.024655,15.260390,0.777401,0.246552,-112.759209,0.025627,0.000000
23.800001,3.537910,-112.714729,-0.002841,0.000987,0.025063,15.737411,0.801702,0.250628,-112.714729,0.026008,0.000000
24.030001,3.575150,-112.714729,-0.002824,0.001002,0.025444,15.903059,0.810140,0.254444,-112.714729,0.026390,0.000000
24.260000,3.676437,-112.803696,-0.002802,0.001022,0.025956,16.353611,0.833093,0.259561,-112.803696,0.026780,0.000000
24.490002,3.604195,-112.803696,-0.002785,0.001030,0.026164,16.032259,0.816722,0.261642,-112.803696,0.027162,0.000000
24.720001,3.671593,-112.759209,-0.002781,0.001049,0.026641,16.332060,0.831995,0.266412,-112.759209,0.027543,0.000000
24.950001,3.718887,-112.848175,-0.002746,0.001064,0.027031,16.542437,0.842712,0.270314,-112.848175,0.027925,0.000000
25.180000,3.798943,-112.803696,-0.002734,0.001082,0.027474,16.898540,0.860853,0.274737,-112.803696,0.028315,0.000000
25.410002,3.802299,-112.892654,-0.002725,0.001093,0.027769,16.913473,0.861613,0.277686,-112.892654,0.028696,0.000000
25.640001,3.940071,-112.937134,-0.002708,0.001111,0.028228,17.526312,0.892833,0.282282,-112.937134,0.029078,0.000000
25.870001,3.918846,-112.892654,-0.002703,0.001123,0.028523,17.431898,0.888023,0.285231,-112.892654,0.029460,0.000000
26.100000,4.020134,-112.937134,-0.002669,0.001144,0.029061,17.882448,0.910975,0.290607,-112.937134,0.029841,0.000000
26.330002,4.055885,-112.892654,-0.002647,0.001158,0.029408,18.041479,0.919077,0.294076,-112.892654,0.030231,0.000000
26.560001,4.044342,-112.937134,-0.002647,0.001171,0.029755,17.990131,0.916461,0.297545,-112.937134,0.030613,0.000000
26.790001,4.108383,-113.026100,-0.002626,0.001186,0.030119,18.275002,0.930973,0.301187,-113.026100,0.030995,0.000000
27.020000,4.182861,-113.026100,-0.002613,0.001204,0.030570,18.606297,0.947850,0.305697,-113.026100,0.031376,0.000000
27.250002,4.189568,-112.937134,-0.002596,0.001213,0.030821,18.636127,0.949370,0.308212,-112.937134,0.031758,0.000000
27.480001,4.210419,-113.026100,-0.002583,0.001227,0.031159,18.728878,0.954095,0.311594,-113.026100,0.032148,0.000000
27.710001,4.208183,-113.115059,-0.002570,0.001235,0.031359,18.718935,0.953588,0.313589,-113.115059,0.032530,0.000000
27.940001,4.561562,-113.070580,-0.002548,0.001267,0.032183,20.290840,1.033665,0.321827,-113.070580,0.032911,0.000000
28.170002,4.479645,-113.070580,-0.002539,0.001278,0.032460,19.926455,1.015102,0.324603,-113.070580,0.033293,0.000000
28.400002,4.466606,-112.981613,-0.002527,0.001292,0.032824,19.868456,1.012147,0.328245,-112.981613,0.033674,0.000000
28.630001,4.562683,-113.115059,-0.002505,0.001309,0.033241,20.295828,1.033919,0.332408,-113.115059,0.034065,0.000000
28.860001,4.573479,-113.159538,-0.002496,0.001322,0.033570,20.343849,1.036365,0.335703,-113.159538,0.034446,0.000000
29.090002,4.624123,-113.159538,-0.002479,0.001335,0.033900,20.569124,1.047841,0.338999,-113.159538,0.034828,0.000000
29.320002,4.655029,-113.159538,-0.002458,0.001349,0.034264,20.706604,1.054845,0.342641,-113.159538,0.035209,0.000000
29.550001,4.662849,-113.159538,-0.002453,0.001360,0.034542,20.741390,1.056617,0.345416,-113.159538,0.035591,0.000000
29.780001,4.828186,-113.204018,-0.002436,0.001377,0.034967,21.476845,1.094083,0.349665,-113.204018,0.035981,0.000000
30.010002,4.992401,-113.204018,-0.002406,0.001396,0.035470,22.207310,1.131294,0.354695,-113.204018,0.036363,0.000000
30.240002,4.995003,-113.248505,-0.002406,0.001411,0.035834,22.218882,1.131884,0.358338,-113.248505,0.036744,0.000000
30.470001,5.072456,-113.248505,-0.002384,0.001427,0.036241,22.563414,1.149435,0.362414,-113.248505,0.037126,0.000000
30.700001,5.115280,-113.248505,-0.002367,0.001441,0.036606,22.753902,1.159139,0.366056,-113.248505,0.037508,0.000000
30.930002,5.170769,-113.248505,-0.002371,0.001456,0.036970,23.000729,1.171713,0.369698,-113.248505,0.037898,0.000000
31.160002,5.272423,-113.337463,-0.002350,0.001473,0.037412,23.452908,1.194748,0.374121,-113.337463,0.038279,0.000000
31.390001,5.196083,-113.337463,-0.002333,0.001481,0.037629,23.113333,1.177449,0.376289,-113.337463,0.038661,0.000000
31.620001,5.350624,-113.337463,-0.002320,0.001499,0.038063,23.800764,1.212469,0.380625,-113.337463,0.039042,0.000000
31.850002,5.451164,-113.381943,-0.002289,0.001517,0.038522,24.247990,1.235252,0.385222,-113.381943,0.039424,0.000000
32.080002,5.578514,-113.381943,-0.002285,0.001533,0.038947,24.814470,1.264109,0.389471,-113.381943,0.039814,0.000000
32.310001,5.588936,-113.426422,-0.002281,0.001548,0.039320,24.860828,1.266471,0.393200,-113.426422,0.040196,0.000000
32.540001,5.619850,-113.381943,-0.002255,0.001562,0.039676,24.998343,1.273476,0.396756,-113.381943,0.040577,0.000000
32.770000,5.683151,-113.381943,-0.002238,0.001575,0.040005,25.279919,1.287820,0.400051,-113.381943,0.040959,0.000000
33.000000,5.843269,-113.426422,-0.002220,0.001593,0.040456,25.992161,1.324104,0.404561,-113.426422,0.041341,0.000000
33.230003,5.838432,-113.515388,-0.002203,0.001604,0.040751,25.970644,1.323008,0.407509,-113.515388,0.041731,0.000000
33.460003,5.952003,-113.470909,-0.002190,0.001621,0.041176,26.475834,1.348743,0.411759,-113.470909,0.042112,0.000000
33.690002,5.936737,-113.515388,-0.002190,0.001632,0.041445,26.407925,1.345284,0.414447,-113.515388,0.042494,0.000000
33.920002,6.169098,-113.470909,-0.002164,0.001653,0.041982,27.441519,1.397938,0.419824,-113.470909,0.042876,0.000000
34.150002,6.261818,-113.515388,-0.002151,0.001669,0.042381,27.853958,1.418948,0.423813,-113.515388,0.043266,0.000000
34.380001,6.314323,-113.559868,-0.002134,0.001684,0.042780,28.087513,1.430846,0.427802,-113.559868,0.043647,0.000000
34.610001,6.226440,-113.559868,-0.002130,0.001695,0.043040,27.696590,1.410932,0.430404,-113.559868,0.044029,0.000000
34.840000,6.291977,-113.559868,-0.002113,0.001707,0.043370,27.988111,1.425782,0.433700,-113.559868,0.044411,0.000000
35.070004,6.586151,-113.559868,-0.002091,0.001727,0.043856,29.296663,1.492443,0.438556,-113.559868,0.044792,0.000000
35.300003,6.634933,-113.648827,-0.002078,0.001739,0.044176,29.513659,1.503497,0.441765,-113.648827,0.045182,0.000000
35.530003,6.740685,-113.693314,-0.002052,0.001756,0.044593,29.984062,1.527461,0.445927,-113.693314,0.045564,0.000000
35.760002,6.755211,-113.693314,-0.002044,0.001770,0.044957,30.048679,1.530753,0.449570,-113.693314,0.045946,0.000000
35.990002,6.995018,-113.693314,-0.002035,0.001789,0.045443,31.115395,1.585094,0.454426,-113.693314,0.046327,0.000000
36.220001,7.039330,-113.737793,-0.002009,0.001804,0.045833,31.312502,1.595135,0.458329,-113.737793,0.046709,0.000000
36.450001,7.078056,-113.737793,-0.001996,0.001818,0.046188,31.484768,1.603910,0.461884,-113.737793,0.047099,0.000000
36.680000,7.130562,-113.737793,-0.001988,0.001832,0.046527,31.718323,1.615808,0.465267,-113.737793,0.047481,0.000000
36.910000,7.285469,-113.826752,-0.001975,0.001847,0.046917,32.407387,1.650911,0.469169,-113.826752,0.047862,0.000000
37.140003,7.311531,-113.782272,-0.001962,0.001860,0.047255,32.523315,1.656817,0.472551,-113.782272,0.048244,0.000000
37.370003,7.540169,-113.826752,-0.001936,0.001875,0.047637,33.540344,1.708627,0.476367,-113.826752,0.048625,0.000000
37.600002,7.741997,-113.826752,-0.001923,0.001894,0.048096,34.438122,1.754362,0.480963,-113.826752,0.049016,0.000000
37.830002,7.860413,-113.915718,-0.001910,0.001909,0.048487,34.964863,1.781195,0.484866,-113.915718,0.049397,0.000000
38.060001,7.927811,-113.915718,-0.001910,0.001925,0.048894,35.264664,1.796468,0.488942,-113.915718,0.049779,0.000000
38.290001,7.958717,-113.871231,-0.001893,0.001940,0.049276,35.402142,1.803471,0.492758,-113.871231,0.050160,0.000000
38.520000,7.910683,-113.871231,-0.001871,0.001950,0.049536,35.188473,1.792586,0.495359,-113.871231,0.050542,0.000000
38.750000,8.080109,-113.871231,-0.001850,0.001963,0.049865,35.942120,1.830979,0.498655,-113.871231,0.050932,0.000000
38.980003,8.243584,-113.960197,-0.001837,0.001980,0.050282,36.669292,1.868023,0.502818,-113.960197,0.051314,0.000000
39.210003,8.373917,-114.004677,-0.001841,0.001994,0.050646,37.249043,1.897557,0.506460,-114.004677,0.051695,0.000000
39.440002,8.488602,-113.960197,-0.001815,0.002009,0.051019,37.759186,1.923545,0.510189,-113.960197,0.052077,0.000000
39.670002,8.840126,-114.004677,-0.001794,0.002028,0.051505,39.322845,2.003201,0.515045,-114.004677,0.052458,0.000000
39.900002,9.016258,-114.004677,-0.001781,0.002045,0.051938,40.106319,2.043113,0.519382,-114.004677,0.052849,0.000000
40.130001,8.995399,-114.093643,-0.001776,0.002059,0.052294,40.013535,2.038387,0.522937,-114.093643,0.053230,0.000000
40.360001,8.997261,-114.093643,-0.001746,0.002070,0.052580,40.021816,2.038809,0.525799,-114.093643,0.053612,0.000000
40.590000,9.072113,-114.049156,-0.001750,0.002083,0.052901,40.354774,2.055770,0.529008,-114.049156,0.053993,0.000000
40.820004,9.567741,-114.049156,-0.001733,0.002104,0.053447,42.559441,2.168081,0.534471,-114.049156,0.054375,0.000000
41.050003,9.568481,-114.049156,-0.001712,0.002116,0.053742,42.562733,2.168249,0.537420,-114.049156,0.054765,0.000000
41.280003,9.828400,-114.138123,-0.001690,0.002132,0.054150,43.718906,2.227147,0.541496,-114.138123,0.055147,0.000000
41.510002,10.123688,-114.227081,-0.001673,0.002150,0.054618,45.032413,2.294060,0.546179,-114.227081,0.055528,0.000000
41.740002,10.196304,-114.182602,-0.001660,0.002166,0.055008,45.355427,2.310516,0.550081,-114.182602,0.055910,0.000000
41.970001,10.331474,-114.093643,-0.001656,0.002181,0.055398,45.956692,2.341146,0.553984,-114.093643,0.056292,0.000000
42.200001,10.372810,-114.182602,-0.001634,0.002195,0.055745,46.140564,2.350512,0.557453,-114.182602,0.056682,0.000000
42.430000,10.302055,-114.182602,-0.001630,0.002204,0.055979,45.825832,2.334479,0.559794,-114.182602,0.057063,0.000000
42.660004,10.771248,-114.227081,-0.001621,0.002225,0.056508,47.912903,2.440800,0.565084,-114.227081,0.057445,0.000000
42.890003,10.944771,-114.271561,-0.001604,0.002238,0.056838,48.684772,2.480121,0.568380,-114.271561,0.057827,0.000000
43.120003,11.045685,-114.227081,-0.001578,0.002253,0.057228,49.133659,2.502988,0.572282,-114.227081,0.058217,0.000000
43.350002,11.444496,-114.271561,-0.001561,0.002272,0.057705,50.907661,2.593360,0.577052,-114.271561,0.058598,0.000000
43.580002,11.346191,-114.316048,-0.001535,0.002280,0.057913,50.470379,2.571084,0.579133,-114.316048,0.058980,0.000000
43.810001,11.478752,-114.316048,-0.001535,0.002293,0.058252,51.060040,2.601122,0.582515,-114.316048,0.059362,0.000000
44.040001,11.062813,-114.360527,-0.001535,0.002293,0.058252,49.209850,2.506869,0.582515,-114.360527,0.059743,0.000000
44.270000,12.285683,-114.316048,-0.001513,0.002330,0.059179,54.649445,2.783976,0.591795,-114.316048,0.060133,0.000000
44.500004,12.491608,-114.405006,-0.001492,0.002344,0.059526,55.565445,2.830639,0.595264,-114.405006,0.060515,0.000000
44.730003,12.723969,-114.405006,-0.001483,0.002362,0.059995,56.599037,2.883292,0.599947,-114.405006,0.060897,0.000000
44.960003,12.824509,-114.360527,-0.001466,0.002375,0.060333,57.046265,2.906075,0.603329,-114.360527,0.061278,0.000000
45.190002,12.949997,-114.449486,-0.001440,0.002389,0.060688,57.604462,2.934511,0.606884,-114.449486,0.061660,0.000000
45.420002,13.232254,-114.449486,-0.001431,0.002405,0.061087,58.860004,2.998472,0.610874,-114.449486,0.062050,0.000000
45.650002,13.728256,-114.493965,-0.001431,0.002424,0.061573,61.066334,3.110867,0.615730,-114.493965,0.062432,0.000000
45.880001,13.418068,-114.538452,-0.001406,0.002434,0.061816,59.686546,3.040578,0.618159,-114.538452,0.062813,0.000000
46.110001,14.211594,-114.582932,-0.001406,0.002456,0.062371,63.216324,3.220393,0.623709,-114.582932,0.063195,0.000000
46.340004,14.111427,-114.493965,-0.001367,0.002467,0.062657,62.770763,3.197695,0.626571,-114.493965,0.063576,0.000000
46.570004,14.518059,-114.582932,-0.001362,0.002485,0.063108,64.579552,3.289839,0.631080,-114.582932,0.063967,0.000000
46.800003,14.492737,-114.582932,-0.001350,0.002493,0.063333,64.466911,3.284101,0.633335,-114.582932,0.064348,0.000000
47.030003,15.103798,-114.671890,-0.001350,0.002513,0.063836,67.185051,3.422570,0.638365,-114.671890,0.064730,0.000000
47.260002,15.447128,-114.582932,-0.001332,0.002531,0.064287,68.712257,3.500369,0.642874,-114.582932,0.065111,0.000000
47.490002,15.810936,-114.627411,-0.001298,0.002548,0.064712,70.330559,3.582809,0.647124,-114.627411,0.065493,0.000000
47.720001,15.896210,-114.627411,-0.001285,0.002561,0.065042,70.709869,3.602133,0.650419,-114.627411,0.065883,0.000000
47.950001,16.082771,-114.582932,-0.001285,0.002574,0.065380,71.539742,3.644408,0.653801,-114.582932,0.066265,0.000000
48.180004,16.376572,-114.760857,-0.001263,0.002589,0.065753,72.846626,3.710984,0.657531,-114.760857,0.066646,0.000000
48.410004,16.868477,-114.671890,-0.001268,0.002607,0.066221,75.034729,3.822451,0.662214,-114.671890,0.067028,0.000000
48.640003,17.069183,-114.716370,-0.001242,0.002620,0.066542,75.927521,3.867932,0.665422,-114.716370,0.067409,0.000000
48.870003,16.977203,-114.671890,-0.001224,0.002629,0.066776,75.518372,3.847089,0.667764,-114.671890,0.067800,0.000000
49.100002,17.644867,-114.760857,-0.001216,0.002646,0.067201,78.488289,3.998384,0.672013,-114.760857,0.068181,0.000000
49.330002,18.656235,-114.716370,-0.001220,0.002670,0.067817,82.987076,4.227563,0.678171,-114.716370,0.068563,0.000000
49.560001,18.593674,-114.760857,-0.001194,0.002681,0.068086,82.708794,4.213387,0.680859,-114.760857,0.068944,0.000000
49.790001,18.916519,-114.805336,-0.001181,0.002697,0.068493,84.144882,4.286544,0.684935,-114.805336,0.069326,0.000000
50.020004,19.117233,-114.760857,-0.001164,0.002710,0.068832,85.037704,4.332027,0.688317,-114.760857,0.069716,0.000000
50.250004,19.623657,-114.849815,-0.001160,0.002726,0.069239,87.290390,4.446784,0.692393,-114.849815,0.070098,0.000000
50.480003,19.767021,-114.894295,-0.001147,0.002737,0.069517,87.928101,4.479271,0.695168,-114.894295,0.070479,0.000000
50.710003,19.877991,-114.894295,-0.001134,0.002748,0.069794,88.421722,4.504417,0.697943,-114.894295,0.070861,0.000000
50.940002,20.477135,-114.849815,-0.001130,0.002766,0.070245,91.086845,4.640185,0.702453,-114.849815,0.071251,0.000000
51.170002,20.989891,-114.894295,-0.001112,0.002783,0.070696,93.367699,4.756377,0.706962,-114.894295,0.071633,0.000000
51.400002,21.478821,-114.938774,-0.001099,0.002796,0.071017,95.542564,4.867170,0.710171,-114.938774,0.072014,0.000000
51.630001,21.945030,-115.027740,-0.001082,0.002814,0.071468,97.616371,4.972815,0.714681,-115.027740,0.072396,0.000000
51.860001,22.461510,-114.938774,-0.001087,0.002830,0.071884,99.913788,5.089851,0.718843,-114.938774,0.072778,0.000000
52.090004,22.588112,-114.938774,-0.001061,0.002840,0.072145,100.476936,5.118539,0.721445,-114.938774,0.073168,0.000000
52.320004,23.381638,-114.983261,-0.001048,0.002862,0.072682,104.006721,5.298355,0.726822,-114.983261,0.073549,0.000000
52.550003,23.874664,-115.027740,-0.001035,0.002876,0.073046,106.199814,5.410076,0.730464,-115.027740,0.073931,0.000000
52.780003,23.756622,-114.983261,-0.001022,0.002885,0.073281,105.674736,5.383327,0.732806,-114.983261,0.074313,0.000000
53.010002,24.304008,-115.027740,-0.001009,0.002902,0.073706,108.109627,5.507367,0.737055,-115.027740,0.074694,0.000000
53.240002,25.211105,-115.027740,-0.000992,0.002921,0.074182,112.144600,5.712918,0.741825,-115.027740,0.075084,0.000000
53.470001,25.781212,-115.072220,-0.000992,0.002936,0.074564,114.680557,5.842106,0.745641,-115.072220,0.075466,0.000000
53.700001,26.225449,-115.161179,-0.000983,0.002952,0.074972,116.656624,5.942771,0.749717,-115.161179,0.075848,0.000000
53.930004,26.486481,-115.116699,-0.000961,0.002964,0.075293,117.817749,6.001922,0.752925,-115.116699,0.076229,0.000000
54.160004,26.805977,-115.161179,-0.000953,0.002979,0.075657,119.238937,6.074321,0.756568,-115.161179,0.076611,0.000000
54.390003,27.645676,-115.161179,-0.000949,0.002993,0.076030,122.974106,6.264600,0.760297,-115.161179,0.077001,0.000000
54.620003,27.923843,-115.161179,-0.000927,0.003007,0.076368,124.211456,6.327633,0.763679,-115.161179,0.077383,0.000000
54.850002,28.808228,-115.250145,-0.000936,0.003023,0.076784,128.145401,6.528038,0.767842,-115.250145,0.077764,0.000000
55.080002,29.376839,-115.294624,-0.000923,0.003038,0.077166,130.674698,6.656887,0.771657,-115.294624,0.078146,0.000000
55.310001,30.262711,-115.294624,-0.000910,0.003056,0.077634,134.615265,6.857628,0.776340,-115.294624,0.078527,0.000000
55.540001,30.800415,-115.205666,-0.000884,0.003070,0.077981,137.007095,6.979474,0.779809,-115.205666,0.078918,0.000000
55.770004,31.252853,-115.294624,-0.000880,0.003085,0.078371,139.019638,7.081998,0.783712,-115.294624,0.079299,0.000000
56.000004,31.492287,-115.339104,-0.000875,0.003097,0.078675,140.084686,7.136254,0.786747,-115.339104,0.079681,0.000000
56.230003,32.233681,-115.339104,-0.000858,0.003112,0.079056,143.382568,7.304256,0.790563,-115.339104,0.080062,0.000000
56.460003,32.897247,-115.339104,-0.000858,0.003125,0.079386,146.334259,7.454623,0.793858,-115.339104,0.080444,0.000000
56.690002,33.578690,-115.339104,-0.000836,0.003142,0.079819,149.365479,7.609040,0.798194,-115.339104,0.080834,0.000000
56.920002,34.308540,-115.383591,-0.000836,0.003159,0.080236,152.612015,7.774426,0.802357,-115.383591,0.081216,0.000000
57.150002,34.965775,-115.428070,-0.000823,0.003172,0.080574,155.535538,7.923358,0.805739,-115.428070,0.081597,0.000000
57.380001,35.999481,-115.383591,-0.000815,0.003191,0.081051,160.133698,8.157598,0.810509,-115.383591,0.081979,0.000000
57.610004,36.685020,-115.428070,-0.000806,0.003206,0.081432,163.183121,8.312944,0.814325,-115.428070,0.082360,0.000000
57.840004,37.170967,-115.428070,-0.000793,0.003219,0.081762,165.344727,8.423061,0.817620,-115.428070,0.082751,0.000000
58.070004,37.773460,-115.472549,-0.000785,0.003232,0.082100,168.024750,8.559588,0.821002,-115.472549,0.083132,0.000000
58.300003,38.571831,-115.517029,-0.000780,0.003249,0.082517,171.576065,8.740502,0.825165,-115.517029,0.083514,0.000000
58.530003,39.290878,-115.472549,-0.000763,0.003263,0.082872,174.774551,8.903440,0.828721,-115.472549,0.083895,0.000000
58.760002,40.030785,-115.517029,-0.000759,0.003279,0.083288,178.065826,9.071105,0.832884,-115.517029,0.084277,0.000000
58.990002,40.890594,-115.561508,-0.000750,0.003294,0.083679,181.890442,9.265942,0.836786,-115.561508,0.084667,0.000000
59.220001,41.938080,-115.561508,-0.000742,0.003313,0.084138,186.549896,9.503304,0.841382,-115.561508,0.085049,0.000000
59.450005,42.667557,-115.605995,-0.000737,0.003326,0.084468,189.794769,9.668607,0.844678,-115.605995,0.085430,0.000000
59.680004,43.523636,-115.650475,-0.000724,0.003342,0.084893,193.602798,9.862597,0.848927,-115.650475,0.085812,0.000000
59.910004,43.726952,-115.650475,-0.000716,0.003352,0.085136,194.507202,9.908669,0.851355,-115.650475,0.086202,0.000000
60.140003,44.357750,-115.650475,-0.000707,0.003362,0.085387,197.313126,10.051610,0.853870,-115.650475,0.086584,0.000000
60.370003,45.551949,-115.650475,-0.000690,0.003381,0.085873,202.625183,10.322220,0.858727,-115.650475,0.086965,0.000000
60.600002,46.640770,-115.694954,-0.000690,0.003399,0.086324,207.468506,10.568950,0.863236,-115.694954,0.087347,0.000000
60.830002,47.488663,-115.650475,-0.000690,0.003414,0.086723,211.240128,10.761085,0.867226,-115.650475,0.087729,0.000000
61.060001,48.330597,-115.694954,-0.000673,0.003429,0.087095,214.985229,10.951870,0.870955,-115.694954,0.088119,0.000000
61.290005,49.497986,-115.694954,-0.000660,0.003446,0.087538,220.178040,11.216404,0.875378,-115.694954,0.088500,0.000000
61.520004,50.208473,-115.739433,-0.000660,0.003459,0.087850,223.338440,11.377402,0.878500,-115.739433,0.088882,0.000000
61.750004,50.866081,-115.739433,-0.000655,0.003473,0.088214,226.263626,11.526419,0.882142,-115.739433,0.089264,0.000000
61.980003,51.767593,-115.783913,-0.000655,0.003488,0.088587,230.273758,11.730704,0.885871,-115.783913,0.089645,0.000000
62.210003,53.138672,-115.739433,-0.000638,0.003504,0.089012,236.372620,12.041394,0.890121,-115.739433,0.090035,0.000000
62.440002,53.846924,-115.828400,-0.000625,0.003517,0.089342,239.523087,12.201887,0.893416,-115.828400,0.090417,0.000000
62.670002,55.003510,-115.828400,-0.000625,0.003533,0.089749,244.667831,12.463973,0.897492,-115.828400,0.090799,0.000000
62.900002,56.196594,-115.872879,-0.000617,0.003549,0.090148,249.974930,12.734330,0.901481,-115.872879,0.091180,0.000000
63.130005,57.284660,-115.828400,-0.000612,0.003567,0.090599,254.814896,12.980889,0.905991,-115.828400,0.091562,0.000000
63.360004,58.256180,-115.917358,-0.000591,0.003581,0.090946,259.136444,13.201039,0.909460,-115.917358,0.091952,0.000000
63.590004,59.142799,-115.872879,-0.000582,0.003595,0.091319,263.080322,13.401950,0.913189,-115.872879,0.092334,0.000000
63.820004,59.651466,-115.961838,-0.000573,0.003604,0.091553,265.342987,13.517216,0.915530,-115.961838,0.092715,0.000000
64.050003,61.358421,-115.917358,-0.000586,0.003626,0.092099,272.935883,13.904017,0.920994,-115.917358,0.093097,0.000000
64.280006,62.283020,-115.917358,-0.000569,0.003639,0.092420,277.048706,14.113534,0.924202,-115.917358,0.093478,0.000000
64.510002,63.632118,-115.917358,-0.000565,0.003657,0.092880,283.049805,14.419245,0.928799,-115.917358,0.093869,0.000000
64.740005,64.896324,-115.961838,-0.000552,0.003673,0.093287,288.673279,14.705717,0.932875,-115.961838,0.094250,0.000000
64.970001,65.412437,-116.006317,-0.000548,0.003683,0.093556,290.969055,14.822670,0.935563,-116.006317,0.094632,0.000000
65.200005,65.845512,-116.006317,-0.000539,0.003693,0.093799,292.895477,14.920807,0.937991,-116.006317,0.095013,0.000000
65.430000,67.391594,-116.050804,-0.000535,0.003700,0.093990,299.772797,15.271153,0.939899,-116.050804,0.094241,0.000000
65.660004,66.843086,-116.006317,-0.000526,0.003700,0.093990,297.332886,15.146860,0.939899,-116.006317,0.094241,0.000000
65.889999,66.423058,-116.095284,-0.000530,0.003699,0.093947,295.464508,15.051681,0.939466,-116.095284,0.093990,0.000000
66.120003,66.022377,-116.184242,-0.000530,0.003698,0.093921,293.682190,14.960884,0.939205,-116.184242,0.093990,0.000000
66.350006,65.674583,-116.139763,-0.000522,0.003697,0.093912,292.135132,14.882073,0.939119,-116.139763,0.093990,0.000000
66.580002,65.359932,-116.139763,-0.000522,0.003697,0.093903,290.735504,14.810773,0.939032,-116.139763,0.093990,0.000000
66.810005,65.104485,-116.184242,-0.000513,0.003697,0.093903,289.599213,14.752887,0.939032,-116.184242,0.093990,0.000000
67.040001,64.864677,-116.184242,-0.000522,0.003697,0.093903,288.532501,14.698546,0.939032,-116.184242,0.093990,0.000000
67.270004,64.639015,-116.228722,-0.000509,0.003697,0.093895,287.528687,14.647410,0.938945,-116.228722,0.093990,0.000000
67.500000,64.425285,-116.228722,-0.000517,0.003697,0.093895,286.577972,14.598979,0.938945,-116.228722,0.093990,0.000000
67.730003,64.241325,-116.184242,-0.000522,0.003697,0.093895,285.759674,14.557293,0.938945,-116.184242,0.093990,0.000000
67.960007,64.085670,-116.228722,-0.000504,0.003697,0.093895,285.067291,14.522020,0.938945,-116.228722,0.093990,0.000000
68.190002,63.933372,-116.273209,-0.000513,0.003697,0.093895,284.389832,14.487510,0.938945,-116.273209,0.093990,0.000000
68.420006,63.784431,-116.273209,-0.000504,0.003697,0.093895,283.727325,14.453758,0.938945,-116.273209,0.093990,0.000000
68.650002,63.642921,-116.317688,-0.000504,0.003696,0.093886,283.097839,14.421692,0.938859,-116.317688,0.093990,0.000000
68.880005,63.518929,-116.273209,-0.000509,0.003696,0.093886,282.546295,14.393595,0.938859,-116.273209,0.093990,0.000000
69.110001,63.411674,-116.317688,-0.000504,0.003696,0.093886,282.069214,14.369290,0.938859,-116.317688,0.093990,0.000000
69.340004,63.297737,-116.362167,-0.000504,0.003696,0.093886,281.562408,14.343472,0.938859,-116.362167,0.093990,0.000000
69.570000,63.189369,-116.406647,-0.000500,0.003696,0.093886,281.080353,14.318916,0.938859,-116.406647,0.093990,0.000000
69.800003,63.072823,-116.362167,-0.000513,0.003696,0.093886,280.561920,14.292506,0.938859,-116.362167,0.093990,0.000000
70.030006,62.988297,-116.362167,-0.000496,0.003696,0.093886,280.185944,14.273353,0.938859,-116.362167,0.093990,0.000000
70.260002,62.908974,-116.406647,-0.000504,0.003696,0.093886,279.833099,14.255377,0.938859,-116.406647,0.093990,0.000000
70.490005,62.803970,-116.451126,-0.000504,0.003696,0.093886,279.366028,14.231584,0.938859,-116.451126,0.093990,0.000000
70.720001,62.722046,-116.495613,-0.000504,0.003696,0.093886,279.001587,14.213019,0.938859,-116.495613,0.093990,0.000000
70.950005,62.649063,-116.495613,-0.000504,0.003696,0.093886,278.676941,14.196481,0.938859,-116.495613,0.093990,0.000000
71.180000,62.578682,-116.451126,-0.000492,0.003696,0.093886,278.363892,14.180532,0.938859,-116.451126,0.093990,0.000000
71.410004,62.501228,-116.495613,-0.000500,0.003696,0.093886,278.019348,14.162981,0.938859,-116.495613,0.093990,0.000000
71.640007,62.431595,-116.540092,-0.000500,0.003696,0.093886,277.709595,14.147202,0.938859,-116.540092,0.093990,0.000000
71.870003,62.350792,-116.584572,-0.000496,0.003696,0.093886,277.350189,14.128891,0.938859,-116.584572,0.093990,0.000000
72.100006,62.295311,-116.629051,-0.000500,0.003696,0.093886,277.103394,14.116320,0.938859,-116.629051,0.093990,0.000000
72.330002,62.244293,-116.540092,-0.000500,0.003696,0.093886,276.876434,14.104758,0.938859,-116.540092,0.093990,0.000000
72.560005,62.177269,-116.584572,-0.000500,0.003696,0.093886,276.578308,14.089571,0.938859,-116.584572,0.093990,0.000000
72.790001,62.105400,-116.584572,-0.000492,0.003696,0.093877,276.258606,14.073285,0.938772,-116.584572,0.093990,0.000000
73.020004,62.064812,-116.718018,-0.000496,0.003696,0.093877,276.078064,14.064088,0.938772,-116.718018,0.093990,0.000000
73.250000,62.001503,-116.629051,-0.000509,0.003696,0.093877,275.796448,14.049741,0.938772,-116.629051,0.093990,0.000000
73.480003,61.946770,-116.629051,-0.000500,0.003696,0.093877,275.553009,14.037339,0.938772,-116.629051,0.093990,0.000000
73.710007,61.886070,-116.673538,-0.000496,0.003696,0.093877,275.282990,14.023583,0.938772,-116.673538,0.093990,0.000000
73.940002,61.845856,-116.718018,-0.000492,0.003696,0.093877,275.104095,14.014471,0.938772,-116.718018,0.093990,0.000000
74.170006,61.816811,-116.806976,-0.000496,0.003696,0.093877,274.974915,14.007890,0.938772,-116.806976,0.093990,0.000000
74.400002,61.747177,-116.762497,-0.000496,0.003696,0.093877,274.665161,13.992110,0.938772,-116.762497,0.093990,0.000000
74.630005,61.686478,-116.762497,-0.000492,0.003696,0.093877,274.395172,13.978355,0.938772,-116.762497,0.093990,0.000000
74.860001,61.670097,-116.762497,-0.000487,0.003696,0.093877,274.322296,13.974644,0.938772,-116.762497,0.093990,0.000000
75.090004,61.630997,-116.806976,-0.000492,0.003696,0.093877,274.148376,13.965783,0.938772,-116.806976,0.093990,0.000000
75.320007,61.569923,-116.851456,-0.000496,0.003696,0.093877,273.876709,13.951944,0.938772,-116.851456,0.093990,0.000000
75.550003,61.533058,-116.806976,-0.000492,0.003696,0.093877,273.712708,13.943590,0.938772,-116.806976,0.093990,0.000000
75.780006,61.511093,-116.895943,-0.000504,0.003696,0.093877,273.615021,13.938613,0.938772,-116.895943,0.093990,0.000000
76.010002,61.464172,-116.895943,-0.000483,0.003696,0.093877,273.406281,13.927980,0.938772,-116.895943,0.093990,0.000000
76.240005,61.417625,-116.851456,-0.000496,0.003696,0.093877,273.199249,13.917434,0.938772,-116.851456,0.093990,0.000000
76.470001,61.375923,-116.940422,-0.000500,0.003696,0.093877,273.013733,13.907983,0.938772,-116.940422,0.093990,0.000000
76.700005,61.339058,-116.895943,-0.000492,0.003696,0.093877,272.849762,13.899630,0.938772,-116.895943,0.093990,0.000000
76.930000,61.317085,-116.940422,-0.000496,0.003696,0.093877,272.752014,13.894650,0.938772,-116.940422,0.093990,0.000000
77.160004,61.263832,-116.940422,-0.000492,0.003696,0.093877,272.515137,13.882583,0.938772,-116.940422,0.093990,0.000000
77.390007,61.231812,-117.073860,-0.000483,0.003696,0.093877,272.372711,13.875327,0.938772,-117.073860,0.093990,0.000000
77.620003,61.201279,-117.073860,-0.000487,0.003696,0.093877,272.236877,13.868408,0.938772,-117.073860,0.093990,0.000000
77.850006,61.168510,-117.073860,-0.000500,0.003696,0.093877,272.091125,13.860983,0.938772,-117.073860,0.093990,0.000000
78.080002,61.135742,-117.029381,-0.000483,0.003696,0.093877,271.945374,13.853558,0.938772,-117.029381,0.093990,0.000000
78.310005,61.107811,-117.073860,-0.000479,0.003696,0.093877,271.821106,13.847228,0.938772,-117.073860,0.093990,0.000000
78.540001,61.073555,-117.118347,-0.000479,0.003696,0.093877,271.668732,13.839465,0.938772,-117.118347,0.093990,0.000000
78.770004,61.046371,-117.073860,-0.000487,0.003696,0.093877,271.547821,13.833305,0.938772,-117.073860,0.093990,0.000000
79.000000,61.021049,-117.162827,-0.000487,0.003696,0.093877,271.435181,13.827568,0.938772,-117.162827,0.093990,0.000000
79.230003,60.990891,-117.073860,-0.000487,0.003696,0.093877,271.301025,13.820734,0.938772,-117.073860,0.093990,0.000000
79.460007,60.954765,-117.118347,-0.000483,0.003696,0.093877,271.140350,13.812548,0.938772,-117.118347,0.093990,0.000000
79.690002,60.936150,-117.207306,-0.000492,0.003696,0.093877,271.057526,13.808329,0.938772,-117.207306,0.093990,0.000000
79.920006,60.888855,-117.207306,-0.000492,0.003696,0.093877,270.847168,13.797612,0.938772,-117.207306,0.093990,0.000000
80.150002,60.860558,-117.118347,-0.000496,0.003696,0.093877,270.721283,13.791200,0.938772,-117.118347,0.093990,0.000000
80.380005,60.843803,-117.162827,-0.000487,0.003696,0.093877,270.646759,13.787403,0.938772,-117.162827,0.093990,0.000000
80.610001,60.824066,-117.251785,-0.000487,0.003696,0.093877,270.558960,13.782930,0.938772,-117.251785,0.093990,0.000000
80.840004,60.795021,-117.207306,-0.000487,0.003696,0.093877,270.429749,13.776348,0.938772,-117.207306,0.093990,0.000000
81.070007,60.760391,-117.251785,-0.000487,0.003696,0.093877,270.275726,13.768502,0.938772,-117.251785,0.093990,0.000000
81.300003,60.732460,-117.296265,-0.000492,0.003696,0.093877,270.151489,13.762173,0.938772,-117.296265,0.093990,0.000000
81.530006,60.714211,-117.296265,-0.000479,0.003696,0.093877,270.070282,13.758037,0.938772,-117.296265,0.093990,0.000000
81.760002,60.701927,-117.251785,-0.000479,0.003696,0.093877,270.015656,13.755254,0.938772,-117.251785,0.093990,0.000000
81.990005,60.663200,-117.385231,-0.000492,0.003696,0.093877,269.843384,13.746478,0.938772,-117.385231,0.093990,0.000000
82.220001,60.632668,-117.340752,-0.000496,0.003696,0.093877,269.707581,13.739559,0.938772,-117.340752,0.093990,0.000000
82.450005,60.642349,-117.296265,-0.000483,0.003696,0.093877,269.750641,13.741753,0.938772,-117.296265,0.093990,0.000000
82.680000,60.608086,-117.296265,-0.000487,0.003696,0.093877,269.598236,13.733989,0.938772,-117.296265,0.093990,0.000000
82.910004,60.564896,-117.385231,-0.000487,0.003696,0.093877,269.406097,13.724202,0.938772,-117.385231,0.093990,0.000000
83.140007,60.557076,-117.385231,-0.000492,0.003696,0.093877,269.371338,13.722430,0.938772,-117.385231,0.093990,0.000000
83.370003,60.539200,-117.385231,-0.000487,0.003696,0.093877,269.291809,13.718379,0.938772,-117.385231,0.093990,0.000000
83.600006,60.522072,-117.429710,-0.000496,0.003696,0.093877,269.215607,13.714498,0.938772,-117.429710,0.093990,0.000000
83.830002,60.479248,-117.474190,-0.000487,0.003696,0.093877,269.025146,13.704793,0.938772,-117.474190,0.093990,0.000000
84.060005,60.452065,-117.385231,-0.000487,0.003696,0.093877,268.904205,13.698633,0.938772,-117.385231,0.093990,0.000000
84.290001,60.446480,-117.518669,-0.000474,0.003696,0.093877,268.879364,13.697368,0.938772,-117.518669,0.093990,0.000000
84.520004,60.436798,-117.518669,-0.000483,0.003696,0.093877,268.836304,13.695174,0.938772,-117.518669,0.093990,0.000000
84.750008,60.409241,-117.518669,-0.000496,0.003696,0.093877,268.713715,13.688930,0.938772,-117.518669,0.093990,0.000000
84.980003,60.387268,-117.518669,-0.000483,0.003696,0.093877,268.615997,13.683950,0.938772,-117.518669,0.093990,0.000000
85.210007,60.366791,-117.563156,-0.000470,0.003696,0.093877,268.524902,13.679310,0.938772,-117.563156,0.093990,0.000000
85.440002,60.350037,-117.607635,-0.000487,0.003696,0.093877,268.450378,13.675513,0.938772,-117.607635,0.093990,0.000000
85.670006,60.327690,-117.652115,-0.000487,0.003696,0.093877,268.350983,13.670449,0.938772,-117.652115,0.093990,0.000000
85.900002,60.297905,-117.652115,-0.000487,0.003696,0.093877,268.218475,13.663701,0.938772,-117.652115,0.093990,0.000000
86.130005,60.285240,-117.607635,-0.000500,0.003696,0.093877,268.162140,13.660831,0.938772,-117.607635,0.093990,0.000000
86.360001,60.272949,-117.652115,-0.000483,0.003696,0.093877,268.107483,13.658046,0.938772,-117.652115,0.093990,0.000000
86.590004,60.265137,-117.785561,-0.000492,0.003696,0.093877,268.072723,13.656276,0.938772,-117.785561,0.093990,0.000000
86.820007,60.229385,-117.696594,-0.000483,0.003696,0.093877,267.913696,13.648174,0.938772,-117.696594,0.093990,0.000000
87.050003,60.216728,-117.741081,-0.000483,0.003696,0.093877,267.857391,13.645306,0.938772,-117.741081,0.093990,0.000000
87.280006,60.207047,-117.652115,-0.000479,0.003696,0.093877,267.814331,13.643112,0.938772,-117.652115,0.093990,0.000000
87.510002,60.186935,-117.696594,-0.000492,0.003696,0.093877,267.724854,13.638555,0.938772,-117.696594,0.093990,0.000000
87.740005,60.161613,-117.830040,-0.000483,0.003696,0.093877,267.612213,13.632817,0.938772,-117.830040,0.093990,0.000000
87.970001,60.144859,-117.785561,-0.000487,0.003696,0.093877,267.537689,13.629021,0.938772,-117.785561,0.093990,0.000000
88.200005,60.136665,-117.741081,-0.000496,0.003696,0.093869,267.501251,13.627163,0.938685,-117.741081,0.093990,0.000000
88.430008,60.116180,-117.785561,-0.000479,0.003696,0.093869,267.410126,13.622521,0.938685,-117.785561,0.093990,0.000000
88.660004,60.090118,-117.741081,-0.000479,0.003696,0.093869,267.294189,13.616615,0.938685,-117.741081,0.093990,0.000000
88.890007,60.074104,-117.874519,-0.000483,0.003696,0.093869,267.222961,13.612987,0.938685,-117.874519,0.093990,0.000000
89.120003,60.057724,-117.918999,-0.000474,0.003696,0.093869,267.150085,13.609275,0.938685,-117.918999,0.093990,0.000000
89.350006,60.056976,-117.830040,-0.000487,0.003696,0.093869,267.146759,13.609105,0.938685,-117.830040,0.093990,0.000000
89.580002,60.032028,-117.918999,-0.000487,0.003696,0.093869,267.035797,13.603452,0.938685,-117.918999,0.093990,0.000000
89.810005,60.004097,-117.918999,-0.000479,0.003696,0.093869,266.911560,13.597122,0.938685,-117.918999,0.093990,0.000000
90.040001,60.003357,-117.963486,-0.000479,0.003696,0.093869,266.908264,13.596955,0.938685,-117.963486,0.093990,0.000000
90.270004,59.985855,-118.007965,-0.000474,0.003696,0.093869,266.830414,13.592989,0.938685,-118.007965,0.093990,0.000000
90.500008,59.948242,-117.963486,-0.000492,0.003696,0.093869,266.663086,13.584466,0.938685,-117.963486,0.093990,0.000000
90.730003,59.946381,-117.963486,-0.000479,0.003696,0.093869,266.654816,13.584044,0.938685,-117.963486,0.093990,0.000000
90.960007,59.943031,-117.963486,-0.000479,0.003696,0.093869,266.639923,13.583285,0.938685,-117.963486,0.093990,0.000000
91.190002,59.929253,-118.052444,-0.000474,0.003696,0.093869,266.578644,13.580163,0.938685,-118.052444,0.093990,0.000000
91.420006,59.885689,-118.052444,-0.000492,0.003696,0.093869,266.384857,13.570292,0.938685,-118.052444,0.093990,0.000000
91.650002,59.883080,-118.052444,-0.000479,0.003696,0.093869,266.373230,13.569700,0.938685,-118.052444,0.093990,0.000000
91.880005,59.884567,-118.096924,-0.000479,0.003696,0.093869,266.379852,13.570037,0.938685,-118.096924,0.093990,0.000000
92.110001,59.860367,-118.141403,-0.000479,0.003696,0.093869,266.272217,13.564552,0.938685,-118.141403,0.093990,0.000000
92.340004,59.833183,-118.185890,-0.000483,0.003696,0.093869,266.151306,13.558393,0.938685,-118.185890,0.093990,0.000000
92.570007,59.815681,-118.141403,-0.000487,0.003696,0.093869,266.073425,13.554427,0.938685,-118.141403,0.093990,0.000000
92.800003,59.825737,-118.141403,-0.000483,0.003696,0.093869,266.118164,13.556706,0.938685,-118.141403,0.093990,0.000000
93.030006,59.809723,-118.185890,-0.000496,0.003696,0.093869,266.046936,13.553077,0.938685,-118.185890,0.093990,0.000000
93.260002,59.784027,-118.141403,-0.000487,0.003696,0.093869,265.932648,13.547254,0.938685,-118.141403,0.093990,0.000000
93.490005,59.768013,-118.230370,-0.000483,0.003696,0.093869,265.861389,13.543625,0.938685,-118.230370,0.093990,0.000000
93.720001,59.765038,-118.230370,-0.000487,0.003696,0.093869,265.848175,13.542952,0.938685,-118.230370,0.093990,0.000000
93.950005,59.747910,-118.274849,-0.000483,0.003696,0.093869,265.771973,13.539069,0.938685,-118.274849,0.093990,0.000000
94.180008,59.738602,-118.230370,-0.000479,0.003696,0.093869,265.730560,13.536961,0.938685,-118.230370,0.093990,0.000000
94.410004,59.720352,-118.230370,-0.000474,0.003696,0.093869,265.649384,13.532825,0.938685,-118.230370,0.093990,0.000000
94.640007,59.709923,-118.274849,-0.000479,0.003696,0.093869,265.602997,13.530462,0.938685,-118.274849,0.093990,0.000000
94.870003,59.700615,-118.408295,-0.000479,0.003696,0.093869,265.561584,13.528353,0.938685,-118.408295,0.093990,0.000000
95.100006,59.688332,-118.363808,-0.000479,0.003696,0.093869,265.506958,13.525569,0.938685,-118.363808,0.093990,0.000000
95.330002,59.660774,-118.319328,-0.000479,0.003696,0.093869,265.384369,13.519325,0.938685,-118.319328,0.093990,0.000000
95.560005,59.654816,-118.408295,-0.000474,0.003696,0.093869,265.357880,13.517974,0.938685,-118.408295,0.093990,0.000000
95.790001,59.655930,-118.408295,-0.000483,0.003696,0.093869,265.362823,13.518227,0.938685,-118.408295,0.093990,0.000000
95.900002,59.636940,-118.363808,-0.000474,0.003696,0.093869,265.278351,13.513925,0.938685,-118.363808,0.093990,0.000000