File: Data/compression 11/AutoNoHeating-10-11-3-240529_05292024_160529.csv
Time (sec),S:Load (lbs),S:HL1 (DIM),S:LVDT (in),S:Position (in),Ch:Position (mm),Ch:Load (N),Ch:Stress (MPa),Ch:Strain (mm/mm),Ch:HL1 (DIM),Set Point (),Cycles ()
0.110000,-0.046921,-1299.555420,-0.015845,-0.012416,-0.315367,-0.208714,-0.010632,-3.153665,-1299.555420,-0.315158,0.000000
0.380000,-0.053246,-1299.599976,-0.015845,-0.012390,-0.314707,-0.236848,-0.012066,-3.147074,-1299.599976,-0.314187,0.000000
0.650000,-0.023834,-1299.599976,-0.015841,-0.012237,-0.310814,-0.106020,-0.005401,-3.108137,-1299.599976,-0.309695,0.000000
0.920000,-0.050270,-1299.599976,-0.015664,-0.012056,-0.306235,-0.223612,-0.011391,-3.062347,-1299.599976,-0.305203,0.000000
1.190000,-0.048035,-1299.555420,-0.015483,-0.011886,-0.301907,-0.213669,-0.010885,-3.019073,-1299.555420,-0.300693,0.000000
1.460000,0.014526,-1299.555420,-0.015332,-0.011714,-0.297545,0.064617,0.003292,-2.975450,-1299.555420,-0.296201,0.000000
1.730000,-0.037979,-1299.555420,-0.015129,-0.011528,-0.292819,-0.168940,-0.008606,-2.928188,-1299.555420,-0.291709,0.000000
2.000000,0.008568,-1299.599976,-0.014939,-0.011347,-0.288214,0.038112,0.001941,-2.882137,-1299.599976,-0.287199,0.000000
2.270000,0.005585,-1299.510986,-0.014771,-0.011168,-0.283669,0.024842,0.001266,-2.836694,-1299.510986,-0.282707,0.000000
2.540000,-0.016380,-1299.555420,-0.014599,-0.010997,-0.279325,-0.072863,-0.003712,-2.793247,-1299.555420,-0.278215,0.000000
2.810000,-0.013031,-1299.599976,-0.014448,-0.010828,-0.275032,-0.057965,-0.002953,-2.750319,-1299.599976,-0.273705,0.000000
3.080000,-0.076340,-1299.599976,-0.014237,-0.010641,-0.270271,-0.339576,-0.017299,-2.702708,-1299.599976,-0.269213,0.000000
3.350000,0.000748,-1299.599976,-0.014077,-0.010468,-0.265883,0.003326,0.000169,-2.658826,-1299.599976,-0.264721,0.000000
3.620000,0.008194,-1299.599976,-0.013896,-0.010287,-0.261278,0.036449,0.001857,-2.612777,-1299.599976,-0.260211,0.000000
3.890000,-0.018990,-1299.466553,-0.013728,-0.010109,-0.256777,-0.084470,-0.004303,-2.567767,-1299.466553,-0.255719,0.000000
4.160000,0.016754,-1299.555420,-0.013538,-0.009937,-0.252397,0.074526,0.003797,-2.523972,-1299.555420,-0.251227,0.000000
4.430000,-0.041336,-1299.555420,-0.013353,-0.009755,-0.247766,-0.183872,-0.009367,-2.477662,-1299.555420,-0.246717,0.000000
4.700000,-0.006699,-1299.599976,-0.013193,-0.009577,-0.243248,-0.029797,-0.001518,-2.432480,-1299.599976,-0.242225,0.000000
4.970000,-0.013405,-1299.555420,-0.013016,-0.009398,-0.238713,-0.059628,-0.003038,-2.387126,-1299.555420,-0.237732,0.000000
5.240000,-0.067772,-1299.555420,-0.012827,-0.009224,-0.234290,-0.301465,-0.015357,-2.342896,-1299.555420,-0.233223,0.000000
5.510000,0.041336,-1299.599976,-0.012659,-0.009053,-0.229936,0.183872,0.009367,-2.299361,-1299.599976,-0.228731,0.000000
5.780000,0.011169,-1299.644409,-0.012469,-0.008871,-0.225323,0.049684,0.002531,-2.253226,-1299.644409,-0.224239,0.000000
6.050000,0.009682,-1299.599976,-0.012284,-0.008687,-0.220648,0.043066,0.002194,-2.206482,-1299.599976,-0.219729,0.000000
6.320000,0.026436,-1299.599976,-0.012102,-0.008509,-0.216121,0.117593,0.005990,-2.161213,-1299.599976,-0.215237,0.000000
6.590000,-0.006699,-1299.555420,-0.011930,-0.008340,-0.211837,-0.029797,-0.001518,-2.118372,-1299.555420,-0.210744,0.000000
6.860000,0.023834,-1299.555420,-0.011775,-0.008166,-0.207423,0.106020,0.005401,-2.074230,-1299.555420,-0.206235,0.000000
7.130000,-0.013405,-1299.644409,-0.011576,-0.007981,-0.202705,-0.059628,-0.003038,-2.027054,-1299.644409,-0.201743,0.000000
7.400001,-0.008934,-1299.555420,-0.011408,-0.007808,-0.198334,-0.039741,-0.002024,-1.983344,-1299.555420,-0.197250,0.000000
7.670001,0.029419,-1299.688965,-0.011232,-0.007632,-0.193859,0.130862,0.006666,-1.938595,-1299.688965,-0.192741,0.000000
7.940001,-0.004097,-1299.510986,-0.011042,-0.007454,-0.189333,-0.018224,-0.000928,-1.893326,-1299.510986,-0.188249,0.000000
8.210000,0.053619,-1299.599976,-0.010878,-0.007275,-0.184797,0.238511,0.012150,-1.847971,-1299.599976,-0.183739,0.000000
8.480000,0.031281,-1299.599976,-0.010693,-0.007097,-0.180261,0.139143,0.007088,-1.802615,-1299.599976,-0.179247,0.000000
8.750000,0.000374,-1299.599976,-0.010507,-0.006920,-0.175778,0.001663,0.000085,-1.757779,-1299.599976,-0.174755,0.000000
9.020000,0.028671,-1299.644409,-0.010339,-0.006753,-0.171537,0.127536,0.006497,-1.715371,-1299.644409,-0.170245,0.000000
9.290001,-0.041336,-1299.644409,-0.010141,-0.006567,-0.166811,-0.183872,-0.009367,-1.668107,-1299.644409,-0.165753,0.000000
9.560000,0.011917,-1299.644409,-0.009968,-0.006395,-0.162431,0.053010,0.002700,-1.624312,-1299.644409,-0.161261,0.000000
9.830001,0.049156,-1299.599976,-0.009804,-0.006213,-0.157800,0.218658,0.011139,-1.578004,-1299.599976,-0.156751,0.000000
10.100000,0.013779,-1299.688965,-0.009645,-0.006041,-0.153447,0.061291,0.003122,-1.534468,-1299.688965,-0.152259,0.000000
10.370001,0.057716,-1299.644409,-0.009442,-0.005859,-0.148816,0.256735,0.013079,-1.488158,-1299.644409,-0.147766,0.000000
10.640000,0.027184,-1299.644409,-0.009274,-0.005684,-0.144376,0.120918,0.006160,-1.443756,-1299.644409,-0.143257,0.000000
10.910001,0.018250,-1299.599976,-0.009089,-0.005504,-0.139814,0.081178,0.004135,-1.398140,-1299.599976,-0.138765,0.000000
11.180000,0.020111,-1299.599976,-0.008925,-0.005328,-0.135330,0.089459,0.004557,-1.353304,-1299.599976,-0.134273,0.000000
11.450001,-0.011917,-1299.644409,-0.008731,-0.005155,-0.130934,-0.053010,-0.002700,-1.309337,-1299.644409,-0.129763,0.000000
11.720000,0.036491,-1299.644409,-0.008567,-0.004983,-0.126563,0.162322,0.008269,-1.265629,-1299.644409,-0.125271,0.000000
11.990001,0.021973,-1299.555420,-0.008360,-0.004799,-0.121889,0.097739,0.004979,-1.218886,-1299.555420,-0.120778,0.000000
12.260000,0.043938,-1299.555420,-0.008196,-0.004620,-0.117344,0.195445,0.009956,-1.173442,-1299.555420,-0.116269,0.000000
12.530001,0.057716,-1299.599976,-0.008015,-0.004437,-0.112696,0.256735,0.013079,-1.126958,-1299.599976,-0.111777,0.000000
12.800000,0.038727,-1299.688965,-0.007834,-0.004265,-0.108334,0.172265,0.008776,-1.083337,-1299.688965,-0.107284,0.000000
13.070001,0.041336,-1299.644409,-0.007653,-0.004093,-0.103972,0.183872,0.009367,-1.039716,-1299.644409,-0.102775,0.000000
13.340001,-0.001114,-1299.555420,-0.007459,-0.003909,-0.099280,-0.004955,-0.000252,-0.992799,-1299.555420,-0.098283,0.000000
13.610001,0.019737,-1299.599976,-0.007295,-0.003734,-0.094840,0.087796,0.004473,-0.948398,-1299.599976,-0.093790,0.000000
13.880001,0.009682,-1299.599976,-0.007131,-0.003561,-0.090443,0.043066,0.002194,-0.904429,-1299.599976,-0.089281,0.000000
14.150001,0.028671,-1299.599976,-0.006937,-0.003382,-0.085899,0.127536,0.006497,-0.858986,-1299.599976,-0.084789,0.000000
14.420001,0.058090,-1299.688965,-0.006765,-0.003204,-0.081372,0.258398,0.013163,-0.813716,-1299.688965,-0.080296,0.000000
14.690001,0.063675,-1299.599976,-0.006562,-0.003026,-0.076862,0.283240,0.014429,-0.768621,-1299.599976,-0.075787,0.000000
14.960001,0.048035,-1299.599976,-0.006390,-0.002845,-0.072266,0.213669,0.010885,-0.722658,-1299.599976,-0.071295,0.000000
15.230000,0.034630,-1299.599976,-0.006222,-0.002672,-0.067860,0.154041,0.007847,-0.678603,-1299.599976,-0.066802,0.000000
15.500001,-0.012291,-1299.599976,-0.006036,-0.002496,-0.063403,-0.054673,-0.002785,-0.634029,-1299.599976,-0.062293,0.000000
15.770000,0.042076,-1299.644409,-0.005859,-0.002322,-0.058971,0.187164,0.009535,-0.589713,-1299.644409,-0.057800,0.000000
16.040001,0.020111,-1299.644409,-0.005687,-0.002139,-0.054332,0.089459,0.004557,-0.543316,-1299.644409,-0.053308,0.000000
16.310001,0.037979,-1299.555420,-0.005514,-0.001965,-0.049900,0.168940,0.008606,-0.499001,-1299.555420,-0.048799,0.000000
16.580000,0.072983,-1299.599976,-0.005342,-0.001786,-0.045373,0.324644,0.016538,-0.453731,-1299.599976,-0.044307,0.000000
16.850000,0.037979,-1299.599976,-0.005161,-0.001612,-0.040942,0.168940,0.008606,-0.409416,-1299.599976,-0.039814,0.000000
17.120001,0.061813,-1299.599976,-0.004963,-0.001431,-0.036345,0.274960,0.014007,-0.363454,-1299.599976,-0.035305,0.000000
17.390001,0.052505,-1299.599976,-0.004786,-0.001250,-0.031749,0.233556,0.011898,-0.317490,-1299.599976,-0.030812,0.000000
17.660002,0.031654,-1299.644409,-0.004618,-0.001082,-0.027474,0.140806,0.007173,-0.274736,-1299.644409,-0.026320,0.000000
17.930000,0.063675,-1299.599976,-0.004441,-0.000907,-0.023042,0.283240,0.014429,-0.230421,-1299.599976,-0.021811,0.000000
18.200001,-0.010056,-1299.644409,-0.004273,-0.000723,-0.018376,-0.044729,-0.002279,-0.183764,-1299.644409,-0.017318,0.000000
18.470001,0.067398,-1299.644409,-0.004087,-0.000547,-0.013893,0.299802,0.015273,-0.138928,-1299.644409,-0.012826,0.000000
18.740002,0.130333,-1299.688965,-0.003911,-0.000368,-0.009357,0.579750,0.029534,-0.093572,-1299.688965,-0.008317,0.000000
19.010000,0.535103,-1299.555420,-0.003721,-0.000187,-0.004752,2.380256,0.121256,-0.047523,-1299.555420,-0.003824,0.000000
19.280001,0.603241,-1299.599976,-0.003673,-0.000000,-0.000000,2.683350,0.136696,-0.000000,-1299.599976,0.000260,0.000000
19.550001,0.575317,-1299.644409,-0.003682,-0.000000,-0.000000,2.559139,0.130369,-0.000000,-1299.644409,0.000260,0.000000
19.820002,0.574944,-1299.688965,-0.003656,-0.000000,-0.000000,2.557477,0.130284,-0.000000,-1299.688965,0.000668,0.000000
20.090000,0.555954,-1299.555420,-0.003665,-0.000000,-0.000000,2.473007,0.125981,-0.000000,-1299.555420,0.001119,0.000000
20.360001,0.524673,-1299.644409,-0.003665,-0.000000,-0.000000,2.333864,0.118893,-0.000000,-1299.644409,0.001570,0.000000
20.630001,0.775650,-1299.599976,-0.003648,0.000050,0.001275,3.450264,0.175765,0.012748,-1299.599976,0.002021,0.000000
20.900002,0.800972,-1299.644409,-0.003635,0.000062,0.001587,3.562901,0.181503,0.015870,-1299.644409,0.002472,0.000000
21.170000,0.847145,-1299.644409,-0.003609,0.000080,0.002029,3.768290,0.191966,0.020293,-1299.644409,0.002923,0.000000
21.440001,0.898537,-1299.644409,-0.003596,0.000101,0.002567,3.996891,0.203611,0.025669,-1299.644409,0.003365,0.000000
21.710001,0.963326,-1299.644409,-0.003583,0.000119,0.003035,4.285086,0.218293,0.030353,-1299.644409,0.003816,0.000000
21.980001,0.989769,-1299.644409,-0.003583,0.000129,0.003287,4.402712,0.224285,0.032868,-1299.644409,0.004267,0.000000
22.250002,1.028862,-1299.599976,-0.003557,0.000144,0.003651,4.576607,0.233143,0.036511,-1299.599976,0.004718,0.000000
22.520000,1.094032,-1299.688965,-0.003523,0.000171,0.004353,4.866498,0.247911,0.043534,-1299.688965,0.005169,0.000000
22.790001,1.132759,-1299.688965,-0.003514,0.000187,0.004744,5.038764,0.256687,0.047438,-1299.688965,0.005620,0.000000
23.060001,1.153984,-1299.688965,-0.003505,0.000203,0.005169,5.133177,0.261497,0.051687,-1299.688965,0.006071,0.000000
23.330002,1.185631,-1299.599976,-0.003484,0.000222,0.005637,5.273949,0.268668,0.056370,-1299.599976,0.006522,0.000000
23.600000,1.233299,-1299.688965,-0.003471,0.000240,0.006105,5.485989,0.279470,0.061052,-1299.688965,0.006973,0.000000
23.870001,1.258247,-1299.733398,-0.003449,0.000254,0.006452,5.596964,0.285123,0.064521,-1299.733398,0.007415,0.000000
24.140001,1.285057,-1299.688965,-0.003432,0.000270,0.006851,5.716219,0.291198,0.068510,-1299.688965,0.007866,0.000000
24.410002,1.355438,-1299.644409,-0.003406,0.000297,0.007545,6.029290,0.307147,0.075448,-1299.644409,0.008317,0.000000
24.680000,1.357300,-1299.644409,-0.003385,0.000312,0.007935,6.037571,0.307569,0.079350,-1299.644409,0.008768,0.000000
24.950001,1.381500,-1299.644409,-0.003376,0.000328,0.008325,6.145220,0.313052,0.083254,-1299.644409,0.009219,0.000000
25.220001,1.366608,-1299.688965,-0.003354,0.000341,0.008655,6.078975,0.309678,0.086549,-1299.688965,0.009670,0.000000
25.490002,1.485023,-1299.688965,-0.003337,0.000366,0.009297,6.605714,0.336511,0.092966,-1299.688965,0.010120,0.000000
25.760002,1.472733,-1299.688965,-0.003316,0.000379,0.009626,6.551042,0.333726,0.096261,-1299.688965,0.010571,0.000000
26.030001,1.493958,-1299.688965,-0.003307,0.000394,0.009999,6.645455,0.338536,0.099991,-1299.688965,0.011022,0.000000
26.300001,1.551308,-1299.644409,-0.003290,0.000418,0.010615,6.900561,0.351531,0.106149,-1299.644409,0.011465,0.000000
26.570002,1.568436,-1299.733398,-0.003251,0.000436,0.011074,6.976750,0.355413,0.110744,-1299.733398,0.011916,0.000000
26.840002,1.546463,-1299.688965,-0.003242,0.000452,0.011473,6.879011,0.350434,0.114733,-1299.688965,0.012367,0.000000
27.110001,1.552048,-1299.644409,-0.003221,0.000466,0.011846,6.903853,0.351699,0.118463,-1299.644409,0.012818,0.000000
27.380001,1.626526,-1299.733398,-0.003216,0.000489,0.012410,7.235148,0.368576,0.124099,-1299.733398,0.013269,0.000000
27.650002,1.663757,-1299.733398,-0.003186,0.000507,0.012870,7.400762,0.377013,0.128696,-1299.733398,0.013719,0.000000
27.920002,1.649612,-1299.733398,-0.003173,0.000518,0.013147,7.337842,0.373808,0.131472,-1299.733398,0.014170,0.000000
28.190001,1.714401,-1299.777832,-0.003156,0.000543,0.013789,7.626038,0.388489,0.137889,-1299.777832,0.014621,0.000000
28.460001,1.725204,-1299.644409,-0.003130,0.000562,0.014275,7.674093,0.390937,0.142745,-1299.644409,0.015072,0.000000
28.730001,1.708817,-1299.599976,-0.003109,0.000579,0.014708,7.601195,0.387223,0.147081,-1299.599976,0.015523,0.000000
29.000002,1.701370,-1299.644409,-0.003104,0.000591,0.015003,7.568073,0.385536,0.150029,-1299.644409,0.015966,0.000000
29.270000,1.784035,-1299.733398,-0.003087,0.000613,0.015575,7.935783,0.404268,0.155754,-1299.733398,0.016417,0.000000
29.540001,1.812340,-1299.688965,-0.003065,0.000627,0.015931,8.061690,0.410682,0.159310,-1299.688965,0.016868,0.000000
29.810001,1.811966,-1299.733398,-0.003057,0.000641,0.016269,8.060027,0.410597,0.162692,-1299.733398,0.017319,0.000000
30.080002,1.842873,-1299.688965,-0.003031,0.000656,0.016659,8.197507,0.417601,0.166594,-1299.688965,0.017770,0.000000
30.350002,1.918091,-1299.644409,-0.003014,0.000684,0.017379,8.532094,0.434646,0.173793,-1299.644409,0.018220,0.000000
30.620001,1.893890,-1299.733398,-0.002992,0.000703,0.017856,8.424445,0.429162,0.178562,-1299.733398,0.018671,0.000000
30.890001,1.894630,-1299.644409,-0.002971,0.000720,0.018290,8.427737,0.429329,0.182897,-1299.644409,0.019122,0.000000
31.160002,1.936340,-1299.733398,-0.002949,0.000734,0.018654,8.613272,0.438781,0.186540,-1299.733398,0.019573,0.000000
31.430002,2.005974,-1299.688965,-0.002936,0.000754,0.019157,8.923018,0.454560,0.191571,-1299.688965,0.020016,0.000000
31.700001,1.978043,-1299.688965,-0.002915,0.000763,0.019391,8.798773,0.448231,0.193912,-1299.688965,0.020466,0.000000
31.970001,2.066292,-1299.644409,-0.002910,0.000787,0.019990,9.191325,0.468228,0.199895,-1299.644409,0.020917,0.000000
32.240002,2.127739,-1299.733398,-0.002880,0.000810,0.020571,9.464656,0.482153,0.205705,-1299.733398,0.021368,0.000000
32.510002,2.118423,-1299.688965,-0.002859,0.000824,0.020917,9.423218,0.480042,0.209174,-1299.688965,0.021819,0.000000
32.780003,2.105392,-1299.599976,-0.002837,0.000842,0.021386,9.365253,0.477089,0.213858,-1299.599976,0.022270,0.000000
33.050003,2.077835,-1299.688965,-0.002824,0.000855,0.021707,9.242672,0.470844,0.217068,-1299.688965,0.022721,0.000000
33.320000,2.245407,-1299.599976,-0.002811,0.000877,0.022288,9.988070,0.508817,0.222877,-1299.599976,0.023172,0.000000
33.590000,2.238701,-1299.777832,-0.002794,0.000891,0.022643,9.958239,0.507297,0.226433,-1299.777832,0.023623,0.000000
33.860001,2.312805,-1299.733398,-0.002772,0.000913,0.023190,10.287871,0.524089,0.231897,-1299.733398,0.024065,0.000000
34.130001,2.342598,-1299.733398,-0.002746,0.000934,0.023727,10.420396,0.530840,0.237273,-1299.733398,0.024516,0.000000
34.400002,2.341103,-1299.644409,-0.002725,0.000946,0.024040,10.413745,0.530501,0.240396,-1299.644409,0.024967,0.000000
34.670002,2.362701,-1299.644409,-0.002712,0.000965,0.024516,10.509821,0.535396,0.245165,-1299.644409,0.025418,0.000000
34.940002,2.375366,-1299.688965,-0.002690,0.000981,0.024924,10.566156,0.538266,0.249241,-1299.688965,0.025869,0.000000
35.210003,2.468826,-1299.733398,-0.002669,0.001004,0.025514,10.981888,0.559444,0.255138,-1299.733398,0.026320,0.000000
35.480003,2.471062,-1299.688965,-0.002647,0.001019,0.025878,10.991832,0.559951,0.258781,-1299.688965,0.026771,0.000000
35.750000,2.497505,-1299.644409,-0.002656,0.001033,0.026233,11.109458,0.565943,0.262335,-1299.644409,0.027222,0.000000
36.020000,2.596184,-1299.644409,-0.002626,0.001057,0.026841,11.548402,0.588304,0.268406,-1299.644409,0.027673,0.000000
36.290001,2.575699,-1299.644409,-0.002613,0.001071,0.027205,11.457281,0.583662,0.272049,-1299.644409,0.028124,0.000000
36.560001,2.604370,-1299.733398,-0.002583,0.001090,0.027690,11.584817,0.590159,0.276905,-1299.733398,0.028566,0.000000
36.830002,2.632675,-1299.733398,-0.002557,0.001105,0.028063,11.710724,0.596573,0.280635,-1299.733398,0.029017,0.000000
37.100002,2.717201,-1299.644409,-0.002552,0.001127,0.028619,12.086715,0.615727,0.286185,-1299.644409,0.029468,0.000000
37.370003,2.748108,-1299.644409,-0.002531,0.001144,0.029052,12.224195,0.622730,0.290521,-1299.644409,0.029919,0.000000
37.640003,2.812531,-1299.733398,-0.002518,0.001160,0.029468,12.510760,0.637329,0.294682,-1299.733398,0.030370,0.000000
37.910004,2.838593,-1299.733398,-0.002492,0.001180,0.029963,12.626690,0.643234,0.299627,-1299.733398,0.030821,0.000000
38.180000,2.911957,-1299.733398,-0.002462,0.001200,0.030492,12.953031,0.659859,0.304917,-1299.733398,0.031272,0.000000
38.450001,2.871361,-1299.688965,-0.002449,0.001215,0.030873,12.772450,0.650660,0.308732,-1299.688965,0.031723,0.000000
38.720001,2.911583,-1299.688965,-0.002449,0.001234,0.031342,12.951367,0.659774,0.313416,-1299.688965,0.032174,0.000000
38.990002,2.999084,-1299.733398,-0.002410,0.001255,0.031888,13.340594,0.679602,0.318879,-1299.733398,0.032616,0.000000
39.260002,3.008026,-1299.777832,-0.002402,0.001270,0.032261,13.380368,0.681628,0.322607,-1299.777832,0.033067,0.000000
39.530003,3.076538,-1299.733398,-0.002376,0.001285,0.032651,13.685125,0.697153,0.326510,-1299.733398,0.033518,0.000000
39.800003,3.192352,-1299.733398,-0.002350,0.001309,0.033249,14.200293,0.723397,0.332494,-1299.733398,0.033969,0.000000
40.070004,3.157722,-1299.777832,-0.002337,0.001323,0.033605,14.046251,0.715550,0.336049,-1299.777832,0.034420,0.000000
40.340000,3.159950,-1299.822388,-0.002337,0.001340,0.034030,14.056161,0.716055,0.340300,-1299.822388,0.034871,0.000000
40.610001,3.252670,-1299.777832,-0.002311,0.001360,0.034550,14.468600,0.737066,0.345502,-1299.777832,0.035322,0.000000
40.880001,3.350983,-1299.866821,-0.002294,0.001380,0.035053,14.905915,0.759344,0.350532,-1299.866821,0.035773,0.000000
41.150002,3.352470,-1299.777832,-0.002276,0.001396,0.035470,14.912533,0.759681,0.354696,-1299.777832,0.036224,0.000000
41.420002,3.398643,-1299.688965,-0.002264,0.001411,0.035851,15.117921,0.770144,0.358511,-1299.688965,0.036675,0.000000
41.690002,3.552437,-1299.777832,-0.002233,0.001434,0.036432,15.802029,0.804994,0.364321,-1299.777832,0.037117,0.000000
41.960003,3.502907,-1299.822388,-0.002229,0.001448,0.036779,15.581708,0.793770,0.367790,-1299.822388,0.037568,0.000000
42.230003,3.499557,-1299.822388,-0.002207,0.001462,0.037126,15.566810,0.793011,0.371258,-1299.822388,0.038019,0.000000
42.500004,3.560623,-1299.777832,-0.002199,0.001479,0.037568,15.838443,0.806849,0.375683,-1299.777832,0.038470,0.000000
42.770000,3.697662,-1299.777832,-0.002173,0.001500,0.038106,16.448023,0.837902,0.381059,-1299.777832,0.038921,0.000000
43.040001,3.760216,-1299.822388,-0.002151,0.001518,0.038557,16.726274,0.852077,0.385569,-1299.822388,0.039372,0.000000
43.310001,3.687233,-1299.866821,-0.002134,0.001528,0.038817,16.401632,0.835539,0.388169,-1299.866821,0.039823,0.000000
43.580002,3.738617,-1299.733398,-0.002126,0.001545,0.039233,16.630199,0.847183,0.392333,-1299.733398,0.040274,0.000000
43.850002,3.976196,-1299.777832,-0.002100,0.001573,0.039944,17.687004,0.901019,0.399445,-1299.777832,0.040725,0.000000
44.120003,3.960930,-1299.733398,-0.002082,0.001587,0.040300,17.619097,0.897560,0.403000,-1299.733398,0.041167,0.000000
44.390003,3.995926,-1299.777832,-0.002078,0.001604,0.040751,17.774767,0.905490,0.407510,-1299.777832,0.041618,0.000000
44.660004,4.071518,-1299.777832,-0.002057,0.001621,0.041185,18.111017,0.922619,0.411846,-1299.777832,0.042069,0.000000
44.930000,4.167221,-1299.822388,-0.002031,0.001641,0.041670,18.536726,0.944306,0.416702,-1299.822388,0.042520,0.000000
45.200001,4.144508,-1299.822388,-0.002009,0.001655,0.042026,18.435694,0.939159,0.420258,-1299.822388,0.042971,0.000000
45.470001,4.207809,-1299.777832,-0.002005,0.001669,0.042399,18.717272,0.953503,0.423986,-1299.777832,0.043422,0.000000
45.740002,4.448730,-1299.777832,-0.001975,0.001697,0.043110,19.788942,1.008097,0.431098,-1299.777832,0.043873,0.000000
46.010002,4.475548,-1299.777832,-0.001970,0.001714,0.043543,19.908232,1.014174,0.435433,-1299.777832,0.044324,0.000000
46.280003,4.470703,-1299.777832,-0.001940,0.001729,0.043916,19.886681,1.013076,0.439163,-1299.777832,0.044775,0.000000
46.550003,4.424156,-1299.777832,-0.001923,0.001741,0.044220,19.679630,1.002528,0.442199,-1299.777832,0.045217,0.000000
46.820004,4.736580,-1299.777832,-0.001906,0.001767,0.044870,21.069359,1.073324,0.448703,-1299.777832,0.045668,0.000000
47.090004,4.670670,-1299.822388,-0.001893,0.001778,0.045165,20.776176,1.058389,0.451652,-1299.822388,0.046119,0.000000
47.360001,4.758545,-1299.822388,-0.001888,0.001794,0.045564,21.167065,1.078302,0.455641,-1299.822388,0.046570,0.000000
47.630001,5.010643,-1299.822388,-0.001871,0.001818,0.046171,22.288454,1.135428,0.461712,-1299.822388,0.047021,0.000000
47.900002,5.018463,-1299.866821,-0.001845,0.001836,0.046622,22.323238,1.137200,0.466221,-1299.866821,0.047472,0.000000
48.170002,5.013252,-1299.866821,-0.001824,0.001854,0.047099,22.300060,1.136019,0.470990,-1299.866821,0.047923,0.000000
48.440002,4.983459,-1299.822388,-0.001819,0.001867,0.047411,22.167536,1.129268,0.474113,-1299.822388,0.048374,0.000000
48.710003,5.273170,-1299.777832,-0.001802,0.001889,0.047984,23.456234,1.194917,0.479836,-1299.777832,0.048825,0.000000
48.980003,5.332748,-1299.822388,-0.001789,0.001905,0.048391,23.721251,1.208418,0.483912,-1299.822388,0.049276,0.000000
49.250004,5.273911,-1299.866821,-0.001759,0.001917,0.048695,23.459526,1.195085,0.486948,-1299.866821,0.049718,0.000000
49.520000,5.617615,-1299.866821,-0.001746,0.001943,0.049354,24.988398,1.272970,0.493539,-1299.866821,0.050169,0.000000
49.790001,5.669746,-1299.822388,-0.001729,0.001961,0.049805,25.220291,1.284783,0.498049,-1299.822388,0.050620,0.000000
50.060001,5.706238,-1299.822388,-0.001716,0.001978,0.050247,25.382614,1.293052,0.502471,-1299.822388,0.051071,0.000000
50.330002,5.656342,-1299.777832,-0.001690,0.001991,0.050577,25.160664,1.281745,0.505766,-1299.777832,0.051522,0.000000
50.600002,5.984398,-1299.866821,-0.001681,0.002013,0.051132,26.619932,1.356084,0.511317,-1299.866821,0.051973,0.000000
50.870003,5.950516,-1299.822388,-0.001664,0.002026,0.051452,26.469215,1.348406,0.514524,-1299.822388,0.052424,0.000000
51.140003,5.906944,-1299.866821,-0.001647,0.002038,0.051773,26.275400,1.338533,0.517734,-1299.866821,0.052875,0.000000
51.410004,6.192924,-1299.866821,-0.001630,0.002059,0.052302,27.547504,1.403337,0.523023,-1299.866821,0.053326,0.000000
51.680004,6.473694,-1299.822388,-0.001604,0.002083,0.052918,28.796429,1.466960,0.529181,-1299.822388,0.053768,0.000000
51.950001,6.538116,-1299.866821,-0.001591,0.002103,0.053404,29.082994,1.481558,0.534037,-1299.866821,0.054219,0.000000
52.220001,6.616318,-1299.822388,-0.001574,0.002120,0.053837,29.430851,1.499279,0.538373,-1299.822388,0.054670,0.000000
52.490002,6.636047,-1299.866821,-0.001556,0.002133,0.054176,29.518614,1.503750,0.541757,-1299.866821,0.055121,0.000000
52.760002,6.877716,-1299.866821,-0.001535,0.002150,0.054609,30.593609,1.558513,0.546092,-1299.866821,0.055572,0.000000
53.030003,6.821495,-1299.955811,-0.001522,0.002162,0.054913,30.343525,1.545773,0.549128,-1299.955811,0.056023,0.000000
53.300003,7.112312,-1299.866821,-0.001518,0.002184,0.055476,31.637146,1.611673,0.554763,-1299.866821,0.056474,0.000000
53.570004,7.579269,-1299.866821,-0.001487,0.002209,0.056118,33.714275,1.717487,0.561183,-1299.866821,0.056925,0.000000
53.840004,7.429947,-1299.777832,-0.001475,0.002224,0.056482,33.050053,1.683650,0.564824,-1299.777832,0.057376,0.000000
54.110004,7.553574,-1299.866821,-0.001462,0.002242,0.056959,33.599972,1.711664,0.569595,-1299.866821,0.057818,0.000000
54.380001,7.670502,-1299.866821,-0.001436,0.002258,0.057341,34.120094,1.738160,0.573410,-1299.866821,0.058269,0.000000
54.650002,8.011223,-1299.866821,-0.001431,0.002276,0.057809,35.635700,1.815369,0.578094,-1299.866821,0.058720,0.000000
54.920002,8.018669,-1299.955811,-0.001401,0.002290,0.058165,35.668823,1.817056,0.581648,-1299.955811,0.059171,0.000000
55.190002,8.322899,-1299.866821,-0.001388,0.002311,0.058711,37.022102,1.885996,0.587111,-1299.866821,0.059622,0.000000
55.460003,8.674416,-1299.822388,-0.001358,0.002333,0.059266,38.585728,1.965651,0.592662,-1299.822388,0.060073,0.000000
55.730003,8.565681,-1299.866821,-0.001362,0.002346,0.059596,38.102055,1.941011,0.595958,-1299.866821,0.060524,0.000000
56.000004,8.815170,-1299.911255,-0.001354,0.002365,0.060064,39.211834,1.997546,0.600640,-1299.911255,0.060975,0.000000
56.270004,8.958534,-1299.911255,-0.001319,0.002382,0.060506,39.849552,2.030033,0.605063,-1299.911255,0.061426,0.000000
56.540001,9.357346,-1299.911255,-0.001298,0.002403,0.061044,41.623550,2.120405,0.610441,-1299.911255,0.061877,0.000000
56.810001,9.316757,-1299.911255,-0.001289,0.002417,0.061400,41.443005,2.111207,0.613995,-1299.911255,0.062319,0.000000
57.080002,9.450439,-1299.822388,-0.001272,0.002431,0.061755,42.037655,2.141500,0.617551,-1299.822388,0.062770,0.000000
57.350002,10.051453,-1299.911255,-0.001255,0.002455,0.062362,44.711094,2.277692,0.623622,-1299.911255,0.063221,0.000000
57.620003,9.907341,-1299.911255,-0.001237,0.002470,0.062726,44.070053,2.245036,0.627265,-1299.911255,0.063672,0.000000
57.890003,10.346741,-1299.955811,-0.001233,0.002491,0.063264,46.024601,2.344605,0.632641,-1299.955811,0.064123,0.000000
58.160004,10.389191,-1299.866821,-0.001216,0.002505,0.063620,46.213428,2.354224,0.636197,-1299.866821,0.064574,0.000000
58.430004,10.826729,-1299.911255,-0.001194,0.002525,0.064140,48.159695,2.453372,0.641400,-1299.911255,0.065024,0.000000
58.700005,11.044197,-1299.911255,-0.001177,0.002542,0.064565,49.127041,2.502651,0.645650,-1299.911255,0.065475,0.000000
58.970001,11.305229,-1299.955811,-0.001155,0.002559,0.064990,50.288170,2.561802,0.649899,-1299.955811,0.065926,0.000000
59.240002,11.617279,-1299.955811,-0.001143,0.002579,0.065510,51.676239,2.632513,0.655103,-1299.955811,0.066369,0.000000
59.510002,12.042900,-1299.911255,-0.001130,0.002599,0.066013,53.569496,2.728960,0.660133,-1299.911255,0.066820,0.000000
59.780003,12.041039,-1299.866821,-0.001108,0.002614,0.066404,53.561214,2.728538,0.664035,-1299.866821,0.067271,0.000000
60.050003,12.531082,-1299.911255,-0.001095,0.002636,0.066950,55.741035,2.839584,0.669499,-1299.911255,0.067722,0.000000
60.320004,12.979416,-1299.955811,-0.001078,0.002655,0.067444,57.735325,2.941178,0.674442,-1299.955811,0.068173,0.000000
60.590004,12.970848,-1299.955811,-0.001052,0.002670,0.067808,57.697212,2.939236,0.678083,-1299.955811,0.068624,0.000000
60.860004,13.247894,-1299.955811,-0.001052,0.002685,0.068190,58.929577,3.002016,0.681900,-1299.955811,0.069075,0.000000
61.130001,13.959496,-1299.911255,-0.001026,0.002708,0.068788,62.094936,3.163267,0.687884,-1299.911255,0.069525,0.000000
61.400002,13.931572,-1299.866821,-0.001018,0.002722,0.069127,61.970726,3.156940,0.691266,-1299.866821,0.069976,0.000000
61.670002,14.209732,-1299.911255,-0.001000,0.002738,0.069551,63.208046,3.219971,0.695514,-1299.911255,0.070419,0.000000
61.940002,14.895645,-1299.955811,-0.000996,0.002759,0.070089,66.259140,3.375401,0.700893,-1299.955811,0.070870,0.000000
62.210003,15.356644,-1299.955811,-0.000961,0.002779,0.070584,68.309761,3.479865,0.705836,-1299.955811,0.071321,0.000000
62.480003,15.596077,-1299.911255,-0.000949,0.002796,0.071017,69.374817,3.534122,0.710171,-1299.911255,0.071772,0.000000
62.750004,15.815407,-1299.955811,-0.000944,0.002810,0.071373,70.350441,3.583822,0.713727,-1299.955811,0.072223,0.000000
63.020004,16.620102,-1299.955811,-0.000940,0.002834,0.071980,73.929909,3.766169,0.719798,-1299.955811,0.072674,0.000000
63.290005,16.700531,-1300.000244,-0.000910,0.002847,0.072309,74.287674,3.784394,0.723093,-1300.000244,0.073125,0.000000
63.560001,16.807404,-1300.000244,-0.000892,0.002861,0.072682,74.763062,3.808612,0.726821,-1300.000244,0.073576,0.000000
63.830002,17.311600,-1299.866821,-0.000888,0.002880,0.073159,77.005844,3.922865,0.731592,-1299.866821,0.074026,0.000000
64.100006,18.097305,-1299.911255,-0.000867,0.002900,0.073653,80.500832,4.100908,0.736535,-1299.911255,0.074477,0.000000
64.370003,18.563515,-1299.911255,-0.000858,0.002917,0.074096,82.574638,4.206553,0.740958,-1299.911255,0.074920,0.000000
64.639999,18.513611,-1300.044800,-0.000841,0.002927,0.074347,82.352654,4.195244,0.743473,-1300.044800,0.075371,0.000000
64.910004,18.864388,-1299.955811,-0.000832,0.002942,0.074737,83.912987,4.274731,0.747375,-1299.955811,0.075821,0.000000
65.180000,20.263390,-1299.955811,-0.000806,0.002972,0.075492,90.136055,4.591750,0.754920,-1299.955811,0.076272,0.000000
65.450005,20.410851,-1300.000244,-0.000798,0.002985,0.075830,90.792000,4.625165,0.758302,-1300.000244,0.076723,0.000000
65.720001,20.879295,-1299.955811,-0.000793,0.003003,0.076281,92.875748,4.731316,0.762812,-1299.955811,0.077174,0.000000
65.990005,21.459450,-1300.000244,-0.000785,0.003021,0.076732,95.456398,4.862781,0.767321,-1300.000244,0.077625,0.000000
66.260002,22.109245,-1300.000244,-0.000767,0.003039,0.077201,98.346832,5.010027,0.772005,-1300.000244,0.078076,0.000000
66.530006,22.333038,-1299.955811,-0.000755,0.003052,0.077530,99.342316,5.060739,0.775300,-1299.955811,0.078527,0.000000
66.800003,23.060654,-1300.000244,-0.000750,0.003074,0.078076,102.578911,5.225619,0.780763,-1300.000244,0.078970,0.000000
67.070000,24.347198,-1300.000244,-0.000729,0.003096,0.078649,108.301750,5.517154,0.786488,-1300.000244,0.079421,0.000000
67.340004,24.756065,-1299.955811,-0.000716,0.003113,0.079065,110.120476,5.609804,0.790649,-1299.955811,0.079871,0.000000
67.610001,25.116898,-1300.044800,-0.000690,0.003127,0.079438,111.725540,5.691570,0.794379,-1300.044800,0.080322,0.000000
67.880005,25.265099,-1300.000244,-0.000686,0.003139,0.079724,112.384773,5.725153,0.797241,-1300.000244,0.080773,0.000000
68.150002,26.753098,-1300.000244,-0.000681,0.003165,0.080383,119.003723,6.062339,0.803832,-1300.000244,0.081224,0.000000
68.420006,26.990677,-1300.000244,-0.000677,0.003177,0.080687,120.060524,6.116175,0.806868,-1300.000244,0.081675,0.000000
68.690002,27.540298,-1300.000244,-0.000660,0.003193,0.081094,122.505363,6.240721,0.810942,-1300.000244,0.082126,0.000000
68.960007,28.849556,-1300.044800,-0.000638,0.003216,0.081693,128.329239,6.537403,0.816926,-1300.044800,0.082577,0.000000
69.230003,29.658348,-1300.000244,-0.000625,0.003234,0.082135,131.926926,6.720677,0.821349,-1300.000244,0.083020,0.000000
69.500000,30.194565,-1299.955811,-0.000617,0.003251,0.082586,134.312134,6.842186,0.825858,-1299.955811,0.083471,0.000000
69.770004,30.597473,-1300.000244,-0.000604,0.003264,0.082915,136.104355,6.933486,0.829155,-1300.000244,0.083921,0.000000
70.040001,31.839333,-1300.000244,-0.000595,0.003288,0.083523,141.628418,7.214896,0.835226,-1300.000244,0.084372,0.000000
70.310005,32.586685,-1300.044800,-0.000595,0.003303,0.083895,144.952820,7.384248,0.838954,-1300.044800,0.084823,0.000000
70.580002,32.800804,-1300.000244,-0.000573,0.003317,0.084242,145.905258,7.432769,0.842423,-1300.000244,0.085274,0.000000
70.850006,34.599358,-1299.955811,-0.000565,0.003343,0.084910,153.905624,7.840326,0.849101,-1299.955811,0.085725,0.000000
71.120003,35.524330,-1299.955811,-0.000552,0.003360,0.085352,158.020111,8.049929,0.853524,-1299.955811,0.086176,0.000000
71.390007,36.244133,-1299.955811,-0.000548,0.003377,0.085769,161.221954,8.213037,0.857686,-1299.955811,0.086627,0.000000
71.660004,36.625435,-1300.044800,-0.000535,0.003388,0.086055,162.918076,8.299442,0.860549,-1300.044800,0.087078,0.000000
71.930000,38.050507,-1300.000244,-0.000526,0.003412,0.086662,169.257111,8.622369,0.866618,-1300.000244,0.087520,0.000000
72.200005,38.581139,-1300.000244,-0.000517,0.003424,0.086974,171.617477,8.742611,0.869740,-1300.000244,0.087971,0.000000
72.470001,38.916649,-1300.000244,-0.000504,0.003437,0.087312,173.109894,8.818639,0.873122,-1300.000244,0.088422,0.000000
72.740005,40.028549,-1300.044800,-0.000500,0.003453,0.087694,178.055878,9.070599,0.876939,-1300.044800,0.088873,0.000000
73.010002,42.050529,-1300.044800,-0.000496,0.003482,0.088440,187.050095,9.528787,0.884398,-1300.044800,0.089324,0.000000
73.280006,43.017586,-1300.000244,-0.000474,0.003500,0.088908,191.351776,9.747925,0.889079,-1300.000244,0.089775,0.000000
73.550003,44.091881,-1300.044800,-0.000466,0.003518,0.089359,196.130478,9.991363,0.893589,-1300.044800,0.090226,0.000000
73.820000,44.666077,-1300.000244,-0.000448,0.003531,0.089697,198.684631,10.121477,0.896971,-1300.000244,0.090677,0.000000
74.090004,45.967148,-1300.000244,-0.000457,0.003549,0.090148,204.472092,10.416305,0.901481,-1300.000244,0.091128,0.000000
74.360001,46.551025,-1300.000244,-0.000457,0.003560,0.090434,207.069305,10.548614,0.904344,-1300.000244,0.091570,0.000000
74.630005,47.745972,-1300.044800,-0.000440,0.003582,0.090972,212.384689,10.819391,0.909720,-1300.044800,0.092021,0.000000
74.900002,49.829391,-1300.000244,-0.000427,0.003606,0.091605,221.652206,11.291502,0.916051,-1300.000244,0.092472,0.000000
75.170006,50.669464,-1300.000244,-0.000418,0.003621,0.091978,225.389038,11.481865,0.919779,-1300.000244,0.092923,0.000000
75.440002,51.862549,-1299.955811,-0.000414,0.003639,0.092420,230.696136,11.752222,0.924203,-1299.955811,0.093374,0.000000
75.710007,52.591652,-1300.000244,-0.000414,0.003651,0.092741,233.939346,11.917439,0.927411,-1300.000244,0.093825,0.000000
75.980003,54.154503,-1300.000244,-0.000392,0.003673,0.093296,240.891266,12.271586,0.932961,-1300.000244,0.094276,0.000000
76.250000,55.204590,-1300.000244,-0.000388,0.003688,0.093686,245.562286,12.509539,0.936864,-1300.000244,0.094727,0.000000
76.520004,56.467308,-1299.955811,-0.000379,0.003705,0.094103,251.179138,12.795674,0.941027,-1299.955811,0.095178,0.000000
76.790001,58.627441,-1300.000244,-0.000388,0.003731,0.094762,260.787872,13.285168,0.947618,-1300.000244,0.095629,0.000000
77.060005,59.351700,-1299.955811,-0.000379,0.003743,0.095074,264.009552,13.449287,0.950739,-1299.955811,0.096071,0.000000
77.330002,60.758896,-1300.044800,-0.000362,0.003762,0.095560,270.269073,13.768163,0.955595,-1300.044800,0.096522,0.000000
77.600006,61.997040,-1300.000244,-0.000358,0.003778,0.095967,275.776611,14.048730,0.959671,-1300.000244,0.096973,0.000000
77.870003,63.772133,-1299.955811,-0.000358,0.003800,0.096531,283.672607,14.450972,0.965309,-1299.955811,0.097424,0.000000
78.140007,64.602150,-1300.000244,-0.000341,0.003813,0.096860,287.364716,14.639056,0.968604,-1300.000244,0.097875,0.000000
78.410004,65.571434,-1300.000244,-0.000336,0.003827,0.097216,291.676300,14.858700,0.972160,-1300.000244,0.098326,0.000000
78.680000,67.425102,-1300.089233,-0.000345,0.003851,0.097806,299.921844,15.278747,0.978057,-1300.089233,0.098777,0.000000
78.950005,67.038582,-1300.044800,-0.000336,0.003842,0.097597,298.202515,15.191160,0.975975,-1300.044800,0.097814,0.000000
79.220001,66.530296,-1299.955811,-0.000319,0.003841,0.097572,295.941528,15.075980,0.975716,-1299.955811,0.097597,0.000000
79.490005,66.090157,-1300.000244,-0.000310,0.003841,0.097554,293.983704,14.976244,0.975542,-1300.000244,0.097597,0.000000
79.760002,65.698418,-1300.000244,-0.000319,0.003840,0.097546,292.241150,14.887474,0.975456,-1300.000244,0.097597,0.000000
80.030006,65.361046,-1300.089233,-0.000306,0.003840,0.097537,290.740448,14.811025,0.975369,-1300.089233,0.097597,0.000000
80.300003,65.057945,-1300.000244,-0.000306,0.003840,0.097528,289.392181,14.742341,0.975282,-1300.000244,0.097597,0.000000
80.570007,64.798393,-1300.000244,-0.000306,0.003840,0.097528,288.237640,14.683526,0.975282,-1300.000244,0.097597,0.000000
80.840004,64.558586,-1300.044800,-0.000310,0.003839,0.097520,287.170929,14.629185,0.975195,-1300.044800,0.097597,0.000000
81.110001,64.340004,-1300.000244,-0.000315,0.003839,0.097520,286.198639,14.579654,0.975195,-1300.000244,0.097597,0.000000
81.380005,64.141151,-1300.089233,-0.000319,0.003839,0.097520,285.314087,14.534593,0.975195,-1300.089233,0.097597,0.000000
81.650002,63.961296,-1300.089233,-0.000319,0.003839,0.097520,284.514069,14.493837,0.975195,-1300.089233,0.097597,0.000000
81.920006,63.783684,-1300.000244,-0.000306,0.003839,0.097520,283.723999,14.453589,0.975195,-1300.000244,0.097597,0.000000
82.190002,63.625420,-1300.044800,-0.000310,0.003839,0.097520,283.019989,14.417727,0.975195,-1300.044800,0.097597,0.000000
82.460007,63.483925,-1300.044800,-0.000310,0.003839,0.097520,282.390594,14.385663,0.975195,-1300.044800,0.097597,0.000000
82.730003,63.336830,-1300.089233,-0.000302,0.003839,0.097511,281.736298,14.352331,0.975108,-1300.089233,0.097597,0.000000
83.000008,63.221031,-1300.044800,-0.000319,0.003839,0.097511,281.221191,14.326091,0.975108,-1300.044800,0.097597,0.000000
83.270004,63.096275,-1300.044800,-0.000289,0.003839,0.097511,280.666260,14.297821,0.975108,-1300.044800,0.097597,0.000000
83.540001,62.987923,-1300.000244,-0.000293,0.003839,0.097511,280.184265,14.273267,0.975108,-1300.000244,0.097597,0.000000
83.810005,62.884026,-1300.000244,-0.000293,0.003839,0.097511,279.722107,14.249724,0.975108,-1300.000244,0.097597,0.000000
84.080002,62.779022,-1300.044800,-0.000297,0.003839,0.097511,279.255035,14.225929,0.975108,-1300.044800,0.097597,0.000000
84.350006,62.674385,-1300.089233,-0.000293,0.003839,0.097511,278.789581,14.202218,0.975108,-1300.089233,0.097597,0.000000
84.620003,62.593575,-1300.089233,-0.000293,0.003839,0.097511,278.430115,14.183907,0.975108,-1300.089233,0.097597,0.000000
84.890007,62.493782,-1300.044800,-0.000289,0.003839,0.097511,277.986237,14.161293,0.975108,-1300.044800,0.097597,0.000000
85.160004,62.408508,-1300.044800,-0.000289,0.003839,0.097511,277.606903,14.141971,0.975108,-1300.044800,0.097597,0.000000
85.430000,62.342972,-1300.089233,-0.000289,0.003839,0.097511,277.315399,14.127119,0.975108,-1300.089233,0.097597,0.000000
85.700005,62.263283,-1300.089233,-0.000302,0.003839,0.097511,276.960907,14.109061,0.975108,-1300.089233,0.097597,0.000000
85.970001,62.180618,-1300.089233,-0.000289,0.003839,0.097511,276.593201,14.090330,0.975108,-1300.089233,0.097597,0.000000
86.240005,62.110611,-1300.000244,-0.000297,0.003839,0.097511,276.281799,14.074465,0.975108,-1300.000244,0.097597,0.000000
86.510002,62.046562,-1300.044800,-0.000285,0.003839,0.097511,275.996887,14.059952,0.975108,-1300.044800,0.097597,0.000000
86.780006,61.981400,-1300.089233,-0.000289,0.003839,0.097511,275.707031,14.045185,0.975108,-1300.089233,0.097597,0.000000
87.050003,61.911018,-1300.044800,-0.000289,0.003839,0.097511,275.393951,14.029238,0.975108,-1300.044800,0.097597,0.000000
87.320007,61.861862,-1300.089233,-0.000285,0.003839,0.097511,275.175293,14.018099,0.975108,-1300.089233,0.097597,0.000000
87.590004,61.787766,-1300.089233,-0.000293,0.003839,0.097511,274.845703,14.001307,0.975108,-1300.089233,0.097597,0.000000
87.860001,61.726318,-1300.044800,-0.000285,0.003839,0.097511,274.572388,13.987384,0.975108,-1300.044800,0.097597,0.000000
88.130005,61.671211,-1300.044800,-0.000293,0.003839,0.097511,274.327240,13.974896,0.975108,-1300.044800,0.097597,0.000000
88.400002,61.612373,-1300.044800,-0.000306,0.003839,0.097511,274.065521,13.961563,0.975108,-1300.044800,0.097597,0.000000
88.670006,61.575142,-1300.089233,-0.000297,0.003839,0.097511,273.899902,13.953127,0.975108,-1300.089233,0.097597,0.000000
88.940002,61.516678,-1300.089233,-0.000285,0.003839,0.097511,273.639862,13.939878,0.975108,-1300.089233,0.097597,0.000000
89.210007,61.465660,-1300.089233,-0.000297,0.003839,0.097511,273.412903,13.928317,0.975108,-1300.089233,0.097597,0.000000
89.480003,61.421349,-1300.044800,-0.000293,0.003839,0.097511,273.215790,13.918277,0.975108,-1300.044800,0.097597,0.000000
89.750008,61.375549,-1300.089233,-0.000293,0.003839,0.097511,273.012085,13.907898,0.975108,-1300.089233,0.097597,0.000000
90.020004,61.318573,-1300.089233,-0.000297,0.003839,0.097511,272.758636,13.894987,0.975108,-1300.089233,0.097597,0.000000
90.290001,61.273888,-1300.089233,-0.000297,0.003839,0.097511,272.559875,13.884862,0.975108,-1300.089233,0.097597,0.000000
90.560005,61.236649,-1300.089233,-0.000285,0.003839,0.097511,272.394226,13.876423,0.975108,-1300.089233,0.097597,0.000000
90.830002,61.197922,-1300.089233,-0.000293,0.003839,0.097511,272.221954,13.867647,0.975108,-1300.089233,0.097597,0.000000
91.100006,61.152122,-1300.044800,-0.000285,0.003839,0.097511,272.018219,13.857269,0.975108,-1300.044800,0.097597,0.000000
91.370003,61.105576,-1300.133667,-0.000302,0.003839,0.097511,271.811188,13.846722,0.975108,-1300.133667,0.097597,0.000000
91.640007,61.074669,-1300.089233,-0.000289,0.003839,0.097511,271.673706,13.839718,0.975108,-1300.089233,0.097597,0.000000
91.910004,61.036316,-1300.089233,-0.000285,0.003839,0.097511,271.503082,13.831027,0.975108,-1300.089233,0.097597,0.000000
92.180008,61.000938,-1300.089233,-0.000285,0.003839,0.097511,271.345734,13.823010,0.975108,-1300.089233,0.097597,0.000000
92.450005,60.944710,-1300.044800,-0.000289,0.003839,0.097511,271.095612,13.810269,0.975108,-1300.044800,0.097597,0.000000
92.720001,60.920883,-1300.133667,-0.000285,0.003839,0.097511,270.989624,13.804869,0.975108,-1300.133667,0.097597,0.000000
92.990005,60.891464,-1300.133667,-0.000289,0.003839,0.097511,270.858765,13.798203,0.975108,-1300.133667,0.097597,0.000000
93.260002,60.864281,-1300.133667,-0.000289,0.003839,0.097511,270.737854,13.792043,0.975108,-1300.133667,0.097597,0.000000
93.530006,60.812889,-1300.089233,-0.000289,0.003839,0.097511,270.509247,13.780397,0.975108,-1300.089233,0.097597,0.000000
93.800003,60.798744,-1300.044800,-0.000293,0.003839,0.097511,270.446320,13.777193,0.975108,-1300.044800,0.097597,0.000000
94.070007,60.761879,-1300.089233,-0.000310,0.003839,0.097511,270.282349,13.768839,0.975108,-1300.089233,0.097597,0.000000
94.340004,60.711609,-1300.133667,-0.000289,0.003839,0.097511,270.058716,13.757447,0.975108,-1300.133667,0.097597,0.000000
94.610008,60.692619,-1300.178223,-0.000289,0.003839,0.097511,269.974243,13.753144,0.975108,-1300.178223,0.097597,0.000000
94.880005,60.676979,-1300.089233,-0.000285,0.003839,0.097511,269.904694,13.749599,0.975108,-1300.089233,0.097597,0.000000
95.150002,60.652023,-1300.089233,-0.000293,0.003839,0.097511,269.793671,13.743945,0.975108,-1300.089233,0.097597,0.000000
95.420006,60.607712,-1300.089233,-0.000293,0.003839,0.097511,269.596558,13.733904,0.975108,-1300.089233,0.097597,0.000000
95.690002,60.577927,-1300.089233,-0.000293,0.003839,0.097511,269.464081,13.727155,0.975108,-1300.089233,0.097597,0.000000
95.960007,60.552231,-1300.133667,-0.000289,0.003839,0.097511,269.349762,13.721332,0.975108,-1300.133667,0.097597,0.000000
96.230003,60.520950,-1300.089233,-0.000285,0.003839,0.097511,269.210632,13.714243,0.975108,-1300.089233,0.097597,0.000000
96.500008,60.496002,-1300.044800,-0.000285,0.003839,0.097511,269.099670,13.708590,0.975108,-1300.044800,0.097597,0.000000
96.770004,60.471802,-1300.178223,-0.000289,0.003839,0.097511,268.992004,13.703107,0.975108,-1300.178223,0.097597,0.000000
97.040001,60.444244,-1300.133667,-0.000280,0.003839,0.097511,268.869415,13.696861,0.975108,-1300.133667,0.097597,0.000000
97.310005,60.423393,-1300.133667,-0.000289,0.003839,0.097511,268.776672,13.692137,0.975108,-1300.133667,0.097597,0.000000
97.580002,60.401047,-1300.044800,-0.000280,0.003839,0.097511,268.677277,13.687073,0.975108,-1300.044800,0.097597,0.000000
97.850006,60.372002,-1300.044800,-0.000297,0.003839,0.097511,268.548065,13.680491,0.975108,-1300.044800,0.097597,0.000000
98.120003,60.350037,-1300.089233,-0.000297,0.003839,0.097511,268.450378,13.675513,0.975108,-1300.089233,0.097597,0.000000
98.390007,60.324715,-1300.133667,-0.000276,0.003839,0.097511,268.337738,13.669776,0.975108,-1300.133667,0.097597,0.000000
98.660004,60.298645,-1300.089233,-0.000293,0.003839,0.097511,268.221771,13.663869,0.975108,-1300.089233,0.097597,0.000000
98.930008,60.280769,-1300.089233,-0.000293,0.003839,0.097511,268.142242,13.659818,0.975108,-1300.089233,0.097597,0.000000
99.200005,60.253220,-1300.089233,-0.000285,0.003839,0.097511,268.019714,13.653575,0.975108,-1300.089233,0.097597,0.000000
99.470001,60.217842,-1300.089233,-0.000293,0.003839,0.097511,267.862335,13.645558,0.975108,-1300.089233,0.097597,0.000000
99.740005,60.212257,-1300.133667,-0.000293,0.003839,0.097511,267.837494,13.644293,0.975108,-1300.133667,0.097597,0.000000
100.010002,60.196243,-1300.133667,-0.000289,0.003839,0.097511,267.766266,13.640663,0.975108,-1300.133667,0.097597,0.000000
100.280006,60.165710,-1300.089233,-0.000280,0.003839,0.097511,267.630432,13.633744,0.975108,-1300.089233,0.097597,0.000000
100.550003,60.159752,-1300.089233,-0.000280,0.003839,0.097511,267.603943,13.632395,0.975108,-1300.089233,0.097597,0.000000
100.820007,60.123627,-1300.089233,-0.000297,0.003839,0.097511,267.443237,13.624208,0.975108,-1300.089233,0.097597,0.000000
101.090004,60.118042,-1300.178223,-0.000297,0.003839,0.097511,267.418396,13.622943,0.975108,-1300.178223,0.097597,0.000000
101.360008,60.091606,-1300.133667,-0.000293,0.003839,0.097511,267.300812,13.616952,0.975108,-1300.133667,0.097597,0.000000
101.630005,60.057724,-1300.133667,-0.000285,0.003839,0.097511,267.150085,13.609275,0.975108,-1300.133667,0.097597,0.000000
101.900002,60.037239,-1300.089233,-0.000285,0.003839,0.097511,267.058990,13.604633,0.975108,-1300.089233,0.097597,0.000000
102.170006,60.011917,-1300.044800,-0.000289,0.003839,0.097511,266.946350,13.598894,0.975108,-1300.044800,0.097597,0.000000
102.440002,60.008568,-1300.089233,-0.000289,0.003839,0.097511,266.931427,13.598136,0.975108,-1300.089233,0.097597,0.000000
102.710007,59.977287,-1300.133667,-0.000285,0.003839,0.097511,266.792297,13.591047,0.975108,-1300.133667,0.097597,0.000000
102.980003,59.970955,-1300.133667,-0.000280,0.003839,0.097511,266.764130,13.589613,0.975108,-1300.133667,0.097597,0.000000
103.250008,59.954201,-1300.044800,-0.000285,0.003839,0.097511,266.689606,13.585816,0.975108,-1300.044800,0.097597,0.000000
103.520004,59.921432,-1300.133667,-0.000289,0.003839,0.097511,266.543854,13.578391,0.975108,-1300.133667,0.097597,0.000000
103.790009,59.917336,-1300.222656,-0.000289,0.003839,0.097511,266.525635,13.577462,0.975108,-1300.222656,0.097597,0.000000
104.060005,59.896484,-1300.178223,-0.000285,0.003839,0.097511,266.432861,13.572738,0.975108,-1300.178223,0.097597,0.000000
104.330002,59.880844,-1300.089233,-0.000285,0.003839,0.097511,266.363312,13.569194,0.975108,-1300.089233,0.097597,0.000000
104.600006,59.869301,-1300.000244,-0.000285,0.003839,0.097511,266.311951,13.566577,0.975108,-1300.000244,0.097597,0.000000
104.870003,59.850685,-1300.133667,-0.000280,0.003839,0.097511,266.229156,13.562359,0.975108,-1300.133667,0.097597,0.000000
105.140007,59.820145,-1300.133667,-0.000285,0.003839,0.097511,266.093292,13.555439,0.975108,-1300.133667,0.097597,0.000000
105.410004,59.805252,-1300.133667,-0.000289,0.003839,0.097511,266.027039,13.552064,0.975108,-1300.133667,0.097597,0.000000
105.680008,59.788864,-1300.089233,-0.000280,0.003839,0.097511,265.954163,13.548350,0.975108,-1300.089233,0.097597,0.000000
105.950005,59.773972,-1300.089233,-0.000280,0.003839,0.097511,265.887909,13.544976,0.975108,-1300.089233,0.097597,0.000000
106.220009,59.765778,-1300.089233,-0.000280,0.003839,0.097511,265.851471,13.543118,0.975108,-1300.089233,0.097597,0.000000
106.490005,59.737480,-1300.133667,-0.000285,0.003839,0.097511,265.725586,13.536707,0.975108,-1300.133667,0.097597,0.000000
106.760002,59.722961,-1300.178223,-0.000289,0.003839,0.097511,265.661011,13.533417,0.975108,-1300.178223,0.097597,0.000000
107.030006,59.719604,-1300.133667,-0.000293,0.003839,0.097511,265.646057,13.532656,0.975108,-1300.133667,0.097597,0.000000
107.300003,59.687210,-1300.133667,-0.000289,0.003839,0.097511,265.501984,13.525315,0.975108,-1300.133667,0.097597,0.000000
107.570007,59.685349,-1300.000244,-0.000280,0.003839,0.097511,265.493683,13.524894,0.975108,-1300.000244,0.097597,0.000000
107.840004,59.670082,-1300.133667,-0.000289,0.003839,0.097511,265.425781,13.521434,0.975108,-1300.133667,0.097597,0.000000
108.110008,59.641777,-1300.178223,-0.000280,0.003839,0.097511,265.299866,13.515020,0.975108,-1300.178223,0.097597,0.000000
108.380005,59.614227,-1300.133667,-0.000289,0.003839,0.097511,265.177338,13.508777,0.975108,-1300.133667,0.097597,0.000000
108.650002,59.617950,-1300.178223,-0.000280,0.003839,0.097511,265.193878,13.509621,0.975108,-1300.178223,0.097597,0.000000
108.920006,59.607521,-1300.089233,-0.000293,0.003839,0.097511,265.147491,13.507257,0.975108,-1300.089233,0.097597,0.000000
109.190002,59.577736,-1300.133667,-0.000285,0.003839,0.097511,265.015015,13.500508,0.975108,-1300.133667,0.097597,0.000000
109.200005,59.580338,-1300.133667,-0.000285,0.003839,0.097511,265.026581,13.501098,0.975108,-1300.133667,0.097597,0.000000