File: Data/compression 11/AutoNoHeating-16-11-4-240530_05302024_173310.csv
Time (sec),S:Load (lbs),S:HL1 (DIM),S:LVDT (in),S:Position (in),Ch:Position (mm),Ch:Load (N),Ch:Stress (MPa),Ch:Strain (mm/mm),Ch:HL1 (DIM),Set Point (),Cycles ()
0.110000,-0.010796,-354.468689,-0.012784,-0.000000,-0.000000,-0.048021,-0.002446,-0.000000,-354.468689,-0.000234,0.000000
0.350000,0.046173,-354.513184,-0.012779,-0.000000,-0.000000,0.205388,0.010463,-0.000000,-354.513184,0.000026,0.000000
0.590000,0.083786,-354.468689,-0.012784,0.000123,0.003131,0.372699,0.018986,0.031307,-354.468689,0.004033,0.000000
0.830000,0.047668,-354.513184,-0.012702,0.000275,0.006981,0.212040,0.010802,0.069812,-354.513184,0.008022,0.000000
1.070000,0.057350,-354.468689,-0.012547,0.000431,0.010936,0.255106,0.012996,0.109357,-354.468689,0.012028,0.000000
1.310000,0.090118,-354.557648,-0.012400,0.000586,0.014873,0.400867,0.020421,0.148729,-354.557648,0.016035,0.000000
1.550000,0.066284,-354.557648,-0.012223,0.000744,0.018906,0.294847,0.015020,0.189055,-354.557648,0.020024,0.000000
1.790000,0.017502,-354.557648,-0.012059,0.000904,0.022955,0.077852,0.003966,0.229555,-354.557648,0.024031,0.000000
2.030000,0.042450,-354.557648,-0.011926,0.001056,0.026815,0.188827,0.009619,0.268146,-354.557648,0.028020,0.000000
2.270000,0.069267,-354.513184,-0.011753,0.001213,0.030813,0.308116,0.015696,0.308125,-354.513184,0.032027,0.000000
2.510000,0.088997,-354.557648,-0.011620,0.001372,0.034854,0.395878,0.020167,0.348538,-354.557648,0.036016,0.000000
2.750000,0.084900,-354.602142,-0.011447,0.001528,0.038808,0.377654,0.019239,0.388083,-354.602142,0.040022,0.000000
2.990000,0.067406,-354.513184,-0.011283,0.001688,0.042876,0.299836,0.015274,0.428756,-354.513184,0.044012,0.000000
3.230000,0.081177,-354.646637,-0.011128,0.001843,0.046804,0.361092,0.018395,0.468042,-354.646637,0.048018,0.000000
3.470000,0.083038,-354.557648,-0.010969,0.002002,0.050845,0.369373,0.018817,0.508454,-354.557648,0.052008,0.000000
3.710000,0.062561,-354.602142,-0.010805,0.002163,0.054947,0.278285,0.014177,0.549474,-354.602142,0.056014,0.000000
3.950000,0.048042,-354.691101,-0.010641,0.002316,0.058824,0.213703,0.010887,0.588239,-354.691101,0.060003,0.000000
4.190000,0.072990,-354.557648,-0.010486,0.002474,0.062848,0.324678,0.016540,0.628478,-354.557648,0.064010,0.000000
4.430000,0.083412,-354.646637,-0.010343,0.002627,0.066733,0.371036,0.018901,0.667330,-354.646637,0.067999,0.000000
4.670000,0.091980,-354.602142,-0.010171,0.002786,0.070757,0.409147,0.020843,0.707569,-354.602142,0.072006,0.000000
4.910000,0.063675,-354.646637,-0.010020,0.002947,0.074859,0.283240,0.014429,0.748589,-354.646637,0.075995,0.000000
5.150000,0.084900,-354.691101,-0.009852,0.003107,0.078918,0.377654,0.019239,0.789175,-354.691101,0.080002,0.000000
5.390000,0.091980,-354.646637,-0.009697,0.003257,0.082733,0.409147,0.020843,0.827333,-354.646637,0.083991,0.000000
5.630000,0.095703,-354.691101,-0.009546,0.003417,0.086792,0.425709,0.021687,0.867919,-354.691101,0.087997,0.000000
5.870000,0.056229,-354.691101,-0.009360,0.003578,0.090877,0.250117,0.012742,0.908766,-354.691101,0.091987,0.000000
6.110000,0.071495,-354.691101,-0.009209,0.003734,0.094831,0.318026,0.016201,0.948311,-354.691101,0.095993,0.000000
6.350000,0.078201,-354.735596,-0.009058,0.003887,0.098725,0.347857,0.017721,0.987250,-354.735596,0.100000,0.000000
6.590000,0.070007,-354.691101,-0.008895,0.004049,0.102853,0.311408,0.015864,1.028530,-354.691101,0.103989,0.000000
6.830000,0.072617,-354.735596,-0.008722,0.004204,0.106790,0.323015,0.016455,1.067902,-354.735596,0.107996,0.000000
7.070000,0.073357,-354.735596,-0.008558,0.004365,0.110866,0.326307,0.016623,1.108661,-354.735596,0.111985,0.000000
7.310000,0.105011,-354.780060,-0.008412,0.004520,0.114812,0.467112,0.023796,1.148120,-354.780060,0.115991,0.000000
7.550000,0.102036,-354.780060,-0.008248,0.004679,0.118845,0.453877,0.023122,1.188446,-354.780060,0.119981,0.000000
7.790000,0.087883,-354.735596,-0.008088,0.004834,0.122790,0.390923,0.019915,1.227905,-354.735596,0.123987,0.000000
8.030001,0.072990,-354.824554,-0.007938,0.004992,0.126788,0.324678,0.016540,1.267884,-354.824554,0.127976,0.000000
8.270000,0.075218,-354.869019,-0.007769,0.005147,0.130726,0.334587,0.017045,1.307256,-354.869019,0.131983,0.000000
8.510000,0.055855,-354.824554,-0.007610,0.005305,0.134750,0.248455,0.012657,1.347495,-354.824554,0.135972,0.000000
8.750000,0.071869,-354.869019,-0.007468,0.005466,0.138825,0.319689,0.016286,1.388255,-354.869019,0.139979,0.000000
8.990001,0.071869,-354.824554,-0.007282,0.005623,0.142815,0.319689,0.016286,1.428147,-354.824554,0.143968,0.000000
9.230000,0.099052,-354.824554,-0.007140,0.005780,0.146804,0.440607,0.022446,1.468040,-354.824554,0.147975,0.000000
9.470000,0.121399,-354.913513,-0.006976,0.005935,0.150750,0.540009,0.027509,1.507498,-354.913513,0.151964,0.000000
9.710000,0.107994,-354.869019,-0.006817,0.006097,0.154852,0.480382,0.024472,1.548518,-354.869019,0.155971,0.000000
9.950001,0.068146,-354.913513,-0.006661,0.006250,0.158754,0.303127,0.015442,1.587543,-354.913513,0.159960,0.000000
10.190001,0.094215,-354.913513,-0.006502,0.006410,0.162813,0.419091,0.021350,1.628130,-354.913513,0.163966,0.000000
10.430000,0.090858,-354.957977,-0.006342,0.006564,0.166733,0.404159,0.020589,1.667328,-354.957977,0.167956,0.000000
10.670000,0.076714,-354.957977,-0.006178,0.006726,0.170852,0.341239,0.017384,1.708521,-354.957977,0.171962,0.000000
10.910001,0.049904,-354.869019,-0.006032,0.006880,0.174746,0.221983,0.011308,1.747460,-354.869019,0.175969,0.000000
11.150001,0.086021,-355.002472,-0.005877,0.007041,0.178831,0.382642,0.019493,1.788306,-355.002472,0.179958,0.000000
11.390000,0.126984,-354.957977,-0.005708,0.007197,0.182794,0.564851,0.028775,1.827938,-354.957977,0.183965,0.000000
11.630000,0.111343,-354.957977,-0.005553,0.007356,0.186835,0.495280,0.025231,1.868351,-354.957977,0.187954,0.000000
11.870001,0.109856,-355.002472,-0.005398,0.007512,0.190798,0.488662,0.024894,1.907983,-355.002472,0.191960,0.000000
12.110001,0.075592,-354.957977,-0.005221,0.007667,0.194753,0.336250,0.017129,1.947529,-354.957977,0.195950,0.000000
12.350000,0.084160,-355.046967,-0.005079,0.007821,0.198655,0.374362,0.019071,1.986554,-355.046967,0.199956,0.000000
12.590000,0.078949,-355.002472,-0.004907,0.007986,0.202853,0.351183,0.017890,2.028528,-355.002472,0.203945,0.000000
12.830001,0.059952,-355.002472,-0.004756,0.008142,0.206816,0.266679,0.013585,2.068160,-355.002472,0.207952,0.000000
13.070001,0.067772,-354.957977,-0.004587,0.008295,0.210701,0.301465,0.015357,2.107012,-354.957977,0.211941,0.000000
13.310000,0.540314,-355.002472,-0.004445,0.008455,0.214768,2.403435,0.122437,2.147685,-355.002472,0.215948,0.000000
13.550000,0.589470,-355.002472,-0.004424,-0.000000,-0.000000,2.622093,0.133576,-0.000000,-355.002472,0.000243,0.000000
13.790001,0.561165,-355.002472,-0.004406,-0.000000,-0.000000,2.496186,0.127162,-0.000000,-355.002472,0.000243,0.000000
14.030001,0.616280,-355.046967,-0.004415,-0.000000,-0.000000,2.741349,0.139651,-0.000000,-355.046967,0.000486,0.000000
14.270000,0.618141,-355.135925,-0.004419,-0.000000,-0.000000,2.749629,0.140073,-0.000000,-355.135925,0.000893,0.000000
14.510000,0.661705,-355.046967,-0.004411,0.000008,0.000199,2.943411,0.149944,0.001995,-355.046967,0.001292,0.000000
14.750001,0.822571,-355.135925,-0.004402,0.000026,0.000650,3.658978,0.186397,0.006504,-355.135925,0.001691,0.000000
14.990001,1.117119,-355.046967,-0.004376,0.000046,0.001179,4.969193,0.253143,0.011794,-355.046967,0.002090,0.000000
15.230000,1.276497,-355.091431,-0.004363,0.000061,0.001552,5.678142,0.289258,0.015523,-355.091431,0.002489,0.000000
15.470000,1.531570,-355.135925,-0.004350,0.000077,0.001960,6.812766,0.347059,0.019599,-355.135925,0.002888,0.000000
15.710001,1.735634,-355.135925,-0.004346,0.000094,0.002394,7.720485,0.393300,0.023935,-355.135925,0.003287,0.000000
15.950001,1.950119,-355.135925,-0.004333,0.000107,0.002706,8.674562,0.441903,0.027057,-355.135925,0.003686,0.000000
16.190001,2.118805,-355.135925,-0.004312,0.000120,0.003053,9.424915,0.480128,0.030526,-355.135925,0.004093,0.000000
16.430000,2.522453,-355.135925,-0.004307,0.000142,0.003599,11.220432,0.571596,0.035990,-355.135925,0.004492,0.000000
16.670000,2.795403,-355.180389,-0.004286,0.000160,0.004076,12.434571,0.633447,0.040760,-355.180389,0.004891,0.000000
16.910002,3.016594,-355.135925,-0.004273,0.000175,0.004440,13.418480,0.683570,0.044402,-355.135925,0.005290,0.000000
17.150002,3.159584,-355.180389,-0.004260,0.000188,0.004787,14.054532,0.715972,0.047871,-355.180389,0.005689,0.000000
17.390001,3.359177,-355.180389,-0.004238,0.000202,0.005143,14.942364,0.761200,0.051426,-355.180389,0.006088,0.000000
17.630001,3.731178,-355.135925,-0.004247,0.000222,0.005628,16.597111,0.845497,0.056283,-355.135925,0.006487,0.000000
17.870001,3.920715,-355.224884,-0.004221,0.000235,0.005958,17.440212,0.888447,0.059578,-355.224884,0.006886,0.000000
18.110001,4.128120,-355.224884,-0.004199,0.000249,0.006322,18.362797,0.935445,0.063221,-355.224884,0.007293,0.000000
18.350000,4.390274,-355.313843,-0.004195,0.000265,0.006738,19.528913,0.994850,0.067383,-355.313843,0.007692,0.000000
18.590000,4.710884,-355.224884,-0.004169,0.000283,0.007198,20.955059,1.067502,0.071980,-355.224884,0.008091,0.000000
18.830002,4.811058,-355.224884,-0.004156,0.000296,0.007528,21.400656,1.090201,0.075275,-355.224884,0.008490,0.000000
19.070002,4.946228,-355.269348,-0.004152,0.000311,0.007900,22.001921,1.120831,0.079004,-355.269348,0.008889,0.000000
19.310001,5.306679,-355.269348,-0.004130,0.000330,0.008386,23.605286,1.202511,0.083861,-355.269348,0.009288,0.000000
19.550001,5.426590,-355.313843,-0.004118,0.000345,0.008750,24.138678,1.229683,0.087503,-355.313843,0.009687,0.000000
19.790001,5.659691,-355.313843,-0.004096,0.000359,0.009115,25.175562,1.282504,0.091145,-355.313843,0.010086,0.000000
20.030001,5.816460,-355.269348,-0.004096,0.000374,0.009496,25.872904,1.318029,0.094961,-355.269348,0.010493,0.000000
20.270000,6.004135,-355.358307,-0.004079,0.000390,0.009895,26.707727,1.360556,0.098950,-355.358307,0.010892,0.000000
20.510000,6.353050,-355.313843,-0.004061,0.000411,0.010441,28.259779,1.439622,0.104414,-355.313843,0.011291,0.000000
20.750002,6.450981,-355.358307,-0.004049,0.000425,0.010797,28.695396,1.461813,0.107970,-355.358307,0.011690,0.000000
20.990002,6.488220,-355.313843,-0.004027,0.000437,0.011109,28.861046,1.470252,0.111092,-355.313843,0.012089,0.000000
21.230001,6.706802,-355.313843,-0.004010,0.000456,0.011595,29.833347,1.519783,0.115948,-355.313843,0.012488,0.000000
21.470001,6.846069,-355.402802,-0.004001,0.000472,0.011994,30.452837,1.551341,0.119937,-355.402802,0.012887,0.000000
21.710001,6.996506,-355.313843,-0.003988,0.000487,0.012375,31.122011,1.585431,0.123753,-355.313843,0.013286,0.000000
21.950001,7.028534,-355.447266,-0.003980,0.000500,0.012688,31.264481,1.592689,0.126875,-355.447266,0.013693,0.000000
22.190001,7.177109,-355.402802,-0.003945,0.000516,0.013095,31.925375,1.626356,0.130951,-355.402802,0.014092,0.000000
22.430000,7.437401,-355.358307,-0.003936,0.000535,0.013581,33.083210,1.685339,0.135808,-355.358307,0.014491,0.000000
22.670002,7.386757,-355.447266,-0.003932,0.000548,0.013928,32.857937,1.673863,0.139276,-355.447266,0.014890,0.000000
22.910002,7.551346,-355.447266,-0.003902,0.000564,0.014327,33.590065,1.711159,0.143266,-355.447266,0.015289,0.000000
23.150002,7.587090,-355.358307,-0.003902,0.000578,0.014691,33.749062,1.719259,0.146908,-355.358307,0.015688,0.000000
23.390001,7.607201,-355.491760,-0.003885,0.000593,0.015072,33.838520,1.723816,0.150724,-355.491760,0.016087,0.000000
23.630001,7.935257,-355.402802,-0.003859,0.000614,0.015584,35.297787,1.798155,0.155840,-355.402802,0.016486,0.000000
23.870001,7.837326,-355.491760,-0.003850,0.000622,0.015810,34.862167,1.775964,0.158095,-355.491760,0.016894,0.000000
24.110001,7.988884,-355.491760,-0.003829,0.000640,0.016260,35.536331,1.810307,0.162605,-355.491760,0.017292,0.000000
24.350000,8.144157,-355.447266,-0.003824,0.000657,0.016677,36.227020,1.845492,0.166768,-355.447266,0.017691,0.000000
24.590002,8.398491,-355.536255,-0.003794,0.000678,0.017214,37.358353,1.903125,0.172144,-355.536255,0.018090,0.000000
24.830002,8.360138,-355.491760,-0.003794,0.000692,0.017579,37.187752,1.894434,0.175787,-355.491760,0.018489,0.000000
25.070002,8.409660,-355.580719,-0.003773,0.000707,0.017952,37.408039,1.905656,0.179516,-355.580719,0.018888,0.000000
25.310001,8.385086,-355.536255,-0.003751,0.000721,0.018316,37.298725,1.900088,0.183158,-355.536255,0.019287,0.000000
25.550001,8.619682,-355.491760,-0.003742,0.000740,0.018784,38.342262,1.953248,0.187841,-355.491760,0.019686,0.000000
25.790001,8.446526,-355.580719,-0.003717,0.000747,0.018975,37.572021,1.914010,0.189749,-355.580719,0.020094,0.000000
26.030001,8.718361,-355.536255,-0.003699,0.000767,0.019469,38.781208,1.975609,0.194692,-355.536255,0.020493,0.000000
26.270000,8.778313,-355.625214,-0.003695,0.000784,0.019903,39.047886,1.989194,0.199028,-355.625214,0.020891,0.000000
26.510002,8.967102,-355.625214,-0.003673,0.000804,0.020432,39.887661,2.031974,0.204318,-355.625214,0.021290,0.000000
26.750002,9.011414,-355.580719,-0.003660,0.000820,0.020831,40.084770,2.042016,0.208308,-355.580719,0.021689,0.000000
26.990002,8.989815,-355.625214,-0.003635,0.000834,0.021178,39.988693,2.037121,0.211776,-355.625214,0.022088,0.000000
27.230001,8.957420,-355.625214,-0.003630,0.000845,0.021464,39.844597,2.029780,0.214638,-355.625214,0.022487,0.000000
27.470001,9.035248,-355.625214,-0.003613,0.000861,0.021880,40.190788,2.047416,0.218801,-355.625214,0.022895,0.000000
27.710001,9.184570,-355.669678,-0.003596,0.000877,0.022288,40.855011,2.081254,0.222877,-355.669678,0.023294,0.000000
27.950001,9.271706,-355.580719,-0.003579,0.000892,0.022661,41.242607,2.100999,0.226606,-355.580719,0.023693,0.000000
28.190001,9.094826,-355.714172,-0.003570,0.000908,0.023060,40.455807,2.060917,0.230595,-355.714172,0.024092,0.000000
28.430002,9.614288,-355.669678,-0.003544,0.000930,0.023615,42.766491,2.178629,0.236146,-355.669678,0.024490,0.000000
28.670002,9.563271,-355.669678,-0.003531,0.000945,0.024005,42.539551,2.167068,0.240048,-355.669678,0.024889,0.000000
28.910002,9.583382,-355.714172,-0.003514,0.000960,0.024386,42.629009,2.171625,0.243864,-355.714172,0.025288,0.000000
29.150002,9.483582,-355.669678,-0.003510,0.000971,0.024673,42.185078,2.149010,0.246726,-355.669678,0.025687,0.000000
29.390001,9.834358,-355.758636,-0.003479,0.000993,0.025210,43.745411,2.228498,0.252103,-355.758636,0.026095,0.000000
29.630001,9.841805,-355.758636,-0.003454,0.001007,0.025566,43.778534,2.230185,0.255658,-355.758636,0.026494,0.000000
29.870001,9.677589,-355.758636,-0.003458,0.001017,0.025835,43.048069,2.192973,0.258347,-355.758636,0.026893,0.000000
30.110001,10.023895,-355.803131,-0.003432,0.001036,0.026312,44.588512,2.271447,0.263116,-355.803131,0.027292,0.000000
30.350002,10.215294,-355.803131,-0.003419,0.001055,0.026806,45.439896,2.314819,0.268059,-355.803131,0.027691,0.000000
30.590002,10.203751,-355.803131,-0.003410,0.001071,0.027196,45.388550,2.312203,0.271962,-355.803131,0.028089,0.000000
30.830002,10.118111,-355.803131,-0.003376,0.001082,0.027474,45.007603,2.292797,0.274737,-355.803131,0.028488,0.000000
31.070002,10.273384,-355.758636,-0.003376,0.001100,0.027942,45.698296,2.327982,0.279420,-355.758636,0.028887,0.000000
31.310001,10.488243,-355.847595,-0.003367,0.001117,0.028376,46.654034,2.376670,0.283756,-355.847595,0.029295,0.000000
31.550001,10.492714,-355.758636,-0.003341,0.001130,0.028696,46.673923,2.377683,0.286965,-355.758636,0.029694,0.000000
31.790001,10.505745,-355.847595,-0.003341,0.001147,0.029121,46.731888,2.380636,0.291214,-355.847595,0.030093,0.000000
32.030003,10.651344,-355.803131,-0.003320,0.001162,0.029503,47.379547,2.413629,0.295030,-355.803131,0.030492,0.000000
32.270000,10.898972,-355.847595,-0.003294,0.001182,0.030015,48.481049,2.469742,0.300147,-355.847595,0.030891,0.000000
32.510002,10.761192,-355.936584,-0.003277,0.001193,0.030310,47.868176,2.438521,0.303095,-355.936584,0.031290,0.000000
32.750000,10.824867,-355.847595,-0.003255,0.001209,0.030700,48.151413,2.452950,0.306998,-355.847595,0.031688,0.000000
32.990002,10.866577,-355.892090,-0.003247,0.001223,0.031064,48.336948,2.462402,0.310640,-355.892090,0.032087,0.000000
33.230003,11.115318,-355.892090,-0.003234,0.001243,0.031567,49.443405,2.518767,0.315670,-355.892090,0.032495,0.000000
33.470001,11.205063,-355.892090,-0.003216,0.001256,0.031905,49.842609,2.539104,0.319052,-355.892090,0.032894,0.000000
33.710003,11.200966,-355.892090,-0.003208,0.001271,0.032295,49.824383,2.538175,0.322955,-355.892090,0.033293,0.000000
33.950001,11.466095,-355.892090,-0.003182,0.001290,0.032755,51.003738,2.598254,0.327551,-355.892090,0.033692,0.000000
34.190002,11.582649,-355.936584,-0.003173,0.001305,0.033154,51.522198,2.624666,0.331540,-355.936584,0.034091,0.000000
34.430000,11.459396,-356.025543,-0.003156,0.001318,0.033484,50.973942,2.596736,0.334836,-356.025543,0.034490,0.000000
34.670002,11.715958,-355.936584,-0.003134,0.001335,0.033917,52.115181,2.654874,0.339172,-355.936584,0.034888,0.000000
34.910000,11.882408,-356.025543,-0.003126,0.001353,0.034368,52.855591,2.692592,0.343682,-356.025543,0.035287,0.000000
35.150002,11.877563,-355.981049,-0.003104,0.001367,0.034724,52.834042,2.691494,0.347237,-355.981049,0.035695,0.000000
35.390003,11.912941,-356.025543,-0.003091,0.001381,0.035088,52.991409,2.699511,0.350880,-356.025543,0.036094,0.000000
35.630001,12.090195,-355.981049,-0.003074,0.001397,0.035478,53.779873,2.739677,0.354782,-355.981049,0.036493,0.000000
35.870003,12.148651,-356.025543,-0.003070,0.001414,0.035903,54.039898,2.752924,0.359031,-356.025543,0.036892,0.000000
36.110001,12.211960,-356.070007,-0.003053,0.001426,0.036233,54.321510,2.767270,0.362327,-356.070007,0.037291,0.000000
36.350002,12.524002,-356.025543,-0.003031,0.001446,0.036727,55.709545,2.837979,0.367270,-356.025543,0.037690,0.000000
36.590000,12.594009,-356.025543,-0.003018,0.001462,0.037135,56.020950,2.853843,0.371346,-356.025543,0.038089,0.000000
36.830002,12.710190,-356.070007,-0.002992,0.001477,0.037516,56.537746,2.880170,0.375162,-356.070007,0.038487,0.000000
37.070004,12.974579,-356.070007,-0.002984,0.001496,0.038011,57.713810,2.940082,0.380105,-356.070007,0.038895,0.000000
37.310001,12.875900,-356.114502,-0.002966,0.001508,0.038314,57.274864,2.917721,0.383140,-356.114502,0.039294,0.000000
37.550003,13.116081,-356.114502,-0.002949,0.001528,0.038800,58.343243,2.972147,0.387997,-356.114502,0.039693,0.000000
37.790001,13.175659,-356.114502,-0.002945,0.001540,0.039121,58.608257,2.985647,0.391206,-356.114502,0.040092,0.000000
38.030003,13.521217,-356.158966,-0.002915,0.001562,0.039667,60.145378,3.063952,0.396669,-356.158966,0.040491,0.000000
38.270000,13.540581,-356.114502,-0.002906,0.001577,0.040048,60.231510,3.068340,0.400485,-356.114502,0.040890,0.000000
38.510002,13.429619,-356.158966,-0.002884,0.001588,0.040343,59.737926,3.043195,0.403433,-356.158966,0.041289,0.000000
38.750000,13.581917,-356.203461,-0.002871,0.001604,0.040751,60.415382,3.077706,0.407509,-356.203461,0.041688,0.000000
38.990002,13.831779,-356.114502,-0.002863,0.001623,0.041228,61.526829,3.134326,0.412279,-356.114502,0.042095,0.000000
39.230003,13.783745,-356.247925,-0.002837,0.001634,0.041514,61.313160,3.123441,0.415141,-356.247925,0.042494,0.000000
39.470001,13.828796,-356.158966,-0.002824,0.001649,0.041896,61.513557,3.133650,0.418957,-356.158966,0.042893,0.000000
39.710003,14.101372,-356.203461,-0.002815,0.001665,0.042295,62.726036,3.195416,0.422946,-356.203461,0.043292,0.000000
39.950001,14.640198,-356.203461,-0.002794,0.001690,0.042919,65.122849,3.317516,0.429190,-356.203461,0.043691,0.000000
40.190002,14.437256,-356.247925,-0.002781,0.001700,0.043170,64.220123,3.271529,0.431705,-356.247925,0.044090,0.000000
40.430000,14.545242,-356.292419,-0.002759,0.001715,0.043552,64.700470,3.295999,0.435521,-356.292419,0.044489,0.000000
40.670002,14.623444,-356.203461,-0.002738,0.001729,0.043925,65.048325,3.313720,0.439250,-356.203461,0.044896,0.000000
40.910004,14.941078,-356.292419,-0.002738,0.001749,0.044428,66.461235,3.385697,0.444280,-356.292419,0.045295,0.000000
41.150002,14.855804,-356.247925,-0.002712,0.001760,0.044705,66.081917,3.366373,0.447055,-356.247925,0.045694,0.000000
41.390003,15.006241,-356.247925,-0.002703,0.001776,0.045104,66.751091,3.400463,0.451044,-356.247925,0.046093,0.000000
41.630001,15.238228,-356.247925,-0.002695,0.001794,0.045555,67.783020,3.453032,0.455554,-356.247925,0.046492,0.000000
41.870003,15.664223,-356.292419,-0.002665,0.001812,0.046015,69.677940,3.549564,0.460150,-356.292419,0.046891,0.000000
42.110001,15.619911,-356.292419,-0.002665,0.001825,0.046362,69.480835,3.539522,0.463619,-356.292419,0.047290,0.000000
42.350002,15.746147,-356.381378,-0.002643,0.001842,0.046778,70.042358,3.568128,0.467782,-356.381378,0.047689,0.000000
42.590000,16.003456,-356.336914,-0.002639,0.001859,0.047212,71.186928,3.626435,0.472118,-356.336914,0.048096,0.000000
42.830002,16.012764,-356.336914,-0.002621,0.001871,0.047533,71.228333,3.628544,0.475326,-356.336914,0.048495,0.000000
43.070004,16.187775,-356.336914,-0.002604,0.001889,0.047975,72.006821,3.668202,0.479749,-356.336914,0.048894,0.000000
43.310001,16.147560,-356.381378,-0.002587,0.001900,0.048252,71.827934,3.659089,0.482524,-356.381378,0.049293,0.000000
43.550003,16.538177,-356.381378,-0.002570,0.001918,0.048712,73.565491,3.747605,0.487121,-356.381378,0.049692,0.000000
43.790001,16.778358,-356.381378,-0.002548,0.001934,0.049128,74.633865,3.802030,0.491283,-356.381378,0.050091,0.000000
44.030003,16.850601,-356.425873,-0.002544,0.001950,0.049527,74.955215,3.818401,0.495273,-356.425873,0.050490,0.000000
44.270000,17.051308,-356.381378,-0.002522,0.001965,0.049918,75.848007,3.863882,0.499175,-356.381378,0.050889,0.000000
44.510002,17.228188,-356.425873,-0.002514,0.001981,0.050308,76.634804,3.903963,0.503078,-356.425873,0.051296,0.000000
44.750004,17.460175,-356.514832,-0.002496,0.001997,0.050724,77.666733,3.956532,0.507240,-356.514832,0.051695,0.000000
44.990002,17.800148,-356.425873,-0.002488,0.002015,0.051175,79.179016,4.033571,0.511750,-356.425873,0.052094,0.000000
45.230003,17.551407,-356.559296,-0.002470,0.002024,0.051409,78.072556,3.977206,0.514091,-356.559296,0.052493,0.000000
45.470001,18.105499,-356.425873,-0.002453,0.002043,0.051895,80.537285,4.102765,0.518948,-356.425873,0.052892,0.000000
45.710003,18.336365,-356.470337,-0.002436,0.002061,0.052354,81.564224,4.155079,0.523544,-356.470337,0.053291,0.000000
45.950001,18.621231,-356.514832,-0.002436,0.002076,0.052736,82.831375,4.219631,0.527360,-356.514832,0.053690,0.000000
46.190002,18.904236,-356.514832,-0.002406,0.002096,0.053230,84.090240,4.283761,0.532303,-356.514832,0.054089,0.000000
46.430000,18.842422,-356.514832,-0.002393,0.002107,0.053525,83.815285,4.269754,0.535252,-356.514832,0.054496,0.000000
46.670002,19.114624,-356.559296,-0.002384,0.002124,0.053941,85.026093,4.331436,0.539414,-356.559296,0.054895,0.000000
46.910004,19.298950,-356.559296,-0.002358,0.002140,0.054358,85.846016,4.373205,0.543577,-356.559296,0.055294,0.000000
47.150002,18.974243,-356.559296,-0.002358,0.002146,0.054496,84.401649,4.299625,0.544965,-356.559296,0.055693,0.000000
47.390003,19.634460,-356.514832,-0.002333,0.002169,0.055104,87.338440,4.449232,0.551035,-356.514832,0.056092,0.000000
47.630001,19.965126,-356.559296,-0.002333,0.002186,0.055528,88.809319,4.524162,0.555285,-356.559296,0.056491,0.000000
47.870003,20.527031,-356.559296,-0.002307,0.002206,0.056031,91.308792,4.651492,0.560315,-356.559296,0.056890,0.000000
48.110001,20.643959,-356.559296,-0.002285,0.002221,0.056422,91.828918,4.677988,0.564217,-356.559296,0.057289,0.000000
48.350002,20.616028,-356.648254,-0.002281,0.002235,0.056760,91.704674,4.671659,0.567599,-356.648254,0.057697,0.000000
48.590004,20.887863,-356.559296,-0.002264,0.002252,0.057194,92.913857,4.733257,0.571935,-356.559296,0.058095,0.000000
48.830002,21.072929,-356.692749,-0.002251,0.002266,0.057566,93.737068,4.775194,0.575664,-356.692749,0.058494,0.000000
49.070004,21.108307,-356.737213,-0.002233,0.002276,0.057818,93.894440,4.783211,0.578179,-356.737213,0.058893,0.000000
49.310001,21.407692,-356.648254,-0.002216,0.002291,0.058182,95.226173,4.851052,0.581822,-356.648254,0.059292,0.000000
49.550003,21.946144,-356.692749,-0.002212,0.002315,0.058798,97.621323,4.973067,0.587979,-356.692749,0.059691,0.000000
49.790001,22.588120,-356.692749,-0.002203,0.002331,0.059206,100.476974,5.118541,0.592055,-356.692749,0.060090,0.000000
50.030003,22.630196,-356.692749,-0.002186,0.002345,0.059561,100.664139,5.128076,0.595611,-356.692749,0.060489,0.000000
50.270004,22.890854,-356.648254,-0.002164,0.002361,0.059977,101.823601,5.187141,0.599773,-356.648254,0.060897,0.000000
50.510002,22.804466,-356.692749,-0.002160,0.002374,0.060298,101.439331,5.167566,0.602982,-356.692749,0.061296,0.000000
50.750004,23.567459,-356.737213,-0.002139,0.002395,0.060836,104.833290,5.340463,0.608359,-356.737213,0.061694,0.000000
50.990002,23.603577,-356.692749,-0.002126,0.002406,0.061122,104.993950,5.348647,0.611221,-356.692749,0.062093,0.000000
51.230003,23.782318,-356.692749,-0.002113,0.002420,0.061460,105.789032,5.389150,0.614603,-356.692749,0.062492,0.000000
51.470001,24.196762,-356.781708,-0.002100,0.002437,0.061894,107.632576,5.483065,0.618939,-356.781708,0.062891,0.000000
51.710003,24.755699,-356.737213,-0.002087,0.002454,0.062336,110.118851,5.609722,0.623362,-356.737213,0.063290,0.000000
51.950001,25.081146,-356.826202,-0.002070,0.002471,0.062761,111.566513,5.683469,0.627611,-356.826202,0.063689,0.000000
52.190002,24.924377,-356.826202,-0.002048,0.002480,0.062995,110.869171,5.647944,0.629953,-356.826202,0.064097,0.000000
52.430004,25.522781,-356.781708,-0.002052,0.002499,0.063472,113.530998,5.783545,0.634723,-356.781708,0.064496,0.000000
52.670002,26.044853,-356.826202,-0.002035,0.002516,0.063906,115.853294,5.901848,0.639059,-356.826202,0.064894,0.000000
52.910004,26.168480,-356.781708,-0.002018,0.002529,0.064227,116.403214,5.929862,0.642267,-356.781708,0.065293,0.000000
53.150002,26.648468,-356.826202,-0.002018,0.002547,0.064695,118.538307,6.038629,0.646950,-356.826202,0.065692,0.000000
53.390003,26.855881,-356.870667,-0.001988,0.002563,0.065111,119.460922,6.085630,0.651113,-356.870667,0.066091,0.000000
53.630001,27.594666,-356.870667,-0.001979,0.002582,0.065571,122.747200,6.253041,0.655709,-356.870667,0.066490,0.000000
53.870003,27.421509,-356.870667,-0.001966,0.002592,0.065831,121.976967,6.213803,0.658311,-356.870667,0.066889,0.000000
54.110004,27.832237,-356.781708,-0.001944,0.002608,0.066247,123.803978,6.306875,0.662474,-356.781708,0.067297,0.000000
54.350002,28.120453,-356.870667,-0.001949,0.002621,0.066586,125.086021,6.372186,0.665856,-356.870667,0.067696,0.000000
54.590004,28.896477,-356.870667,-0.001914,0.002643,0.067141,128.537949,6.548035,0.671406,-356.870667,0.068095,0.000000
54.830002,29.135910,-356.915161,-0.001914,0.002655,0.067435,129.602997,6.602292,0.674355,-356.915161,0.068493,0.000000
55.070004,29.589088,-356.915161,-0.001897,0.002673,0.067886,131.618835,6.704983,0.678864,-356.915161,0.068892,0.000000
55.310001,30.179298,-356.870667,-0.001888,0.002690,0.068337,134.244217,6.838727,0.683374,-356.870667,0.069291,0.000000
55.550003,30.577736,-356.915161,-0.001880,0.002705,0.068719,136.016556,6.929014,0.687190,-356.915161,0.069690,0.000000
55.790001,30.823509,-356.959625,-0.001854,0.002719,0.069057,137.109818,6.984707,0.690572,-356.959625,0.070098,0.000000
56.030003,31.224174,-356.915161,-0.001841,0.002734,0.069447,138.892059,7.075499,0.694474,-356.915161,0.070497,0.000000
56.270004,31.984192,-357.004120,-0.001850,0.002754,0.069950,142.272797,7.247722,0.699504,-357.004120,0.070896,0.000000
56.510002,32.304802,-356.959625,-0.001819,0.002770,0.070358,143.698929,7.320373,0.703580,-356.959625,0.071295,0.000000
56.750004,32.821655,-356.915161,-0.001815,0.002784,0.070722,145.998016,7.437493,0.707223,-356.915161,0.071694,0.000000
56.990002,32.991829,-357.004120,-0.001794,0.002798,0.071078,146.754990,7.476056,0.710778,-357.004120,0.072092,0.000000
57.230003,33.659119,-357.004120,-0.001785,0.002816,0.071537,149.723236,7.627265,0.715374,-357.004120,0.072491,0.000000
57.470001,33.738068,-357.048584,-0.001772,0.002827,0.071815,150.074417,7.645155,0.718150,-357.048584,0.072890,0.000000
57.710003,34.592285,-357.004120,-0.001755,0.002846,0.072292,153.874176,7.838724,0.722919,-357.004120,0.073298,0.000000
57.950005,35.089401,-357.004120,-0.001746,0.002861,0.072665,156.085449,7.951372,0.726648,-357.004120,0.073697,0.000000
58.190002,35.597694,-357.004120,-0.001746,0.002878,0.073090,158.346451,8.066553,0.730898,-357.004120,0.074096,0.000000
58.430004,36.453407,-357.004120,-0.001725,0.002896,0.073567,162.152847,8.260460,0.735668,-357.004120,0.074495,0.000000
58.670002,36.461594,-357.137543,-0.001712,0.002906,0.073818,162.189270,8.262315,0.738182,-357.137543,0.074894,0.000000
58.910004,37.526581,-357.048584,-0.001703,0.002928,0.074373,166.926575,8.503645,0.743733,-357.048584,0.075293,0.000000
59.150002,37.857994,-357.093079,-0.001707,0.002939,0.074642,168.400772,8.578744,0.746421,-357.093079,0.075691,0.000000
59.390003,38.896912,-357.137543,-0.001686,0.002962,0.075223,173.022110,8.814166,0.752232,-357.137543,0.076090,0.000000
59.630001,39.374664,-357.048584,-0.001656,0.002976,0.075579,175.147247,8.922426,0.755787,-357.048584,0.076498,0.000000
59.870003,39.492340,-357.093079,-0.001669,0.002988,0.075900,175.670700,8.949092,0.758996,-357.093079,0.076897,0.000000
60.110004,40.010681,-357.137543,-0.001651,0.003004,0.076290,177.976395,9.066549,0.762898,-357.137543,0.077296,0.000000
60.350002,40.929321,-357.137543,-0.001638,0.003024,0.076802,182.062714,9.274716,0.768015,-357.137543,0.077695,0.000000
60.590004,41.141945,-357.226532,-0.001625,0.003035,0.077096,183.008514,9.322898,0.770964,-357.226532,0.078094,0.000000
60.830002,41.539642,-357.137543,-0.001617,0.003046,0.077365,184.777557,9.413017,0.773652,-357.137543,0.078493,0.000000
61.070004,42.430725,-357.182037,-0.001604,0.003065,0.077860,188.741287,9.614940,0.778595,-357.182037,0.078892,0.000000
61.310001,43.954849,-357.137543,-0.001582,0.003089,0.078458,195.520935,9.960311,0.784579,-357.137543,0.079290,0.000000
61.550003,43.712807,-357.137543,-0.001574,0.003097,0.078675,194.444275,9.905464,0.786747,-357.137543,0.079698,0.000000
61.790005,44.544685,-357.226532,-0.001561,0.003114,0.079100,198.144653,10.093970,0.790997,-357.226532,0.080097,0.000000
62.030003,45.191872,-357.270996,-0.001552,0.003129,0.079473,201.023483,10.240624,0.794726,-357.270996,0.080496,0.000000
62.270004,46.202858,-357.226532,-0.001552,0.003149,0.079984,205.520584,10.469717,0.799842,-357.226532,0.080895,0.000000
62.510002,46.397240,-357.270996,-0.001526,0.003159,0.080227,206.385223,10.513764,0.802270,-357.270996,0.081294,0.000000
62.750004,47.166931,-357.182037,-0.001522,0.003175,0.080635,209.808990,10.688179,0.806346,-357.182037,0.081693,0.000000
62.990002,48.093765,-357.315491,-0.001513,0.003192,0.081086,213.931747,10.898203,0.810856,-357.315491,0.082092,0.000000
63.230003,49.173279,-357.226532,-0.001496,0.003212,0.081589,218.733673,11.142824,0.815886,-357.226532,0.082491,0.000000
63.470001,49.827164,-357.315491,-0.001505,0.003228,0.081979,221.642288,11.290997,0.819788,-357.315491,0.082898,0.000000
63.710003,50.345505,-357.315491,-0.001487,0.003243,0.082360,223.947983,11.408454,0.823604,-357.315491,0.083297,0.000000
63.950005,51.233238,-357.270996,-0.001475,0.003258,0.082751,227.896820,11.609617,0.827507,-357.270996,0.083696,0.000000
64.190002,51.774673,-357.315491,-0.001466,0.003272,0.083098,230.305252,11.732308,0.830976,-357.315491,0.084095,0.000000
64.430000,52.567078,-357.315491,-0.001462,0.003288,0.083514,233.830032,11.911870,0.835138,-357.315491,0.084494,0.000000
64.670006,52.893280,-357.315491,-0.001449,0.003299,0.083783,235.281067,11.985788,0.837827,-357.315491,0.084893,0.000000
64.910004,53.924377,-357.315491,-0.001431,0.003316,0.084234,239.867615,12.219439,0.842336,-357.315491,0.085292,0.000000
65.150002,54.821793,-357.315491,-0.001423,0.003334,0.084685,243.859512,12.422796,0.846846,-357.315491,0.085691,0.000000
65.389999,55.731873,-357.404449,-0.001423,0.003351,0.085118,247.907745,12.629024,0.851182,-357.404449,0.086098,0.000000
65.630005,56.332878,-357.359955,-0.001401,0.003365,0.085465,250.581161,12.765213,0.854651,-357.359955,0.086497,0.000000
65.870003,57.144279,-357.359955,-0.001401,0.003379,0.085838,254.190445,12.949079,0.858380,-357.359955,0.086896,0.000000
66.110001,58.063293,-357.448914,-0.001393,0.003397,0.086272,258.278442,13.157331,0.862716,-357.448914,0.087295,0.000000
66.350006,59.234032,-357.315491,-0.001384,0.003414,0.086723,263.486145,13.422624,0.867226,-357.315491,0.087694,0.000000
66.590004,59.402344,-357.493408,-0.001375,0.003423,0.086939,264.234833,13.460764,0.869394,-357.493408,0.088093,0.000000
66.830002,60.722038,-357.404449,-0.001367,0.003442,0.087416,270.105103,13.759810,0.874164,-357.404449,0.088492,0.000000
67.070000,61.806381,-357.404449,-0.001358,0.003461,0.087911,274.928528,14.005527,0.879107,-357.404449,0.088891,0.000000
67.310005,62.971169,-357.493408,-0.001345,0.003475,0.088275,280.109741,14.269470,0.882749,-357.493408,0.089298,0.000000
67.550003,63.996674,-357.448914,-0.001337,0.003495,0.088761,284.671417,14.501853,0.887606,-357.448914,0.089697,0.000000
67.790001,64.577957,-357.493408,-0.001341,0.003506,0.089047,287.257111,14.633574,0.890467,-357.493408,0.090096,0.000000
68.030006,65.623199,-357.448914,-0.001319,0.003523,0.089480,291.906555,14.870430,0.894803,-357.448914,0.090495,0.000000
68.270004,66.640152,-357.493408,-0.001315,0.003540,0.089923,296.430206,15.100874,0.899226,-357.493408,0.090894,0.000000
68.510002,66.885910,-357.493408,-0.001311,0.003549,0.090139,297.523376,15.156564,0.901394,-357.493408,0.091293,0.000000
68.750000,67.120880,-357.448914,-0.001285,0.003546,0.090079,298.568573,15.209809,0.900787,-357.448914,0.090356,0.000000
68.990005,66.417099,-357.537872,-0.001289,0.003545,0.090044,295.438019,15.050330,0.900440,-357.537872,0.090079,0.000000
69.230003,65.769913,-357.537872,-0.001276,0.003544,0.090009,292.559174,14.903675,0.900094,-357.537872,0.090079,0.000000
69.470001,65.194229,-357.448914,-0.001281,0.003543,0.089992,289.998413,14.773223,0.899920,-357.448914,0.090079,0.000000
69.710007,64.670670,-357.582367,-0.001285,0.003543,0.089983,287.669495,14.654583,0.899833,-357.582367,0.090079,0.000000
69.950005,64.190689,-357.537872,-0.001281,0.003542,0.089975,285.534454,14.545818,0.899747,-357.537872,0.090079,0.000000
70.190002,63.758362,-357.626862,-0.001281,0.003542,0.089975,283.611359,14.447851,0.899747,-357.626862,0.090079,0.000000
70.430000,63.350235,-357.582367,-0.001272,0.003542,0.089975,281.795929,14.355369,0.899747,-357.582367,0.090079,0.000000
70.670006,62.984940,-357.582367,-0.001268,0.003542,0.089975,280.170990,14.272592,0.899747,-357.582367,0.090079,0.000000
70.910004,62.654274,-357.626862,-0.001268,0.003542,0.089966,278.700134,14.197661,0.899660,-357.626862,0.090079,0.000000
71.150002,62.331429,-357.582367,-0.001268,0.003542,0.089966,277.264038,14.124504,0.899660,-357.582367,0.090079,0.000000
71.390007,62.040977,-357.626862,-0.001263,0.003542,0.089966,275.972046,14.058686,0.899660,-357.626862,0.090079,0.000000
71.630005,61.760956,-357.626862,-0.001263,0.003542,0.089966,274.726440,13.995233,0.899660,-357.626862,0.090079,0.000000
71.870003,61.507744,-357.626862,-0.001250,0.003542,0.089966,273.600098,13.937854,0.899660,-357.626862,0.090079,0.000000
72.110001,61.263840,-357.626862,-0.001259,0.003542,0.089966,272.515167,13.882585,0.899660,-357.626862,0.090079,0.000000
72.350006,61.046371,-357.715820,-0.001255,0.003542,0.089966,271.547821,13.833305,0.899660,-357.715820,0.090079,0.000000
72.590004,60.834862,-357.626862,-0.001246,0.003542,0.089966,270.606995,13.785377,0.899660,-357.626862,0.090079,0.000000
72.830002,60.626709,-357.671326,-0.001259,0.003542,0.089966,269.681061,13.738209,0.899660,-357.671326,0.090079,0.000000
73.070000,60.437546,-357.626862,-0.001242,0.003542,0.089966,268.839630,13.695343,0.899660,-357.626862,0.090079,0.000000
73.310005,60.239067,-357.804779,-0.001250,0.003542,0.089966,267.956757,13.650368,0.899660,-357.804779,0.090079,0.000000
73.550003,60.067406,-357.760284,-0.001246,0.003542,0.089966,267.193176,13.611469,0.899660,-357.760284,0.090079,0.000000
73.790001,59.906540,-357.760284,-0.001250,0.003542,0.089966,266.477600,13.575016,0.899660,-357.760284,0.090079,0.000000
74.030006,59.732269,-357.804779,-0.001237,0.003542,0.089966,265.702393,13.535525,0.899660,-357.804779,0.090079,0.000000
74.270004,59.570290,-357.715820,-0.001237,0.003542,0.089966,264.981873,13.498820,0.899660,-357.715820,0.090079,0.000000
74.510002,59.438843,-357.804779,-0.001250,0.003542,0.089966,264.397186,13.469034,0.899660,-357.804779,0.090079,0.000000
74.750000,59.287659,-357.804779,-0.001255,0.003542,0.089966,263.724670,13.434775,0.899660,-357.804779,0.090079,0.000000
74.990005,59.156212,-357.715820,-0.001237,0.003542,0.089966,263.139984,13.404989,0.899660,-357.715820,0.090079,0.000000
75.230003,59.020668,-357.804779,-0.001242,0.003542,0.089966,262.537048,13.374274,0.899660,-357.804779,0.090079,0.000000
75.470001,58.901505,-357.804779,-0.001233,0.003542,0.089966,262.006989,13.347272,0.899660,-357.804779,0.090079,0.000000
75.710007,58.781601,-357.760284,-0.001237,0.003542,0.089966,261.473633,13.320101,0.899660,-357.760284,0.090079,0.000000
75.950005,58.666168,-357.849243,-0.001229,0.003542,0.089966,260.960144,13.293944,0.899660,-357.849243,0.090079,0.000000
76.190002,58.552223,-357.760284,-0.001242,0.003542,0.089966,260.453308,13.268124,0.899660,-357.760284,0.090079,0.000000
76.430000,58.440140,-357.893738,-0.001233,0.003542,0.089966,259.954712,13.242724,0.899660,-357.893738,0.090079,0.000000
76.670006,58.337364,-357.849243,-0.001237,0.003542,0.089966,259.497559,13.219436,0.899660,-357.849243,0.090079,0.000000
76.910004,58.236824,-357.893738,-0.001237,0.003542,0.089966,259.050323,13.196652,0.899660,-357.893738,0.090079,0.000000
77.150002,58.138512,-357.804779,-0.001233,0.003542,0.089966,258.613007,13.174376,0.899660,-357.804779,0.090079,0.000000
77.390007,58.036110,-357.849243,-0.001242,0.003542,0.089966,258.157501,13.151171,0.899660,-357.849243,0.090079,0.000000
77.630005,57.944511,-357.938202,-0.001233,0.003542,0.089966,257.750061,13.130414,0.899660,-357.938202,0.090079,0.000000
77.870003,57.851044,-357.849243,-0.001233,0.003542,0.089966,257.334290,13.109234,0.899660,-357.849243,0.090079,0.000000
78.110001,57.765396,-357.893738,-0.001233,0.003542,0.089957,256.953308,13.089827,0.899573,-357.893738,0.090079,0.000000
78.350006,57.673050,-357.982697,-0.001229,0.003542,0.089957,256.542542,13.068900,0.899573,-357.982697,0.090079,0.000000
78.590004,57.598946,-357.893738,-0.001237,0.003542,0.089957,256.212921,13.052108,0.899573,-357.893738,0.090079,0.000000
78.830002,57.491333,-357.938202,-0.001224,0.003542,0.089957,255.734222,13.027722,0.899573,-357.938202,0.090079,0.000000
79.070007,57.415367,-357.938202,-0.001220,0.003542,0.089957,255.396301,13.010508,0.899573,-357.938202,0.090079,0.000000
79.310005,57.349457,-357.893738,-0.001220,0.003542,0.089957,255.103119,12.995572,0.899573,-357.893738,0.090079,0.000000
79.550003,57.274986,-358.027161,-0.001224,0.003542,0.089957,254.771866,12.978697,0.899573,-358.027161,0.090079,0.000000
79.790001,57.201256,-357.982697,-0.001229,0.003542,0.089957,254.443893,12.961990,0.899573,-357.982697,0.090079,0.000000
80.030006,57.146515,-357.982697,-0.001224,0.003542,0.089957,254.200394,12.949586,0.899573,-357.982697,0.090079,0.000000
80.270004,57.067200,-357.982697,-0.001224,0.003542,0.089957,253.847580,12.931612,0.899573,-357.982697,0.090079,0.000000
80.510002,57.002403,-357.938202,-0.001224,0.003542,0.089957,253.559357,12.916929,0.899573,-357.938202,0.090079,0.000000
80.750008,56.936867,-357.982697,-0.001229,0.003542,0.089957,253.267838,12.902079,0.899573,-357.982697,0.090079,0.000000
80.990005,56.858673,-357.982697,-0.001224,0.003542,0.089957,252.920013,12.884359,0.899573,-357.982697,0.090079,0.000000
81.230003,56.812500,-358.116150,-0.001224,0.003542,0.089957,252.714615,12.873897,0.899573,-358.116150,0.090079,0.000000
81.470001,56.737648,-358.027161,-0.001229,0.003542,0.089957,252.381668,12.856935,0.899573,-358.027161,0.090079,0.000000
81.710007,56.668762,-358.027161,-0.001220,0.003542,0.089957,252.075241,12.841326,0.899573,-358.027161,0.090079,0.000000
81.950005,56.605461,-358.116150,-0.001224,0.003542,0.089957,251.793671,12.826981,0.899573,-358.116150,0.090079,0.000000
82.190002,56.551460,-358.071655,-0.001207,0.003542,0.089957,251.553452,12.814744,0.899573,-358.071655,0.090079,0.000000
82.430000,56.496727,-358.071655,-0.001229,0.003542,0.089957,251.309998,12.802341,0.899573,-358.071655,0.090079,0.000000
82.670006,56.436401,-358.116150,-0.001203,0.003542,0.089957,251.041656,12.788671,0.899573,-358.116150,0.090079,0.000000
82.910004,56.376823,-358.160614,-0.001220,0.003542,0.089957,250.776642,12.775171,0.899573,-358.160614,0.090079,0.000000
83.150002,56.341820,-358.160614,-0.001224,0.003542,0.089957,250.620926,12.767240,0.899573,-358.160614,0.090079,0.000000
83.390007,56.275536,-358.116150,-0.001224,0.003542,0.089957,250.326080,12.752219,0.899573,-358.116150,0.090079,0.000000
83.630005,56.224152,-358.116150,-0.001229,0.003542,0.089957,250.097519,12.740575,0.899573,-358.116150,0.090079,0.000000
83.870003,56.186913,-358.249573,-0.001220,0.003542,0.089957,249.931870,12.732137,0.899573,-358.249573,0.090079,0.000000
84.110001,56.130310,-358.205109,-0.001203,0.003542,0.089957,249.680084,12.719310,0.899573,-358.205109,0.090079,0.000000
84.350006,56.073334,-358.160614,-0.001220,0.003542,0.089957,249.426651,12.706399,0.899573,-358.160614,0.090079,0.000000
84.590004,56.045784,-358.160614,-0.001212,0.003542,0.089957,249.304092,12.700156,0.899573,-358.160614,0.090079,0.000000
84.830002,55.979126,-358.205109,-0.001220,0.003542,0.089957,249.007584,12.685052,0.899573,-358.205109,0.090079,0.000000
85.070007,55.938911,-358.205109,-0.001207,0.003542,0.089957,248.828705,12.675939,0.899573,-358.205109,0.090079,0.000000
85.310005,55.887894,-358.160614,-0.001220,0.003542,0.089957,248.601761,12.664378,0.899573,-358.160614,0.090079,0.000000
85.550003,55.842094,-358.205109,-0.001229,0.003542,0.089957,248.398041,12.653999,0.899573,-358.205109,0.090079,0.000000
85.790001,55.781029,-358.205109,-0.001207,0.003542,0.089957,248.126404,12.640162,0.899573,-358.205109,0.090079,0.000000
86.030006,55.743416,-358.205109,-0.001220,0.003542,0.089957,247.959091,12.631639,0.899573,-358.205109,0.090079,0.000000
86.270004,55.704315,-358.338531,-0.001212,0.003542,0.089957,247.785172,12.622778,0.899573,-358.338531,0.090079,0.000000
86.510002,55.645485,-358.249573,-0.001207,0.003542,0.089957,247.523483,12.609447,0.899573,-358.249573,0.090079,0.000000
86.750008,55.604523,-358.294067,-0.001220,0.003542,0.089957,247.341263,12.600164,0.899573,-358.294067,0.090079,0.000000
86.990005,55.577713,-358.249573,-0.001207,0.003542,0.089957,247.222015,12.594090,0.899573,-358.249573,0.090079,0.000000
87.230003,55.532654,-358.294067,-0.001207,0.003542,0.089957,247.021576,12.583879,0.899573,-358.294067,0.090079,0.000000
87.470001,55.497650,-358.338531,-0.001216,0.003542,0.089957,246.865875,12.575947,0.899573,-358.338531,0.090079,0.000000
87.710007,55.453712,-358.294067,-0.001212,0.003542,0.089957,246.670425,12.565990,0.899573,-358.294067,0.090079,0.000000
87.950005,55.417961,-358.294067,-0.001212,0.003542,0.089957,246.511398,12.557889,0.899573,-358.294067,0.090079,0.000000
88.190002,55.384445,-358.383026,-0.001199,0.003542,0.089957,246.362320,12.550294,0.899573,-358.383026,0.090079,0.000000
88.430008,55.350563,-358.338531,-0.001207,0.003542,0.089957,246.211594,12.542617,0.899573,-358.338531,0.090079,0.000000
88.670006,55.319656,-358.427490,-0.001207,0.003542,0.089957,246.074127,12.535613,0.899573,-358.427490,0.090079,0.000000
88.910004,55.273109,-358.338531,-0.001203,0.003542,0.089957,245.867065,12.525065,0.899573,-358.338531,0.090079,0.000000
89.150002,55.231773,-358.338531,-0.001216,0.003542,0.089957,245.683197,12.515699,0.899573,-358.338531,0.090079,0.000000
89.390007,55.201988,-358.383026,-0.001212,0.003542,0.089957,245.550705,12.508949,0.899573,-358.383026,0.090079,0.000000
89.630005,55.161766,-358.338531,-0.001220,0.003542,0.089957,245.371796,12.499835,0.899573,-358.338531,0.090079,0.000000
89.870003,55.128998,-358.516479,-0.001212,0.003542,0.089957,245.226028,12.492410,0.899573,-358.516479,0.090079,0.000000
90.110001,55.083946,-358.383026,-0.001203,0.003542,0.089957,245.025635,12.482201,0.899573,-358.383026,0.090079,0.000000
90.350006,55.065323,-358.427490,-0.001212,0.003542,0.089957,244.942795,12.477981,0.899573,-358.427490,0.090079,0.000000
90.590004,55.026230,-358.427490,-0.001212,0.003542,0.089957,244.768890,12.469122,0.899573,-358.427490,0.090079,0.000000
90.830002,54.984520,-358.383026,-0.001216,0.003542,0.089957,244.583359,12.459670,0.899573,-358.383026,0.090079,0.000000
91.070007,54.951378,-358.516479,-0.001212,0.003542,0.089957,244.435944,12.452160,0.899573,-358.516479,0.090079,0.000000
91.310005,54.918236,-358.427490,-0.001207,0.003542,0.089957,244.288513,12.444650,0.899573,-358.427490,0.090079,0.000000
91.550003,54.886955,-358.427490,-0.001203,0.003542,0.089957,244.149368,12.437562,0.899573,-358.427490,0.090079,0.000000
91.790001,54.847862,-358.516479,-0.001203,0.003542,0.089957,243.975479,12.428703,0.899573,-358.516479,0.090079,0.000000
92.030006,54.824402,-358.471985,-0.001194,0.003542,0.089957,243.871124,12.423388,0.899573,-358.471985,0.090079,0.000000
92.270004,54.789772,-358.560944,-0.001212,0.003542,0.089957,243.717072,12.415540,0.899573,-358.560944,0.090079,0.000000
92.510002,54.762962,-358.471985,-0.001216,0.003542,0.089957,243.597824,12.409465,0.899573,-358.471985,0.090079,0.000000
92.750008,54.736893,-358.516479,-0.001212,0.003542,0.089957,243.481857,12.403557,0.899573,-358.516479,0.090079,0.000000
92.990005,54.698540,-358.560944,-0.001199,0.003542,0.089957,243.311264,12.394866,0.899573,-358.560944,0.090079,0.000000
93.230003,54.677315,-358.516479,-0.001220,0.003542,0.089957,243.216843,12.390057,0.899573,-358.516479,0.090079,0.000000
93.470001,54.650871,-358.605438,-0.001216,0.003542,0.089957,243.099213,12.384064,0.899573,-358.605438,0.090079,0.000000
93.710007,54.614380,-358.560944,-0.001203,0.003542,0.089957,242.936890,12.375795,0.899573,-358.560944,0.090079,0.000000
93.950005,54.593529,-358.560944,-0.001203,0.003542,0.089957,242.844147,12.371070,0.899573,-358.560944,0.090079,0.000000
94.190002,54.579750,-358.605438,-0.001212,0.003542,0.089957,242.782852,12.367948,0.899573,-358.605438,0.090079,0.000000
94.430008,54.543259,-358.560944,-0.001194,0.003542,0.089957,242.620529,12.359679,0.899573,-358.560944,0.090079,0.000000
94.670006,54.514214,-358.605438,-0.001207,0.003542,0.089957,242.491333,12.353098,0.899573,-358.605438,0.090079,0.000000
94.910004,54.494850,-358.605438,-0.001207,0.003542,0.089957,242.405197,12.348710,0.899573,-358.605438,0.090079,0.000000
95.150002,54.478470,-358.605438,-0.001212,0.003542,0.089957,242.332336,12.344997,0.899573,-358.605438,0.090079,0.000000
95.390007,54.437874,-358.694397,-0.001216,0.003542,0.089957,242.151764,12.335798,0.899573,-358.694397,0.090079,0.000000
95.630005,54.409950,-358.649902,-0.001199,0.003542,0.089957,242.027542,12.329471,0.899573,-358.649902,0.090079,0.000000
95.870003,54.390587,-358.649902,-0.001207,0.003542,0.089957,241.941406,12.325084,0.899573,-358.649902,0.090079,0.000000
96.110008,54.373459,-358.649902,-0.001207,0.003542,0.089957,241.865219,12.321202,0.899573,-358.649902,0.090079,0.000000
96.350006,54.328026,-358.649902,-0.001207,0.003542,0.089957,241.663132,12.310906,0.899573,-358.649902,0.090079,0.000000
96.590004,54.315742,-358.738861,-0.001207,0.003542,0.089957,241.608490,12.308123,0.899573,-358.738861,0.090079,0.000000
96.830002,54.289673,-358.694397,-0.001207,0.003542,0.089957,241.492523,12.302216,0.899573,-358.694397,0.090079,0.000000
97.070007,54.256531,-358.649902,-0.001203,0.003542,0.089957,241.345108,12.294705,0.899573,-358.649902,0.090079,0.000000
97.310005,54.240891,-358.783356,-0.001212,0.003542,0.089957,241.275528,12.291162,0.899573,-358.783356,0.090079,0.000000
97.550003,54.211472,-358.649902,-0.001199,0.003542,0.089957,241.144669,12.284494,0.899573,-358.649902,0.090079,0.000000
97.790001,54.200676,-358.783356,-0.001207,0.003542,0.089957,241.096649,12.282049,0.899573,-358.783356,0.090079,0.000000
98.030006,54.160835,-358.738861,-0.001194,0.003542,0.089957,240.919434,12.273021,0.899573,-358.738861,0.090079,0.000000
98.270004,54.150032,-358.694397,-0.001203,0.003542,0.089957,240.871368,12.270573,0.899573,-358.694397,0.090079,0.000000
98.510002,54.106094,-358.783356,-0.001203,0.003542,0.089957,240.675934,12.260616,0.899573,-358.783356,0.090079,0.000000
98.750008,54.103111,-358.738861,-0.001199,0.003542,0.089957,240.662659,12.259940,0.899573,-358.738861,0.090079,0.000000
98.990005,54.061783,-358.783356,-0.001207,0.003542,0.089957,240.478821,12.250575,0.899573,-358.783356,0.090079,0.000000
99.100006,54.062157,-358.738861,-0.001207,0.003542,0.089957,240.480484,12.250659,0.899573,-358.738861,0.090079,0.000000