File: Data/compression 11/AutoNoHeating-10-11-4-240529_05292024_160857.csv
Time (sec),S:Load (lbs),S:HL1 (DIM),S:LVDT (in),S:Position (in),Ch:Position (mm),Ch:Load (N),Ch:Stress (MPa),Ch:Strain (mm/mm),Ch:HL1 (DIM),Set Point (),Cycles ()
0.110000,-0.020111,-1300.089233,-0.008998,-0.005565,-0.141349,-0.089459,-0.004557,-1.413492,-1300.089233,-0.141184,0.000000
0.350000,0.000374,-1300.178223,-0.008994,-0.005558,-0.141184,0.001663,0.000085,-1.411843,-1300.178223,-0.140751,0.000000
0.590000,-0.000000,-1300.133667,-0.008990,-0.005417,-0.137603,-0.000000,-0.000000,-1.376027,-1300.133667,-0.136744,0.000000
0.830000,-0.020111,-1300.178223,-0.008860,-0.005264,-0.133717,-0.089459,-0.004557,-1.337175,-1300.178223,-0.132755,0.000000
1.070000,-0.041702,-1300.133667,-0.008709,-0.005115,-0.129919,-0.185501,-0.009450,-1.299192,-1300.133667,-0.128748,0.000000
1.310000,-0.012291,-1300.133667,-0.008537,-0.004957,-0.125904,-0.054673,-0.002785,-1.259038,-1300.133667,-0.124742,0.000000
1.550000,-0.011543,-1300.133667,-0.008399,-0.004803,-0.122001,-0.051347,-0.002616,-1.220014,-1300.133667,-0.120753,0.000000
1.790000,0.010429,-1300.133667,-0.008222,-0.004640,-0.117847,0.046392,0.002363,-1.178473,-1300.133667,-0.116746,0.000000
2.030000,-0.012657,-1300.133667,-0.008080,-0.004485,-0.113919,-0.056302,-0.002868,-1.139187,-1300.133667,-0.112757,0.000000
2.270000,0.009308,-1300.178223,-0.007912,-0.004321,-0.109747,0.041403,0.002109,-1.097474,-1300.178223,-0.108750,0.000000
2.510000,0.014153,-1300.089233,-0.007752,-0.004167,-0.105853,0.062954,0.003207,-1.058535,-1300.089233,-0.104761,0.000000
2.750000,-0.001862,-1300.133667,-0.007593,-0.004006,-0.101760,-0.008281,-0.000422,-1.017603,-1300.133667,-0.100754,0.000000
2.990000,-0.021225,-1300.133667,-0.007437,-0.003856,-0.097944,-0.094413,-0.004810,-0.979444,-1300.133667,-0.096765,0.000000
3.230000,-0.011543,-1300.133667,-0.007286,-0.003694,-0.093817,-0.051347,-0.002616,-0.938166,-1300.133667,-0.092758,0.000000
3.470000,0.004471,-1300.178223,-0.007127,-0.003545,-0.090035,0.019887,0.001013,-0.900355,-1300.178223,-0.088769,0.000000
3.710000,-0.024200,-1300.133667,-0.006959,-0.003378,-0.085812,-0.107649,-0.005484,-0.858119,-1300.133667,-0.084763,0.000000
3.950000,0.002235,-1300.222656,-0.006799,-0.003224,-0.081901,0.009944,0.000507,-0.819008,-1300.222656,-0.080773,0.000000
4.190000,-0.003349,-1300.133667,-0.006648,-0.003069,-0.077955,-0.014898,-0.000759,-0.779548,-1300.133667,-0.076767,0.000000
4.430000,0.039101,-1300.133667,-0.006489,-0.002909,-0.073896,0.173928,0.008860,-0.738963,-1300.133667,-0.072778,0.000000
4.670000,0.019737,-1300.222656,-0.006299,-0.002744,-0.069708,0.087796,0.004473,-0.697075,-1300.222656,-0.068771,0.000000
4.910000,-0.020477,-1300.133667,-0.006153,-0.002592,-0.065848,-0.091088,-0.004640,-0.658485,-1300.133667,-0.064782,0.000000
5.150000,-0.010796,-1300.178223,-0.006010,-0.002438,-0.061937,-0.048021,-0.002446,-0.619373,-1300.178223,-0.060775,0.000000
5.390000,0.004471,-1300.178223,-0.005846,-0.002279,-0.057887,0.019887,0.001013,-0.578873,-1300.178223,-0.056786,0.000000
5.630000,-0.010429,-1300.133667,-0.005691,-0.002122,-0.053889,-0.046392,-0.002363,-0.538893,-1300.133667,-0.052779,0.000000
5.870000,-0.029419,-1300.178223,-0.005540,-0.001962,-0.049839,-0.130862,-0.006666,-0.498395,-1300.178223,-0.048790,0.000000
6.110000,-0.000000,-1300.089233,-0.005372,-0.001809,-0.045937,-0.000000,-0.000000,-0.459369,-1300.089233,-0.044783,0.000000
6.350000,0.013031,-1300.222656,-0.005217,-0.001649,-0.041878,0.057965,0.002953,-0.418783,-1300.222656,-0.040777,0.000000
6.590000,0.044685,-1300.178223,-0.005062,-0.001490,-0.037837,0.198770,0.010126,-0.378370,-1300.178223,-0.036788,0.000000
6.830000,0.024948,-1300.133667,-0.004902,-0.001333,-0.033848,0.110975,0.005653,-0.338477,-1300.133667,-0.032781,0.000000
7.070000,-0.001488,-1300.267212,-0.004738,-0.001178,-0.029911,-0.006618,-0.000337,-0.299107,-1300.267212,-0.028792,0.000000
7.310000,0.027557,-1300.133667,-0.004583,-0.001017,-0.025843,0.122581,0.006245,-0.258433,-1300.133667,-0.024785,0.000000
7.550000,0.023834,-1300.222656,-0.004424,-0.000867,-0.022028,0.106020,0.005401,-0.220275,-1300.222656,-0.020796,0.000000
7.790000,0.010796,-1300.178223,-0.004251,-0.000701,-0.017813,0.048021,0.002446,-0.178129,-1300.178223,-0.016789,0.000000
8.030001,-0.016014,-1300.178223,-0.004100,-0.000547,-0.013893,-0.071234,-0.003629,-0.138930,-1300.178223,-0.012800,0.000000
8.270000,0.039841,-1300.222656,-0.003945,-0.000389,-0.009869,0.177220,0.009028,-0.098691,-1300.222656,-0.008794,0.000000
8.510000,0.160866,-1300.178223,-0.003790,-0.000233,-0.005914,0.715567,0.036453,-0.059145,-1300.178223,-0.004804,0.000000
8.750000,0.571594,-1300.222656,-0.003622,-0.000069,-0.001752,2.542578,0.129525,-0.017518,-1300.222656,-0.000798,0.000000
8.990001,0.682556,-1300.222656,-0.003548,-0.000000,-0.000000,3.036161,0.154669,-0.000000,-1300.222656,0.000269,0.000000
9.230000,0.647926,-1300.222656,-0.003548,-0.000000,-0.000000,2.882120,0.146822,-0.000000,-1300.222656,0.000269,0.000000
9.470000,0.630058,-1300.178223,-0.003553,-0.000000,-0.000000,2.802639,0.142773,-0.000000,-1300.178223,0.000425,0.000000
9.710000,0.558189,-1300.178223,-0.003544,0.000000,0.000009,2.482950,0.126488,0.000087,-1300.178223,0.000824,0.000000
9.950001,0.567871,-1300.178223,-0.003561,0.000000,0.000009,2.526017,0.128681,0.000087,-1300.178223,0.001223,0.000000
10.190001,0.719055,-1300.178223,-0.003535,0.000035,0.000885,3.198517,0.162940,0.008847,-1300.178223,0.001631,0.000000
10.430000,0.770065,-1300.222656,-0.003527,0.000046,0.001171,3.425421,0.174499,0.011709,-1300.222656,0.002029,0.000000
10.670000,0.829643,-1300.267212,-0.003510,0.000066,0.001674,3.690438,0.188000,0.016739,-1300.267212,0.002428,0.000000
10.910001,0.872841,-1300.222656,-0.003492,0.000081,0.002055,3.882590,0.197789,0.020554,-1300.222656,0.002827,0.000000
11.150001,0.912315,-1300.222656,-0.003479,0.000096,0.002428,4.058181,0.206734,0.024282,-1300.222656,0.003226,0.000000
11.390000,0.928322,-1300.222656,-0.003462,0.000109,0.002758,4.129382,0.210361,0.027579,-1300.222656,0.003625,0.000000
11.630000,0.985298,-1300.133667,-0.003462,0.000123,0.003131,4.382825,0.223272,0.031307,-1300.133667,0.004024,0.000000
11.870001,1.012482,-1300.222656,-0.003445,0.000140,0.003547,4.503744,0.229432,0.035470,-1300.222656,0.004423,0.000000
12.110001,1.062752,-1300.222656,-0.003423,0.000156,0.003955,4.727356,0.240823,0.039546,-1300.222656,0.004830,0.000000
12.350000,1.064613,-1300.222656,-0.003410,0.000167,0.004241,4.735637,0.241245,0.042408,-1300.222656,0.005229,0.000000
12.590000,1.098495,-1300.311646,-0.003397,0.000180,0.004570,4.886352,0.248923,0.045703,-1300.311646,0.005628,0.000000
12.830001,1.159195,-1300.133667,-0.003363,0.000206,0.005221,5.156357,0.262677,0.052207,-1300.133667,0.006027,0.000000
13.070001,1.191589,-1300.178223,-0.003363,0.000219,0.005550,5.300454,0.270018,0.055504,-1300.178223,0.006426,0.000000
13.310000,1.179306,-1300.222656,-0.003346,0.000235,0.005975,5.245815,0.267235,0.059752,-1300.222656,0.006825,0.000000
13.550000,1.204254,-1300.133667,-0.003320,0.000248,0.006296,5.356790,0.272888,0.062962,-1300.133667,0.007224,0.000000
13.790001,1.258995,-1300.222656,-0.003303,0.000267,0.006782,5.600290,0.285292,0.067818,-1300.222656,0.007623,0.000000
14.030001,1.289902,-1300.222656,-0.003298,0.000281,0.007137,5.737770,0.292296,0.071374,-1300.222656,0.008031,0.000000
14.270000,1.283569,-1300.267212,-0.003290,0.000291,0.007398,5.709601,0.290861,0.073976,-1300.267212,0.008430,0.000000
14.510000,1.342400,-1300.222656,-0.003268,0.000306,0.007770,5.971292,0.304192,0.077704,-1300.222656,0.008828,0.000000
14.750001,1.389694,-1300.222656,-0.003242,0.000333,0.008455,6.181669,0.314909,0.084555,-1300.222656,0.009227,0.000000
14.990001,1.397888,-1300.222656,-0.003225,0.000348,0.008828,6.218117,0.316766,0.088285,-1300.222656,0.009626,0.000000
15.230000,1.396767,-1300.267212,-0.003216,0.000360,0.009149,6.213129,0.316512,0.091492,-1300.267212,0.010025,0.000000
15.470000,1.396400,-1300.222656,-0.003186,0.000373,0.009470,6.211499,0.316429,0.094702,-1300.222656,0.010424,0.000000
15.710001,1.469757,-1300.267212,-0.003169,0.000389,0.009887,6.537806,0.333052,0.098865,-1300.267212,0.010823,0.000000
15.950001,1.499542,-1300.222656,-0.003152,0.000408,0.010372,6.670297,0.339801,0.103721,-1300.222656,0.011231,0.000000
16.190001,1.484650,-1300.222656,-0.003134,0.000417,0.010598,6.604052,0.336426,0.105975,-1300.222656,0.011629,0.000000
16.430000,1.518906,-1300.178223,-0.003139,0.000432,0.010979,6.756430,0.344189,0.109792,-1300.178223,0.012028,0.000000
16.670000,1.576256,-1300.267212,-0.003104,0.000456,0.011586,7.011536,0.357185,0.115861,-1300.267212,0.012427,0.000000
16.910002,1.591522,-1300.178223,-0.003083,0.000473,0.012011,7.079444,0.360644,0.120112,-1300.178223,0.012826,0.000000
17.150002,1.559494,-1300.267212,-0.003078,0.000486,0.012341,6.936976,0.353386,0.123406,-1300.267212,0.013225,0.000000
17.390001,1.581841,-1300.178223,-0.003053,0.000500,0.012705,7.036378,0.358450,0.127049,-1300.178223,0.013624,0.000000
17.630001,1.637695,-1300.267212,-0.003040,0.000517,0.013130,7.284832,0.371107,0.131298,-1300.267212,0.014023,0.000000
17.870001,1.669350,-1300.311646,-0.003014,0.000535,0.013589,7.425638,0.378280,0.135895,-1300.311646,0.014431,0.000000
18.110001,1.658546,-1300.133667,-0.003009,0.000546,0.013876,7.377583,0.375832,0.138756,-1300.133667,0.014830,0.000000
18.350000,1.692436,-1300.267212,-0.003005,0.000560,0.014231,7.528332,0.383512,0.142312,-1300.267212,0.015229,0.000000
18.590000,1.766907,-1300.178223,-0.002962,0.000585,0.014864,7.859594,0.400387,0.148642,-1300.178223,0.015627,0.000000
18.830002,1.740471,-1300.222656,-0.002966,0.000599,0.015203,7.742001,0.394396,0.152026,-1300.222656,0.016026,0.000000
19.070002,1.734886,-1300.356079,-0.002949,0.000613,0.015567,7.717159,0.393131,0.155667,-1300.356079,0.016425,0.000000
19.310001,1.747543,-1300.267212,-0.002940,0.000627,0.015922,7.773461,0.395999,0.159223,-1300.267212,0.016824,0.000000
19.550001,1.752388,-1300.311646,-0.002915,0.000637,0.016174,7.795011,0.397097,0.161738,-1300.311646,0.017223,0.000000
19.790001,1.849571,-1300.267212,-0.002893,0.000660,0.016755,8.227304,0.419119,0.167548,-1300.267212,0.017631,0.000000
20.030001,1.825371,-1300.178223,-0.002884,0.000670,0.017006,8.119655,0.413635,0.170063,-1300.178223,0.018030,0.000000
20.270000,1.882713,-1300.267212,-0.002871,0.000684,0.017379,8.374727,0.426629,0.173793,-1300.267212,0.018429,0.000000
20.510000,1.943787,-1300.311646,-0.002846,0.000709,0.018012,8.646395,0.440468,0.180123,-1300.311646,0.018828,0.000000
20.750002,1.950111,-1300.222656,-0.002824,0.000725,0.018403,8.674529,0.441902,0.184025,-1300.222656,0.019227,0.000000
20.990002,1.925911,-1300.311646,-0.002807,0.000740,0.018793,8.566880,0.436418,0.187928,-1300.311646,0.019625,0.000000
21.230001,1.920700,-1300.178223,-0.002811,0.000753,0.019122,8.543700,0.435237,0.191224,-1300.178223,0.020024,0.000000
21.470001,1.882713,-1300.267212,-0.002785,0.000764,0.019409,8.374727,0.426629,0.194086,-1300.267212,0.020432,0.000000
21.710001,2.003365,-1300.267212,-0.002759,0.000780,0.019816,8.911410,0.453969,0.198162,-1300.267212,0.020831,0.000000
21.950001,2.029427,-1300.267212,-0.002759,0.000797,0.020250,9.027340,0.459875,0.202498,-1300.267212,0.021230,0.000000
22.190001,2.073746,-1300.311646,-0.002738,0.000812,0.020623,9.224482,0.469918,0.206228,-1300.311646,0.021629,0.000000
22.430000,2.143379,-1300.178223,-0.002716,0.000834,0.021178,9.534227,0.485697,0.211776,-1300.178223,0.022028,0.000000
22.670002,2.143379,-1300.267212,-0.002699,0.000852,0.021629,9.534227,0.485697,0.216286,-1300.267212,0.022426,0.000000
22.910002,2.134811,-1300.133667,-0.002673,0.000866,0.022002,9.496116,0.483755,0.220016,-1300.133667,0.022825,0.000000
23.150002,2.153061,-1300.267212,-0.002669,0.000880,0.022357,9.577293,0.487891,0.223572,-1300.267212,0.023224,0.000000
23.390001,2.179871,-1300.267212,-0.002656,0.000895,0.022730,9.696548,0.493966,0.227300,-1300.267212,0.023632,0.000000
23.630001,2.263649,-1300.178223,-0.002634,0.000912,0.023155,10.069214,0.512950,0.231550,-1300.178223,0.024031,0.000000
23.870001,2.262161,-1300.311646,-0.002617,0.000924,0.023467,10.062595,0.512613,0.234671,-1300.311646,0.024430,0.000000
24.110001,2.343338,-1300.222656,-0.002600,0.000942,0.023935,10.423688,0.531008,0.239355,-1300.222656,0.024829,0.000000
24.350000,2.355255,-1300.267212,-0.002596,0.000959,0.024369,10.476698,0.533708,0.243690,-1300.267212,0.025228,0.000000
24.590002,2.363075,-1300.222656,-0.002574,0.000973,0.024707,10.511484,0.535480,0.247072,-1300.222656,0.025627,0.000000
24.830002,2.406647,-1300.222656,-0.002557,0.000992,0.025184,10.705299,0.545354,0.251843,-1300.222656,0.026026,0.000000
25.070002,2.411858,-1300.311646,-0.002544,0.001003,0.025479,10.728478,0.546535,0.254792,-1300.311646,0.026424,0.000000
25.310001,2.433083,-1300.222656,-0.002539,0.001019,0.025878,10.822892,0.551344,0.258781,-1300.222656,0.026832,0.000000
25.550001,2.525055,-1300.267212,-0.002505,0.001039,0.026398,11.232005,0.572186,0.263983,-1300.267212,0.027231,0.000000
25.790001,2.512772,-1300.267212,-0.002488,0.001052,0.026711,11.177366,0.569402,0.267106,-1300.267212,0.027630,0.000000
26.030001,2.522827,-1300.267212,-0.002475,0.001064,0.027014,11.222095,0.571681,0.270141,-1300.267212,0.028029,0.000000
26.270000,2.590225,-1300.267212,-0.002458,0.001083,0.027500,11.521897,0.586953,0.274997,-1300.267212,0.028428,0.000000
26.510002,2.649803,-1300.222656,-0.002440,0.001101,0.027977,11.786913,0.600454,0.279768,-1300.222656,0.028827,0.000000
26.750002,2.651665,-1300.222656,-0.002440,0.001117,0.028367,11.795194,0.600876,0.283670,-1300.222656,0.029226,0.000000
26.990002,2.667305,-1300.222656,-0.002397,0.001129,0.028688,11.864765,0.604420,0.286878,-1300.222656,0.029625,0.000000
27.230001,2.664322,-1300.178223,-0.002393,0.001145,0.029078,11.851496,0.603744,0.290782,-1300.178223,0.030032,0.000000
27.470001,2.786461,-1300.267212,-0.002376,0.001166,0.029625,12.394797,0.631421,0.296246,-1300.267212,0.030431,0.000000
27.710001,2.774544,-1300.222656,-0.002363,0.001177,0.029902,12.341787,0.628721,0.299020,-1300.222656,0.030830,0.000000
27.950001,2.872108,-1300.311646,-0.002354,0.001196,0.030379,12.775777,0.650829,0.303789,-1300.311646,0.031229,0.000000
28.190001,2.890358,-1300.222656,-0.002324,0.001209,0.030700,12.856955,0.654964,0.306999,-1300.222656,0.031628,0.000000
28.430002,2.944725,-1300.133667,-0.002307,0.001229,0.031229,13.098791,0.667284,0.312288,-1300.133667,0.032027,0.000000
28.670002,2.923126,-1300.267212,-0.002289,0.001244,0.031602,13.002715,0.662390,0.316018,-1300.267212,0.032426,0.000000
28.910002,2.911957,-1300.222656,-0.002272,0.001257,0.031931,12.953031,0.659859,0.319313,-1300.222656,0.032825,0.000000
29.150002,3.056808,-1300.267212,-0.002264,0.001278,0.032469,13.597363,0.692683,0.324689,-1300.267212,0.033232,0.000000
29.390001,3.095901,-1300.222656,-0.002238,0.001294,0.032877,13.771257,0.701541,0.328765,-1300.222656,0.033631,0.000000
29.630001,3.082870,-1300.178223,-0.002220,0.001307,0.033206,13.713293,0.698588,0.332062,-1300.178223,0.034030,0.000000
29.870001,3.149902,-1300.222656,-0.002220,0.001321,0.033562,14.011465,0.713778,0.335616,-1300.222656,0.034429,0.000000
30.110001,3.245598,-1300.178223,-0.002195,0.001342,0.034099,14.437140,0.735463,0.340994,-1300.178223,0.034828,0.000000
30.350002,3.214691,-1300.222656,-0.002177,0.001355,0.034420,14.299661,0.728459,0.344202,-1300.222656,0.035227,0.000000
30.590002,3.234055,-1300.222656,-0.002164,0.001367,0.034732,14.385793,0.732847,0.347325,-1300.222656,0.035626,0.000000
30.830002,3.266083,-1300.178223,-0.002143,0.001384,0.035157,14.528262,0.740105,0.351573,-1300.178223,0.036025,0.000000
31.070002,3.345398,-1300.267212,-0.002130,0.001403,0.035634,14.881073,0.758078,0.356344,-1300.267212,0.036432,0.000000
31.310001,3.406837,-1300.222656,-0.002100,0.001420,0.036068,15.154370,0.772000,0.360680,-1300.222656,0.036831,0.000000
31.550001,3.393059,-1300.178223,-0.002095,0.001433,0.036397,15.093080,0.768878,0.363974,-1300.178223,0.037230,0.000000
31.790001,3.493973,-1300.311646,-0.002070,0.001448,0.036788,15.541967,0.791746,0.367879,-1300.311646,0.037629,0.000000
32.030003,3.594887,-1300.178223,-0.002070,0.001468,0.037282,15.990855,0.814613,0.372822,-1300.178223,0.038028,0.000000
32.270000,3.591164,-1300.267212,-0.002035,0.001482,0.037646,15.974294,0.813769,0.376463,-1300.267212,0.038427,0.000000
32.510002,3.613876,-1300.222656,-0.002035,0.001496,0.037993,16.075325,0.818916,0.379932,-1300.222656,0.038826,0.000000
32.750000,3.641800,-1300.222656,-0.002035,0.001510,0.038357,16.199535,0.825244,0.383575,-1300.222656,0.039225,0.000000
32.990002,3.667122,-1300.222656,-0.002022,0.001522,0.038670,16.312172,0.830982,0.386697,-1300.222656,0.039632,0.000000
33.230003,3.770271,-1300.178223,-0.001988,0.001541,0.039147,16.771004,0.854356,0.391466,-1300.178223,0.040031,0.000000
33.470001,3.828735,-1300.267212,-0.001979,0.001557,0.039537,17.031065,0.867604,0.395368,-1300.267212,0.040430,0.000000
33.710003,3.896881,-1300.222656,-0.001966,0.001571,0.039910,17.334192,0.883046,0.399098,-1300.222656,0.040829,0.000000
33.950001,4.008217,-1300.222656,-0.001957,0.001591,0.040413,17.829439,0.908275,0.404128,-1300.222656,0.041228,0.000000
34.190002,4.015663,-1300.222656,-0.001919,0.001606,0.040794,17.862562,0.909962,0.407944,-1300.222656,0.041627,0.000000
34.430000,4.049927,-1300.178223,-0.001910,0.001621,0.041185,18.014975,0.917727,0.411846,-1300.178223,0.042026,0.000000
34.670002,4.083809,-1300.267212,-0.001893,0.001636,0.041566,18.165689,0.925404,0.415661,-1300.267212,0.042433,0.000000
34.910000,4.161636,-1300.267212,-0.001876,0.001653,0.041982,18.511883,0.943040,0.419824,-1300.267212,0.042832,0.000000
35.150002,4.249146,-1300.178223,-0.001884,0.001669,0.042381,18.901144,0.962870,0.423814,-1300.178223,0.043231,0.000000
35.390003,4.285263,-1300.222656,-0.001863,0.001684,0.042772,19.061802,0.971054,0.427716,-1300.222656,0.043630,0.000000
35.630001,4.228287,-1300.178223,-0.001837,0.001693,0.043006,18.808359,0.958143,0.430059,-1300.178223,0.044029,0.000000
35.870003,4.454689,-1300.267212,-0.001832,0.001716,0.043587,19.815447,1.009447,0.435869,-1300.267212,0.044428,0.000000
36.110001,4.560448,-1300.267212,-0.001794,0.001734,0.044055,20.285885,1.033412,0.440550,-1300.267212,0.044827,0.000000
36.350002,4.570869,-1300.311646,-0.001794,0.001750,0.044445,20.332243,1.035774,0.444455,-1300.311646,0.045226,0.000000
36.590000,4.537361,-1300.267212,-0.001768,0.001761,0.044740,20.183191,1.028181,0.447403,-1300.267212,0.045634,0.000000
36.830002,4.551880,-1300.222656,-0.001768,0.001775,0.045078,20.247772,1.031471,0.450785,-1300.222656,0.046032,0.000000
37.070004,4.833397,-1300.356079,-0.001746,0.001797,0.045651,21.500023,1.095263,0.456508,-1300.356079,0.046431,0.000000
37.310001,4.801369,-1300.222656,-0.001720,0.001810,0.045963,21.357555,1.088006,0.459630,-1300.222656,0.046830,0.000000
37.550003,4.744400,-1300.222656,-0.001725,0.001820,0.046232,21.104145,1.075096,0.462319,-1300.222656,0.047229,0.000000
37.790001,4.837860,-1300.356079,-0.001694,0.001832,0.046535,21.519876,1.096275,0.465355,-1300.356079,0.047628,0.000000
38.030003,5.163689,-1300.267212,-0.001669,0.001859,0.047229,22.969234,1.170109,0.472292,-1300.267212,0.048027,0.000000
38.270000,5.183426,-1300.311646,-0.001664,0.001876,0.047645,23.057030,1.174581,0.476454,-1300.311646,0.048426,0.000000
38.510002,5.124588,-1300.222656,-0.001660,0.001889,0.047975,22.795305,1.161248,0.479751,-1300.222656,0.048833,0.000000
38.750000,5.149170,-1300.267212,-0.001634,0.001901,0.048279,22.904652,1.166819,0.482786,-1300.267212,0.049232,0.000000
38.990002,5.306679,-1300.222656,-0.001617,0.001917,0.048686,23.605286,1.202511,0.486861,-1300.222656,0.049631,0.000000
39.230003,5.460472,-1300.178223,-0.001600,0.001937,0.049189,24.289392,1.237361,0.491891,-1300.178223,0.050030,0.000000
39.470001,5.358070,-1300.222656,-0.001582,0.001945,0.049415,23.833887,1.214156,0.494146,-1300.222656,0.050429,0.000000
39.710003,5.572182,-1300.222656,-0.001578,0.001963,0.049866,24.786303,1.262674,0.498656,-1300.222656,0.050828,0.000000
39.950001,5.820183,-1300.267212,-0.001556,0.001985,0.050412,25.889465,1.318872,0.504120,-1300.267212,0.051227,0.000000
40.190002,5.825768,-1300.222656,-0.001531,0.002001,0.050819,25.914309,1.320138,0.508194,-1300.222656,0.051626,0.000000
40.430000,5.823532,-1300.222656,-0.001518,0.002014,0.051149,25.904364,1.319631,0.511491,-1300.222656,0.052034,0.000000
40.670002,5.822044,-1300.267212,-0.001513,0.002025,0.051444,25.897747,1.319294,0.514439,-1300.267212,0.052433,0.000000
40.910004,6.007484,-1300.222656,-0.001492,0.002045,0.051947,26.722626,1.361315,0.519469,-1300.222656,0.052831,0.000000
41.150002,6.178780,-1300.222656,-0.001487,0.002059,0.052303,27.484585,1.400131,0.523025,-1300.222656,0.053230,0.000000
41.390003,6.103928,-1300.267212,-0.001466,0.002070,0.052580,27.151627,1.383170,0.525800,-1300.267212,0.053629,0.000000
41.630001,6.350815,-1300.222656,-0.001466,0.002088,0.053031,28.249836,1.439115,0.530309,-1300.222656,0.054028,0.000000
41.870003,6.636421,-1300.222656,-0.001427,0.002109,0.053569,29.520275,1.503834,0.535686,-1300.222656,0.054427,0.000000
42.110001,6.674774,-1300.222656,-0.001410,0.002125,0.053976,29.690878,1.512525,0.539762,-1300.222656,0.054826,0.000000
42.350002,6.735847,-1300.267212,-0.001410,0.002141,0.054384,29.962545,1.526365,0.543838,-1300.267212,0.055234,0.000000
42.590000,6.814415,-1300.311646,-0.001375,0.002155,0.054748,30.312031,1.544169,0.547479,-1300.311646,0.055633,0.000000
42.830002,6.708290,-1300.267212,-0.001375,0.002165,0.054991,29.839964,1.520120,0.549909,-1300.267212,0.056032,0.000000
43.070004,6.904160,-1300.356079,-0.001367,0.002179,0.055338,30.711235,1.564505,0.553378,-1300.356079,0.056431,0.000000
43.310001,7.101891,-1300.311646,-0.001341,0.002197,0.055806,31.590788,1.609311,0.558060,-1300.311646,0.056829,0.000000
43.550003,7.345421,-1300.267212,-0.001328,0.002216,0.056274,32.674065,1.664496,0.562744,-1300.267212,0.057228,0.000000
43.790001,7.631775,-1300.311646,-0.001298,0.002235,0.056777,33.947830,1.729385,0.567774,-1300.311646,0.057627,0.000000
44.030003,7.683159,-1300.267212,-0.001285,0.002251,0.057176,34.176399,1.741029,0.571763,-1300.267212,0.058026,0.000000
44.270000,7.738647,-1300.311646,-0.001268,0.002268,0.057601,34.423222,1.753603,0.576012,-1300.311646,0.058434,0.000000
44.510002,7.740883,-1300.311646,-0.001268,0.002279,0.057887,34.433167,1.754109,0.578873,-1300.311646,0.058833,0.000000
44.750004,7.887596,-1300.311646,-0.001255,0.002293,0.058252,35.085781,1.787355,0.582516,-1300.311646,0.059232,0.000000
44.990002,8.201874,-1300.311646,-0.001233,0.002312,0.058720,36.483757,1.858571,0.587200,-1300.311646,0.059630,0.000000
45.230003,8.255127,-1300.311646,-0.001220,0.002326,0.059075,36.720638,1.870638,0.590754,-1300.311646,0.060029,0.000000
45.470001,8.531799,-1300.311646,-0.001203,0.002342,0.059474,37.951340,1.933333,0.594743,-1300.311646,0.060428,0.000000
45.710003,8.744049,-1300.267212,-0.001173,0.002360,0.059943,38.895473,1.981430,0.599427,-1300.267212,0.060827,0.000000
45.950001,8.867310,-1300.267212,-0.001186,0.002376,0.060359,39.443764,2.009361,0.603590,-1300.267212,0.061226,0.000000
46.190002,9.057213,-1300.356079,-0.001147,0.002392,0.060766,40.288494,2.052394,0.607665,-1300.356079,0.061634,0.000000
46.430000,9.049393,-1300.311646,-0.001147,0.002404,0.061070,40.253708,2.050622,0.610700,-1300.311646,0.062033,0.000000
46.670002,9.266487,-1300.311646,-0.001130,0.002421,0.061495,41.219395,2.099816,0.614951,-1300.311646,0.062432,0.000000
46.910004,9.612793,-1300.311646,-0.001112,0.002439,0.061963,42.759838,2.178290,0.619633,-1300.311646,0.062831,0.000000
47.150002,9.628433,-1300.356079,-0.001099,0.002453,0.062310,42.829411,2.181834,0.623102,-1300.356079,0.063230,0.000000
47.390003,9.714828,-1300.311646,-0.001082,0.002466,0.062649,43.213715,2.201412,0.626485,-1300.311646,0.063628,0.000000
47.630001,9.987404,-1300.311646,-0.001078,0.002482,0.063039,44.426189,2.263178,0.630387,-1300.311646,0.064027,0.000000
47.870003,10.386955,-1300.356079,-0.001061,0.002501,0.063516,46.203484,2.353718,0.635156,-1300.356079,0.064426,0.000000
48.110001,10.556389,-1300.356079,-0.001043,0.002518,0.063958,46.957161,2.392112,0.639579,-1300.356079,0.064834,0.000000
48.350002,10.525856,-1300.311646,-0.001030,0.002530,0.064253,46.821346,2.385193,0.642528,-1300.311646,0.065233,0.000000
48.590004,10.806992,-1300.356079,-0.001013,0.002546,0.064660,48.071899,2.448899,0.646604,-1300.356079,0.065632,0.000000
48.830002,11.312302,-1300.267212,-0.000996,0.002566,0.065181,50.319630,2.563404,0.651808,-1300.267212,0.066031,0.000000
49.070004,11.263153,-1300.356079,-0.000987,0.002578,0.065476,50.101006,2.552267,0.654757,-1300.356079,0.066430,0.000000
49.310001,11.760269,-1300.311646,-0.000961,0.002598,0.065979,52.312290,2.664915,0.659787,-1300.311646,0.066829,0.000000
49.550003,11.889107,-1300.311646,-0.000961,0.002614,0.066386,52.885387,2.694110,0.663861,-1300.311646,0.067227,0.000000
49.790001,12.293129,-1300.311646,-0.000940,0.002632,0.066854,54.682568,2.785663,0.668545,-1300.311646,0.067635,0.000000
50.030003,12.286057,-1300.311646,-0.000931,0.002645,0.067175,54.651108,2.784060,0.671755,-1300.311646,0.068034,0.000000
50.270004,12.403358,-1300.356079,-0.000910,0.002657,0.067488,55.172894,2.810641,0.674875,-1300.356079,0.068433,0.000000
50.510002,13.092247,-1300.356079,-0.000884,0.002680,0.068077,58.237225,2.966745,0.680772,-1300.356079,0.068832,0.000000
50.750004,13.286995,-1300.311646,-0.000884,0.002695,0.068459,59.103504,3.010876,0.684589,-1300.311646,0.069231,0.000000
50.990002,13.314926,-1300.356079,-0.000875,0.002706,0.068745,59.227749,3.017205,0.687450,-1300.356079,0.069630,0.000000
51.230003,13.613190,-1300.311646,-0.000854,0.002721,0.069109,60.554493,3.084793,0.691093,-1300.311646,0.070029,0.000000
51.470001,14.379906,-1300.356079,-0.000849,0.002744,0.069708,63.965015,3.258533,0.697077,-1300.356079,0.070427,0.000000
51.710003,14.306549,-1300.311646,-0.000819,0.002755,0.069976,63.638710,3.241910,0.699765,-1300.311646,0.070835,0.000000
51.950001,14.401878,-1300.267212,-0.000819,0.002767,0.070289,64.062752,3.263512,0.702887,-1300.267212,0.071234,0.000000
52.190002,14.831970,-1300.400635,-0.000793,0.002784,0.070705,65.975899,3.360973,0.707051,-1300.400635,0.071633,0.000000
52.430004,15.439682,-1300.311646,-0.000789,0.002804,0.071234,68.679138,3.498682,0.712340,-1300.311646,0.072032,0.000000
52.670002,15.794922,-1300.400635,-0.000776,0.002821,0.071642,70.259323,3.579180,0.716416,-1300.400635,0.072431,0.000000
52.910004,15.942009,-1300.356079,-0.000759,0.002834,0.071980,70.913597,3.612511,0.719798,-1300.356079,0.072830,0.000000
53.150002,16.279755,-1300.356079,-0.000755,0.002848,0.072327,72.415962,3.689045,0.723267,-1300.356079,0.073229,0.000000
53.390003,17.029709,-1300.356079,-0.000733,0.002870,0.072899,75.751930,3.858987,0.728990,-1300.356079,0.073628,0.000000
53.630001,17.178658,-1300.356079,-0.000733,0.002883,0.073220,76.414482,3.892740,0.732199,-1300.356079,0.074035,0.000000
53.870003,17.310852,-1300.400635,-0.000711,0.002895,0.073532,77.002518,3.922695,0.735322,-1300.400635,0.074434,0.000000
54.110004,17.774086,-1300.356079,-0.000698,0.002911,0.073948,79.063080,4.027666,0.739483,-1300.356079,0.074833,0.000000
54.350002,17.994530,-1300.311646,-0.000694,0.002925,0.074304,80.043663,4.077619,0.743039,-1300.311646,0.075232,0.000000
54.590004,18.681183,-1300.311646,-0.000673,0.002944,0.074781,83.098053,4.233216,0.747810,-1300.311646,0.075631,0.000000
54.830002,18.982803,-1300.267212,-0.000673,0.002956,0.075084,84.439728,4.301565,0.750844,-1300.267212,0.076030,0.000000
55.070004,19.372681,-1300.311646,-0.000651,0.002970,0.075449,86.173988,4.389912,0.754487,-1300.311646,0.076429,0.000000
55.310001,20.320366,-1300.222656,-0.000634,0.002994,0.076047,90.389503,4.604661,0.760471,-1300.222656,0.076827,0.000000
55.550003,20.665184,-1300.356079,-0.000629,0.003008,0.076411,91.923332,4.682797,0.764114,-1300.356079,0.077235,0.000000
55.790001,20.948555,-1300.311646,-0.000617,0.003021,0.076741,93.183830,4.747010,0.767408,-1300.311646,0.077634,0.000000
56.030003,21.331726,-1300.356079,-0.000608,0.003036,0.077123,94.888260,4.833838,0.771225,-1300.356079,0.078033,0.000000
56.270004,21.896248,-1300.356079,-0.000595,0.003053,0.077556,97.399376,4.961761,0.775561,-1300.356079,0.078432,0.000000
56.510002,22.553482,-1300.356079,-0.000573,0.003070,0.077990,100.322899,5.110692,0.779897,-1300.356079,0.078831,0.000000
56.750004,22.899414,-1300.356079,-0.000578,0.003084,0.078328,101.861679,5.189081,0.783278,-1300.356079,0.079230,0.000000
56.990002,22.972778,-1300.311646,-0.000560,0.003095,0.078623,102.188019,5.205706,0.786227,-1300.311646,0.079629,0.000000
57.230003,24.439552,-1300.267212,-0.000556,0.003119,0.079230,108.712555,5.538082,0.792298,-1300.267212,0.080028,0.000000
57.470001,24.939644,-1300.400635,-0.000543,0.003135,0.079620,110.937073,5.651404,0.796200,-1300.400635,0.080435,0.000000
57.710003,25.336967,-1300.356079,-0.000522,0.003149,0.079984,112.704460,5.741439,0.799843,-1300.356079,0.080834,0.000000
57.950005,25.590927,-1300.356079,-0.000509,0.003163,0.080340,113.834129,5.798987,0.803399,-1300.356079,0.081233,0.000000
58.190002,25.867973,-1300.356079,-0.000517,0.003174,0.080617,115.066490,5.861766,0.806173,-1300.356079,0.081632,0.000000
58.430004,27.227127,-1300.356079,-0.000500,0.003197,0.081207,121.112312,6.169755,0.812070,-1300.356079,0.082031,0.000000
58.670002,27.523537,-1300.356079,-0.000479,0.003209,0.081519,122.430809,6.236923,0.815193,-1300.356079,0.082430,0.000000
58.910004,27.761482,-1300.356079,-0.000466,0.003221,0.081814,123.489243,6.290842,0.818141,-1300.356079,0.082829,0.000000
59.150002,28.239609,-1300.356079,-0.000470,0.003236,0.082204,125.616051,6.399187,0.822043,-1300.356079,0.083228,0.000000
59.390003,29.864647,-1300.356079,-0.000444,0.003261,0.082820,132.844589,6.767426,0.828201,-1300.356079,0.083635,0.000000
59.630001,30.540131,-1300.267212,-0.000427,0.003276,0.083202,135.849289,6.920492,0.832016,-1300.267212,0.084034,0.000000
59.870003,31.004852,-1300.356079,-0.000427,0.003291,0.083592,137.916473,7.025800,0.835919,-1300.356079,0.084433,0.000000
60.110004,31.249496,-1300.356079,-0.000410,0.003301,0.083843,139.004700,7.081237,0.838434,-1300.356079,0.084832,0.000000
60.350002,32.165535,-1300.356079,-0.000414,0.003320,0.084329,143.079453,7.288815,0.843292,-1300.356079,0.085231,0.000000
60.590004,33.205940,-1300.311646,-0.000405,0.003337,0.084771,147.707397,7.524574,0.847714,-1300.311646,0.085630,0.000000
60.830002,33.288979,-1300.267212,-0.000397,0.003346,0.084997,148.076767,7.543391,0.849968,-1300.267212,0.086029,0.000000
61.070004,34.304443,-1300.311646,-0.000375,0.003366,0.085491,152.593781,7.773498,0.854911,-1300.311646,0.086428,0.000000
61.310001,35.584656,-1300.311646,-0.000362,0.003384,0.085960,158.288452,8.063599,0.859595,-1300.311646,0.086835,0.000000
61.550003,36.338341,-1300.356079,-0.000366,0.003400,0.086367,161.641006,8.234386,0.863671,-1300.356079,0.087234,0.000000
61.790005,36.925941,-1300.356079,-0.000354,0.003415,0.086731,164.254791,8.367538,0.867312,-1300.356079,0.087633,0.000000
62.030003,37.283051,-1300.356079,-0.000332,0.003424,0.086974,165.843292,8.448460,0.869740,-1300.356079,0.088032,0.000000
62.270004,38.296272,-1300.400635,-0.000336,0.003448,0.087572,170.350327,8.678059,0.875724,-1300.400635,0.088431,0.000000
62.510002,39.277473,-1300.400635,-0.000323,0.003459,0.087867,174.714935,8.900403,0.878673,-1300.400635,0.088830,0.000000
62.750004,39.628624,-1300.400635,-0.000328,0.003469,0.088102,176.276917,8.979975,0.881016,-1300.400635,0.089229,0.000000
62.990002,40.968788,-1300.356079,-0.000310,0.003491,0.088665,182.238266,9.283660,0.886651,-1300.356079,0.089637,0.000000
63.230003,42.299278,-1300.400635,-0.000293,0.003510,0.089151,188.156586,9.585153,0.891509,-1300.400635,0.090035,0.000000
63.470001,43.165787,-1300.400635,-0.000285,0.003524,0.089506,192.011002,9.781507,0.895063,-1300.400635,0.090434,0.000000
63.710003,44.100441,-1300.311646,-0.000280,0.003541,0.089940,196.168564,9.993303,0.899401,-1300.311646,0.090833,0.000000
63.950005,44.888756,-1300.445068,-0.000280,0.003554,0.090278,199.675156,10.171937,0.902783,-1300.445068,0.091232,0.000000
64.190002,45.192986,-1300.356079,-0.000272,0.003565,0.090547,201.028442,10.240877,0.905472,-1300.356079,0.091631,0.000000
64.430000,46.136574,-1300.311646,-0.000263,0.003582,0.090989,205.225723,10.454697,0.909894,-1300.311646,0.092030,0.000000
64.670006,47.361679,-1300.356079,-0.000263,0.003596,0.091345,210.675278,10.732309,0.913450,-1300.356079,0.092429,0.000000
64.910004,48.530930,-1300.356079,-0.000254,0.003615,0.091822,215.876358,10.997266,0.918219,-1300.356079,0.092837,0.000000
65.150002,50.065475,-1300.356079,-0.000237,0.003634,0.092308,222.702362,11.344999,0.923075,-1300.356079,0.093236,0.000000
65.389999,51.199722,-1300.356079,-0.000220,0.003650,0.092706,227.747742,11.602023,0.927065,-1300.356079,0.093634,0.000000
65.630005,52.157097,-1300.400635,-0.000233,0.003667,0.093132,232.006348,11.818967,0.931315,-1300.400635,0.094033,0.000000
65.870003,52.845985,-1300.356079,-0.000207,0.003677,0.093400,235.070679,11.975072,0.934002,-1300.356079,0.094432,0.000000
66.110001,53.796654,-1300.400635,-0.000207,0.003692,0.093773,239.299469,12.190495,0.937732,-1300.400635,0.094831,0.000000
66.350006,55.204590,-1300.400635,-0.000207,0.003710,0.094241,245.562286,12.509539,0.942414,-1300.400635,0.095230,0.000000
66.590004,56.019714,-1300.356079,-0.000194,0.003724,0.094597,249.188141,12.694249,0.945970,-1300.356079,0.095629,0.000000
66.830002,57.410149,-1300.400635,-0.000190,0.003743,0.095065,255.373093,13.009325,0.950654,-1300.400635,0.096037,0.000000
67.070000,58.844902,-1300.356079,-0.000177,0.003760,0.095499,261.755188,13.334446,0.954990,-1300.356079,0.096436,0.000000
67.310005,59.830574,-1300.400635,-0.000185,0.003775,0.095880,266.139679,13.557802,0.958805,-1300.400635,0.096834,0.000000
67.550003,61.127922,-1300.489624,-0.000172,0.003791,0.096297,271.910583,13.851786,0.962968,-1300.489624,0.097233,0.000000
67.790001,62.016029,-1300.311646,-0.000164,0.003807,0.096687,275.861084,14.053033,0.966870,-1300.311646,0.097632,0.000000
68.030006,63.198677,-1300.445068,-0.000164,0.003820,0.097025,281.121765,14.321025,0.970252,-1300.445068,0.098031,0.000000
68.270004,64.792061,-1300.356079,-0.000164,0.003839,0.097511,288.209473,14.682091,0.975110,-1300.356079,0.098430,0.000000
68.510002,65.685387,-1300.311646,-0.000155,0.003851,0.097823,292.183197,14.884521,0.978231,-1300.311646,0.098829,0.000000
68.750000,66.749260,-1300.489624,-0.000147,0.003867,0.098213,296.915527,15.125598,0.982133,-1300.489624,0.099237,0.000000
68.990005,67.118645,-1300.356079,-0.000134,0.003866,0.098187,298.558655,15.209302,0.981874,-1300.356079,0.098421,0.000000
69.230003,66.628227,-1300.445068,-0.000138,0.003866,0.098187,296.377167,15.098171,0.981874,-1300.445068,0.098421,0.000000
69.470001,66.279320,-1300.400635,-0.000121,0.003863,0.098109,294.825134,15.019109,0.981094,-1300.400635,0.098187,0.000000
69.710007,65.896141,-1300.445068,-0.000134,0.003862,0.098083,293.120667,14.932280,0.980833,-1300.445068,0.098187,0.000000
69.950005,65.555061,-1300.400635,-0.000125,0.003861,0.098075,291.603485,14.854989,0.980746,-1300.400635,0.098187,0.000000
70.190002,65.256416,-1300.400635,-0.000112,0.003861,0.098066,290.275024,14.787314,0.980659,-1300.400635,0.098187,0.000000
70.430000,64.987190,-1300.400635,-0.000121,0.003861,0.098057,289.077454,14.726308,0.980574,-1300.400635,0.098187,0.000000
70.670006,64.764137,-1300.400635,-0.000121,0.003860,0.098049,288.085266,14.675763,0.980487,-1300.400635,0.098187,0.000000
70.910004,64.545174,-1300.445068,-0.000121,0.003860,0.098049,287.111267,14.626145,0.980487,-1300.445068,0.098187,0.000000
71.150002,64.336281,-1300.489624,-0.000116,0.003860,0.098040,286.182068,14.578809,0.980399,-1300.489624,0.098187,0.000000
71.390007,64.161263,-1300.400635,-0.000108,0.003860,0.098040,285.403564,14.539150,0.980399,-1300.400635,0.098187,0.000000
71.630005,63.975822,-1300.445068,-0.000103,0.003860,0.098040,284.578674,14.497129,0.980399,-1300.445068,0.098187,0.000000
71.870003,63.827614,-1300.400635,-0.000108,0.003859,0.098031,283.919403,14.463545,0.980312,-1300.400635,0.098187,0.000000
72.110001,63.675697,-1300.400635,-0.000116,0.003859,0.098031,283.243652,14.429119,0.980312,-1300.400635,0.098187,0.000000
72.350006,63.547218,-1300.489624,-0.000116,0.003859,0.098031,282.672150,14.400005,0.980312,-1300.489624,0.098187,0.000000
72.590004,63.403114,-1300.356079,-0.000116,0.003859,0.098031,282.031128,14.367352,0.980312,-1300.356079,0.098187,0.000000
72.830002,63.283211,-1300.489624,-0.000121,0.003859,0.098031,281.497772,14.340180,0.980312,-1300.489624,0.098187,0.000000
73.070000,63.163307,-1300.400635,-0.000112,0.003859,0.098031,280.964417,14.313009,0.980312,-1300.400635,0.098187,0.000000
73.310005,63.059410,-1300.445068,-0.000112,0.003859,0.098031,280.502258,14.289467,0.980312,-1300.445068,0.098187,0.000000
73.550003,62.953285,-1300.445068,-0.000099,0.003859,0.098023,280.030212,14.265418,0.980225,-1300.445068,0.098187,0.000000
73.790001,62.856842,-1300.400635,-0.000108,0.003859,0.098023,279.601196,14.243565,0.980225,-1300.400635,0.098187,0.000000
74.030006,62.752953,-1300.489624,-0.000103,0.003859,0.098023,279.139069,14.220022,0.980225,-1300.489624,0.098187,0.000000
74.270004,62.668053,-1300.445068,-0.000108,0.003859,0.098023,278.761414,14.200784,0.980225,-1300.445068,0.098187,0.000000
74.510002,62.576073,-1300.489624,-0.000116,0.003859,0.098023,278.352264,14.179941,0.980225,-1300.489624,0.098187,0.000000
74.750000,62.501228,-1300.445068,-0.000099,0.003859,0.098023,278.019348,14.162981,0.980225,-1300.445068,0.098187,0.000000
74.990005,62.418190,-1300.445068,-0.000103,0.003859,0.098023,277.649963,14.144164,0.980225,-1300.445068,0.098187,0.000000
75.230003,62.353027,-1300.534058,-0.000108,0.003859,0.098023,277.360107,14.129397,0.980225,-1300.534058,0.098187,0.000000
75.470001,62.274452,-1300.489624,-0.000103,0.003859,0.098023,277.010590,14.111592,0.980225,-1300.489624,0.098187,0.000000
75.710007,62.215988,-1300.445068,-0.000103,0.003859,0.098023,276.750549,14.098344,0.980225,-1300.445068,0.098187,0.000000
75.950005,62.146355,-1300.489624,-0.000095,0.003859,0.098023,276.440796,14.082565,0.980225,-1300.489624,0.098187,0.000000
76.190002,62.089760,-1300.489624,-0.000095,0.003859,0.098023,276.189056,14.069741,0.980225,-1300.489624,0.098187,0.000000
76.430000,62.012672,-1300.534058,-0.000099,0.003859,0.098023,275.846130,14.052272,0.980225,-1300.534058,0.098187,0.000000
76.670006,61.955330,-1300.445068,-0.000091,0.003859,0.098023,275.591064,14.039278,0.980225,-1300.445068,0.098187,0.000000
76.910004,61.903946,-1300.445068,-0.000095,0.003859,0.098023,275.362518,14.027635,0.980225,-1300.445068,0.098187,0.000000
77.150002,61.838776,-1300.445068,-0.000099,0.003859,0.098023,275.072601,14.012866,0.980225,-1300.445068,0.098187,0.000000
77.390007,61.794838,-1300.489624,-0.000099,0.003859,0.098023,274.877167,14.002911,0.980225,-1300.489624,0.098187,0.000000
77.630005,61.747177,-1300.489624,-0.000095,0.003859,0.098023,274.665161,13.992110,0.980225,-1300.489624,0.098187,0.000000
77.870003,61.686104,-1300.445068,-0.000099,0.003859,0.098023,274.393494,13.978271,0.980225,-1300.445068,0.098187,0.000000
78.110001,61.633972,-1300.489624,-0.000103,0.003859,0.098014,274.161591,13.966457,0.980138,-1300.489624,0.098187,0.000000
78.350006,61.578117,-1300.489624,-0.000095,0.003859,0.098014,273.913147,13.953800,0.980138,-1300.489624,0.098187,0.000000
78.590004,61.528221,-1300.489624,-0.000099,0.003859,0.098014,273.691193,13.942494,0.980138,-1300.489624,0.098187,0.000000
78.830002,61.492096,-1300.445068,-0.000099,0.003859,0.098014,273.530518,13.934308,0.980138,-1300.445068,0.098187,0.000000
79.070007,61.455605,-1300.445068,-0.000099,0.003859,0.098014,273.368195,13.926039,0.980138,-1300.445068,0.098187,0.000000
79.310005,61.391930,-1300.489624,-0.000095,0.003859,0.098014,273.084930,13.911611,0.980138,-1300.489624,0.098187,0.000000
79.550003,61.350967,-1300.489624,-0.000103,0.003859,0.098014,272.902740,13.902328,0.980138,-1300.489624,0.098187,0.000000
79.790001,61.327881,-1300.445068,-0.000095,0.003859,0.098014,272.800049,13.897097,0.980138,-1300.445068,0.098187,0.000000
80.030006,61.277611,-1300.489624,-0.000095,0.003859,0.098014,272.576416,13.885705,0.980138,-1300.489624,0.098187,0.000000
80.270004,61.245216,-1300.489624,-0.000091,0.003859,0.098014,272.432343,13.878365,0.980138,-1300.489624,0.098187,0.000000
80.510002,61.198296,-1300.534058,-0.000108,0.003859,0.098014,272.223602,13.867732,0.980138,-1300.534058,0.098187,0.000000
80.750008,61.164413,-1300.400635,-0.000091,0.003859,0.098014,272.072906,13.860054,0.980138,-1300.400635,0.098187,0.000000
80.990005,61.117493,-1300.445068,-0.000099,0.003859,0.098014,271.864197,13.849422,0.980138,-1300.445068,0.098187,0.000000
81.230003,61.089935,-1300.489624,-0.000103,0.003859,0.098014,271.741608,13.843178,0.980138,-1300.489624,0.098187,0.000000
81.470001,61.047112,-1300.489624,-0.000095,0.003859,0.098014,271.551117,13.833473,0.980138,-1300.489624,0.098187,0.000000
81.710007,61.008385,-1300.534058,-0.000095,0.003859,0.098014,271.378845,13.824697,0.980138,-1300.534058,0.098187,0.000000
81.950005,60.975616,-1300.489624,-0.000099,0.003859,0.098014,271.233093,13.817272,0.980138,-1300.489624,0.098187,0.000000
82.190002,60.931679,-1300.445068,-0.000086,0.003859,0.098014,271.037659,13.807316,0.980138,-1300.445068,0.098187,0.000000
82.430000,60.911942,-1300.489624,-0.000082,0.003859,0.098014,270.949860,13.802843,0.980138,-1300.489624,0.098187,0.000000
82.670006,60.874702,-1300.489624,-0.000099,0.003859,0.098014,270.784210,13.794404,0.980138,-1300.489624,0.098187,0.000000
82.910004,60.849388,-1300.489624,-0.000091,0.003859,0.098014,270.671600,13.788669,0.980138,-1300.489624,0.098187,0.000000
83.150002,60.813637,-1300.445068,-0.000099,0.003859,0.098014,270.512573,13.780567,0.980138,-1300.445068,0.098187,0.000000
83.390007,60.797249,-1300.489624,-0.000095,0.003859,0.098014,270.439667,13.776854,0.980138,-1300.489624,0.098187,0.000000
83.630005,60.765228,-1300.445068,-0.000086,0.003859,0.098014,270.297241,13.769598,0.980138,-1300.445068,0.098187,0.000000
83.870003,60.734322,-1300.489624,-0.000099,0.003859,0.098014,270.159760,13.762593,0.980138,-1300.489624,0.098187,0.000000
84.110001,60.692986,-1300.489624,-0.000095,0.003859,0.098014,269.975891,13.753227,0.980138,-1300.489624,0.098187,0.000000
84.350006,60.678841,-1300.445068,-0.000091,0.003859,0.098014,269.912964,13.750022,0.980138,-1300.445068,0.098187,0.000000
84.590004,60.641228,-1300.489624,-0.000108,0.003859,0.098014,269.745667,13.741498,0.980138,-1300.489624,0.098187,0.000000
84.830002,60.621864,-1300.489624,-0.000082,0.003859,0.098014,269.659515,13.737110,0.980138,-1300.489624,0.098187,0.000000
85.070007,60.591331,-1300.489624,-0.000086,0.003859,0.098014,269.523712,13.730192,0.980138,-1300.489624,0.098187,0.000000
85.310005,60.557816,-1300.445068,-0.000086,0.003859,0.098014,269.374603,13.722597,0.980138,-1300.445068,0.098187,0.000000
85.550003,60.520210,-1300.489624,-0.000095,0.003859,0.098014,269.207336,13.714076,0.980138,-1300.489624,0.098187,0.000000
85.790001,60.502335,-1300.534058,-0.000095,0.003859,0.098014,269.127838,13.710025,0.980138,-1300.534058,0.098187,0.000000
86.030006,60.494141,-1300.489624,-0.000086,0.003859,0.098014,269.091370,13.708169,0.980138,-1300.489624,0.098187,0.000000
86.270004,60.468819,-1300.445068,-0.000099,0.003859,0.098014,268.978729,13.702430,0.980138,-1300.445068,0.098187,0.000000
86.510002,60.440147,-1300.489624,-0.000095,0.003859,0.098014,268.851196,13.695932,0.980138,-1300.489624,0.098187,0.000000
86.750008,60.418549,-1300.489624,-0.000095,0.003859,0.098014,268.755127,13.691038,0.980138,-1300.489624,0.098187,0.000000
86.990005,60.397697,-1300.534058,-0.000095,0.003859,0.098014,268.662384,13.686315,0.980138,-1300.534058,0.098187,0.000000
87.230003,60.372002,-1300.445068,-0.000086,0.003859,0.098014,268.548065,13.680491,0.980138,-1300.445068,0.098187,0.000000
87.470001,60.348915,-1300.489624,-0.000086,0.003859,0.098014,268.445374,13.675260,0.980138,-1300.489624,0.098187,0.000000
87.710007,60.318008,-1300.489624,-0.000086,0.003859,0.098014,268.307892,13.668257,0.980138,-1300.489624,0.098187,0.000000
87.950005,60.299393,-1300.489624,-0.000091,0.003859,0.098014,268.225098,13.664038,0.980138,-1300.489624,0.098187,0.000000
88.190002,60.273697,-1300.623047,-0.000086,0.003859,0.098014,268.110809,13.658215,0.980138,-1300.623047,0.098187,0.000000
88.430008,60.247261,-1300.489624,-0.000091,0.003859,0.098014,267.993195,13.652225,0.980138,-1300.489624,0.098187,0.000000
88.670006,60.220818,-1300.489624,-0.000082,0.003859,0.098014,267.875580,13.646232,0.980138,-1300.489624,0.098187,0.000000
88.910004,60.213745,-1300.534058,-0.000095,0.003859,0.098014,267.844116,13.644629,0.980138,-1300.534058,0.098187,0.000000
89.150002,60.193268,-1300.489624,-0.000099,0.003859,0.098014,267.753021,13.639990,0.980138,-1300.489624,0.098187,0.000000
89.390007,60.157516,-1300.578491,-0.000082,0.003859,0.098014,267.593994,13.631888,0.980138,-1300.578491,0.098187,0.000000
89.630005,60.154167,-1300.445068,-0.000095,0.003859,0.098014,267.579102,13.631129,0.980138,-1300.445068,0.098187,0.000000
89.870003,60.126236,-1300.623047,-0.000099,0.003859,0.098014,267.454865,13.624800,0.980138,-1300.623047,0.098187,0.000000
90.110001,60.118042,-1300.578491,-0.000091,0.003859,0.098014,267.418396,13.622943,0.980138,-1300.578491,0.098187,0.000000
90.350006,60.092720,-1300.489624,-0.000091,0.003859,0.098014,267.305756,13.617205,0.980138,-1300.489624,0.098187,0.000000
90.590004,60.068893,-1300.445068,-0.000082,0.003859,0.098014,267.199768,13.611806,0.980138,-1300.445068,0.098187,0.000000
90.830002,60.054741,-1300.489624,-0.000086,0.003859,0.098014,267.136841,13.608599,0.980138,-1300.489624,0.098187,0.000000
91.070007,60.039101,-1300.578491,-0.000086,0.003859,0.098014,267.067261,13.605055,0.980138,-1300.578491,0.098187,0.000000
91.310005,60.016388,-1300.489624,-0.000091,0.003859,0.098014,266.966217,13.599908,0.980138,-1300.489624,0.098187,0.000000
91.550003,59.992928,-1300.489624,-0.000091,0.003859,0.098014,266.861877,13.594591,0.980138,-1300.489624,0.098187,0.000000
91.790001,59.970955,-1300.578491,-0.000099,0.003859,0.098014,266.764130,13.589613,0.980138,-1300.578491,0.098187,0.000000
92.030006,59.959785,-1300.445068,-0.000091,0.003859,0.098014,266.714447,13.587082,0.980138,-1300.445068,0.098187,0.000000
92.270004,59.944893,-1300.534058,-0.000082,0.003859,0.098014,266.648193,13.583707,0.980138,-1300.534058,0.098187,0.000000
92.510002,59.918449,-1300.445068,-0.000086,0.003859,0.098014,266.530579,13.577715,0.980138,-1300.445068,0.098187,0.000000
92.750008,59.903931,-1300.534058,-0.000095,0.003859,0.098014,266.466003,13.574425,0.980138,-1300.534058,0.098187,0.000000
92.990005,59.896858,-1300.578491,-0.000082,0.003859,0.098014,266.434540,13.572823,0.980138,-1300.578491,0.098187,0.000000
93.230003,59.878609,-1300.445068,-0.000091,0.003859,0.098014,266.353363,13.568687,0.980138,-1300.445068,0.098187,0.000000
93.470001,59.869675,-1300.578491,-0.000091,0.003859,0.098014,266.313599,13.566663,0.980138,-1300.578491,0.098187,0.000000
93.710007,59.841003,-1300.534058,-0.000099,0.003859,0.098014,266.186066,13.560165,0.980138,-1300.534058,0.098187,0.000000
93.950005,59.827965,-1300.534058,-0.000095,0.003859,0.098014,266.128082,13.557211,0.980138,-1300.534058,0.098187,0.000000
94.190002,59.802643,-1300.623047,-0.000082,0.003859,0.098014,266.015442,13.551473,0.980138,-1300.623047,0.098187,0.000000
94.430008,59.789238,-1300.489624,-0.000082,0.003859,0.098014,265.955811,13.548435,0.980138,-1300.489624,0.098187,0.000000
94.670006,59.769875,-1300.667480,-0.000086,0.003859,0.098014,265.869690,13.544047,0.980138,-1300.667480,0.098187,0.000000
94.910004,59.757217,-1300.534058,-0.000086,0.003859,0.098014,265.813385,13.541180,0.980138,-1300.534058,0.098187,0.000000
95.150002,59.730774,-1300.578491,-0.000086,0.003859,0.098014,265.695740,13.535187,0.980138,-1300.578491,0.098187,0.000000
95.390007,59.723328,-1300.623047,-0.000095,0.003859,0.098014,265.662628,13.533499,0.980138,-1300.623047,0.098187,0.000000
95.630005,59.699501,-1300.534058,-0.000091,0.003859,0.098014,265.556641,13.528100,0.980138,-1300.534058,0.098187,0.000000
95.870003,59.694656,-1300.534058,-0.000086,0.003859,0.098014,265.535095,13.527002,0.980138,-1300.534058,0.098187,0.000000
96.110008,59.666733,-1300.489624,-0.000091,0.003859,0.098014,265.410889,13.520675,0.980138,-1300.489624,0.098187,0.000000
96.350006,59.656677,-1300.623047,-0.000086,0.003859,0.098014,265.366150,13.518396,0.980138,-1300.623047,0.098187,0.000000
96.590004,59.650345,-1300.534058,-0.000095,0.003859,0.098014,265.337982,13.516961,0.980138,-1300.534058,0.098187,0.000000
96.830002,59.625771,-1300.534058,-0.000095,0.003859,0.098014,265.228668,13.511394,0.980138,-1300.534058,0.098187,0.000000
97.070007,59.611244,-1300.623047,-0.000095,0.003859,0.098014,265.164062,13.508101,0.980138,-1300.623047,0.098187,0.000000
97.310005,59.613106,-1300.489624,-0.000086,0.003859,0.098014,265.172333,13.508523,0.980138,-1300.489624,0.098187,0.000000
97.550003,59.600822,-1300.623047,-0.000099,0.003859,0.098014,265.117706,13.505739,0.980138,-1300.623047,0.098187,0.000000
97.790001,59.591507,-1300.578491,-0.000095,0.003859,0.098014,265.076263,13.503629,0.980138,-1300.578491,0.098187,0.000000
98.030006,59.571777,-1300.534058,-0.000091,0.003859,0.098014,264.988495,13.499158,0.980138,-1300.534058,0.098187,0.000000
98.270004,59.557251,-1300.578491,-0.000095,0.003859,0.098014,264.923889,13.495867,0.980138,-1300.578491,0.098187,0.000000
98.510002,59.535652,-1300.489624,-0.000082,0.003859,0.098014,264.827820,13.490972,0.980138,-1300.489624,0.098187,0.000000
98.750008,59.520012,-1300.534058,-0.000086,0.003859,0.098014,264.758240,13.487427,0.980138,-1300.534058,0.098187,0.000000
98.990005,59.506981,-1300.534058,-0.000091,0.003859,0.098014,264.700256,13.484475,0.980138,-1300.534058,0.098187,0.000000
99.230003,59.498047,-1300.534058,-0.000086,0.003859,0.098014,264.660522,13.482450,0.980138,-1300.534058,0.098187,0.000000
99.400002,59.494324,-1300.534058,-0.000091,0.003859,0.098014,264.643982,13.481606,0.980138,-1300.534058,0.098187,0.000000